{"f":274,"recv_ms":1786845516292,"raw":{"event_type":"price_change","market":"0xd5f15f31689703aea70b93a52194a0964220d10d92ee7497346f146a8b6ef8ab","price_changes":[{"asset_id":"2151378744569768920256500242561922410292857798164019061749528550808091180185","best_ask":"0.83","best_bid":"0.82","hash":"ab5ac7d4f0ef685dddb1226ef60f901672286ec6","price":"0.02","side":"BUY","size":"3745.18"},{"asset_id":"17406866367975599232214757606801140480252276357934486651183783311435802862074","best_ask":"0.18","best_bid":"0.17","hash":"555efdac62c7eed1d0e5ce9a5f36cf4135b29a0d","price":"0.98","side":"SELL","size":"3745.18"}],"timestamp":"1786845516079"}}
{"f":275,"recv_ms":1786845516292,"raw":{"event_type":"price_change","market":"0xd5f15f31689703aea70b93a52194a0964220d10d92ee7497346f146a8b6ef8ab","price_changes":[{"asset_id":"2151378744569768920256500242561922410292857798164019061749528550808091180185","best_ask":"0.83","best_bid":"0.82","hash":"74951f05048118427fc8b1aeb2bb47e7cc1115c2","price":"0.12","side":"BUY","size":"39.6"},{"asset_id":"17406866367975599232214757606801140480252276357934486651183783311435802862074","best_ask":"0.18","best_bid":"0.17","hash":"e6fe20794466b9af2d484dd5ad4d5be8d7bbc224","price":"0.88","side":"SELL","size":"39.6"}],"timestamp":"1786845516079"}}
{"f":276,"recv_ms":1786845516292,"raw":{"event_type":"price_change","market":"0xd5f15f31689703aea70b93a52194a0964220d10d92ee7497346f146a8b6ef8ab","price_changes":[{"asset_id":"2151378744569768920256500242561922410292857798164019061749528550808091180185","best_ask":"0.83","best_bid":"0.82","hash":"55ed0d933a61ced69e30c9fa3f27d1313efdf10a","price":"0.05","side":"BUY","size":"682.3"},{"asset_id":"17406866367975599232214757606801140480252276357934486651183783311435802862074","best_ask":"0.18","best_bid":"0.17","hash":"366f4a83d8485e60f57f25f18743a47b02523224","price":"0.95","side":"SELL","size":"682.3"}],"timestamp":"1786845516079"}}
{"f":277,"recv_ms":1786845516294,"raw":{"event_type":"price_change","market":"0xd5f15f31689703aea70b93a52194a0964220d10d92ee7497346f146a8b6ef8ab","price_changes":[{"asset_id":"2151378744569768920256500242561922410292857798164019061749528550808091180185","best_ask":"0.83","best_bid":"0.82","hash":"9b6296d43238aa666cb739448b9b7cf1c95121df","price":"0.11","side":"BUY","size":"51.6"},{"asset_id":"17406866367975599232214757606801140480252276357934486651183783311435802862074","best_ask":"0.18","best_bid":"0.17","hash":"c40c5a76346854dba0e26fdf3f28982afa489341","price":"0.89","side":"SELL","size":"51.6"}],"timestamp":"1786845516080"}}
{"f":278,"recv_ms":1786845516294,"raw":{"event_type":"price_change","market":"0xd5f15f31689703aea70b93a52194a0964220d10d92ee7497346f146a8b6ef8ab","price_changes":[{"asset_id":"2151378744569768920256500242561922410292857798164019061749528550808091180185","best_ask":"0.83","best_bid":"0.82","hash":"246e11768fdf1e54eb7392dd3ee2cb939509ebaa","price":"0.07","side":"BUY","size":"314.9"},{"asset_id":"17406866367975599232214757606801140480252276357934486651183783311435802862074","best_ask":"0.18","best_bid":"0.17","hash":"c5db1a54f66b6c3811b9c98a2906e286e0248903","price":"0.93","side":"SELL","size":"314.9"}],"timestamp":"1786845516080"}}
{"f":279,"recv_ms":1786845516294,"raw":{"event_type":"price_change","market":"0xd5f15f31689703aea70b93a52194a0964220d10d92ee7497346f146a8b6ef8ab","price_changes":[{"asset_id":"2151378744569768920256500242561922410292857798164019061749528550808091180185","best_ask":"0.83","best_bid":"0.82","hash":"c35b6caf868a148e1762ea75654ec9befb614219","price":"0.09","side":"BUY","size":"61.7"},{"asset_id":"17406866367975599232214757606801140480252276357934486651183783311435802862074","best_ask":"0.18","best_bid":"0.17","hash":"c8e1d0c7fd869311004541ec4e8c09fe418340a5","price":"0.91","side":"SELL","size":"61.7"}],"timestamp":"1786845516080"}}
{"f":280,"recv_ms":1786845516295,"raw":{"event_type":"price_change","market":"0xd5f15f31689703aea70b93a52194a0964220d10d92ee7497346f146a8b6ef8ab","price_changes":[{"asset_id":"2151378744569768920256500242561922410292857798164019061749528550808091180185","best_ask":"0.83","best_bid":"0.82","hash":"d1935a0652f95db051b78353e226052d527b7ae0","price":"0.04","side":"BUY","size":"397.7"},{"asset_id":"17406866367975599232214757606801140480252276357934486651183783311435802862074","best_ask":"0.18","best_bid":"0.17","hash":"b7e2cc8f244a42967f3971fb32ce7da9dde36ce4","price":"0.96","side":"SELL","size":"397.7"}],"timestamp":"1786845516080"}}
{"f":281,"recv_ms":1786845516295,"raw":{"event_type":"price_change","market":"0xd5f15f31689703aea70b93a52194a0964220d10d92ee7497346f146a8b6ef8ab","price_changes":[{"asset_id":"2151378744569768920256500242561922410292857798164019061749528550808091180185","best_ask":"0.83","best_bid":"0.82","hash":"5f29f3f114d3d9d469c78071a22c3bb7e16f4713","price":"0.01","side":"BUY","size":"5777.58"},{"asset_id":"17406866367975599232214757606801140480252276357934486651183783311435802862074","best_ask":"0.18","best_bid":"0.17","hash":"fc4933ad4fab02f6e2ea6dc1a460db71e6779831","price":"0.99","side":"SELL","size":"5777.58"}],"timestamp":"1786845516081"}}
{"f":282,"recv_ms":1786845516295,"raw":{"event_type":"price_change","market":"0xd5f15f31689703aea70b93a52194a0964220d10d92ee7497346f146a8b6ef8ab","price_changes":[{"asset_id":"2151378744569768920256500242561922410292857798164019061749528550808091180185","best_ask":"0.83","best_bid":"0.82","hash":"469b931c7263b9991a18969ef5c488d424abd7fb","price":"0.01","side":"BUY","size":"5782.58"},{"asset_id":"17406866367975599232214757606801140480252276357934486651183783311435802862074","best_ask":"0.18","best_bid":"0.17","hash":"a1ee7ee6af556c36e5b908e36ab4da52ce3ce8fa","price":"0.99","side":"SELL","size":"5782.58"}],"timestamp":"1786845516081"}}
{"f":283,"recv_ms":1786845516295,"raw":{"event_type":"price_change","market":"0xd5f15f31689703aea70b93a52194a0964220d10d92ee7497346f146a8b6ef8ab","price_changes":[{"asset_id":"2151378744569768920256500242561922410292857798164019061749528550808091180185","best_ask":"0.83","best_bid":"0.82","hash":"14ecae49eea8dc3e9d11d48c8336d22beef492ae","price":"0.01","side":"BUY","size":"5787.58"},{"asset_id":"17406866367975599232214757606801140480252276357934486651183783311435802862074","best_ask":"0.18","best_bid":"0.17","hash":"4ac0ca6b19b5e99058a6ed6769a531f2d5275475","price":"0.99","side":"SELL","size":"5787.58"}],"timestamp":"1786845516082"}}
{"f":284,"recv_ms":1786845516295,"raw":{"event_type":"price_change","market":"0xd5f15f31689703aea70b93a52194a0964220d10d92ee7497346f146a8b6ef8ab","price_changes":[{"asset_id":"2151378744569768920256500242561922410292857798164019061749528550808091180185","best_ask":"0.83","best_bid":"0.82","hash":"aeca92c18ddc042afb4b09b42d2e8a175ca0aa99","price":"0.06","side":"BUY","size":"406.1"},{"asset_id":"17406866367975599232214757606801140480252276357934486651183783311435802862074","best_ask":"0.18","best_bid":"0.17","hash":"51db3bccb9273f07e5bb0ef6ab1ddf89718e0185","price":"0.94","side":"SELL","size":"406.1"}],"timestamp":"1786845516083"}}
{"f":285,"recv_ms":1786845516295,"raw":{"event_type":"price_change","market":"0xd5f15f31689703aea70b93a52194a0964220d10d92ee7497346f146a8b6ef8ab","price_changes":[{"asset_id":"2151378744569768920256500242561922410292857798164019061749528550808091180185","best_ask":"0.83","best_bid":"0.82","hash":"32652b35d66595f88e17dcf7d043c9eb0b372393","price":"0.15","side":"BUY","size":"40.39"},{"asset_id":"17406866367975599232214757606801140480252276357934486651183783311435802862074","best_ask":"0.18","best_bid":"0.17","hash":"3f12a3a2cabfd7c3fd38980e84668b4309693171","price":"0.85","side":"SELL","size":"40.39"}],"timestamp":"1786845516083"}}
{"f":286,"recv_ms":1786845516296,"raw":{"event_type":"price_change","market":"0xd5f15f31689703aea70b93a52194a0964220d10d92ee7497346f146a8b6ef8ab","price_changes":[{"asset_id":"2151378744569768920256500242561922410292857798164019061749528550808091180185","best_ask":"0.83","best_bid":"0.82","hash":"e1626b71c6e663bd6d3624aa292e71e160114157","price":"0.16","side":"BUY","size":"29.3"},{"asset_id":"17406866367975599232214757606801140480252276357934486651183783311435802862074","best_ask":"0.18","best_bid":"0.17","hash":"cf7a4642cbb567c08c2e30ec8f2b1e5cc6dca451","price":"0.84","side":"SELL","size":"29.3"}],"timestamp":"1786845516083"}}
{"f":287,"recv_ms":1786845516296,"raw":{"event_type":"price_change","market":"0xd5f15f31689703aea70b93a52194a0964220d10d92ee7497346f146a8b6ef8ab","price_changes":[{"asset_id":"2151378744569768920256500242561922410292857798164019061749528550808091180185","best_ask":"0.83","best_bid":"0.82","hash":"74a43b8652e5347b26d15d31bd5894208d363a7b","price":"0.01","side":"BUY","size":"5792.58"},{"asset_id":"17406866367975599232214757606801140480252276357934486651183783311435802862074","best_ask":"0.18","best_bid":"0.17","hash":"f75a0ff48a31c9ec1a81f6da80f19becc55e730f","price":"0.99","side":"SELL","size":"5792.58"}],"timestamp":"1786845516083"}}
{"f":288,"recv_ms":1786845516296,"raw":{"event_type":"price_change","market":"0xd5f15f31689703aea70b93a52194a0964220d10d92ee7497346f146a8b6ef8ab","price_changes":[{"asset_id":"17406866367975599232214757606801140480252276357934486651183783311435802862074","best_ask":"0.18","best_bid":"0.17","hash":"df413c18cd54062220cbe4fecc70ea576dd6ab30","price":"0.01","side":"BUY","size":"5588.18"},{"asset_id":"2151378744569768920256500242561922410292857798164019061749528550808091180185","best_ask":"0.83","best_bid":"0.82","hash":"3ff402a7a09b9b15bf947662a130d97fb18767bc","price":"0.99","side":"SELL","size":"5588.18"}],"timestamp":"1786845516084"}}
{"f":289,"recv_ms":1786845516296,"raw":{"event_type":"price_change","market":"0xd5f15f31689703aea70b93a52194a0964220d10d92ee7497346f146a8b6ef8ab","price_changes":[{"asset_id":"2151378744569768920256500242561922410292857798164019061749528550808091180185","best_ask":"0.83","best_bid":"0.82","hash":"0a824340cc8385bc3dfe965678285642d8555b12","price":"0.14","side":"BUY","size":"31.6"},{"asset_id":"17406866367975599232214757606801140480252276357934486651183783311435802862074","best_ask":"0.18","best_bid":"0.17","hash":"c8c831f1f5c1cd21a788ad84c99ea1da5f83722f","price":"0.86","side":"SELL","size":"31.6"}],"timestamp":"1786845516084"}}
{"f":290,"recv_ms":1786845516305,"raw":{"event_type":"price_change","market":"0xd5f15f31689703aea70b93a52194a0964220d10d92ee7497346f146a8b6ef8ab","price_changes":[{"asset_id":"2151378744569768920256500242561922410292857798164019061749528550808091180185","best_ask":"0.83","best_bid":"0.82","hash":"b7f2a82fe335ca89bf14bf93fce7c94cc498121f","price":"0.1","side":"BUY","size":"93.9"},{"asset_id":"17406866367975599232214757606801140480252276357934486651183783311435802862074","best_ask":"0.18","best_bid":"0.17","hash":"8895bb921b6a067d7c8503f0b834eeb779bb2cfb","price":"0.9","side":"SELL","size":"93.9"}],"timestamp":"1786845516085"}}
{"f":291,"recv_ms":1786845516305,"raw":{"event_type":"price_change","market":"0xd5f15f31689703aea70b93a52194a0964220d10d92ee7497346f146a8b6ef8ab","price_changes":[{"asset_id":"2151378744569768920256500242561922410292857798164019061749528550808091180185","best_ask":"0.83","best_bid":"0.82","hash":"bf3742154dd29794f1830b584781970c7ba3900f","price":"0.17","side":"BUY","size":"28.39"},{"asset_id":"17406866367975599232214757606801140480252276357934486651183783311435802862074","best_ask":"0.18","best_bid":"0.17","hash":"5f18991a0942f8498e86986d965ad9035aace147","price":"0.83","side":"SELL","size":"28.39"}],"timestamp":"1786845516089"}}
{"f":292,"recv_ms":1786845516305,"raw":{"event_type":"price_change","market":"0xd5f15f31689703aea70b93a52194a0964220d10d92ee7497346f146a8b6ef8ab","price_changes":[{"asset_id":"2151378744569768920256500242561922410292857798164019061749528550808091180185","best_ask":"0.83","best_bid":"0.82","hash":"cb0d1f7a08681a280e9937b073399f910e92d5e7","price":"0.01","side":"BUY","size":"5892.58"},{"asset_id":"17406866367975599232214757606801140480252276357934486651183783311435802862074","best_ask":"0.18","best_bid":"0.17","hash":"cc772403b1cb92b87a04fbd525a1a81469cf1ed4","price":"0.99","side":"SELL","size":"5892.58"}],"timestamp":"1786845516093"}}
{"f":293,"recv_ms":1786845516307,"raw":{"event_type":"price_change","market":"0xd5f15f31689703aea70b93a52194a0964220d10d92ee7497346f146a8b6ef8ab","price_changes":[{"asset_id":"17406866367975599232214757606801140480252276357934486651183783311435802862074","best_ask":"0.18","best_bid":"0.17","hash":"d41c0811d7bfc6b025a03a7016288f97c9f6f689","price":"0.33","side":"SELL","size":"10"},{"asset_id":"2151378744569768920256500242561922410292857798164019061749528550808091180185","best_ask":"0.83","best_bid":"0.82","hash":"0f17838cee996553d8b15c644a9ffa36b9d7d340","price":"0.67","side":"BUY","size":"10"}],"timestamp":"1786845516094"}}
{"f":294,"recv_ms":1786845516307,"raw":{"event_type":"price_change","market":"0xd5f15f31689703aea70b93a52194a0964220d10d92ee7497346f146a8b6ef8ab","price_changes":[{"asset_id":"17406866367975599232214757606801140480252276357934486651183783311435802862074","best_ask":"0.18","best_bid":"0.17","hash":"6e49e257950a19268830d2cd8a4ab15e5a147455","price":"0.31","side":"SELL","size":"100"},{"asset_id":"2151378744569768920256500242561922410292857798164019061749528550808091180185","best_ask":"0.83","best_bid":"0.82","hash":"fe9f4d3cb51541b59afdeee23ac4d7c212716b26","price":"0.69","side":"BUY","size":"100"}],"timestamp":"1786845516094"}}
{"f":295,"recv_ms":1786845516307,"raw":{"event_type":"price_change","market":"0xd5f15f31689703aea70b93a52194a0964220d10d92ee7497346f146a8b6ef8ab","price_changes":[{"asset_id":"17406866367975599232214757606801140480252276357934486651183783311435802862074","best_ask":"0.18","best_bid":"0.17","hash":"3c2d95b18e62d083b8af11a4ed2205d99e249261","price":"0.32","side":"SELL","size":"105"},{"asset_id":"2151378744569768920256500242561922410292857798164019061749528550808091180185","best_ask":"0.83","best_bid":"0.82","hash":"65d22112c66f4ef62521a872f16455085001e726","price":"0.68","side":"BUY","size":"105"}],"timestamp":"1786845516095"}}
{"f":296,"recv_ms":1786845516310,"raw":{"event_type":"price_change","market":"0xd5f15f31689703aea70b93a52194a0964220d10d92ee7497346f146a8b6ef8ab","price_changes":[{"asset_id":"2151378744569768920256500242561922410292857798164019061749528550808091180185","best_ask":"0.83","best_bid":"0.82","hash":"d8277a8492ae8e2de5ed1d1301ffcb00d1e1420e","price":"0.13","side":"BUY","size":"38"},{"asset_id":"17406866367975599232214757606801140480252276357934486651183783311435802862074","best_ask":"0.18","best_bid":"0.17","hash":"0eb1d5feaef1d2afb5fe9dcac1dd6e5a5f35ce59","price":"0.87","side":"SELL","size":"38"}],"timestamp":"1786845516096"}}
{"f":297,"recv_ms":1786845516310,"raw":{"event_type":"price_change","market":"0xd5f15f31689703aea70b93a52194a0964220d10d92ee7497346f146a8b6ef8ab","price_changes":[{"asset_id":"2151378744569768920256500242561922410292857798164019061749528550808091180185","best_ask":"0.83","best_bid":"0.82","hash":"cdf0258954d5cbbd3aa260f8fc098c2098f313c2","price":"0.05","side":"BUY","size":"677.3"},{"asset_id":"17406866367975599232214757606801140480252276357934486651183783311435802862074","best_ask":"0.18","best_bid":"0.17","hash":"dbcb8c5a3bfb78ea7859f62188c9f6e289f84541","price":"0.95","side":"SELL","size":"677.3"}],"timestamp":"1786845516098"}}
{"f":298,"recv_ms":1786845516310,"raw":{"event_type":"price_change","market":"0xd5f15f31689703aea70b93a52194a0964220d10d92ee7497346f146a8b6ef8ab","price_changes":[{"asset_id":"2151378744569768920256500242561922410292857798164019061749528550808091180185","best_ask":"0.83","best_bid":"0.82","hash":"36cee50a4aaae35aecf7ab84425d13109fb10d4f","price":"0.03","side":"BUY","size":"737.3"},{"asset_id":"17406866367975599232214757606801140480252276357934486651183783311435802862074","best_ask":"0.18","best_bid":"0.17","hash":"6972738a66129e4aab2e5264be289888d5d28efb","price":"0.97","side":"SELL","size":"737.3"}],"timestamp":"1786845516098"}}
{"f":299,"recv_ms":1786845516310,"raw":{"event_type":"price_change","market":"0xd5f15f31689703aea70b93a52194a0964220d10d92ee7497346f146a8b6ef8ab","price_changes":[{"asset_id":"2151378744569768920256500242561922410292857798164019061749528550808091180185","best_ask":"0.83","best_bid":"0.82","hash":"45c3f8d89a65411df0f48f53356190b5c7051885","price":"0.08","side":"BUY","size":"60.29"},{"asset_id":"17406866367975599232214757606801140480252276357934486651183783311435802862074","best_ask":"0.18","best_bid":"0.17","hash":"3ae32859e727e570248d43611c84efd57186d840","price":"0.92","side":"SELL","size":"60.29"}],"timestamp":"1786845516099"}}
{"f":300,"recv_ms":1786845516313,"raw":{"event_type":"price_change","market":"0xd5f15f31689703aea70b93a52194a0964220d10d92ee7497346f146a8b6ef8ab","price_changes":[{"asset_id":"2151378744569768920256500242561922410292857798164019061749528550808091180185","best_ask":"0.83","best_bid":"0.82","hash":"6074bb24caf8347fe487d10331577ba1ff467a7b","price":"0.09","side":"BUY","size":"56.7"},{"asset_id":"17406866367975599232214757606801140480252276357934486651183783311435802862074","best_ask":"0.18","best_bid":"0.17","hash":"b253cc0b92f91178d539f021bb9eee0c62a81a79","price":"0.91","side":"SELL","size":"56.7"}],"timestamp":"1786845516100"}}
{"f":301,"recv_ms":1786845516314,"raw":{"event_type":"price_change","market":"0xd5f15f31689703aea70b93a52194a0964220d10d92ee7497346f146a8b6ef8ab","price_changes":[{"asset_id":"2151378744569768920256500242561922410292857798164019061749528550808091180185","best_ask":"0.83","best_bid":"0.82","hash":"9a4390a0c69cada4d8ef951dde65f95de85fd8e3","price":"0.04","side":"BUY","size":"392.7"},{"asset_id":"17406866367975599232214757606801140480252276357934486651183783311435802862074","best_ask":"0.18","best_bid":"0.17","hash":"d5e59a2196b7bd9d7eee0fab91ee9af86fa06c19","price":"0.96","side":"SELL","size":"392.7"}],"timestamp":"1786845516100"}}
{"f":302,"recv_ms":1786845516314,"raw":{"event_type":"price_change","market":"0xd5f15f31689703aea70b93a52194a0964220d10d92ee7497346f146a8b6ef8ab","price_changes":[{"asset_id":"2151378744569768920256500242561922410292857798164019061749528550808091180185","best_ask":"0.83","best_bid":"0.82","hash":"5a3c96d2ca38568d1138ba151c982925b7cb579b","price":"0.13","side":"BUY","size":"33"},{"asset_id":"17406866367975599232214757606801140480252276357934486651183783311435802862074","best_ask":"0.18","best_bid":"0.17","hash":"dbb6aa878a6e8d73f28c1546be1d8cf1ecf8897d","price":"0.87","side":"SELL","size":"33"}],"timestamp":"1786845516100"}}
{"f":303,"recv_ms":1786845516314,"raw":{"event_type":"price_change","market":"0xd5f15f31689703aea70b93a52194a0964220d10d92ee7497346f146a8b6ef8ab","price_changes":[{"asset_id":"2151378744569768920256500242561922410292857798164019061749528550808091180185","best_ask":"0.83","best_bid":"0.82","hash":"f01d6a246e266dc043ebc9b30c98c0db80736634","price":"0.07","side":"BUY","size":"309.9"},{"asset_id":"17406866367975599232214757606801140480252276357934486651183783311435802862074","best_ask":"0.18","best_bid":"0.17","hash":"115e958f93a5aff8cb4f2ee442f8ba0332c01a5c","price":"0.93","side":"SELL","size":"309.9"}],"timestamp":"1786845516101"}}
{"f":304,"recv_ms":1786845516314,"raw":{"event_type":"price_change","market":"0xd5f15f31689703aea70b93a52194a0964220d10d92ee7497346f146a8b6ef8ab","price_changes":[{"asset_id":"2151378744569768920256500242561922410292857798164019061749528550808091180185","best_ask":"0.83","best_bid":"0.82","hash":"a7bdb6c408514e43cd86349194b0eb3b9ef48a21","price":"0.02","side":"BUY","size":"3740.18"},{"asset_id":"17406866367975599232214757606801140480252276357934486651183783311435802862074","best_ask":"0.18","best_bid":"0.17","hash":"ce0a5b3099aa92e855dfadbba30b15b3dcaf1b08","price":"0.98","side":"SELL","size":"3740.18"}],"timestamp":"1786845516101"}}
{"f":305,"recv_ms":1786845516314,"raw":{"event_type":"price_change","market":"0xd5f15f31689703aea70b93a52194a0964220d10d92ee7497346f146a8b6ef8ab","price_changes":[{"asset_id":"2151378744569768920256500242561922410292857798164019061749528550808091180185","best_ask":"0.83","best_bid":"0.82","hash":"fd6b8c231dfbb29e6b5403dc1831b71fb7884209","price":"0.01","side":"BUY","size":"5887.58"},{"asset_id":"17406866367975599232214757606801140480252276357934486651183783311435802862074","best_ask":"0.18","best_bid":"0.17","hash":"8cdc5010182a02cd152d2db8ef29c52db9f13ca5","price":"0.99","side":"SELL","size":"5887.58"}],"timestamp":"1786845516101"}}
{"f":306,"recv_ms":1786845516314,"raw":{"event_type":"price_change","market":"0xd5f15f31689703aea70b93a52194a0964220d10d92ee7497346f146a8b6ef8ab","price_changes":[{"asset_id":"2151378744569768920256500242561922410292857798164019061749528550808091180185","best_ask":"0.83","best_bid":"0.82","hash":"cc415cf62ba59bcd113d465e20f33aec50b24bcf","price":"0.11","side":"BUY","size":"46.6"},{"asset_id":"17406866367975599232214757606801140480252276357934486651183783311435802862074","best_ask":"0.18","best_bid":"0.17","hash":"c0662635927de55b00ac0f6fb985ff3e4b000e06","price":"0.89","side":"SELL","size":"46.6"}],"timestamp":"1786845516101"}}
{"f":307,"recv_ms":1786845516315,"raw":{"event_type":"price_change","market":"0xd5f15f31689703aea70b93a52194a0964220d10d92ee7497346f146a8b6ef8ab","price_changes":[{"asset_id":"2151378744569768920256500242561922410292857798164019061749528550808091180185","best_ask":"0.83","best_bid":"0.82","hash":"3ad3066f2796c4652c114f8b558097140627611f","price":"0.01","side":"BUY","size":"5882.58"},{"asset_id":"17406866367975599232214757606801140480252276357934486651183783311435802862074","best_ask":"0.18","best_bid":"0.17","hash":"e2136c624504213cb2036aa4c70beeaa006fa9ce","price":"0.99","side":"SELL","size":"5882.58"}],"timestamp":"1786845516102"}}
{"f":308,"recv_ms":1786845516315,"raw":{"event_type":"price_change","market":"0xd5f15f31689703aea70b93a52194a0964220d10d92ee7497346f146a8b6ef8ab","price_changes":[{"asset_id":"2151378744569768920256500242561922410292857798164019061749528550808091180185","best_ask":"0.83","best_bid":"0.82","hash":"c77da9a1c41fdc54a290b953662d103fc5da4df7","price":"0.14","side":"BUY","size":"26.6"},{"asset_id":"17406866367975599232214757606801140480252276357934486651183783311435802862074","best_ask":"0.18","best_bid":"0.17","hash":"f2323194d45770cabfe27acf9d4092b850585263","price":"0.86","side":"SELL","size":"26.6"}],"timestamp":"1786845516102"}}
{"f":309,"recv_ms":1786845516315,"raw":{"event_type":"price_change","market":"0xd5f15f31689703aea70b93a52194a0964220d10d92ee7497346f146a8b6ef8ab","price_changes":[{"asset_id":"2151378744569768920256500242561922410292857798164019061749528550808091180185","best_ask":"0.83","best_bid":"0.82","hash":"bd8df0811d117a7bb2855eab6856fb2a44a79a73","price":"0.06","side":"BUY","size":"401.1"},{"asset_id":"17406866367975599232214757606801140480252276357934486651183783311435802862074","best_ask":"0.18","best_bid":"0.17","hash":"9f627ecaef5493e1e856f53c4e593a688cd3a142","price":"0.94","side":"SELL","size":"401.1"}],"timestamp":"1786845516103"}}
{"f":310,"recv_ms":1786845516317,"raw":{"event_type":"price_change","market":"0xd5f15f31689703aea70b93a52194a0964220d10d92ee7497346f146a8b6ef8ab","price_changes":[{"asset_id":"2151378744569768920256500242561922410292857798164019061749528550808091180185","best_ask":"0.83","best_bid":"0.82","hash":"47c34dca9b78b23fa551d1392344d8edd1cc81fc","price":"0.15","side":"BUY","size":"35.39"},{"asset_id":"17406866367975599232214757606801140480252276357934486651183783311435802862074","best_ask":"0.18","best_bid":"0.17","hash":"1b295e018a53c85976bfd3033430c306c9eb87b4","price":"0.85","side":"SELL","size":"35.39"}],"timestamp":"1786845516104"}}
{"f":311,"recv_ms":1786845516317,"raw":{"event_type":"price_change","market":"0xd5f15f31689703aea70b93a52194a0964220d10d92ee7497346f146a8b6ef8ab","price_changes":[{"asset_id":"2151378744569768920256500242561922410292857798164019061749528550808091180185","best_ask":"0.83","best_bid":"0.82","hash":"fd2478c8a15057316044d093b4da2538af3e05cc","price":"0.1","side":"BUY","size":"88.9"},{"asset_id":"17406866367975599232214757606801140480252276357934486651183783311435802862074","best_ask":"0.18","best_bid":"0.17","hash":"9ba141a7ac0412de852936025d508b206de0812f","price":"0.9","side":"SELL","size":"88.9"}],"timestamp":"1786845516105"}}
{"f":312,"recv_ms":1786845516318,"raw":{"event_type":"price_change","market":"0xd5f15f31689703aea70b93a52194a0964220d10d92ee7497346f146a8b6ef8ab","price_changes":[{"asset_id":"2151378744569768920256500242561922410292857798164019061749528550808091180185","best_ask":"0.83","best_bid":"0.82","hash":"cf72e1a1070c66c4fe36ff11234ddbb4b340ae53","price":"0.07","side":"BUY","size":"304.9"},{"asset_id":"17406866367975599232214757606801140480252276357934486651183783311435802862074","best_ask":"0.18","best_bid":"0.17","hash":"ed86bc62006de51acbaa560b47ba90546cf70cc2","price":"0.93","side":"SELL","size":"304.9"}],"timestamp":"1786845516105"}}
{"f":313,"recv_ms":1786845516319,"raw":{"event_type":"price_change","market":"0xd5f15f31689703aea70b93a52194a0964220d10d92ee7497346f146a8b6ef8ab","price_changes":[{"asset_id":"2151378744569768920256500242561922410292857798164019061749528550808091180185","best_ask":"0.83","best_bid":"0.82","hash":"c8fb2c60de2b31d4d18cd74f0df52d2ce8166739","price":"0.06","side":"BUY","size":"396.1"},{"asset_id":"17406866367975599232214757606801140480252276357934486651183783311435802862074","best_ask":"0.18","best_bid":"0.17","hash":"fb6849269eb2036f6dd2946b269427e1860ea720","price":"0.94","side":"SELL","size":"396.1"}],"timestamp":"1786845516106"}}
{"f":314,"recv_ms":1786845516319,"raw":{"event_type":"price_change","market":"0xd5f15f31689703aea70b93a52194a0964220d10d92ee7497346f146a8b6ef8ab","price_changes":[{"asset_id":"2151378744569768920256500242561922410292857798164019061749528550808091180185","best_ask":"0.83","best_bid":"0.82","hash":"26c2193c9cb486e0575ea5d32e8acc5daf7a0d42","price":"0.04","side":"BUY","size":"387.7"},{"asset_id":"17406866367975599232214757606801140480252276357934486651183783311435802862074","best_ask":"0.18","best_bid":"0.17","hash":"9cdd58586d0bcece05099c4a99541b880f010732","price":"0.96","side":"SELL","size":"387.7"}],"timestamp":"1786845516106"}}
{"f":315,"recv_ms":1786845516319,"raw":{"event_type":"price_change","market":"0xd5f15f31689703aea70b93a52194a0964220d10d92ee7497346f146a8b6ef8ab","price_changes":[{"asset_id":"2151378744569768920256500242561922410292857798164019061749528550808091180185","best_ask":"0.83","best_bid":"0.82","hash":"07c10f1ad6b41b9262d78870f6e7e5f972dbb730","price":"0.03","side":"BUY","size":"732.3"},{"asset_id":"17406866367975599232214757606801140480252276357934486651183783311435802862074","best_ask":"0.18","best_bid":"0.17","hash":"28136ff3c9e56cb75a25cd9e715f59c028b79053","price":"0.97","side":"SELL","size":"732.3"}],"timestamp":"1786845516107"}}
{"f":316,"recv_ms":1786845516320,"raw":{"event_type":"price_change","market":"0xd5f15f31689703aea70b93a52194a0964220d10d92ee7497346f146a8b6ef8ab","price_changes":[{"asset_id":"2151378744569768920256500242561922410292857798164019061749528550808091180185","best_ask":"0.83","best_bid":"0.82","hash":"12d8f429487b7023fb082b014811b46f50e323ce","price":"0.05","side":"BUY","size":"672.3"},{"asset_id":"17406866367975599232214757606801140480252276357934486651183783311435802862074","best_ask":"0.18","best_bid":"0.17","hash":"a259c3683cebedfdf2632a1963ef5be8faa6c442","price":"0.95","side":"SELL","size":"672.3"}],"timestamp":"1786845516107"}}
{"f":317,"recv_ms":1786845516321,"raw":{"event_type":"price_change","market":"0xd5f15f31689703aea70b93a52194a0964220d10d92ee7497346f146a8b6ef8ab","price_changes":[{"asset_id":"2151378744569768920256500242561922410292857798164019061749528550808091180185","best_ask":"0.83","best_bid":"0.82","hash":"4cd8f314d5b447e4c5818efbd35288d55271adeb","price":"0.09","side":"BUY","size":"51.7"},{"asset_id":"17406866367975599232214757606801140480252276357934486651183783311435802862074","best_ask":"0.18","best_bid":"0.17","hash":"c286835797d630920d0112801359964e69fc4a0e","price":"0.91","side":"SELL","size":"51.7"}],"timestamp":"1786845516108"}}
{"f":318,"recv_ms":1786845516321,"raw":{"event_type":"price_change","market":"0xd5f15f31689703aea70b93a52194a0964220d10d92ee7497346f146a8b6ef8ab","price_changes":[{"asset_id":"2151378744569768920256500242561922410292857798164019061749528550808091180185","best_ask":"0.83","best_bid":"0.82","hash":"09ad6b45b8f337412776b6ae1fce4a1d47ac1b05","price":"0.16","side":"BUY","size":"24.3"},{"asset_id":"17406866367975599232214757606801140480252276357934486651183783311435802862074","best_ask":"0.18","best_bid":"0.17","hash":"38dd311f5a3dd797f8391aa7b8c5394925a2c532","price":"0.84","side":"SELL","size":"24.3"}],"timestamp":"1786845516109"}}
{"f":319,"recv_ms":1786845516321,"raw":{"event_type":"price_change","market":"0xd5f15f31689703aea70b93a52194a0964220d10d92ee7497346f146a8b6ef8ab","price_changes":[{"asset_id":"2151378744569768920256500242561922410292857798164019061749528550808091180185","best_ask":"0.83","best_bid":"0.82","hash":"279760301b179ae2ca8bc669dbcb8f27d92c6853","price":"0.14","side":"BUY","size":"21.6"},{"asset_id":"17406866367975599232214757606801140480252276357934486651183783311435802862074","best_ask":"0.18","best_bid":"0.17","hash":"6df397a53e59fd00ace9db7c8475bb933f7bc438","price":"0.86","side":"SELL","size":"21.6"}],"timestamp":"1786845516109"}}
{"f":320,"recv_ms":1786845516322,"raw":{"event_type":"price_change","market":"0xd5f15f31689703aea70b93a52194a0964220d10d92ee7497346f146a8b6ef8ab","price_changes":[{"asset_id":"2151378744569768920256500242561922410292857798164019061749528550808091180185","best_ask":"0.83","best_bid":"0.82","hash":"515a3252270d8c5619a927f811f10603dad73fd4","price":"0.15","side":"BUY","size":"30.39"},{"asset_id":"17406866367975599232214757606801140480252276357934486651183783311435802862074","best_ask":"0.18","best_bid":"0.17","hash":"6ab4b2de4a5638a8931dde6efd7e99ecb8b7a0c1","price":"0.85","side":"SELL","size":"30.39"}],"timestamp":"1786845516109"}}
{"f":321,"recv_ms":1786845516322,"raw":{"event_type":"price_change","market":"0xd5f15f31689703aea70b93a52194a0964220d10d92ee7497346f146a8b6ef8ab","price_changes":[{"asset_id":"2151378744569768920256500242561922410292857798164019061749528550808091180185","best_ask":"0.83","best_bid":"0.82","hash":"9dd20a62a4459a9916ee076da470060d2e3130fd","price":"0.16","side":"BUY","size":"19.3"},{"asset_id":"17406866367975599232214757606801140480252276357934486651183783311435802862074","best_ask":"0.18","best_bid":"0.17","hash":"292ff8838fbcf3d48465bd958c5b91ee21f2eebe","price":"0.84","side":"SELL","size":"19.3"}],"timestamp":"1786845516109"}}
{"f":322,"recv_ms":1786845516325,"raw":{"event_type":"price_change","market":"0xd5f15f31689703aea70b93a52194a0964220d10d92ee7497346f146a8b6ef8ab","price_changes":[{"asset_id":"2151378744569768920256500242561922410292857798164019061749528550808091180185","best_ask":"0.83","best_bid":"0.82","hash":"c5c230c31fcc7f8e812a7caafb5f277c38875b5f","price":"0.19","side":"BUY","size":"26.89"},{"asset_id":"17406866367975599232214757606801140480252276357934486651183783311435802862074","best_ask":"0.18","best_bid":"0.17","hash":"ac15ba45942fe7c3565441a4c1c2c4a17f704cd6","price":"0.81","side":"SELL","size":"26.89"}],"timestamp":"1786845516110"}}
{"f":323,"recv_ms":1786845516325,"raw":{"event_type":"price_change","market":"0xd5f15f31689703aea70b93a52194a0964220d10d92ee7497346f146a8b6ef8ab","price_changes":[{"asset_id":"2151378744569768920256500242561922410292857798164019061749528550808091180185","best_ask":"0.83","best_bid":"0.82","hash":"775ce9b1431d4b41a8d5c9dc3060aea387ac086d","price":"0.08","side":"BUY","size":"55.29"},{"asset_id":"17406866367975599232214757606801140480252276357934486651183783311435802862074","best_ask":"0.18","best_bid":"0.17","hash":"e37f5307a11855945e0f66636da5d920babc2536","price":"0.92","side":"SELL","size":"55.29"}],"timestamp":"1786845516111"}}
{"f":324,"recv_ms":1786845516325,"raw":{"event_type":"price_change","market":"0xd5f15f31689703aea70b93a52194a0964220d10d92ee7497346f146a8b6ef8ab","price_changes":[{"asset_id":"2151378744569768920256500242561922410292857798164019061749528550808091180185","best_ask":"0.83","best_bid":"0.82","hash":"7bdc24d4b79fa7b28d1d7355a10187eed0102e81","price":"0.12","side":"BUY","size":"34.6"},{"asset_id":"17406866367975599232214757606801140480252276357934486651183783311435802862074","best_ask":"0.18","best_bid":"0.17","hash":"8cc790674587b9a38a15c25a4258b8535f8a22c6","price":"0.88","side":"SELL","size":"34.6"}],"timestamp":"1786845516112"}}
{"f":325,"recv_ms":1786845516325,"raw":{"event_type":"price_change","market":"0xd5f15f31689703aea70b93a52194a0964220d10d92ee7497346f146a8b6ef8ab","price_changes":[{"asset_id":"2151378744569768920256500242561922410292857798164019061749528550808091180185","best_ask":"0.83","best_bid":"0.82","hash":"419f74c417d62c61cbe6b28f89dfa7561810cc98","price":"0.12","side":"BUY","size":"29.6"},{"asset_id":"17406866367975599232214757606801140480252276357934486651183783311435802862074","best_ask":"0.18","best_bid":"0.17","hash":"2521b3c30180277bd89ae08fb5f89ea3317cb34b","price":"0.88","side":"SELL","size":"29.6"}],"timestamp":"1786845516112"}}
{"f":326,"recv_ms":1786845516325,"raw":{"event_type":"price_change","market":"0xd5f15f31689703aea70b93a52194a0964220d10d92ee7497346f146a8b6ef8ab","price_changes":[{"asset_id":"2151378744569768920256500242561922410292857798164019061749528550808091180185","best_ask":"0.83","best_bid":"0.82","hash":"73b39f126f149d5f140d8a35c965bd19c773eb64","price":"0.02","side":"BUY","size":"3735.18"},{"asset_id":"17406866367975599232214757606801140480252276357934486651183783311435802862074","best_ask":"0.18","best_bid":"0.17","hash":"dedb97068be226395a2a9503a9265cb2a7d0395d","price":"0.98","side":"SELL","size":"3735.18"}],"timestamp":"1786845516112"}}
{"f":327,"recv_ms":1786845516325,"raw":{"event_type":"price_change","market":"0xd5f15f31689703aea70b93a52194a0964220d10d92ee7497346f146a8b6ef8ab","price_changes":[{"asset_id":"2151378744569768920256500242561922410292857798164019061749528550808091180185","best_ask":"0.83","best_bid":"0.82","hash":"5c551e23d35c43548a03b36bf3cc0094794d1ad0","price":"0.18","side":"BUY","size":"17.6"},{"asset_id":"17406866367975599232214757606801140480252276357934486651183783311435802862074","best_ask":"0.18","best_bid":"0.17","hash":"226d93e8397982c1e0acc115417bf685baf9c85e","price":"0.82","side":"SELL","size":"17.6"}],"timestamp":"1786845516113"}}
{"f":328,"recv_ms":1786845516325,"raw":{"event_type":"price_change","market":"0xd5f15f31689703aea70b93a52194a0964220d10d92ee7497346f146a8b6ef8ab","price_changes":[{"asset_id":"2151378744569768920256500242561922410292857798164019061749528550808091180185","best_ask":"0.83","best_bid":"0.82","hash":"aa9c01bca25dadc267d8d8203acb331092bdea87","price":"0.2","side":"BUY","size":"49.1"},{"asset_id":"17406866367975599232214757606801140480252276357934486651183783311435802862074","best_ask":"0.18","best_bid":"0.17","hash":"904a9b3acea04c0f23c5a6f255310a51ac577715","price":"0.8","side":"SELL","size":"49.1"}],"timestamp":"1786845516113"}}
{"f":329,"recv_ms":1786845516325,"raw":{"event_type":"price_change","market":"0xd5f15f31689703aea70b93a52194a0964220d10d92ee7497346f146a8b6ef8ab","price_changes":[{"asset_id":"2151378744569768920256500242561922410292857798164019061749528550808091180185","best_ask":"0.83","best_bid":"0.82","hash":"d80e6341d60e2717383d1299c0c505351fc1bcf9","price":"0.01","side":"BUY","size":"5877.58"},{"asset_id":"17406866367975599232214757606801140480252276357934486651183783311435802862074","best_ask":"0.18","best_bid":"0.17","hash":"8fc819ec61ba6c0425aecd77442468d7e599d100","price":"0.99","side":"SELL","size":"5877.58"}],"timestamp":"1786845516113"}}
{"f":330,"recv_ms":1786845516328,"raw":{"event_type":"price_change","market":"0xd5f15f31689703aea70b93a52194a0964220d10d92ee7497346f146a8b6ef8ab","price_changes":[{"asset_id":"2151378744569768920256500242561922410292857798164019061749528550808091180185","best_ask":"0.83","best_bid":"0.82","hash":"f59528f250d65c92f429a0138e61746377c863fd","price":"0.01","side":"BUY","size":"5883.58"},{"asset_id":"17406866367975599232214757606801140480252276357934486651183783311435802862074","best_ask":"0.18","best_bid":"0.17","hash":"a897f6f59136690bbb09f3d17ad43e8225cc7a85","price":"0.99","side":"SELL","size":"5883.58"}],"timestamp":"1786845516114"}}
{"f":331,"recv_ms":1786845516330,"raw":{"event_type":"price_change","market":"0xd5f15f31689703aea70b93a52194a0964220d10d92ee7497346f146a8b6ef8ab","price_changes":[{"asset_id":"2151378744569768920256500242561922410292857798164019061749528550808091180185","best_ask":"0.83","best_bid":"0.82","hash":"6279668979255b16aca638eef0e0734df1e8dc70","price":"0.21","side":"BUY","size":"20.7"},{"asset_id":"17406866367975599232214757606801140480252276357934486651183783311435802862074","best_ask":"0.18","best_bid":"0.17","hash":"7f91c8c03f7c6369d8905b6ecd7f14d79ed29fc8","price":"0.79","side":"SELL","size":"20.7"}],"timestamp":"1786845516114"}}
{"f":332,"recv_ms":1786845516330,"raw":{"event_type":"price_change","market":"0xd5f15f31689703aea70b93a52194a0964220d10d92ee7497346f146a8b6ef8ab","price_changes":[{"asset_id":"2151378744569768920256500242561922410292857798164019061749528550808091180185","best_ask":"0.83","best_bid":"0.82","hash":"8fb2230cc7c1426d0ecfe74de39c293242585b87","price":"0.23","side":"BUY","size":"114.7"},{"asset_id":"17406866367975599232214757606801140480252276357934486651183783311435802862074","best_ask":"0.18","best_bid":"0.17","hash":"3a75b46e8464af78c3e0449c63b800d3580cc7db","price":"0.77","side":"SELL","size":"114.7"}],"timestamp":"1786845516115"}}
{"f":333,"recv_ms":1786845516330,"raw":{"event_type":"price_change","market":"0xd5f15f31689703aea70b93a52194a0964220d10d92ee7497346f146a8b6ef8ab","price_changes":[{"asset_id":"2151378744569768920256500242561922410292857798164019061749528550808091180185","best_ask":"0.83","best_bid":"0.82","hash":"0061db087ae2a3d66e2c36f806d957366d72b146","price":"0.13","side":"BUY","size":"28"},{"asset_id":"17406866367975599232214757606801140480252276357934486651183783311435802862074","best_ask":"0.18","best_bid":"0.17","hash":"97095eafe14c793cfdd86b2e7795285b8affa8fb","price":"0.87","side":"SELL","size":"28"}],"timestamp":"1786845516115"}}
{"f":334,"recv_ms":1786845516330,"raw":{"event_type":"price_change","market":"0xd5f15f31689703aea70b93a52194a0964220d10d92ee7497346f146a8b6ef8ab","price_changes":[{"asset_id":"2151378744569768920256500242561922410292857798164019061749528550808091180185","best_ask":"0.83","best_bid":"0.82","hash":"45f4479664afe3ebd36d525c5d5fa514817155e9","price":"0.1","side":"BUY","size":"83.9"},{"asset_id":"17406866367975599232214757606801140480252276357934486651183783311435802862074","best_ask":"0.18","best_bid":"0.17","hash":"7d23786c76429cb5940847b0260c88464dfd8ef9","price":"0.9","side":"SELL","size":"83.9"}],"timestamp":"1786845516115"}}
{"f":335,"recv_ms":1786845516330,"raw":{"event_type":"price_change","market":"0xd5f15f31689703aea70b93a52194a0964220d10d92ee7497346f146a8b6ef8ab","price_changes":[{"asset_id":"2151378744569768920256500242561922410292857798164019061749528550808091180185","best_ask":"0.83","best_bid":"0.82","hash":"70e7485f0fd936be2c3eb92c1df4cfb9c3a8ce21","price":"0.22","side":"BUY","size":"25.2"},{"asset_id":"17406866367975599232214757606801140480252276357934486651183783311435802862074","best_ask":"0.18","best_bid":"0.17","hash":"35d3fe5b8d6ddc4182236b0fb40d64d2feb7bcc4","price":"0.78","side":"SELL","size":"25.2"}],"timestamp":"1786845516117"}}
{"f":336,"recv_ms":1786845516333,"raw":{"event_type":"price_change","market":"0xd5f15f31689703aea70b93a52194a0964220d10d92ee7497346f146a8b6ef8ab","price_changes":[{"asset_id":"2151378744569768920256500242561922410292857798164019061749528550808091180185","best_ask":"0.83","best_bid":"0.82","hash":"be3adb2b9fb752c55c0d88918190191aa8231104","price":"0.11","side":"BUY","size":"41.6"},{"asset_id":"17406866367975599232214757606801140480252276357934486651183783311435802862074","best_ask":"0.18","best_bid":"0.17","hash":"c02b44e747074f88af903d51982b82c42d15706a","price":"0.89","side":"SELL","size":"41.6"}],"timestamp":"1786845516118"}}
{"f":337,"recv_ms":1786845516333,"raw":{"event_type":"price_change","market":"0xd5f15f31689703aea70b93a52194a0964220d10d92ee7497346f146a8b6ef8ab","price_changes":[{"asset_id":"2151378744569768920256500242561922410292857798164019061749528550808091180185","best_ask":"0.83","best_bid":"0.82","hash":"4e412d61c185d954c8731a28a1ffd74435ac775a","price":"0.17","side":"BUY","size":"23.39"},{"asset_id":"17406866367975599232214757606801140480252276357934486651183783311435802862074","best_ask":"0.18","best_bid":"0.17","hash":"fd5d33fdb688d049393ea824b303bcb441d79e61","price":"0.83","side":"SELL","size":"23.39"}],"timestamp":"1786845516118"}}
{"f":338,"recv_ms":1786845516338,"raw":{"event_type":"price_change","market":"0xd5f15f31689703aea70b93a52194a0964220d10d92ee7497346f146a8b6ef8ab","price_changes":[{"asset_id":"17406866367975599232214757606801140480252276357934486651183783311435802862074","best_ask":"0.18","best_bid":"0.17","hash":"2616e6c7bb864a80573b2378c62ec2824e948f36","price":"0.01","side":"BUY","size":"5593.18"},{"asset_id":"2151378744569768920256500242561922410292857798164019061749528550808091180185","best_ask":"0.83","best_bid":"0.82","hash":"763462957ff617cf3c682123136f7506fc2450d7","price":"0.99","side":"SELL","size":"5593.18"}],"timestamp":"1786845516121"}}
{"f":339,"recv_ms":1786845516338,"raw":{"event_type":"price_change","market":"0xd5f15f31689703aea70b93a52194a0964220d10d92ee7497346f146a8b6ef8ab","price_changes":[{"asset_id":"2151378744569768920256500242561922410292857798164019061749528550808091180185","best_ask":"0.83","best_bid":"0.82","hash":"ea7a8236307617deee7d7dab02f12c190470abc0","price":"0.17","side":"BUY","size":"18.39"},{"asset_id":"17406866367975599232214757606801140480252276357934486651183783311435802862074","best_ask":"0.18","best_bid":"0.17","hash":"8e54a719b8af287c32d9b96ff53267ae815c4bb6","price":"0.83","side":"SELL","size":"18.39"}],"timestamp":"1786845516123"}}
{"f":340,"recv_ms":1786845516347,"raw":{"event_type":"price_change","market":"0xd5f15f31689703aea70b93a52194a0964220d10d92ee7497346f146a8b6ef8ab","price_changes":[{"asset_id":"2151378744569768920256500242561922410292857798164019061749528550808091180185","best_ask":"0.83","best_bid":"0.82","hash":"0b83e2533c315598169a9998d0e706c4ab5a2c1f","price":"0.01","side":"BUY","size":"5783.58"},{"asset_id":"17406866367975599232214757606801140480252276357934486651183783311435802862074","best_ask":"0.18","best_bid":"0.17","hash":"e78fd1761c32329f26706ffe91c2b5c2426f2521","price":"0.99","side":"SELL","size":"5783.58"}],"timestamp":"1786845516126"}}
{"f":341,"recv_ms":1786845516347,"raw":{"event_type":"price_change","market":"0xd5f15f31689703aea70b93a52194a0964220d10d92ee7497346f146a8b6ef8ab","price_changes":[{"asset_id":"2151378744569768920256500242561922410292857798164019061749528550808091180185","best_ask":"0.83","best_bid":"0.82","hash":"f070341f5aef993250169ae84b544c07c01ecb1c","price":"0.01","side":"BUY","size":"5683.58"},{"asset_id":"17406866367975599232214757606801140480252276357934486651183783311435802862074","best_ask":"0.18","best_bid":"0.17","hash":"d751833913fdb393333865350294ad97a535560b","price":"0.99","side":"SELL","size":"5683.58"}],"timestamp":"1786845516130"}}
{"f":342,"recv_ms":1786845516355,"raw":{"event_type":"price_change","market":"0xd5f15f31689703aea70b93a52194a0964220d10d92ee7497346f146a8b6ef8ab","price_changes":[{"asset_id":"2151378744569768920256500242561922410292857798164019061749528550808091180185","best_ask":"0.83","best_bid":"0.82","hash":"86017148b48bfa0d8722f912305c24b351fc107c","price":"0.01","side":"BUY","size":"5677.58"},{"asset_id":"17406866367975599232214757606801140480252276357934486651183783311435802862074","best_ask":"0.18","best_bid":"0.17","hash":"068f329f44f940eece3ad22517bc3c54d3be6bfb","price":"0.99","side":"SELL","size":"5677.58"}],"timestamp":"1786845516144"}}
{"f":343,"recv_ms":1786845516366,"raw":{"event_type":"price_change","market":"0xd5f15f31689703aea70b93a52194a0964220d10d92ee7497346f146a8b6ef8ab","price_changes":[{"asset_id":"17406866367975599232214757606801140480252276357934486651183783311435802862074","best_ask":"0.18","best_bid":"0.17","hash":"05bc12a5856ac02c84568893d9c5f24fe52972b0","price":"0.01","side":"BUY","size":"5588.18"},{"asset_id":"2151378744569768920256500242561922410292857798164019061749528550808091180185","best_ask":"0.83","best_bid":"0.82","hash":"4bd60a9289b52ce34a90487e39b15a4c94f6b551","price":"0.99","side":"SELL","size":"5588.18"}],"timestamp":"1786845516144"}}
{"f":344,"recv_ms":1786845516366,"raw":{"event_type":"price_change","market":"0xd5f15f31689703aea70b93a52194a0964220d10d92ee7497346f146a8b6ef8ab","price_changes":[{"asset_id":"2151378744569768920256500242561922410292857798164019061749528550808091180185","best_ask":"0.83","best_bid":"0.82","hash":"26275c0290eb8c72984fc5a07a99435082dfa429","price":"0.01","side":"BUY","size":"5672.58"},{"asset_id":"17406866367975599232214757606801140480252276357934486651183783311435802862074","best_ask":"0.18","best_bid":"0.17","hash":"ec5de8730970c6ff59cbf88858b7f233f1dd58b8","price":"0.99","side":"SELL","size":"5672.58"}],"timestamp":"1786845516145"}}
{"f":345,"recv_ms":1786845516376,"raw":{"event_type":"price_change","market":"0x0f808668c26a078e39fb08c32be2c04739e31f58d8d58dc81f3771760aa097da","price_changes":[{"asset_id":"109981215458957430670008039613114505679239971255550615765913446335529931163020","best_ask":"0.51","best_bid":"0.5","hash":"3937b97c601aaf56311dbb6c2db5a848a7496dd6","price":"0.13","side":"BUY","size":"33.2"},{"asset_id":"9052432239268584294914812202913499895678363531348080565599375753720096525063","best_ask":"0.5","best_bid":"0.49","hash":"85834514384a702a045ff2ba89cabf1f6be09ef4","price":"0.87","side":"SELL","size":"33.2"}],"timestamp":"1786845516154"}}
{"f":346,"recv_ms":1786845516376,"raw":{"event_type":"price_change","market":"0xd5f15f31689703aea70b93a52194a0964220d10d92ee7497346f146a8b6ef8ab","price_changes":[{"asset_id":"2151378744569768920256500242561922410292857798164019061749528550808091180185","best_ask":"0.83","best_bid":"0.82","hash":"c725ce228ebfe6a4ce7b1e5e8b44ae932b1dcf7b","price":"0.01","side":"BUY","size":"5677.59"},{"asset_id":"17406866367975599232214757606801140480252276357934486651183783311435802862074","best_ask":"0.18","best_bid":"0.17","hash":"9825bf47d9745ab61d8401311cd8e79d7f47bf41","price":"0.99","side":"SELL","size":"5677.59"}],"timestamp":"1786845516155"}}
{"f":347,"recv_ms":1786845516391,"raw":{"event_type":"price_change","market":"0xd5f15f31689703aea70b93a52194a0964220d10d92ee7497346f146a8b6ef8ab","price_changes":[{"asset_id":"2151378744569768920256500242561922410292857798164019061749528550808091180185","best_ask":"0.83","best_bid":"0.82","hash":"f64885d89ad30364305fa73ba98493f7d283a691","price":"0.01","side":"BUY","size":"5777.59"},{"asset_id":"17406866367975599232214757606801140480252276357934486651183783311435802862074","best_ask":"0.18","best_bid":"0.17","hash":"62cb3e57f4eec573ffaa344eed0bead9a64e5e49","price":"0.99","side":"SELL","size":"5777.59"}],"timestamp":"1786845516177"}}
{"f":348,"recv_ms":1786845516394,"raw":{"event_type":"price_change","market":"0xd5f15f31689703aea70b93a52194a0964220d10d92ee7497346f146a8b6ef8ab","price_changes":[{"asset_id":"2151378744569768920256500242561922410292857798164019061749528550808091180185","best_ask":"0.83","best_bid":"0.82","hash":"9690697318d33434eb946256202d6477b43ff759","price":"0.01","side":"BUY","size":"5772.59"},{"asset_id":"17406866367975599232214757606801140480252276357934486651183783311435802862074","best_ask":"0.18","best_bid":"0.17","hash":"475c4b27f211df8e27f079f2dc71fe05466eb3c4","price":"0.99","side":"SELL","size":"5772.59"}],"timestamp":"1786845516180"}}
{"f":349,"recv_ms":1786845516404,"raw":{"event_type":"price_change","market":"0xd5f15f31689703aea70b93a52194a0964220d10d92ee7497346f146a8b6ef8ab","price_changes":[{"asset_id":"2151378744569768920256500242561922410292857798164019061749528550808091180185","best_ask":"0.83","best_bid":"0.82","hash":"5310daba51e414bbf2df994ccce32fcaaffd45e2","price":"0.01","side":"BUY","size":"5767.58"},{"asset_id":"17406866367975599232214757606801140480252276357934486651183783311435802862074","best_ask":"0.18","best_bid":"0.17","hash":"5b0120b9d5fabd43ab2443a16d9f899ccbc3b32c","price":"0.99","side":"SELL","size":"5767.58"}],"timestamp":"1786845516183"}}
{"f":350,"recv_ms":1786845516404,"raw":{"event_type":"price_change","market":"0xd5f15f31689703aea70b93a52194a0964220d10d92ee7497346f146a8b6ef8ab","price_changes":[{"asset_id":"17406866367975599232214757606801140480252276357934486651183783311435802862074","best_ask":"0.18","best_bid":"0.17","hash":"fbfaf54523ab7201655f3af62123661cd839671c","price":"0.17","side":"BUY","size":"130.83"},{"asset_id":"2151378744569768920256500242561922410292857798164019061749528550808091180185","best_ask":"0.83","best_bid":"0.82","hash":"144121687f7b6948d628b8a58b6322fe46e4a101","price":"0.83","side":"SELL","size":"130.83"}],"timestamp":"1786845516184"}}
{"f":351,"recv_ms":1786845516404,"raw":{"event_type":"price_change","market":"0xd5f15f31689703aea70b93a52194a0964220d10d92ee7497346f146a8b6ef8ab","price_changes":[{"asset_id":"2151378744569768920256500242561922410292857798164019061749528550808091180185","best_ask":"0.83","best_bid":"0.82","hash":"5a1d43373b9b43f324ec5c0756f787bbee9bdd6b","price":"0.5","side":"BUY","size":"655.4"},{"asset_id":"17406866367975599232214757606801140480252276357934486651183783311435802862074","best_ask":"0.18","best_bid":"0.17","hash":"81fae77f5266ff3004302adae60255ccb7abef11","price":"0.5","side":"SELL","size":"655.4"}],"timestamp":"1786845516190"}}
{"f":352,"recv_ms":1786845516426,"raw":{"event_type":"price_change","market":"0xd5f15f31689703aea70b93a52194a0964220d10d92ee7497346f146a8b6ef8ab","price_changes":[{"asset_id":"17406866367975599232214757606801140480252276357934486651183783311435802862074","best_ask":"0.18","best_bid":"0.17","hash":"da400e96b0c260db3decbbfe7cbda0b58a244d9b","price":"0.17","side":"BUY","size":"128.04"},{"asset_id":"2151378744569768920256500242561922410292857798164019061749528550808091180185","best_ask":"0.83","best_bid":"0.82","hash":"07af3a68eb4f9d19c633965801e852117b46f485","price":"0.83","side":"SELL","size":"128.04"}],"timestamp":"1786845516194"}}
{"f":353,"recv_ms":1786845516429,"raw":{"event_type":"price_change","market":"0xd5f15f31689703aea70b93a52194a0964220d10d92ee7497346f146a8b6ef8ab","price_changes":[{"asset_id":"2151378744569768920256500242561922410292857798164019061749528550808091180185","best_ask":"0.83","best_bid":"0.82","hash":"19123aa17cbb238c22b1140c6fb9b249f8757f10","price":"0.01","side":"BUY","size":"5667.58"},{"asset_id":"17406866367975599232214757606801140480252276357934486651183783311435802862074","best_ask":"0.18","best_bid":"0.17","hash":"89c86c5f03a501b950db271e20f14118a0c11755","price":"0.99","side":"SELL","size":"5667.58"}],"timestamp":"1786845516215"}}
{"f":354,"recv_ms":1786845516430,"raw":{"event_type":"price_change","market":"0xd5f15f31689703aea70b93a52194a0964220d10d92ee7497346f146a8b6ef8ab","price_changes":[{"asset_id":"2151378744569768920256500242561922410292857798164019061749528550808091180185","best_ask":"0.83","best_bid":"0.82","hash":"01c1f4b883c144bb558e742257ba90dc0259e181","price":"0.01","side":"BUY","size":"5672.58"},{"asset_id":"17406866367975599232214757606801140480252276357934486651183783311435802862074","best_ask":"0.18","best_bid":"0.17","hash":"541963bf7b2379b9e60944545f8853bef8a42d6c","price":"0.99","side":"SELL","size":"5672.58"}],"timestamp":"1786845516216"}}
{"f":355,"recv_ms":1786845516436,"raw":{"event_type":"price_change","market":"0xd5f15f31689703aea70b93a52194a0964220d10d92ee7497346f146a8b6ef8ab","price_changes":[{"asset_id":"2151378744569768920256500242561922410292857798164019061749528550808091180185","best_ask":"0.83","best_bid":"0.82","hash":"fdcb7dcfbd1db3fcb52d32ee2c65f5b747e7994b","price":"0.01","side":"BUY","size":"5678.58"},{"asset_id":"17406866367975599232214757606801140480252276357934486651183783311435802862074","best_ask":"0.18","best_bid":"0.17","hash":"8a45cacbe0c88e9cd93c3c071a7b82236876c9e9","price":"0.99","side":"SELL","size":"5678.58"}],"timestamp":"1786845516219"}}
{"f":356,"recv_ms":1786845516436,"raw":{"event_type":"price_change","market":"0xd5f15f31689703aea70b93a52194a0964220d10d92ee7497346f146a8b6ef8ab","price_changes":[{"asset_id":"2151378744569768920256500242561922410292857798164019061749528550808091180185","best_ask":"0.83","best_bid":"0.82","hash":"960180eb02ae618f37e3d66da1ed154f383cff87","price":"0.01","side":"BUY","size":"5673.58"},{"asset_id":"17406866367975599232214757606801140480252276357934486651183783311435802862074","best_ask":"0.18","best_bid":"0.17","hash":"e2624b96b25ed19846128025e16c871b870707d7","price":"0.99","side":"SELL","size":"5673.58"}],"timestamp":"1786845516219"}}
{"f":357,"recv_ms":1786845516449,"raw":{"event_type":"price_change","market":"0xd5f15f31689703aea70b93a52194a0964220d10d92ee7497346f146a8b6ef8ab","price_changes":[{"asset_id":"2151378744569768920256500242561922410292857798164019061749528550808091180185","best_ask":"0.83","best_bid":"0.82","hash":"809147efa758afe87f7798a15310d69c0aa251b8","price":"0.01","side":"BUY","size":"5668.58"},{"asset_id":"17406866367975599232214757606801140480252276357934486651183783311435802862074","best_ask":"0.18","best_bid":"0.17","hash":"d2736f726e41517a2d94b460fda2946ff1cec7bd","price":"0.99","side":"SELL","size":"5668.58"}],"timestamp":"1786845516233"}}
{"f":358,"recv_ms":1786845516455,"raw":{"event_type":"price_change","market":"0xd5f15f31689703aea70b93a52194a0964220d10d92ee7497346f146a8b6ef8ab","price_changes":[{"asset_id":"2151378744569768920256500242561922410292857798164019061749528550808091180185","best_ask":"0.83","best_bid":"0.82","hash":"38c234df118305613c373f586f02950022d39962","price":"0.82","side":"BUY","size":"25"},{"asset_id":"17406866367975599232214757606801140480252276357934486651183783311435802862074","best_ask":"0.18","best_bid":"0.17","hash":"c1edf10dd41caeca291ec1671cf9a3c635ef5b9c","price":"0.18","side":"SELL","size":"25"}],"timestamp":"1786845516237"}}
{"f":359,"recv_ms":1786845516455,"raw":{"event_type":"price_change","market":"0xd5f15f31689703aea70b93a52194a0964220d10d92ee7497346f146a8b6ef8ab","price_changes":[{"asset_id":"2151378744569768920256500242561922410292857798164019061749528550808091180185","best_ask":"0.83","best_bid":"0.82","hash":"52a2743992c20254b63a5402f1af5101a02e9a81","price":"0.01","side":"BUY","size":"5673.58"},{"asset_id":"17406866367975599232214757606801140480252276357934486651183783311435802862074","best_ask":"0.18","best_bid":"0.17","hash":"5a9dad47d59ac50fedd01f28841dccc8e7ff32e5","price":"0.99","side":"SELL","size":"5673.58"}],"timestamp":"1786845516241"}}
{"f":360,"recv_ms":1786845516466,"raw":{"event_type":"price_change","market":"0xd5f15f31689703aea70b93a52194a0964220d10d92ee7497346f146a8b6ef8ab","price_changes":[{"asset_id":"2151378744569768920256500242561922410292857798164019061749528550808091180185","best_ask":"0.83","best_bid":"0.82","hash":"ac7527219ca26278bfb05b40aa1a6c922be2d1c0","price":"0.01","side":"BUY","size":"5667.58"},{"asset_id":"17406866367975599232214757606801140480252276357934486651183783311435802862074","best_ask":"0.18","best_bid":"0.17","hash":"35dea7fbf32e6853beb9ae3c7ee3e909f2547eb5","price":"0.99","side":"SELL","size":"5667.58"}],"timestamp":"1786845516243"}}
{"f":361,"recv_ms":1786845516481,"raw":{"event_type":"price_change","market":"0xd5f15f31689703aea70b93a52194a0964220d10d92ee7497346f146a8b6ef8ab","price_changes":[{"asset_id":"2151378744569768920256500242561922410292857798164019061749528550808091180185","best_ask":"0.83","best_bid":"0.82","hash":"34089df8501c7e79b0840c1001b83c12db18f7f2","price":"0.01","side":"BUY","size":"5767.58"},{"asset_id":"17406866367975599232214757606801140480252276357934486651183783311435802862074","best_ask":"0.18","best_bid":"0.17","hash":"511ad06e90e58954bf6c3e98cdfb2764287fce1d","price":"0.99","side":"SELL","size":"5767.58"}],"timestamp":"1786845516256"}}
{"f":362,"recv_ms":1786845516492,"raw":{"event_type":"price_change","market":"0xd5f15f31689703aea70b93a52194a0964220d10d92ee7497346f146a8b6ef8ab","price_changes":[{"asset_id":"2151378744569768920256500242561922410292857798164019061749528550808091180185","best_ask":"0.83","best_bid":"0.82","hash":"b2ce196cb07abcbde1cf2773f525485ce74a1684","price":"0.83","side":"SELL","size":"111.92"},{"asset_id":"17406866367975599232214757606801140480252276357934486651183783311435802862074","best_ask":"0.18","best_bid":"0.17","hash":"ed234763bc882ebae04b79ad2c80184a496fb099","price":"0.17","side":"BUY","size":"111.92"}],"timestamp":"1786845516270"}}
{"f":363,"recv_ms":1786845516492,"raw":{"event_type":"price_change","market":"0xd5f15f31689703aea70b93a52194a0964220d10d92ee7497346f146a8b6ef8ab","price_changes":[{"asset_id":"17406866367975599232214757606801140480252276357934486651183783311435802862074","best_ask":"0.18","best_bid":"0.17","hash":"ed234763bc882ebae04b79ad2c80184a496fb099","price":"0.17","side":"BUY","size":"111.92"},{"asset_id":"2151378744569768920256500242561922410292857798164019061749528550808091180185","best_ask":"0.83","best_bid":"0.82","hash":"b2ce196cb07abcbde1cf2773f525485ce74a1684","price":"0.83","side":"SELL","size":"111.92"}],"timestamp":"1786845516270"}}
{"f":364,"recv_ms":1786845516492,"raw":{"event_type":"price_change","market":"0xd5f15f31689703aea70b93a52194a0964220d10d92ee7497346f146a8b6ef8ab","price_changes":[{"asset_id":"17406866367975599232214757606801140480252276357934486651183783311435802862074","best_ask":"0.18","best_bid":"0.17","hash":"fa8d65b575486d9f8edf53db7c7428cbd532b5d4","price":"0.17","side":"BUY","size":"90.06"},{"asset_id":"2151378744569768920256500242561922410292857798164019061749528550808091180185","best_ask":"0.83","best_bid":"0.82","hash":"fc7021af45d1be107e38e0c7e3fa1eb4a111edb5","price":"0.83","side":"SELL","size":"90.06"}],"timestamp":"1786845516280"}}
{"f":365,"recv_ms":1786845516497,"raw":{"event_type":"price_change","market":"0xd5f15f31689703aea70b93a52194a0964220d10d92ee7497346f146a8b6ef8ab","price_changes":[{"asset_id":"2151378744569768920256500242561922410292857798164019061749528550808091180185","best_ask":"0.83","best_bid":"0.82","hash":"fff2d6f51b588dded2eb71f00453607ad4899a65","price":"0.01","side":"BUY","size":"5772.58"},{"asset_id":"17406866367975599232214757606801140480252276357934486651183783311435802862074","best_ask":"0.18","best_bid":"0.17","hash":"93cdc3d6bc0c7ad3b9d03337356dfeecddba0ae1","price":"0.99","side":"SELL","size":"5772.58"}],"timestamp":"1786845516284"}}
{"f":366,"recv_ms":1786845516499,"raw":{"event_type":"price_change","market":"0xd5f15f31689703aea70b93a52194a0964220d10d92ee7497346f146a8b6ef8ab","price_changes":[{"asset_id":"2151378744569768920256500242561922410292857798164019061749528550808091180185","best_ask":"0.83","best_bid":"0.82","hash":"6dcb2b3c2053f6b217b39f4d17007b1b652737bf","price":"0.01","side":"BUY","size":"5777.58"},{"asset_id":"17406866367975599232214757606801140480252276357934486651183783311435802862074","best_ask":"0.18","best_bid":"0.17","hash":"8dfc81803bac1ac1c6329b178de4a832fee80911","price":"0.99","side":"SELL","size":"5777.58"}],"timestamp":"1786845516285"}}
{"f":367,"recv_ms":1786845516499,"raw":{"event_type":"price_change","market":"0xd5f15f31689703aea70b93a52194a0964220d10d92ee7497346f146a8b6ef8ab","price_changes":[{"asset_id":"2151378744569768920256500242561922410292857798164019061749528550808091180185","best_ask":"0.83","best_bid":"0.82","hash":"e06d51fa4a23dcbb34528a78811dfd180f62916e","price":"0.75","side":"BUY","size":"201.9"},{"asset_id":"17406866367975599232214757606801140480252276357934486651183783311435802862074","best_ask":"0.18","best_bid":"0.17","hash":"2a3a4994c5b77cf96bcfc91bbaa8f0c7acee4161","price":"0.25","side":"SELL","size":"201.9"}],"timestamp":"1786845516286"}}
{"f":368,"recv_ms":1786845516502,"raw":{"event_type":"price_change","market":"0xd5f15f31689703aea70b93a52194a0964220d10d92ee7497346f146a8b6ef8ab","price_changes":[{"asset_id":"2151378744569768920256500242561922410292857798164019061749528550808091180185","best_ask":"0.83","best_bid":"0.82","hash":"8804b224f7db4219e8a0700fd1b8fbc4529c6392","price":"0.01","side":"BUY","size":"5782.58"},{"asset_id":"17406866367975599232214757606801140480252276357934486651183783311435802862074","best_ask":"0.18","best_bid":"0.17","hash":"c2e6c09d83b0fa7818c91da4ed0f0a3f19cba73e","price":"0.99","side":"SELL","size":"5782.58"}],"timestamp":"1786845516287"}}
{"f":369,"recv_ms":1786845516502,"raw":{"event_type":"price_change","market":"0xd5f15f31689703aea70b93a52194a0964220d10d92ee7497346f146a8b6ef8ab","price_changes":[{"asset_id":"2151378744569768920256500242561922410292857798164019061749528550808091180185","best_ask":"0.83","best_bid":"0.82","hash":"4e5d0f8a01b1a5c043cfa9f4899c0029329d3c21","price":"0.75","side":"BUY","size":"101.9"},{"asset_id":"17406866367975599232214757606801140480252276357934486651183783311435802862074","best_ask":"0.18","best_bid":"0.17","hash":"c83c21e6c5625f8d2ad6f88fc338d5a9957c137b","price":"0.25","side":"SELL","size":"101.9"}],"timestamp":"1786845516290"}}
{"f":370,"recv_ms":1786845516506,"raw":{"event_type":"price_change","market":"0xd5f15f31689703aea70b93a52194a0964220d10d92ee7497346f146a8b6ef8ab","price_changes":[{"asset_id":"17406866367975599232214757606801140480252276357934486651183783311435802862074","best_ask":"0.18","best_bid":"0.17","hash":"3984ac6bddcd0d305732c457efb03bc3650d2013","price":"0.1","side":"BUY","size":"66"},{"asset_id":"2151378744569768920256500242561922410292857798164019061749528550808091180185","best_ask":"0.83","best_bid":"0.82","hash":"e34ded32ca2f29c415c3dd1cba44445da5b8279c","price":"0.9","side":"SELL","size":"66"}],"timestamp":"1786845516291"}}
{"f":371,"recv_ms":1786845516506,"raw":{"event_type":"price_change","market":"0xd5f15f31689703aea70b93a52194a0964220d10d92ee7497346f146a8b6ef8ab","price_changes":[{"asset_id":"2151378744569768920256500242561922410292857798164019061749528550808091180185","best_ask":"0.83","best_bid":"0.82","hash":"c0704ec52fd3dbdf67e6fcec3147f10754e8c446","price":"0.01","side":"BUY","size":"5682.58"},{"asset_id":"17406866367975599232214757606801140480252276357934486651183783311435802862074","best_ask":"0.18","best_bid":"0.17","hash":"a5e7d890751cbc283285ad81ac3e5de275e3f047","price":"0.99","side":"SELL","size":"5682.58"}],"timestamp":"1786845516293"}}
{"f":372,"recv_ms":1786845516516,"raw":{"event_type":"price_change","market":"0xd5f15f31689703aea70b93a52194a0964220d10d92ee7497346f146a8b6ef8ab","price_changes":[{"asset_id":"17406866367975599232214757606801140480252276357934486651183783311435802862074","best_ask":"0.18","best_bid":"0.17","hash":"5cbf37950f5b53859f3817dfc81e7885afa4a52e","price":"0.08","side":"BUY","size":"70.29"},{"asset_id":"2151378744569768920256500242561922410292857798164019061749528550808091180185","best_ask":"0.83","best_bid":"0.82","hash":"dc2ddb9b01e2f496ba25808657f5e52114d99874","price":"0.92","side":"SELL","size":"70.29"}],"timestamp":"1786845516295"}}
{"f":373,"recv_ms":1786845516516,"raw":{"event_type":"price_change","market":"0xd5f15f31689703aea70b93a52194a0964220d10d92ee7497346f146a8b6ef8ab","price_changes":[{"asset_id":"2151378744569768920256500242561922410292857798164019061749528550808091180185","best_ask":"0.83","best_bid":"0.82","hash":"7017d19ccca7201703a4dd978ad853b52ce907fa","price":"0.73","side":"BUY","size":"25"},{"asset_id":"17406866367975599232214757606801140480252276357934486651183783311435802862074","best_ask":"0.18","best_bid":"0.17","hash":"f8da468399678c369947b804a36109c688e9a77c","price":"0.27","side":"SELL","size":"25"}],"timestamp":"1786845516304"}}
{"f":374,"recv_ms":1786845516523,"raw":{"event_type":"price_change","market":"0xd5f15f31689703aea70b93a52194a0964220d10d92ee7497346f146a8b6ef8ab","price_changes":[{"asset_id":"17406866367975599232214757606801140480252276357934486651183783311435802862074","best_ask":"0.18","best_bid":"0.17","hash":"0554294fd94fef5404a95842adb60d83f6b6c2cd","price":"0.27","side":"SELL","size":"12"},{"asset_id":"2151378744569768920256500242561922410292857798164019061749528550808091180185","best_ask":"0.83","best_bid":"0.82","hash":"e4af4cdd7d326045dd01a6fce5d1e8295e9547d8","price":"0.73","side":"BUY","size":"12"}],"timestamp":"1786845516305"}}
{"f":375,"recv_ms":1786845516523,"raw":{"event_type":"price_change","market":"0xd5f15f31689703aea70b93a52194a0964220d10d92ee7497346f146a8b6ef8ab","price_changes":[{"asset_id":"2151378744569768920256500242561922410292857798164019061749528550808091180185","best_ask":"0.83","best_bid":"0.82","hash":"3604e3c9cdab1d5e5b88696175ba82e7eff01500","price":"0.01","side":"BUY","size":"5677.53"},{"asset_id":"17406866367975599232214757606801140480252276357934486651183783311435802862074","best_ask":"0.18","best_bid":"0.17","hash":"66d2e4c72f89c4dee8610de1357b9357847e09c8","price":"0.99","side":"SELL","size":"5677.53"}],"timestamp":"1786845516309"}}
{"f":376,"recv_ms":1786845516527,"raw":{"event_type":"price_change","market":"0xd5f15f31689703aea70b93a52194a0964220d10d92ee7497346f146a8b6ef8ab","price_changes":[{"asset_id":"2151378744569768920256500242561922410292857798164019061749528550808091180185","best_ask":"0.83","best_bid":"0.82","hash":"d8b084841884b386ed21edbf05a7150146701cf9","price":"0.01","side":"BUY","size":"5683.53"},{"asset_id":"17406866367975599232214757606801140480252276357934486651183783311435802862074","best_ask":"0.18","best_bid":"0.17","hash":"e520b41860aa7fbcf91b12672315704d643c8c73","price":"0.99","side":"SELL","size":"5683.53"}],"timestamp":"1786845516311"}}
{"f":377,"recv_ms":1786845516527,"raw":{"event_type":"price_change","market":"0xd5f15f31689703aea70b93a52194a0964220d10d92ee7497346f146a8b6ef8ab","price_changes":[{"asset_id":"2151378744569768920256500242561922410292857798164019061749528550808091180185","best_ask":"0.83","best_bid":"0.82","hash":"fbfe6f1cd2d4cf3e7ec8bd10ebf0d081c37664c2","price":"0.82","side":"BUY","size":"64.22"},{"asset_id":"17406866367975599232214757606801140480252276357934486651183783311435802862074","best_ask":"0.18","best_bid":"0.17","hash":"d441f9551fce95b348ee1a75ee07ea362f1c55d2","price":"0.18","side":"SELL","size":"64.22"}],"timestamp":"1786845516316"}}
{"f":378,"recv_ms":1786845516535,"raw":{"event_type":"price_change","market":"0xd5f15f31689703aea70b93a52194a0964220d10d92ee7497346f146a8b6ef8ab","price_changes":[{"asset_id":"2151378744569768920256500242561922410292857798164019061749528550808091180185","best_ask":"0.83","best_bid":"0.82","hash":"0748f4a5656b05a8fa7d09f86f5343d970fe599e","price":"0.01","side":"BUY","size":"5678.53"},{"asset_id":"17406866367975599232214757606801140480252276357934486651183783311435802862074","best_ask":"0.18","best_bid":"0.17","hash":"37dbf160c87722f585fa62f24faa129d8d3234c9","price":"0.99","side":"SELL","size":"5678.53"}],"timestamp":"1786845516321"}}
{"f":379,"recv_ms":1786845516541,"raw":{"event_type":"price_change","market":"0xd5f15f31689703aea70b93a52194a0964220d10d92ee7497346f146a8b6ef8ab","price_changes":[{"asset_id":"17406866367975599232214757606801140480252276357934486651183783311435802862074","best_ask":"0.18","best_bid":"0.17","hash":"f772f58bd1c70ef49223d1395d5c31aae714d572","price":"0.17","side":"BUY","size":"35.29"},{"asset_id":"2151378744569768920256500242561922410292857798164019061749528550808091180185","best_ask":"0.83","best_bid":"0.82","hash":"238a7e4708787243f28636745543c0e5e7bd06de","price":"0.83","side":"SELL","size":"35.29"}],"timestamp":"1786845516324"}}
{"f":380,"recv_ms":1786845516541,"raw":{"event_type":"price_change","market":"0xd5f15f31689703aea70b93a52194a0964220d10d92ee7497346f146a8b6ef8ab","price_changes":[{"asset_id":"2151378744569768920256500242561922410292857798164019061749528550808091180185","best_ask":"0.83","best_bid":"0.82","hash":"04ae5d87f97eece906cac6d0a591bfa778b8fc57","price":"0.74","side":"BUY","size":"13"},{"asset_id":"17406866367975599232214757606801140480252276357934486651183783311435802862074","best_ask":"0.18","best_bid":"0.17","hash":"b988412fde8a136176ebab5671248feb3cdc5bf3","price":"0.26","side":"SELL","size":"13"}],"timestamp":"1786845516325"}}
{"f":381,"recv_ms":1786845516547,"raw":{"event_type":"price_change","market":"0xd5f15f31689703aea70b93a52194a0964220d10d92ee7497346f146a8b6ef8ab","price_changes":[{"asset_id":"17406866367975599232214757606801140480252276357934486651183783311435802862074","best_ask":"0.18","best_bid":"0.17","hash":"8ac0a6a5ca755dc31bfb544efa37ed9114abffd8","price":"0.26","side":"SELL","size":"26"},{"asset_id":"2151378744569768920256500242561922410292857798164019061749528550808091180185","best_ask":"0.83","best_bid":"0.82","hash":"a08fab8c26bbbcaf298aa11bae341fca94793f74","price":"0.74","side":"BUY","size":"26"}],"timestamp":"1786845516329"}}
{"f":382,"recv_ms":1786845516547,"raw":{"event_type":"price_change","market":"0xd5f15f31689703aea70b93a52194a0964220d10d92ee7497346f146a8b6ef8ab","price_changes":[{"asset_id":"17406866367975599232214757606801140480252276357934486651183783311435802862074","best_ask":"0.18","best_bid":"0.17","hash":"3599975497ffb07e2159954bbe5c15acda081d38","price":"0.01","side":"BUY","size":"5688.18"},{"asset_id":"2151378744569768920256500242561922410292857798164019061749528550808091180185","best_ask":"0.83","best_bid":"0.82","hash":"94826c143bc6facaceb74f5a4aaa9d1ecbf722a1","price":"0.99","side":"SELL","size":"5688.18"}],"timestamp":"1786845516330"}}
{"f":383,"recv_ms":1786845516554,"raw":{"event_type":"price_change","market":"0xd5f15f31689703aea70b93a52194a0964220d10d92ee7497346f146a8b6ef8ab","price_changes":[{"asset_id":"2151378744569768920256500242561922410292857798164019061749528550808091180185","best_ask":"0.83","best_bid":"0.82","hash":"21091a4b547513a9b32861604f81961184c97c59","price":"0.01","side":"BUY","size":"5778.53"},{"asset_id":"17406866367975599232214757606801140480252276357934486651183783311435802862074","best_ask":"0.18","best_bid":"0.17","hash":"ea46736abfa33ac9196f02d9eca4effb966758c9","price":"0.99","side":"SELL","size":"5778.53"}],"timestamp":"1786845516335"}}
{"f":384,"recv_ms":1786845516554,"raw":{"event_type":"price_change","market":"0xd5f15f31689703aea70b93a52194a0964220d10d92ee7497346f146a8b6ef8ab","price_changes":[{"asset_id":"17406866367975599232214757606801140480252276357934486651183783311435802862074","best_ask":"0.18","best_bid":"0.17","hash":"e466ab6d5c435551ea88406c8f8daa2df4a50743","price":"0.17","side":"BUY","size":"25.29"},{"asset_id":"2151378744569768920256500242561922410292857798164019061749528550808091180185","best_ask":"0.83","best_bid":"0.82","hash":"5cb51d0d0c96993e0a83069a764e6bc6bc091481","price":"0.83","side":"SELL","size":"25.29"}],"timestamp":"1786845516336"}}
{"f":385,"recv_ms":1786845516555,"raw":{"event_type":"price_change","market":"0xd5f15f31689703aea70b93a52194a0964220d10d92ee7497346f146a8b6ef8ab","price_changes":[{"asset_id":"2151378744569768920256500242561922410292857798164019061749528550808091180185","best_ask":"0.83","best_bid":"0.82","hash":"2176391fc0da9ac458e97bba8013bad2a2acec51","price":"0.01","side":"BUY","size":"5772.53"},{"asset_id":"17406866367975599232214757606801140480252276357934486651183783311435802862074","best_ask":"0.18","best_bid":"0.17","hash":"9a74901d31dd4049761ce6abc07cb0049482bc9b","price":"0.99","side":"SELL","size":"5772.53"}],"timestamp":"1786845516342"}}
{"f":386,"recv_ms":1786845516555,"raw":{"event_type":"price_change","market":"0xd5f15f31689703aea70b93a52194a0964220d10d92ee7497346f146a8b6ef8ab","price_changes":[{"asset_id":"17406866367975599232214757606801140480252276357934486651183783311435802862074","best_ask":"0.18","best_bid":"0.17","hash":"4add7523cb85f3b60311f9de63a1f07ed6ee0969","price":"0.17","side":"BUY","size":"15.29"},{"asset_id":"2151378744569768920256500242561922410292857798164019061749528550808091180185","best_ask":"0.83","best_bid":"0.82","hash":"5359292712451c872c157d06d79870a7bb5657c4","price":"0.83","side":"SELL","size":"15.29"}],"timestamp":"1786845516342"}}
{"f":387,"recv_ms":1786845516562,"raw":{"event_type":"price_change","market":"0xd5f15f31689703aea70b93a52194a0964220d10d92ee7497346f146a8b6ef8ab","price_changes":[{"asset_id":"2151378744569768920256500242561922410292857798164019061749528550808091180185","best_ask":"0.83","best_bid":"0.82","hash":"3fe9e366dccab19e070b7be0947e35ace146d1c4","price":"0.82","side":"BUY","size":"74.22"},{"asset_id":"17406866367975599232214757606801140480252276357934486651183783311435802862074","best_ask":"0.18","best_bid":"0.17","hash":"177500c3b7cd70fb408d67d779ab9acc7a5d3ba4","price":"0.18","side":"SELL","size":"74.22"}],"timestamp":"1786845516347"}}
{"f":388,"recv_ms":1786845516563,"raw":{"event_type":"price_change","market":"0xd5f15f31689703aea70b93a52194a0964220d10d92ee7497346f146a8b6ef8ab","price_changes":[{"asset_id":"17406866367975599232214757606801140480252276357934486651183783311435802862074","best_ask":"0.18","best_bid":"0.17","hash":"6f8f90bab46b99a74afbc2643e64fd0398632d0e","price":"0.17","side":"BUY","size":"25.29"},{"asset_id":"2151378744569768920256500242561922410292857798164019061749528550808091180185","best_ask":"0.83","best_bid":"0.82","hash":"50d9aa3d92e9c5d35cb86da791b5e00872adf922","price":"0.83","side":"SELL","size":"25.29"}],"timestamp":"1786845516350"}}
{"f":389,"recv_ms":1786845516563,"raw":{"event_type":"price_change","market":"0xd5f15f31689703aea70b93a52194a0964220d10d92ee7497346f146a8b6ef8ab","price_changes":[{"asset_id":"2151378744569768920256500242561922410292857798164019061749528550808091180185","best_ask":"0.83","best_bid":"0.82","hash":"296cdfb395ff46461978fb396adb46a290696243","price":"0.01","side":"BUY","size":"5767.53"},{"asset_id":"17406866367975599232214757606801140480252276357934486651183783311435802862074","best_ask":"0.18","best_bid":"0.17","hash":"9aac7e3f8e02bb22c94a4e15e9cdd383cf771d2a","price":"0.99","side":"SELL","size":"5767.53"}],"timestamp":"1786845516350"}}
{"f":390,"recv_ms":1786845516566,"raw":{"event_type":"price_change","market":"0xd5f15f31689703aea70b93a52194a0964220d10d92ee7497346f146a8b6ef8ab","price_changes":[{"asset_id":"2151378744569768920256500242561922410292857798164019061749528550808091180185","best_ask":"0.83","best_bid":"0.82","hash":"273fdbb137c9f640a8040688701d7dc1faf97fab","price":"0.01","side":"BUY","size":"5772.54"},{"asset_id":"17406866367975599232214757606801140480252276357934486651183783311435802862074","best_ask":"0.18","best_bid":"0.17","hash":"8d81950b44d2ee9469dc88b8f7dbbac48dda464c","price":"0.99","side":"SELL","size":"5772.54"}],"timestamp":"1786845516352"}}
{"f":391,"recv_ms":1786845516566,"raw":{"event_type":"price_change","market":"0xd5f15f31689703aea70b93a52194a0964220d10d92ee7497346f146a8b6ef8ab","price_changes":[{"asset_id":"17406866367975599232214757606801140480252276357934486651183783311435802862074","best_ask":"0.18","best_bid":"0.17","hash":"b80690066d737e9ac2d1af36e47ff2d023f46e3e","price":"0.17","side":"BUY","size":"15.29"},{"asset_id":"2151378744569768920256500242561922410292857798164019061749528550808091180185","best_ask":"0.83","best_bid":"0.82","hash":"9f8b34b1b6fb02dfe636f10d830c80f9b6671363","price":"0.83","side":"SELL","size":"15.29"}],"timestamp":"1786845516352"}}
{"f":392,"recv_ms":1786845516572,"raw":{"event_type":"price_change","market":"0xd5f15f31689703aea70b93a52194a0964220d10d92ee7497346f146a8b6ef8ab","price_changes":[{"asset_id":"2151378744569768920256500242561922410292857798164019061749528550808091180185","best_ask":"0.83","best_bid":"0.82","hash":"e51b6e667f1be437440dfa37917cc985a4b0795f","price":"0.82","side":"BUY","size":"82.28"},{"asset_id":"17406866367975599232214757606801140480252276357934486651183783311435802862074","best_ask":"0.18","best_bid":"0.17","hash":"3a88b0baa07f61afb6b4cdf41eab1b5d4dd719fe","price":"0.18","side":"SELL","size":"82.28"}],"timestamp":"1786845516353"}}
{"f":393,"recv_ms":1786845516572,"raw":{"event_type":"price_change","market":"0xd5f15f31689703aea70b93a52194a0964220d10d92ee7497346f146a8b6ef8ab","price_changes":[{"asset_id":"17406866367975599232214757606801140480252276357934486651183783311435802862074","best_ask":"0.18","best_bid":"0.17","hash":"6a21d8dce4e9d39b48a38743fbd44c96bc2ba310","price":"0.2","side":"SELL","size":"95.42"},{"asset_id":"2151378744569768920256500242561922410292857798164019061749528550808091180185","best_ask":"0.83","best_bid":"0.82","hash":"a45a416aad88344fa51b4f362be3fb47bf5cf59e","price":"0.8","side":"BUY","size":"95.42"}],"timestamp":"1786845516354"}}
{"f":394,"recv_ms":1786845516572,"raw":{"event_type":"price_change","market":"0xd5f15f31689703aea70b93a52194a0964220d10d92ee7497346f146a8b6ef8ab","price_changes":[{"asset_id":"2151378744569768920256500242561922410292857798164019061749528550808091180185","best_ask":"0.83","best_bid":"0.82","hash":"b961446590c74cd24ee9daf62ab715b158d4ec41","price":"0.82","side":"BUY","size":"90.44"},{"asset_id":"17406866367975599232214757606801140480252276357934486651183783311435802862074","best_ask":"0.18","best_bid":"0.17","hash":"c9b6f22a2eacdb6d4c32b107376398285396ef73","price":"0.18","side":"SELL","size":"90.44"}],"timestamp":"1786845516358"}}
{"f":395,"recv_ms":1786845516585,"raw":{"event_type":"price_change","market":"0xd5f15f31689703aea70b93a52194a0964220d10d92ee7497346f146a8b6ef8ab","price_changes":[{"asset_id":"2151378744569768920256500242561922410292857798164019061749528550808091180185","best_ask":"0.83","best_bid":"0.82","hash":"fb734474e901ef63471fb0454882d356076c6dd5","price":"0.82","side":"BUY","size":"98.9"},{"asset_id":"17406866367975599232214757606801140480252276357934486651183783311435802862074","best_ask":"0.18","best_bid":"0.17","hash":"b925b1aefac3a8a3f43755a1adf95c32fcc66de1","price":"0.18","side":"SELL","size":"98.9"}],"timestamp":"1786845516359"}}
{"f":396,"recv_ms":1786845516585,"raw":{"event_type":"price_change","market":"0xd5f15f31689703aea70b93a52194a0964220d10d92ee7497346f146a8b6ef8ab","price_changes":[{"asset_id":"17406866367975599232214757606801140480252276357934486651183783311435802862074","best_ask":"0.18","best_bid":"0.17","hash":"822671c524e74380e79d2e80d234b34b07291d8e","price":"0.18","side":"SELL","size":"107.36"},{"asset_id":"2151378744569768920256500242561922410292857798164019061749528550808091180185","best_ask":"0.83","best_bid":"0.82","hash":"6045ab357a25cd6e9ebe17a98ba6a8d251832a5a","price":"0.82","side":"BUY","size":"107.36"}],"timestamp":"1786845516359"}}
{"f":397,"recv_ms":1786845516585,"raw":{"event_type":"price_change","market":"0xd5f15f31689703aea70b93a52194a0964220d10d92ee7497346f146a8b6ef8ab","price_changes":[{"asset_id":"2151378744569768920256500242561922410292857798164019061749528550808091180185","best_ask":"0.83","best_bid":"0.82","hash":"0605af423cf0e3e3ffe9bbe2012ba88dededec80","price":"0.82","side":"BUY","size":"115.32"},{"asset_id":"17406866367975599232214757606801140480252276357934486651183783311435802862074","best_ask":"0.18","best_bid":"0.17","hash":"bd77aeb008206ca6fb0c2596f0a8c9f55b839f73","price":"0.18","side":"SELL","size":"115.32"}],"timestamp":"1786845516363"}}
{"f":398,"recv_ms":1786845516596,"raw":{"event_type":"price_change","market":"0xd5f15f31689703aea70b93a52194a0964220d10d92ee7497346f146a8b6ef8ab","price_changes":[{"asset_id":"2151378744569768920256500242561922410292857798164019061749528550808091180185","best_ask":"0.83","best_bid":"0.82","hash":"24dbb1e481190a7fdb5797c11cde2677e3ca908a","price":"0.01","side":"BUY","size":"5672.54"},{"asset_id":"17406866367975599232214757606801140480252276357934486651183783311435802862074","best_ask":"0.18","best_bid":"0.17","hash":"c6ea553c9ad56e76dccf99ed340230791faeff3e","price":"0.99","side":"SELL","size":"5672.54"}],"timestamp":"1786845516375"}}
{"f":399,"recv_ms":1786845516598,"raw":{"event_type":"price_change","market":"0xd5f15f31689703aea70b93a52194a0964220d10d92ee7497346f146a8b6ef8ab","price_changes":[{"asset_id":"2151378744569768920256500242561922410292857798164019061749528550808091180185","best_ask":"0.83","best_bid":"0.82","hash":"a52a13e9bfffad9a703f85e78063ea9b626344a1","price":"0.8","side":"BUY","size":"103.32"},{"asset_id":"17406866367975599232214757606801140480252276357934486651183783311435802862074","best_ask":"0.18","best_bid":"0.17","hash":"726de357ebb415c59329703034282ce2ab9d6763","price":"0.2","side":"SELL","size":"103.32"}],"timestamp":"1786845516384"}}
{"f":400,"recv_ms":1786845516598,"raw":{"event_type":"price_change","market":"0xd5f15f31689703aea70b93a52194a0964220d10d92ee7497346f146a8b6ef8ab","price_changes":[{"asset_id":"17406866367975599232214757606801140480252276357934486651183783311435802862074","best_ask":"0.18","best_bid":"0.17","hash":"52156f2dbe0cb4c539b5a1a4863523fe13584615","price":"0.05","side":"BUY","size":"754.7"},{"asset_id":"2151378744569768920256500242561922410292857798164019061749528550808091180185","best_ask":"0.83","best_bid":"0.82","hash":"701a3c07173722ad5bb8156121ba293ab4d8e56f","price":"0.95","side":"SELL","size":"754.7"}],"timestamp":"1786845516385"}}
{"f":401,"recv_ms":1786845516601,"raw":{"event_type":"price_change","market":"0xd5f15f31689703aea70b93a52194a0964220d10d92ee7497346f146a8b6ef8ab","price_changes":[{"asset_id":"17406866367975599232214757606801140480252276357934486651183783311435802862074","best_ask":"0.18","best_bid":"0.17","hash":"a05817d5c1e9fc066279e66769cdea9cff201af5","price":"0.09","side":"BUY","size":"71.7"},{"asset_id":"2151378744569768920256500242561922410292857798164019061749528550808091180185","best_ask":"0.83","best_bid":"0.82","hash":"bb3688dedf12189eb54fbba3e25ef5a7fcaefefb","price":"0.91","side":"SELL","size":"71.7"}],"timestamp":"1786845516386"}}
{"f":402,"recv_ms":1786845516601,"raw":{"event_type":"price_change","market":"0xd5f15f31689703aea70b93a52194a0964220d10d92ee7497346f146a8b6ef8ab","price_changes":[{"asset_id":"17406866367975599232214757606801140480252276357934486651183783311435802862074","best_ask":"0.18","best_bid":"0.17","hash":"e68a0e5232828c6b75e6728d999518e6e64e7f49","price":"0.03","side":"BUY","size":"606.3"},{"asset_id":"2151378744569768920256500242561922410292857798164019061749528550808091180185","best_ask":"0.83","best_bid":"0.82","hash":"4a3fa7d94a93738200bbe500ba1649fd7c996146","price":"0.97","side":"SELL","size":"606.3"}],"timestamp":"1786845516387"}}
{"f":403,"recv_ms":1786845516603,"raw":{"event_type":"price_change","market":"0xd5f15f31689703aea70b93a52194a0964220d10d92ee7497346f146a8b6ef8ab","price_changes":[{"asset_id":"2151378744569768920256500242561922410292857798164019061749528550808091180185","best_ask":"0.83","best_bid":"0.82","hash":"5368353743d672f4ead0acfe100d57b8d8540c71","price":"0.01","side":"BUY","size":"5667.54"},{"asset_id":"17406866367975599232214757606801140480252276357934486651183783311435802862074","best_ask":"0.18","best_bid":"0.17","hash":"20ba170acc1fcf82964cf4b5f8b8489e52b243a5","price":"0.99","side":"SELL","size":"5667.54"}],"timestamp":"1786845516387"}}
{"f":404,"recv_ms":1786845516603,"raw":{"event_type":"price_change","market":"0xd5f15f31689703aea70b93a52194a0964220d10d92ee7497346f146a8b6ef8ab","price_changes":[{"asset_id":"2151378744569768920256500242561922410292857798164019061749528550808091180185","best_ask":"0.83","best_bid":"0.82","hash":"c0b5ea1dc4edfa7e562311547671cfe85a8ba670","price":"0.01","side":"BUY","size":"5662.53"},{"asset_id":"17406866367975599232214757606801140480252276357934486651183783311435802862074","best_ask":"0.18","best_bid":"0.17","hash":"eaa06dc5cdc8ce9b51e0b067af2d3f42812005ca","price":"0.99","side":"SELL","size":"5662.53"}],"timestamp":"1786845516387"}}
{"f":405,"recv_ms":1786845516603,"raw":{"event_type":"price_change","market":"0xd5f15f31689703aea70b93a52194a0964220d10d92ee7497346f146a8b6ef8ab","price_changes":[{"asset_id":"17406866367975599232214757606801140480252276357934486651183783311435802862074","best_ask":"0.18","best_bid":"0.17","hash":"a349db320e58fcfba01c9c9c04c7578122711175","price":"0.07","side":"BUY","size":"459.86"},{"asset_id":"2151378744569768920256500242561922410292857798164019061749528550808091180185","best_ask":"0.83","best_bid":"0.82","hash":"9681cd41d9990442f4c8ea424dd045a11186a125","price":"0.93","side":"SELL","size":"459.86"}],"timestamp":"1786845516388"}}
{"f":406,"recv_ms":1786845516603,"raw":{"event_type":"price_change","market":"0xd5f15f31689703aea70b93a52194a0964220d10d92ee7497346f146a8b6ef8ab","price_changes":[{"asset_id":"17406866367975599232214757606801140480252276357934486651183783311435802862074","best_ask":"0.18","best_bid":"0.17","hash":"85f023647d62b135773fd9b5fc1f505a30389754","price":"0.01","side":"BUY","size":"5683.18"},{"asset_id":"2151378744569768920256500242561922410292857798164019061749528550808091180185","best_ask":"0.83","best_bid":"0.82","hash":"dce53023ef65d050c57bd1bb0f04d7c573554951","price":"0.99","side":"SELL","size":"5683.18"}],"timestamp":"1786845516388"}}
{"f":407,"recv_ms":1786845516603,"raw":{"event_type":"price_change","market":"0xd5f15f31689703aea70b93a52194a0964220d10d92ee7497346f146a8b6ef8ab","price_changes":[{"asset_id":"17406866367975599232214757606801140480252276357934486651183783311435802862074","best_ask":"0.18","best_bid":"0.17","hash":"8ac68c52f4a960e396380fbf9e48b498d87a44f0","price":"0.17","side":"BUY","size":"14.08"},{"asset_id":"2151378744569768920256500242561922410292857798164019061749528550808091180185","best_ask":"0.83","best_bid":"0.82","hash":"541a13418ade0a55781e46f4c9daeb03ade9fe67","price":"0.83","side":"SELL","size":"14.08"}],"timestamp":"1786845516388"}}
{"f":408,"recv_ms":1786845516614,"raw":{"event_type":"price_change","market":"0xd5f15f31689703aea70b93a52194a0964220d10d92ee7497346f146a8b6ef8ab","price_changes":[{"asset_id":"2151378744569768920256500242561922410292857798164019061749528550808091180185","best_ask":"0.83","best_bid":"0.82","hash":"49b1dcf8443560b254189f742752e90baee448d6","price":"0.82","side":"BUY","size":"125.32"},{"asset_id":"17406866367975599232214757606801140480252276357934486651183783311435802862074","best_ask":"0.18","best_bid":"0.17","hash":"96e2638a1b32ff34dbe28b9e284718fbedf3f0f0","price":"0.18","side":"SELL","size":"125.32"}],"timestamp":"1786845516392"}}
{"f":409,"recv_ms":1786845516614,"raw":{"event_type":"price_change","market":"0xd5f15f31689703aea70b93a52194a0964220d10d92ee7497346f146a8b6ef8ab","price_changes":[{"asset_id":"17406866367975599232214757606801140480252276357934486651183783311435802862074","best_ask":"0.18","best_bid":"0.17","hash":"b01b45b9df70366682605fe0c2c61f0b7f5ed518","price":"0.15","side":"BUY","size":"5"},{"asset_id":"2151378744569768920256500242561922410292857798164019061749528550808091180185","best_ask":"0.83","best_bid":"0.82","hash":"7234a3266d9188f8c49e877127a97f062a7bcc42","price":"0.85","side":"SELL","size":"5"}],"timestamp":"1786845516393"}}
{"f":410,"recv_ms":1786845516621,"raw":{"event_type":"price_change","market":"0xd5f15f31689703aea70b93a52194a0964220d10d92ee7497346f146a8b6ef8ab","price_changes":[{"asset_id":"17406866367975599232214757606801140480252276357934486651183783311435802862074","best_ask":"0.18","best_bid":"0.17","hash":"51e131695b3d3ae9360d466865edbfb350050256","price":"0.05","side":"BUY","size":"554.7"},{"asset_id":"2151378744569768920256500242561922410292857798164019061749528550808091180185","best_ask":"0.83","best_bid":"0.82","hash":"594128e30ead27c36d1787ec556526b72b7aab7e","price":"0.95","side":"SELL","size":"554.7"}],"timestamp":"1786845516403"}}
{"f":411,"recv_ms":1786845516621,"raw":{"event_type":"price_change","market":"0xd5f15f31689703aea70b93a52194a0964220d10d92ee7497346f146a8b6ef8ab","price_changes":[{"asset_id":"17406866367975599232214757606801140480252276357934486651183783311435802862074","best_ask":"0.18","best_bid":"0.17","hash":"7335ada720161de76a06529bb062b2478cc07d06","price":"0.46","side":"SELL","size":"49"},{"asset_id":"2151378744569768920256500242561922410292857798164019061749528550808091180185","best_ask":"0.83","best_bid":"0.82","hash":"a42bf744ee939fdab88b743388550a4bc8b393d0","price":"0.54","side":"BUY","size":"49"}],"timestamp":"1786845516404"}}
{"f":412,"recv_ms":1786845516621,"raw":{"event_type":"price_change","market":"0xd5f15f31689703aea70b93a52194a0964220d10d92ee7497346f146a8b6ef8ab","price_changes":[{"asset_id":"17406866367975599232214757606801140480252276357934486651183783311435802862074","best_ask":"0.18","best_bid":"0.17","hash":"f493afde482db41b81966dbcf691f56189107d30","price":"0.06","side":"BUY","size":"383.1"},{"asset_id":"2151378744569768920256500242561922410292857798164019061749528550808091180185","best_ask":"0.83","best_bid":"0.82","hash":"15e4a26787e94703e03e2f245ea50813afbb337c","price":"0.94","side":"SELL","size":"383.1"}],"timestamp":"1786845516406"}}
{"f":413,"recv_ms":1786845516621,"raw":{"event_type":"price_change","market":"0xd5f15f31689703aea70b93a52194a0964220d10d92ee7497346f146a8b6ef8ab","price_changes":[{"asset_id":"17406866367975599232214757606801140480252276357934486651183783311435802862074","best_ask":"0.18","best_bid":"0.17","hash":"a1f3dbc57a419fdf74153f2e39decb25b4e8dd9f","price":"0.03","side":"BUY","size":"806.3"},{"asset_id":"2151378744569768920256500242561922410292857798164019061749528550808091180185","best_ask":"0.83","best_bid":"0.82","hash":"6a64a5965ee0c5592584d2ebc75323251b07f3e4","price":"0.97","side":"SELL","size":"806.3"}],"timestamp":"1786845516408"}}
{"f":414,"recv_ms":1786845516621,"raw":{"event_type":"price_change","market":"0xd5f15f31689703aea70b93a52194a0964220d10d92ee7497346f146a8b6ef8ab","price_changes":[{"asset_id":"2151378744569768920256500242561922410292857798164019061749528550808091180185","best_ask":"0.83","best_bid":"0.82","hash":"8a211f1d7cad5afcb5f5a0d01265f4070d8a247e","price":"0.67","side":"BUY","size":"20"},{"asset_id":"17406866367975599232214757606801140480252276357934486651183783311435802862074","best_ask":"0.18","best_bid":"0.17","hash":"a2d6aad4f6f1778631b00e8218f683a1a305542b","price":"0.33","side":"SELL","size":"20"}],"timestamp":"1786845516409"}}
{"f":415,"recv_ms":1786845516625,"raw":{"event_type":"price_change","market":"0xd5f15f31689703aea70b93a52194a0964220d10d92ee7497346f146a8b6ef8ab","price_changes":[{"asset_id":"2151378744569768920256500242561922410292857798164019061749528550808091180185","best_ask":"0.83","best_bid":"0.82","hash":"9e0873f5421398d31680dc35b57d2da5b8387353","price":"0.01","side":"BUY","size":"5668.53"},{"asset_id":"17406866367975599232214757606801140480252276357934486651183783311435802862074","best_ask":"0.18","best_bid":"0.17","hash":"b963aacdac79732bda2c2e8edc361b65e43d8a01","price":"0.99","side":"SELL","size":"5668.53"}],"timestamp":"1786845516410"}}
{"f":416,"recv_ms":1786845516625,"raw":{"event_type":"price_change","market":"0xd5f15f31689703aea70b93a52194a0964220d10d92ee7497346f146a8b6ef8ab","price_changes":[{"asset_id":"17406866367975599232214757606801140480252276357934486651183783311435802862074","best_ask":"0.18","best_bid":"0.17","hash":"ab9da2d7d1b8733d9c23f79f7a8aa3ed91c937b1","price":"0.01","side":"BUY","size":"5583.18"},{"asset_id":"2151378744569768920256500242561922410292857798164019061749528550808091180185","best_ask":"0.83","best_bid":"0.82","hash":"a433faaa97be4ef873579ed280579ba40e8dc999","price":"0.99","side":"SELL","size":"5583.18"}],"timestamp":"1786845516413"}}
{"f":417,"recv_ms":1786845516626,"raw":{"event_type":"price_change","market":"0xd5f15f31689703aea70b93a52194a0964220d10d92ee7497346f146a8b6ef8ab","price_changes":[{"asset_id":"2151378744569768920256500242561922410292857798164019061749528550808091180185","best_ask":"0.83","best_bid":"0.82","hash":"58aaaa3a892b60782a147f72556034cb39c67ca1","price":"0.01","side":"BUY","size":"5768.53"},{"asset_id":"17406866367975599232214757606801140480252276357934486651183783311435802862074","best_ask":"0.18","best_bid":"0.17","hash":"cd1f5d34d06b59cb223faf91cc367e0aff1150d2","price":"0.99","side":"SELL","size":"5768.53"}],"timestamp":"1786845516413"}}
{"f":418,"recv_ms":1786845516626,"raw":{"event_type":"price_change","market":"0xd5f15f31689703aea70b93a52194a0964220d10d92ee7497346f146a8b6ef8ab","price_changes":[{"asset_id":"2151378744569768920256500242561922410292857798164019061749528550808091180185","best_ask":"0.83","best_bid":"0.82","hash":"333d406134851c0ca4c7bd8a1ab023d80be52c1d","price":"0.82","side":"BUY","size":"135.32"},{"asset_id":"17406866367975599232214757606801140480252276357934486651183783311435802862074","best_ask":"0.18","best_bid":"0.17","hash":"0bf9be2f936d729d13832d268a0dad57c422e61b","price":"0.18","side":"SELL","size":"135.32"}],"timestamp":"1786845516414"}}
{"f":419,"recv_ms":1786845516629,"raw":{"event_type":"price_change","market":"0xd5f15f31689703aea70b93a52194a0964220d10d92ee7497346f146a8b6ef8ab","price_changes":[{"asset_id":"17406866367975599232214757606801140480252276357934486651183783311435802862074","best_ask":"0.18","best_bid":"0.17","hash":"ec87670977d4a1ee7afcb33eb5ca01680cd2c762","price":"0.32","side":"SELL","size":"115"},{"asset_id":"2151378744569768920256500242561922410292857798164019061749528550808091180185","best_ask":"0.83","best_bid":"0.82","hash":"846b2c80edb4ef0a576563dc04befce74152978c","price":"0.68","side":"BUY","size":"115"}],"timestamp":"1786845516415"}}
{"f":420,"recv_ms":1786845516629,"raw":{"event_type":"price_change","market":"0xd5f15f31689703aea70b93a52194a0964220d10d92ee7497346f146a8b6ef8ab","price_changes":[{"asset_id":"17406866367975599232214757606801140480252276357934486651183783311435802862074","best_ask":"0.18","best_bid":"0.17","hash":"f1ad63534a8a70ecbf48da6e49ad6341d6725d66","price":"0.04","side":"BUY","size":"767.7"},{"asset_id":"2151378744569768920256500242561922410292857798164019061749528550808091180185","best_ask":"0.83","best_bid":"0.82","hash":"fd88344cf57d226920b3fcea192b6271c98b74a1","price":"0.96","side":"SELL","size":"767.7"}],"timestamp":"1786845516417"}}
{"f":421,"recv_ms":1786845516632,"raw":{"event_type":"price_change","market":"0xd5f15f31689703aea70b93a52194a0964220d10d92ee7497346f146a8b6ef8ab","price_changes":[{"asset_id":"2151378744569768920256500242561922410292857798164019061749528550808091180185","best_ask":"0.83","best_bid":"0.82","hash":"ac3d2f762bda1321c9c13559670c8fd72298589f","price":"0.8","side":"BUY","size":"93.32"},{"asset_id":"17406866367975599232214757606801140480252276357934486651183783311435802862074","best_ask":"0.18","best_bid":"0.17","hash":"15dcc0bc582ac3c5e6ce36a1e4520797e44cf2ee","price":"0.2","side":"SELL","size":"93.32"}],"timestamp":"1786845516418"}}
{"f":422,"recv_ms":1786845516632,"raw":{"event_type":"price_change","market":"0xd5f15f31689703aea70b93a52194a0964220d10d92ee7497346f146a8b6ef8ab","price_changes":[{"asset_id":"17406866367975599232214757606801140480252276357934486651183783311435802862074","best_ask":"0.18","best_bid":"0.17","hash":"3097fd75546ee167986496464c34fb433cda05fa","price":"0.01","side":"BUY","size":"5578.18"},{"asset_id":"2151378744569768920256500242561922410292857798164019061749528550808091180185","best_ask":"0.83","best_bid":"0.82","hash":"899af2c0527567c06c8e2fe627b657cd013a1804","price":"0.99","side":"SELL","size":"5578.18"}],"timestamp":"1786845516420"}}
{"f":423,"recv_ms":1786845516639,"raw":{"event_type":"price_change","market":"0xd5f15f31689703aea70b93a52194a0964220d10d92ee7497346f146a8b6ef8ab","price_changes":[{"asset_id":"17406866367975599232214757606801140480252276357934486651183783311435802862074","best_ask":"0.18","best_bid":"0.17","hash":"6dec3014016161d6f1b86421516dbb1c6e772944","price":"0.01","side":"BUY","size":"5583.18"},{"asset_id":"2151378744569768920256500242561922410292857798164019061749528550808091180185","best_ask":"0.83","best_bid":"0.82","hash":"1b479c32e98e32d0919fc0678cfe655b2035db73","price":"0.99","side":"SELL","size":"5583.18"}],"timestamp":"1786845516421"}}
{"f":424,"recv_ms":1786845516640,"raw":{"event_type":"price_change","market":"0xd5f15f31689703aea70b93a52194a0964220d10d92ee7497346f146a8b6ef8ab","price_changes":[{"asset_id":"17406866367975599232214757606801140480252276357934486651183783311435802862074","best_ask":"0.18","best_bid":"0.17","hash":"2b986a7e80cdc8a9858fca05963ef1dd880b3093","price":"0.01","side":"BUY","size":"5578.18"},{"asset_id":"2151378744569768920256500242561922410292857798164019061749528550808091180185","best_ask":"0.83","best_bid":"0.82","hash":"fb9999a1a26df4d54cb89c6e5e049584e022b8d2","price":"0.99","side":"SELL","size":"5578.18"}],"timestamp":"1786845516427"}}
{"f":425,"recv_ms":1786845516644,"raw":{"event_type":"price_change","market":"0xd5f15f31689703aea70b93a52194a0964220d10d92ee7497346f146a8b6ef8ab","price_changes":[{"asset_id":"17406866367975599232214757606801140480252276357934486651183783311435802862074","best_ask":"0.18","best_bid":"0.17","hash":"3bef3560b36260c9fc2e903f8a823dca148decb1","price":"0.17","side":"BUY","size":"10.29"},{"asset_id":"2151378744569768920256500242561922410292857798164019061749528550808091180185","best_ask":"0.83","best_bid":"0.82","hash":"adcc715cd7d99bc4d90286f31c87cb69322dea7d","price":"0.83","side":"SELL","size":"10.29"}],"timestamp":"1786845516427"}}
{"f":426,"recv_ms":1786845516644,"raw":{"event_type":"price_change","market":"0xd5f15f31689703aea70b93a52194a0964220d10d92ee7497346f146a8b6ef8ab","price_changes":[{"asset_id":"2151378744569768920256500242561922410292857798164019061749528550808091180185","best_ask":"0.83","best_bid":"0.82","hash":"e084f966a577e6ba4321cac973e77fdbcfc32b9f","price":"0.55","side":"BUY","size":"119"},{"asset_id":"17406866367975599232214757606801140480252276357934486651183783311435802862074","best_ask":"0.18","best_bid":"0.17","hash":"0476b931f4d08e0ae542ab4831ac45cb793ab951","price":"0.45","side":"SELL","size":"119"}],"timestamp":"1786845516430"}}
{"f":427,"recv_ms":1786845516650,"raw":{"event_type":"price_change","market":"0xd5f15f31689703aea70b93a52194a0964220d10d92ee7497346f146a8b6ef8ab","price_changes":[{"asset_id":"17406866367975599232214757606801140480252276357934486651183783311435802862074","best_ask":"0.18","best_bid":"0.17","hash":"e8a24990b1acfa82175935fcc865772c35b347cb","price":"0.01","side":"BUY","size":"5583.18"},{"asset_id":"2151378744569768920256500242561922410292857798164019061749528550808091180185","best_ask":"0.83","best_bid":"0.82","hash":"ab51ab5176eb5285a520e73dbf9a12088965e0c6","price":"0.99","side":"SELL","size":"5583.18"}],"timestamp":"1786845516436"}}
{"f":428,"recv_ms":1786845516660,"raw":{"event_type":"price_change","market":"0xd5f15f31689703aea70b93a52194a0964220d10d92ee7497346f146a8b6ef8ab","price_changes":[{"asset_id":"17406866367975599232214757606801140480252276357934486651183783311435802862074","best_ask":"0.18","best_bid":"0.17","hash":"09082a2be9dfd73d1200d2492f4f7aadeaa1e830","price":"0.34","side":"SELL","size":"28"},{"asset_id":"2151378744569768920256500242561922410292857798164019061749528550808091180185","best_ask":"0.83","best_bid":"0.82","hash":"80eb6dd8861f21d365dc09a5cf6cc9b6068e900a","price":"0.66","side":"BUY","size":"28"}],"timestamp":"1786845516438"}}
{"f":429,"recv_ms":1786845516660,"raw":{"event_type":"price_change","market":"0xd5f15f31689703aea70b93a52194a0964220d10d92ee7497346f146a8b6ef8ab","price_changes":[{"asset_id":"2151378744569768920256500242561922410292857798164019061749528550808091180185","best_ask":"0.83","best_bid":"0.82","hash":"e9df43e9748add502d6d2e13c101107d2f5e1306","price":"0.01","side":"BUY","size":"5762.53"},{"asset_id":"17406866367975599232214757606801140480252276357934486651183783311435802862074","best_ask":"0.18","best_bid":"0.17","hash":"d4142d3248ba2112f4f3d7480fd7e0b35c443b7f","price":"0.99","side":"SELL","size":"5762.53"}],"timestamp":"1786845516440"}}
{"f":430,"recv_ms":1786845516671,"raw":{"event_type":"price_change","market":"0xd5f15f31689703aea70b93a52194a0964220d10d92ee7497346f146a8b6ef8ab","price_changes":[{"asset_id":"17406866367975599232214757606801140480252276357934486651183783311435802862074","best_ask":"0.18","best_bid":"0.17","hash":"2f2715c901940aa32a53cc891c91461e5b455f7e","price":"0.16","side":"BUY","size":"33.33"},{"asset_id":"2151378744569768920256500242561922410292857798164019061749528550808091180185","best_ask":"0.83","best_bid":"0.82","hash":"0e1c4f7b708c940feb339a2ce47a9ee50e91c911","price":"0.84","side":"SELL","size":"33.33"}],"timestamp":"1786845516448"}}
{"f":431,"recv_ms":1786845516671,"raw":{"asset_id":"2151378744569768920256500242561922410292857798164019061749528550808091180185","event_type":"last_trade_price","fee_rate_bps":"0","market":"0xd5f15f31689703aea70b93a52194a0964220d10d92ee7497346f146a8b6ef8ab","price":"0.83","side":"BUY","size":"21.86","timestamp":"1786845516449","transaction_hash":"0xa6f25374499ab85583a609de3021919b5ada0f883f8d835aa5f55c8ff2904441"}}
{"f":432,"recv_ms":1786845516671,"raw":{"event_type":"price_change","market":"0xd5f15f31689703aea70b93a52194a0964220d10d92ee7497346f146a8b6ef8ab","price_changes":[{"asset_id":"2151378744569768920256500242561922410292857798164019061749528550808091180185","best_ask":"0.83","best_bid":"0.82","hash":"d6835afef2d5b8877015a67d2b8764f8249c44de","price":"0.56","side":"BUY","size":"19"},{"asset_id":"17406866367975599232214757606801140480252276357934486651183783311435802862074","best_ask":"0.18","best_bid":"0.17","hash":"2f8c3d8d0cd16ceb4ef2683bc6c152dcadd4ade7","price":"0.44","side":"SELL","size":"19"}],"timestamp":"1786845516456"}}
{"f":433,"recv_ms":1786845516676,"raw":{"event_type":"price_change","market":"0xd5f15f31689703aea70b93a52194a0964220d10d92ee7497346f146a8b6ef8ab","price_changes":[{"asset_id":"2151378744569768920256500242561922410292857798164019061749528550808091180185","best_ask":"0.83","best_bid":"0.82","hash":"7ee33632bab8946faedc4f165a5fe53959444344","price":"0.65","side":"BUY","size":"28"},{"asset_id":"17406866367975599232214757606801140480252276357934486651183783311435802862074","best_ask":"0.18","best_bid":"0.17","hash":"f3bc19097b904119d1c783fe11b4f1cc9d7632cb","price":"0.35","side":"SELL","size":"28"}],"timestamp":"1786845516461"}}
{"f":434,"recv_ms":1786845516680,"raw":{"event_type":"price_change","market":"0xd5f15f31689703aea70b93a52194a0964220d10d92ee7497346f146a8b6ef8ab","price_changes":[{"asset_id":"2151378744569768920256500242561922410292857798164019061749528550808091180185","best_ask":"0.83","best_bid":"0.82","hash":"a53e74abc36fcb70ea5281f85496abf2fae264be","price":"0.01","side":"BUY","size":"5662.53"},{"asset_id":"17406866367975599232214757606801140480252276357934486651183783311435802862074","best_ask":"0.18","best_bid":"0.17","hash":"7675f29a051ba94d2a6a559371a9775bd3079702","price":"0.99","side":"SELL","size":"5662.53"}],"timestamp":"1786845516465"}}
{"f":435,"recv_ms":1786845516680,"raw":{"event_type":"price_change","market":"0xd5f15f31689703aea70b93a52194a0964220d10d92ee7497346f146a8b6ef8ab","price_changes":[{"asset_id":"17406866367975599232214757606801140480252276357934486651183783311435802862074","best_ask":"0.18","best_bid":"0.17","hash":"01591c4fa64cd2a8a3944c20c88242a2abd6a530","price":"0.17","side":"BUY","size":"9.07"},{"asset_id":"2151378744569768920256500242561922410292857798164019061749528550808091180185","best_ask":"0.83","best_bid":"0.82","hash":"c99c8fcc184ef76f3ddeb9b779def04d2ffbdefb","price":"0.83","side":"SELL","size":"9.07"}],"timestamp":"1786845516466"}}
{"f":436,"recv_ms":1786845516700,"raw":{"event_type":"price_change","market":"0xd5f15f31689703aea70b93a52194a0964220d10d92ee7497346f146a8b6ef8ab","price_changes":[{"asset_id":"2151378744569768920256500242561922410292857798164019061749528550808091180185","best_ask":"0.83","best_bid":"0.82","hash":"20052c4564d95537a085826124f1363faf5cc08d","price":"0.57","side":"BUY","size":"24"},{"asset_id":"17406866367975599232214757606801140480252276357934486651183783311435802862074","best_ask":"0.18","best_bid":"0.17","hash":"2f5106b600ad117f22eaf4e146994f91bdc784f4","price":"0.43","side":"SELL","size":"24"}],"timestamp":"1786845516480"}}
{"f":437,"recv_ms":1786845516701,"raw":{"event_type":"price_change","market":"0xd5f15f31689703aea70b93a52194a0964220d10d92ee7497346f146a8b6ef8ab","price_changes":[{"asset_id":"2151378744569768920256500242561922410292857798164019061749528550808091180185","best_ask":"0.83","best_bid":"0.82","hash":"a2475942af807b259e36a1e73419eb13503539d3","price":"0.64","side":"BUY","size":"262.13"},{"asset_id":"17406866367975599232214757606801140480252276357934486651183783311435802862074","best_ask":"0.18","best_bid":"0.17","hash":"483bd164c7e40cb0850fc253a1c295677da615de","price":"0.36","side":"SELL","size":"262.13"}],"timestamp":"1786845516487"}}
{"f":438,"recv_ms":1786845516701,"raw":{"event_type":"price_change","market":"0xd5f15f31689703aea70b93a52194a0964220d10d92ee7497346f146a8b6ef8ab","price_changes":[{"asset_id":"2151378744569768920256500242561922410292857798164019061749528550808091180185","best_ask":"0.83","best_bid":"0.82","hash":"7a7b2a25d37ce5ec02d45bb57b2d3d92f43fd1eb","price":"0.01","side":"BUY","size":"5667.53"},{"asset_id":"17406866367975599232214757606801140480252276357934486651183783311435802862074","best_ask":"0.18","best_bid":"0.17","hash":"9729d56a37687f78dca02d0587e1a563a7de871f","price":"0.99","side":"SELL","size":"5667.53"}],"timestamp":"1786845516488"}}
{"f":439,"recv_ms":1786845516701,"raw":{"event_type":"price_change","market":"0xd5f15f31689703aea70b93a52194a0964220d10d92ee7497346f146a8b6ef8ab","price_changes":[{"asset_id":"2151378744569768920256500242561922410292857798164019061749528550808091180185","best_ask":"0.83","best_bid":"0.82","hash":"0c528ca0390135cbda96e421b0703e6739e24874","price":"0.01","side":"BUY","size":"5672.53"},{"asset_id":"17406866367975599232214757606801140480252276357934486651183783311435802862074","best_ask":"0.18","best_bid":"0.17","hash":"e73b6eff27d7998bc0d452d6e67419dcd08a9f8a","price":"0.99","side":"SELL","size":"5672.53"}],"timestamp":"1786845516489"}}
{"f":440,"recv_ms":1786845516701,"raw":{"event_type":"price_change","market":"0xd5f15f31689703aea70b93a52194a0964220d10d92ee7497346f146a8b6ef8ab","price_changes":[{"asset_id":"2151378744569768920256500242561922410292857798164019061749528550808091180185","best_ask":"0.83","best_bid":"0.82","hash":"12b0d2657ffbc50f7988b9ed77c32a5ea464b641","price":"0.01","side":"BUY","size":"5677.53"},{"asset_id":"17406866367975599232214757606801140480252276357934486651183783311435802862074","best_ask":"0.18","best_bid":"0.17","hash":"0ff20acb552986acea06e123fbe017b572143a6c","price":"0.99","side":"SELL","size":"5677.53"}],"timestamp":"1786845516489"}}
{"f":441,"recv_ms":1786845516701,"raw":{"asset_id":"2151378744569768920256500242561922410292857798164019061749528550808091180185","event_type":"last_trade_price","fee_rate_bps":"0","market":"0xd5f15f31689703aea70b93a52194a0964220d10d92ee7497346f146a8b6ef8ab","price":"0.83","side":"BUY","size":"1.204817","timestamp":"1786845516468","transaction_hash":"0xa2e0aee928820a959936f5e1beebb8d5826c02229345f1db09bdc361aaca6519"}}
{"f":442,"recv_ms":1786845516723,"raw":{"event_type":"price_change","market":"0xd5f15f31689703aea70b93a52194a0964220d10d92ee7497346f146a8b6ef8ab","price_changes":[{"asset_id":"2151378744569768920256500242561922410292857798164019061749528550808091180185","best_ask":"0.83","best_bid":"0.82","hash":"7920adf9b045b1ffa85de39f9c7d56117aa9ccba","price":"0.01","side":"BUY","size":"5777.53"},{"asset_id":"17406866367975599232214757606801140480252276357934486651183783311435802862074","best_ask":"0.18","best_bid":"0.17","hash":"2429bf6506277605c9b6c98903c006c6ff639173","price":"0.99","side":"SELL","size":"5777.53"}],"timestamp":"1786845516497"}}
{"f":443,"recv_ms":1786845516729,"raw":{"event_type":"price_change","market":"0xd5f15f31689703aea70b93a52194a0964220d10d92ee7497346f146a8b6ef8ab","price_changes":[{"asset_id":"2151378744569768920256500242561922410292857798164019061749528550808091180185","best_ask":"0.83","best_bid":"0.82","hash":"3beaca44f66e97d9e0ec73bed2127d6c33014c43","price":"0.63","side":"BUY","size":"28"},{"asset_id":"17406866367975599232214757606801140480252276357934486651183783311435802862074","best_ask":"0.18","best_bid":"0.17","hash":"4b1bd5efdf3a90e8e0e2d5e81d8aac7dbc28b54e","price":"0.37","side":"SELL","size":"28"}],"timestamp":"1786845516512"}}
{"f":444,"recv_ms":1786845516729,"raw":{"event_type":"price_change","market":"0xd5f15f31689703aea70b93a52194a0964220d10d92ee7497346f146a8b6ef8ab","price_changes":[{"asset_id":"2151378744569768920256500242561922410292857798164019061749528550808091180185","best_ask":"0.83","best_bid":"0.82","hash":"c8d302e00ce1c3a234c289562545a900291fa3a6","price":"0.01","side":"BUY","size":"5782.53"},{"asset_id":"17406866367975599232214757606801140480252276357934486651183783311435802862074","best_ask":"0.18","best_bid":"0.17","hash":"39ac09d87de59343aa14c0c05fb0a1a6dad9fc9b","price":"0.99","side":"SELL","size":"5782.53"}],"timestamp":"1786845516516"}}
{"f":445,"recv_ms":1786845516744,"raw":{"event_type":"price_change","market":"0xd5f15f31689703aea70b93a52194a0964220d10d92ee7497346f146a8b6ef8ab","price_changes":[{"asset_id":"2151378744569768920256500242561922410292857798164019061749528550808091180185","best_ask":"0.83","best_bid":"0.82","hash":"956b174c7d0a085dd15c5502b53e1cbe19112d92","price":"0.01","side":"BUY","size":"5777.53"},{"asset_id":"17406866367975599232214757606801140480252276357934486651183783311435802862074","best_ask":"0.18","best_bid":"0.17","hash":"e45342f09215c7583d0399d70cbd3c77236b6d8f","price":"0.99","side":"SELL","size":"5777.53"}],"timestamp":"1786845516521"}}
{"f":446,"recv_ms":1786845516748,"raw":{"event_type":"price_change","market":"0xd5f15f31689703aea70b93a52194a0964220d10d92ee7497346f146a8b6ef8ab","price_changes":[{"asset_id":"2151378744569768920256500242561922410292857798164019061749528550808091180185","best_ask":"0.83","best_bid":"0.82","hash":"2987f2cef43b843cefcd7b62104731e2b531ee64","price":"0.82","side":"BUY","size":"130.32"},{"asset_id":"17406866367975599232214757606801140480252276357934486651183783311435802862074","best_ask":"0.18","best_bid":"0.17","hash":"7048c074fda9db861a1c53e57223dfdc6e4b2c18","price":"0.18","side":"SELL","size":"130.32"}],"timestamp":"1786845516533"}}
{"f":447,"recv_ms":1786845516748,"raw":{"event_type":"price_change","market":"0xd5f15f31689703aea70b93a52194a0964220d10d92ee7497346f146a8b6ef8ab","price_changes":[{"asset_id":"2151378744569768920256500242561922410292857798164019061749528550808091180185","best_ask":"0.83","best_bid":"0.82","hash":"84cdf4203ebf8ad15377f65bedf109bf6ddbe295","price":"0.01","side":"BUY","size":"5772.53"},{"asset_id":"17406866367975599232214757606801140480252276357934486651183783311435802862074","best_ask":"0.18","best_bid":"0.17","hash":"16adade3c9a594bf06136900e86c5ea1bc3acc9b","price":"0.99","side":"SELL","size":"5772.53"}],"timestamp":"1786845516535"}}
{"f":448,"recv_ms":1786845516758,"raw":{"event_type":"price_change","market":"0xd5f15f31689703aea70b93a52194a0964220d10d92ee7497346f146a8b6ef8ab","price_changes":[{"asset_id":"2151378744569768920256500242561922410292857798164019061749528550808091180185","best_ask":"0.83","best_bid":"0.82","hash":"4c9c4b63d10d0038ac42ac871cae0a45d8c68f31","price":"0.01","side":"BUY","size":"5672.53"},{"asset_id":"17406866367975599232214757606801140480252276357934486651183783311435802862074","best_ask":"0.18","best_bid":"0.17","hash":"de541015cc4fc5434d1e3a37384b83361629cb72","price":"0.99","side":"SELL","size":"5672.53"}],"timestamp":"1786845516537"}}
{"f":449,"recv_ms":1786845516758,"raw":{"event_type":"price_change","market":"0xd5f15f31689703aea70b93a52194a0964220d10d92ee7497346f146a8b6ef8ab","price_changes":[{"asset_id":"2151378744569768920256500242561922410292857798164019061749528550808091180185","best_ask":"0.83","best_bid":"0.82","hash":"a93d6f2b1dfaa6be5d7ade7f99626a440c34c4fd","price":"0.01","side":"BUY","size":"5678.53"},{"asset_id":"17406866367975599232214757606801140480252276357934486651183783311435802862074","best_ask":"0.18","best_bid":"0.17","hash":"3866c3071780c8b6d40ea5caf4254affafc25e95","price":"0.99","side":"SELL","size":"5678.53"}],"timestamp":"1786845516539"}}
{"f":450,"recv_ms":1786845516767,"raw":{"event_type":"price_change","market":"0xd5f15f31689703aea70b93a52194a0964220d10d92ee7497346f146a8b6ef8ab","price_changes":[{"asset_id":"2151378744569768920256500242561922410292857798164019061749528550808091180185","best_ask":"0.83","best_bid":"0.82","hash":"6bc809e18e90a5f7b4fa765a1a1181e72fa017ad","price":"0.01","side":"BUY","size":"5683.54"},{"asset_id":"17406866367975599232214757606801140480252276357934486651183783311435802862074","best_ask":"0.18","best_bid":"0.17","hash":"587d5a1dfa2ba2ebcd71683db89b6943e75ce933","price":"0.99","side":"SELL","size":"5683.54"}],"timestamp":"1786845516554"}}
{"f":451,"recv_ms":1786845516777,"raw":{"event_type":"price_change","market":"0xd5f15f31689703aea70b93a52194a0964220d10d92ee7497346f146a8b6ef8ab","price_changes":[{"asset_id":"2151378744569768920256500242561922410292857798164019061749528550808091180185","best_ask":"0.83","best_bid":"0.82","hash":"eed202c70e24ba9b66d79b7400ab61489b3d4d0c","price":"0.01","side":"BUY","size":"5678.54"},{"asset_id":"17406866367975599232214757606801140480252276357934486651183783311435802862074","best_ask":"0.18","best_bid":"0.17","hash":"0c90aa7cb68be763af09823af37d2a3cbd5b07e6","price":"0.99","side":"SELL","size":"5678.54"}],"timestamp":"1786845516554"}}
{"f":452,"recv_ms":1786845516777,"raw":{"event_type":"price_change","market":"0xd5f15f31689703aea70b93a52194a0964220d10d92ee7497346f146a8b6ef8ab","price_changes":[{"asset_id":"2151378744569768920256500242561922410292857798164019061749528550808091180185","best_ask":"0.83","best_bid":"0.82","hash":"31c0a7d54816ee496029fc3c402d92ce2be0eef4","price":"0.12","side":"BUY","size":"34.6"},{"asset_id":"17406866367975599232214757606801140480252276357934486651183783311435802862074","best_ask":"0.18","best_bid":"0.17","hash":"4c1d1c7163b30cd56900d3064c88e9ab0e27451f","price":"0.88","side":"SELL","size":"34.6"}],"timestamp":"1786845516563"}}
{"f":453,"recv_ms":1786845516777,"raw":{"event_type":"price_change","market":"0xd5f15f31689703aea70b93a52194a0964220d10d92ee7497346f146a8b6ef8ab","price_changes":[{"asset_id":"2151378744569768920256500242561922410292857798164019061749528550808091180185","best_ask":"0.83","best_bid":"0.82","hash":"d713f8cfee9385f4d63b2a53ffac6cee19456595","price":"0.18","side":"BUY","size":"22.6"},{"asset_id":"17406866367975599232214757606801140480252276357934486651183783311435802862074","best_ask":"0.18","best_bid":"0.17","hash":"a17e869bf6cfc1b0005705729f5548976fc8c323","price":"0.82","side":"SELL","size":"22.6"}],"timestamp":"1786845516564"}}
{"f":454,"recv_ms":1786845516785,"raw":{"event_type":"price_change","market":"0xd5f15f31689703aea70b93a52194a0964220d10d92ee7497346f146a8b6ef8ab","price_changes":[{"asset_id":"2151378744569768920256500242561922410292857798164019061749528550808091180185","best_ask":"0.83","best_bid":"0.82","hash":"e7b8fad9d6ccc32c2b099c08ee9c8d9adafbe9ce","price":"0.16","side":"BUY","size":"24.3"},{"asset_id":"17406866367975599232214757606801140480252276357934486651183783311435802862074","best_ask":"0.18","best_bid":"0.17","hash":"f42828ed91b465d66000201f24cae0d12f5a4e50","price":"0.84","side":"SELL","size":"24.3"}],"timestamp":"1786845516565"}}
{"f":455,"recv_ms":1786845516785,"raw":{"event_type":"price_change","market":"0xd5f15f31689703aea70b93a52194a0964220d10d92ee7497346f146a8b6ef8ab","price_changes":[{"asset_id":"2151378744569768920256500242561922410292857798164019061749528550808091180185","best_ask":"0.83","best_bid":"0.82","hash":"994995989d39e040fd41118f6f65d6d2519de009","price":"0.2","side":"BUY","size":"54.1"},{"asset_id":"17406866367975599232214757606801140480252276357934486651183783311435802862074","best_ask":"0.18","best_bid":"0.17","hash":"a77a32f6398ea3a885be9215f9931959f292e71d","price":"0.8","side":"SELL","size":"54.1"}],"timestamp":"1786845516565"}}
{"f":456,"recv_ms":1786845516785,"raw":{"event_type":"price_change","market":"0xd5f15f31689703aea70b93a52194a0964220d10d92ee7497346f146a8b6ef8ab","price_changes":[{"asset_id":"2151378744569768920256500242561922410292857798164019061749528550808091180185","best_ask":"0.83","best_bid":"0.82","hash":"3ace3c3056adb33d3a1a62a5a146155700544b5c","price":"0.14","side":"BUY","size":"26.6"},{"asset_id":"17406866367975599232214757606801140480252276357934486651183783311435802862074","best_ask":"0.18","best_bid":"0.17","hash":"bf9a052c5f80c31f90ba17a36b28a5731a98b45c","price":"0.86","side":"SELL","size":"26.6"}],"timestamp":"1786845516566"}}
{"f":457,"recv_ms":1786845516788,"raw":{"event_type":"price_change","market":"0xd5f15f31689703aea70b93a52194a0964220d10d92ee7497346f146a8b6ef8ab","price_changes":[{"asset_id":"2151378744569768920256500242561922410292857798164019061749528550808091180185","best_ask":"0.83","best_bid":"0.82","hash":"1f21054f553989d137e067015f61e7f79bae149f","price":"0.01","side":"BUY","size":"5778.54"},{"asset_id":"17406866367975599232214757606801140480252276357934486651183783311435802862074","best_ask":"0.18","best_bid":"0.17","hash":"0893e915d8961a75b38e7514831df91eb96f0c0d","price":"0.99","side":"SELL","size":"5778.54"}],"timestamp":"1786845516574"}}
{"f":458,"recv_ms":1786845516795,"raw":{"event_type":"price_change","market":"0xd5f15f31689703aea70b93a52194a0964220d10d92ee7497346f146a8b6ef8ab","price_changes":[{"asset_id":"2151378744569768920256500242561922410292857798164019061749528550808091180185","best_ask":"0.83","best_bid":"0.82","hash":"6c2d48a8ec5cb300716c58d447a44864b01c75d7","price":"0.82","side":"BUY","size":"137.32"},{"asset_id":"17406866367975599232214757606801140480252276357934486651183783311435802862074","best_ask":"0.18","best_bid":"0.17","hash":"e654248261bcbb215872dea46d28fa5988107f7a","price":"0.18","side":"SELL","size":"137.32"}],"timestamp":"1786845516576"}}
{"f":459,"recv_ms":1786845516816,"raw":{"event_type":"price_change","market":"0xd5f15f31689703aea70b93a52194a0964220d10d92ee7497346f146a8b6ef8ab","price_changes":[{"asset_id":"2151378744569768920256500242561922410292857798164019061749528550808091180185","best_ask":"0.83","best_bid":"0.82","hash":"dcca3e224d3a6e10f3155ad7eb2597e93c5e82ac","price":"0.01","side":"BUY","size":"5773.53"},{"asset_id":"17406866367975599232214757606801140480252276357934486651183783311435802862074","best_ask":"0.18","best_bid":"0.17","hash":"5b399d8c8f523f574da841c905606f10cd021c28","price":"0.99","side":"SELL","size":"5773.53"}],"timestamp":"1786845516583"}}
{"f":460,"recv_ms":1786845516816,"raw":{"event_type":"price_change","market":"0xd5f15f31689703aea70b93a52194a0964220d10d92ee7497346f146a8b6ef8ab","price_changes":[{"asset_id":"2151378744569768920256500242561922410292857798164019061749528550808091180185","best_ask":"0.83","best_bid":"0.82","hash":"9a9409d07cd879e434ecf3a5f28189a13e4e3160","price":"0.01","side":"BUY","size":"5768.53"},{"asset_id":"17406866367975599232214757606801140480252276357934486651183783311435802862074","best_ask":"0.18","best_bid":"0.17","hash":"db95469a904b7d5501ee43beac63891973609a53","price":"0.99","side":"SELL","size":"5768.53"}],"timestamp":"1786845516598"}}
{"f":461,"recv_ms":1786845516823,"raw":{"event_type":"price_change","market":"0xd5f15f31689703aea70b93a52194a0964220d10d92ee7497346f146a8b6ef8ab","price_changes":[{"asset_id":"2151378744569768920256500242561922410292857798164019061749528550808091180185","best_ask":"0.83","best_bid":"0.82","hash":"6e5082de69d5f25270df92ad8aac792a1612a146","price":"0.01","side":"BUY","size":"5668.53"},{"asset_id":"17406866367975599232214757606801140480252276357934486651183783311435802862074","best_ask":"0.18","best_bid":"0.17","hash":"24e2ff8f7728050541e802fbf54d98eeb5c9f97e","price":"0.99","side":"SELL","size":"5668.53"}],"timestamp":"1786845516608"}}
{"f":462,"recv_ms":1786845516833,"raw":{"event_type":"price_change","market":"0xd5f15f31689703aea70b93a52194a0964220d10d92ee7497346f146a8b6ef8ab","price_changes":[{"asset_id":"2151378744569768920256500242561922410292857798164019061749528550808091180185","best_ask":"0.83","best_bid":"0.82","hash":"0b7bac5dfb2cfb9cb0a280549d17e070acc444c2","price":"0.82","side":"BUY","size":"130.32"},{"asset_id":"17406866367975599232214757606801140480252276357934486651183783311435802862074","best_ask":"0.18","best_bid":"0.17","hash":"1abf45fd53d3dbaa5294b3ce693bafa7e5258fad","price":"0.18","side":"SELL","size":"130.32"}],"timestamp":"1786845516611"}}
{"f":463,"recv_ms":1786845516833,"raw":{"event_type":"price_change","market":"0xd5f15f31689703aea70b93a52194a0964220d10d92ee7497346f146a8b6ef8ab","price_changes":[{"asset_id":"2151378744569768920256500242561922410292857798164019061749528550808091180185","best_ask":"0.83","best_bid":"0.82","hash":"fc97e3b5baa9798514e1b1956ab9638d03c7cacb","price":"0.01","side":"BUY","size":"5663.53"},{"asset_id":"17406866367975599232214757606801140480252276357934486651183783311435802862074","best_ask":"0.18","best_bid":"0.17","hash":"334eec4b0edd74f63130a31a2d9a6cb316d9fdb3","price":"0.99","side":"SELL","size":"5663.53"}],"timestamp":"1786845516616"}}
{"f":464,"recv_ms":1786845516833,"raw":{"asset_id":"2151378744569768920256500242561922410292857798164019061749528550808091180185","event_type":"last_trade_price","fee_rate_bps":"0","market":"0xd5f15f31689703aea70b93a52194a0964220d10d92ee7497346f146a8b6ef8ab","price":"0.83","side":"BUY","size":"1.216864","timestamp":"1786845516618","transaction_hash":"0xd3a6bf62df5b7386659790700b075ed348b2620b402a64f0f358dd787040c309"}}
{"f":465,"recv_ms":1786845516837,"raw":{"event_type":"price_change","market":"0xd5f15f31689703aea70b93a52194a0964220d10d92ee7497346f146a8b6ef8ab","price_changes":[{"asset_id":"2151378744569768920256500242561922410292857798164019061749528550808091180185","best_ask":"0.83","best_bid":"0.82","hash":"fa38bae0ffaa5c92239637e1b87b92b35303da66","price":"0.01","side":"BUY","size":"5668.53"},{"asset_id":"17406866367975599232214757606801140480252276357934486651183783311435802862074","best_ask":"0.18","best_bid":"0.17","hash":"dcd356746605d0b85e3e8b61ce94851b18afd7fc","price":"0.99","side":"SELL","size":"5668.53"}],"timestamp":"1786845516622"}}
{"f":466,"recv_ms":1786845516837,"raw":{"event_type":"price_change","market":"0xd5f15f31689703aea70b93a52194a0964220d10d92ee7497346f146a8b6ef8ab","price_changes":[{"asset_id":"2151378744569768920256500242561922410292857798164019061749528550808091180185","best_ask":"0.83","best_bid":"0.82","hash":"834b77ee95a5af19bdd481c0ac232c2ef437782a","price":"0.01","side":"BUY","size":"5673.53"},{"asset_id":"17406866367975599232214757606801140480252276357934486651183783311435802862074","best_ask":"0.18","best_bid":"0.17","hash":"3cbdba1a6258b5864c586b68e5763cd5d392bc7d","price":"0.99","side":"SELL","size":"5673.53"}],"timestamp":"1786845516624"}}
{"f":467,"recv_ms":1786845516845,"raw":{"event_type":"price_change","market":"0xd5f15f31689703aea70b93a52194a0964220d10d92ee7497346f146a8b6ef8ab","price_changes":[{"asset_id":"2151378744569768920256500242561922410292857798164019061749528550808091180185","best_ask":"0.83","best_bid":"0.82","hash":"ca8b01286d7ac402d8327fd3b00edeaada412eda","price":"0.01","side":"BUY","size":"5668.53"},{"asset_id":"17406866367975599232214757606801140480252276357934486651183783311435802862074","best_ask":"0.18","best_bid":"0.17","hash":"a19066b774edbb62878145605a6676ab5c172552","price":"0.99","side":"SELL","size":"5668.53"}],"timestamp":"1786845516626"}}
{"f":468,"recv_ms":1786845516855,"raw":{"event_type":"price_change","market":"0x0f808668c26a078e39fb08c32be2c04739e31f58d8d58dc81f3771760aa097da","price_changes":[{"asset_id":"109981215458957430670008039613114505679239971255550615765913446335529931163020","best_ask":"0.51","best_bid":"0.5","hash":"f7cbec6547cc113b007417c7d80c5c17176e71d1","price":"0.13","side":"BUY","size":"38.2"},{"asset_id":"9052432239268584294914812202913499895678363531348080565599375753720096525063","best_ask":"0.5","best_bid":"0.49","hash":"ab4e180decb2ce94faca0b184837dcd337b45eff","price":"0.87","side":"SELL","size":"38.2"}],"timestamp":"1786845516641"}}
{"f":469,"recv_ms":1786845516872,"raw":{"event_type":"price_change","market":"0xd5f15f31689703aea70b93a52194a0964220d10d92ee7497346f146a8b6ef8ab","price_changes":[{"asset_id":"2151378744569768920256500242561922410292857798164019061749528550808091180185","best_ask":"0.83","best_bid":"0.82","hash":"6068eb4eda75e1ab113b43e9138a4c7699254474","price":"0.01","side":"BUY","size":"5662.53"},{"asset_id":"17406866367975599232214757606801140480252276357934486651183783311435802862074","best_ask":"0.18","best_bid":"0.17","hash":"f2b2be73660861785d2024abdd8aeb3011aee123","price":"0.99","side":"SELL","size":"5662.53"}],"timestamp":"1786845516644"}}
{"f":470,"recv_ms":1786845516872,"raw":{"event_type":"price_change","market":"0xd5f15f31689703aea70b93a52194a0964220d10d92ee7497346f146a8b6ef8ab","price_changes":[{"asset_id":"2151378744569768920256500242561922410292857798164019061749528550808091180185","best_ask":"0.83","best_bid":"0.82","hash":"bf39b02d908c17ccc76097041823166347d08417","price":"0.01","side":"BUY","size":"5762.53"},{"asset_id":"17406866367975599232214757606801140480252276357934486651183783311435802862074","best_ask":"0.18","best_bid":"0.17","hash":"c933aa5ce2faba6695aff9b4936157639eb4203c","price":"0.99","side":"SELL","size":"5762.53"}],"timestamp":"1786845516652"}}
{"f":471,"recv_ms":1786845516908,"raw":{"event_type":"price_change","market":"0xd5f15f31689703aea70b93a52194a0964220d10d92ee7497346f146a8b6ef8ab","price_changes":[{"asset_id":"2151378744569768920256500242561922410292857798164019061749528550808091180185","best_ask":"0.83","best_bid":"0.82","hash":"616149dd7542f764e1d42702d19c26fed5e7effd","price":"0.67","side":"BUY","size":"10"},{"asset_id":"17406866367975599232214757606801140480252276357934486651183783311435802862074","best_ask":"0.18","best_bid":"0.17","hash":"4559c056e49bd838efe810727fc23f6926f10c94","price":"0.33","side":"SELL","size":"10"}],"timestamp":"1786845516696"}}
{"f":472,"recv_ms":1786845516919,"raw":{"event_type":"price_change","market":"0xd5f15f31689703aea70b93a52194a0964220d10d92ee7497346f146a8b6ef8ab","price_changes":[{"asset_id":"17406866367975599232214757606801140480252276357934486651183783311435802862074","best_ask":"0.18","best_bid":"0.17","hash":"f7faaaec791967b02866a418efba64beedba7262","price":"0.32","side":"SELL","size":"105"},{"asset_id":"2151378744569768920256500242561922410292857798164019061749528550808091180185","best_ask":"0.83","best_bid":"0.82","hash":"0b4e1cab0e97d38389dc4a03aeaffca512a40254","price":"0.68","side":"BUY","size":"105"}],"timestamp":"1786845516697"}}
{"f":473,"recv_ms":1786845516922,"raw":{"event_type":"price_change","market":"0xd5f15f31689703aea70b93a52194a0964220d10d92ee7497346f146a8b6ef8ab","price_changes":[{"asset_id":"2151378744569768920256500242561922410292857798164019061749528550808091180185","best_ask":"0.83","best_bid":"0.82","hash":"d6a415c0f33f68bb6b45e3b2048b2d0a61556e58","price":"0.01","side":"BUY","size":"5662.53"},{"asset_id":"17406866367975599232214757606801140480252276357934486651183783311435802862074","best_ask":"0.18","best_bid":"0.17","hash":"a27a3a8de3956d8ce6969b7e14560edfa7643836","price":"0.99","side":"SELL","size":"5662.53"}],"timestamp":"1786845516708"}}
{"f":474,"recv_ms":1786845516922,"raw":{"event_type":"price_change","market":"0xd5f15f31689703aea70b93a52194a0964220d10d92ee7497346f146a8b6ef8ab","price_changes":[{"asset_id":"2151378744569768920256500242561922410292857798164019061749528550808091180185","best_ask":"0.83","best_bid":"0.82","hash":"018cc649b750f9c970f879290d9f63ea227f5e75","price":"0.01","side":"BUY","size":"5667.53"},{"asset_id":"17406866367975599232214757606801140480252276357934486651183783311435802862074","best_ask":"0.18","best_bid":"0.17","hash":"c4c1368d644ab09a3c4f0a6b861f2eb320e2096e","price":"0.99","side":"SELL","size":"5667.53"}],"timestamp":"1786845516710"}}
{"f":475,"recv_ms":1786845516923,"raw":{"event_type":"price_change","market":"0xd5f15f31689703aea70b93a52194a0964220d10d92ee7497346f146a8b6ef8ab","price_changes":[{"asset_id":"2151378744569768920256500242561922410292857798164019061749528550808091180185","best_ask":"0.83","best_bid":"0.82","hash":"b47a3d5b78c18e41a7e43728ec398fe84cfb1a51","price":"0.01","side":"BUY","size":"5672.53"},{"asset_id":"17406866367975599232214757606801140480252276357934486651183783311435802862074","best_ask":"0.18","best_bid":"0.17","hash":"73b0ab05b6deea65085250f683cb174680f7afe3","price":"0.99","side":"SELL","size":"5672.53"}],"timestamp":"1786845516711"}}
{"f":476,"recv_ms":1786845516923,"raw":{"event_type":"price_change","market":"0xd5f15f31689703aea70b93a52194a0964220d10d92ee7497346f146a8b6ef8ab","price_changes":[{"asset_id":"2151378744569768920256500242561922410292857798164019061749528550808091180185","best_ask":"0.83","best_bid":"0.82","hash":"178369a5d5a95402dcddeaea3820ff88c680280f","price":"0.01","side":"BUY","size":"5677.53"},{"asset_id":"17406866367975599232214757606801140480252276357934486651183783311435802862074","best_ask":"0.18","best_bid":"0.17","hash":"52da98b70530950b5126cddd830c1400cbb16994","price":"0.99","side":"SELL","size":"5677.53"}],"timestamp":"1786845516712"}}
{"f":477,"recv_ms":1786845516935,"raw":{"event_type":"price_change","market":"0xd5f15f31689703aea70b93a52194a0964220d10d92ee7497346f146a8b6ef8ab","price_changes":[{"asset_id":"2151378744569768920256500242561922410292857798164019061749528550808091180185","best_ask":"0.83","best_bid":"0.82","hash":"aa47255e4d1d7accfce0d35b3eac0bfc60239d3e","price":"0.01","side":"BUY","size":"5683.53"},{"asset_id":"17406866367975599232214757606801140480252276357934486651183783311435802862074","best_ask":"0.18","best_bid":"0.17","hash":"4030c48d71d6a840dcd070b984b9f2ff58b8327f","price":"0.99","side":"SELL","size":"5683.53"}],"timestamp":"1786845516712"}}
{"f":478,"recv_ms":1786845516935,"raw":{"event_type":"price_change","market":"0xd5f15f31689703aea70b93a52194a0964220d10d92ee7497346f146a8b6ef8ab","price_changes":[{"asset_id":"2151378744569768920256500242561922410292857798164019061749528550808091180185","best_ask":"0.83","best_bid":"0.82","hash":"d4c45024a9241398a0adf1fc3c7cb55ebd73935d","price":"0.08","side":"BUY","size":"60.29"},{"asset_id":"17406866367975599232214757606801140480252276357934486651183783311435802862074","best_ask":"0.18","best_bid":"0.17","hash":"304a755818dff7b9f7a2d6488e0f6fada37a851a","price":"0.92","side":"SELL","size":"60.29"}],"timestamp":"1786845516723"}}
{"f":479,"recv_ms":1786845516936,"raw":{"event_type":"price_change","market":"0xd5f15f31689703aea70b93a52194a0964220d10d92ee7497346f146a8b6ef8ab","price_changes":[{"asset_id":"2151378744569768920256500242561922410292857798164019061749528550808091180185","best_ask":"0.83","best_bid":"0.82","hash":"d730823d0240c7296b7740588420089fb1ec3e23","price":"0.1","side":"BUY","size":"88.9"},{"asset_id":"17406866367975599232214757606801140480252276357934486651183783311435802862074","best_ask":"0.18","best_bid":"0.17","hash":"9dfe42e8ba59d8bf1f0eabbef63a2890975d7397","price":"0.9","side":"SELL","size":"88.9"}],"timestamp":"1786845516724"}}
{"f":480,"recv_ms":1786845516937,"raw":{"event_type":"price_change","market":"0xd5f15f31689703aea70b93a52194a0964220d10d92ee7497346f146a8b6ef8ab","price_changes":[{"asset_id":"2151378744569768920256500242561922410292857798164019061749528550808091180185","best_ask":"0.83","best_bid":"0.82","hash":"9b52c469d08526f42f470789b3ea338d6c5a2d1b","price":"0.04","side":"BUY","size":"392.7"},{"asset_id":"17406866367975599232214757606801140480252276357934486651183783311435802862074","best_ask":"0.18","best_bid":"0.17","hash":"9cd58ae83991aeeaa201513ee67edb438ea11868","price":"0.96","side":"SELL","size":"392.7"}],"timestamp":"1786845516725"}}
{"f":481,"recv_ms":1786845516937,"raw":{"event_type":"price_change","market":"0xd5f15f31689703aea70b93a52194a0964220d10d92ee7497346f146a8b6ef8ab","price_changes":[{"asset_id":"2151378744569768920256500242561922410292857798164019061749528550808091180185","best_ask":"0.83","best_bid":"0.82","hash":"1a9983c3582fc6dde2949a1e5678fa38217e69be","price":"0.05","side":"BUY","size":"677.3"},{"asset_id":"17406866367975599232214757606801140480252276357934486651183783311435802862074","best_ask":"0.18","best_bid":"0.17","hash":"65438ff8652db3f49ab0ff6958333489c0b9d520","price":"0.95","side":"SELL","size":"677.3"}],"timestamp":"1786845516726"}}
{"f":482,"recv_ms":1786845516940,"raw":{"event_type":"price_change","market":"0xd5f15f31689703aea70b93a52194a0964220d10d92ee7497346f146a8b6ef8ab","price_changes":[{"asset_id":"2151378744569768920256500242561922410292857798164019061749528550808091180185","best_ask":"0.83","best_bid":"0.82","hash":"53ae094f1e8eb1ba909a599c5e6ab4a67b594945","price":"0.06","side":"BUY","size":"401.1"},{"asset_id":"17406866367975599232214757606801140480252276357934486651183783311435802862074","best_ask":"0.18","best_bid":"0.17","hash":"e0b4d48170ab2d982da5e9d427ce453e44908302","price":"0.94","side":"SELL","size":"401.1"}],"timestamp":"1786845516726"}}
{"f":483,"recv_ms":1786845516940,"raw":{"event_type":"price_change","market":"0xd5f15f31689703aea70b93a52194a0964220d10d92ee7497346f146a8b6ef8ab","price_changes":[{"asset_id":"2151378744569768920256500242561922410292857798164019061749528550808091180185","best_ask":"0.83","best_bid":"0.82","hash":"053ed991af7a8ee3f9e34ae9cbffec5a097a3172","price":"0.01","side":"BUY","size":"5688.53"},{"asset_id":"17406866367975599232214757606801140480252276357934486651183783311435802862074","best_ask":"0.18","best_bid":"0.17","hash":"8f2c9fbb11a0b1afda62857a5803440d6fd89d41","price":"0.99","side":"SELL","size":"5688.53"}],"timestamp":"1786845516727"}}
{"f":484,"recv_ms":1786845516943,"raw":{"event_type":"price_change","market":"0xd5f15f31689703aea70b93a52194a0964220d10d92ee7497346f146a8b6ef8ab","price_changes":[{"asset_id":"2151378744569768920256500242561922410292857798164019061749528550808091180185","best_ask":"0.83","best_bid":"0.82","hash":"60d83f353f76ae025f01aa9c17d680fb838c3303","price":"0.15","side":"BUY","size":"35.39"},{"asset_id":"17406866367975599232214757606801140480252276357934486651183783311435802862074","best_ask":"0.18","best_bid":"0.17","hash":"c9125020b9fd2a24dd2cfb839dcbdec713fbb8d5","price":"0.85","side":"SELL","size":"35.39"}],"timestamp":"1786845516728"}}
{"f":485,"recv_ms":1786845516946,"raw":{"event_type":"price_change","market":"0xd5f15f31689703aea70b93a52194a0964220d10d92ee7497346f146a8b6ef8ab","price_changes":[{"asset_id":"2151378744569768920256500242561922410292857798164019061749528550808091180185","best_ask":"0.83","best_bid":"0.82","hash":"ca43ae0e806c27f9b77e9eaec286b297bb20061d","price":"0.07","side":"BUY","size":"309.9"},{"asset_id":"17406866367975599232214757606801140480252276357934486651183783311435802862074","best_ask":"0.18","best_bid":"0.17","hash":"a5bc43f326a8232e44c655b6329210276a415b40","price":"0.93","side":"SELL","size":"309.9"}],"timestamp":"1786845516729"}}
{"f":486,"recv_ms":1786845516946,"raw":{"event_type":"price_change","market":"0xd5f15f31689703aea70b93a52194a0964220d10d92ee7497346f146a8b6ef8ab","price_changes":[{"asset_id":"2151378744569768920256500242561922410292857798164019061749528550808091180185","best_ask":"0.83","best_bid":"0.82","hash":"1435a1e609989679b9707d8052f93ee6116d68b9","price":"0.03","side":"BUY","size":"737.3"},{"asset_id":"17406866367975599232214757606801140480252276357934486651183783311435802862074","best_ask":"0.18","best_bid":"0.17","hash":"1d68a61c03e48301626751bbee6315afa3fb0cc5","price":"0.97","side":"SELL","size":"737.3"}],"timestamp":"1786845516730"}}
{"f":487,"recv_ms":1786845516946,"raw":{"event_type":"price_change","market":"0xd5f15f31689703aea70b93a52194a0964220d10d92ee7497346f146a8b6ef8ab","price_changes":[{"asset_id":"2151378744569768920256500242561922410292857798164019061749528550808091180185","best_ask":"0.83","best_bid":"0.82","hash":"8ae9cf66de3f5742587538fb068768d7675b18d0","price":"0.17","side":"BUY","size":"23.39"},{"asset_id":"17406866367975599232214757606801140480252276357934486651183783311435802862074","best_ask":"0.18","best_bid":"0.17","hash":"acc3adc97472d4cc9a6f0dba045028da5c99591a","price":"0.83","side":"SELL","size":"23.39"}],"timestamp":"1786845516731"}}
{"f":488,"recv_ms":1786845516946,"raw":{"event_type":"price_change","market":"0xd5f15f31689703aea70b93a52194a0964220d10d92ee7497346f146a8b6ef8ab","price_changes":[{"asset_id":"2151378744569768920256500242561922410292857798164019061749528550808091180185","best_ask":"0.83","best_bid":"0.82","hash":"edc2018f1014753e2d4cce7e4689b742de470325","price":"0.09","side":"BUY","size":"56.7"},{"asset_id":"17406866367975599232214757606801140480252276357934486651183783311435802862074","best_ask":"0.18","best_bid":"0.17","hash":"adc0e1f370e5373667b4fcab9b4f4c2c330fa2d8","price":"0.91","side":"SELL","size":"56.7"}],"timestamp":"1786845516731"}}
{"f":489,"recv_ms":1786845516949,"raw":{"event_type":"price_change","market":"0xd5f15f31689703aea70b93a52194a0964220d10d92ee7497346f146a8b6ef8ab","price_changes":[{"asset_id":"2151378744569768920256500242561922410292857798164019061749528550808091180185","best_ask":"0.83","best_bid":"0.82","hash":"a7260c9349905df4bd7ccb66f9dcc5425f234a44","price":"0.13","side":"BUY","size":"33"},{"asset_id":"17406866367975599232214757606801140480252276357934486651183783311435802862074","best_ask":"0.18","best_bid":"0.17","hash":"777074cd1de7d3c393498b91818f84c8f857d336","price":"0.87","side":"SELL","size":"33"}],"timestamp":"1786845516732"}}
{"f":490,"recv_ms":1786845516949,"raw":{"event_type":"price_change","market":"0xd5f15f31689703aea70b93a52194a0964220d10d92ee7497346f146a8b6ef8ab","price_changes":[{"asset_id":"2151378744569768920256500242561922410292857798164019061749528550808091180185","best_ask":"0.83","best_bid":"0.82","hash":"b8ad6a4ea11b2f81bfde9d44312ae43d909225e5","price":"0.02","side":"BUY","size":"3740.18"},{"asset_id":"17406866367975599232214757606801140480252276357934486651183783311435802862074","best_ask":"0.18","best_bid":"0.17","hash":"8e661befd2f8cc6e10ea5c6d50094f7e4d36c641","price":"0.98","side":"SELL","size":"3740.18"}],"timestamp":"1786845516733"}}
{"f":491,"recv_ms":1786845516949,"raw":{"event_type":"price_change","market":"0xd5f15f31689703aea70b93a52194a0964220d10d92ee7497346f146a8b6ef8ab","price_changes":[{"asset_id":"2151378744569768920256500242561922410292857798164019061749528550808091180185","best_ask":"0.83","best_bid":"0.82","hash":"84a46c1e66ce955fb7045967ddfd49c8681dcd37","price":"0.14","side":"BUY","size":"31.6"},{"asset_id":"17406866367975599232214757606801140480252276357934486651183783311435802862074","best_ask":"0.18","best_bid":"0.17","hash":"342418f33cdaf458c1b1ca0905eab112db7ab3bb","price":"0.86","side":"SELL","size":"31.6"}],"timestamp":"1786845516733"}}
{"f":492,"recv_ms":1786845516949,"raw":{"event_type":"price_change","market":"0xd5f15f31689703aea70b93a52194a0964220d10d92ee7497346f146a8b6ef8ab","price_changes":[{"asset_id":"2151378744569768920256500242561922410292857798164019061749528550808091180185","best_ask":"0.83","best_bid":"0.82","hash":"19febc1e87e7aabd58423012280aac9a439df51f","price":"0.16","side":"BUY","size":"29.3"},{"asset_id":"17406866367975599232214757606801140480252276357934486651183783311435802862074","best_ask":"0.18","best_bid":"0.17","hash":"1ca5c42c07d55b5fb7aadfa1841fba79881cfceb","price":"0.84","side":"SELL","size":"29.3"}],"timestamp":"1786845516734"}}
{"f":493,"recv_ms":1786845516949,"raw":{"event_type":"price_change","market":"0xd5f15f31689703aea70b93a52194a0964220d10d92ee7497346f146a8b6ef8ab","price_changes":[{"asset_id":"2151378744569768920256500242561922410292857798164019061749528550808091180185","best_ask":"0.83","best_bid":"0.82","hash":"92a36a0cf61f5a16ce3e2725de59ded7a7e4ff69","price":"0.12","side":"BUY","size":"39.6"},{"asset_id":"17406866367975599232214757606801140480252276357934486651183783311435802862074","best_ask":"0.18","best_bid":"0.17","hash":"44fa9d604c792993c60b4a3781d3f0fe573f5863","price":"0.88","side":"SELL","size":"39.6"}],"timestamp":"1786845516735"}}
{"f":494,"recv_ms":1786845516952,"raw":{"event_type":"price_change","market":"0xd5f15f31689703aea70b93a52194a0964220d10d92ee7497346f146a8b6ef8ab","price_changes":[{"asset_id":"2151378744569768920256500242561922410292857798164019061749528550808091180185","best_ask":"0.83","best_bid":"0.82","hash":"8af19ea1e2c5db5920fd794244c7673e75ffa5d8","price":"0.01","side":"BUY","size":"5788.53"},{"asset_id":"17406866367975599232214757606801140480252276357934486651183783311435802862074","best_ask":"0.18","best_bid":"0.17","hash":"871f750c545eb4d82a7d266bbbf93375f06621d0","price":"0.99","side":"SELL","size":"5788.53"}],"timestamp":"1786845516738"}}
{"f":495,"recv_ms":1786845516952,"raw":{"event_type":"price_change","market":"0xd5f15f31689703aea70b93a52194a0964220d10d92ee7497346f146a8b6ef8ab","price_changes":[{"asset_id":"2151378744569768920256500242561922410292857798164019061749528550808091180185","best_ask":"0.83","best_bid":"0.82","hash":"c84a1504ae8c75c9b0fb2f034690d0a0ff4af1f0","price":"0.11","side":"BUY","size":"46.6"},{"asset_id":"17406866367975599232214757606801140480252276357934486651183783311435802862074","best_ask":"0.18","best_bid":"0.17","hash":"c6eeac2a66977ce067c9327ecacde10b352a01bb","price":"0.89","side":"SELL","size":"46.6"}],"timestamp":"1786845516741"}}
{"f":496,"recv_ms":1786845516957,"raw":{"event_type":"price_change","market":"0xd5f15f31689703aea70b93a52194a0964220d10d92ee7497346f146a8b6ef8ab","price_changes":[{"asset_id":"2151378744569768920256500242561922410292857798164019061749528550808091180185","best_ask":"0.83","best_bid":"0.82","hash":"44a3a7b21b6b5e6fb74afb8bd78f59dc07ec9fa8","price":"0.82","side":"BUY","size":"137.27"},{"asset_id":"17406866367975599232214757606801140480252276357934486651183783311435802862074","best_ask":"0.18","best_bid":"0.17","hash":"6cd8c41249f39b54747a73da76dc8c446e14444e","price":"0.18","side":"SELL","size":"137.27"}],"timestamp":"1786845516741"}}
{"f":497,"recv_ms":1786845516964,"raw":{"event_type":"price_change","market":"0xd5f15f31689703aea70b93a52194a0964220d10d92ee7497346f146a8b6ef8ab","price_changes":[{"asset_id":"2151378744569768920256500242561922410292857798164019061749528550808091180185","best_ask":"0.83","best_bid":"0.82","hash":"f48d4ad314a6cacff1b7a5daf26b1764a68b8994","price":"0.01","side":"BUY","size":"5782.53"},{"asset_id":"17406866367975599232214757606801140480252276357934486651183783311435802862074","best_ask":"0.18","best_bid":"0.17","hash":"a6d5e39d70350599f58d8956c9d04bfbc8d8d3f1","price":"0.99","side":"SELL","size":"5782.53"}],"timestamp":"1786845516743"}}
{"f":498,"recv_ms":1786845516964,"raw":{"event_type":"price_change","market":"0xd5f15f31689703aea70b93a52194a0964220d10d92ee7497346f146a8b6ef8ab","price_changes":[{"asset_id":"2151378744569768920256500242561922410292857798164019061749528550808091180185","best_ask":"0.83","best_bid":"0.82","hash":"c7f73a841518622baa1504927fb657095eac22b9","price":"0.01","side":"BUY","size":"5777.53"},{"asset_id":"17406866367975599232214757606801140480252276357934486651183783311435802862074","best_ask":"0.18","best_bid":"0.17","hash":"105b87caf4e1aa9c1fbf1f48a69e29e2bf7e92fa","price":"0.99","side":"SELL","size":"5777.53"}],"timestamp":"1786845516746"}}
{"f":499,"recv_ms":1786845516964,"raw":{"event_type":"price_change","market":"0xd5f15f31689703aea70b93a52194a0964220d10d92ee7497346f146a8b6ef8ab","price_changes":[{"asset_id":"17406866367975599232214757606801140480252276357934486651183783311435802862074","best_ask":"0.18","best_bid":"0.17","hash":"1cde0bd31d523567b2cd2abb670a8e16f0597d50","price":"0.34","side":"SELL","size":"18"},{"asset_id":"2151378744569768920256500242561922410292857798164019061749528550808091180185","best_ask":"0.83","best_bid":"0.82","hash":"cb6d64a5bc8e97624505fb0a03f40af25065964e","price":"0.66","side":"BUY","size":"18"}],"timestamp":"1786845516747"}}
{"f":500,"recv_ms":1786845516964,"raw":{"event_type":"price_change","market":"0xd5f15f31689703aea70b93a52194a0964220d10d92ee7497346f146a8b6ef8ab","price_changes":[{"asset_id":"2151378744569768920256500242561922410292857798164019061749528550808091180185","best_ask":"0.83","best_bid":"0.82","hash":"c298bb79ff520b777a12cc78cb91c147b5a0c5db","price":"0.01","side":"BUY","size":"5782.54"},{"asset_id":"17406866367975599232214757606801140480252276357934486651183783311435802862074","best_ask":"0.18","best_bid":"0.17","hash":"8f73117d52daf9f578072dcb2e846912ce0151f1","price":"0.99","side":"SELL","size":"5782.54"}],"timestamp":"1786845516753"}}
{"f":501,"recv_ms":1786845516996,"raw":{"event_type":"price_change","market":"0xd5f15f31689703aea70b93a52194a0964220d10d92ee7497346f146a8b6ef8ab","price_changes":[{"asset_id":"2151378744569768920256500242561922410292857798164019061749528550808091180185","best_ask":"0.83","best_bid":"0.82","hash":"42530c0b8254760982e431323cc136ea25ff8468","price":"0.82","side":"BUY","size":"187.27"},{"asset_id":"17406866367975599232214757606801140480252276357934486651183783311435802862074","best_ask":"0.18","best_bid":"0.17","hash":"c52667d17782ce7072497df92719476677d675ee","price":"0.18","side":"SELL","size":"187.27"}],"timestamp":"1786845516773"}}
{"f":502,"recv_ms":1786845516996,"raw":{"event_type":"price_change","market":"0xd5f15f31689703aea70b93a52194a0964220d10d92ee7497346f146a8b6ef8ab","price_changes":[{"asset_id":"17406866367975599232214757606801140480252276357934486651183783311435802862074","best_ask":"0.18","best_bid":"0.16","hash":"395dfb4a0c5d4928d54a2009c5bd392ee0b80d02","price":"0.17","side":"BUY","size":"0"},{"asset_id":"2151378744569768920256500242561922410292857798164019061749528550808091180185","best_ask":"0.84","best_bid":"0.82","hash":"680e54d23faad40e00157880ad63b4bcc0b73c5a","price":"0.83","side":"SELL","size":"0"}],"timestamp":"1786845516773"}}
{"f":503,"recv_ms":1786845516996,"raw":{"event_type":"price_change","market":"0xd5f15f31689703aea70b93a52194a0964220d10d92ee7497346f146a8b6ef8ab","price_changes":[{"asset_id":"2151378744569768920256500242561922410292857798164019061749528550808091180185","best_ask":"0.84","best_bid":"0.83","hash":"a26e8a83c2e6003317d55ce27eb641235a59d789","price":"0.83","side":"BUY","size":"33.33"},{"asset_id":"17406866367975599232214757606801140480252276357934486651183783311435802862074","best_ask":"0.17","best_bid":"0.16","hash":"40d8d1c61296e6c069ddb36e5e29fd50f6a4104b","price":"0.17","side":"SELL","size":"33.33"}],"timestamp":"1786845516779"}}
{"f":504,"recv_ms":1786845516996,"raw":{"event_type":"price_change","market":"0xd5f15f31689703aea70b93a52194a0964220d10d92ee7497346f146a8b6ef8ab","price_changes":[{"asset_id":"17406866367975599232214757606801140480252276357934486651183783311435802862074","best_ask":"0.17","best_bid":"0.16","hash":"f71a39db2e9d92009f5e6a7c8740c3d71fa4ebcc","price":"0.17","side":"SELL","size":"38.33"},{"asset_id":"2151378744569768920256500242561922410292857798164019061749528550808091180185","best_ask":"0.84","best_bid":"0.83","hash":"56d0cfadb7f504c615ecc38f377ff03920944ad2","price":"0.83","side":"BUY","size":"38.33"}],"timestamp":"1786845516780"}}
{"f":505,"recv_ms":1786845516996,"raw":{"event_type":"price_change","market":"0xd5f15f31689703aea70b93a52194a0964220d10d92ee7497346f146a8b6ef8ab","price_changes":[{"asset_id":"17406866367975599232214757606801140480252276357934486651183783311435802862074","best_ask":"0.17","best_bid":"0.16","hash":"2c21bf85aeaa1909d4d64b2e520a388d6a9c089a","price":"0.17","side":"SELL","size":"44.33"},{"asset_id":"2151378744569768920256500242561922410292857798164019061749528550808091180185","best_ask":"0.84","best_bid":"0.83","hash":"cbadb5cf55111de29a8842c554913a9c734bf086","price":"0.83","side":"BUY","size":"44.33"}],"timestamp":"1786845516781"}}
{"f":506,"recv_ms":1786845516996,"raw":{"event_type":"price_change","market":"0xd5f15f31689703aea70b93a52194a0964220d10d92ee7497346f146a8b6ef8ab","price_changes":[{"asset_id":"2151378744569768920256500242561922410292857798164019061749528550808091180185","best_ask":"0.84","best_bid":"0.83","hash":"a11637f6edc06b7d162a8af3171874bd9db4d0c6","price":"0.83","side":"BUY","size":"76.33"},{"asset_id":"17406866367975599232214757606801140480252276357934486651183783311435802862074","best_ask":"0.17","best_bid":"0.16","hash":"ef9f1193fd19d2d0306b7a18f28dbec188f8ef22","price":"0.17","side":"SELL","size":"76.33"}],"timestamp":"1786845516781"}}
{"f":507,"recv_ms":1786845516996,"raw":{"event_type":"price_change","market":"0xd5f15f31689703aea70b93a52194a0964220d10d92ee7497346f146a8b6ef8ab","price_changes":[{"asset_id":"17406866367975599232214757606801140480252276357934486651183783311435802862074","best_ask":"0.17","best_bid":"0.16","hash":"44defc15c0ccfb8994ef64083bbf8a45931e59c9","price":"0.17","side":"SELL","size":"81.33"},{"asset_id":"2151378744569768920256500242561922410292857798164019061749528550808091180185","best_ask":"0.84","best_bid":"0.83","hash":"3814ffbcfc0c57c5e0f8150bab06c71582d8f95d","price":"0.83","side":"BUY","size":"81.33"}],"timestamp":"1786845516782"}}
{"f":508,"recv_ms":1786845516997,"raw":{"event_type":"price_change","market":"0xd5f15f31689703aea70b93a52194a0964220d10d92ee7497346f146a8b6ef8ab","price_changes":[{"asset_id":"17406866367975599232214757606801140480252276357934486651183783311435802862074","best_ask":"0.17","best_bid":"0.16","hash":"f2eed9419b55e4233d76f0ca308b690b1ce8452d","price":"0.17","side":"SELL","size":"91.33"},{"asset_id":"2151378744569768920256500242561922410292857798164019061749528550808091180185","best_ask":"0.84","best_bid":"0.83","hash":"6be96a784a16473367fcb7ad352caf655a8093b0","price":"0.83","side":"BUY","size":"91.33"}],"timestamp":"1786845516783"}}
{"f":509,"recv_ms":1786845516997,"raw":{"event_type":"price_change","market":"0xd5f15f31689703aea70b93a52194a0964220d10d92ee7497346f146a8b6ef8ab","price_changes":[{"asset_id":"2151378744569768920256500242561922410292857798164019061749528550808091180185","best_ask":"0.84","best_bid":"0.83","hash":"35cea117c5f606df16c0ff13c2993bb723aff4c0","price":"0.83","side":"BUY","size":"124.66"},{"asset_id":"17406866367975599232214757606801140480252276357934486651183783311435802862074","best_ask":"0.17","best_bid":"0.16","hash":"39ebc7245ba4d825b904864686f9775823887fe1","price":"0.17","side":"SELL","size":"124.66"}],"timestamp":"1786845516784"}}
{"f":510,"recv_ms":1786845516997,"raw":{"event_type":"price_change","market":"0xd5f15f31689703aea70b93a52194a0964220d10d92ee7497346f146a8b6ef8ab","price_changes":[{"asset_id":"17406866367975599232214757606801140480252276357934486651183783311435802862074","best_ask":"0.17","best_bid":"0.16","hash":"fb3c911d4b9e3bc489e3bcf38de28c698c1a27e0","price":"0.17","side":"SELL","size":"130.66"},{"asset_id":"2151378744569768920256500242561922410292857798164019061749528550808091180185","best_ask":"0.84","best_bid":"0.83","hash":"1d8b2adf289052d3b882043d369c8b303c93fa0a","price":"0.83","side":"BUY","size":"130.66"}],"timestamp":"1786845516785"}}
{"f":511,"recv_ms":1786845516997,"raw":{"event_type":"price_change","market":"0xd5f15f31689703aea70b93a52194a0964220d10d92ee7497346f146a8b6ef8ab","price_changes":[{"asset_id":"2151378744569768920256500242561922410292857798164019061749528550808091180185","best_ask":"0.84","best_bid":"0.83","hash":"87d62c6572dd6b150bc0438c7fcaa8e87e5a01c5","price":"0.01","side":"BUY","size":"5777.54"},{"asset_id":"17406866367975599232214757606801140480252276357934486651183783311435802862074","best_ask":"0.17","best_bid":"0.16","hash":"df4b9a785dcaaaf188fb125f366efc14674ecc65","price":"0.99","side":"SELL","size":"5777.54"}],"timestamp":"1786845516785"}}
{"f":512,"recv_ms":1786845516997,"raw":{"event_type":"price_change","market":"0xd5f15f31689703aea70b93a52194a0964220d10d92ee7497346f146a8b6ef8ab","price_changes":[{"asset_id":"2151378744569768920256500242561922410292857798164019061749528550808091180185","best_ask":"0.84","best_bid":"0.83","hash":"2865db227139d47900c89c7961147f2669cd9e5e","price":"0.01","side":"BUY","size":"5677.54"},{"asset_id":"17406866367975599232214757606801140480252276357934486651183783311435802862074","best_ask":"0.17","best_bid":"0.16","hash":"d668641482f1427fbb2dd8c4beda26944d34cfc1","price":"0.99","side":"SELL","size":"5677.54"}],"timestamp":"1786845516785"}}
{"f":513,"recv_ms":1786845516998,"raw":{"event_type":"price_change","market":"0xd5f15f31689703aea70b93a52194a0964220d10d92ee7497346f146a8b6ef8ab","price_changes":[{"asset_id":"17406866367975599232214757606801140480252276357934486651183783311435802862074","best_ask":"0.17","best_bid":"0.16","hash":"84f765aed0f64f9f9bedfdac19cefbdd68d5e094","price":"0.17","side":"SELL","size":"136.66"},{"asset_id":"2151378744569768920256500242561922410292857798164019061749528550808091180185","best_ask":"0.84","best_bid":"0.83","hash":"3e785e2769755ddd51cd5de1a89856f6b61a1dfa","price":"0.83","side":"BUY","size":"136.66"}],"timestamp":"1786845516786"}}
{"f":514,"recv_ms":1786845516998,"raw":{"event_type":"price_change","market":"0xd5f15f31689703aea70b93a52194a0964220d10d92ee7497346f146a8b6ef8ab","price_changes":[{"asset_id":"17406866367975599232214757606801140480252276357934486651183783311435802862074","best_ask":"0.17","best_bid":"0.16","hash":"648885f89c9783218feabeecb38f227db31c0746","price":"0.17","side":"SELL","size":"146.66"},{"asset_id":"2151378744569768920256500242561922410292857798164019061749528550808091180185","best_ask":"0.84","best_bid":"0.83","hash":"817d66b31bba13571a783aaa1197426ec5df2e3a","price":"0.83","side":"BUY","size":"146.66"}],"timestamp":"1786845516786"}}
{"f":515,"recv_ms":1786845516999,"raw":{"event_type":"price_change","market":"0xd5f15f31689703aea70b93a52194a0964220d10d92ee7497346f146a8b6ef8ab","price_changes":[{"asset_id":"17406866367975599232214757606801140480252276357934486651183783311435802862074","best_ask":"0.17","best_bid":"0.16","hash":"c7f300e284960ae9545349e7ee9140f69f557ae9","price":"0.17","side":"SELL","size":"152.66"},{"asset_id":"2151378744569768920256500242561922410292857798164019061749528550808091180185","best_ask":"0.84","best_bid":"0.83","hash":"d4ea533ea1edd1e5ae040d78720a398c7abe52d4","price":"0.83","side":"BUY","size":"152.66"}],"timestamp":"1786845516787"}}
{"f":516,"recv_ms":1786845516999,"raw":{"event_type":"price_change","market":"0xd5f15f31689703aea70b93a52194a0964220d10d92ee7497346f146a8b6ef8ab","price_changes":[{"asset_id":"2151378744569768920256500242561922410292857798164019061749528550808091180185","best_ask":"0.84","best_bid":"0.83","hash":"f273d09e27f2992b447db982362a07f0d5c69bfe","price":"0.01","side":"BUY","size":"5672.53"},{"asset_id":"17406866367975599232214757606801140480252276357934486651183783311435802862074","best_ask":"0.17","best_bid":"0.16","hash":"3cdc6ecb7fb9a769eb0bcfee5b16b28c7a9557f5","price":"0.99","side":"SELL","size":"5672.53"}],"timestamp":"1786845516788"}}
{"f":517,"recv_ms":1786845517000,"raw":{"event_type":"price_change","market":"0xd5f15f31689703aea70b93a52194a0964220d10d92ee7497346f146a8b6ef8ab","price_changes":[{"asset_id":"17406866367975599232214757606801140480252276357934486651183783311435802862074","best_ask":"0.17","best_bid":"0.16","hash":"b2853d1d6f248600a67a7eb2d01a5e40c6813bea","price":"0.17","side":"SELL","size":"157.66"},{"asset_id":"2151378744569768920256500242561922410292857798164019061749528550808091180185","best_ask":"0.84","best_bid":"0.83","hash":"0338ad6b2aa20a6c75b0882bd4933f0cd336b739","price":"0.83","side":"BUY","size":"157.66"}],"timestamp":"1786845516788"}}
{"f":518,"recv_ms":1786845517000,"raw":{"event_type":"price_change","market":"0xd5f15f31689703aea70b93a52194a0964220d10d92ee7497346f146a8b6ef8ab","price_changes":[{"asset_id":"17406866367975599232214757606801140480252276357934486651183783311435802862074","best_ask":"0.17","best_bid":"0.16","hash":"4a1bc19b33568cc2ef8802392cb5a58bb5ee99ad","price":"0.17","side":"SELL","size":"169.66"},{"asset_id":"2151378744569768920256500242561922410292857798164019061749528550808091180185","best_ask":"0.84","best_bid":"0.83","hash":"34bf0f190b475510a4ce6f0636614427b70db1eb","price":"0.83","side":"BUY","size":"169.66"}],"timestamp":"1786845516789"}}
{"f":519,"recv_ms":1786845517004,"raw":{"event_type":"price_change","market":"0xd5f15f31689703aea70b93a52194a0964220d10d92ee7497346f146a8b6ef8ab","price_changes":[{"asset_id":"2151378744569768920256500242561922410292857798164019061749528550808091180185","best_ask":"0.84","best_bid":"0.83","hash":"9c39aebb57b67f3ea85d7acaa0bdb8d59b83276e","price":"0.83","side":"BUY","size":"202.99"},{"asset_id":"17406866367975599232214757606801140480252276357934486651183783311435802862074","best_ask":"0.17","best_bid":"0.16","hash":"7b42b3c3f9c914bb025450aa091a3d57c40caa39","price":"0.17","side":"SELL","size":"202.99"}],"timestamp":"1786845516789"}}
{"f":520,"recv_ms":1786845517004,"raw":{"event_type":"price_change","market":"0xd5f15f31689703aea70b93a52194a0964220d10d92ee7497346f146a8b6ef8ab","price_changes":[{"asset_id":"2151378744569768920256500242561922410292857798164019061749528550808091180185","best_ask":"0.84","best_bid":"0.83","hash":"10fdd0ed247bf5fbb3a02f6a1cc9356ef2a76dad","price":"0.83","side":"BUY","size":"212.99"},{"asset_id":"17406866367975599232214757606801140480252276357934486651183783311435802862074","best_ask":"0.17","best_bid":"0.16","hash":"057082423cf2d7e4553667982f8ddf473d4ef8a0","price":"0.17","side":"SELL","size":"212.99"}],"timestamp":"1786845516790"}}
{"f":521,"recv_ms":1786845517006,"raw":{"event_type":"price_change","market":"0xd5f15f31689703aea70b93a52194a0964220d10d92ee7497346f146a8b6ef8ab","price_changes":[{"asset_id":"2151378744569768920256500242561922410292857798164019061749528550808091180185","best_ask":"0.84","best_bid":"0.83","hash":"21e512dfb73b22be5f41a901df2ac8efad4c1903","price":"0.42","side":"BUY","size":"62.7"},{"asset_id":"17406866367975599232214757606801140480252276357934486651183783311435802862074","best_ask":"0.17","best_bid":"0.16","hash":"279a1e371566f00a502e5b73c7eb6309733d6fce","price":"0.58","side":"SELL","size":"62.7"}],"timestamp":"1786845516793"}}
{"f":522,"recv_ms":1786845517006,"raw":{"event_type":"price_change","market":"0xd5f15f31689703aea70b93a52194a0964220d10d92ee7497346f146a8b6ef8ab","price_changes":[{"asset_id":"2151378744569768920256500242561922410292857798164019061749528550808091180185","best_ask":"0.84","best_bid":"0.83","hash":"21e512dfb73b22be5f41a901df2ac8efad4c1903","price":"0.43","side":"BUY","size":"62.6"},{"asset_id":"17406866367975599232214757606801140480252276357934486651183783311435802862074","best_ask":"0.17","best_bid":"0.16","hash":"279a1e371566f00a502e5b73c7eb6309733d6fce","price":"0.57","side":"SELL","size":"62.6"}],"timestamp":"1786845516793"}}
{"f":523,"recv_ms":1786845517006,"raw":{"event_type":"price_change","market":"0xd5f15f31689703aea70b93a52194a0964220d10d92ee7497346f146a8b6ef8ab","price_changes":[{"asset_id":"2151378744569768920256500242561922410292857798164019061749528550808091180185","best_ask":"0.84","best_bid":"0.83","hash":"21e512dfb73b22be5f41a901df2ac8efad4c1903","price":"0.44","side":"BUY","size":"93.6"},{"asset_id":"17406866367975599232214757606801140480252276357934486651183783311435802862074","best_ask":"0.17","best_bid":"0.16","hash":"279a1e371566f00a502e5b73c7eb6309733d6fce","price":"0.56","side":"SELL","size":"93.6"}],"timestamp":"1786845516793"}}
{"f":524,"recv_ms":1786845517006,"raw":{"event_type":"price_change","market":"0xd5f15f31689703aea70b93a52194a0964220d10d92ee7497346f146a8b6ef8ab","price_changes":[{"asset_id":"2151378744569768920256500242561922410292857798164019061749528550808091180185","best_ask":"0.84","best_bid":"0.83","hash":"21e512dfb73b22be5f41a901df2ac8efad4c1903","price":"0.45","side":"BUY","size":"21.5"},{"asset_id":"17406866367975599232214757606801140480252276357934486651183783311435802862074","best_ask":"0.17","best_bid":"0.16","hash":"279a1e371566f00a502e5b73c7eb6309733d6fce","price":"0.55","side":"SELL","size":"21.5"}],"timestamp":"1786845516793"}}
{"f":525,"recv_ms":1786845517006,"raw":{"event_type":"price_change","market":"0xd5f15f31689703aea70b93a52194a0964220d10d92ee7497346f146a8b6ef8ab","price_changes":[{"asset_id":"2151378744569768920256500242561922410292857798164019061749528550808091180185","best_ask":"0.84","best_bid":"0.83","hash":"21e512dfb73b22be5f41a901df2ac8efad4c1903","price":"0.46","side":"BUY","size":"21.5"},{"asset_id":"17406866367975599232214757606801140480252276357934486651183783311435802862074","best_ask":"0.17","best_bid":"0.16","hash":"279a1e371566f00a502e5b73c7eb6309733d6fce","price":"0.54","side":"SELL","size":"21.5"}],"timestamp":"1786845516793"}}
{"f":526,"recv_ms":1786845517006,"raw":{"event_type":"price_change","market":"0xd5f15f31689703aea70b93a52194a0964220d10d92ee7497346f146a8b6ef8ab","price_changes":[{"asset_id":"2151378744569768920256500242561922410292857798164019061749528550808091180185","best_ask":"0.84","best_bid":"0.83","hash":"21e512dfb73b22be5f41a901df2ac8efad4c1903","price":"0.47","side":"BUY","size":"21.4"},{"asset_id":"17406866367975599232214757606801140480252276357934486651183783311435802862074","best_ask":"0.17","best_bid":"0.16","hash":"279a1e371566f00a502e5b73c7eb6309733d6fce","price":"0.53","side":"SELL","size":"21.4"}],"timestamp":"1786845516793"}}
{"f":527,"recv_ms":1786845517008,"raw":{"event_type":"price_change","market":"0xd5f15f31689703aea70b93a52194a0964220d10d92ee7497346f146a8b6ef8ab","price_changes":[{"asset_id":"2151378744569768920256500242561922410292857798164019061749528550808091180185","best_ask":"0.84","best_bid":"0.83","hash":"21e512dfb73b22be5f41a901df2ac8efad4c1903","price":"0.48","side":"BUY","size":"20.4"},{"asset_id":"17406866367975599232214757606801140480252276357934486651183783311435802862074","best_ask":"0.17","best_bid":"0.16","hash":"279a1e371566f00a502e5b73c7eb6309733d6fce","price":"0.52","side":"SELL","size":"20.4"}],"timestamp":"1786845516793"}}
{"f":528,"recv_ms":1786845517008,"raw":{"event_type":"price_change","market":"0xd5f15f31689703aea70b93a52194a0964220d10d92ee7497346f146a8b6ef8ab","price_changes":[{"asset_id":"2151378744569768920256500242561922410292857798164019061749528550808091180185","best_ask":"0.84","best_bid":"0.83","hash":"21e512dfb73b22be5f41a901df2ac8efad4c1903","price":"0.49","side":"BUY","size":"20.4"},{"asset_id":"17406866367975599232214757606801140480252276357934486651183783311435802862074","best_ask":"0.17","best_bid":"0.16","hash":"279a1e371566f00a502e5b73c7eb6309733d6fce","price":"0.51","side":"SELL","size":"20.4"}],"timestamp":"1786845516793"}}
{"f":529,"recv_ms":1786845517008,"raw":{"event_type":"price_change","market":"0xd5f15f31689703aea70b93a52194a0964220d10d92ee7497346f146a8b6ef8ab","price_changes":[{"asset_id":"2151378744569768920256500242561922410292857798164019061749528550808091180185","best_ask":"0.84","best_bid":"0.83","hash":"21e512dfb73b22be5f41a901df2ac8efad4c1903","price":"0.41","side":"BUY","size":"132.7"},{"asset_id":"17406866367975599232214757606801140480252276357934486651183783311435802862074","best_ask":"0.17","best_bid":"0.16","hash":"279a1e371566f00a502e5b73c7eb6309733d6fce","price":"0.59","side":"SELL","size":"132.7"}],"timestamp":"1786845516793"}}
{"f":530,"recv_ms":1786845517008,"raw":{"event_type":"price_change","market":"0xd5f15f31689703aea70b93a52194a0964220d10d92ee7497346f146a8b6ef8ab","price_changes":[{"asset_id":"17406866367975599232214757606801140480252276357934486651183783311435802862074","best_ask":"0.17","best_bid":"0.16","hash":"f6e9c8bd2e8ffb29576f4ab34fe067bccb5a1781","price":"0.16","side":"BUY","size":"63.33"},{"asset_id":"2151378744569768920256500242561922410292857798164019061749528550808091180185","best_ask":"0.84","best_bid":"0.83","hash":"f75cba8b736c7fb1abfc60fc591b0bd5ba007d89","price":"0.84","side":"SELL","size":"63.33"}],"timestamp":"1786845516794"}}
{"f":531,"recv_ms":1786845517008,"raw":{"event_type":"price_change","market":"0xd5f15f31689703aea70b93a52194a0964220d10d92ee7497346f146a8b6ef8ab","price_changes":[{"asset_id":"17406866367975599232214757606801140480252276357934486651183783311435802862074","best_ask":"0.17","best_bid":"0.16","hash":"07810ed6905a9d093a70143a93d1560e0a964239","price":"0.1","side":"BUY","size":"96"},{"asset_id":"2151378744569768920256500242561922410292857798164019061749528550808091180185","best_ask":"0.84","best_bid":"0.83","hash":"cabd0a89b8632dfea4d8f518fad62c2c61111490","price":"0.9","side":"SELL","size":"96"}],"timestamp":"1786845516796"}}
{"f":532,"recv_ms":1786845517008,"raw":{"event_type":"price_change","market":"0xd5f15f31689703aea70b93a52194a0964220d10d92ee7497346f146a8b6ef8ab","price_changes":[{"asset_id":"17406866367975599232214757606801140480252276357934486651183783311435802862074","best_ask":"0.17","best_bid":"0.16","hash":"882185daa46210aab260225db2ea27027fceb109","price":"0.13","side":"BUY","size":"40"},{"asset_id":"2151378744569768920256500242561922410292857798164019061749528550808091180185","best_ask":"0.84","best_bid":"0.83","hash":"cce76d6b4ce67c9d75f665257f4dd9c10996790e","price":"0.87","side":"SELL","size":"40"}],"timestamp":"1786845516797"}}
{"f":533,"recv_ms":1786845517009,"raw":{"event_type":"price_change","market":"0xd5f15f31689703aea70b93a52194a0964220d10d92ee7497346f146a8b6ef8ab","price_changes":[{"asset_id":"2151378744569768920256500242561922410292857798164019061749528550808091180185","best_ask":"0.84","best_bid":"0.83","hash":"6ae01e053975417b95db6cf8b4b9e1141f28ac30","price":"0.82","side":"BUY","size":"177.27"},{"asset_id":"17406866367975599232214757606801140480252276357934486651183783311435802862074","best_ask":"0.17","best_bid":"0.16","hash":"b3994b3677b9c3b7ca58f948af54920bfd64c708","price":"0.18","side":"SELL","size":"177.27"}],"timestamp":"1786845516797"}}
{"f":534,"recv_ms":1786845517009,"raw":{"event_type":"price_change","market":"0xd5f15f31689703aea70b93a52194a0964220d10d92ee7497346f146a8b6ef8ab","price_changes":[{"asset_id":"2151378744569768920256500242561922410292857798164019061749528550808091180185","best_ask":"0.84","best_bid":"0.83","hash":"2b42a689992eb52e6c00ecb3c92cb6d9c6a8e233","price":"0.01","side":"BUY","size":"5752.53"},{"asset_id":"17406866367975599232214757606801140480252276357934486651183783311435802862074","best_ask":"0.17","best_bid":"0.16","hash":"213a7b57aec0d72daf604ca02c4bae82c7b533a7","price":"0.99","side":"SELL","size":"5752.53"}],"timestamp":"1786845516797"}}
{"f":535,"recv_ms":1786845517010,"raw":{"event_type":"price_change","market":"0xd5f15f31689703aea70b93a52194a0964220d10d92ee7497346f146a8b6ef8ab","price_changes":[{"asset_id":"17406866367975599232214757606801140480252276357934486651183783311435802862074","best_ask":"0.17","best_bid":"0.16","hash":"933918936025e9d674a63728a3d5abaaf139eb46","price":"0.11","side":"BUY","size":"40"},{"asset_id":"2151378744569768920256500242561922410292857798164019061749528550808091180185","best_ask":"0.84","best_bid":"0.83","hash":"9cdb7a3972c8a523d46dc3bdfd01dc645db42aec","price":"0.89","side":"SELL","size":"40"}],"timestamp":"1786845516798"}}
{"f":536,"recv_ms":1786845517010,"raw":{"event_type":"price_change","market":"0xd5f15f31689703aea70b93a52194a0964220d10d92ee7497346f146a8b6ef8ab","price_changes":[{"asset_id":"17406866367975599232214757606801140480252276357934486651183783311435802862074","best_ask":"0.17","best_bid":"0.16","hash":"ea9801da061f85eaccfdb08b48e51b4ea2a09b5d","price":"0.16","side":"BUY","size":"33.33"},{"asset_id":"2151378744569768920256500242561922410292857798164019061749528550808091180185","best_ask":"0.84","best_bid":"0.83","hash":"203424f3936eb081881df2ebf51f1d95361f4fbb","price":"0.84","side":"SELL","size":"33.33"}],"timestamp":"1786845516799"}}
{"f":537,"recv_ms":1786845517011,"raw":{"event_type":"price_change","market":"0xd5f15f31689703aea70b93a52194a0964220d10d92ee7497346f146a8b6ef8ab","price_changes":[{"asset_id":"2151378744569768920256500242561922410292857798164019061749528550808091180185","best_ask":"0.84","best_bid":"0.83","hash":"839602e35ae135398119061fcdda4ed4aaab0bc6","price":"0.82","side":"BUY","size":"167.27"},{"asset_id":"17406866367975599232214757606801140480252276357934486651183783311435802862074","best_ask":"0.17","best_bid":"0.16","hash":"e1ad54646635e0af9f94934accbcc71cac9b4316","price":"0.18","side":"SELL","size":"167.27"}],"timestamp":"1786845516799"}}
{"f":538,"recv_ms":1786845517011,"raw":{"event_type":"price_change","market":"0xd5f15f31689703aea70b93a52194a0964220d10d92ee7497346f146a8b6ef8ab","price_changes":[{"asset_id":"2151378744569768920256500242561922410292857798164019061749528550808091180185","best_ask":"0.84","best_bid":"0.83","hash":"548b46941562b82897ef9fdc2041fa9e1b6df45c","price":"0.06","side":"BUY","size":"481.1"},{"asset_id":"17406866367975599232214757606801140480252276357934486651183783311435802862074","best_ask":"0.17","best_bid":"0.16","hash":"27979797946e000080bcbfce6434794af0afc878","price":"0.94","side":"SELL","size":"481.1"}],"timestamp":"1786845516799"}}
{"f":539,"recv_ms":1786845517011,"raw":{"event_type":"price_change","market":"0xd5f15f31689703aea70b93a52194a0964220d10d92ee7497346f146a8b6ef8ab","price_changes":[{"asset_id":"2151378744569768920256500242561922410292857798164019061749528550808091180185","best_ask":"0.84","best_bid":"0.83","hash":"2992ee61d4fc6d064ae651467b0e153fa8f53cee","price":"0.82","side":"BUY","size":"157.27"},{"asset_id":"17406866367975599232214757606801140480252276357934486651183783311435802862074","best_ask":"0.17","best_bid":"0.16","hash":"80e4dc6ca8ed84ad66c81a22b1056cad50c3c0a6","price":"0.18","side":"SELL","size":"157.27"}],"timestamp":"1786845516800"}}
{"f":540,"recv_ms":1786845517011,"raw":{"event_type":"price_change","market":"0xd5f15f31689703aea70b93a52194a0964220d10d92ee7497346f146a8b6ef8ab","price_changes":[{"asset_id":"17406866367975599232214757606801140480252276357934486651183783311435802862074","best_ask":"0.17","best_bid":"0.16","hash":"152a8c686866c8ffbbec984bfe08e5c087329f4d","price":"0.15","side":"BUY","size":"35"},{"asset_id":"2151378744569768920256500242561922410292857798164019061749528550808091180185","best_ask":"0.84","best_bid":"0.83","hash":"8d25202076447ca009eb05bda6a8274e48945431","price":"0.85","side":"SELL","size":"35"}],"timestamp":"1786845516800"}}
{"f":541,"recv_ms":1786845517012,"raw":{"event_type":"price_change","market":"0xd5f15f31689703aea70b93a52194a0964220d10d92ee7497346f146a8b6ef8ab","price_changes":[{"asset_id":"2151378744569768920256500242561922410292857798164019061749528550808091180185","best_ask":"0.84","best_bid":"0.83","hash":"525753c9b4be08442b639a7ebf22da0aac31e0c2","price":"0.05","side":"BUY","size":"757.3"},{"asset_id":"17406866367975599232214757606801140480252276357934486651183783311435802862074","best_ask":"0.17","best_bid":"0.16","hash":"f400767204c7a41ed9731d345a19771b087b5a35","price":"0.95","side":"SELL","size":"757.3"}],"timestamp":"1786845516801"}}
{"f":542,"recv_ms":1786845517013,"raw":{"event_type":"price_change","market":"0xd5f15f31689703aea70b93a52194a0964220d10d92ee7497346f146a8b6ef8ab","price_changes":[{"asset_id":"17406866367975599232214757606801140480252276357934486651183783311435802862074","best_ask":"0.17","best_bid":"0.16","hash":"8afee978e29fa6bbefd6db45bbebca874f0e6b79","price":"0.15","side":"BUY","size":"5"},{"asset_id":"2151378744569768920256500242561922410292857798164019061749528550808091180185","best_ask":"0.84","best_bid":"0.83","hash":"74bb3a5de8f288954c53673ea18e017b5ab11b35","price":"0.85","side":"SELL","size":"5"}],"timestamp":"1786845516801"}}
{"f":543,"recv_ms":1786845517013,"raw":{"event_type":"price_change","market":"0xd5f15f31689703aea70b93a52194a0964220d10d92ee7497346f146a8b6ef8ab","price_changes":[{"asset_id":"17406866367975599232214757606801140480252276357934486651183783311435802862074","best_ask":"0.17","best_bid":"0.16","hash":"8afee978e29fa6bbefd6db45bbebca874f0e6b79","price":"0.11","side":"BUY","size":"10"},{"asset_id":"2151378744569768920256500242561922410292857798164019061749528550808091180185","best_ask":"0.84","best_bid":"0.83","hash":"74bb3a5de8f288954c53673ea18e017b5ab11b35","price":"0.89","side":"SELL","size":"10"}],"timestamp":"1786845516801"}}
{"f":544,"recv_ms":1786845517013,"raw":{"event_type":"price_change","market":"0xd5f15f31689703aea70b93a52194a0964220d10d92ee7497346f146a8b6ef8ab","price_changes":[{"asset_id":"17406866367975599232214757606801140480252276357934486651183783311435802862074","best_ask":"0.17","best_bid":"0.16","hash":"8afee978e29fa6bbefd6db45bbebca874f0e6b79","price":"0.1","side":"BUY","size":"66"},{"asset_id":"2151378744569768920256500242561922410292857798164019061749528550808091180185","best_ask":"0.84","best_bid":"0.83","hash":"74bb3a5de8f288954c53673ea18e017b5ab11b35","price":"0.9","side":"SELL","size":"66"}],"timestamp":"1786845516801"}}
{"f":545,"recv_ms":1786845517013,"raw":{"event_type":"price_change","market":"0xd5f15f31689703aea70b93a52194a0964220d10d92ee7497346f146a8b6ef8ab","price_changes":[{"asset_id":"17406866367975599232214757606801140480252276357934486651183783311435802862074","best_ask":"0.17","best_bid":"0.16","hash":"8afee978e29fa6bbefd6db45bbebca874f0e6b79","price":"0.13","side":"BUY","size":"10"},{"asset_id":"2151378744569768920256500242561922410292857798164019061749528550808091180185","best_ask":"0.84","best_bid":"0.83","hash":"74bb3a5de8f288954c53673ea18e017b5ab11b35","price":"0.87","side":"SELL","size":"10"}],"timestamp":"1786845516801"}}
{"f":546,"recv_ms":1786845517013,"raw":{"event_type":"price_change","market":"0xd5f15f31689703aea70b93a52194a0964220d10d92ee7497346f146a8b6ef8ab","price_changes":[{"asset_id":"2151378744569768920256500242561922410292857798164019061749528550808091180185","best_ask":"0.84","best_bid":"0.83","hash":"fbaf572991badc8fc93c53ab5d1324d06bb8224b","price":"0.83","side":"BUY","size":"222.99"},{"asset_id":"17406866367975599232214757606801140480252276357934486651183783311435802862074","best_ask":"0.17","best_bid":"0.16","hash":"879faeeab2434cabe5dfc93691fbc15c6976f6cf","price":"0.17","side":"SELL","size":"222.99"}],"timestamp":"1786845516802"}}
{"f":547,"recv_ms":1786845517018,"raw":{"event_type":"price_change","market":"0xd5f15f31689703aea70b93a52194a0964220d10d92ee7497346f146a8b6ef8ab","price_changes":[{"asset_id":"2151378744569768920256500242561922410292857798164019061749528550808091180185","best_ask":"0.84","best_bid":"0.83","hash":"1cf124d6d8a4749a27e406499aac74077bbcebc5","price":"0.08","side":"BUY","size":"140.29"},{"asset_id":"17406866367975599232214757606801140480252276357934486651183783311435802862074","best_ask":"0.17","best_bid":"0.16","hash":"d97aebaef2739f040113b501ebfac4981e505075","price":"0.92","side":"SELL","size":"140.29"}],"timestamp":"1786845516803"}}
{"f":548,"recv_ms":1786845517019,"raw":{"event_type":"price_change","market":"0xd5f15f31689703aea70b93a52194a0964220d10d92ee7497346f146a8b6ef8ab","price_changes":[{"asset_id":"17406866367975599232214757606801140480252276357934486651183783311435802862074","best_ask":"0.17","best_bid":"0.16","hash":"2d6e4e7bca704207ee0eaa9f4dce9ad4591c689b","price":"0.08","side":"BUY","size":"83.29"},{"asset_id":"2151378744569768920256500242561922410292857798164019061749528550808091180185","best_ask":"0.84","best_bid":"0.83","hash":"4c23843cc881e3ca82992b73b0cb1a3b6ecd8191","price":"0.92","side":"SELL","size":"83.29"}],"timestamp":"1786845516803"}}
{"f":549,"recv_ms":1786845517019,"raw":{"event_type":"price_change","market":"0xd5f15f31689703aea70b93a52194a0964220d10d92ee7497346f146a8b6ef8ab","price_changes":[{"asset_id":"2151378744569768920256500242561922410292857798164019061749528550808091180185","best_ask":"0.84","best_bid":"0.83","hash":"a314e2d62d776b7a247751049c90f8ae96551786","price":"0.14","side":"BUY","size":"111.6"},{"asset_id":"17406866367975599232214757606801140480252276357934486651183783311435802862074","best_ask":"0.17","best_bid":"0.16","hash":"1bff2db9e0602ca566f936dd8401956d44ac435f","price":"0.86","side":"SELL","size":"111.6"}],"timestamp":"1786845516804"}}
{"f":550,"recv_ms":1786845517019,"raw":{"event_type":"price_change","market":"0xd5f15f31689703aea70b93a52194a0964220d10d92ee7497346f146a8b6ef8ab","price_changes":[{"asset_id":"2151378744569768920256500242561922410292857798164019061749528550808091180185","best_ask":"0.84","best_bid":"0.83","hash":"aebe8dca25f79ceab1384479610af14b7200fb34","price":"0.83","side":"BUY","size":"232.99"},{"asset_id":"17406866367975599232214757606801140480252276357934486651183783311435802862074","best_ask":"0.17","best_bid":"0.16","hash":"e4ed8c7dc24cf412bb11fa366f35c5cc4cf5f608","price":"0.17","side":"SELL","size":"232.99"}],"timestamp":"1786845516805"}}
{"f":551,"recv_ms":1786845517019,"raw":{"event_type":"price_change","market":"0xd5f15f31689703aea70b93a52194a0964220d10d92ee7497346f146a8b6ef8ab","price_changes":[{"asset_id":"2151378744569768920256500242561922410292857798164019061749528550808091180185","best_ask":"0.84","best_bid":"0.83","hash":"b2eeaa05c06ec78768b796460f40d12437f52ecf","price":"0.03","side":"BUY","size":"817.3"},{"asset_id":"17406866367975599232214757606801140480252276357934486651183783311435802862074","best_ask":"0.17","best_bid":"0.16","hash":"1097bac7a8c370153f492a0487a0e39820ffabde","price":"0.97","side":"SELL","size":"817.3"}],"timestamp":"1786845516806"}}
{"f":552,"recv_ms":1786845517019,"raw":{"event_type":"price_change","market":"0xd5f15f31689703aea70b93a52194a0964220d10d92ee7497346f146a8b6ef8ab","price_changes":[{"asset_id":"2151378744569768920256500242561922410292857798164019061749528550808091180185","best_ask":"0.84","best_bid":"0.83","hash":"dcf2286c88cfe494f8eb13f32992f92e8017c81f","price":"0.5","side":"BUY","size":"625.4"},{"asset_id":"17406866367975599232214757606801140480252276357934486651183783311435802862074","best_ask":"0.17","best_bid":"0.16","hash":"966de52b233e6b4f5321a1da0c21e90ef5ca5826","price":"0.5","side":"SELL","size":"625.4"}],"timestamp":"1786845516806"}}
{"f":553,"recv_ms":1786845517019,"raw":{"event_type":"price_change","market":"0xd5f15f31689703aea70b93a52194a0964220d10d92ee7497346f146a8b6ef8ab","price_changes":[{"asset_id":"2151378744569768920256500242561922410292857798164019061749528550808091180185","best_ask":"0.84","best_bid":"0.83","hash":"0893c83d0ebe577cf6f646b96e019b3b291c9df2","price":"0.07","side":"BUY","size":"389.9"},{"asset_id":"17406866367975599232214757606801140480252276357934486651183783311435802862074","best_ask":"0.17","best_bid":"0.16","hash":"568774e444ed71abc2fce17cd0b1f84c914e4a9a","price":"0.93","side":"SELL","size":"389.9"}],"timestamp":"1786845516807"}}
{"f":554,"recv_ms":1786845517019,"raw":{"event_type":"price_change","market":"0xd5f15f31689703aea70b93a52194a0964220d10d92ee7497346f146a8b6ef8ab","price_changes":[{"asset_id":"17406866367975599232214757606801140480252276357934486651183783311435802862074","best_ask":"0.17","best_bid":"0.16","hash":"ba2b05fd03ce143925df5292ea5a79b3217fe8cc","price":"0.2","side":"SELL","size":"76"},{"asset_id":"2151378744569768920256500242561922410292857798164019061749528550808091180185","best_ask":"0.84","best_bid":"0.83","hash":"a32115776ea33f3b6bfda8828ab89884e6c0ee1e","price":"0.8","side":"BUY","size":"76"}],"timestamp":"1786845516807"}}
{"f":555,"recv_ms":1786845517019,"raw":{"event_type":"price_change","market":"0xd5f15f31689703aea70b93a52194a0964220d10d92ee7497346f146a8b6ef8ab","price_changes":[{"asset_id":"2151378744569768920256500242561922410292857798164019061749528550808091180185","best_ask":"0.84","best_bid":"0.83","hash":"a32115776ea33f3b6bfda8828ab89884e6c0ee1e","price":"0.8","side":"BUY","size":"76"},{"asset_id":"17406866367975599232214757606801140480252276357934486651183783311435802862074","best_ask":"0.17","best_bid":"0.16","hash":"ba2b05fd03ce143925df5292ea5a79b3217fe8cc","price":"0.2","side":"SELL","size":"76"}],"timestamp":"1786845516807"}}
{"f":556,"recv_ms":1786845517019,"raw":{"event_type":"price_change","market":"0xd5f15f31689703aea70b93a52194a0964220d10d92ee7497346f146a8b6ef8ab","price_changes":[{"asset_id":"2151378744569768920256500242561922410292857798164019061749528550808091180185","best_ask":"0.84","best_bid":"0.83","hash":"e2d80eaf38f2d16295688755e43d79a0776a7de1","price":"0.12","side":"BUY","size":"119.6"},{"asset_id":"17406866367975599232214757606801140480252276357934486651183783311435802862074","best_ask":"0.17","best_bid":"0.16","hash":"c876553aaecdca4b7b3f95bc015a74be48c0e017","price":"0.88","side":"SELL","size":"119.6"}],"timestamp":"1786845516808"}}
{"f":557,"recv_ms":1786845517021,"raw":{"event_type":"price_change","market":"0xd5f15f31689703aea70b93a52194a0964220d10d92ee7497346f146a8b6ef8ab","price_changes":[{"asset_id":"2151378744569768920256500242561922410292857798164019061749528550808091180185","best_ask":"0.84","best_bid":"0.83","hash":"ea977f10fb508948ab4cdc19887ded60c3e22794","price":"0.1","side":"BUY","size":"168.9"},{"asset_id":"17406866367975599232214757606801140480252276357934486651183783311435802862074","best_ask":"0.17","best_bid":"0.16","hash":"9b3075acb3a09099238f40710167ac6eaca84839","price":"0.9","side":"SELL","size":"168.9"}],"timestamp":"1786845516808"}}
{"f":558,"recv_ms":1786845517021,"raw":{"event_type":"price_change","market":"0xd5f15f31689703aea70b93a52194a0964220d10d92ee7497346f146a8b6ef8ab","price_changes":[{"asset_id":"2151378744569768920256500242561922410292857798164019061749528550808091180185","best_ask":"0.84","best_bid":"0.83","hash":"17a0b084d4375022f89438394a21f5b9afc530c0","price":"0.15","side":"BUY","size":"115.39"},{"asset_id":"17406866367975599232214757606801140480252276357934486651183783311435802862074","best_ask":"0.17","best_bid":"0.16","hash":"c6d68a774788a8e875e7ab66e6b5ba89ecd76ba2","price":"0.85","side":"SELL","size":"115.39"}],"timestamp":"1786845516809"}}
{"f":559,"recv_ms":1786845517022,"raw":{"event_type":"price_change","market":"0xd5f15f31689703aea70b93a52194a0964220d10d92ee7497346f146a8b6ef8ab","price_changes":[{"asset_id":"2151378744569768920256500242561922410292857798164019061749528550808091180185","best_ask":"0.84","best_bid":"0.83","hash":"c9c0151c55d35669171e991ec81f8384d667f341","price":"0.17","side":"BUY","size":"103.39"},{"asset_id":"17406866367975599232214757606801140480252276357934486651183783311435802862074","best_ask":"0.17","best_bid":"0.16","hash":"04ed6392dffba98968ffa3ae9d5c235244d4a76f","price":"0.83","side":"SELL","size":"103.39"}],"timestamp":"1786845516810"}}
{"f":560,"recv_ms":1786845517022,"raw":{"event_type":"price_change","market":"0xd5f15f31689703aea70b93a52194a0964220d10d92ee7497346f146a8b6ef8ab","price_changes":[{"asset_id":"2151378744569768920256500242561922410292857798164019061749528550808091180185","best_ask":"0.84","best_bid":"0.83","hash":"b22ce77c0e647b4423f8d9e959b6c036bfa8e936","price":"0.13","side":"BUY","size":"113"},{"asset_id":"17406866367975599232214757606801140480252276357934486651183783311435802862074","best_ask":"0.17","best_bid":"0.16","hash":"99c8bd709a4a8afe3088ec8643f5fd23f402391b","price":"0.87","side":"SELL","size":"113"}],"timestamp":"1786845516810"}}
{"f":561,"recv_ms":1786845517023,"raw":{"event_type":"price_change","market":"0xd5f15f31689703aea70b93a52194a0964220d10d92ee7497346f146a8b6ef8ab","price_changes":[{"asset_id":"2151378744569768920256500242561922410292857798164019061749528550808091180185","best_ask":"0.84","best_bid":"0.83","hash":"0fd780b4b72230b9cbf5e486f211af0270c85722","price":"0.02","side":"BUY","size":"3820.18"},{"asset_id":"17406866367975599232214757606801140480252276357934486651183783311435802862074","best_ask":"0.17","best_bid":"0.16","hash":"159b7aa5e8e7ba486ff95a98bed69c14fba5508c","price":"0.98","side":"SELL","size":"3820.18"}],"timestamp":"1786845516811"}}
{"f":562,"recv_ms":1786845517023,"raw":{"event_type":"price_change","market":"0xd5f15f31689703aea70b93a52194a0964220d10d92ee7497346f146a8b6ef8ab","price_changes":[{"asset_id":"2151378744569768920256500242561922410292857798164019061749528550808091180185","best_ask":"0.84","best_bid":"0.83","hash":"721d4a6578d60fe9cf5850f30be7cd70753e4f7c","price":"0.53","side":"BUY","size":"569.64"},{"asset_id":"17406866367975599232214757606801140480252276357934486651183783311435802862074","best_ask":"0.17","best_bid":"0.16","hash":"9a5426178a0ec4c38733ae8b0eea0926c6936204","price":"0.47","side":"SELL","size":"569.64"}],"timestamp":"1786845516812"}}
{"f":563,"recv_ms":1786845517024,"raw":{"event_type":"price_change","market":"0xd5f15f31689703aea70b93a52194a0964220d10d92ee7497346f146a8b6ef8ab","price_changes":[{"asset_id":"2151378744569768920256500242561922410292857798164019061749528550808091180185","best_ask":"0.84","best_bid":"0.83","hash":"d6d9c3d4fde15a5f29e4ee9bba8cc8894830193f","price":"0.04","side":"BUY","size":"472.7"},{"asset_id":"17406866367975599232214757606801140480252276357934486651183783311435802862074","best_ask":"0.17","best_bid":"0.16","hash":"8b72b653967fa9c88d77fc1ab58a7cf8e9ca6237","price":"0.96","side":"SELL","size":"472.7"}],"timestamp":"1786845516812"}}
{"f":564,"recv_ms":1786845517024,"raw":{"event_type":"price_change","market":"0xd5f15f31689703aea70b93a52194a0964220d10d92ee7497346f146a8b6ef8ab","price_changes":[{"asset_id":"17406866367975599232214757606801140480252276357934486651183783311435802862074","best_ask":"0.17","best_bid":"0.16","hash":"e81783a7146db2f8ee3b9d9d03ab1950151920a1","price":"0.18","side":"SELL","size":"162.44"},{"asset_id":"2151378744569768920256500242561922410292857798164019061749528550808091180185","best_ask":"0.84","best_bid":"0.83","hash":"c97fb6b9eadb5b829d5c327e84d3e600ab32364d","price":"0.82","side":"BUY","size":"162.44"}],"timestamp":"1786845516813"}}
{"f":565,"recv_ms":1786845517025,"raw":{"event_type":"price_change","market":"0xd5f15f31689703aea70b93a52194a0964220d10d92ee7497346f146a8b6ef8ab","price_changes":[{"asset_id":"2151378744569768920256500242561922410292857798164019061749528550808091180185","best_ask":"0.84","best_bid":"0.83","hash":"b9c6893656d88e635c00e36fdeb527980a968ee5","price":"0.09","side":"BUY","size":"136.7"},{"asset_id":"17406866367975599232214757606801140480252276357934486651183783311435802862074","best_ask":"0.17","best_bid":"0.16","hash":"c606b8179717c26860beccc91e88ab4144865548","price":"0.91","side":"SELL","size":"136.7"}],"timestamp":"1786845516814"}}
{"f":566,"recv_ms":1786845517026,"raw":{"event_type":"price_change","market":"0xd5f15f31689703aea70b93a52194a0964220d10d92ee7497346f146a8b6ef8ab","price_changes":[{"asset_id":"17406866367975599232214757606801140480252276357934486651183783311435802862074","best_ask":"0.17","best_bid":"0.16","hash":"d700f4587efd6bd764111139901003ec1e8a644a","price":"0.01","side":"BUY","size":"5578.18"},{"asset_id":"2151378744569768920256500242561922410292857798164019061749528550808091180185","best_ask":"0.84","best_bid":"0.83","hash":"2ea42eee98e0393a26cef757fa8b941c27cb648d","price":"0.99","side":"SELL","size":"5578.18"}],"timestamp":"1786845516815"}}
{"f":567,"recv_ms":1786845517026,"raw":{"event_type":"price_change","market":"0xd5f15f31689703aea70b93a52194a0964220d10d92ee7497346f146a8b6ef8ab","price_changes":[{"asset_id":"2151378744569768920256500242561922410292857798164019061749528550808091180185","best_ask":"0.84","best_bid":"0.83","hash":"2c203b1ee59565bb47d5de1d9252c60572e96984","price":"0.67","side":"BUY","size":"40"},{"asset_id":"17406866367975599232214757606801140480252276357934486651183783311435802862074","best_ask":"0.17","best_bid":"0.16","hash":"be58ad74661e23de595c1a7fd1243487b0939c4f","price":"0.33","side":"SELL","size":"40"}],"timestamp":"1786845516815"}}
{"f":568,"recv_ms":1786845517027,"raw":{"event_type":"price_change","market":"0xd5f15f31689703aea70b93a52194a0964220d10d92ee7497346f146a8b6ef8ab","price_changes":[{"asset_id":"2151378744569768920256500242561922410292857798164019061749528550808091180185","best_ask":"0.84","best_bid":"0.83","hash":"954a3ba9f747667aea3c984152e4bfe4ee30e98a","price":"0.16","side":"BUY","size":"109.3"},{"asset_id":"17406866367975599232214757606801140480252276357934486651183783311435802862074","best_ask":"0.17","best_bid":"0.16","hash":"be47557ee12521ce70fcf36ac392b4de76612299","price":"0.84","side":"SELL","size":"109.3"}],"timestamp":"1786845516816"}}
{"f":569,"recv_ms":1786845517028,"raw":{"event_type":"price_change","market":"0xd5f15f31689703aea70b93a52194a0964220d10d92ee7497346f146a8b6ef8ab","price_changes":[{"asset_id":"2151378744569768920256500242561922410292857798164019061749528550808091180185","best_ask":"0.84","best_bid":"0.83","hash":"1c837bca2ca777add566a262be78e9a5f98c3f87","price":"0.01","side":"BUY","size":"5747.53"},{"asset_id":"17406866367975599232214757606801140480252276357934486651183783311435802862074","best_ask":"0.17","best_bid":"0.16","hash":"0da03676ba57467b493b3892dac67f2732854667","price":"0.99","side":"SELL","size":"5747.53"}],"timestamp":"1786845516816"}}
{"f":570,"recv_ms":1786845517028,"raw":{"event_type":"price_change","market":"0xd5f15f31689703aea70b93a52194a0964220d10d92ee7497346f146a8b6ef8ab","price_changes":[{"asset_id":"17406866367975599232214757606801140480252276357934486651183783311435802862074","best_ask":"0.17","best_bid":"0.16","hash":"eb3732d7aba711291c2c163776890a04a47a9c4f","price":"0.01","side":"BUY","size":"5583.18"},{"asset_id":"2151378744569768920256500242561922410292857798164019061749528550808091180185","best_ask":"0.84","best_bid":"0.83","hash":"1682c6c5c44b5bf84772008289126dde998cafd8","price":"0.99","side":"SELL","size":"5583.18"}],"timestamp":"1786845516817"}}
{"f":571,"recv_ms":1786845517029,"raw":{"event_type":"price_change","market":"0xd5f15f31689703aea70b93a52194a0964220d10d92ee7497346f146a8b6ef8ab","price_changes":[{"asset_id":"2151378744569768920256500242561922410292857798164019061749528550808091180185","best_ask":"0.84","best_bid":"0.83","hash":"19f4515f9fe81fadf6f664144c01953ac3e965c7","price":"0.11","side":"BUY","size":"126.6"},{"asset_id":"17406866367975599232214757606801140480252276357934486651183783311435802862074","best_ask":"0.17","best_bid":"0.16","hash":"883fe343d69c6a80bff756f17535807417ad9784","price":"0.89","side":"SELL","size":"126.6"}],"timestamp":"1786845516817"}}
{"f":572,"recv_ms":1786845517029,"raw":{"event_type":"price_change","market":"0xd5f15f31689703aea70b93a52194a0964220d10d92ee7497346f146a8b6ef8ab","price_changes":[{"asset_id":"2151378744569768920256500242561922410292857798164019061749528550808091180185","best_ask":"0.84","best_bid":"0.83","hash":"aec5387a5ca51d19d26140d92262d89a65acbee9","price":"0.46","side":"BUY","size":"51.5"},{"asset_id":"17406866367975599232214757606801140480252276357934486651183783311435802862074","best_ask":"0.17","best_bid":"0.16","hash":"3985186304b525a0540ae6661396f96fcaad49df","price":"0.54","side":"SELL","size":"51.5"}],"timestamp":"1786845516818"}}
{"f":573,"recv_ms":1786845517031,"raw":{"event_type":"price_change","market":"0xd5f15f31689703aea70b93a52194a0964220d10d92ee7497346f146a8b6ef8ab","price_changes":[{"asset_id":"2151378744569768920256500242561922410292857798164019061749528550808091180185","best_ask":"0.84","best_bid":"0.83","hash":"e1392eb7ee6012309af6df6c073fc1d112af5316","price":"0.01","side":"BUY","size":"5847.53"},{"asset_id":"17406866367975599232214757606801140480252276357934486651183783311435802862074","best_ask":"0.17","best_bid":"0.16","hash":"75953457bed9907c8f6c47814edd25567818516f","price":"0.99","side":"SELL","size":"5847.53"}],"timestamp":"1786845516818"}}
{"f":574,"recv_ms":1786845517031,"raw":{"event_type":"price_change","market":"0xd5f15f31689703aea70b93a52194a0964220d10d92ee7497346f146a8b6ef8ab","price_changes":[{"asset_id":"2151378744569768920256500242561922410292857798164019061749528550808091180185","best_ask":"0.84","best_bid":"0.83","hash":"129f3ca6611abe5133dc61ec9c2d0fc8f5a44bc4","price":"0.01","side":"BUY","size":"5853.53"},{"asset_id":"17406866367975599232214757606801140480252276357934486651183783311435802862074","best_ask":"0.17","best_bid":"0.16","hash":"5b725e2a3b3e3b8b871ff7ae36e0f39b06a16f72","price":"0.99","side":"SELL","size":"5853.53"}],"timestamp":"1786845516819"}}
{"f":575,"recv_ms":1786845517031,"raw":{"event_type":"price_change","market":"0xd5f15f31689703aea70b93a52194a0964220d10d92ee7497346f146a8b6ef8ab","price_changes":[{"asset_id":"2151378744569768920256500242561922410292857798164019061749528550808091180185","best_ask":"0.84","best_bid":"0.83","hash":"57c2d6a9033f1d19eafd7eb1b61d6056d213e8f2","price":"0.55","side":"BUY","size":"149"},{"asset_id":"17406866367975599232214757606801140480252276357934486651183783311435802862074","best_ask":"0.17","best_bid":"0.16","hash":"a7242562f9142be02f3946d9b8e7ea2b8b0e7af5","price":"0.45","side":"SELL","size":"149"}],"timestamp":"1786845516820"}}
{"f":576,"recv_ms":1786845517031,"raw":{"event_type":"price_change","market":"0xd5f15f31689703aea70b93a52194a0964220d10d92ee7497346f146a8b6ef8ab","price_changes":[{"asset_id":"17406866367975599232214757606801140480252276357934486651183783311435802862074","best_ask":"0.17","best_bid":"0.16","hash":"0b4334247b76d54ff96d2a221f969e12ed9542fd","price":"0.01","side":"BUY","size":"5578.18"},{"asset_id":"2151378744569768920256500242561922410292857798164019061749528550808091180185","best_ask":"0.84","best_bid":"0.83","hash":"a0c3be0511b87b1440a2daf2a7dfac8de94f3163","price":"0.99","side":"SELL","size":"5578.18"}],"timestamp":"1786845516820"}}
{"f":577,"recv_ms":1786845517035,"raw":{"event_type":"price_change","market":"0xd5f15f31689703aea70b93a52194a0964220d10d92ee7497346f146a8b6ef8ab","price_changes":[{"asset_id":"2151378744569768920256500242561922410292857798164019061749528550808091180185","best_ask":"0.84","best_bid":"0.83","hash":"d67d1ed96e59d475103ee2a513eb9b83e35ad1d6","price":"0.42","side":"BUY","size":"92.7"},{"asset_id":"17406866367975599232214757606801140480252276357934486651183783311435802862074","best_ask":"0.17","best_bid":"0.16","hash":"d7d7f36b574d6d713c6ae6fc51a4ba8294c48904","price":"0.58","side":"SELL","size":"92.7"}],"timestamp":"1786845516821"}}
{"f":578,"recv_ms":1786845517036,"raw":{"event_type":"price_change","market":"0xd5f15f31689703aea70b93a52194a0964220d10d92ee7497346f146a8b6ef8ab","price_changes":[{"asset_id":"2151378744569768920256500242561922410292857798164019061749528550808091180185","best_ask":"0.84","best_bid":"0.83","hash":"20e555ebfdcaa2868cdd2bffe3e515ac3a2a158f","price":"0.47","side":"BUY","size":"51.4"},{"asset_id":"17406866367975599232214757606801140480252276357934486651183783311435802862074","best_ask":"0.17","best_bid":"0.16","hash":"966b9c0b0c2c3a5beb090c75a3c02ad75fd4e4d2","price":"0.53","side":"SELL","size":"51.4"}],"timestamp":"1786845516821"}}
{"f":579,"recv_ms":1786845517036,"raw":{"event_type":"price_change","market":"0xd5f15f31689703aea70b93a52194a0964220d10d92ee7497346f146a8b6ef8ab","price_changes":[{"asset_id":"2151378744569768920256500242561922410292857798164019061749528550808091180185","best_ask":"0.84","best_bid":"0.83","hash":"91628a2d0bd8437ae2be4a27c8a4c8e209126414","price":"0.44","side":"BUY","size":"123.6"},{"asset_id":"17406866367975599232214757606801140480252276357934486651183783311435802862074","best_ask":"0.17","best_bid":"0.16","hash":"b4a6789eb1eef927a52a0460aaf2e64368d53930","price":"0.56","side":"SELL","size":"123.6"}],"timestamp":"1786845516822"}}
{"f":580,"recv_ms":1786845517036,"raw":{"event_type":"price_change","market":"0xd5f15f31689703aea70b93a52194a0964220d10d92ee7497346f146a8b6ef8ab","price_changes":[{"asset_id":"2151378744569768920256500242561922410292857798164019061749528550808091180185","best_ask":"0.84","best_bid":"0.83","hash":"e8f7990e04c155815a4a2a0d4a1fdefef815543a","price":"0.48","side":"BUY","size":"50.4"},{"asset_id":"17406866367975599232214757606801140480252276357934486651183783311435802862074","best_ask":"0.17","best_bid":"0.16","hash":"ea9b9dc0cfce5160004110ff95fc77a03c9d38dd","price":"0.52","side":"SELL","size":"50.4"}],"timestamp":"1786845516823"}}
{"f":581,"recv_ms":1786845517036,"raw":{"event_type":"price_change","market":"0xd5f15f31689703aea70b93a52194a0964220d10d92ee7497346f146a8b6ef8ab","price_changes":[{"asset_id":"2151378744569768920256500242561922410292857798164019061749528550808091180185","best_ask":"0.84","best_bid":"0.83","hash":"3e75de5b12ce3acdad2984e1154052fba141b507","price":"0.45","side":"BUY","size":"51.5"},{"asset_id":"17406866367975599232214757606801140480252276357934486651183783311435802862074","best_ask":"0.17","best_bid":"0.16","hash":"639dfc74a208744ca8f2066bbe10e412d4d214a7","price":"0.55","side":"SELL","size":"51.5"}],"timestamp":"1786845516824"}}
{"f":582,"recv_ms":1786845517036,"raw":{"event_type":"price_change","market":"0xd5f15f31689703aea70b93a52194a0964220d10d92ee7497346f146a8b6ef8ab","price_changes":[{"asset_id":"17406866367975599232214757606801140480252276357934486651183783311435802862074","best_ask":"0.17","best_bid":"0.16","hash":"4ee6fef2b5ee4a7acd8a1716317e606f2769bc7c","price":"0.01","side":"BUY","size":"5583.18"},{"asset_id":"2151378744569768920256500242561922410292857798164019061749528550808091180185","best_ask":"0.84","best_bid":"0.83","hash":"8f57dd368309dc586af3c7d37aef48357acaea4c","price":"0.99","side":"SELL","size":"5583.18"}],"timestamp":"1786845516824"}}
{"f":583,"recv_ms":1786845517038,"raw":{"event_type":"price_change","market":"0xd5f15f31689703aea70b93a52194a0964220d10d92ee7497346f146a8b6ef8ab","price_changes":[{"asset_id":"2151378744569768920256500242561922410292857798164019061749528550808091180185","best_ask":"0.84","best_bid":"0.83","hash":"eea3074bac354694463ab96100fff6408e280e7d","price":"0.43","side":"BUY","size":"92.6"},{"asset_id":"17406866367975599232214757606801140480252276357934486651183783311435802862074","best_ask":"0.17","best_bid":"0.16","hash":"e27373120c495d2f0b5831946c17591a1c4cfb4d","price":"0.57","side":"SELL","size":"92.6"}],"timestamp":"1786845516825"}}
{"f":584,"recv_ms":1786845517038,"raw":{"event_type":"price_change","market":"0xd5f15f31689703aea70b93a52194a0964220d10d92ee7497346f146a8b6ef8ab","price_changes":[{"asset_id":"2151378744569768920256500242561922410292857798164019061749528550808091180185","best_ask":"0.84","best_bid":"0.83","hash":"99896bc33a9334c3e91765fea1ce0b231d2c1ce2","price":"0.82","side":"BUY","size":"112.44"},{"asset_id":"17406866367975599232214757606801140480252276357934486651183783311435802862074","best_ask":"0.17","best_bid":"0.16","hash":"302307e752ea60391402d0e71b4c833a48791047","price":"0.18","side":"SELL","size":"112.44"}],"timestamp":"1786845516826"}}
{"f":585,"recv_ms":1786845517039,"raw":{"event_type":"price_change","market":"0xd5f15f31689703aea70b93a52194a0964220d10d92ee7497346f146a8b6ef8ab","price_changes":[{"asset_id":"2151378744569768920256500242561922410292857798164019061749528550808091180185","best_ask":"0.84","best_bid":"0.83","hash":"c23dae90ae7088ceb668840ae292332471e5f50b","price":"0.49","side":"BUY","size":"50.4"},{"asset_id":"17406866367975599232214757606801140480252276357934486651183783311435802862074","best_ask":"0.17","best_bid":"0.16","hash":"82d405dd99657481135d591fd82dd4c0bed5e605","price":"0.51","side":"SELL","size":"50.4"}],"timestamp":"1786845516826"}}
{"f":586,"recv_ms":1786845517039,"raw":{"event_type":"price_change","market":"0xd5f15f31689703aea70b93a52194a0964220d10d92ee7497346f146a8b6ef8ab","price_changes":[{"asset_id":"17406866367975599232214757606801140480252276357934486651183783311435802862074","best_ask":"0.17","best_bid":"0.16","hash":"510e17f3f57933ab61d650408746bcd71eb281f6","price":"0.11","side":"BUY","size":"40"},{"asset_id":"2151378744569768920256500242561922410292857798164019061749528550808091180185","best_ask":"0.84","best_bid":"0.83","hash":"288cc225fa8ad0e844587c7b615df46fd53cd3cd","price":"0.89","side":"SELL","size":"40"}],"timestamp":"1786845516827"}}
{"f":587,"recv_ms":1786845517048,"raw":{"event_type":"price_change","market":"0xd5f15f31689703aea70b93a52194a0964220d10d92ee7497346f146a8b6ef8ab","price_changes":[{"asset_id":"2151378744569768920256500242561922410292857798164019061749528550808091180185","best_ask":"0.84","best_bid":"0.83","hash":"aec07fb096b958e4325fdcf790ae5273ffb753d7","price":"0.83","side":"BUY","size":"282.99"},{"asset_id":"17406866367975599232214757606801140480252276357934486651183783311435802862074","best_ask":"0.17","best_bid":"0.16","hash":"43b1541b025b45bad000f2aabfa3a5d9ec490884","price":"0.17","side":"SELL","size":"282.99"}],"timestamp":"1786845516828"}}
