{"f":588,"recv_ms":1786845517048,"raw":{"event_type":"price_change","market":"0xd5f15f31689703aea70b93a52194a0964220d10d92ee7497346f146a8b6ef8ab","price_changes":[{"asset_id":"2151378744569768920256500242561922410292857798164019061749528550808091180185","best_ask":"0.84","best_bid":"0.83","hash":"26a31583691562bd35c38fd2aa3945bb9fca15ed","price":"0.5","side":"BUY","size":"655.4"},{"asset_id":"17406866367975599232214757606801140480252276357934486651183783311435802862074","best_ask":"0.17","best_bid":"0.16","hash":"02082b64adefd5f8ad5a3cde89286dd2d60c3fcb","price":"0.5","side":"SELL","size":"655.4"}],"timestamp":"1786845516829"}}
{"f":589,"recv_ms":1786845517053,"raw":{"event_type":"price_change","market":"0xd5f15f31689703aea70b93a52194a0964220d10d92ee7497346f146a8b6ef8ab","price_changes":[{"asset_id":"17406866367975599232214757606801140480252276357934486651183783311435802862074","best_ask":"0.17","best_bid":"0.16","hash":"3e2b44325909463f5b2c3b2f4507284ddc930809","price":"0.08","side":"BUY","size":"70.29"},{"asset_id":"2151378744569768920256500242561922410292857798164019061749528550808091180185","best_ask":"0.84","best_bid":"0.83","hash":"0364e896fa00905fc35aa1d027f3988ef1917b17","price":"0.92","side":"SELL","size":"70.29"}],"timestamp":"1786845516837"}}
{"f":590,"recv_ms":1786845517054,"raw":{"event_type":"price_change","market":"0xd5f15f31689703aea70b93a52194a0964220d10d92ee7497346f146a8b6ef8ab","price_changes":[{"asset_id":"2151378744569768920256500242561922410292857798164019061749528550808091180185","best_ask":"0.84","best_bid":"0.83","hash":"dae47d1ca423a5ebbda0e70ccb40e0c0405fd679","price":"0.82","side":"BUY","size":"117.61"},{"asset_id":"17406866367975599232214757606801140480252276357934486651183783311435802862074","best_ask":"0.17","best_bid":"0.16","hash":"f8fba32e75f03ec044d0528ec3be6fc826f523b9","price":"0.18","side":"SELL","size":"117.61"}],"timestamp":"1786845516842"}}
{"f":591,"recv_ms":1786845517062,"raw":{"event_type":"price_change","market":"0xd5f15f31689703aea70b93a52194a0964220d10d92ee7497346f146a8b6ef8ab","price_changes":[{"asset_id":"2151378744569768920256500242561922410292857798164019061749528550808091180185","best_ask":"0.84","best_bid":"0.83","hash":"3354f4f4f226ef6e92022a6d489b1f7597478685","price":"0.01","side":"BUY","size":"5847.53"},{"asset_id":"17406866367975599232214757606801140480252276357934486651183783311435802862074","best_ask":"0.17","best_bid":"0.16","hash":"a516034cb4b026c4ff445670e66e5b1141748a76","price":"0.99","side":"SELL","size":"5847.53"}],"timestamp":"1786845516843"}}
{"f":592,"recv_ms":1786845517062,"raw":{"event_type":"price_change","market":"0xd5f15f31689703aea70b93a52194a0964220d10d92ee7497346f146a8b6ef8ab","price_changes":[{"asset_id":"2151378744569768920256500242561922410292857798164019061749528550808091180185","best_ask":"0.84","best_bid":"0.83","hash":"551854fb13fdc9594a8e1a0280b4767f2c9a1641","price":"0.01","side":"BUY","size":"5852.53"},{"asset_id":"17406866367975599232214757606801140480252276357934486651183783311435802862074","best_ask":"0.17","best_bid":"0.16","hash":"458505fc746eb9ab79821d532946a258c3e284a9","price":"0.99","side":"SELL","size":"5852.53"}],"timestamp":"1786845516845"}}
{"f":593,"recv_ms":1786845517083,"raw":{"event_type":"price_change","market":"0xd5f15f31689703aea70b93a52194a0964220d10d92ee7497346f146a8b6ef8ab","price_changes":[{"asset_id":"2151378744569768920256500242561922410292857798164019061749528550808091180185","best_ask":"0.84","best_bid":"0.83","hash":"d64480e3eacf485de302200e202723b0591a8a33","price":"0.01","side":"BUY","size":"5752.53"},{"asset_id":"17406866367975599232214757606801140480252276357934486651183783311435802862074","best_ask":"0.17","best_bid":"0.16","hash":"253b503bdb7136ac7074f4a608f44b8f93556d8c","price":"0.99","side":"SELL","size":"5752.53"}],"timestamp":"1786845516851"}}
{"f":594,"recv_ms":1786845517083,"raw":{"event_type":"price_change","market":"0xd5f15f31689703aea70b93a52194a0964220d10d92ee7497346f146a8b6ef8ab","price_changes":[{"asset_id":"2151378744569768920256500242561922410292857798164019061749528550808091180185","best_ask":"0.84","best_bid":"0.83","hash":"7b5eabe0e0d4e30fe92690e77ebbbd4bf55b399a","price":"0.7","side":"BUY","size":"40"},{"asset_id":"17406866367975599232214757606801140480252276357934486651183783311435802862074","best_ask":"0.17","best_bid":"0.16","hash":"e11a5fd31775435aca8c36e43cd0b1df19ab0838","price":"0.3","side":"SELL","size":"40"}],"timestamp":"1786845516852"}}
{"f":595,"recv_ms":1786845517088,"raw":{"event_type":"price_change","market":"0xd5f15f31689703aea70b93a52194a0964220d10d92ee7497346f146a8b6ef8ab","price_changes":[{"asset_id":"2151378744569768920256500242561922410292857798164019061749528550808091180185","best_ask":"0.84","best_bid":"0.83","hash":"8fb2f8950b531851e9a4ab22470ed431232c802c","price":"0.01","side":"BUY","size":"5747.53"},{"asset_id":"17406866367975599232214757606801140480252276357934486651183783311435802862074","best_ask":"0.17","best_bid":"0.16","hash":"12cbbd71f6a0a234528858698a7019eae6def590","price":"0.99","side":"SELL","size":"5747.53"}],"timestamp":"1786845516872"}}
{"f":596,"recv_ms":1786845517108,"raw":{"event_type":"price_change","market":"0xd5f15f31689703aea70b93a52194a0964220d10d92ee7497346f146a8b6ef8ab","price_changes":[{"asset_id":"2151378744569768920256500242561922410292857798164019061749528550808091180185","best_ask":"0.84","best_bid":"0.83","hash":"4d7470e4635f725c10cead26ce81f387e3699a03","price":"0.52","side":"BUY","size":"40"},{"asset_id":"17406866367975599232214757606801140480252276357934486651183783311435802862074","best_ask":"0.17","best_bid":"0.16","hash":"ca412b051919e4d66daa6d0ff223cbc35648aff2","price":"0.48","side":"SELL","size":"40"}],"timestamp":"1786845516877"}}
{"f":597,"recv_ms":1786845517109,"raw":{"event_type":"price_change","market":"0xd5f15f31689703aea70b93a52194a0964220d10d92ee7497346f146a8b6ef8ab","price_changes":[{"asset_id":"2151378744569768920256500242561922410292857798164019061749528550808091180185","best_ask":"0.84","best_bid":"0.83","hash":"7cb39653301a996edad602bd8e188c9337c74f3b","price":"0.53","side":"BUY","size":"669.64"},{"asset_id":"17406866367975599232214757606801140480252276357934486651183783311435802862074","best_ask":"0.17","best_bid":"0.16","hash":"c4cc92e6fa21b111e8d728de09a99ea203a8af1f","price":"0.47","side":"SELL","size":"669.64"}],"timestamp":"1786845516878"}}
{"f":598,"recv_ms":1786845517111,"raw":{"event_type":"price_change","market":"0xd5f15f31689703aea70b93a52194a0964220d10d92ee7497346f146a8b6ef8ab","price_changes":[{"asset_id":"2151378744569768920256500242561922410292857798164019061749528550808091180185","best_ask":"0.84","best_bid":"0.83","hash":"c744949e5af3064710f7d33eac0ba031ac2c3631","price":"0.01","side":"BUY","size":"5847.53"},{"asset_id":"17406866367975599232214757606801140480252276357934486651183783311435802862074","best_ask":"0.17","best_bid":"0.16","hash":"a506aa6bedcd049e6b32552427f7bb62ab282e7c","price":"0.99","side":"SELL","size":"5847.53"}],"timestamp":"1786845516893"}}
{"f":599,"recv_ms":1786845517129,"raw":{"asset_id":"2151378744569768920256500242561922410292857798164019061749528550808091180185","event_type":"last_trade_price","fee_rate_bps":"0","market":"0xd5f15f31689703aea70b93a52194a0964220d10d92ee7497346f146a8b6ef8ab","price":"0.83","side":"BUY","size":"9.07","timestamp":"1786845516886","transaction_hash":"0x861cf8cd571e429981325f5be89e929f6bc1a4c33406f9d4bb12ee6d0ad6c2ff"}}
{"f":600,"recv_ms":1786845517129,"raw":{"event_type":"price_change","market":"0xd5f15f31689703aea70b93a52194a0964220d10d92ee7497346f146a8b6ef8ab","price_changes":[{"asset_id":"17406866367975599232214757606801140480252276357934486651183783311435802862074","best_ask":"0.17","best_bid":"0.16","hash":"c85bbc1ec1d4859a64a950ebd765c10f379148ec","price":"0.01","side":"BUY","size":"5683.18"},{"asset_id":"2151378744569768920256500242561922410292857798164019061749528550808091180185","best_ask":"0.84","best_bid":"0.83","hash":"aadf1fa8b091e05646fd3970cff54b1f2c4c23cb","price":"0.99","side":"SELL","size":"5683.18"}],"timestamp":"1786845516917"}}
{"f":601,"recv_ms":1786845517131,"raw":{"event_type":"price_change","market":"0xd5f15f31689703aea70b93a52194a0964220d10d92ee7497346f146a8b6ef8ab","price_changes":[{"asset_id":"2151378744569768920256500242561922410292857798164019061749528550808091180185","best_ask":"0.84","best_bid":"0.83","hash":"f565433b2a50325450be573c74759256dd620e89","price":"0.01","side":"BUY","size":"5852.53"},{"asset_id":"17406866367975599232214757606801140480252276357934486651183783311435802862074","best_ask":"0.17","best_bid":"0.16","hash":"5703eebdfc52ce79a795bbbfa5d455b885a32082","price":"0.99","side":"SELL","size":"5852.53"}],"timestamp":"1786845516918"}}
{"f":602,"recv_ms":1786845517131,"raw":{"event_type":"price_change","market":"0xd5f15f31689703aea70b93a52194a0964220d10d92ee7497346f146a8b6ef8ab","price_changes":[{"asset_id":"2151378744569768920256500242561922410292857798164019061749528550808091180185","best_ask":"0.84","best_bid":"0.83","hash":"9bfe6968ffc7c02dd310e3171dd77192fe881cb0","price":"0.01","side":"BUY","size":"5857.53"},{"asset_id":"17406866367975599232214757606801140480252276357934486651183783311435802862074","best_ask":"0.17","best_bid":"0.16","hash":"42db5e62d848e7409031d5b8817e956a14fee21a","price":"0.99","side":"SELL","size":"5857.53"}],"timestamp":"1786845516919"}}
{"f":603,"recv_ms":1786845517131,"raw":{"event_type":"price_change","market":"0xd5f15f31689703aea70b93a52194a0964220d10d92ee7497346f146a8b6ef8ab","price_changes":[{"asset_id":"2151378744569768920256500242561922410292857798164019061749528550808091180185","best_ask":"0.84","best_bid":"0.83","hash":"a43b711d7f6583a286822d3c57cc5071ea4e7e58","price":"0.01","side":"BUY","size":"5863.53"},{"asset_id":"17406866367975599232214757606801140480252276357934486651183783311435802862074","best_ask":"0.17","best_bid":"0.16","hash":"9287700777821467a8e2a0b061759d18010fda27","price":"0.99","side":"SELL","size":"5863.53"}],"timestamp":"1786845516919"}}
{"f":604,"recv_ms":1786845517131,"raw":{"event_type":"price_change","market":"0xd5f15f31689703aea70b93a52194a0964220d10d92ee7497346f146a8b6ef8ab","price_changes":[{"asset_id":"2151378744569768920256500242561922410292857798164019061749528550808091180185","best_ask":"0.84","best_bid":"0.83","hash":"8f202f090d5d610dbc7b74928c1d60d7f1ebf84e","price":"0.01","side":"BUY","size":"5868.53"},{"asset_id":"17406866367975599232214757606801140480252276357934486651183783311435802862074","best_ask":"0.17","best_bid":"0.16","hash":"2c5f4899d84aea40cfbe2173ebcdbc70e6b89447","price":"0.99","side":"SELL","size":"5868.53"}],"timestamp":"1786845516920"}}
{"f":605,"recv_ms":1786845517140,"raw":{"event_type":"price_change","market":"0xd5f15f31689703aea70b93a52194a0964220d10d92ee7497346f146a8b6ef8ab","price_changes":[{"asset_id":"2151378744569768920256500242561922410292857798164019061749528550808091180185","best_ask":"0.84","best_bid":"0.83","hash":"a9638367a838862184e599a824ad49eb311f91d9","price":"0.76","side":"BUY","size":"100"},{"asset_id":"17406866367975599232214757606801140480252276357934486651183783311435802862074","best_ask":"0.17","best_bid":"0.16","hash":"a468a6359aa7f6457f263547fac31e97fbda0957","price":"0.24","side":"SELL","size":"100"}],"timestamp":"1786845516921"}}
{"f":606,"recv_ms":1786845517148,"raw":{"event_type":"price_change","market":"0xd5f15f31689703aea70b93a52194a0964220d10d92ee7497346f146a8b6ef8ab","price_changes":[{"asset_id":"2151378744569768920256500242561922410292857798164019061749528550808091180185","best_ask":"0.84","best_bid":"0.83","hash":"bcf610e6239f420eeacf4ffdff51d0c043a61828","price":"0.01","side":"BUY","size":"5768.53"},{"asset_id":"17406866367975599232214757606801140480252276357934486651183783311435802862074","best_ask":"0.17","best_bid":"0.16","hash":"8d23fb5a39faf752a5be2b5c5188fbbfd017cdae","price":"0.99","side":"SELL","size":"5768.53"}],"timestamp":"1786845516936"}}
{"f":607,"recv_ms":1786845517163,"raw":{"event_type":"price_change","market":"0xd5f15f31689703aea70b93a52194a0964220d10d92ee7497346f146a8b6ef8ab","price_changes":[{"asset_id":"2151378744569768920256500242561922410292857798164019061749528550808091180185","best_ask":"0.84","best_bid":"0.83","hash":"b52519c5c6cf202a94c7b38f2c7172a5f4cabcd3","price":"0.8","side":"BUY","size":"66"},{"asset_id":"17406866367975599232214757606801140480252276357934486651183783311435802862074","best_ask":"0.17","best_bid":"0.16","hash":"4799b15043b7880519dcb786d59df527911fadcc","price":"0.2","side":"SELL","size":"66"}],"timestamp":"1786845516937"}}
{"f":608,"recv_ms":1786845517163,"raw":{"event_type":"price_change","market":"0xd5f15f31689703aea70b93a52194a0964220d10d92ee7497346f146a8b6ef8ab","price_changes":[{"asset_id":"2151378744569768920256500242561922410292857798164019061749528550808091180185","best_ask":"0.84","best_bid":"0.83","hash":"97de4f96338fbe67acb8512bcd658682f5fc4d74","price":"0.01","side":"BUY","size":"5762.53"},{"asset_id":"17406866367975599232214757606801140480252276357934486651183783311435802862074","best_ask":"0.17","best_bid":"0.16","hash":"e34112037fbcec31c222123e4e7ba7f8615c0a7d","price":"0.99","side":"SELL","size":"5762.53"}],"timestamp":"1786845516944"}}
{"f":609,"recv_ms":1786845517170,"raw":{"event_type":"price_change","market":"0xd5f15f31689703aea70b93a52194a0964220d10d92ee7497346f146a8b6ef8ab","price_changes":[{"asset_id":"2151378744569768920256500242561922410292857798164019061749528550808091180185","best_ask":"0.84","best_bid":"0.83","hash":"c78076a64f9b0a6e7db8ccf979359080ed6834ae","price":"0.01","side":"BUY","size":"5767.54"},{"asset_id":"17406866367975599232214757606801140480252276357934486651183783311435802862074","best_ask":"0.17","best_bid":"0.16","hash":"c76c4471ae53ef9bc4398c3e6aa2f4d307d7d888","price":"0.99","side":"SELL","size":"5767.54"}],"timestamp":"1786845516952"}}
{"f":610,"recv_ms":1786845517170,"raw":{"event_type":"price_change","market":"0xd5f15f31689703aea70b93a52194a0964220d10d92ee7497346f146a8b6ef8ab","price_changes":[{"asset_id":"2151378744569768920256500242561922410292857798164019061749528550808091180185","best_ask":"0.84","best_bid":"0.83","hash":"dae524999d3e8ae15e110812b95eac7897688391","price":"0.01","side":"BUY","size":"5762.54"},{"asset_id":"17406866367975599232214757606801140480252276357934486651183783311435802862074","best_ask":"0.17","best_bid":"0.16","hash":"f4775fcb7868310c033aa1a607b71b3817243584","price":"0.99","side":"SELL","size":"5762.54"}],"timestamp":"1786845516953"}}
{"f":611,"recv_ms":1786845517187,"raw":{"event_type":"price_change","market":"0xd5f15f31689703aea70b93a52194a0964220d10d92ee7497346f146a8b6ef8ab","price_changes":[{"asset_id":"2151378744569768920256500242561922410292857798164019061749528550808091180185","best_ask":"0.84","best_bid":"0.83","hash":"cb092f29118c301756e1b6c5d17035ac149f414b","price":"0.01","side":"BUY","size":"5862.54"},{"asset_id":"17406866367975599232214757606801140480252276357934486651183783311435802862074","best_ask":"0.17","best_bid":"0.16","hash":"07ceca629a74fe455cdecdea47a7d61081af1322","price":"0.99","side":"SELL","size":"5862.54"}],"timestamp":"1786845516973"}}
{"f":612,"recv_ms":1786845517197,"raw":{"event_type":"price_change","market":"0xd5f15f31689703aea70b93a52194a0964220d10d92ee7497346f146a8b6ef8ab","price_changes":[{"asset_id":"2151378744569768920256500242561922410292857798164019061749528550808091180185","best_ask":"0.84","best_bid":"0.83","hash":"1e1574a963c2e533b089a06a23952de2f320d8a3","price":"0.83","side":"BUY","size":"292.99"},{"asset_id":"17406866367975599232214757606801140480252276357934486651183783311435802862074","best_ask":"0.17","best_bid":"0.16","hash":"2cc2660ecfef66dad6cdba6f30ee99bf6a4ac4cb","price":"0.17","side":"SELL","size":"292.99"}],"timestamp":"1786845516975"}}
{"f":613,"recv_ms":1786845517197,"raw":{"event_type":"price_change","market":"0xd5f15f31689703aea70b93a52194a0964220d10d92ee7497346f146a8b6ef8ab","price_changes":[{"asset_id":"2151378744569768920256500242561922410292857798164019061749528550808091180185","best_ask":"0.84","best_bid":"0.83","hash":"76add5fa59f737fc7b349be2a0e0c984abad7253","price":"0.01","side":"BUY","size":"5857.53"},{"asset_id":"17406866367975599232214757606801140480252276357934486651183783311435802862074","best_ask":"0.17","best_bid":"0.16","hash":"9b26c5210f6f7e2f16089f6bccaab688fa3d9cf6","price":"0.99","side":"SELL","size":"5857.53"}],"timestamp":"1786845516979"}}
{"f":614,"recv_ms":1786845517199,"raw":{"event_type":"price_change","market":"0xd5f15f31689703aea70b93a52194a0964220d10d92ee7497346f146a8b6ef8ab","price_changes":[{"asset_id":"2151378744569768920256500242561922410292857798164019061749528550808091180185","best_ask":"0.84","best_bid":"0.83","hash":"56e7c4ed0996f94af918df31274b451abad3d43f","price":"0.01","side":"BUY","size":"5852.53"},{"asset_id":"17406866367975599232214757606801140480252276357934486651183783311435802862074","best_ask":"0.17","best_bid":"0.16","hash":"7f8b9113a05561049bc1bbfe804f63978d8760fb","price":"0.99","side":"SELL","size":"5852.53"}],"timestamp":"1786845516986"}}
{"f":615,"recv_ms":1786845517230,"raw":{"event_type":"price_change","market":"0xd5f15f31689703aea70b93a52194a0964220d10d92ee7497346f146a8b6ef8ab","price_changes":[{"asset_id":"2151378744569768920256500242561922410292857798164019061749528550808091180185","best_ask":"0.84","best_bid":"0.83","hash":"cef59971d7de5212576ee1162126d067b0ff31bd","price":"0.01","side":"BUY","size":"5858.53"},{"asset_id":"17406866367975599232214757606801140480252276357934486651183783311435802862074","best_ask":"0.17","best_bid":"0.16","hash":"fbb739899b70497c47739e4e6ede4ad498756bc8","price":"0.99","side":"SELL","size":"5858.53"}],"timestamp":"1786845517014"}}
{"f":616,"recv_ms":1786845517231,"raw":{"event_type":"price_change","market":"0xd5f15f31689703aea70b93a52194a0964220d10d92ee7497346f146a8b6ef8ab","price_changes":[{"asset_id":"2151378744569768920256500242561922410292857798164019061749528550808091180185","best_ask":"0.84","best_bid":"0.83","hash":"8d2466268531436df0118e9a5d339b9b813c53ce","price":"0.01","side":"BUY","size":"5758.53"},{"asset_id":"17406866367975599232214757606801140480252276357934486651183783311435802862074","best_ask":"0.17","best_bid":"0.16","hash":"2260332ac31ce9b186df0c46386a774a2836b08d","price":"0.99","side":"SELL","size":"5758.53"}],"timestamp":"1786845517017"}}
{"f":617,"recv_ms":1786845517245,"raw":{"event_type":"price_change","market":"0xd5f15f31689703aea70b93a52194a0964220d10d92ee7497346f146a8b6ef8ab","price_changes":[{"asset_id":"2151378744569768920256500242561922410292857798164019061749528550808091180185","best_ask":"0.84","best_bid":"0.83","hash":"9ef36c5087ec3d358970ca4fe24dc6b24889d309","price":"0.01","side":"BUY","size":"5763.53"},{"asset_id":"17406866367975599232214757606801140480252276357934486651183783311435802862074","best_ask":"0.17","best_bid":"0.16","hash":"a14aedff2343b73d5daf40b281fcf9e8b69bbd11","price":"0.99","side":"SELL","size":"5763.53"}],"timestamp":"1786845517019"}}
{"f":618,"recv_ms":1786845517245,"raw":{"event_type":"price_change","market":"0xd5f15f31689703aea70b93a52194a0964220d10d92ee7497346f146a8b6ef8ab","price_changes":[{"asset_id":"17406866367975599232214757606801140480252276357934486651183783311435802862074","best_ask":"0.17","best_bid":"0.16","hash":"f4adb3576fbf38ca1ef5b688958655a6d09dbb29","price":"0.01","side":"BUY","size":"5688.18"},{"asset_id":"2151378744569768920256500242561922410292857798164019061749528550808091180185","best_ask":"0.84","best_bid":"0.83","hash":"58c5034573b395aebdf53f8f1f77aa5341d20925","price":"0.99","side":"SELL","size":"5688.18"}],"timestamp":"1786845517020"}}
{"f":619,"recv_ms":1786845517254,"raw":{"event_type":"price_change","market":"0xd5f15f31689703aea70b93a52194a0964220d10d92ee7497346f146a8b6ef8ab","price_changes":[{"asset_id":"17406866367975599232214757606801140480252276357934486651183783311435802862074","best_ask":"0.17","best_bid":"0.16","hash":"93ada9420125b408ed5cfa2e3384e1a3b80ae77a","price":"0.01","side":"BUY","size":"5693.18"},{"asset_id":"2151378744569768920256500242561922410292857798164019061749528550808091180185","best_ask":"0.84","best_bid":"0.83","hash":"258ec9c48e7304fb374ae7c158f733b22ce9193f","price":"0.99","side":"SELL","size":"5693.18"}],"timestamp":"1786845517025"}}
{"f":620,"recv_ms":1786845517254,"raw":{"event_type":"price_change","market":"0xd5f15f31689703aea70b93a52194a0964220d10d92ee7497346f146a8b6ef8ab","price_changes":[{"asset_id":"2151378744569768920256500242561922410292857798164019061749528550808091180185","best_ask":"0.84","best_bid":"0.83","hash":"c44c370cc1ba583abcef5d5eaed547f4f7b04ecb","price":"0.01","side":"BUY","size":"5758.53"},{"asset_id":"17406866367975599232214757606801140480252276357934486651183783311435802862074","best_ask":"0.17","best_bid":"0.16","hash":"15c581a3c0bcc8dda3bc7d3bc0fdc61eb0d68ee1","price":"0.99","side":"SELL","size":"5758.53"}],"timestamp":"1786845517025"}}
{"f":621,"recv_ms":1786845517254,"raw":{"event_type":"price_change","market":"0xd5f15f31689703aea70b93a52194a0964220d10d92ee7497346f146a8b6ef8ab","price_changes":[{"asset_id":"2151378744569768920256500242561922410292857798164019061749528550808091180185","best_ask":"0.84","best_bid":"0.83","hash":"a3f4304e3aafe15999a564821560ffd1ea3d2aae","price":"0.01","side":"BUY","size":"5753.53"},{"asset_id":"17406866367975599232214757606801140480252276357934486651183783311435802862074","best_ask":"0.17","best_bid":"0.16","hash":"0472acea8671dff12663386f462f213761ddf025","price":"0.99","side":"SELL","size":"5753.53"}],"timestamp":"1786845517038"}}
{"f":622,"recv_ms":1786845517255,"raw":{"event_type":"price_change","market":"0xd5f15f31689703aea70b93a52194a0964220d10d92ee7497346f146a8b6ef8ab","price_changes":[{"asset_id":"2151378744569768920256500242561922410292857798164019061749528550808091180185","best_ask":"0.84","best_bid":"0.83","hash":"720bc4b52ccda04316c2f26014f5af57f4f24e77","price":"0.75","side":"BUY","size":"71.9"},{"asset_id":"17406866367975599232214757606801140480252276357934486651183783311435802862074","best_ask":"0.17","best_bid":"0.16","hash":"4aad440a48ab7156baad0f7ea151205225c214a3","price":"0.25","side":"SELL","size":"71.9"}],"timestamp":"1786845517040"}}
{"f":623,"recv_ms":1786845517255,"raw":{"event_type":"price_change","market":"0xd5f15f31689703aea70b93a52194a0964220d10d92ee7497346f146a8b6ef8ab","price_changes":[{"asset_id":"2151378744569768920256500242561922410292857798164019061749528550808091180185","best_ask":"0.84","best_bid":"0.83","hash":"5f3619386957b792f6ca60837e95be6c0a6186f8","price":"0.01","side":"BUY","size":"5748.53"},{"asset_id":"17406866367975599232214757606801140480252276357934486651183783311435802862074","best_ask":"0.17","best_bid":"0.16","hash":"625e5128d101163e7756efdda2dfa796fbf53ddb","price":"0.99","side":"SELL","size":"5748.53"}],"timestamp":"1786845517041"}}
{"f":624,"recv_ms":1786845517255,"raw":{"event_type":"price_change","market":"0xd5f15f31689703aea70b93a52194a0964220d10d92ee7497346f146a8b6ef8ab","price_changes":[{"asset_id":"2151378744569768920256500242561922410292857798164019061749528550808091180185","best_ask":"0.84","best_bid":"0.83","hash":"8a136f63a1e12b6c7cca9a68158df92a3a102879","price":"0.01","side":"BUY","size":"5753.53"},{"asset_id":"17406866367975599232214757606801140480252276357934486651183783311435802862074","best_ask":"0.17","best_bid":"0.16","hash":"411100d80d9fe2f13e13fbe10730021923e6d782","price":"0.99","side":"SELL","size":"5753.53"}],"timestamp":"1786845517041"}}
{"f":625,"recv_ms":1786845517255,"raw":{"event_type":"price_change","market":"0xd5f15f31689703aea70b93a52194a0964220d10d92ee7497346f146a8b6ef8ab","price_changes":[{"asset_id":"2151378744569768920256500242561922410292857798164019061749528550808091180185","best_ask":"0.84","best_bid":"0.83","hash":"9c6e6e5ebdd2ff4c2d6672b244d598b39da4d816","price":"0.01","side":"BUY","size":"5758.53"},{"asset_id":"17406866367975599232214757606801140480252276357934486651183783311435802862074","best_ask":"0.17","best_bid":"0.16","hash":"3f735b79b9703db32a1e34ab90d92ba7540d41ad","price":"0.99","side":"SELL","size":"5758.53"}],"timestamp":"1786845517042"}}
{"f":626,"recv_ms":1786845517259,"raw":{"event_type":"price_change","market":"0xd5f15f31689703aea70b93a52194a0964220d10d92ee7497346f146a8b6ef8ab","price_changes":[{"asset_id":"2151378744569768920256500242561922410292857798164019061749528550808091180185","best_ask":"0.84","best_bid":"0.83","hash":"1519d8bda95f40bde472d64f9c589a37bf54548a","price":"0.01","side":"BUY","size":"5753.53"},{"asset_id":"17406866367975599232214757606801140480252276357934486651183783311435802862074","best_ask":"0.17","best_bid":"0.16","hash":"19c00c550e76cabdadbe7c362bbc5b63b255cb40","price":"0.99","side":"SELL","size":"5753.53"}],"timestamp":"1786845517042"}}
{"f":627,"recv_ms":1786845517259,"raw":{"event_type":"price_change","market":"0xd5f15f31689703aea70b93a52194a0964220d10d92ee7497346f146a8b6ef8ab","price_changes":[{"asset_id":"2151378744569768920256500242561922410292857798164019061749528550808091180185","best_ask":"0.84","best_bid":"0.83","hash":"35aa933f39460b707b5769de7bdbad20012ebae2","price":"0.01","side":"BUY","size":"5747.53"},{"asset_id":"17406866367975599232214757606801140480252276357934486651183783311435802862074","best_ask":"0.17","best_bid":"0.16","hash":"293fa7c961da62dd0dd042ab9aa7ee827f3d3c6d","price":"0.99","side":"SELL","size":"5747.53"}],"timestamp":"1786845517043"}}
{"f":628,"recv_ms":1786845517259,"raw":{"event_type":"price_change","market":"0xd5f15f31689703aea70b93a52194a0964220d10d92ee7497346f146a8b6ef8ab","price_changes":[{"asset_id":"17406866367975599232214757606801140480252276357934486651183783311435802862074","best_ask":"0.17","best_bid":"0.16","hash":"e0cecd2b566966d715f2c9d24b3a69900cb87030","price":"0.01","side":"BUY","size":"5688.18"},{"asset_id":"2151378744569768920256500242561922410292857798164019061749528550808091180185","best_ask":"0.84","best_bid":"0.83","hash":"a7df493a34d21b816b52338d09a12ef85f1cda20","price":"0.99","side":"SELL","size":"5688.18"}],"timestamp":"1786845517043"}}
{"f":629,"recv_ms":1786845517259,"raw":{"event_type":"price_change","market":"0xd5f15f31689703aea70b93a52194a0964220d10d92ee7497346f146a8b6ef8ab","price_changes":[{"asset_id":"2151378744569768920256500242561922410292857798164019061749528550808091180185","best_ask":"0.84","best_bid":"0.83","hash":"67c6bac20bfb8533f35bf51f481ce4a5705c1d7c","price":"0.76","side":"BUY","size":"130"},{"asset_id":"17406866367975599232214757606801140480252276357934486651183783311435802862074","best_ask":"0.17","best_bid":"0.16","hash":"6de3d496e31e5118617165e2822cebf5b1dd8e2e","price":"0.24","side":"SELL","size":"130"}],"timestamp":"1786845517044"}}
{"f":630,"recv_ms":1786845517260,"raw":{"event_type":"price_change","market":"0xd5f15f31689703aea70b93a52194a0964220d10d92ee7497346f146a8b6ef8ab","price_changes":[{"asset_id":"2151378744569768920256500242561922410292857798164019061749528550808091180185","best_ask":"0.84","best_bid":"0.83","hash":"696bb9ab8106a9baca1d896c38f38bd8a70978c8","price":"0.65","side":"BUY","size":"18"},{"asset_id":"17406866367975599232214757606801140480252276357934486651183783311435802862074","best_ask":"0.17","best_bid":"0.16","hash":"4a4b5f64da78b5aed2deb9b25d9e1105db922cf6","price":"0.35","side":"SELL","size":"18"}],"timestamp":"1786845517045"}}
{"f":631,"recv_ms":1786845517260,"raw":{"event_type":"price_change","market":"0xd5f15f31689703aea70b93a52194a0964220d10d92ee7497346f146a8b6ef8ab","price_changes":[{"asset_id":"2151378744569768920256500242561922410292857798164019061749528550808091180185","best_ask":"0.84","best_bid":"0.83","hash":"696bb9ab8106a9baca1d896c38f38bd8a70978c8","price":"0.64","side":"BUY","size":"252.13"},{"asset_id":"17406866367975599232214757606801140480252276357934486651183783311435802862074","best_ask":"0.17","best_bid":"0.16","hash":"4a4b5f64da78b5aed2deb9b25d9e1105db922cf6","price":"0.36","side":"SELL","size":"252.13"}],"timestamp":"1786845517045"}}
{"f":632,"recv_ms":1786845517273,"raw":{"event_type":"price_change","market":"0xd5f15f31689703aea70b93a52194a0964220d10d92ee7497346f146a8b6ef8ab","price_changes":[{"asset_id":"2151378744569768920256500242561922410292857798164019061749528550808091180185","best_ask":"0.84","best_bid":"0.83","hash":"9ba2ec4e8538633ec6dbb5c979a7650d7d2e5d53","price":"0.01","side":"BUY","size":"5847.53"},{"asset_id":"17406866367975599232214757606801140480252276357934486651183783311435802862074","best_ask":"0.17","best_bid":"0.16","hash":"f03e8d1191c183717b524504672e242293b941b0","price":"0.99","side":"SELL","size":"5847.53"}],"timestamp":"1786845517056"}}
{"f":633,"recv_ms":1786845517273,"raw":{"event_type":"price_change","market":"0xd5f15f31689703aea70b93a52194a0964220d10d92ee7497346f146a8b6ef8ab","price_changes":[{"asset_id":"2151378744569768920256500242561922410292857798164019061749528550808091180185","best_ask":"0.84","best_bid":"0.83","hash":"d701d97ea0172e6370b3deca171ebfb4cd897d1c","price":"0.83","side":"BUY","size":"287.1"},{"asset_id":"17406866367975599232214757606801140480252276357934486651183783311435802862074","best_ask":"0.17","best_bid":"0.16","hash":"b9b017d9418a8952ab4618bc69f80f3017fa6f31","price":"0.17","side":"SELL","size":"287.1"}],"timestamp":"1786845517061"}}
{"f":634,"recv_ms":1786845517293,"raw":{"asks":[{"price":"0.99","size":"5688.18"},{"price":"0.98","size":"1867.69"},{"price":"0.97","size":"806.3"},{"price":"0.96","size":"767.7"},{"price":"0.95","size":"554.7"},{"price":"0.94","size":"383.1"},{"price":"0.93","size":"459.86"},{"price":"0.92","size":"70.29"},{"price":"0.91","size":"71.7"},{"price":"0.9","size":"66"},{"price":"0.89","size":"40"},{"price":"0.88","size":"5"},{"price":"0.87","size":"10"},{"price":"0.86","size":"7"},{"price":"0.85","size":"5"},{"price":"0.84","size":"33.33"}],"asset_id":"2151378744569768920256500242561922410292857798164019061749528550808091180185","bids":[{"price":"0.01","size":"5847.53"},{"price":"0.02","size":"3820.18"},{"price":"0.03","size":"817.3"},{"price":"0.04","size":"472.7"},{"price":"0.05","size":"757.3"},{"price":"0.06","size":"481.1"},{"price":"0.07","size":"389.9"},{"price":"0.08","size":"140.29"},{"price":"0.09","size":"136.7"},{"price":"0.1","size":"168.9"},{"price":"0.11","size":"126.6"},{"price":"0.12","size":"119.6"},{"price":"0.13","size":"113"},{"price":"0.14","size":"111.6"},{"price":"0.15","size":"115.39"},{"price":"0.16","size":"109.3"},{"price":"0.17","size":"103.39"},{"price":"0.18","size":"22.6"},{"price":"0.19","size":"26.89"},{"price":"0.2","size":"54.1"},{"price":"0.21","size":"20.7"},{"price":"0.22","size":"25.2"},{"price":"0.23","size":"114.7"},{"price":"0.24","size":"14.3"},{"price":"0.25","size":"113.9"},{"price":"0.26","size":"13.5"},{"price":"0.27","size":"113.2"},{"price":"0.28","size":"12.9"},{"price":"0.29","size":"112.6"},{"price":"0.3","size":"22.4"},{"price":"0.31","size":"112.2"},{"price":"0.32","size":"11.9"},{"price":"0.33","size":"111.8"},{"price":"0.34","size":"26.6"},{"price":"0.35","size":"125.4"},{"price":"0.36","size":"155.3"},{"price":"0.37","size":"155.2"},{"price":"0.38","size":"24"},{"price":"0.39","size":"133.9"},{"price":"0.4","size":"38.8"},{"price":"0.41","size":"132.7"},{"price":"0.42","size":"92.7"},{"price":"0.43","size":"92.6"},{"price":"0.44","size":"123.6"},{"price":"0.45","size":"51.5"},{"price":"0.46","size":"51.5"},{"price":"0.47","size":"51.4"},{"price":"0.48","size":"50.4"},{"price":"0.49","size":"50.4"},{"price":"0.5","size":"655.4"},{"price":"0.51","size":"40"},{"price":"0.52","size":"40"},{"price":"0.53","size":"669.64"},{"price":"0.54","size":"49"},{"price":"0.55","size":"149"},{"price":"0.56","size":"19"},{"price":"0.57","size":"24"},{"price":"0.58","size":"29"},{"price":"0.59","size":"28"},{"price":"0.6","size":"28"},{"price":"0.61","size":"94.22"},{"price":"0.62","size":"198.66"},{"price":"0.63","size":"28"},{"price":"0.64","size":"252.13"},{"price":"0.65","size":"18"},{"price":"0.66","size":"18"},{"price":"0.67","size":"40"},{"price":"0.68","size":"105"},{"price":"0.69","size":"100"},{"price":"0.7","size":"40"},{"price":"0.71","size":"5"},{"price":"0.72","size":"20"},{"price":"0.73","size":"12"},{"price":"0.74","size":"26"},{"price":"0.75","size":"71.9"},{"price":"0.76","size":"130"},{"price":"0.77","size":"45"},{"price":"0.78","size":"7"},{"price":"0.79","size":"5"},{"price":"0.8","size":"66"},{"price":"0.81","size":"10"},{"price":"0.82","size":"117.61"},{"price":"0.83","size":"287.1"}],"event_type":"book","hash":"d701d97ea0172e6370b3deca171ebfb4cd897d1c","market":"0xd5f15f31689703aea70b93a52194a0964220d10d92ee7497346f146a8b6ef8ab","timestamp":"1786845517061"}}
{"f":635,"recv_ms":1786845517324,"raw":{"event_type":"price_change","market":"0xd5f15f31689703aea70b93a52194a0964220d10d92ee7497346f146a8b6ef8ab","price_changes":[{"asset_id":"17406866367975599232214757606801140480252276357934486651183783311435802862074","best_ask":"0.17","best_bid":"0.16","hash":"34e1624aefa810905afd8d7f24b7f7421559c5fb","price":"0.3","side":"SELL","size":"132"},{"asset_id":"2151378744569768920256500242561922410292857798164019061749528550808091180185","best_ask":"0.84","best_bid":"0.83","hash":"2177f75e77c0947a5c02bc6367dfd4a3cb36d2c0","price":"0.7","side":"BUY","size":"132"}],"timestamp":"1786845517085"}}
{"f":636,"recv_ms":1786845517328,"raw":{"event_type":"price_change","market":"0xd5f15f31689703aea70b93a52194a0964220d10d92ee7497346f146a8b6ef8ab","price_changes":[{"asset_id":"2151378744569768920256500242561922410292857798164019061749528550808091180185","best_ask":"0.84","best_bid":"0.83","hash":"07241cdc965d5fd53c530dfa89d4d995dd372884","price":"0.76","side":"BUY","size":"30"},{"asset_id":"17406866367975599232214757606801140480252276357934486651183783311435802862074","best_ask":"0.17","best_bid":"0.16","hash":"2169ae8dd0e1d1774035001604b03d0a5b7fa985","price":"0.24","side":"SELL","size":"30"}],"timestamp":"1786845517112"}}
{"f":637,"recv_ms":1786845517328,"raw":{"event_type":"price_change","market":"0xd5f15f31689703aea70b93a52194a0964220d10d92ee7497346f146a8b6ef8ab","price_changes":[{"asset_id":"2151378744569768920256500242561922410292857798164019061749528550808091180185","best_ask":"0.84","best_bid":"0.83","hash":"278b5eb49569bf94724c7250fc0b88f1bf799093","price":"0.77","side":"BUY","size":"145"},{"asset_id":"17406866367975599232214757606801140480252276357934486651183783311435802862074","best_ask":"0.17","best_bid":"0.16","hash":"a7158540751290cf14babf3a0e0d28f8db850db4","price":"0.23","side":"SELL","size":"145"}],"timestamp":"1786845517112"}}
{"f":638,"recv_ms":1786845517328,"raw":{"event_type":"price_change","market":"0xd5f15f31689703aea70b93a52194a0964220d10d92ee7497346f146a8b6ef8ab","price_changes":[{"asset_id":"2151378744569768920256500242561922410292857798164019061749528550808091180185","best_ask":"0.84","best_bid":"0.83","hash":"11f5ba1cd24c5d2afcd133e8ed0a8745fe0f0ac8","price":"0.01","side":"BUY","size":"5747.53"},{"asset_id":"17406866367975599232214757606801140480252276357934486651183783311435802862074","best_ask":"0.17","best_bid":"0.16","hash":"cab0f50b6fc51d56693f38c5d55ea758badd67f3","price":"0.99","side":"SELL","size":"5747.53"}],"timestamp":"1786845517114"}}
{"f":639,"recv_ms":1786845517335,"raw":{"event_type":"price_change","market":"0xd5f15f31689703aea70b93a52194a0964220d10d92ee7497346f146a8b6ef8ab","price_changes":[{"asset_id":"2151378744569768920256500242561922410292857798164019061749528550808091180185","best_ask":"0.84","best_bid":"0.83","hash":"267e564ca6ddb1de6db2241a71a98fdefc68fd4b","price":"0.03","side":"BUY","size":"822.3"},{"asset_id":"17406866367975599232214757606801140480252276357934486651183783311435802862074","best_ask":"0.17","best_bid":"0.16","hash":"0dda76c2214ad5440ed0f755a95552c3ce904f4e","price":"0.97","side":"SELL","size":"822.3"}],"timestamp":"1786845517117"}}
{"f":640,"recv_ms":1786845517335,"raw":{"event_type":"price_change","market":"0xd5f15f31689703aea70b93a52194a0964220d10d92ee7497346f146a8b6ef8ab","price_changes":[{"asset_id":"2151378744569768920256500242561922410292857798164019061749528550808091180185","best_ask":"0.84","best_bid":"0.83","hash":"acce0f762d6a38e674cc479a52b370b58fc8d7bc","price":"0.01","side":"BUY","size":"5753.53"},{"asset_id":"17406866367975599232214757606801140480252276357934486651183783311435802862074","best_ask":"0.17","best_bid":"0.16","hash":"5298f877dea31401d0ae67c38d70652587563e53","price":"0.99","side":"SELL","size":"5753.53"}],"timestamp":"1786845517117"}}
{"f":641,"recv_ms":1786845517335,"raw":{"event_type":"price_change","market":"0xd5f15f31689703aea70b93a52194a0964220d10d92ee7497346f146a8b6ef8ab","price_changes":[{"asset_id":"2151378744569768920256500242561922410292857798164019061749528550808091180185","best_ask":"0.84","best_bid":"0.83","hash":"c1ccd25a83baa0a8b4f74cb9d3ffdf0209ae6eaa","price":"0.06","side":"BUY","size":"486.1"},{"asset_id":"17406866367975599232214757606801140480252276357934486651183783311435802862074","best_ask":"0.17","best_bid":"0.16","hash":"b2f8c76af5a985e273cf18fbff57dd67e0a91f03","price":"0.94","side":"SELL","size":"486.1"}],"timestamp":"1786845517121"}}
{"f":642,"recv_ms":1786845517335,"raw":{"event_type":"price_change","market":"0xd5f15f31689703aea70b93a52194a0964220d10d92ee7497346f146a8b6ef8ab","price_changes":[{"asset_id":"2151378744569768920256500242561922410292857798164019061749528550808091180185","best_ask":"0.84","best_bid":"0.83","hash":"857695ba4e958a4741c71d129b0d235bf6181dea","price":"0.1","side":"BUY","size":"173.9"},{"asset_id":"17406866367975599232214757606801140480252276357934486651183783311435802862074","best_ask":"0.17","best_bid":"0.16","hash":"bab856b7674c1babbe773513ec6aec15595a397c","price":"0.9","side":"SELL","size":"173.9"}],"timestamp":"1786845517122"}}
{"f":643,"recv_ms":1786845517335,"raw":{"event_type":"price_change","market":"0xd5f15f31689703aea70b93a52194a0964220d10d92ee7497346f146a8b6ef8ab","price_changes":[{"asset_id":"2151378744569768920256500242561922410292857798164019061749528550808091180185","best_ask":"0.84","best_bid":"0.83","hash":"b20382cfc058a48c498b3b370bafdce89360491a","price":"0.07","side":"BUY","size":"394.9"},{"asset_id":"17406866367975599232214757606801140480252276357934486651183783311435802862074","best_ask":"0.17","best_bid":"0.16","hash":"3f2b48cc15af5c458d58a69cc0b8dfaee34c222f","price":"0.93","side":"SELL","size":"394.9"}],"timestamp":"1786845517123"}}
{"f":644,"recv_ms":1786845517335,"raw":{"event_type":"price_change","market":"0xd5f15f31689703aea70b93a52194a0964220d10d92ee7497346f146a8b6ef8ab","price_changes":[{"asset_id":"2151378744569768920256500242561922410292857798164019061749528550808091180185","best_ask":"0.84","best_bid":"0.83","hash":"fe916978590f458332e5ec99015f8f976452b0b2","price":"0.01","side":"BUY","size":"5758.53"},{"asset_id":"17406866367975599232214757606801140480252276357934486651183783311435802862074","best_ask":"0.17","best_bid":"0.16","hash":"35050116d75a088be5a5190cdb1094fdc891967e","price":"0.99","side":"SELL","size":"5758.53"}],"timestamp":"1786845517123"}}
{"f":645,"recv_ms":1786845517339,"raw":{"event_type":"price_change","market":"0xd5f15f31689703aea70b93a52194a0964220d10d92ee7497346f146a8b6ef8ab","price_changes":[{"asset_id":"2151378744569768920256500242561922410292857798164019061749528550808091180185","best_ask":"0.84","best_bid":"0.83","hash":"a974cdc29cda7d9edd083b39b0d4c4cb8db5f9a0","price":"0.12","side":"BUY","size":"124.6"},{"asset_id":"17406866367975599232214757606801140480252276357934486651183783311435802862074","best_ask":"0.17","best_bid":"0.16","hash":"b546af3b3f95049f184b304b4eb988f41fd3148f","price":"0.88","side":"SELL","size":"124.6"}],"timestamp":"1786845517124"}}
{"f":646,"recv_ms":1786845517339,"raw":{"event_type":"price_change","market":"0xd5f15f31689703aea70b93a52194a0964220d10d92ee7497346f146a8b6ef8ab","price_changes":[{"asset_id":"2151378744569768920256500242561922410292857798164019061749528550808091180185","best_ask":"0.84","best_bid":"0.83","hash":"9b08dfcecfb90044edc5a5cf45480f5552d569ee","price":"0.13","side":"BUY","size":"118"},{"asset_id":"17406866367975599232214757606801140480252276357934486651183783311435802862074","best_ask":"0.17","best_bid":"0.16","hash":"092ed0642c6ffe7d5d7ffba2375bf89424c2416f","price":"0.87","side":"SELL","size":"118"}],"timestamp":"1786845517125"}}
{"f":647,"recv_ms":1786845517340,"raw":{"event_type":"price_change","market":"0xd5f15f31689703aea70b93a52194a0964220d10d92ee7497346f146a8b6ef8ab","price_changes":[{"asset_id":"2151378744569768920256500242561922410292857798164019061749528550808091180185","best_ask":"0.84","best_bid":"0.83","hash":"d499d1a382ff10e69894f00b2e6b3e1171652454","price":"0.11","side":"BUY","size":"131.6"},{"asset_id":"17406866367975599232214757606801140480252276357934486651183783311435802862074","best_ask":"0.17","best_bid":"0.16","hash":"fdb5e92e53a885ce2901ef52eb9f071d0f32ef3b","price":"0.89","side":"SELL","size":"131.6"}],"timestamp":"1786845517126"}}
{"f":648,"recv_ms":1786845517340,"raw":{"event_type":"price_change","market":"0xd5f15f31689703aea70b93a52194a0964220d10d92ee7497346f146a8b6ef8ab","price_changes":[{"asset_id":"2151378744569768920256500242561922410292857798164019061749528550808091180185","best_ask":"0.84","best_bid":"0.83","hash":"5104dd73052f550d426df4661fc502aada9d519f","price":"0.14","side":"BUY","size":"116.6"},{"asset_id":"17406866367975599232214757606801140480252276357934486651183783311435802862074","best_ask":"0.17","best_bid":"0.16","hash":"1b9ae878d3935bdb5498f21d98f8e444593307cd","price":"0.86","side":"SELL","size":"116.6"}],"timestamp":"1786845517127"}}
{"f":649,"recv_ms":1786845517342,"raw":{"event_type":"price_change","market":"0xd5f15f31689703aea70b93a52194a0964220d10d92ee7497346f146a8b6ef8ab","price_changes":[{"asset_id":"2151378744569768920256500242561922410292857798164019061749528550808091180185","best_ask":"0.84","best_bid":"0.83","hash":"c07f63d5bc88bdfb3ccdd94b9b4eb7249c3b9c57","price":"0.05","side":"BUY","size":"762.3"},{"asset_id":"17406866367975599232214757606801140480252276357934486651183783311435802862074","best_ask":"0.17","best_bid":"0.16","hash":"043f804cff6917b2fbb432c40a7084add80e7731","price":"0.95","side":"SELL","size":"762.3"}],"timestamp":"1786845517128"}}
{"f":650,"recv_ms":1786845517342,"raw":{"event_type":"price_change","market":"0xd5f15f31689703aea70b93a52194a0964220d10d92ee7497346f146a8b6ef8ab","price_changes":[{"asset_id":"2151378744569768920256500242561922410292857798164019061749528550808091180185","best_ask":"0.84","best_bid":"0.83","hash":"43060c6c7045086fa4c96e2b1ad1c6492160baca","price":"0.17","side":"BUY","size":"108.39"},{"asset_id":"17406866367975599232214757606801140480252276357934486651183783311435802862074","best_ask":"0.17","best_bid":"0.16","hash":"1db3b91922a7723ec951562dab459f5ba738f15d","price":"0.83","side":"SELL","size":"108.39"}],"timestamp":"1786845517129"}}
{"f":651,"recv_ms":1786845517343,"raw":{"event_type":"price_change","market":"0xd5f15f31689703aea70b93a52194a0964220d10d92ee7497346f146a8b6ef8ab","price_changes":[{"asset_id":"2151378744569768920256500242561922410292857798164019061749528550808091180185","best_ask":"0.84","best_bid":"0.83","hash":"6be2c2be07c0c71da652d6f009acd72ebad02861","price":"0.16","side":"BUY","size":"114.3"},{"asset_id":"17406866367975599232214757606801140480252276357934486651183783311435802862074","best_ask":"0.17","best_bid":"0.16","hash":"baf6b37b1912423d41606e66ae852fa49083149c","price":"0.84","side":"SELL","size":"114.3"}],"timestamp":"1786845517130"}}
{"f":652,"recv_ms":1786845517343,"raw":{"event_type":"price_change","market":"0xd5f15f31689703aea70b93a52194a0964220d10d92ee7497346f146a8b6ef8ab","price_changes":[{"asset_id":"2151378744569768920256500242561922410292857798164019061749528550808091180185","best_ask":"0.84","best_bid":"0.83","hash":"19e99d6018539ec1ad2a759f890a62ab4e3a4df1","price":"0.04","side":"BUY","size":"477.7"},{"asset_id":"17406866367975599232214757606801140480252276357934486651183783311435802862074","best_ask":"0.17","best_bid":"0.16","hash":"ed4d07a0f7828896ac4852d422b5f3b10c4e749a","price":"0.96","side":"SELL","size":"477.7"}],"timestamp":"1786845517131"}}
{"f":653,"recv_ms":1786845517344,"raw":{"event_type":"price_change","market":"0xd5f15f31689703aea70b93a52194a0964220d10d92ee7497346f146a8b6ef8ab","price_changes":[{"asset_id":"2151378744569768920256500242561922410292857798164019061749528550808091180185","best_ask":"0.84","best_bid":"0.83","hash":"4ab8e8812a30d736c474547a225adf9bb668295d","price":"0.01","side":"BUY","size":"5763.53"},{"asset_id":"17406866367975599232214757606801140480252276357934486651183783311435802862074","best_ask":"0.17","best_bid":"0.16","hash":"553b03ea6f45261f0ee0c17cbf63abdd52c1ecf0","price":"0.99","side":"SELL","size":"5763.53"}],"timestamp":"1786845517132"}}
{"f":654,"recv_ms":1786845517344,"raw":{"event_type":"price_change","market":"0xd5f15f31689703aea70b93a52194a0964220d10d92ee7497346f146a8b6ef8ab","price_changes":[{"asset_id":"2151378744569768920256500242561922410292857798164019061749528550808091180185","best_ask":"0.84","best_bid":"0.83","hash":"c4ecb602448153ab4a2bd74b77e6e7a2abb2b7ab","price":"0.19","side":"BUY","size":"31.89"},{"asset_id":"17406866367975599232214757606801140480252276357934486651183783311435802862074","best_ask":"0.17","best_bid":"0.16","hash":"88eb94fcd1ee9823a55b738344aef6b7be20d016","price":"0.81","side":"SELL","size":"31.89"}],"timestamp":"1786845517132"}}
{"f":655,"recv_ms":1786845517344,"raw":{"asset_id":"17406866367975599232214757606801140480252276357934486651183783311435802862074","event_type":"last_trade_price","fee_rate_bps":"0","market":"0xd5f15f31689703aea70b93a52194a0964220d10d92ee7497346f146a8b6ef8ab","price":"0.17","side":"BUY","size":"5.882351","timestamp":"1786845517130","transaction_hash":"0xf7108249ba6798b1ca6ad55bfdd1bc5a33199b804a56b9a29ab54a8de368dccb"}}
{"f":656,"recv_ms":1786845517344,"raw":{"event_type":"price_change","market":"0xd5f15f31689703aea70b93a52194a0964220d10d92ee7497346f146a8b6ef8ab","price_changes":[{"asset_id":"2151378744569768920256500242561922410292857798164019061749528550808091180185","best_ask":"0.84","best_bid":"0.83","hash":"505f7ade9c3c8491cf6ea894aa58890aa23bd659","price":"0.01","side":"BUY","size":"5768.53"},{"asset_id":"17406866367975599232214757606801140480252276357934486651183783311435802862074","best_ask":"0.17","best_bid":"0.16","hash":"38e49f3e221171a6dddca874c9d985add712e19d","price":"0.99","side":"SELL","size":"5768.53"}],"timestamp":"1786845517133"}}
{"f":657,"recv_ms":1786845517348,"raw":{"event_type":"price_change","market":"0xd5f15f31689703aea70b93a52194a0964220d10d92ee7497346f146a8b6ef8ab","price_changes":[{"asset_id":"2151378744569768920256500242561922410292857798164019061749528550808091180185","best_ask":"0.84","best_bid":"0.83","hash":"babf111043bf98175c997b1903e2ca15d5b7d52a","price":"0.51","side":"BUY","size":"50.4"},{"asset_id":"17406866367975599232214757606801140480252276357934486651183783311435802862074","best_ask":"0.17","best_bid":"0.16","hash":"c4533535cde2fe8e9b8aa01258e81b184a8a07d5","price":"0.49","side":"SELL","size":"50.4"}],"timestamp":"1786845517134"}}
{"f":658,"recv_ms":1786845517348,"raw":{"event_type":"price_change","market":"0xd5f15f31689703aea70b93a52194a0964220d10d92ee7497346f146a8b6ef8ab","price_changes":[{"asset_id":"2151378744569768920256500242561922410292857798164019061749528550808091180185","best_ask":"0.84","best_bid":"0.83","hash":"43934cebdbfee228cb0e77c5af5f63002cceb18b","price":"0.22","side":"BUY","size":"30.2"},{"asset_id":"17406866367975599232214757606801140480252276357934486651183783311435802862074","best_ask":"0.17","best_bid":"0.16","hash":"68291de0ad710c7cafcdba646573090605ab28de","price":"0.78","side":"SELL","size":"30.2"}],"timestamp":"1786845517135"}}
{"f":659,"recv_ms":1786845517349,"raw":{"event_type":"price_change","market":"0xd5f15f31689703aea70b93a52194a0964220d10d92ee7497346f146a8b6ef8ab","price_changes":[{"asset_id":"2151378744569768920256500242561922410292857798164019061749528550808091180185","best_ask":"0.84","best_bid":"0.83","hash":"21c879e740d537d95423323180b0e5ef63a7b724","price":"0.01","side":"BUY","size":"5773.53"},{"asset_id":"17406866367975599232214757606801140480252276357934486651183783311435802862074","best_ask":"0.17","best_bid":"0.16","hash":"71df387c80696eafc001b87791f5fe5295fd3275","price":"0.99","side":"SELL","size":"5773.53"}],"timestamp":"1786845517135"}}
{"f":660,"recv_ms":1786845517349,"raw":{"event_type":"price_change","market":"0xd5f15f31689703aea70b93a52194a0964220d10d92ee7497346f146a8b6ef8ab","price_changes":[{"asset_id":"2151378744569768920256500242561922410292857798164019061749528550808091180185","best_ask":"0.84","best_bid":"0.83","hash":"ac48a77dc80ed419b08c7beafa6439ebb8412156","price":"0.08","side":"BUY","size":"145.29"},{"asset_id":"17406866367975599232214757606801140480252276357934486651183783311435802862074","best_ask":"0.17","best_bid":"0.16","hash":"bbc015ed64e37d05334e2e67d6cb94c4c339eaa8","price":"0.92","side":"SELL","size":"145.29"}],"timestamp":"1786845517136"}}
{"f":661,"recv_ms":1786845517349,"raw":{"event_type":"price_change","market":"0xd5f15f31689703aea70b93a52194a0964220d10d92ee7497346f146a8b6ef8ab","price_changes":[{"asset_id":"2151378744569768920256500242561922410292857798164019061749528550808091180185","best_ask":"0.84","best_bid":"0.83","hash":"e070fd30cde851c79eacfa24fe115c12a848fb0c","price":"0.21","side":"BUY","size":"25.7"},{"asset_id":"17406866367975599232214757606801140480252276357934486651183783311435802862074","best_ask":"0.17","best_bid":"0.16","hash":"b676594013bed784a8c1a0315136175848ea799b","price":"0.79","side":"SELL","size":"25.7"}],"timestamp":"1786845517137"}}
{"f":662,"recv_ms":1786845517349,"raw":{"event_type":"price_change","market":"0xd5f15f31689703aea70b93a52194a0964220d10d92ee7497346f146a8b6ef8ab","price_changes":[{"asset_id":"2151378744569768920256500242561922410292857798164019061749528550808091180185","best_ask":"0.84","best_bid":"0.83","hash":"7eb2a0ab1020d99fb7e8615eb7ec21c33fe79dcc","price":"0.02","side":"BUY","size":"3825.18"},{"asset_id":"17406866367975599232214757606801140480252276357934486651183783311435802862074","best_ask":"0.17","best_bid":"0.16","hash":"32666a7b5f7b581e2be395846e52598d189c5b70","price":"0.98","side":"SELL","size":"3825.18"}],"timestamp":"1786845517138"}}
{"f":663,"recv_ms":1786845517352,"raw":{"event_type":"price_change","market":"0xd5f15f31689703aea70b93a52194a0964220d10d92ee7497346f146a8b6ef8ab","price_changes":[{"asset_id":"2151378744569768920256500242561922410292857798164019061749528550808091180185","best_ask":"0.84","best_bid":"0.83","hash":"9b3f9db1c7c8a93cac7b113aca86a48a7bc4f94e","price":"0.23","side":"BUY","size":"119.7"},{"asset_id":"17406866367975599232214757606801140480252276357934486651183783311435802862074","best_ask":"0.17","best_bid":"0.16","hash":"53a5dac6eceac17da7e84925e17e85836e4a1bbe","price":"0.77","side":"SELL","size":"119.7"}],"timestamp":"1786845517138"}}
{"f":664,"recv_ms":1786845517352,"raw":{"event_type":"price_change","market":"0xd5f15f31689703aea70b93a52194a0964220d10d92ee7497346f146a8b6ef8ab","price_changes":[{"asset_id":"2151378744569768920256500242561922410292857798164019061749528550808091180185","best_ask":"0.84","best_bid":"0.83","hash":"892e07cd700f863ebe631731c26b8f3f3195a446","price":"0.15","side":"BUY","size":"120.39"},{"asset_id":"17406866367975599232214757606801140480252276357934486651183783311435802862074","best_ask":"0.17","best_bid":"0.16","hash":"f8ed6219ad55a67117a9b377b3522295c70b3c1b","price":"0.85","side":"SELL","size":"120.39"}],"timestamp":"1786845517139"}}
{"f":665,"recv_ms":1786845517353,"raw":{"event_type":"price_change","market":"0xd5f15f31689703aea70b93a52194a0964220d10d92ee7497346f146a8b6ef8ab","price_changes":[{"asset_id":"2151378744569768920256500242561922410292857798164019061749528550808091180185","best_ask":"0.84","best_bid":"0.83","hash":"b4c378fed113992acac6736b15d447e6ee873043","price":"0.18","side":"BUY","size":"27.6"},{"asset_id":"17406866367975599232214757606801140480252276357934486651183783311435802862074","best_ask":"0.17","best_bid":"0.16","hash":"d075f0a5ea46b5f07d26a22033e3d72db92490c2","price":"0.82","side":"SELL","size":"27.6"}],"timestamp":"1786845517140"}}
{"f":666,"recv_ms":1786845517353,"raw":{"event_type":"price_change","market":"0xd5f15f31689703aea70b93a52194a0964220d10d92ee7497346f146a8b6ef8ab","price_changes":[{"asset_id":"2151378744569768920256500242561922410292857798164019061749528550808091180185","best_ask":"0.84","best_bid":"0.83","hash":"92bcf970029145ca522e3282ea1258aedb9786ee","price":"0.09","side":"BUY","size":"141.7"},{"asset_id":"17406866367975599232214757606801140480252276357934486651183783311435802862074","best_ask":"0.17","best_bid":"0.16","hash":"8b6512f2dc2d575b9263b8076a6571a70bfdc248","price":"0.91","side":"SELL","size":"141.7"}],"timestamp":"1786845517141"}}
{"f":667,"recv_ms":1786845517354,"raw":{"event_type":"price_change","market":"0xd5f15f31689703aea70b93a52194a0964220d10d92ee7497346f146a8b6ef8ab","price_changes":[{"asset_id":"2151378744569768920256500242561922410292857798164019061749528550808091180185","best_ask":"0.84","best_bid":"0.83","hash":"804833fb09f5c50d80c896fab8c4d1ad4a69738d","price":"0.01","side":"BUY","size":"5873.53"},{"asset_id":"17406866367975599232214757606801140480252276357934486651183783311435802862074","best_ask":"0.17","best_bid":"0.16","hash":"67469298f757c1d4476e117b407ffe503a5adaed","price":"0.99","side":"SELL","size":"5873.53"}],"timestamp":"1786845517142"}}
{"f":668,"recv_ms":1786845517364,"raw":{"event_type":"price_change","market":"0xd5f15f31689703aea70b93a52194a0964220d10d92ee7497346f146a8b6ef8ab","price_changes":[{"asset_id":"2151378744569768920256500242561922410292857798164019061749528550808091180185","best_ask":"0.84","best_bid":"0.83","hash":"19e75ec29dccc4daba9d00ab40a7c4e264fe9ca3","price":"0.2","side":"BUY","size":"59.1"},{"asset_id":"17406866367975599232214757606801140480252276357934486651183783311435802862074","best_ask":"0.17","best_bid":"0.16","hash":"747f7193b842d3a900c9d673ce46c60060f5e02b","price":"0.8","side":"SELL","size":"59.1"}],"timestamp":"1786845517143"}}
{"f":669,"recv_ms":1786845517364,"raw":{"event_type":"price_change","market":"0xd5f15f31689703aea70b93a52194a0964220d10d92ee7497346f146a8b6ef8ab","price_changes":[{"asset_id":"2151378744569768920256500242561922410292857798164019061749528550808091180185","best_ask":"0.84","best_bid":"0.83","hash":"57784a4b8f26354cf927b4cdc408c3b05058a3eb","price":"0.01","side":"BUY","size":"5867.53"},{"asset_id":"17406866367975599232214757606801140480252276357934486651183783311435802862074","best_ask":"0.17","best_bid":"0.16","hash":"a9ff35f3fabf9396464967913755d7b9ee885c8b","price":"0.99","side":"SELL","size":"5867.53"}],"timestamp":"1786845517144"}}
{"f":670,"recv_ms":1786845517378,"raw":{"event_type":"price_change","market":"0xd5f15f31689703aea70b93a52194a0964220d10d92ee7497346f146a8b6ef8ab","price_changes":[{"asset_id":"2151378744569768920256500242561922410292857798164019061749528550808091180185","best_ask":"0.84","best_bid":"0.83","hash":"fb46512222d5430afa3bb415f7855523dc17bc78","price":"0.01","side":"BUY","size":"5872.54"},{"asset_id":"17406866367975599232214757606801140480252276357934486651183783311435802862074","best_ask":"0.17","best_bid":"0.16","hash":"b9161ac955d3bccf34a6258efba1e9b41aa26bb5","price":"0.99","side":"SELL","size":"5872.54"}],"timestamp":"1786845517153"}}
{"f":671,"recv_ms":1786845517378,"raw":{"event_type":"price_change","market":"0xd5f15f31689703aea70b93a52194a0964220d10d92ee7497346f146a8b6ef8ab","price_changes":[{"asset_id":"2151378744569768920256500242561922410292857798164019061749528550808091180185","best_ask":"0.84","best_bid":"0.83","hash":"86e65153705ba0146d95c3e8ba45553ad11f4e16","price":"0.01","side":"BUY","size":"5867.54"},{"asset_id":"17406866367975599232214757606801140480252276357934486651183783311435802862074","best_ask":"0.17","best_bid":"0.16","hash":"90ecadb816aa6881ede3d3026c008d33d4d38136","price":"0.99","side":"SELL","size":"5867.54"}],"timestamp":"1786845517166"}}
{"f":672,"recv_ms":1786845517383,"raw":{"event_type":"price_change","market":"0xd5f15f31689703aea70b93a52194a0964220d10d92ee7497346f146a8b6ef8ab","price_changes":[{"asset_id":"17406866367975599232214757606801140480252276357934486651183783311435802862074","best_ask":"0.17","best_bid":"0.16","hash":"95bce0791bbe64dbc55ffac65ed84eda2f82ff1d","price":"0.01","side":"BUY","size":"5693.18"},{"asset_id":"2151378744569768920256500242561922410292857798164019061749528550808091180185","best_ask":"0.84","best_bid":"0.83","hash":"05ebba3678d705e51dcc2ac679b148be2103eec5","price":"0.99","side":"SELL","size":"5693.18"}],"timestamp":"1786845517167"}}
{"f":673,"recv_ms":1786845517389,"raw":{"event_type":"price_change","market":"0xd5f15f31689703aea70b93a52194a0964220d10d92ee7497346f146a8b6ef8ab","price_changes":[{"asset_id":"2151378744569768920256500242561922410292857798164019061749528550808091180185","best_ask":"0.84","best_bid":"0.83","hash":"9451e023c4f0830a870af4b3899d48dee7d0c90d","price":"0.01","side":"BUY","size":"5767.54"},{"asset_id":"17406866367975599232214757606801140480252276357934486651183783311435802862074","best_ask":"0.17","best_bid":"0.16","hash":"6bb1c91e1a2d1a70316a330dd46d22e7f8233e62","price":"0.99","side":"SELL","size":"5767.54"}],"timestamp":"1786845517176"}}
{"f":674,"recv_ms":1786845517393,"raw":{"event_type":"price_change","market":"0xd5f15f31689703aea70b93a52194a0964220d10d92ee7497346f146a8b6ef8ab","price_changes":[{"asset_id":"17406866367975599232214757606801140480252276357934486651183783311435802862074","best_ask":"0.17","best_bid":"0.16","hash":"cbaf9c3db01327bdfff7889c600685ae574768d0","price":"0.01","side":"BUY","size":"5688.18"},{"asset_id":"2151378744569768920256500242561922410292857798164019061749528550808091180185","best_ask":"0.84","best_bid":"0.83","hash":"e19155fc709ca4312704427dd34f2b4968b3e9ce","price":"0.99","side":"SELL","size":"5688.18"}],"timestamp":"1786845517178"}}
{"f":675,"recv_ms":1786845517393,"raw":{"event_type":"price_change","market":"0xd5f15f31689703aea70b93a52194a0964220d10d92ee7497346f146a8b6ef8ab","price_changes":[{"asset_id":"2151378744569768920256500242561922410292857798164019061749528550808091180185","best_ask":"0.84","best_bid":"0.83","hash":"aa4ce863ed10714b550bbc02d0d7432216cfd3c3","price":"0.01","side":"BUY","size":"5762.53"},{"asset_id":"17406866367975599232214757606801140480252276357934486651183783311435802862074","best_ask":"0.17","best_bid":"0.16","hash":"c3b5c5693ea65ef857c77479cb35fe59d375510b","price":"0.99","side":"SELL","size":"5762.53"}],"timestamp":"1786845517181"}}
{"f":676,"recv_ms":1786845517394,"raw":{"event_type":"price_change","market":"0xd5f15f31689703aea70b93a52194a0964220d10d92ee7497346f146a8b6ef8ab","price_changes":[{"asset_id":"17406866367975599232214757606801140480252276357934486651183783311435802862074","best_ask":"0.17","best_bid":"0.16","hash":"55e87f168f62102a34e3bbc46f267643b138ad42","price":"0.04","side":"BUY","size":"567.7"},{"asset_id":"2151378744569768920256500242561922410292857798164019061749528550808091180185","best_ask":"0.84","best_bid":"0.83","hash":"ee253b320049438a3442d7af0e8bcb9071f8b5a7","price":"0.96","side":"SELL","size":"567.7"}],"timestamp":"1786845517182"}}
{"f":677,"recv_ms":1786845517394,"raw":{"event_type":"price_change","market":"0xd5f15f31689703aea70b93a52194a0964220d10d92ee7497346f146a8b6ef8ab","price_changes":[{"asset_id":"17406866367975599232214757606801140480252276357934486651183783311435802862074","best_ask":"0.17","best_bid":"0.16","hash":"281640b5607e1cfa13468fb8b8f5b5b24ac81914","price":"0.03","side":"BUY","size":"606.3"},{"asset_id":"2151378744569768920256500242561922410292857798164019061749528550808091180185","best_ask":"0.84","best_bid":"0.83","hash":"d60b639fcaec625e35dad61de330a6302e303a48","price":"0.97","side":"SELL","size":"606.3"}],"timestamp":"1786845517182"}}
{"f":678,"recv_ms":1786845517399,"raw":{"event_type":"price_change","market":"0xd5f15f31689703aea70b93a52194a0964220d10d92ee7497346f146a8b6ef8ab","price_changes":[{"asset_id":"17406866367975599232214757606801140480252276357934486651183783311435802862074","best_ask":"0.17","best_bid":"0.16","hash":"3c8086325f3f900270b5cf06cebce2cb0cf48f49","price":"0.04","side":"BUY","size":"367.7"},{"asset_id":"2151378744569768920256500242561922410292857798164019061749528550808091180185","best_ask":"0.84","best_bid":"0.83","hash":"1620d07015249b9eab2af28f9966d2574f9a86cb","price":"0.96","side":"SELL","size":"367.7"}],"timestamp":"1786845517183"}}
{"f":679,"recv_ms":1786845517400,"raw":{"event_type":"price_change","market":"0xd5f15f31689703aea70b93a52194a0964220d10d92ee7497346f146a8b6ef8ab","price_changes":[{"asset_id":"17406866367975599232214757606801140480252276357934486651183783311435802862074","best_ask":"0.17","best_bid":"0.16","hash":"3b15b2b5bc8bbe169ad42077891534c20f76ae1d","price":"0.02","side":"BUY","size":"2067.69"},{"asset_id":"2151378744569768920256500242561922410292857798164019061749528550808091180185","best_ask":"0.84","best_bid":"0.83","hash":"1817a5cc9421f1395a98f59cabd6fbba7d3fd4f3","price":"0.98","side":"SELL","size":"2067.69"}],"timestamp":"1786845517187"}}
{"f":680,"recv_ms":1786845517402,"raw":{"event_type":"price_change","market":"0xd5f15f31689703aea70b93a52194a0964220d10d92ee7497346f146a8b6ef8ab","price_changes":[{"asset_id":"17406866367975599232214757606801140480252276357934486651183783311435802862074","best_ask":"0.17","best_bid":"0.16","hash":"bf98681e3014fa854875d568acc325400158360c","price":"0.01","side":"BUY","size":"5888.18"},{"asset_id":"2151378744569768920256500242561922410292857798164019061749528550808091180185","best_ask":"0.84","best_bid":"0.83","hash":"2818135d15a27eb280301a96d9054f3c3f5e368c","price":"0.99","side":"SELL","size":"5888.18"}],"timestamp":"1786845517188"}}
{"f":681,"recv_ms":1786845517402,"raw":{"event_type":"price_change","market":"0xd5f15f31689703aea70b93a52194a0964220d10d92ee7497346f146a8b6ef8ab","price_changes":[{"asset_id":"17406866367975599232214757606801140480252276357934486651183783311435802862074","best_ask":"0.17","best_bid":"0.16","hash":"135db333521cff444e250cdd982ee2d268a2bc77","price":"0.01","side":"BUY","size":"6088.18"},{"asset_id":"2151378744569768920256500242561922410292857798164019061749528550808091180185","best_ask":"0.84","best_bid":"0.83","hash":"4814c606bd5c647247a5cba73bd8940ecca0d9fe","price":"0.99","side":"SELL","size":"6088.18"}],"timestamp":"1786845517189"}}
{"f":682,"recv_ms":1786845517412,"raw":{"event_type":"price_change","market":"0xd5f15f31689703aea70b93a52194a0964220d10d92ee7497346f146a8b6ef8ab","price_changes":[{"asset_id":"17406866367975599232214757606801140480252276357934486651183783311435802862074","best_ask":"0.17","best_bid":"0.16","hash":"1740c08b55876451fdfa7a1f75b8267e7782e5db","price":"0.01","side":"BUY","size":"6083.18"},{"asset_id":"2151378744569768920256500242561922410292857798164019061749528550808091180185","best_ask":"0.84","best_bid":"0.83","hash":"16b9d191261442b1f144aaf8100ee7c5572ebcc2","price":"0.99","side":"SELL","size":"6083.18"}],"timestamp":"1786845517190"}}
{"f":683,"recv_ms":1786845517412,"raw":{"event_type":"price_change","market":"0xd5f15f31689703aea70b93a52194a0964220d10d92ee7497346f146a8b6ef8ab","price_changes":[{"asset_id":"2151378744569768920256500242561922410292857798164019061749528550808091180185","best_ask":"0.84","best_bid":"0.83","hash":"58f6eab658b882cd674f0a1ebda4d7aeebe33936","price":"0.01","side":"BUY","size":"5757.53"},{"asset_id":"17406866367975599232214757606801140480252276357934486651183783311435802862074","best_ask":"0.17","best_bid":"0.16","hash":"583f193704a38b12c0188567cf100924c8507143","price":"0.99","side":"SELL","size":"5757.53"}],"timestamp":"1786845517198"}}
{"f":684,"recv_ms":1786845517427,"raw":{"event_type":"price_change","market":"0xd5f15f31689703aea70b93a52194a0964220d10d92ee7497346f146a8b6ef8ab","price_changes":[{"asset_id":"2151378744569768920256500242561922410292857798164019061749528550808091180185","best_ask":"0.84","best_bid":"0.83","hash":"c32ab3d600d831f6742c37f76c66ac1e70ec52a5","price":"0.01","side":"BUY","size":"5857.53"},{"asset_id":"17406866367975599232214757606801140480252276357934486651183783311435802862074","best_ask":"0.17","best_bid":"0.16","hash":"ce57b8e9a2e19334e0ca93eaec5061945b1d65bc","price":"0.99","side":"SELL","size":"5857.53"}],"timestamp":"1786845517214"}}
{"f":685,"recv_ms":1786845517429,"raw":{"event_type":"price_change","market":"0xd5f15f31689703aea70b93a52194a0964220d10d92ee7497346f146a8b6ef8ab","price_changes":[{"asset_id":"17406866367975599232214757606801140480252276357934486651183783311435802862074","best_ask":"0.17","best_bid":"0.16","hash":"be49c47c7bf31ac2d0e351237085690fc77ce0ef","price":"0.01","side":"BUY","size":"6088.18"},{"asset_id":"2151378744569768920256500242561922410292857798164019061749528550808091180185","best_ask":"0.84","best_bid":"0.83","hash":"3f0290b2af5fe6afb789a66712c1968c16b0d438","price":"0.99","side":"SELL","size":"6088.18"}],"timestamp":"1786845517216"}}
{"f":686,"recv_ms":1786845517429,"raw":{"event_type":"price_change","market":"0xd5f15f31689703aea70b93a52194a0964220d10d92ee7497346f146a8b6ef8ab","price_changes":[{"asset_id":"17406866367975599232214757606801140480252276357934486651183783311435802862074","best_ask":"0.17","best_bid":"0.16","hash":"676828347c680e68d61360ce003ab95a5315e4f2","price":"0.01","side":"BUY","size":"6083.18"},{"asset_id":"2151378744569768920256500242561922410292857798164019061749528550808091180185","best_ask":"0.84","best_bid":"0.83","hash":"67ee4d849844c9f3ac98d6dae2d4d592cad8cdaf","price":"0.99","side":"SELL","size":"6083.18"}],"timestamp":"1786845517217"}}
{"f":687,"recv_ms":1786845517436,"raw":{"event_type":"price_change","market":"0xd5f15f31689703aea70b93a52194a0964220d10d92ee7497346f146a8b6ef8ab","price_changes":[{"asset_id":"2151378744569768920256500242561922410292857798164019061749528550808091180185","best_ask":"0.84","best_bid":"0.83","hash":"971992ac49bc016961b5569dafaf33337ce17c7a","price":"0.01","side":"BUY","size":"5863.53"},{"asset_id":"17406866367975599232214757606801140480252276357934486651183783311435802862074","best_ask":"0.17","best_bid":"0.16","hash":"9ff186988e225480d90d10c56ba8159474e9706b","price":"0.99","side":"SELL","size":"5863.53"}],"timestamp":"1786845517219"}}
{"f":688,"recv_ms":1786845517436,"raw":{"event_type":"price_change","market":"0xd5f15f31689703aea70b93a52194a0964220d10d92ee7497346f146a8b6ef8ab","price_changes":[{"asset_id":"17406866367975599232214757606801140480252276357934486651183783311435802862074","best_ask":"0.17","best_bid":"0.16","hash":"a1aebf14f8bf473b1b46c0f72f1c502b38317bfe","price":"0.01","side":"BUY","size":"6078.18"},{"asset_id":"2151378744569768920256500242561922410292857798164019061749528550808091180185","best_ask":"0.84","best_bid":"0.83","hash":"a1c196d209278e705454b40f00b30e17084ae5a1","price":"0.99","side":"SELL","size":"6078.18"}],"timestamp":"1786845517220"}}
{"f":689,"recv_ms":1786845517439,"raw":{"event_type":"price_change","market":"0xd5f15f31689703aea70b93a52194a0964220d10d92ee7497346f146a8b6ef8ab","price_changes":[{"asset_id":"17406866367975599232214757606801140480252276357934486651183783311435802862074","best_ask":"0.17","best_bid":"0.16","hash":"0fbece779360a3093f5a6a57d88b3a73923e3216","price":"0.01","side":"BUY","size":"6083.18"},{"asset_id":"2151378744569768920256500242561922410292857798164019061749528550808091180185","best_ask":"0.84","best_bid":"0.83","hash":"7a4745fe28e62b8642408d8cdde4e22df0364385","price":"0.99","side":"SELL","size":"6083.18"}],"timestamp":"1786845517224"}}
{"f":690,"recv_ms":1786845517457,"raw":{"event_type":"price_change","market":"0xd5f15f31689703aea70b93a52194a0964220d10d92ee7497346f146a8b6ef8ab","price_changes":[{"asset_id":"2151378744569768920256500242561922410292857798164019061749528550808091180185","best_ask":"0.84","best_bid":"0.83","hash":"4badaa3c020e9346096f1e47cbc48ab2c561d17a","price":"0.01","side":"BUY","size":"5858.53"},{"asset_id":"17406866367975599232214757606801140480252276357934486651183783311435802862074","best_ask":"0.17","best_bid":"0.16","hash":"96abd86f0ba92fbcd67ac3c4d3114be54544f10b","price":"0.99","side":"SELL","size":"5858.53"}],"timestamp":"1786845517234"}}
{"f":691,"recv_ms":1786845517467,"raw":{"event_type":"price_change","market":"0xd5f15f31689703aea70b93a52194a0964220d10d92ee7497346f146a8b6ef8ab","price_changes":[{"asset_id":"2151378744569768920256500242561922410292857798164019061749528550808091180185","best_ask":"0.84","best_bid":"0.83","hash":"ff008b4ab4cb67c1970c117cfe26e58d30d940e3","price":"0.01","side":"BUY","size":"5852.53"},{"asset_id":"17406866367975599232214757606801140480252276357934486651183783311435802862074","best_ask":"0.17","best_bid":"0.16","hash":"585e9c1d41fc5446440030961544c3a101e63b88","price":"0.99","side":"SELL","size":"5852.53"}],"timestamp":"1786845517247"}}
{"f":692,"recv_ms":1786845517467,"raw":{"event_type":"price_change","market":"0xd5f15f31689703aea70b93a52194a0964220d10d92ee7497346f146a8b6ef8ab","price_changes":[{"asset_id":"2151378744569768920256500242561922410292857798164019061749528550808091180185","best_ask":"0.84","best_bid":"0.83","hash":"838e5c53ac88940c466a4ee9871355342c882e70","price":"0.01","side":"BUY","size":"5752.53"},{"asset_id":"17406866367975599232214757606801140480252276357934486651183783311435802862074","best_ask":"0.17","best_bid":"0.16","hash":"95572ba284fdcb4b5021e962235df54db239e787","price":"0.99","side":"SELL","size":"5752.53"}],"timestamp":"1786845517249"}}
{"f":693,"recv_ms":1786845517495,"raw":{"event_type":"price_change","market":"0xd5f15f31689703aea70b93a52194a0964220d10d92ee7497346f146a8b6ef8ab","price_changes":[{"asset_id":"2151378744569768920256500242561922410292857798164019061749528550808091180185","best_ask":"0.84","best_bid":"0.83","hash":"6785ed20a8eecc2968c4016cea70e421a2e06a23","price":"0.64","side":"BUY","size":"246.49"},{"asset_id":"17406866367975599232214757606801140480252276357934486651183783311435802862074","best_ask":"0.17","best_bid":"0.16","hash":"5a62d750a53f0d962ea2f0cfaf888fff2cb9c882","price":"0.36","side":"SELL","size":"246.49"}],"timestamp":"1786845517266"}}
{"f":694,"recv_ms":1786845517519,"raw":{"event_type":"price_change","market":"0xd5f15f31689703aea70b93a52194a0964220d10d92ee7497346f146a8b6ef8ab","price_changes":[{"asset_id":"2151378744569768920256500242561922410292857798164019061749528550808091180185","best_ask":"0.84","best_bid":"0.83","hash":"f0ae59ac09c4a6d425a4f9195f6af35e04788dbb","price":"0.01","side":"BUY","size":"5852.53"},{"asset_id":"17406866367975599232214757606801140480252276357934486651183783311435802862074","best_ask":"0.17","best_bid":"0.16","hash":"3901432bf4d612b470ba981e3c9fe9a5f8aed2cb","price":"0.99","side":"SELL","size":"5852.53"}],"timestamp":"1786845517293"}}
{"f":695,"recv_ms":1786845517522,"raw":{"event_type":"price_change","market":"0xd5f15f31689703aea70b93a52194a0964220d10d92ee7497346f146a8b6ef8ab","price_changes":[{"asset_id":"2151378744569768920256500242561922410292857798164019061749528550808091180185","best_ask":"0.84","best_bid":"0.83","hash":"68437a440f655ef7d74ea3c1ffac905106947e56","price":"0.65","side":"BUY","size":"23.71"},{"asset_id":"17406866367975599232214757606801140480252276357934486651183783311435802862074","best_ask":"0.17","best_bid":"0.16","hash":"375f1eb83876b54effd8d2adc5c3c7320350f3dc","price":"0.35","side":"SELL","size":"23.71"}],"timestamp":"1786845517308"}}
{"f":696,"recv_ms":1786845517533,"raw":{"event_type":"price_change","market":"0xd5f15f31689703aea70b93a52194a0964220d10d92ee7497346f146a8b6ef8ab","price_changes":[{"asset_id":"2151378744569768920256500242561922410292857798164019061749528550808091180185","best_ask":"0.84","best_bid":"0.83","hash":"636cbe043c8545adb8f8dc5059ea977dde2c0c38","price":"0.01","side":"BUY","size":"5858.53"},{"asset_id":"17406866367975599232214757606801140480252276357934486651183783311435802862074","best_ask":"0.17","best_bid":"0.16","hash":"d351cb2a64e120422cb9d28aef11a86742fa53d3","price":"0.99","side":"SELL","size":"5858.53"}],"timestamp":"1786845517316"}}
{"f":697,"recv_ms":1786845517550,"raw":{"event_type":"price_change","market":"0xd5f15f31689703aea70b93a52194a0964220d10d92ee7497346f146a8b6ef8ab","price_changes":[{"asset_id":"2151378744569768920256500242561922410292857798164019061749528550808091180185","best_ask":"0.84","best_bid":"0.83","hash":"4dc4c295f931f42a686748003a65056d0cddc716","price":"0.01","side":"BUY","size":"5758.53"},{"asset_id":"17406866367975599232214757606801140480252276357934486651183783311435802862074","best_ask":"0.17","best_bid":"0.16","hash":"6451abb8cac95365df1c21b2b054a280ba735a9a","price":"0.99","side":"SELL","size":"5758.53"}],"timestamp":"1786845517323"}}
{"f":698,"recv_ms":1786845517550,"raw":{"event_type":"price_change","market":"0xd5f15f31689703aea70b93a52194a0964220d10d92ee7497346f146a8b6ef8ab","price_changes":[{"asset_id":"2151378744569768920256500242561922410292857798164019061749528550808091180185","best_ask":"0.84","best_bid":"0.83","hash":"d365a9d9dca1cb4a6b7dfda7ae8a7691ab847842","price":"0.01","side":"BUY","size":"5763.53"},{"asset_id":"17406866367975599232214757606801140480252276357934486651183783311435802862074","best_ask":"0.17","best_bid":"0.16","hash":"799afb4acee8d1545c5f99efea9e196a564dc3e0","price":"0.99","side":"SELL","size":"5763.53"}],"timestamp":"1786845517339"}}
{"f":699,"recv_ms":1786845517556,"raw":{"event_type":"price_change","market":"0xd5f15f31689703aea70b93a52194a0964220d10d92ee7497346f146a8b6ef8ab","price_changes":[{"asset_id":"2151378744569768920256500242561922410292857798164019061749528550808091180185","best_ask":"0.84","best_bid":"0.83","hash":"4db595817b5020bb237ccdb21d4c7d07e79305fb","price":"0.01","side":"BUY","size":"5768.53"},{"asset_id":"17406866367975599232214757606801140480252276357934486651183783311435802862074","best_ask":"0.17","best_bid":"0.16","hash":"0181bef9ddac20a033382f093aa202d5f2cd8951","price":"0.99","side":"SELL","size":"5768.53"}],"timestamp":"1786845517340"}}
{"f":700,"recv_ms":1786845517556,"raw":{"event_type":"price_change","market":"0xd5f15f31689703aea70b93a52194a0964220d10d92ee7497346f146a8b6ef8ab","price_changes":[{"asset_id":"2151378744569768920256500242561922410292857798164019061749528550808091180185","best_ask":"0.84","best_bid":"0.83","hash":"42a338180a095729e9359863c801f80bfcdecd3e","price":"0.01","side":"BUY","size":"5773.53"},{"asset_id":"17406866367975599232214757606801140480252276357934486651183783311435802862074","best_ask":"0.17","best_bid":"0.16","hash":"c39859f257efdab5608a6adbd51d565109556936","price":"0.99","side":"SELL","size":"5773.53"}],"timestamp":"1786845517340"}}
{"f":701,"recv_ms":1786845517563,"raw":{"event_type":"price_change","market":"0xd5f15f31689703aea70b93a52194a0964220d10d92ee7497346f146a8b6ef8ab","price_changes":[{"asset_id":"2151378744569768920256500242561922410292857798164019061749528550808091180185","best_ask":"0.84","best_bid":"0.83","hash":"8d33e26e026eb1dd41a017db73972b40e843d91b","price":"0.01","side":"BUY","size":"5767.53"},{"asset_id":"17406866367975599232214757606801140480252276357934486651183783311435802862074","best_ask":"0.17","best_bid":"0.16","hash":"b70ffc728ce071b4bf15ab7d2907e72b6d1281be","price":"0.99","side":"SELL","size":"5767.53"}],"timestamp":"1786845517345"}}
{"f":702,"recv_ms":1786845517563,"raw":{"event_type":"price_change","market":"0xd5f15f31689703aea70b93a52194a0964220d10d92ee7497346f146a8b6ef8ab","price_changes":[{"asset_id":"2151378744569768920256500242561922410292857798164019061749528550808091180185","best_ask":"0.84","best_bid":"0.83","hash":"daefe65d3baf293de037813f1c2829e53abf97ea","price":"0.65","side":"BUY","size":"18"},{"asset_id":"17406866367975599232214757606801140480252276357934486651183783311435802862074","best_ask":"0.17","best_bid":"0.16","hash":"632a6699d96b8296611d8b27c882537f24ee4070","price":"0.35","side":"SELL","size":"18"}],"timestamp":"1786845517350"}}
{"f":703,"recv_ms":1786845517577,"raw":{"event_type":"price_change","market":"0xd5f15f31689703aea70b93a52194a0964220d10d92ee7497346f146a8b6ef8ab","price_changes":[{"asset_id":"2151378744569768920256500242561922410292857798164019061749528550808091180185","best_ask":"0.84","best_bid":"0.83","hash":"a68cb5360c1af26ef5a29b0ca992b346a370cc55","price":"0.01","side":"BUY","size":"5772.54"},{"asset_id":"17406866367975599232214757606801140480252276357934486651183783311435802862074","best_ask":"0.17","best_bid":"0.16","hash":"5554c8afef8853ece961d9bb31c37cc4fcde8f19","price":"0.99","side":"SELL","size":"5772.54"}],"timestamp":"1786845517353"}}
{"f":704,"recv_ms":1786845517604,"raw":{"event_type":"price_change","market":"0xd5f15f31689703aea70b93a52194a0964220d10d92ee7497346f146a8b6ef8ab","price_changes":[{"asset_id":"2151378744569768920256500242561922410292857798164019061749528550808091180185","best_ask":"0.84","best_bid":"0.83","hash":"c5821ef90a3ae420dceee7f751127cd903b2106f","price":"0.01","side":"BUY","size":"5767.54"},{"asset_id":"17406866367975599232214757606801140480252276357934486651183783311435802862074","best_ask":"0.17","best_bid":"0.16","hash":"5b1dae57f869e8822aa89dfa32c444ed43142adc","price":"0.99","side":"SELL","size":"5767.54"}],"timestamp":"1786845517373"}}
{"f":705,"recv_ms":1786845517604,"raw":{"event_type":"price_change","market":"0xd5f15f31689703aea70b93a52194a0964220d10d92ee7497346f146a8b6ef8ab","price_changes":[{"asset_id":"2151378744569768920256500242561922410292857798164019061749528550808091180185","best_ask":"0.84","best_bid":"0.83","hash":"88e8f744a47eeb270b172d8b370f1d24778d3590","price":"0.01","side":"BUY","size":"5867.54"},{"asset_id":"17406866367975599232214757606801140480252276357934486651183783311435802862074","best_ask":"0.17","best_bid":"0.16","hash":"302d839fe2c54dcd1f37e500f1e2fb57661ff84a","price":"0.99","side":"SELL","size":"5867.54"}],"timestamp":"1786845517374"}}
{"f":706,"recv_ms":1786845517604,"raw":{"event_type":"price_change","market":"0xd5f15f31689703aea70b93a52194a0964220d10d92ee7497346f146a8b6ef8ab","price_changes":[{"asset_id":"2151378744569768920256500242561922410292857798164019061749528550808091180185","best_ask":"0.84","best_bid":"0.83","hash":"931eee6ca540699d49c414ef8bd375f1b60ff8bc","price":"0.01","side":"BUY","size":"5862.53"},{"asset_id":"17406866367975599232214757606801140480252276357934486651183783311435802862074","best_ask":"0.17","best_bid":"0.16","hash":"03436f939cc9d9a8e61747c06877bbeec69eb97c","price":"0.99","side":"SELL","size":"5862.53"}],"timestamp":"1786845517378"}}
{"f":707,"recv_ms":1786845517607,"raw":{"event_type":"price_change","market":"0xd5f15f31689703aea70b93a52194a0964220d10d92ee7497346f146a8b6ef8ab","price_changes":[{"asset_id":"2151378744569768920256500242561922410292857798164019061749528550808091180185","best_ask":"0.84","best_bid":"0.83","hash":"3a492ef854c649ee5c599ee617f921869caea5da","price":"0.65","side":"BUY","size":"23.71"},{"asset_id":"17406866367975599232214757606801140480252276357934486651183783311435802862074","best_ask":"0.17","best_bid":"0.16","hash":"2308e854a4874b22a0ab6bf4b6827eb92b7e348b","price":"0.35","side":"SELL","size":"23.71"}],"timestamp":"1786845517392"}}
{"f":708,"recv_ms":1786845517620,"raw":{"event_type":"price_change","market":"0xd5f15f31689703aea70b93a52194a0964220d10d92ee7497346f146a8b6ef8ab","price_changes":[{"asset_id":"2151378744569768920256500242561922410292857798164019061749528550808091180185","best_ask":"0.84","best_bid":"0.83","hash":"c9aa010f06122a367e32345186adfe3071676a09","price":"0.01","side":"BUY","size":"5762.53"},{"asset_id":"17406866367975599232214757606801140480252276357934486651183783311435802862074","best_ask":"0.17","best_bid":"0.16","hash":"3ac3f774a8f3586c4910e28e67a898f90f2e7607","price":"0.99","side":"SELL","size":"5762.53"}],"timestamp":"1786845517408"}}
{"f":709,"recv_ms":1786845517632,"raw":{"event_type":"price_change","market":"0xd5f15f31689703aea70b93a52194a0964220d10d92ee7497346f146a8b6ef8ab","price_changes":[{"asset_id":"2151378744569768920256500242561922410292857798164019061749528550808091180185","best_ask":"0.84","best_bid":"0.83","hash":"3720401b9d76935f7b44b92cec5b2d501fbfb93e","price":"0.01","side":"BUY","size":"5757.53"},{"asset_id":"17406866367975599232214757606801140480252276357934486651183783311435802862074","best_ask":"0.17","best_bid":"0.16","hash":"d2b345a300617cf4cc17a91c316483440543d780","price":"0.99","side":"SELL","size":"5757.53"}],"timestamp":"1786845517409"}}
{"f":710,"recv_ms":1786845517632,"raw":{"event_type":"price_change","market":"0xd5f15f31689703aea70b93a52194a0964220d10d92ee7497346f146a8b6ef8ab","price_changes":[{"asset_id":"2151378744569768920256500242561922410292857798164019061749528550808091180185","best_ask":"0.84","best_bid":"0.83","hash":"af6be4467db60605b1bd0b32f534bb5006286048","price":"0.01","side":"BUY","size":"5763.53"},{"asset_id":"17406866367975599232214757606801140480252276357934486651183783311435802862074","best_ask":"0.17","best_bid":"0.16","hash":"a4bd7e29e7319bcaadfc8e413630b39ce4e281d7","price":"0.99","side":"SELL","size":"5763.53"}],"timestamp":"1786845517419"}}
{"f":711,"recv_ms":1786845517634,"raw":{"event_type":"price_change","market":"0xd5f15f31689703aea70b93a52194a0964220d10d92ee7497346f146a8b6ef8ab","price_changes":[{"asset_id":"2151378744569768920256500242561922410292857798164019061749528550808091180185","best_ask":"0.84","best_bid":"0.83","hash":"899662f62cb147ef2a4663b18f9e766aaf4a2d47","price":"0.01","side":"BUY","size":"5768.53"},{"asset_id":"17406866367975599232214757606801140480252276357934486651183783311435802862074","best_ask":"0.17","best_bid":"0.16","hash":"6b0850754f0ab333f2114e577106c4abcba49d3d","price":"0.99","side":"SELL","size":"5768.53"}],"timestamp":"1786845517420"}}
{"f":712,"recv_ms":1786845517635,"raw":{"event_type":"price_change","market":"0xd5f15f31689703aea70b93a52194a0964220d10d92ee7497346f146a8b6ef8ab","price_changes":[{"asset_id":"2151378744569768920256500242561922410292857798164019061749528550808091180185","best_ask":"0.84","best_bid":"0.83","hash":"9f440e37bd0a647fb30b0ee66b4569c0f76f0c59","price":"0.01","side":"BUY","size":"5763.53"},{"asset_id":"17406866367975599232214757606801140480252276357934486651183783311435802862074","best_ask":"0.17","best_bid":"0.16","hash":"18f6ba6162f7d557b7cad68307f9c2a0eaf2fed9","price":"0.99","side":"SELL","size":"5763.53"}],"timestamp":"1786845517421"}}
{"f":713,"recv_ms":1786845517642,"raw":{"event_type":"price_change","market":"0xd5f15f31689703aea70b93a52194a0964220d10d92ee7497346f146a8b6ef8ab","price_changes":[{"asset_id":"2151378744569768920256500242561922410292857798164019061749528550808091180185","best_ask":"0.84","best_bid":"0.83","hash":"7a82174920541e6a429429833d0e1a98bde4f475","price":"0.01","side":"BUY","size":"5758.53"},{"asset_id":"17406866367975599232214757606801140480252276357934486651183783311435802862074","best_ask":"0.17","best_bid":"0.16","hash":"6f9c2c2902bfa731012e434660a74e3ffb6dae9d","price":"0.99","side":"SELL","size":"5758.53"}],"timestamp":"1786845517429"}}
{"f":714,"recv_ms":1786845517655,"raw":{"event_type":"price_change","market":"0xd5f15f31689703aea70b93a52194a0964220d10d92ee7497346f146a8b6ef8ab","price_changes":[{"asset_id":"2151378744569768920256500242561922410292857798164019061749528550808091180185","best_ask":"0.84","best_bid":"0.83","hash":"e7bf61318e943c967215a03f6d26c93b90509c89","price":"0.01","side":"BUY","size":"5763.53"},{"asset_id":"17406866367975599232214757606801140480252276357934486651183783311435802862074","best_ask":"0.17","best_bid":"0.16","hash":"ba76025a9e4b25db4e0a8c7ab03b7abc81f17910","price":"0.99","side":"SELL","size":"5763.53"}],"timestamp":"1786845517431"}}
{"f":715,"recv_ms":1786845517655,"raw":{"event_type":"price_change","market":"0xd5f15f31689703aea70b93a52194a0964220d10d92ee7497346f146a8b6ef8ab","price_changes":[{"asset_id":"2151378744569768920256500242561922410292857798164019061749528550808091180185","best_ask":"0.84","best_bid":"0.83","hash":"12ef7a3dfdd9c59595e136c738efdeaf18aa2125","price":"0.01","side":"BUY","size":"5758.53"},{"asset_id":"17406866367975599232214757606801140480252276357934486651183783311435802862074","best_ask":"0.17","best_bid":"0.16","hash":"6d4808c1e91b1a31ba489e7668e82ac85fcc235c","price":"0.99","side":"SELL","size":"5758.53"}],"timestamp":"1786845517440"}}
{"f":716,"recv_ms":1786845517662,"raw":{"event_type":"price_change","market":"0xd5f15f31689703aea70b93a52194a0964220d10d92ee7497346f146a8b6ef8ab","price_changes":[{"asset_id":"2151378744569768920256500242561922410292857798164019061749528550808091180185","best_ask":"0.84","best_bid":"0.83","hash":"a641f403a7306f87e2c9d1d637cfd22a50457e66","price":"0.01","side":"BUY","size":"5752.53"},{"asset_id":"17406866367975599232214757606801140480252276357934486651183783311435802862074","best_ask":"0.17","best_bid":"0.16","hash":"faa702e82a7826224b122335050870fb96d52f98","price":"0.99","side":"SELL","size":"5752.53"}],"timestamp":"1786845517444"}}
{"f":717,"recv_ms":1786845517690,"raw":{"event_type":"price_change","market":"0xd5f15f31689703aea70b93a52194a0964220d10d92ee7497346f146a8b6ef8ab","price_changes":[{"asset_id":"2151378744569768920256500242561922410292857798164019061749528550808091180185","best_ask":"0.84","best_bid":"0.83","hash":"5f267c9dcb4da843f5d28f8446fc8dd562d47fe9","price":"0.01","side":"BUY","size":"5852.53"},{"asset_id":"17406866367975599232214757606801140480252276357934486651183783311435802862074","best_ask":"0.17","best_bid":"0.16","hash":"61909d2cf92bcff445075c602f7fe9f5ae76d50a","price":"0.99","side":"SELL","size":"5852.53"}],"timestamp":"1786845517453"}}
{"f":718,"recv_ms":1786845519295,"raw":{"event_type":"price_change","market":"0xd5f15f31689703aea70b93a52194a0964220d10d92ee7497346f146a8b6ef8ab","price_changes":[{"asset_id":"2151378744569768920256500242561922410292857798164019061749528550808091180185","best_ask":"0.84","best_bid":"0.83","hash":"570838c5023037f581b6bbc5b6bf05ff0186709b","price":"0.5","side":"BUY","size":"650.4"},{"asset_id":"17406866367975599232214757606801140480252276357934486651183783311435802862074","best_ask":"0.17","best_bid":"0.16","hash":"8e2aec5c953a10f7dda7fa6d2df646ffbe2e0f07","price":"0.5","side":"SELL","size":"650.4"}],"timestamp":"1786845517479"}}
{"f":719,"recv_ms":1786845519295,"raw":{"event_type":"price_change","market":"0xd5f15f31689703aea70b93a52194a0964220d10d92ee7497346f146a8b6ef8ab","price_changes":[{"asset_id":"2151378744569768920256500242561922410292857798164019061749528550808091180185","best_ask":"0.84","best_bid":"0.83","hash":"0644277b71e45a43fc013ec64f093545ae94ec54","price":"0.01","side":"BUY","size":"5752.53"},{"asset_id":"17406866367975599232214757606801140480252276357934486651183783311435802862074","best_ask":"0.17","best_bid":"0.16","hash":"5b7ab53207a466100421ba0e60ad73eb833b8da7","price":"0.99","side":"SELL","size":"5752.53"}],"timestamp":"1786845519026"}}
{"f":720,"recv_ms":1786845519295,"raw":{"event_type":"price_change","market":"0xd5f15f31689703aea70b93a52194a0964220d10d92ee7497346f146a8b6ef8ab","price_changes":[{"asset_id":"2151378744569768920256500242561922410292857798164019061749528550808091180185","best_ask":"0.84","best_bid":"0.83","hash":"67f421f4e5cd7e9834a309c3cf17eb4bba8828cb","price":"0.01","side":"BUY","size":"5758.53"},{"asset_id":"17406866367975599232214757606801140480252276357934486651183783311435802862074","best_ask":"0.17","best_bid":"0.16","hash":"8737a0b851352e36f6ba5b56a36d8948ebcd0952","price":"0.99","side":"SELL","size":"5758.53"}],"timestamp":"1786845519026"}}
{"f":721,"recv_ms":1786845519312,"raw":{"event_type":"price_change","market":"0xf636967aa9d8794331ee10b9af364ea18fa3f1a9935f8c83ae9a249d8b08a931","price_changes":[{"asset_id":"91326336689285362968457805980185782713434399212786273576721749759222414518998","best_ask":"0.51","best_bid":"0.5","hash":"74a43ff488953d1d7535196b649df3f409941b9c","price":"0.13","side":"BUY","size":"18"},{"asset_id":"68567158191229273715522065688080768784240867677122603193993480690378524045921","best_ask":"0.5","best_bid":"0.49","hash":"1e3d151e7def6d6777d1c43f1f69f02b914597ee","price":"0.87","side":"SELL","size":"18"}],"timestamp":"1786845518280"}}
{"f":722,"recv_ms":1786845519312,"raw":{"event_type":"price_change","market":"0xd5f15f31689703aea70b93a52194a0964220d10d92ee7497346f146a8b6ef8ab","price_changes":[{"asset_id":"2151378744569768920256500242561922410292857798164019061749528550808091180185","best_ask":"0.84","best_bid":"0.83","hash":"d1f8177be231781e66b43d7758d227224e55a79f","price":"0.01","side":"BUY","size":"5858.53"},{"asset_id":"17406866367975599232214757606801140480252276357934486651183783311435802862074","best_ask":"0.17","best_bid":"0.16","hash":"c7e209dc66df2c0edb12f02819e785c0d10fd6e6","price":"0.99","side":"SELL","size":"5858.53"}],"timestamp":"1786845519051"}}
{"f":723,"recv_ms":1786845519325,"raw":{"event_type":"price_change","market":"0xd5f15f31689703aea70b93a52194a0964220d10d92ee7497346f146a8b6ef8ab","price_changes":[{"asset_id":"2151378744569768920256500242561922410292857798164019061749528550808091180185","best_ask":"0.84","best_bid":"0.83","hash":"6f87cbada657d4e063f5e6bf35cab6d79ca8a3cd","price":"0.01","side":"BUY","size":"5863.54"},{"asset_id":"17406866367975599232214757606801140480252276357934486651183783311435802862074","best_ask":"0.17","best_bid":"0.16","hash":"60887833b4db4dd8bf048dd8285540b55b0b5140","price":"0.99","side":"SELL","size":"5863.54"}],"timestamp":"1786845519100"}}
{"f":724,"recv_ms":1786845519332,"raw":{"event_type":"price_change","market":"0xd5f15f31689703aea70b93a52194a0964220d10d92ee7497346f146a8b6ef8ab","price_changes":[{"asset_id":"2151378744569768920256500242561922410292857798164019061749528550808091180185","best_ask":"0.84","best_bid":"0.83","hash":"fee2c963e0cb7438a43f42bca3a2e3fea9d327a9","price":"0.01","side":"BUY","size":"5868.54"},{"asset_id":"17406866367975599232214757606801140480252276357934486651183783311435802862074","best_ask":"0.17","best_bid":"0.16","hash":"6ae8d92cd9b7511bff4ae9844ec28a6c4065ebeb","price":"0.99","side":"SELL","size":"5868.54"}],"timestamp":"1786845519119"}}
{"f":725,"recv_ms":1786845519334,"raw":{"event_type":"price_change","market":"0xd5f15f31689703aea70b93a52194a0964220d10d92ee7497346f146a8b6ef8ab","price_changes":[{"asset_id":"2151378744569768920256500242561922410292857798164019061749528550808091180185","best_ask":"0.84","best_bid":"0.83","hash":"efe9712f597707b4a25832293dbf13c8b6679983","price":"0.82","side":"BUY","size":"110.66"},{"asset_id":"17406866367975599232214757606801140480252276357934486651183783311435802862074","best_ask":"0.17","best_bid":"0.16","hash":"aa9c24cc3f4b3e636e3e4dafcbc1dc9055be932b","price":"0.18","side":"SELL","size":"110.66"}],"timestamp":"1786845519121"}}
{"f":726,"recv_ms":1786845519334,"raw":{"event_type":"price_change","market":"0xd5f15f31689703aea70b93a52194a0964220d10d92ee7497346f146a8b6ef8ab","price_changes":[{"asset_id":"17406866367975599232214757606801140480252276357934486651183783311435802862074","best_ask":"0.17","best_bid":"0.16","hash":"ad1e5d09d2918632c7a2d485c248b08dcc4ab20d","price":"0.35","side":"SELL","size":"33.71"},{"asset_id":"2151378744569768920256500242561922410292857798164019061749528550808091180185","best_ask":"0.84","best_bid":"0.83","hash":"089dfc2f3c44ff767626e06bf9e364fd15961b8f","price":"0.65","side":"BUY","size":"33.71"}],"timestamp":"1786845519121"}}
{"f":727,"recv_ms":1786845519353,"raw":{"event_type":"price_change","market":"0xd5f15f31689703aea70b93a52194a0964220d10d92ee7497346f146a8b6ef8ab","price_changes":[{"asset_id":"17406866367975599232214757606801140480252276357934486651183783311435802862074","best_ask":"0.17","best_bid":"0.16","hash":"b0d5610e4128fbe99fb25855e70b739a9d3983b9","price":"0.16","side":"BUY","size":"38.33"},{"asset_id":"2151378744569768920256500242561922410292857798164019061749528550808091180185","best_ask":"0.84","best_bid":"0.83","hash":"ae7667d94fca54f158a4f1ae5207d7dfbf649bea","price":"0.84","side":"SELL","size":"38.33"}],"timestamp":"1786845519123"}}
{"f":728,"recv_ms":1786845519367,"raw":{"event_type":"price_change","market":"0xd5f15f31689703aea70b93a52194a0964220d10d92ee7497346f146a8b6ef8ab","price_changes":[{"asset_id":"2151378744569768920256500242561922410292857798164019061749528550808091180185","best_ask":"0.84","best_bid":"0.83","hash":"deed1589a7b7f92baba6a98a8732d3174f7f72b3","price":"0.9","side":"SELL","size":"53"},{"asset_id":"17406866367975599232214757606801140480252276357934486651183783311435802862074","best_ask":"0.17","best_bid":"0.16","hash":"26f30149d3a0caf07af972442d6a36da7c3c1c0c","price":"0.1","side":"BUY","size":"53"}],"timestamp":"1786845519153"}}
{"f":729,"recv_ms":1786845519367,"raw":{"event_type":"price_change","market":"0xd5f15f31689703aea70b93a52194a0964220d10d92ee7497346f146a8b6ef8ab","price_changes":[{"asset_id":"17406866367975599232214757606801140480252276357934486651183783311435802862074","best_ask":"0.17","best_bid":"0.16","hash":"60c3657ebcdbe76d6617e32395ba975f52f824a5","price":"0.1","side":"BUY","size":"40"},{"asset_id":"2151378744569768920256500242561922410292857798164019061749528550808091180185","best_ask":"0.84","best_bid":"0.83","hash":"da313b701208cd8e98c62823f6a166ceb43ddc27","price":"0.9","side":"SELL","size":"40"}],"timestamp":"1786845519153"}}
{"f":730,"recv_ms":1786845519367,"raw":{"event_type":"price_change","market":"0xd5f15f31689703aea70b93a52194a0964220d10d92ee7497346f146a8b6ef8ab","price_changes":[{"asset_id":"2151378744569768920256500242561922410292857798164019061749528550808091180185","best_ask":"0.84","best_bid":"0.83","hash":"d92a5cc9a8cef466a1cd2529ab1b1cf3915b6e49","price":"0.8","side":"BUY","size":"0"},{"asset_id":"17406866367975599232214757606801140480252276357934486651183783311435802862074","best_ask":"0.17","best_bid":"0.16","hash":"65620f0d58e2be5119ccdfacddc1ad772eb465fc","price":"0.2","side":"SELL","size":"0"}],"timestamp":"1786845519154"}}
{"f":731,"recv_ms":1786845519367,"raw":{"event_type":"price_change","market":"0xd5f15f31689703aea70b93a52194a0964220d10d92ee7497346f146a8b6ef8ab","price_changes":[{"asset_id":"2151378744569768920256500242561922410292857798164019061749528550808091180185","best_ask":"0.84","best_bid":"0.83","hash":"c54823fb69485470e73a4739bd7365afd90a9e62","price":"0.63","side":"BUY","size":"18"},{"asset_id":"17406866367975599232214757606801140480252276357934486651183783311435802862074","best_ask":"0.17","best_bid":"0.16","hash":"b292b2b7b4cc4404b9ffb3cf071c4ea9063393e0","price":"0.37","side":"SELL","size":"18"}],"timestamp":"1786845519154"}}
{"f":732,"recv_ms":1786845519367,"raw":{"event_type":"price_change","market":"0xd5f15f31689703aea70b93a52194a0964220d10d92ee7497346f146a8b6ef8ab","price_changes":[{"asset_id":"17406866367975599232214757606801140480252276357934486651183783311435802862074","best_ask":"0.17","best_bid":"0.16","hash":"6289ff2f76469b8a217ecfd0f0511f30b512588d","price":"0.11","side":"BUY","size":"10"},{"asset_id":"2151378744569768920256500242561922410292857798164019061749528550808091180185","best_ask":"0.84","best_bid":"0.83","hash":"dd9a1bcdab80240aa86bcd0fea081fcffb76f45c","price":"0.89","side":"SELL","size":"10"}],"timestamp":"1786845519154"}}
{"f":733,"recv_ms":1786845519368,"raw":{"event_type":"price_change","market":"0xd5f15f31689703aea70b93a52194a0964220d10d92ee7497346f146a8b6ef8ab","price_changes":[{"asset_id":"17406866367975599232214757606801140480252276357934486651183783311435802862074","best_ask":"0.17","best_bid":"0.16","hash":"fff7166e13d6caa0ac673ba3433a6abb3f850511","price":"0.01","side":"BUY","size":"5883.18"},{"asset_id":"2151378744569768920256500242561922410292857798164019061749528550808091180185","best_ask":"0.84","best_bid":"0.83","hash":"021a66e734e9af7350fffb5daf990391797a35a4","price":"0.99","side":"SELL","size":"5883.18"}],"timestamp":"1786845519155"}}
{"f":734,"recv_ms":1786845519368,"raw":{"event_type":"price_change","market":"0xd5f15f31689703aea70b93a52194a0964220d10d92ee7497346f146a8b6ef8ab","price_changes":[{"asset_id":"17406866367975599232214757606801140480252276357934486651183783311435802862074","best_ask":"0.17","best_bid":"0.16","hash":"cc2aa22664da2754b615082347a47eb9c4951c81","price":"0.01","side":"BUY","size":"5683.18"},{"asset_id":"2151378744569768920256500242561922410292857798164019061749528550808091180185","best_ask":"0.84","best_bid":"0.83","hash":"2445f59304d71d67ea027cdd5fdbea37feb57991","price":"0.99","side":"SELL","size":"5683.18"}],"timestamp":"1786845519155"}}
{"f":735,"recv_ms":1786845519382,"raw":{"event_type":"price_change","market":"0xd5f15f31689703aea70b93a52194a0964220d10d92ee7497346f146a8b6ef8ab","price_changes":[{"asset_id":"2151378744569768920256500242561922410292857798164019061749528550808091180185","best_ask":"0.84","best_bid":"0.83","hash":"eb98338aca590bc7dc6fbcf0b6bca5bc36e6b399","price":"0.74","side":"BUY","size":"13"},{"asset_id":"17406866367975599232214757606801140480252276357934486651183783311435802862074","best_ask":"0.17","best_bid":"0.16","hash":"73cd6ec7f2498f89ee71892516b0c57ff6c6d7e0","price":"0.26","side":"SELL","size":"13"}],"timestamp":"1786845519155"}}
{"f":736,"recv_ms":1786845519382,"raw":{"event_type":"price_change","market":"0xd5f15f31689703aea70b93a52194a0964220d10d92ee7497346f146a8b6ef8ab","price_changes":[{"asset_id":"2151378744569768920256500242561922410292857798164019061749528550808091180185","best_ask":"0.84","best_bid":"0.83","hash":"372ded075df9115dbe05f263b6d21502ee045440","price":"0.01","side":"BUY","size":"5873.54"},{"asset_id":"17406866367975599232214757606801140480252276357934486651183783311435802862074","best_ask":"0.17","best_bid":"0.16","hash":"d32c676045bc520d26f343c97008d3f8772501f8","price":"0.99","side":"SELL","size":"5873.54"}],"timestamp":"1786845519155"}}
{"f":737,"recv_ms":1786845519415,"raw":{"event_type":"price_change","market":"0xd5f15f31689703aea70b93a52194a0964220d10d92ee7497346f146a8b6ef8ab","price_changes":[{"asset_id":"17406866367975599232214757606801140480252276357934486651183783311435802862074","best_ask":"0.17","best_bid":"0.16","hash":"48eac7a056df0571bb1ddd883f19ace546a6d543","price":"0.3","side":"SELL","size":"40"},{"asset_id":"2151378744569768920256500242561922410292857798164019061749528550808091180185","best_ask":"0.84","best_bid":"0.83","hash":"643fc0a81833725a55b924d06485c00fa95bcf4c","price":"0.7","side":"BUY","size":"40"}],"timestamp":"1786845519199"}}
{"f":738,"recv_ms":1786845519415,"raw":{"event_type":"price_change","market":"0xd5f15f31689703aea70b93a52194a0964220d10d92ee7497346f146a8b6ef8ab","price_changes":[{"asset_id":"17406866367975599232214757606801140480252276357934486651183783311435802862074","best_ask":"0.17","best_bid":"0.16","hash":"645d3202d016122b3fe931ad4fc1b311b98ddac8","price":"0.32","side":"SELL","size":"30"},{"asset_id":"2151378744569768920256500242561922410292857798164019061749528550808091180185","best_ask":"0.84","best_bid":"0.83","hash":"144ceaaa4c5dbcc2be8e737881929535eb4566a2","price":"0.68","side":"BUY","size":"30"}],"timestamp":"1786845519200"}}
{"f":739,"recv_ms":1786845519415,"raw":{"event_type":"price_change","market":"0xd5f15f31689703aea70b93a52194a0964220d10d92ee7497346f146a8b6ef8ab","price_changes":[{"asset_id":"17406866367975599232214757606801140480252276357934486651183783311435802862074","best_ask":"0.17","best_bid":"0.16","hash":"cdd333c37504de2fe585868e15fe55ef0067f42f","price":"0.29","side":"SELL","size":"79"},{"asset_id":"2151378744569768920256500242561922410292857798164019061749528550808091180185","best_ask":"0.84","best_bid":"0.83","hash":"f5a7b85b2951510a0ccb688971d59e8b61a2a747","price":"0.71","side":"BUY","size":"79"}],"timestamp":"1786845519200"}}
{"f":740,"recv_ms":1786845519424,"raw":{"event_type":"price_change","market":"0xd5f15f31689703aea70b93a52194a0964220d10d92ee7497346f146a8b6ef8ab","price_changes":[{"asset_id":"2151378744569768920256500242561922410292857798164019061749528550808091180185","best_ask":"0.84","best_bid":"0.83","hash":"4ac1cbe84e0478a8a2e3060b8d409dbd0f2089ed","price":"0.01","side":"BUY","size":"5878.54"},{"asset_id":"17406866367975599232214757606801140480252276357934486651183783311435802862074","best_ask":"0.17","best_bid":"0.16","hash":"e5f0e6ac9ab656cf1c61e69a5d5aa9baf81a14a9","price":"0.99","side":"SELL","size":"5878.54"}],"timestamp":"1786845519203"}}
{"f":741,"recv_ms":1786845519432,"raw":{"event_type":"price_change","market":"0xd5f15f31689703aea70b93a52194a0964220d10d92ee7497346f146a8b6ef8ab","price_changes":[{"asset_id":"17406866367975599232214757606801140480252276357934486651183783311435802862074","best_ask":"0.17","best_bid":"0.16","hash":"dcd0a95f88083dee0917ef68e64674ec8d15eb27","price":"0.01","side":"BUY","size":"5688.18"},{"asset_id":"2151378744569768920256500242561922410292857798164019061749528550808091180185","best_ask":"0.84","best_bid":"0.83","hash":"89e017eda536f74c55f56d6daa27b982812ee907","price":"0.99","side":"SELL","size":"5688.18"}],"timestamp":"1786845519213"}}
{"f":742,"recv_ms":1786845519432,"raw":{"event_type":"price_change","market":"0xd5f15f31689703aea70b93a52194a0964220d10d92ee7497346f146a8b6ef8ab","price_changes":[{"asset_id":"17406866367975599232214757606801140480252276357934486651183783311435802862074","best_ask":"0.17","best_bid":"0.16","hash":"c84fd43e2a9d6cabc5b242faad50989987b772d6","price":"0.16","side":"BUY","size":"32.37"},{"asset_id":"2151378744569768920256500242561922410292857798164019061749528550808091180185","best_ask":"0.84","best_bid":"0.83","hash":"420cbd40fb726361fd961208f72817dd5935124e","price":"0.84","side":"SELL","size":"32.37"}],"timestamp":"1786845519219"}}
{"f":743,"recv_ms":1786845519468,"raw":{"event_type":"price_change","market":"0xd5f15f31689703aea70b93a52194a0964220d10d92ee7497346f146a8b6ef8ab","price_changes":[{"asset_id":"17406866367975599232214757606801140480252276357934486651183783311435802862074","best_ask":"0.17","best_bid":"0.16","hash":"841d3ffdba194d771a7c762e6c64148b6b7b9041","price":"0.01","side":"BUY","size":"5588.18"},{"asset_id":"2151378744569768920256500242561922410292857798164019061749528550808091180185","best_ask":"0.84","best_bid":"0.83","hash":"6984708e2a27618198d18bda7a91e9fce641c0c2","price":"0.99","side":"SELL","size":"5588.18"}],"timestamp":"1786845519254"}}
{"f":744,"recv_ms":1786845519471,"raw":{"event_type":"price_change","market":"0xd5f15f31689703aea70b93a52194a0964220d10d92ee7497346f146a8b6ef8ab","price_changes":[{"asset_id":"2151378744569768920256500242561922410292857798164019061749528550808091180185","best_ask":"0.84","best_bid":"0.83","hash":"ec6b0133e415137a69fcff6db6d960cb3589cd58","price":"0.53","side":"BUY","size":"569.64"},{"asset_id":"17406866367975599232214757606801140480252276357934486651183783311435802862074","best_ask":"0.17","best_bid":"0.16","hash":"c39522d6cfacdbd2cf9079bbc6930cb291939293","price":"0.47","side":"SELL","size":"569.64"}],"timestamp":"1786845519255"}}
{"f":745,"recv_ms":1786845519471,"raw":{"event_type":"price_change","market":"0xd5f15f31689703aea70b93a52194a0964220d10d92ee7497346f146a8b6ef8ab","price_changes":[{"asset_id":"2151378744569768920256500242561922410292857798164019061749528550808091180185","best_ask":"0.84","best_bid":"0.83","hash":"f239cbda04d32dd068185e2da21dafe4e84d4ead","price":"0.69","side":"BUY","size":"90"},{"asset_id":"17406866367975599232214757606801140480252276357934486651183783311435802862074","best_ask":"0.17","best_bid":"0.16","hash":"8358754c633a2fe34573cc57db5ce968f918f18f","price":"0.31","side":"SELL","size":"90"}],"timestamp":"1786845519255"}}
{"f":746,"recv_ms":1786845519471,"raw":{"event_type":"price_change","market":"0xd5f15f31689703aea70b93a52194a0964220d10d92ee7497346f146a8b6ef8ab","price_changes":[{"asset_id":"2151378744569768920256500242561922410292857798164019061749528550808091180185","best_ask":"0.84","best_bid":"0.83","hash":"86f03dfcb3708f6abc8ecbdbab1bd704cee02025","price":"0.77","side":"BUY","size":"45"},{"asset_id":"17406866367975599232214757606801140480252276357934486651183783311435802862074","best_ask":"0.17","best_bid":"0.16","hash":"579b197c979bd7a321d8c22a89d065553125c7bb","price":"0.23","side":"SELL","size":"45"}],"timestamp":"1786845519255"}}
{"f":747,"recv_ms":1786845519471,"raw":{"event_type":"price_change","market":"0xd5f15f31689703aea70b93a52194a0964220d10d92ee7497346f146a8b6ef8ab","price_changes":[{"asset_id":"2151378744569768920256500242561922410292857798164019061749528550808091180185","best_ask":"0.84","best_bid":"0.83","hash":"e2abd6e90e1c4a1ea93575d765886a4287cb3bf2","price":"0.52","side":"BUY","size":"140"},{"asset_id":"17406866367975599232214757606801140480252276357934486651183783311435802862074","best_ask":"0.17","best_bid":"0.16","hash":"b53a67e8363d1084d0d616c7d00b86c5c2bc8baa","price":"0.48","side":"SELL","size":"140"}],"timestamp":"1786845519256"}}
{"f":748,"recv_ms":1786845519474,"raw":{"event_type":"price_change","market":"0xd5f15f31689703aea70b93a52194a0964220d10d92ee7497346f146a8b6ef8ab","price_changes":[{"asset_id":"2151378744569768920256500242561922410292857798164019061749528550808091180185","best_ask":"0.84","best_bid":"0.83","hash":"c360b80a107f8432b82cd515dc3bbabfb601a261","price":"0.76","side":"BUY","size":"0"},{"asset_id":"17406866367975599232214757606801140480252276357934486651183783311435802862074","best_ask":"0.17","best_bid":"0.16","hash":"9c7992f11b220f189f8b0c77368c997786cf3484","price":"0.24","side":"SELL","size":"0"}],"timestamp":"1786845519262"}}
{"f":749,"recv_ms":1786845519476,"raw":{"event_type":"price_change","market":"0xd5f15f31689703aea70b93a52194a0964220d10d92ee7497346f146a8b6ef8ab","price_changes":[{"asset_id":"2151378744569768920256500242561922410292857798164019061749528550808091180185","best_ask":"0.84","best_bid":"0.83","hash":"fcf395e362ea5c8de2a0bc34286f53e94cacb154","price":"0.7","side":"BUY","size":"30"},{"asset_id":"17406866367975599232214757606801140480252276357934486651183783311435802862074","best_ask":"0.17","best_bid":"0.16","hash":"ffa9dca887bc6d4eb9d308e9975b94a86d09bd4e","price":"0.3","side":"SELL","size":"30"}],"timestamp":"1786845519263"}}
{"f":750,"recv_ms":1786845519500,"raw":{"event_type":"price_change","market":"0xd5f15f31689703aea70b93a52194a0964220d10d92ee7497346f146a8b6ef8ab","price_changes":[{"asset_id":"17406866367975599232214757606801140480252276357934486651183783311435802862074","best_ask":"0.17","best_bid":"0.16","hash":"b1514a1bb3f0f02023c17b920c1036b60d66cf51","price":"0.16","side":"BUY","size":"31.17"},{"asset_id":"2151378744569768920256500242561922410292857798164019061749528550808091180185","best_ask":"0.84","best_bid":"0.83","hash":"f307990575895a048df6e9cd3dccfea6b6026ee6","price":"0.84","side":"SELL","size":"31.17"}],"timestamp":"1786845519264"}}
{"f":751,"recv_ms":1786845519547,"raw":{"event_type":"price_change","market":"0xd5f15f31689703aea70b93a52194a0964220d10d92ee7497346f146a8b6ef8ab","price_changes":[{"asset_id":"2151378744569768920256500242561922410292857798164019061749528550808091180185","best_ask":"0.84","best_bid":"0.83","hash":"654b8a03ac585e7bac830793a8cfc13e07114734","price":"0.37","side":"BUY","size":"255.2"},{"asset_id":"17406866367975599232214757606801140480252276357934486651183783311435802862074","best_ask":"0.17","best_bid":"0.16","hash":"f0e3192a59a540d3ed34e8d16c0ac4d1de8469d8","price":"0.63","side":"SELL","size":"255.2"}],"timestamp":"1786845519279"}}
{"f":752,"recv_ms":1786845519547,"raw":{"event_type":"price_change","market":"0xd5f15f31689703aea70b93a52194a0964220d10d92ee7497346f146a8b6ef8ab","price_changes":[{"asset_id":"2151378744569768920256500242561922410292857798164019061749528550808091180185","best_ask":"0.84","best_bid":"0.83","hash":"40ddaae783e20ad8f3e5234990d74cf96db9f1af","price":"0.36","side":"BUY","size":"55.3"},{"asset_id":"17406866367975599232214757606801140480252276357934486651183783311435802862074","best_ask":"0.17","best_bid":"0.16","hash":"ab0318eee6f7b24a34b60bd9f0902086f70558a4","price":"0.64","side":"SELL","size":"55.3"}],"timestamp":"1786845519286"}}
{"f":753,"recv_ms":1786845519547,"raw":{"event_type":"price_change","market":"0xd5f15f31689703aea70b93a52194a0964220d10d92ee7497346f146a8b6ef8ab","price_changes":[{"asset_id":"17406866367975599232214757606801140480252276357934486651183783311435802862074","best_ask":"0.17","best_bid":"0.16","hash":"98f701750f07daab23249978aba982120f18100d","price":"0.07","side":"BUY","size":"359.86"},{"asset_id":"2151378744569768920256500242561922410292857798164019061749528550808091180185","best_ask":"0.84","best_bid":"0.83","hash":"f8b9a9abbbad3f6a5036d62010c57113c603cdaf","price":"0.93","side":"SELL","size":"359.86"}],"timestamp":"1786845519287"}}
{"f":754,"recv_ms":1786845519547,"raw":{"event_type":"price_change","market":"0xd5f15f31689703aea70b93a52194a0964220d10d92ee7497346f146a8b6ef8ab","price_changes":[{"asset_id":"2151378744569768920256500242561922410292857798164019061749528550808091180185","best_ask":"0.84","best_bid":"0.83","hash":"f5d2cb5f62c48fdcb73178948a9b55c7ff0add6f","price":"0.02","side":"BUY","size":"3116.85"},{"asset_id":"17406866367975599232214757606801140480252276357934486651183783311435802862074","best_ask":"0.17","best_bid":"0.16","hash":"7628ecde4a2df5127d0b39dd9f1f3b148ac2fe59","price":"0.98","side":"SELL","size":"3116.85"}],"timestamp":"1786845519287"}}
{"f":755,"recv_ms":1786845519565,"raw":{"event_type":"price_change","market":"0xd5f15f31689703aea70b93a52194a0964220d10d92ee7497346f146a8b6ef8ab","price_changes":[{"asset_id":"17406866367975599232214757606801140480252276357934486651183783311435802862074","best_ask":"0.17","best_bid":"0.16","hash":"35b4ce99cea7b1a381d0397fc0697896f572c140","price":"0.02","side":"BUY","size":"1992.69"},{"asset_id":"2151378744569768920256500242561922410292857798164019061749528550808091180185","best_ask":"0.84","best_bid":"0.83","hash":"5d46587f28c780ea812aafce180412da9f1e8682","price":"0.98","side":"SELL","size":"1992.69"}],"timestamp":"1786845519287"}}
{"f":756,"recv_ms":1786845519565,"raw":{"event_type":"price_change","market":"0xd5f15f31689703aea70b93a52194a0964220d10d92ee7497346f146a8b6ef8ab","price_changes":[{"asset_id":"17406866367975599232214757606801140480252276357934486651183783311435802862074","best_ask":"0.17","best_bid":"0.16","hash":"4724ee0fdc31600e4d72f3d5577d820972f11deb","price":"0.02","side":"BUY","size":"1917.69"},{"asset_id":"2151378744569768920256500242561922410292857798164019061749528550808091180185","best_ask":"0.84","best_bid":"0.83","hash":"086f782c07d2599675baeea0dde5fd9913bb9d44","price":"0.98","side":"SELL","size":"1917.69"}],"timestamp":"1786845519288"}}
{"f":757,"recv_ms":1786845519565,"raw":{"event_type":"price_change","market":"0xd5f15f31689703aea70b93a52194a0964220d10d92ee7497346f146a8b6ef8ab","price_changes":[{"asset_id":"2151378744569768920256500242561922410292857798164019061749528550808091180185","best_ask":"0.84","best_bid":"0.83","hash":"6a128b3cd6cf1c1a5151c0964f50381ad4719b33","price":"0.02","side":"BUY","size":"2408.52"},{"asset_id":"17406866367975599232214757606801140480252276357934486651183783311435802862074","best_ask":"0.17","best_bid":"0.16","hash":"4bee54ca7046722b9e800583743d883ea385ad56","price":"0.98","side":"SELL","size":"2408.52"}],"timestamp":"1786845519288"}}
{"f":758,"recv_ms":1786845519565,"raw":{"event_type":"price_change","market":"0xd5f15f31689703aea70b93a52194a0964220d10d92ee7497346f146a8b6ef8ab","price_changes":[{"asset_id":"2151378744569768920256500242561922410292857798164019061749528550808091180185","best_ask":"0.84","best_bid":"0.83","hash":"da7a9db15eb8f702727390856dd19f9858a9e715","price":"0.02","side":"BUY","size":"1700.19"},{"asset_id":"17406866367975599232214757606801140480252276357934486651183783311435802862074","best_ask":"0.17","best_bid":"0.16","hash":"840bd01a9c5a527e85ba9bf8f595b5990e630bac","price":"0.98","side":"SELL","size":"1700.19"}],"timestamp":"1786845519288"}}
{"f":759,"recv_ms":1786845519565,"raw":{"event_type":"price_change","market":"0xd5f15f31689703aea70b93a52194a0964220d10d92ee7497346f146a8b6ef8ab","price_changes":[{"asset_id":"2151378744569768920256500242561922410292857798164019061749528550808091180185","best_ask":"0.84","best_bid":"0.83","hash":"6d8eda602473a3ee099b85f0b34952c7db8d90e4","price":"0.05","side":"BUY","size":"708.3"},{"asset_id":"17406866367975599232214757606801140480252276357934486651183783311435802862074","best_ask":"0.17","best_bid":"0.16","hash":"ca74b029e7253375e406b23818c886284b1b0caa","price":"0.95","side":"SELL","size":"708.3"}],"timestamp":"1786845519288"}}
{"f":760,"recv_ms":1786845519590,"raw":{"event_type":"price_change","market":"0xd5f15f31689703aea70b93a52194a0964220d10d92ee7497346f146a8b6ef8ab","price_changes":[{"asset_id":"2151378744569768920256500242561922410292857798164019061749528550808091180185","best_ask":"0.84","best_bid":"0.83","hash":"346188e58f6fb1c19a4b86239dc2d3a70ff2ef86","price":"0.05","side":"BUY","size":"654.3"},{"asset_id":"17406866367975599232214757606801140480252276357934486651183783311435802862074","best_ask":"0.17","best_bid":"0.16","hash":"7f26f24a99916ac0b0f0b98ac913911a6783d6b7","price":"0.95","side":"SELL","size":"654.3"}],"timestamp":"1786845519288"}}
{"f":761,"recv_ms":1786845519590,"raw":{"event_type":"price_change","market":"0xd5f15f31689703aea70b93a52194a0964220d10d92ee7497346f146a8b6ef8ab","price_changes":[{"asset_id":"2151378744569768920256500242561922410292857798164019061749528550808091180185","best_ask":"0.84","best_bid":"0.83","hash":"d31f7147ea811e6d27969bd626de8f186fad5f30","price":"0.05","side":"BUY","size":"600.3"},{"asset_id":"17406866367975599232214757606801140480252276357934486651183783311435802862074","best_ask":"0.17","best_bid":"0.16","hash":"345ca629416f821d0cf336d8f1f8c1c687e86d81","price":"0.95","side":"SELL","size":"600.3"}],"timestamp":"1786845519289"}}
{"f":762,"recv_ms":1786845519590,"raw":{"event_type":"price_change","market":"0xd5f15f31689703aea70b93a52194a0964220d10d92ee7497346f146a8b6ef8ab","price_changes":[{"asset_id":"17406866367975599232214757606801140480252276357934486651183783311435802862074","best_ask":"0.17","best_bid":"0.16","hash":"ae1495212b1c6a3edd81f7124166abb6716e8495","price":"0.02","side":"BUY","size":"1842.69"},{"asset_id":"2151378744569768920256500242561922410292857798164019061749528550808091180185","best_ask":"0.84","best_bid":"0.83","hash":"84cfb364562d4d169bf30378ef4297ac4ab6d636","price":"0.98","side":"SELL","size":"1842.69"}],"timestamp":"1786845519289"}}
{"f":763,"recv_ms":1786845519590,"raw":{"event_type":"price_change","market":"0xd5f15f31689703aea70b93a52194a0964220d10d92ee7497346f146a8b6ef8ab","price_changes":[{"asset_id":"17406866367975599232214757606801140480252276357934486651183783311435802862074","best_ask":"0.17","best_bid":"0.16","hash":"bae9be0dc4c45d029c2e699f71683eb076668a15","price":"0.3","side":"SELL","size":"40"},{"asset_id":"2151378744569768920256500242561922410292857798164019061749528550808091180185","best_ask":"0.84","best_bid":"0.83","hash":"4761ad4a8958eaaa9148d8aaa443ecd9247c34e2","price":"0.7","side":"BUY","size":"40"}],"timestamp":"1786845519290"}}
{"f":764,"recv_ms":1786845519590,"raw":{"event_type":"price_change","market":"0xd5f15f31689703aea70b93a52194a0964220d10d92ee7497346f146a8b6ef8ab","price_changes":[{"asset_id":"2151378744569768920256500242561922410292857798164019061749528550808091180185","best_ask":"0.84","best_bid":"0.83","hash":"452cdf9d728e0865d660089c38db2a0518f78e45","price":"0.82","side":"BUY","size":"102.6"},{"asset_id":"17406866367975599232214757606801140480252276357934486651183783311435802862074","best_ask":"0.17","best_bid":"0.16","hash":"a44a34ae5d719f10565c6cdbc08c18eb506133fb","price":"0.18","side":"SELL","size":"102.6"}],"timestamp":"1786845519304"}}
{"f":765,"recv_ms":1786845519593,"raw":{"event_type":"price_change","market":"0xd5f15f31689703aea70b93a52194a0964220d10d92ee7497346f146a8b6ef8ab","price_changes":[{"asset_id":"2151378744569768920256500242561922410292857798164019061749528550808091180185","best_ask":"0.84","best_bid":"0.83","hash":"526217f15c9fdd32ba69c042e76bba4b63523448","price":"0.82","side":"BUY","size":"94.44"},{"asset_id":"17406866367975599232214757606801140480252276357934486651183783311435802862074","best_ask":"0.17","best_bid":"0.16","hash":"d6c4529f7acd28207110918a2b05607b85911413","price":"0.18","side":"SELL","size":"94.44"}],"timestamp":"1786845519304"}}
{"f":766,"recv_ms":1786845519593,"raw":{"event_type":"price_change","market":"0xd5f15f31689703aea70b93a52194a0964220d10d92ee7497346f146a8b6ef8ab","price_changes":[{"asset_id":"2151378744569768920256500242561922410292857798164019061749528550808091180185","best_ask":"0.84","best_bid":"0.83","hash":"868b7644938c095409b49241e466e931908b0af1","price":"0.82","side":"BUY","size":"86.48"},{"asset_id":"17406866367975599232214757606801140480252276357934486651183783311435802862074","best_ask":"0.17","best_bid":"0.16","hash":"93305fdab0fca2497621ee48e43ed13c53ba267b","price":"0.18","side":"SELL","size":"86.48"}],"timestamp":"1786845519305"}}
{"f":767,"recv_ms":1786845519593,"raw":{"event_type":"price_change","market":"0xd5f15f31689703aea70b93a52194a0964220d10d92ee7497346f146a8b6ef8ab","price_changes":[{"asset_id":"2151378744569768920256500242561922410292857798164019061749528550808091180185","best_ask":"0.84","best_bid":"0.83","hash":"5ac092ec559c8c30e897379681e1afece361ee85","price":"0.82","side":"BUY","size":"76.14"},{"asset_id":"17406866367975599232214757606801140480252276357934486651183783311435802862074","best_ask":"0.17","best_bid":"0.16","hash":"277bb0228860b3ae1466f058587da2b01271a1d4","price":"0.18","side":"SELL","size":"76.14"}],"timestamp":"1786845519305"}}
{"f":768,"recv_ms":1786845519593,"raw":{"event_type":"price_change","market":"0xd5f15f31689703aea70b93a52194a0964220d10d92ee7497346f146a8b6ef8ab","price_changes":[{"asset_id":"17406866367975599232214757606801140480252276357934486651183783311435802862074","best_ask":"0.17","best_bid":"0.16","hash":"277bb0228860b3ae1466f058587da2b01271a1d4","price":"0.18","side":"SELL","size":"76.14"},{"asset_id":"2151378744569768920256500242561922410292857798164019061749528550808091180185","best_ask":"0.84","best_bid":"0.83","hash":"5ac092ec559c8c30e897379681e1afece361ee85","price":"0.82","side":"BUY","size":"76.14"}],"timestamp":"1786845519305"}}
{"f":769,"recv_ms":1786845519593,"raw":{"event_type":"price_change","market":"0xd5f15f31689703aea70b93a52194a0964220d10d92ee7497346f146a8b6ef8ab","price_changes":[{"asset_id":"17406866367975599232214757606801140480252276357934486651183783311435802862074","best_ask":"0.17","best_bid":"0.16","hash":"48fcbe699b7b17a9e91ed3f6cc439fd1af5634a8","price":"0.18","side":"SELL","size":"59.22"},{"asset_id":"2151378744569768920256500242561922410292857798164019061749528550808091180185","best_ask":"0.84","best_bid":"0.83","hash":"bd7c747ccc5219331641c7b8ac067fce8fb2ef62","price":"0.82","side":"BUY","size":"59.22"}],"timestamp":"1786845519305"}}
{"f":770,"recv_ms":1786845519593,"raw":{"event_type":"price_change","market":"0xd5f15f31689703aea70b93a52194a0964220d10d92ee7497346f146a8b6ef8ab","price_changes":[{"asset_id":"2151378744569768920256500242561922410292857798164019061749528550808091180185","best_ask":"0.84","best_bid":"0.83","hash":"bd7c747ccc5219331641c7b8ac067fce8fb2ef62","price":"0.82","side":"BUY","size":"59.22"},{"asset_id":"17406866367975599232214757606801140480252276357934486651183783311435802862074","best_ask":"0.17","best_bid":"0.16","hash":"48fcbe699b7b17a9e91ed3f6cc439fd1af5634a8","price":"0.18","side":"SELL","size":"59.22"}],"timestamp":"1786845519305"}}
{"f":771,"recv_ms":1786845519593,"raw":{"event_type":"price_change","market":"0xd5f15f31689703aea70b93a52194a0964220d10d92ee7497346f146a8b6ef8ab","price_changes":[{"asset_id":"17406866367975599232214757606801140480252276357934486651183783311435802862074","best_ask":"0.17","best_bid":"0.16","hash":"2a1ec0290380fe795cc3fa72ce4d15e89f761b32","price":"0.07","side":"BUY","size":"344.86"},{"asset_id":"2151378744569768920256500242561922410292857798164019061749528550808091180185","best_ask":"0.84","best_bid":"0.83","hash":"b2a1950727066cf2f5c1ee8788a3126935658b84","price":"0.93","side":"SELL","size":"344.86"}],"timestamp":"1786845519306"}}
{"f":772,"recv_ms":1786845519593,"raw":{"event_type":"price_change","market":"0xd5f15f31689703aea70b93a52194a0964220d10d92ee7497346f146a8b6ef8ab","price_changes":[{"asset_id":"2151378744569768920256500242561922410292857798164019061749528550808091180185","best_ask":"0.84","best_bid":"0.83","hash":"e0e28a6a40f51c8d2f8153b8775952626df6eead","price":"0.68","side":"BUY","size":"20"},{"asset_id":"17406866367975599232214757606801140480252276357934486651183783311435802862074","best_ask":"0.17","best_bid":"0.16","hash":"8c754c491383b67fe069028044341a3e44ed3122","price":"0.32","side":"SELL","size":"20"}],"timestamp":"1786845519306"}}
{"f":773,"recv_ms":1786845519593,"raw":{"event_type":"price_change","market":"0xd5f15f31689703aea70b93a52194a0964220d10d92ee7497346f146a8b6ef8ab","price_changes":[{"asset_id":"17406866367975599232214757606801140480252276357934486651183783311435802862074","best_ask":"0.17","best_bid":"0.16","hash":"d447829b4021a4842c5243740585c6cf9b83720c","price":"0.32","side":"SELL","size":"10"},{"asset_id":"2151378744569768920256500242561922410292857798164019061749528550808091180185","best_ask":"0.84","best_bid":"0.83","hash":"c5189528eb0465a2ba46a81fd0e9bf49429f77a6","price":"0.68","side":"BUY","size":"10"}],"timestamp":"1786845519307"}}
{"f":774,"recv_ms":1786845519593,"raw":{"event_type":"price_change","market":"0xd5f15f31689703aea70b93a52194a0964220d10d92ee7497346f146a8b6ef8ab","price_changes":[{"asset_id":"2151378744569768920256500242561922410292857798164019061749528550808091180185","best_ask":"0.84","best_bid":"0.83","hash":"08ea16584eca2e3e46c5434b47dc3b4cb1ba49f9","price":"0.69","side":"BUY","size":"100"},{"asset_id":"17406866367975599232214757606801140480252276357934486651183783311435802862074","best_ask":"0.17","best_bid":"0.16","hash":"b01bc0730f454945bf7b1a47ec203e768650c9e2","price":"0.31","side":"SELL","size":"100"}],"timestamp":"1786845519307"}}
{"f":775,"recv_ms":1786845519593,"raw":{"event_type":"price_change","market":"0xd5f15f31689703aea70b93a52194a0964220d10d92ee7497346f146a8b6ef8ab","price_changes":[{"asset_id":"17406866367975599232214757606801140480252276357934486651183783311435802862074","best_ask":"0.17","best_bid":"0.16","hash":"ace830a4dfb7f810b28a1fb40f03c518dcd67343","price":"0.31","side":"SELL","size":"110"},{"asset_id":"2151378744569768920256500242561922410292857798164019061749528550808091180185","best_ask":"0.84","best_bid":"0.83","hash":"2715617ea9cfcee74474bfe7890c215015182931","price":"0.69","side":"BUY","size":"110"}],"timestamp":"1786845519312"}}
{"f":776,"recv_ms":1786845519593,"raw":{"event_type":"price_change","market":"0xd5f15f31689703aea70b93a52194a0964220d10d92ee7497346f146a8b6ef8ab","price_changes":[{"asset_id":"17406866367975599232214757606801140480252276357934486651183783311435802862074","best_ask":"0.17","best_bid":"0.15","hash":"8638e9208f997a158fcced5d811f3cba3ac57a02","price":"0.15","side":"BUY","size":"0.09"},{"asset_id":"2151378744569768920256500242561922410292857798164019061749528550808091180185","best_ask":"0.85","best_bid":"0.83","hash":"ef42c4eb6a9949782ee5a0b16840bcc68f40b20e","price":"0.85","side":"SELL","size":"0.09"}],"timestamp":"1786845519314"}}
{"f":777,"recv_ms":1786845519593,"raw":{"event_type":"price_change","market":"0xd5f15f31689703aea70b93a52194a0964220d10d92ee7497346f146a8b6ef8ab","price_changes":[{"asset_id":"17406866367975599232214757606801140480252276357934486651183783311435802862074","best_ask":"0.17","best_bid":"0.15","hash":"8638e9208f997a158fcced5d811f3cba3ac57a02","price":"0.16","side":"BUY","size":"0"},{"asset_id":"2151378744569768920256500242561922410292857798164019061749528550808091180185","best_ask":"0.85","best_bid":"0.83","hash":"ef42c4eb6a9949782ee5a0b16840bcc68f40b20e","price":"0.84","side":"SELL","size":"0"}],"timestamp":"1786845519314"}}
{"f":778,"recv_ms":1786845519699,"raw":{"asset_id":"2151378744569768920256500242561922410292857798164019061749528550808091180185","event_type":"last_trade_price","fee_rate_bps":"0","market":"0xd5f15f31689703aea70b93a52194a0964220d10d92ee7497346f146a8b6ef8ab","price":"0.84","side":"BUY","size":"5.952375","timestamp":"1786845519485","transaction_hash":"0xedb6ffbd1f822c5fdfe1d732572489e9ae5170868af1723ce8c861665526ccab"}}
{"f":779,"recv_ms":1786845519720,"raw":{"asset_id":"2151378744569768920256500242561922410292857798164019061749528550808091180185","event_type":"last_trade_price","fee_rate_bps":"0","market":"0xd5f15f31689703aea70b93a52194a0964220d10d92ee7497346f146a8b6ef8ab","price":"0.84","side":"BUY","size":"1.190475","timestamp":"1786845519494","transaction_hash":"0x88e7839032203b010ffa675eeb173c805048df50edb2d3051378bf8f4fbe2b2a"}}
{"f":780,"recv_ms":1786845519728,"raw":{"event_type":"price_change","market":"0xd5f15f31689703aea70b93a52194a0964220d10d92ee7497346f146a8b6ef8ab","price_changes":[{"asset_id":"17406866367975599232214757606801140480252276357934486651183783311435802862074","best_ask":"0.17","best_bid":"0.15","hash":"41d065656f4004c1a142108b52dad56cd3831bbc","price":"0.26","side":"SELL","size":"0"},{"asset_id":"2151378744569768920256500242561922410292857798164019061749528550808091180185","best_ask":"0.85","best_bid":"0.83","hash":"9e3523aae0c1e94d73d1b1c1ff9af250e18f53a4","price":"0.74","side":"BUY","size":"0"}],"timestamp":"1786845519505"}}
{"f":781,"recv_ms":1786845519728,"raw":{"event_type":"price_change","market":"0xd5f15f31689703aea70b93a52194a0964220d10d92ee7497346f146a8b6ef8ab","price_changes":[{"asset_id":"2151378744569768920256500242561922410292857798164019061749528550808091180185","best_ask":"0.85","best_bid":"0.83","hash":"a13ad0af3ff031e058261178032a2a7feca5717c","price":"0.69","side":"BUY","size":"60"},{"asset_id":"17406866367975599232214757606801140480252276357934486651183783311435802862074","best_ask":"0.17","best_bid":"0.15","hash":"648bfb1bafe959cc0bcc5040fd9937c14ee1cb28","price":"0.31","side":"SELL","size":"60"}],"timestamp":"1786845519507"}}
{"f":782,"recv_ms":1786845519730,"raw":{"event_type":"price_change","market":"0xd5f15f31689703aea70b93a52194a0964220d10d92ee7497346f146a8b6ef8ab","price_changes":[{"asset_id":"17406866367975599232214757606801140480252276357934486651183783311435802862074","best_ask":"0.17","best_bid":"0.14","hash":"24c990e0dfdb0a04fd3ba8944e447058c29efd9d","price":"0.14","side":"BUY","size":"1.39"},{"asset_id":"2151378744569768920256500242561922410292857798164019061749528550808091180185","best_ask":"0.86","best_bid":"0.83","hash":"b6b3993154c6f64b68774c34f9a3f414c8c7af0a","price":"0.86","side":"SELL","size":"1.39"}],"timestamp":"1786845519508"}}
{"f":783,"recv_ms":1786845519730,"raw":{"event_type":"price_change","market":"0xd5f15f31689703aea70b93a52194a0964220d10d92ee7497346f146a8b6ef8ab","price_changes":[{"asset_id":"17406866367975599232214757606801140480252276357934486651183783311435802862074","best_ask":"0.17","best_bid":"0.14","hash":"24c990e0dfdb0a04fd3ba8944e447058c29efd9d","price":"0.15","side":"BUY","size":"0"},{"asset_id":"2151378744569768920256500242561922410292857798164019061749528550808091180185","best_ask":"0.86","best_bid":"0.83","hash":"b6b3993154c6f64b68774c34f9a3f414c8c7af0a","price":"0.85","side":"SELL","size":"0"}],"timestamp":"1786845519508"}}
{"f":784,"recv_ms":1786845519742,"raw":{"event_type":"price_change","market":"0xd5f15f31689703aea70b93a52194a0964220d10d92ee7497346f146a8b6ef8ab","price_changes":[{"asset_id":"17406866367975599232214757606801140480252276357934486651183783311435802862074","best_ask":"0.17","best_bid":"0.14","hash":"a602b81935747c5f037ae839fab6b9ceab93a59a","price":"0.01","side":"BUY","size":"5583.18"},{"asset_id":"2151378744569768920256500242561922410292857798164019061749528550808091180185","best_ask":"0.86","best_bid":"0.83","hash":"871e20d6c85bc65d42a8a85f2cc36274d2cae044","price":"0.99","side":"SELL","size":"5583.18"}],"timestamp":"1786845519515"}}
{"f":785,"recv_ms":1786845519742,"raw":{"event_type":"price_change","market":"0xd5f15f31689703aea70b93a52194a0964220d10d92ee7497346f146a8b6ef8ab","price_changes":[{"asset_id":"2151378744569768920256500242561922410292857798164019061749528550808091180185","best_ask":"0.86","best_bid":"0.83","hash":"a5ea41733fb1b7f8c6853ec21190206d8133f677","price":"0.01","side":"BUY","size":"5873.54"},{"asset_id":"17406866367975599232214757606801140480252276357934486651183783311435802862074","best_ask":"0.17","best_bid":"0.14","hash":"4544a428a6cd729bd7a3af79d240c08b845746d2","price":"0.99","side":"SELL","size":"5873.54"}],"timestamp":"1786845519516"}}
{"f":786,"recv_ms":1786845519742,"raw":{"event_type":"price_change","market":"0xd5f15f31689703aea70b93a52194a0964220d10d92ee7497346f146a8b6ef8ab","price_changes":[{"asset_id":"17406866367975599232214757606801140480252276357934486651183783311435802862074","best_ask":"0.17","best_bid":"0.14","hash":"1ba231ebd62828f2369f9371876493779bb2c319","price":"0.01","side":"BUY","size":"5588.18"},{"asset_id":"2151378744569768920256500242561922410292857798164019061749528550808091180185","best_ask":"0.86","best_bid":"0.83","hash":"79cc253c1cbd0a915acb7eb6b31c068bc6882720","price":"0.99","side":"SELL","size":"5588.18"}],"timestamp":"1786845519516"}}
{"f":787,"recv_ms":1786845519745,"raw":{"event_type":"price_change","market":"0xd5f15f31689703aea70b93a52194a0964220d10d92ee7497346f146a8b6ef8ab","price_changes":[{"asset_id":"2151378744569768920256500242561922410292857798164019061749528550808091180185","best_ask":"0.86","best_bid":"0.83","hash":"89fe4b7d47a2ed372deb0970f0f96209ddef24f4","price":"0.81","side":"BUY","size":"18.53"},{"asset_id":"17406866367975599232214757606801140480252276357934486651183783311435802862074","best_ask":"0.17","best_bid":"0.14","hash":"d57b5d52df0a529868148c14ccb356de02bd30b7","price":"0.19","side":"SELL","size":"18.53"}],"timestamp":"1786845519517"}}
{"f":788,"recv_ms":1786845519745,"raw":{"event_type":"price_change","market":"0xd5f15f31689703aea70b93a52194a0964220d10d92ee7497346f146a8b6ef8ab","price_changes":[{"asset_id":"17406866367975599232214757606801140480252276357934486651183783311435802862074","best_ask":"0.17","best_bid":"0.14","hash":"6acaaecd857358dc3a8e095626695eb4ff8d4309","price":"0.01","side":"BUY","size":"5593.18"},{"asset_id":"2151378744569768920256500242561922410292857798164019061749528550808091180185","best_ask":"0.86","best_bid":"0.83","hash":"f19921b5823c7a261af52c4e882c365d3dc166e3","price":"0.99","side":"SELL","size":"5593.18"}],"timestamp":"1786845519519"}}
{"f":789,"recv_ms":1786845519745,"raw":{"event_type":"price_change","market":"0xd5f15f31689703aea70b93a52194a0964220d10d92ee7497346f146a8b6ef8ab","price_changes":[{"asset_id":"2151378744569768920256500242561922410292857798164019061749528550808091180185","best_ask":"0.86","best_bid":"0.83","hash":"321315efea15919cee88f6b5c456c30902500c31","price":"0.83","side":"BUY","size":"292.64"},{"asset_id":"17406866367975599232214757606801140480252276357934486651183783311435802862074","best_ask":"0.17","best_bid":"0.14","hash":"0849ad75d52029cb726329b73f90d6d040f582cc","price":"0.17","side":"SELL","size":"292.64"}],"timestamp":"1786845519520"}}
{"f":790,"recv_ms":1786845519745,"raw":{"event_type":"price_change","market":"0xd5f15f31689703aea70b93a52194a0964220d10d92ee7497346f146a8b6ef8ab","price_changes":[{"asset_id":"2151378744569768920256500242561922410292857798164019061749528550808091180185","best_ask":"0.86","best_bid":"0.83","hash":"278038adcb6249dbac8e8891f49dda638b0fb601","price":"0.83","side":"BUY","size":"301.96"},{"asset_id":"17406866367975599232214757606801140480252276357934486651183783311435802862074","best_ask":"0.17","best_bid":"0.14","hash":"e31e6a916b84ab9c1370bceaa1c7ba8880b38668","price":"0.17","side":"SELL","size":"301.96"}],"timestamp":"1786845519521"}}
{"f":791,"recv_ms":1786845519745,"raw":{"event_type":"price_change","market":"0xd5f15f31689703aea70b93a52194a0964220d10d92ee7497346f146a8b6ef8ab","price_changes":[{"asset_id":"17406866367975599232214757606801140480252276357934486651183783311435802862074","best_ask":"0.17","best_bid":"0.14","hash":"6c1f8fbb9f8b17132c9cc256583b1aa6ca57172e","price":"0.17","side":"SELL","size":"311.24"},{"asset_id":"2151378744569768920256500242561922410292857798164019061749528550808091180185","best_ask":"0.86","best_bid":"0.83","hash":"b0c6f11c995425fafd5a0e7ba1d3bb53155bc752","price":"0.83","side":"BUY","size":"311.24"}],"timestamp":"1786845519523"}}
{"f":792,"recv_ms":1786845519745,"raw":{"event_type":"price_change","market":"0xd5f15f31689703aea70b93a52194a0964220d10d92ee7497346f146a8b6ef8ab","price_changes":[{"asset_id":"2151378744569768920256500242561922410292857798164019061749528550808091180185","best_ask":"0.86","best_bid":"0.83","hash":"3efc47fa78933c899128de15fb66e5799eae7e59","price":"0.83","side":"BUY","size":"320.52"},{"asset_id":"17406866367975599232214757606801140480252276357934486651183783311435802862074","best_ask":"0.17","best_bid":"0.14","hash":"4489c25d1dcd3d7842efbcbfc9849f310507eab0","price":"0.17","side":"SELL","size":"320.52"}],"timestamp":"1786845519524"}}
{"f":793,"recv_ms":1786845519745,"raw":{"event_type":"price_change","market":"0xd5f15f31689703aea70b93a52194a0964220d10d92ee7497346f146a8b6ef8ab","price_changes":[{"asset_id":"2151378744569768920256500242561922410292857798164019061749528550808091180185","best_ask":"0.86","best_bid":"0.83","hash":"62b6fb7fa234cd3a600dedb26dc6062868a42c5e","price":"0.01","side":"BUY","size":"5868.54"},{"asset_id":"17406866367975599232214757606801140480252276357934486651183783311435802862074","best_ask":"0.17","best_bid":"0.14","hash":"9659253da87cd83e3c9224e671a6ecfab3f06a38","price":"0.99","side":"SELL","size":"5868.54"}],"timestamp":"1786845519525"}}
{"f":794,"recv_ms":1786845519745,"raw":{"event_type":"price_change","market":"0xd5f15f31689703aea70b93a52194a0964220d10d92ee7497346f146a8b6ef8ab","price_changes":[{"asset_id":"17406866367975599232214757606801140480252276357934486651183783311435802862074","best_ask":"0.17","best_bid":"0.14","hash":"df3afa16b367e9d667d29f77cc0eece973d7742b","price":"0.01","side":"BUY","size":"5588.18"},{"asset_id":"2151378744569768920256500242561922410292857798164019061749528550808091180185","best_ask":"0.86","best_bid":"0.83","hash":"712d132c60a5a805d35c338e632d6885f6138b1b","price":"0.99","side":"SELL","size":"5588.18"}],"timestamp":"1786845519526"}}
{"f":795,"recv_ms":1786845519745,"raw":{"event_type":"price_change","market":"0xd5f15f31689703aea70b93a52194a0964220d10d92ee7497346f146a8b6ef8ab","price_changes":[{"asset_id":"17406866367975599232214757606801140480252276357934486651183783311435802862074","best_ask":"0.17","best_bid":"0.14","hash":"03f45ea1e43bf86c2738d1a71139d399a0d675ca","price":"0.01","side":"BUY","size":"5593.18"},{"asset_id":"2151378744569768920256500242561922410292857798164019061749528550808091180185","best_ask":"0.86","best_bid":"0.83","hash":"1bdfe302e30b252be9ee919d282978a5018de0c9","price":"0.99","side":"SELL","size":"5593.18"}],"timestamp":"1786845519526"}}
{"f":796,"recv_ms":1786845519745,"raw":{"event_type":"price_change","market":"0xd5f15f31689703aea70b93a52194a0964220d10d92ee7497346f146a8b6ef8ab","price_changes":[{"asset_id":"2151378744569768920256500242561922410292857798164019061749528550808091180185","best_ask":"0.86","best_bid":"0.83","hash":"4d87fde23cee58c8bb30f39ce37d3697a0f946b1","price":"0.01","side":"BUY","size":"5873.55"},{"asset_id":"17406866367975599232214757606801140480252276357934486651183783311435802862074","best_ask":"0.17","best_bid":"0.14","hash":"a2d14cba140aba63f325e928d390a3401119f64a","price":"0.99","side":"SELL","size":"5873.55"}],"timestamp":"1786845519527"}}
{"f":797,"recv_ms":1786845519745,"raw":{"event_type":"price_change","market":"0xd5f15f31689703aea70b93a52194a0964220d10d92ee7497346f146a8b6ef8ab","price_changes":[{"asset_id":"2151378744569768920256500242561922410292857798164019061749528550808091180185","best_ask":"0.86","best_bid":"0.83","hash":"ae1494971fc11a3835045db405931d3d192fc3d0","price":"0.01","side":"BUY","size":"5878.55"},{"asset_id":"17406866367975599232214757606801140480252276357934486651183783311435802862074","best_ask":"0.17","best_bid":"0.14","hash":"8fc58fa9a6e8ac508585999dc87912139a649fa3","price":"0.99","side":"SELL","size":"5878.55"}],"timestamp":"1786845519528"}}
{"f":798,"recv_ms":1786845519750,"raw":{"event_type":"price_change","market":"0xd5f15f31689703aea70b93a52194a0964220d10d92ee7497346f146a8b6ef8ab","price_changes":[{"asset_id":"17406866367975599232214757606801140480252276357934486651183783311435802862074","best_ask":"0.17","best_bid":"0.14","hash":"1d6f34340bc9d67c64e7cf873d80724793558d24","price":"0.34","side":"SELL","size":"28"},{"asset_id":"2151378744569768920256500242561922410292857798164019061749528550808091180185","best_ask":"0.86","best_bid":"0.83","hash":"6dd11c599cf38dbfd6470d35b41b20f18d4f138e","price":"0.66","side":"BUY","size":"28"}],"timestamp":"1786845519530"}}
{"f":799,"recv_ms":1786845519750,"raw":{"event_type":"price_change","market":"0xd5f15f31689703aea70b93a52194a0964220d10d92ee7497346f146a8b6ef8ab","price_changes":[{"asset_id":"2151378744569768920256500242561922410292857798164019061749528550808091180185","best_ask":"0.86","best_bid":"0.83","hash":"6e809f4e765ee6cae5b2fe1693a63967a2ada120","price":"0.57","side":"BUY","size":"34"},{"asset_id":"17406866367975599232214757606801140480252276357934486651183783311435802862074","best_ask":"0.17","best_bid":"0.14","hash":"92b1a34623d636ca05d8b4fdb22e00e57b826b4f","price":"0.43","side":"SELL","size":"34"}],"timestamp":"1786845519531"}}
{"f":800,"recv_ms":1786845519750,"raw":{"event_type":"price_change","market":"0xd5f15f31689703aea70b93a52194a0964220d10d92ee7497346f146a8b6ef8ab","price_changes":[{"asset_id":"2151378744569768920256500242561922410292857798164019061749528550808091180185","best_ask":"0.86","best_bid":"0.83","hash":"4658a2c4c56bd2793b7771537c40f95ac016cf17","price":"0.01","side":"BUY","size":"5873.54"},{"asset_id":"17406866367975599232214757606801140480252276357934486651183783311435802862074","best_ask":"0.17","best_bid":"0.14","hash":"025986965b8cfdef90a2a0eaccf6fd7d3e2a192d","price":"0.99","side":"SELL","size":"5873.54"}],"timestamp":"1786845519532"}}
{"f":801,"recv_ms":1786845519750,"raw":{"event_type":"price_change","market":"0xd5f15f31689703aea70b93a52194a0964220d10d92ee7497346f146a8b6ef8ab","price_changes":[{"asset_id":"2151378744569768920256500242561922410292857798164019061749528550808091180185","best_ask":"0.86","best_bid":"0.83","hash":"ef82305457d58b516d6c7bcbd42eb5f7e4e7d022","price":"0.01","side":"BUY","size":"5867.54"},{"asset_id":"17406866367975599232214757606801140480252276357934486651183783311435802862074","best_ask":"0.17","best_bid":"0.14","hash":"70d7f230c66b183b4f33601730a9e8eba7986132","price":"0.99","side":"SELL","size":"5867.54"}],"timestamp":"1786845519532"}}
{"f":802,"recv_ms":1786845519750,"raw":{"event_type":"price_change","market":"0xd5f15f31689703aea70b93a52194a0964220d10d92ee7497346f146a8b6ef8ab","price_changes":[{"asset_id":"17406866367975599232214757606801140480252276357934486651183783311435802862074","best_ask":"0.17","best_bid":"0.14","hash":"20090ff9a366ac50b20bffc83ec67c2cdd9b6cc2","price":"0.35","side":"SELL","size":"23.71"},{"asset_id":"2151378744569768920256500242561922410292857798164019061749528550808091180185","best_ask":"0.86","best_bid":"0.83","hash":"15092c3274467742a65dceb44e629dfbbccc3f50","price":"0.65","side":"BUY","size":"23.71"}],"timestamp":"1786845519532"}}
{"f":803,"recv_ms":1786845519756,"raw":{"event_type":"price_change","market":"0xd5f15f31689703aea70b93a52194a0964220d10d92ee7497346f146a8b6ef8ab","price_changes":[{"asset_id":"2151378744569768920256500242561922410292857798164019061749528550808091180185","best_ask":"0.86","best_bid":"0.83","hash":"5169d34b2b134e5d579e19153b1d13abec735ccb","price":"0.01","side":"BUY","size":"5872.54"},{"asset_id":"17406866367975599232214757606801140480252276357934486651183783311435802862074","best_ask":"0.17","best_bid":"0.14","hash":"5c655c938becacd4ab9d6c1b09e051b7ee3b9728","price":"0.99","side":"SELL","size":"5872.54"}],"timestamp":"1786845519533"}}
{"f":804,"recv_ms":1786845519756,"raw":{"event_type":"price_change","market":"0xd5f15f31689703aea70b93a52194a0964220d10d92ee7497346f146a8b6ef8ab","price_changes":[{"asset_id":"17406866367975599232214757606801140480252276357934486651183783311435802862074","best_ask":"0.17","best_bid":"0.14","hash":"0642971f3912bff8142a99c089665ed6e57e0afc","price":"0.09","side":"BUY","size":"40"},{"asset_id":"2151378744569768920256500242561922410292857798164019061749528550808091180185","best_ask":"0.86","best_bid":"0.83","hash":"69a9ddaffcc552c782b9552bfbc7a3411e9be1d2","price":"0.91","side":"SELL","size":"40"}],"timestamp":"1786845519534"}}
{"f":805,"recv_ms":1786845519756,"raw":{"event_type":"price_change","market":"0xd5f15f31689703aea70b93a52194a0964220d10d92ee7497346f146a8b6ef8ab","price_changes":[{"asset_id":"2151378744569768920256500242561922410292857798164019061749528550808091180185","best_ask":"0.86","best_bid":"0.83","hash":"db545700893219cd1c85b70d1d7ffd75e2cef4bc","price":"0.42","side":"BUY","size":"62.7"},{"asset_id":"17406866367975599232214757606801140480252276357934486651183783311435802862074","best_ask":"0.17","best_bid":"0.14","hash":"0a8ebc6ea88e82595db493d4dd2cf8ee9ac689ab","price":"0.58","side":"SELL","size":"62.7"}],"timestamp":"1786845519534"}}
{"f":806,"recv_ms":1786845519756,"raw":{"event_type":"price_change","market":"0xd5f15f31689703aea70b93a52194a0964220d10d92ee7497346f146a8b6ef8ab","price_changes":[{"asset_id":"17406866367975599232214757606801140480252276357934486651183783311435802862074","best_ask":"0.17","best_bid":"0.14","hash":"dbd56d978541afb9c595af6ca3a0fc4651bd8248","price":"0.09","side":"BUY","size":"10"},{"asset_id":"2151378744569768920256500242561922410292857798164019061749528550808091180185","best_ask":"0.86","best_bid":"0.83","hash":"8415f041902c5fa06c0c6e86caf2773cb9cff4ff","price":"0.91","side":"SELL","size":"10"}],"timestamp":"1786845519535"}}
{"f":807,"recv_ms":1786845519756,"raw":{"event_type":"price_change","market":"0xd5f15f31689703aea70b93a52194a0964220d10d92ee7497346f146a8b6ef8ab","price_changes":[{"asset_id":"17406866367975599232214757606801140480252276357934486651183783311435802862074","best_ask":"0.17","best_bid":"0.14","hash":"dbd56d978541afb9c595af6ca3a0fc4651bd8248","price":"0.08","side":"BUY","size":"40.29"},{"asset_id":"2151378744569768920256500242561922410292857798164019061749528550808091180185","best_ask":"0.86","best_bid":"0.83","hash":"8415f041902c5fa06c0c6e86caf2773cb9cff4ff","price":"0.92","side":"SELL","size":"40.29"}],"timestamp":"1786845519535"}}
{"f":808,"recv_ms":1786845519756,"raw":{"event_type":"price_change","market":"0xd5f15f31689703aea70b93a52194a0964220d10d92ee7497346f146a8b6ef8ab","price_changes":[{"asset_id":"2151378744569768920256500242561922410292857798164019061749528550808091180185","best_ask":"0.86","best_bid":"0.83","hash":"1e0b7dc452315ed404f38e54ad57acd0282109b8","price":"0.43","side":"BUY","size":"62.6"},{"asset_id":"17406866367975599232214757606801140480252276357934486651183783311435802862074","best_ask":"0.17","best_bid":"0.14","hash":"f292e3a9608e418b04d628d4bf6a43c8ef060ad2","price":"0.57","side":"SELL","size":"62.6"}],"timestamp":"1786845519536"}}
{"f":809,"recv_ms":1786845519756,"raw":{"event_type":"price_change","market":"0xd5f15f31689703aea70b93a52194a0964220d10d92ee7497346f146a8b6ef8ab","price_changes":[{"asset_id":"2151378744569768920256500242561922410292857798164019061749528550808091180185","best_ask":"0.86","best_bid":"0.83","hash":"dd4b7dd03b56ec75f379cbb4eb8c2ba6cfcb0630","price":"0.01","side":"BUY","size":"5867.54"},{"asset_id":"17406866367975599232214757606801140480252276357934486651183783311435802862074","best_ask":"0.17","best_bid":"0.14","hash":"818cb47e3a8c01734a76cebdf828484dadbae101","price":"0.99","side":"SELL","size":"5867.54"}],"timestamp":"1786845519537"}}
{"f":810,"recv_ms":1786845519756,"raw":{"event_type":"price_change","market":"0xd5f15f31689703aea70b93a52194a0964220d10d92ee7497346f146a8b6ef8ab","price_changes":[{"asset_id":"2151378744569768920256500242561922410292857798164019061749528550808091180185","best_ask":"0.86","best_bid":"0.83","hash":"fc79b1a74e366004af5479f05d3a630211f82336","price":"0.75","side":"BUY","size":"84.9"},{"asset_id":"17406866367975599232214757606801140480252276357934486651183783311435802862074","best_ask":"0.17","best_bid":"0.14","hash":"bd19ad0db9dd8dfee8ea213ee82cc3411c812d86","price":"0.25","side":"SELL","size":"84.9"}],"timestamp":"1786845519537"}}
{"f":811,"recv_ms":1786845519756,"raw":{"event_type":"price_change","market":"0xd5f15f31689703aea70b93a52194a0964220d10d92ee7497346f146a8b6ef8ab","price_changes":[{"asset_id":"2151378744569768920256500242561922410292857798164019061749528550808091180185","best_ask":"0.86","best_bid":"0.83","hash":"f24a1f449934312ea1aa662414cb1b53cffd2976","price":"0.01","side":"BUY","size":"5862.54"},{"asset_id":"17406866367975599232214757606801140480252276357934486651183783311435802862074","best_ask":"0.17","best_bid":"0.14","hash":"aeb76822e3a1dfc7d48035db103e86d54c9b2531","price":"0.99","side":"SELL","size":"5862.54"}],"timestamp":"1786845519538"}}
{"f":812,"recv_ms":1786845519758,"raw":{"event_type":"price_change","market":"0xd5f15f31689703aea70b93a52194a0964220d10d92ee7497346f146a8b6ef8ab","price_changes":[{"asset_id":"2151378744569768920256500242561922410292857798164019061749528550808091180185","best_ask":"0.86","best_bid":"0.83","hash":"bc01e998e7a0a0697f2f0525f925359508714a56","price":"0.52","side":"BUY","size":"150.4"},{"asset_id":"17406866367975599232214757606801140480252276357934486651183783311435802862074","best_ask":"0.17","best_bid":"0.14","hash":"bc9c58099da33bfdb95f84471c8dcb382a4027e6","price":"0.48","side":"SELL","size":"150.4"}],"timestamp":"1786845519539"}}
{"f":813,"recv_ms":1786845519758,"raw":{"event_type":"price_change","market":"0xd5f15f31689703aea70b93a52194a0964220d10d92ee7497346f146a8b6ef8ab","price_changes":[{"asset_id":"2151378744569768920256500242561922410292857798164019061749528550808091180185","best_ask":"0.86","best_bid":"0.83","hash":"28147469205a493a5853115eea934519d0c169ea","price":"0.53","side":"BUY","size":"269.83"},{"asset_id":"17406866367975599232214757606801140480252276357934486651183783311435802862074","best_ask":"0.17","best_bid":"0.14","hash":"184661732c52a188782e7ffff9595e6a7615ff46","price":"0.47","side":"SELL","size":"269.83"}],"timestamp":"1786845519540"}}
{"f":814,"recv_ms":1786845519767,"raw":{"event_type":"price_change","market":"0xd5f15f31689703aea70b93a52194a0964220d10d92ee7497346f146a8b6ef8ab","price_changes":[{"asset_id":"2151378744569768920256500242561922410292857798164019061749528550808091180185","best_ask":"0.86","best_bid":"0.83","hash":"f65c583dc2341e285016f3b548ef1976ae812ce4","price":"0.5","side":"BUY","size":"450.4"},{"asset_id":"17406866367975599232214757606801140480252276357934486651183783311435802862074","best_ask":"0.17","best_bid":"0.14","hash":"aef231a0803290deffd258713bc4b88385e6f869","price":"0.5","side":"SELL","size":"450.4"}],"timestamp":"1786845519540"}}
{"f":815,"recv_ms":1786845519767,"raw":{"event_type":"price_change","market":"0xd5f15f31689703aea70b93a52194a0964220d10d92ee7497346f146a8b6ef8ab","price_changes":[{"asset_id":"2151378744569768920256500242561922410292857798164019061749528550808091180185","best_ask":"0.86","best_bid":"0.83","hash":"4164b4fd8e69d1017342c53ab93854ffec355879","price":"0.5","side":"BUY","size":"250.4"},{"asset_id":"17406866367975599232214757606801140480252276357934486651183783311435802862074","best_ask":"0.17","best_bid":"0.14","hash":"c0ceaa29b4af98ce48f1bd3cd5ab73fdaf9ed889","price":"0.5","side":"SELL","size":"250.4"}],"timestamp":"1786845519540"}}
{"f":816,"recv_ms":1786845519767,"raw":{"event_type":"price_change","market":"0xd5f15f31689703aea70b93a52194a0964220d10d92ee7497346f146a8b6ef8ab","price_changes":[{"asset_id":"2151378744569768920256500242561922410292857798164019061749528550808091180185","best_ask":"0.86","best_bid":"0.83","hash":"cdd298d6ba37db8c114092d19bdfaec21070dcf9","price":"0.53","side":"BUY","size":"138.13"},{"asset_id":"17406866367975599232214757606801140480252276357934486651183783311435802862074","best_ask":"0.17","best_bid":"0.14","hash":"36a6b567570034e9cdba898ca81e5aff23286a0c","price":"0.47","side":"SELL","size":"138.13"}],"timestamp":"1786845519541"}}
{"f":817,"recv_ms":1786845519767,"raw":{"event_type":"price_change","market":"0xd5f15f31689703aea70b93a52194a0964220d10d92ee7497346f146a8b6ef8ab","price_changes":[{"asset_id":"2151378744569768920256500242561922410292857798164019061749528550808091180185","best_ask":"0.86","best_bid":"0.83","hash":"d9037e4e0b38b6c27d485a5354c85200f3b9c9d4","price":"0.5","side":"BUY","size":"50.4"},{"asset_id":"17406866367975599232214757606801140480252276357934486651183783311435802862074","best_ask":"0.17","best_bid":"0.14","hash":"c529c80656b2c3559bd5b988a770b25e700b6645","price":"0.5","side":"SELL","size":"50.4"}],"timestamp":"1786845519541"}}
{"f":818,"recv_ms":1786845519767,"raw":{"event_type":"price_change","market":"0xd5f15f31689703aea70b93a52194a0964220d10d92ee7497346f146a8b6ef8ab","price_changes":[{"asset_id":"2151378744569768920256500242561922410292857798164019061749528550808091180185","best_ask":"0.86","best_bid":"0.83","hash":"9b7b9407ffd3aeb97735a284201d1e3b3cc68ae9","price":"0.53","side":"BUY","size":"39"},{"asset_id":"17406866367975599232214757606801140480252276357934486651183783311435802862074","best_ask":"0.17","best_bid":"0.14","hash":"10ee5f51b1b2f18928eec7fd5b9872a2afd24711","price":"0.47","side":"SELL","size":"39"}],"timestamp":"1786845519541"}}
{"f":819,"recv_ms":1786845519767,"raw":{"event_type":"price_change","market":"0xd5f15f31689703aea70b93a52194a0964220d10d92ee7497346f146a8b6ef8ab","price_changes":[{"asset_id":"2151378744569768920256500242561922410292857798164019061749528550808091180185","best_ask":"0.86","best_bid":"0.83","hash":"b1ed259752540a5701b04b62839745d3b1e78b11","price":"0.44","side":"BUY","size":"323.6"},{"asset_id":"17406866367975599232214757606801140480252276357934486651183783311435802862074","best_ask":"0.17","best_bid":"0.14","hash":"4eb38cfdbb6cdc6fe4bd2bddd57a1f8c8afcccb3","price":"0.56","side":"SELL","size":"323.6"}],"timestamp":"1786845519542"}}
{"f":820,"recv_ms":1786845519767,"raw":{"event_type":"price_change","market":"0xd5f15f31689703aea70b93a52194a0964220d10d92ee7497346f146a8b6ef8ab","price_changes":[{"asset_id":"17406866367975599232214757606801140480252276357934486651183783311435802862074","best_ask":"0.17","best_bid":"0.14","hash":"64b8c564e1233618f7f538e0874c251153296788","price":"0.01","side":"BUY","size":"5588.18"},{"asset_id":"2151378744569768920256500242561922410292857798164019061749528550808091180185","best_ask":"0.86","best_bid":"0.83","hash":"1dcc086c13df3ea892956de928b84bfb78e78440","price":"0.99","side":"SELL","size":"5588.18"}],"timestamp":"1786845519543"}}
{"f":821,"recv_ms":1786845519767,"raw":{"event_type":"price_change","market":"0xd5f15f31689703aea70b93a52194a0964220d10d92ee7497346f146a8b6ef8ab","price_changes":[{"asset_id":"2151378744569768920256500242561922410292857798164019061749528550808091180185","best_ask":"0.86","best_bid":"0.83","hash":"09b0646daa52f4c5ba3b86ed67e44780c9d5d34d","price":"0.44","side":"BUY","size":"523.6"},{"asset_id":"17406866367975599232214757606801140480252276357934486651183783311435802862074","best_ask":"0.17","best_bid":"0.14","hash":"0f19ee2aa58eb4652d487c510c0d2a413239e8cf","price":"0.56","side":"SELL","size":"523.6"}],"timestamp":"1786845519543"}}
{"f":822,"recv_ms":1786845519767,"raw":{"event_type":"price_change","market":"0xd5f15f31689703aea70b93a52194a0964220d10d92ee7497346f146a8b6ef8ab","price_changes":[{"asset_id":"2151378744569768920256500242561922410292857798164019061749528550808091180185","best_ask":"0.86","best_bid":"0.83","hash":"115b6cc7a69cf57053fc5d2d35e0e825fd476421","price":"0.92","side":"SELL","size":"53.29"},{"asset_id":"17406866367975599232214757606801140480252276357934486651183783311435802862074","best_ask":"0.17","best_bid":"0.14","hash":"7db983d4026e85f98ae63d1e6a3bb868da870145","price":"0.08","side":"BUY","size":"53.29"}],"timestamp":"1786845519544"}}
{"f":823,"recv_ms":1786845519771,"raw":{"event_type":"price_change","market":"0xd5f15f31689703aea70b93a52194a0964220d10d92ee7497346f146a8b6ef8ab","price_changes":[{"asset_id":"2151378744569768920256500242561922410292857798164019061749528550808091180185","best_ask":"0.86","best_bid":"0.83","hash":"e5431794ef24e5726428f0733654d05ad80c4d18","price":"0.74","side":"BUY","size":"30"},{"asset_id":"17406866367975599232214757606801140480252276357934486651183783311435802862074","best_ask":"0.17","best_bid":"0.14","hash":"d60fdb6c6ed1e29037989e21079d57b9a9c6a3b9","price":"0.26","side":"SELL","size":"30"}],"timestamp":"1786845519545"}}
{"f":824,"recv_ms":1786845519771,"raw":{"event_type":"price_change","market":"0xd5f15f31689703aea70b93a52194a0964220d10d92ee7497346f146a8b6ef8ab","price_changes":[{"asset_id":"17406866367975599232214757606801140480252276357934486651183783311435802862074","best_ask":"0.17","best_bid":"0.14","hash":"07bb2db56ee25760cf95b04ec3be4f50cd760207","price":"0.02","side":"BUY","size":"1742.69"},{"asset_id":"2151378744569768920256500242561922410292857798164019061749528550808091180185","best_ask":"0.86","best_bid":"0.83","hash":"6606125e5a5d0255c9403cd52b48620fef1d309f","price":"0.98","side":"SELL","size":"1742.69"}],"timestamp":"1786845519546"}}
{"f":825,"recv_ms":1786845519771,"raw":{"event_type":"price_change","market":"0xd5f15f31689703aea70b93a52194a0964220d10d92ee7497346f146a8b6ef8ab","price_changes":[{"asset_id":"2151378744569768920256500242561922410292857798164019061749528550808091180185","best_ask":"0.86","best_bid":"0.83","hash":"019a4f306d65e664c5901dcf8c0f6484f8b4b601","price":"0.52","side":"BUY","size":"50.4"},{"asset_id":"17406866367975599232214757606801140480252276357934486651183783311435802862074","best_ask":"0.17","best_bid":"0.14","hash":"693c543bb42d829bfc876bcbf2d0b962fb0e1a2d","price":"0.48","side":"SELL","size":"50.4"}],"timestamp":"1786845519547"}}
{"f":826,"recv_ms":1786845519771,"raw":{"event_type":"price_change","market":"0xd5f15f31689703aea70b93a52194a0964220d10d92ee7497346f146a8b6ef8ab","price_changes":[{"asset_id":"2151378744569768920256500242561922410292857798164019061749528550808091180185","best_ask":"0.86","best_bid":"0.83","hash":"3fe19537d736c401da6b940b49cf0a8a969764f7","price":"0.37","side":"BUY","size":"155.2"},{"asset_id":"17406866367975599232214757606801140480252276357934486651183783311435802862074","best_ask":"0.17","best_bid":"0.14","hash":"866388c7b7ec18340ebbc90adbe2d5bd90228799","price":"0.63","side":"SELL","size":"155.2"}],"timestamp":"1786845519547"}}
{"f":827,"recv_ms":1786845519771,"raw":{"event_type":"price_change","market":"0xd5f15f31689703aea70b93a52194a0964220d10d92ee7497346f146a8b6ef8ab","price_changes":[{"asset_id":"2151378744569768920256500242561922410292857798164019061749528550808091180185","best_ask":"0.86","best_bid":"0.83","hash":"3b654d1064621dc6eccbecb181bc6933fc6fe73e","price":"0.83","side":"BUY","size":"325.52"},{"asset_id":"17406866367975599232214757606801140480252276357934486651183783311435802862074","best_ask":"0.17","best_bid":"0.14","hash":"f222ba9c2352c910990ed30f45a723fb86c983c1","price":"0.17","side":"SELL","size":"325.52"}],"timestamp":"1786845519548"}}
{"f":828,"recv_ms":1786845519771,"raw":{"event_type":"price_change","market":"0xd5f15f31689703aea70b93a52194a0964220d10d92ee7497346f146a8b6ef8ab","price_changes":[{"asset_id":"2151378744569768920256500242561922410292857798164019061749528550808091180185","best_ask":"0.86","best_bid":"0.84","hash":"7d6b3ab617febb3ea165cd4ece332badf828ea90","price":"0.84","side":"BUY","size":"33.33"},{"asset_id":"17406866367975599232214757606801140480252276357934486651183783311435802862074","best_ask":"0.16","best_bid":"0.14","hash":"4845fbebad64532a0d43a5da205f9ea5ec25d6d0","price":"0.16","side":"SELL","size":"33.33"}],"timestamp":"1786845519549"}}
{"f":829,"recv_ms":1786845519771,"raw":{"event_type":"price_change","market":"0xd5f15f31689703aea70b93a52194a0964220d10d92ee7497346f146a8b6ef8ab","price_changes":[{"asset_id":"2151378744569768920256500242561922410292857798164019061749528550808091180185","best_ask":"0.86","best_bid":"0.84","hash":"14e44d76bf3ae36a1a80c1ced870cc589200e52c","price":"0.36","side":"BUY","size":"155.3"},{"asset_id":"17406866367975599232214757606801140480252276357934486651183783311435802862074","best_ask":"0.16","best_bid":"0.14","hash":"83f570ff9cc492339ef5233b089e22441885220b","price":"0.64","side":"SELL","size":"155.3"}],"timestamp":"1786845519550"}}
{"f":830,"recv_ms":1786845519771,"raw":{"event_type":"price_change","market":"0xd5f15f31689703aea70b93a52194a0964220d10d92ee7497346f146a8b6ef8ab","price_changes":[{"asset_id":"17406866367975599232214757606801140480252276357934486651183783311435802862074","best_ask":"0.16","best_bid":"0.14","hash":"40e174ca68169aadf200341b7076b12c016bc8b8","price":"0.16","side":"SELL","size":"48.33"},{"asset_id":"2151378744569768920256500242561922410292857798164019061749528550808091180185","best_ask":"0.86","best_bid":"0.84","hash":"a82b3300a3c324803c5084f654afc73fac11431b","price":"0.84","side":"BUY","size":"48.33"}],"timestamp":"1786845519551"}}
{"f":831,"recv_ms":1786845519771,"raw":{"event_type":"price_change","market":"0xd5f15f31689703aea70b93a52194a0964220d10d92ee7497346f146a8b6ef8ab","price_changes":[{"asset_id":"2151378744569768920256500242561922410292857798164019061749528550808091180185","best_ask":"0.86","best_bid":"0.84","hash":"e3e4996fda43c83eb1cd4b91cd84c43df458a968","price":"0.84","side":"BUY","size":"81.66"},{"asset_id":"17406866367975599232214757606801140480252276357934486651183783311435802862074","best_ask":"0.16","best_bid":"0.14","hash":"ae4d57292031fab55fa7ca030b933bdedf3c09d0","price":"0.16","side":"SELL","size":"81.66"}],"timestamp":"1786845519552"}}
{"f":832,"recv_ms":1786845519771,"raw":{"event_type":"price_change","market":"0xd5f15f31689703aea70b93a52194a0964220d10d92ee7497346f146a8b6ef8ab","price_changes":[{"asset_id":"2151378744569768920256500242561922410292857798164019061749528550808091180185","best_ask":"0.86","best_bid":"0.84","hash":"e137306a5d77661a7e58766b137add2fb6bf6271","price":"0.84","side":"BUY","size":"91.66"},{"asset_id":"17406866367975599232214757606801140480252276357934486651183783311435802862074","best_ask":"0.16","best_bid":"0.14","hash":"e49729c9c658d68c6b609723c521ca8e4821da0d","price":"0.16","side":"SELL","size":"91.66"}],"timestamp":"1786845519552"}}
{"f":833,"recv_ms":1786845519771,"raw":{"event_type":"price_change","market":"0xd5f15f31689703aea70b93a52194a0964220d10d92ee7497346f146a8b6ef8ab","price_changes":[{"asset_id":"17406866367975599232214757606801140480252276357934486651183783311435802862074","best_ask":"0.16","best_bid":"0.14","hash":"30be5933211104222d88c6d03affc5a07583cc0f","price":"0.16","side":"SELL","size":"101.66"},{"asset_id":"2151378744569768920256500242561922410292857798164019061749528550808091180185","best_ask":"0.86","best_bid":"0.84","hash":"da289e1505dd07d94b4514c4952d0b7909a1b68c","price":"0.84","side":"BUY","size":"101.66"}],"timestamp":"1786845519554"}}
{"f":834,"recv_ms":1786845519774,"raw":{"event_type":"price_change","market":"0xd5f15f31689703aea70b93a52194a0964220d10d92ee7497346f146a8b6ef8ab","price_changes":[{"asset_id":"17406866367975599232214757606801140480252276357934486651183783311435802862074","best_ask":"0.16","best_bid":"0.14","hash":"5681eb2cd6177fca22db37c0acd8de3236195f40","price":"0.16","side":"SELL","size":"118.66"},{"asset_id":"2151378744569768920256500242561922410292857798164019061749528550808091180185","best_ask":"0.86","best_bid":"0.84","hash":"e57f2b8bf40d11c5a9669fda3d53056658d73a1d","price":"0.84","side":"BUY","size":"118.66"}],"timestamp":"1786845519555"}}
{"f":835,"recv_ms":1786845519774,"raw":{"event_type":"price_change","market":"0xd5f15f31689703aea70b93a52194a0964220d10d92ee7497346f146a8b6ef8ab","price_changes":[{"asset_id":"17406866367975599232214757606801140480252276357934486651183783311435802862074","best_ask":"0.16","best_bid":"0.14","hash":"817a994593dbea4faf5d987af500a70f274d8efd","price":"0.16","side":"SELL","size":"123.66"},{"asset_id":"2151378744569768920256500242561922410292857798164019061749528550808091180185","best_ask":"0.86","best_bid":"0.84","hash":"8d7295edcad2be465a7ddaf50f770cb606b4ae03","price":"0.84","side":"BUY","size":"123.66"}],"timestamp":"1786845519556"}}
{"f":836,"recv_ms":1786845519774,"raw":{"event_type":"price_change","market":"0xd5f15f31689703aea70b93a52194a0964220d10d92ee7497346f146a8b6ef8ab","price_changes":[{"asset_id":"2151378744569768920256500242561922410292857798164019061749528550808091180185","best_ask":"0.86","best_bid":"0.84","hash":"a6635c44a8302321e13a973ec772739e14ecdecc","price":"0.84","side":"BUY","size":"155.66"},{"asset_id":"17406866367975599232214757606801140480252276357934486651183783311435802862074","best_ask":"0.16","best_bid":"0.14","hash":"693a9c8d2772e8df239556ab6596761ba4f76cfb","price":"0.16","side":"SELL","size":"155.66"}],"timestamp":"1786845519557"}}
{"f":837,"recv_ms":1786845519774,"raw":{"event_type":"price_change","market":"0xd5f15f31689703aea70b93a52194a0964220d10d92ee7497346f146a8b6ef8ab","price_changes":[{"asset_id":"17406866367975599232214757606801140480252276357934486651183783311435802862074","best_ask":"0.16","best_bid":"0.14","hash":"354bd503b7a30b10da7e25d2f9644a6badeee603","price":"0.16","side":"SELL","size":"160.66"},{"asset_id":"2151378744569768920256500242561922410292857798164019061749528550808091180185","best_ask":"0.86","best_bid":"0.84","hash":"b34209f5aaa456ceab459fe017f77c87255e3193","price":"0.84","side":"BUY","size":"160.66"}],"timestamp":"1786845519559"}}
{"f":838,"recv_ms":1786845519774,"raw":{"event_type":"price_change","market":"0xd5f15f31689703aea70b93a52194a0964220d10d92ee7497346f146a8b6ef8ab","price_changes":[{"asset_id":"17406866367975599232214757606801140480252276357934486651183783311435802862074","best_ask":"0.16","best_bid":"0.14","hash":"8a5333d06f1837d99113c1466058c5c37c4dd28a","price":"0.16","side":"SELL","size":"165.66"},{"asset_id":"2151378744569768920256500242561922410292857798164019061749528550808091180185","best_ask":"0.86","best_bid":"0.84","hash":"7fee3d8c62c6ab3555230067c7a6a0d77a64760a","price":"0.84","side":"BUY","size":"165.66"}],"timestamp":"1786845519560"}}
{"f":839,"recv_ms":1786845519777,"raw":{"event_type":"price_change","market":"0xd5f15f31689703aea70b93a52194a0964220d10d92ee7497346f146a8b6ef8ab","price_changes":[{"asset_id":"2151378744569768920256500242561922410292857798164019061749528550808091180185","best_ask":"0.86","best_bid":"0.84","hash":"90524a07f1cfda396a45ce7cf02f3adae0df3ede","price":"0.84","side":"BUY","size":"198.99"},{"asset_id":"17406866367975599232214757606801140480252276357934486651183783311435802862074","best_ask":"0.16","best_bid":"0.14","hash":"bffffb83be64e4fc76ed7f5d96b94642858647f8","price":"0.16","side":"SELL","size":"198.99"}],"timestamp":"1786845519561"}}
{"f":840,"recv_ms":1786845519777,"raw":{"event_type":"price_change","market":"0xd5f15f31689703aea70b93a52194a0964220d10d92ee7497346f146a8b6ef8ab","price_changes":[{"asset_id":"2151378744569768920256500242561922410292857798164019061749528550808091180185","best_ask":"0.86","best_bid":"0.84","hash":"4783540b3d39fe7b7d989bae5821e11326a9e434","price":"0.84","side":"BUY","size":"203.99"},{"asset_id":"17406866367975599232214757606801140480252276357934486651183783311435802862074","best_ask":"0.16","best_bid":"0.14","hash":"85c4bcfec3967b49e0b1f4d74cffcb6055427a28","price":"0.16","side":"SELL","size":"203.99"}],"timestamp":"1786845519562"}}
{"f":841,"recv_ms":1786845519777,"raw":{"event_type":"price_change","market":"0xd5f15f31689703aea70b93a52194a0964220d10d92ee7497346f146a8b6ef8ab","price_changes":[{"asset_id":"17406866367975599232214757606801140480252276357934486651183783311435802862074","best_ask":"0.16","best_bid":"0.14","hash":"bd55dc7665988ac8c7f9b3dc2155fb551d97bde0","price":"0.29","side":"SELL","size":"5"},{"asset_id":"2151378744569768920256500242561922410292857798164019061749528550808091180185","best_ask":"0.86","best_bid":"0.84","hash":"771e1289258b8ca4bae69643107e3d4a781af620","price":"0.71","side":"BUY","size":"5"}],"timestamp":"1786845519563"}}
{"f":842,"recv_ms":1786845519778,"raw":{"event_type":"price_change","market":"0xd5f15f31689703aea70b93a52194a0964220d10d92ee7497346f146a8b6ef8ab","price_changes":[{"asset_id":"2151378744569768920256500242561922410292857798164019061749528550808091180185","best_ask":"0.86","best_bid":"0.84","hash":"ccb9733ef7dd7eeb20c16a6c3d552b9061500a8a","price":"0.45","side":"BUY","size":"21.5"},{"asset_id":"17406866367975599232214757606801140480252276357934486651183783311435802862074","best_ask":"0.16","best_bid":"0.14","hash":"59c8e1fa1319695a7c1130a83d7a3fe76c110bf6","price":"0.55","side":"SELL","size":"21.5"}],"timestamp":"1786845519563"}}
{"f":843,"recv_ms":1786845519778,"raw":{"event_type":"price_change","market":"0xd5f15f31689703aea70b93a52194a0964220d10d92ee7497346f146a8b6ef8ab","price_changes":[{"asset_id":"2151378744569768920256500242561922410292857798164019061749528550808091180185","best_ask":"0.86","best_bid":"0.84","hash":"ccb9733ef7dd7eeb20c16a6c3d552b9061500a8a","price":"0.46","side":"BUY","size":"21.5"},{"asset_id":"17406866367975599232214757606801140480252276357934486651183783311435802862074","best_ask":"0.16","best_bid":"0.14","hash":"59c8e1fa1319695a7c1130a83d7a3fe76c110bf6","price":"0.54","side":"SELL","size":"21.5"}],"timestamp":"1786845519563"}}
{"f":844,"recv_ms":1786845519780,"raw":{"event_type":"price_change","market":"0xd5f15f31689703aea70b93a52194a0964220d10d92ee7497346f146a8b6ef8ab","price_changes":[{"asset_id":"2151378744569768920256500242561922410292857798164019061749528550808091180185","best_ask":"0.86","best_bid":"0.84","hash":"ccb9733ef7dd7eeb20c16a6c3d552b9061500a8a","price":"0.47","side":"BUY","size":"21.4"},{"asset_id":"17406866367975599232214757606801140480252276357934486651183783311435802862074","best_ask":"0.16","best_bid":"0.14","hash":"59c8e1fa1319695a7c1130a83d7a3fe76c110bf6","price":"0.53","side":"SELL","size":"21.4"}],"timestamp":"1786845519563"}}
{"f":845,"recv_ms":1786845519780,"raw":{"event_type":"price_change","market":"0xd5f15f31689703aea70b93a52194a0964220d10d92ee7497346f146a8b6ef8ab","price_changes":[{"asset_id":"2151378744569768920256500242561922410292857798164019061749528550808091180185","best_ask":"0.86","best_bid":"0.84","hash":"ccb9733ef7dd7eeb20c16a6c3d552b9061500a8a","price":"0.48","side":"BUY","size":"20.4"},{"asset_id":"17406866367975599232214757606801140480252276357934486651183783311435802862074","best_ask":"0.16","best_bid":"0.14","hash":"59c8e1fa1319695a7c1130a83d7a3fe76c110bf6","price":"0.52","side":"SELL","size":"20.4"}],"timestamp":"1786845519563"}}
{"f":846,"recv_ms":1786845519780,"raw":{"event_type":"price_change","market":"0xd5f15f31689703aea70b93a52194a0964220d10d92ee7497346f146a8b6ef8ab","price_changes":[{"asset_id":"2151378744569768920256500242561922410292857798164019061749528550808091180185","best_ask":"0.86","best_bid":"0.84","hash":"ccb9733ef7dd7eeb20c16a6c3d552b9061500a8a","price":"0.49","side":"BUY","size":"20.4"},{"asset_id":"17406866367975599232214757606801140480252276357934486651183783311435802862074","best_ask":"0.16","best_bid":"0.14","hash":"59c8e1fa1319695a7c1130a83d7a3fe76c110bf6","price":"0.51","side":"SELL","size":"20.4"}],"timestamp":"1786845519563"}}
{"f":847,"recv_ms":1786845519783,"raw":{"event_type":"price_change","market":"0xd5f15f31689703aea70b93a52194a0964220d10d92ee7497346f146a8b6ef8ab","price_changes":[{"asset_id":"2151378744569768920256500242561922410292857798164019061749528550808091180185","best_ask":"0.86","best_bid":"0.84","hash":"ccb9733ef7dd7eeb20c16a6c3d552b9061500a8a","price":"0.5","side":"BUY","size":"20.4"},{"asset_id":"17406866367975599232214757606801140480252276357934486651183783311435802862074","best_ask":"0.16","best_bid":"0.14","hash":"59c8e1fa1319695a7c1130a83d7a3fe76c110bf6","price":"0.5","side":"SELL","size":"20.4"}],"timestamp":"1786845519563"}}
{"f":848,"recv_ms":1786845519783,"raw":{"event_type":"price_change","market":"0xd5f15f31689703aea70b93a52194a0964220d10d92ee7497346f146a8b6ef8ab","price_changes":[{"asset_id":"2151378744569768920256500242561922410292857798164019061749528550808091180185","best_ask":"0.86","best_bid":"0.84","hash":"ccb9733ef7dd7eeb20c16a6c3d552b9061500a8a","price":"0.51","side":"BUY","size":"20.4"},{"asset_id":"17406866367975599232214757606801140480252276357934486651183783311435802862074","best_ask":"0.16","best_bid":"0.14","hash":"59c8e1fa1319695a7c1130a83d7a3fe76c110bf6","price":"0.49","side":"SELL","size":"20.4"}],"timestamp":"1786845519563"}}
{"f":849,"recv_ms":1786845519783,"raw":{"event_type":"price_change","market":"0xd5f15f31689703aea70b93a52194a0964220d10d92ee7497346f146a8b6ef8ab","price_changes":[{"asset_id":"2151378744569768920256500242561922410292857798164019061749528550808091180185","best_ask":"0.86","best_bid":"0.84","hash":"ccb9733ef7dd7eeb20c16a6c3d552b9061500a8a","price":"0.52","side":"BUY","size":"20.4"},{"asset_id":"17406866367975599232214757606801140480252276357934486651183783311435802862074","best_ask":"0.16","best_bid":"0.14","hash":"59c8e1fa1319695a7c1130a83d7a3fe76c110bf6","price":"0.48","side":"SELL","size":"20.4"}],"timestamp":"1786845519563"}}
{"f":850,"recv_ms":1786845519783,"raw":{"event_type":"price_change","market":"0xd5f15f31689703aea70b93a52194a0964220d10d92ee7497346f146a8b6ef8ab","price_changes":[{"asset_id":"2151378744569768920256500242561922410292857798164019061749528550808091180185","best_ask":"0.86","best_bid":"0.84","hash":"ccb9733ef7dd7eeb20c16a6c3d552b9061500a8a","price":"0.53","side":"BUY","size":"9"},{"asset_id":"17406866367975599232214757606801140480252276357934486651183783311435802862074","best_ask":"0.16","best_bid":"0.14","hash":"59c8e1fa1319695a7c1130a83d7a3fe76c110bf6","price":"0.47","side":"SELL","size":"9"}],"timestamp":"1786845519563"}}
{"f":851,"recv_ms":1786845519783,"raw":{"event_type":"price_change","market":"0xd5f15f31689703aea70b93a52194a0964220d10d92ee7497346f146a8b6ef8ab","price_changes":[{"asset_id":"2151378744569768920256500242561922410292857798164019061749528550808091180185","best_ask":"0.86","best_bid":"0.84","hash":"ccb9733ef7dd7eeb20c16a6c3d552b9061500a8a","price":"0.44","side":"BUY","size":"493.6"},{"asset_id":"17406866367975599232214757606801140480252276357934486651183783311435802862074","best_ask":"0.16","best_bid":"0.14","hash":"59c8e1fa1319695a7c1130a83d7a3fe76c110bf6","price":"0.56","side":"SELL","size":"493.6"}],"timestamp":"1786845519563"}}
{"f":852,"recv_ms":1786845519783,"raw":{"event_type":"price_change","market":"0xd5f15f31689703aea70b93a52194a0964220d10d92ee7497346f146a8b6ef8ab","price_changes":[{"asset_id":"17406866367975599232214757606801140480252276357934486651183783311435802862074","best_ask":"0.16","best_bid":"0.14","hash":"25c70d1b2f9522a40168bfd7837e0a8b4c54e399","price":"0.1","side":"BUY","size":"70"},{"asset_id":"2151378744569768920256500242561922410292857798164019061749528550808091180185","best_ask":"0.86","best_bid":"0.84","hash":"7b3c08f04d41236d37b643692705ddbd3f2fb219","price":"0.9","side":"SELL","size":"70"}],"timestamp":"1786845519564"}}
{"f":853,"recv_ms":1786845519783,"raw":{"event_type":"price_change","market":"0xd5f15f31689703aea70b93a52194a0964220d10d92ee7497346f146a8b6ef8ab","price_changes":[{"asset_id":"2151378744569768920256500242561922410292857798164019061749528550808091180185","best_ask":"0.86","best_bid":"0.84","hash":"af236f890b3e5a2bec65e7dee794c106237805e6","price":"0.54","side":"BUY","size":"19"},{"asset_id":"17406866367975599232214757606801140480252276357934486651183783311435802862074","best_ask":"0.16","best_bid":"0.14","hash":"81ecf32f078f23addf95c22a01ad33886b28b988","price":"0.46","side":"SELL","size":"19"}],"timestamp":"1786845519564"}}
{"f":854,"recv_ms":1786845519783,"raw":{"event_type":"price_change","market":"0xd5f15f31689703aea70b93a52194a0964220d10d92ee7497346f146a8b6ef8ab","price_changes":[{"asset_id":"17406866367975599232214757606801140480252276357934486651183783311435802862074","best_ask":"0.16","best_bid":"0.14","hash":"04fd65c52462fecbc3a683894f234c0b75c76042","price":"0.32","side":"SELL","size":"105"},{"asset_id":"2151378744569768920256500242561922410292857798164019061749528550808091180185","best_ask":"0.86","best_bid":"0.84","hash":"af6c508763902a172ab9a82e639278c83dc79e1b","price":"0.68","side":"BUY","size":"105"}],"timestamp":"1786845519565"}}
{"f":855,"recv_ms":1786845519783,"raw":{"event_type":"price_change","market":"0xd5f15f31689703aea70b93a52194a0964220d10d92ee7497346f146a8b6ef8ab","price_changes":[{"asset_id":"2151378744569768920256500242561922410292857798164019061749528550808091180185","best_ask":"0.86","best_bid":"0.84","hash":"0ed9c79dd14523afb19579c9117d2b927ec8a060","price":"0.16","side":"BUY","size":"109.3"},{"asset_id":"17406866367975599232214757606801140480252276357934486651183783311435802862074","best_ask":"0.16","best_bid":"0.14","hash":"f30b6a3cf799dafd3c6738ebc0096da0326abd30","price":"0.84","side":"SELL","size":"109.3"}],"timestamp":"1786845519566"}}
{"f":856,"recv_ms":1786845519783,"raw":{"event_type":"price_change","market":"0xd5f15f31689703aea70b93a52194a0964220d10d92ee7497346f146a8b6ef8ab","price_changes":[{"asset_id":"2151378744569768920256500242561922410292857798164019061749528550808091180185","best_ask":"0.86","best_bid":"0.84","hash":"fcec3f5cc4e6990100106397c918a5260a26c93a","price":"0.14","side":"BUY","size":"111.6"},{"asset_id":"17406866367975599232214757606801140480252276357934486651183783311435802862074","best_ask":"0.16","best_bid":"0.14","hash":"fc4dec331e40ea6f9aadd2483dc9a5620966efb6","price":"0.86","side":"SELL","size":"111.6"}],"timestamp":"1786845519566"}}
{"f":857,"recv_ms":1786845519783,"raw":{"event_type":"price_change","market":"0xd5f15f31689703aea70b93a52194a0964220d10d92ee7497346f146a8b6ef8ab","price_changes":[{"asset_id":"2151378744569768920256500242561922410292857798164019061749528550808091180185","best_ask":"0.86","best_bid":"0.84","hash":"a5bf2fab7d0f81fb402735364ea174d7f0035c0b","price":"0.2","side":"BUY","size":"54.1"},{"asset_id":"17406866367975599232214757606801140480252276357934486651183783311435802862074","best_ask":"0.16","best_bid":"0.14","hash":"9360cba95239b999bdb0c9092e99b8f77b659627","price":"0.8","side":"SELL","size":"54.1"}],"timestamp":"1786845519566"}}
{"f":858,"recv_ms":1786845519783,"raw":{"event_type":"price_change","market":"0xd5f15f31689703aea70b93a52194a0964220d10d92ee7497346f146a8b6ef8ab","price_changes":[{"asset_id":"2151378744569768920256500242561922410292857798164019061749528550808091180185","best_ask":"0.86","best_bid":"0.84","hash":"078816babc0d61a1ac90432ae4caad39c2260256","price":"0.12","side":"BUY","size":"119.6"},{"asset_id":"17406866367975599232214757606801140480252276357934486651183783311435802862074","best_ask":"0.16","best_bid":"0.14","hash":"5898067e4e03f70b417cfec3c401e4b510377be4","price":"0.88","side":"SELL","size":"119.6"}],"timestamp":"1786845519567"}}
{"f":859,"recv_ms":1786845519783,"raw":{"event_type":"price_change","market":"0xd5f15f31689703aea70b93a52194a0964220d10d92ee7497346f146a8b6ef8ab","price_changes":[{"asset_id":"2151378744569768920256500242561922410292857798164019061749528550808091180185","best_ask":"0.86","best_bid":"0.84","hash":"efaadbc8ab241866778489a2137c099ac45811ca","price":"0.18","side":"BUY","size":"22.6"},{"asset_id":"17406866367975599232214757606801140480252276357934486651183783311435802862074","best_ask":"0.16","best_bid":"0.14","hash":"3b1fa32ceae1097d069905274926e5b6c9ca90d6","price":"0.82","side":"SELL","size":"22.6"}],"timestamp":"1786845519567"}}
{"f":860,"recv_ms":1786845519785,"raw":{"event_type":"price_change","market":"0xd5f15f31689703aea70b93a52194a0964220d10d92ee7497346f146a8b6ef8ab","price_changes":[{"asset_id":"2151378744569768920256500242561922410292857798164019061749528550808091180185","best_ask":"0.86","best_bid":"0.84","hash":"3516e431d18e5d44ef20b90562a7a9493aa5cd92","price":"0.84","side":"BUY","size":"213.99"},{"asset_id":"17406866367975599232214757606801140480252276357934486651183783311435802862074","best_ask":"0.16","best_bid":"0.14","hash":"4413ee10d44478efbf5020e3a289296a54c93668","price":"0.16","side":"SELL","size":"213.99"}],"timestamp":"1786845519568"}}
{"f":861,"recv_ms":1786845519785,"raw":{"event_type":"price_change","market":"0xd5f15f31689703aea70b93a52194a0964220d10d92ee7497346f146a8b6ef8ab","price_changes":[{"asset_id":"2151378744569768920256500242561922410292857798164019061749528550808091180185","best_ask":"0.86","best_bid":"0.84","hash":"d7abf44f2848561dd235ae380d533b774d32edd4","price":"0.53","side":"BUY","size":"14"},{"asset_id":"17406866367975599232214757606801140480252276357934486651183783311435802862074","best_ask":"0.16","best_bid":"0.14","hash":"dbc558f8dea793debe8259ee4518c3c304178f8a","price":"0.47","side":"SELL","size":"14"}],"timestamp":"1786845519569"}}
{"f":862,"recv_ms":1786845519785,"raw":{"event_type":"price_change","market":"0xd5f15f31689703aea70b93a52194a0964220d10d92ee7497346f146a8b6ef8ab","price_changes":[{"asset_id":"2151378744569768920256500242561922410292857798164019061749528550808091180185","best_ask":"0.86","best_bid":"0.84","hash":"5c0c8d81ffd1c1ed32f9d2a8d670f40d7cda0947","price":"0.84","side":"BUY","size":"223.99"},{"asset_id":"17406866367975599232214757606801140480252276357934486651183783311435802862074","best_ask":"0.16","best_bid":"0.14","hash":"d9cef27b5bf9b6629013fd681cd0feee75fb42e8","price":"0.16","side":"SELL","size":"223.99"}],"timestamp":"1786845519570"}}
{"f":863,"recv_ms":1786845519804,"raw":{"event_type":"price_change","market":"0xd5f15f31689703aea70b93a52194a0964220d10d92ee7497346f146a8b6ef8ab","price_changes":[{"asset_id":"2151378744569768920256500242561922410292857798164019061749528550808091180185","best_ask":"0.86","best_bid":"0.84","hash":"c794d8344abcb7db19013ac2f4b51998f027e249","price":"0.82","side":"BUY","size":"49.22"},{"asset_id":"17406866367975599232214757606801140480252276357934486651183783311435802862074","best_ask":"0.16","best_bid":"0.14","hash":"735923a8d839df65fcde96fb85224517da67ef8d","price":"0.18","side":"SELL","size":"49.22"}],"timestamp":"1786845519571"}}
{"f":864,"recv_ms":1786845519804,"raw":{"event_type":"price_change","market":"0xd5f15f31689703aea70b93a52194a0964220d10d92ee7497346f146a8b6ef8ab","price_changes":[{"asset_id":"2151378744569768920256500242561922410292857798164019061749528550808091180185","best_ask":"0.86","best_bid":"0.84","hash":"ee8316b0f416f5a0b58e19137e910b0f95366c67","price":"0.83","side":"BUY","size":"292.19"},{"asset_id":"17406866367975599232214757606801140480252276357934486651183783311435802862074","best_ask":"0.16","best_bid":"0.14","hash":"91bf986c471179e6e72aea18528ec36e8674794a","price":"0.17","side":"SELL","size":"292.19"}],"timestamp":"1786845519572"}}
{"f":865,"recv_ms":1786845519804,"raw":{"event_type":"price_change","market":"0xd5f15f31689703aea70b93a52194a0964220d10d92ee7497346f146a8b6ef8ab","price_changes":[{"asset_id":"2151378744569768920256500242561922410292857798164019061749528550808091180185","best_ask":"0.86","best_bid":"0.84","hash":"a300943fdf4d0ccf32d48d1346bde971d8a94a7a","price":"0.44","side":"BUY","size":"693.6"},{"asset_id":"17406866367975599232214757606801140480252276357934486651183783311435802862074","best_ask":"0.16","best_bid":"0.14","hash":"a0a21b4f8e1edf738179131878557d7b429cc796","price":"0.56","side":"SELL","size":"693.6"}],"timestamp":"1786845519572"}}
{"f":866,"recv_ms":1786845519804,"raw":{"event_type":"price_change","market":"0xd5f15f31689703aea70b93a52194a0964220d10d92ee7497346f146a8b6ef8ab","price_changes":[{"asset_id":"17406866367975599232214757606801140480252276357934486651183783311435802862074","best_ask":"0.16","best_bid":"0.14","hash":"a29d49254620bc0b24dbe483ad210b7601c70e8c","price":"0.01","side":"BUY","size":"5593.18"},{"asset_id":"2151378744569768920256500242561922410292857798164019061749528550808091180185","best_ask":"0.86","best_bid":"0.84","hash":"a0d276532ad6c5ec73f20499116cb3c6888fb043","price":"0.99","side":"SELL","size":"5593.18"}],"timestamp":"1786845519573"}}
{"f":867,"recv_ms":1786845519804,"raw":{"event_type":"price_change","market":"0xd5f15f31689703aea70b93a52194a0964220d10d92ee7497346f146a8b6ef8ab","price_changes":[{"asset_id":"2151378744569768920256500242561922410292857798164019061749528550808091180185","best_ask":"0.86","best_bid":"0.84","hash":"c0ef5354b544407d5fafd6b0b5d2f22091faf0e8","price":"0.84","side":"BUY","size":"217.74"},{"asset_id":"17406866367975599232214757606801140480252276357934486651183783311435802862074","best_ask":"0.16","best_bid":"0.14","hash":"5e8b7292d325e02d4bdec11de1e2f6e759b5e25f","price":"0.16","side":"SELL","size":"217.74"}],"timestamp":"1786845519575"}}
{"f":868,"recv_ms":1786845519813,"raw":{"event_type":"price_change","market":"0xd5f15f31689703aea70b93a52194a0964220d10d92ee7497346f146a8b6ef8ab","price_changes":[{"asset_id":"2151378744569768920256500242561922410292857798164019061749528550808091180185","best_ask":"0.86","best_bid":"0.84","hash":"bc3af2e9e0067bd815ee369e19e827946509a14d","price":"0.69","side":"BUY","size":"50"},{"asset_id":"17406866367975599232214757606801140480252276357934486651183783311435802862074","best_ask":"0.16","best_bid":"0.14","hash":"bcc64cd3fdedd7aa312219d8da1d52880cb0557c","price":"0.31","side":"SELL","size":"50"}],"timestamp":"1786845519579"}}
{"f":869,"recv_ms":1786845519813,"raw":{"event_type":"price_change","market":"0xd5f15f31689703aea70b93a52194a0964220d10d92ee7497346f146a8b6ef8ab","price_changes":[{"asset_id":"2151378744569768920256500242561922410292857798164019061749528550808091180185","best_ask":"0.86","best_bid":"0.84","hash":"5dcc0972b39a77ff959ea3325bb9e379da7bec33","price":"0.01","side":"BUY","size":"5867.54"},{"asset_id":"17406866367975599232214757606801140480252276357934486651183783311435802862074","best_ask":"0.16","best_bid":"0.14","hash":"8d0252805962152c8f99f8550ca1d9f9d1fe15e1","price":"0.99","side":"SELL","size":"5867.54"}],"timestamp":"1786845519580"}}
{"f":870,"recv_ms":1786845519813,"raw":{"event_type":"price_change","market":"0xd5f15f31689703aea70b93a52194a0964220d10d92ee7497346f146a8b6ef8ab","price_changes":[{"asset_id":"17406866367975599232214757606801140480252276357934486651183783311435802862074","best_ask":"0.16","best_bid":"0.14","hash":"618f860401bdf0927af2f16b1ec9331246bcb37c","price":"0.31","side":"SELL","size":"40"},{"asset_id":"2151378744569768920256500242561922410292857798164019061749528550808091180185","best_ask":"0.86","best_bid":"0.84","hash":"32339e54abc17c9af930ee0d0881702613c68081","price":"0.69","side":"BUY","size":"40"}],"timestamp":"1786845519581"}}
{"f":871,"recv_ms":1786845519841,"raw":{"event_type":"price_change","market":"0xd5f15f31689703aea70b93a52194a0964220d10d92ee7497346f146a8b6ef8ab","price_changes":[{"asset_id":"17406866367975599232214757606801140480252276357934486651183783311435802862074","best_ask":"0.16","best_bid":"0.14","hash":"7b4f9c1d7a36c5b2a35e5be15a5d8878b85c902a","price":"0.01","side":"BUY","size":"5598.18"},{"asset_id":"2151378744569768920256500242561922410292857798164019061749528550808091180185","best_ask":"0.86","best_bid":"0.84","hash":"64e6362fc659354f9a04581a5c83d3e56d087c43","price":"0.99","side":"SELL","size":"5598.18"}],"timestamp":"1786845519581"}}
{"f":872,"recv_ms":1786845519841,"raw":{"event_type":"price_change","market":"0xd5f15f31689703aea70b93a52194a0964220d10d92ee7497346f146a8b6ef8ab","price_changes":[{"asset_id":"2151378744569768920256500242561922410292857798164019061749528550808091180185","best_ask":"0.86","best_bid":"0.84","hash":"6ff194aa3ccbe12015b06d14258bc27748084b16","price":"0.67","side":"BUY","size":"47"},{"asset_id":"17406866367975599232214757606801140480252276357934486651183783311435802862074","best_ask":"0.16","best_bid":"0.14","hash":"601116e0a4419504997f71b2d631154c8f96e800","price":"0.33","side":"SELL","size":"47"}],"timestamp":"1786845519582"}}
{"f":873,"recv_ms":1786845519841,"raw":{"event_type":"price_change","market":"0xd5f15f31689703aea70b93a52194a0964220d10d92ee7497346f146a8b6ef8ab","price_changes":[{"asset_id":"17406866367975599232214757606801140480252276357934486651183783311435802862074","best_ask":"0.16","best_bid":"0.14","hash":"d558ff1e351db8d1f04db4c94e488f2014a9de56","price":"0.25","side":"SELL","size":"97.9"},{"asset_id":"2151378744569768920256500242561922410292857798164019061749528550808091180185","best_ask":"0.86","best_bid":"0.84","hash":"67a5cdd10698d8fc08df8454da1bf3b0c2203e20","price":"0.75","side":"BUY","size":"97.9"}],"timestamp":"1786845519583"}}
{"f":874,"recv_ms":1786845519841,"raw":{"event_type":"price_change","market":"0xd5f15f31689703aea70b93a52194a0964220d10d92ee7497346f146a8b6ef8ab","price_changes":[{"asset_id":"2151378744569768920256500242561922410292857798164019061749528550808091180185","best_ask":"0.86","best_bid":"0.84","hash":"92d2926fa515540f527705b7c5a7ab9efa2bc21a","price":"0.01","side":"BUY","size":"5872.55"},{"asset_id":"17406866367975599232214757606801140480252276357934486651183783311435802862074","best_ask":"0.16","best_bid":"0.14","hash":"b80ddd12696f74cbc7cbaff1677ec0f3c93ab1c8","price":"0.99","side":"SELL","size":"5872.55"}],"timestamp":"1786845519584"}}
{"f":875,"recv_ms":1786845519841,"raw":{"event_type":"price_change","market":"0xd5f15f31689703aea70b93a52194a0964220d10d92ee7497346f146a8b6ef8ab","price_changes":[{"asset_id":"2151378744569768920256500242561922410292857798164019061749528550808091180185","best_ask":"0.86","best_bid":"0.84","hash":"6d2c5b307ddf1ee897959f2d4d626568a7bb3c0e","price":"0.56","side":"BUY","size":"29"},{"asset_id":"17406866367975599232214757606801140480252276357934486651183783311435802862074","best_ask":"0.16","best_bid":"0.14","hash":"003ac620bd53251baeda5670c035e1eef72b97a0","price":"0.44","side":"SELL","size":"29"}],"timestamp":"1786845519585"}}
{"f":876,"recv_ms":1786845519841,"raw":{"event_type":"price_change","market":"0xd5f15f31689703aea70b93a52194a0964220d10d92ee7497346f146a8b6ef8ab","price_changes":[{"asset_id":"2151378744569768920256500242561922410292857798164019061749528550808091180185","best_ask":"0.86","best_bid":"0.84","hash":"8d65fd6e35269fbb590edea4ff7d7a3404bd6c7a","price":"0.01","side":"BUY","size":"5877.55"},{"asset_id":"17406866367975599232214757606801140480252276357934486651183783311435802862074","best_ask":"0.16","best_bid":"0.14","hash":"7295edc382130828a3f585451b950371679a7abb","price":"0.99","side":"SELL","size":"5877.55"}],"timestamp":"1786845519586"}}
{"f":877,"recv_ms":1786845519841,"raw":{"event_type":"price_change","market":"0xd5f15f31689703aea70b93a52194a0964220d10d92ee7497346f146a8b6ef8ab","price_changes":[{"asset_id":"2151378744569768920256500242561922410292857798164019061749528550808091180185","best_ask":"0.86","best_bid":"0.84","hash":"37bbe3b9ec31bf431f3bd213ccb0d89838ffdb1b","price":"0.81","side":"BUY","size":"10"},{"asset_id":"17406866367975599232214757606801140480252276357934486651183783311435802862074","best_ask":"0.16","best_bid":"0.14","hash":"da4b2db82bdaee3017dcb4d2540812e1dd83992f","price":"0.19","side":"SELL","size":"10"}],"timestamp":"1786845519586"}}
{"f":878,"recv_ms":1786845519841,"raw":{"event_type":"price_change","market":"0xd5f15f31689703aea70b93a52194a0964220d10d92ee7497346f146a8b6ef8ab","price_changes":[{"asset_id":"17406866367975599232214757606801140480252276357934486651183783311435802862074","best_ask":"0.16","best_bid":"0.14","hash":"8df64eb8c3ce333613008f90464afd8923d9d9db","price":"0.18","side":"SELL","size":"58.64"},{"asset_id":"2151378744569768920256500242561922410292857798164019061749528550808091180185","best_ask":"0.86","best_bid":"0.84","hash":"17ce450681e74b3c7f687d6bc6c98efdb7d4a691","price":"0.82","side":"BUY","size":"58.64"}],"timestamp":"1786845519587"}}
{"f":879,"recv_ms":1786845519841,"raw":{"event_type":"price_change","market":"0xd5f15f31689703aea70b93a52194a0964220d10d92ee7497346f146a8b6ef8ab","price_changes":[{"asset_id":"2151378744569768920256500242561922410292857798164019061749528550808091180185","best_ask":"0.86","best_bid":"0.84","hash":"2793c29430e23367e9ac161f0d7fa8c3a88ecf8c","price":"0.71","side":"BUY","size":"15"},{"asset_id":"17406866367975599232214757606801140480252276357934486651183783311435802862074","best_ask":"0.16","best_bid":"0.14","hash":"d187fcc2fc7f3ea85b11df19bf7e701d6d3c9cf8","price":"0.29","side":"SELL","size":"15"}],"timestamp":"1786845519587"}}
{"f":880,"recv_ms":1786845519841,"raw":{"event_type":"price_change","market":"0xd5f15f31689703aea70b93a52194a0964220d10d92ee7497346f146a8b6ef8ab","price_changes":[{"asset_id":"2151378744569768920256500242561922410292857798164019061749528550808091180185","best_ask":"0.86","best_bid":"0.85","hash":"f84dcb4b4cdfc68f0bcff3c1ad576ea343668dfd","price":"0.85","side":"BUY","size":"33.33"},{"asset_id":"17406866367975599232214757606801140480252276357934486651183783311435802862074","best_ask":"0.15","best_bid":"0.14","hash":"321fe97b22fe4c2843a47db327173c439278025d","price":"0.15","side":"SELL","size":"33.33"}],"timestamp":"1786845519589"}}
{"f":881,"recv_ms":1786845519848,"raw":{"event_type":"price_change","market":"0xd5f15f31689703aea70b93a52194a0964220d10d92ee7497346f146a8b6ef8ab","price_changes":[{"asset_id":"2151378744569768920256500242561922410292857798164019061749528550808091180185","best_ask":"0.86","best_bid":"0.85","hash":"ec04a6b52dc63e31aec188df2b9a8a36a43acd0d","price":"0.83","side":"BUY","size":"286.65"},{"asset_id":"17406866367975599232214757606801140480252276357934486651183783311435802862074","best_ask":"0.15","best_bid":"0.14","hash":"80d9fcdb1fea3e47dde3ba68011eca3b4c952408","price":"0.17","side":"SELL","size":"286.65"}],"timestamp":"1786845519590"}}
{"f":882,"recv_ms":1786845519848,"raw":{"event_type":"price_change","market":"0xd5f15f31689703aea70b93a52194a0964220d10d92ee7497346f146a8b6ef8ab","price_changes":[{"asset_id":"17406866367975599232214757606801140480252276357934486651183783311435802862074","best_ask":"0.15","best_bid":"0.14","hash":"6b0eec4c34116577437386ed29ac6f4a67e7106d","price":"0.34","side":"SELL","size":"18"},{"asset_id":"2151378744569768920256500242561922410292857798164019061749528550808091180185","best_ask":"0.86","best_bid":"0.85","hash":"fa9fbb96b9b1b0c010029b6a8efad341baed1f43","price":"0.66","side":"BUY","size":"18"}],"timestamp":"1786845519590"}}
{"f":883,"recv_ms":1786845519848,"raw":{"event_type":"price_change","market":"0xd5f15f31689703aea70b93a52194a0964220d10d92ee7497346f146a8b6ef8ab","price_changes":[{"asset_id":"2151378744569768920256500242561922410292857798164019061749528550808091180185","best_ask":"0.86","best_bid":"0.85","hash":"ead31369d1d4eb815900e15beec6fff3d6e06ef9","price":"0.85","side":"BUY","size":"66.66"},{"asset_id":"17406866367975599232214757606801140480252276357934486651183783311435802862074","best_ask":"0.15","best_bid":"0.14","hash":"dfcda7202f9ba1730ffc2c0ecf69900088d15fe5","price":"0.15","side":"SELL","size":"66.66"}],"timestamp":"1786845519590"}}
{"f":884,"recv_ms":1786845519848,"raw":{"event_type":"price_change","market":"0xd5f15f31689703aea70b93a52194a0964220d10d92ee7497346f146a8b6ef8ab","price_changes":[{"asset_id":"2151378744569768920256500242561922410292857798164019061749528550808091180185","best_ask":"0.86","best_bid":"0.85","hash":"b8566ff79ffe68fac7e5bd897d00201cdeb7c5ec","price":"0.85","side":"BUY","size":"73.03"},{"asset_id":"17406866367975599232214757606801140480252276357934486651183783311435802862074","best_ask":"0.15","best_bid":"0.14","hash":"9c505a7a39c1f759b46abc0d225d53a1e1d87575","price":"0.15","side":"SELL","size":"73.03"}],"timestamp":"1786845519591"}}
{"f":885,"recv_ms":1786845519849,"raw":{"event_type":"price_change","market":"0xd5f15f31689703aea70b93a52194a0964220d10d92ee7497346f146a8b6ef8ab","price_changes":[{"asset_id":"2151378744569768920256500242561922410292857798164019061749528550808091180185","best_ask":"0.86","best_bid":"0.85","hash":"b2f21c31e411763d527561aaf74059ee42429427","price":"0.85","side":"BUY","size":"83.03"},{"asset_id":"17406866367975599232214757606801140480252276357934486651183783311435802862074","best_ask":"0.15","best_bid":"0.14","hash":"804a458e7ca83379d071b5ee3c4403f0adbffc53","price":"0.15","side":"SELL","size":"83.03"}],"timestamp":"1786845519592"}}
{"f":886,"recv_ms":1786845519849,"raw":{"event_type":"price_change","market":"0xd5f15f31689703aea70b93a52194a0964220d10d92ee7497346f146a8b6ef8ab","price_changes":[{"asset_id":"2151378744569768920256500242561922410292857798164019061749528550808091180185","best_ask":"0.86","best_bid":"0.85","hash":"07c43d64a3792cc1fa89023fee284bc3be6c9822","price":"0.04","side":"BUY","size":"552.7"},{"asset_id":"17406866367975599232214757606801140480252276357934486651183783311435802862074","best_ask":"0.15","best_bid":"0.14","hash":"92839e22676fd0b7b9bfca41b02295c99cef9725","price":"0.96","side":"SELL","size":"552.7"}],"timestamp":"1786845519593"}}
{"f":887,"recv_ms":1786845519849,"raw":{"event_type":"price_change","market":"0xd5f15f31689703aea70b93a52194a0964220d10d92ee7497346f146a8b6ef8ab","price_changes":[{"asset_id":"17406866367975599232214757606801140480252276357934486651183783311435802862074","best_ask":"0.15","best_bid":"0.14","hash":"e173eaa830adbe27da9ab4696c1a5d5740da64c3","price":"0.01","side":"BUY","size":"5593.18"},{"asset_id":"2151378744569768920256500242561922410292857798164019061749528550808091180185","best_ask":"0.86","best_bid":"0.85","hash":"2c4ec67ab001e6f86c2a3002c54834c1e83f5d37","price":"0.99","side":"SELL","size":"5593.18"}],"timestamp":"1786845519594"}}
{"f":888,"recv_ms":1786845519849,"raw":{"event_type":"price_change","market":"0xd5f15f31689703aea70b93a52194a0964220d10d92ee7497346f146a8b6ef8ab","price_changes":[{"asset_id":"2151378744569768920256500242561922410292857798164019061749528550808091180185","best_ask":"0.86","best_bid":"0.85","hash":"d6db3feb414b2ebaa53162ee6914c4c86b72d382","price":"0.85","side":"BUY","size":"116.36"},{"asset_id":"17406866367975599232214757606801140480252276357934486651183783311435802862074","best_ask":"0.15","best_bid":"0.14","hash":"ed02468e3abfb73f7e47be27f32f6caa8ffd7fa6","price":"0.15","side":"SELL","size":"116.36"}],"timestamp":"1786845519594"}}
{"f":889,"recv_ms":1786845519849,"raw":{"event_type":"price_change","market":"0xd5f15f31689703aea70b93a52194a0964220d10d92ee7497346f146a8b6ef8ab","price_changes":[{"asset_id":"17406866367975599232214757606801140480252276357934486651183783311435802862074","best_ask":"0.15","best_bid":"0.14","hash":"5bfc530af3cea4cee0f95f7f250ec24e11608fa1","price":"0.17","side":"SELL","size":"277.37"},{"asset_id":"2151378744569768920256500242561922410292857798164019061749528550808091180185","best_ask":"0.86","best_bid":"0.85","hash":"56c201bf6e23c1871fc3f7f57f7946471736af86","price":"0.83","side":"BUY","size":"277.37"}],"timestamp":"1786845519595"}}
{"f":890,"recv_ms":1786845519851,"raw":{"event_type":"price_change","market":"0xd5f15f31689703aea70b93a52194a0964220d10d92ee7497346f146a8b6ef8ab","price_changes":[{"asset_id":"2151378744569768920256500242561922410292857798164019061749528550808091180185","best_ask":"0.86","best_bid":"0.85","hash":"5182495e78f6e9c664e2175c9f1a644872d06489","price":"0.85","side":"BUY","size":"125.64"},{"asset_id":"17406866367975599232214757606801140480252276357934486651183783311435802862074","best_ask":"0.15","best_bid":"0.14","hash":"2a393c1681d5d81259d9902f87f4016afcdca086","price":"0.15","side":"SELL","size":"125.64"}],"timestamp":"1786845519595"}}
{"f":891,"recv_ms":1786845519851,"raw":{"event_type":"price_change","market":"0xd5f15f31689703aea70b93a52194a0964220d10d92ee7497346f146a8b6ef8ab","price_changes":[{"asset_id":"2151378744569768920256500242561922410292857798164019061749528550808091180185","best_ask":"0.86","best_bid":"0.85","hash":"6868527263f6c513fcf755a59155bc44942ed330","price":"0.83","side":"BUY","size":"245.37"},{"asset_id":"17406866367975599232214757606801140480252276357934486651183783311435802862074","best_ask":"0.15","best_bid":"0.14","hash":"a6f52763b33b7881f57f2db66609b208622ee329","price":"0.17","side":"SELL","size":"245.37"}],"timestamp":"1786845519596"}}
{"f":892,"recv_ms":1786845519851,"raw":{"event_type":"price_change","market":"0xd5f15f31689703aea70b93a52194a0964220d10d92ee7497346f146a8b6ef8ab","price_changes":[{"asset_id":"2151378744569768920256500242561922410292857798164019061749528550808091180185","best_ask":"0.86","best_bid":"0.85","hash":"607a8d64e2c769e11f8558dfdd24db707143b8b5","price":"0.83","side":"BUY","size":"235.37"},{"asset_id":"17406866367975599232214757606801140480252276357934486651183783311435802862074","best_ask":"0.15","best_bid":"0.14","hash":"3c31d49a8b44664d21b6cc7d7cb669a2cac9f3c4","price":"0.17","side":"SELL","size":"235.37"}],"timestamp":"1786845519597"}}
{"f":893,"recv_ms":1786845519851,"raw":{"event_type":"price_change","market":"0xd5f15f31689703aea70b93a52194a0964220d10d92ee7497346f146a8b6ef8ab","price_changes":[{"asset_id":"2151378744569768920256500242561922410292857798164019061749528550808091180185","best_ask":"0.86","best_bid":"0.85","hash":"6e9a03cb904ec762842e322f7d7c1a08847873e6","price":"0.47","side":"BUY","size":"153.1"},{"asset_id":"17406866367975599232214757606801140480252276357934486651183783311435802862074","best_ask":"0.15","best_bid":"0.14","hash":"9a0428792804af5878069981b6da650d495ae599","price":"0.53","side":"SELL","size":"153.1"}],"timestamp":"1786845519597"}}
{"f":894,"recv_ms":1786845519851,"raw":{"event_type":"price_change","market":"0xd5f15f31689703aea70b93a52194a0964220d10d92ee7497346f146a8b6ef8ab","price_changes":[{"asset_id":"2151378744569768920256500242561922410292857798164019061749528550808091180185","best_ask":"0.86","best_bid":"0.85","hash":"6376dd15cae9c91cd1273549dc8dc1be1fa84593","price":"0.83","side":"BUY","size":"225.37"},{"asset_id":"17406866367975599232214757606801140480252276357934486651183783311435802862074","best_ask":"0.15","best_bid":"0.14","hash":"ea0efb4e09cc7132d9cac18979aa48478db54c6c","price":"0.17","side":"SELL","size":"225.37"}],"timestamp":"1786845519598"}}
{"f":895,"recv_ms":1786845519851,"raw":{"event_type":"price_change","market":"0xd5f15f31689703aea70b93a52194a0964220d10d92ee7497346f146a8b6ef8ab","price_changes":[{"asset_id":"2151378744569768920256500242561922410292857798164019061749528550808091180185","best_ask":"0.86","best_bid":"0.85","hash":"34d05b1efeb02e0741b8fb7d62ea9ab3266d3427","price":"0.55","side":"BUY","size":"119"},{"asset_id":"17406866367975599232214757606801140480252276357934486651183783311435802862074","best_ask":"0.15","best_bid":"0.14","hash":"6b30cb3298a628c1f23e171be25d5ed09f28764c","price":"0.45","side":"SELL","size":"119"}],"timestamp":"1786845519598"}}
{"f":896,"recv_ms":1786845519851,"raw":{"event_type":"price_change","market":"0xd5f15f31689703aea70b93a52194a0964220d10d92ee7497346f146a8b6ef8ab","price_changes":[{"asset_id":"2151378744569768920256500242561922410292857798164019061749528550808091180185","best_ask":"0.86","best_bid":"0.85","hash":"84ffee22aea8251dd36949535ecb7ed7f155fe05","price":"0.85","side":"BUY","size":"135.64"},{"asset_id":"17406866367975599232214757606801140480252276357934486651183783311435802862074","best_ask":"0.15","best_bid":"0.14","hash":"616a9b2e36d22699d063b05e8db80bc05d542734","price":"0.15","side":"SELL","size":"135.64"}],"timestamp":"1786845519598"}}
{"f":897,"recv_ms":1786845519851,"raw":{"event_type":"price_change","market":"0xd5f15f31689703aea70b93a52194a0964220d10d92ee7497346f146a8b6ef8ab","price_changes":[{"asset_id":"17406866367975599232214757606801140480252276357934486651183783311435802862074","best_ask":"0.15","best_bid":"0.14","hash":"0c419624eaabfda29e72631a52c10631c1d1833d","price":"0.16","side":"SELL","size":"223.74"},{"asset_id":"2151378744569768920256500242561922410292857798164019061749528550808091180185","best_ask":"0.86","best_bid":"0.85","hash":"d8464e61728e7ceec54b639dc3f92a03e66b1591","price":"0.84","side":"BUY","size":"223.74"}],"timestamp":"1786845519599"}}
