{"v":1,"kind":"header","tool":"polymarket-live-clob-research/0.1.0","started_ms":1786845512066,"clock":{"local_ms":1786845513551,"server_ms":1786845513545,"rtt_ms":183,"offset_ms":-6},"underlying":"btc","source_url":"wss://ws-subscriptions-clob.polymarket.com/ws/market","markets":[{"slug":"btc-updown-5m-1786845300","title":"Bitcoin Up or Down - August 15, 9:55PM-10:00PM ET","question":"Bitcoin Up or Down - August 15, 9:55PM-10:00PM ET","condition_id":"0xd5f15f31689703aea70b93a52194a0964220d10d92ee7497346f146a8b6ef8ab","open_ts":1786845300,"close_ts":1786845600,"up_token":"17406866367975599232214757606801140480252276357934486651183783311435802862074","down_token":"2151378744569768920256500242561922410292857798164019061749528550808091180185","tick_size":100,"min_size":5000000,"accepting_orders":true},{"slug":"btc-updown-5m-1786845600","title":"Bitcoin Up or Down - August 15, 10:00PM-10:05PM ET","question":"Bitcoin Up or Down - August 15, 10:00PM-10:05PM ET","condition_id":"0x0c33f1586ca3445a41be2863746ffb0edc32df6500f4926657b2643fe8a78258","open_ts":1786845600,"close_ts":1786845900,"up_token":"45654842686110167876337056449737479301235917003519988189654649607054904571464","down_token":"84378280634731141017197924889292000863571415141565530467641465700960218022429","tick_size":100,"min_size":5000000,"accepting_orders":true},{"slug":"btc-updown-5m-1786845900","title":"Bitcoin Up or Down - August 15, 10:05PM-10:10PM ET","question":"Bitcoin Up or Down - August 15, 10:05PM-10:10PM ET","condition_id":"0xf636967aa9d8794331ee10b9af364ea18fa3f1a9935f8c83ae9a249d8b08a931","open_ts":1786845900,"close_ts":1786846200,"up_token":"91326336689285362968457805980185782713434399212786273576721749759222414518998","down_token":"68567158191229273715522065688080768784240867677122603193993480690378524045921","tick_size":100,"min_size":5000000,"accepting_orders":true},{"slug":"btc-updown-5m-1786846200","title":"Bitcoin Up or Down - August 15, 10:10PM-10:15PM ET","question":"Bitcoin Up or Down - August 15, 10:10PM-10:15PM ET","condition_id":"0x0f808668c26a078e39fb08c32be2c04739e31f58d8d58dc81f3771760aa097da","open_ts":1786846200,"close_ts":1786846500,"up_token":"109981215458957430670008039613114505679239971255550615765913446335529931163020","down_token":"9052432239268584294914812202913499895678363531348080565599375753720096525063","tick_size":100,"min_size":5000000,"accepting_orders":true}]}
{"f":1,"recv_ms":1786845513867,"lifecycle":{"type":"market_open","slug":"btc-updown-5m-1786845300","condition_id":"0xd5f15f31689703aea70b93a52194a0964220d10d92ee7497346f146a8b6ef8ab","up_token":"17406866367975599232214757606801140480252276357934486651183783311435802862074","down_token":"2151378744569768920256500242561922410292857798164019061749528550808091180185","close_ms":1786845600000}}
{"f":2,"recv_ms":1786845513867,"lifecycle":{"type":"market_open","slug":"btc-updown-5m-1786845600","condition_id":"0x0c33f1586ca3445a41be2863746ffb0edc32df6500f4926657b2643fe8a78258","up_token":"45654842686110167876337056449737479301235917003519988189654649607054904571464","down_token":"84378280634731141017197924889292000863571415141565530467641465700960218022429","close_ms":1786845900000}}
{"f":3,"recv_ms":1786845513867,"lifecycle":{"type":"market_open","slug":"btc-updown-5m-1786845900","condition_id":"0xf636967aa9d8794331ee10b9af364ea18fa3f1a9935f8c83ae9a249d8b08a931","up_token":"91326336689285362968457805980185782713434399212786273576721749759222414518998","down_token":"68567158191229273715522065688080768784240867677122603193993480690378524045921","close_ms":1786846200000}}
{"f":4,"recv_ms":1786845513867,"lifecycle":{"type":"market_open","slug":"btc-updown-5m-1786846200","condition_id":"0x0f808668c26a078e39fb08c32be2c04739e31f58d8d58dc81f3771760aa097da","up_token":"109981215458957430670008039613114505679239971255550615765913446335529931163020","down_token":"9052432239268584294914812202913499895678363531348080565599375753720096525063","close_ms":1786846500000}}
{"f":5,"recv_ms":1786845515154,"raw":{"asks":[{"price":"0.99","size":"5588.18"},{"price":"0.98","size":"1867.69"},{"price":"0.97","size":"611.3"},{"price":"0.96","size":"367.7"},{"price":"0.95","size":"759.7"},{"price":"0.94","size":"783.1"},{"price":"0.93","size":"464.86"},{"price":"0.92","size":"83.29"},{"price":"0.91","size":"76.7"},{"price":"0.9","size":"96"},{"price":"0.89","size":"10"},{"price":"0.88","size":"5"},{"price":"0.87","size":"10"},{"price":"0.86","size":"7"},{"price":"0.85","size":"5"},{"price":"0.84","size":"63.33"},{"price":"0.83","size":"143.31"}],"asset_id":"2151378744569768920256500242561922410292857798164019061749528550808091180185","bids":[{"price":"0.01","size":"5852.53"},{"price":"0.02","size":"1700.19"},{"price":"0.03","size":"2947.29"},{"price":"0.04","size":"477.7"},{"price":"0.05","size":"762.3"},{"price":"0.06","size":"486.1"},{"price":"0.07","size":"394.9"},{"price":"0.08","size":"145.29"},{"price":"0.09","size":"141.7"},{"price":"0.1","size":"173.9"},{"price":"0.11","size":"131.6"},{"price":"0.12","size":"124.6"},{"price":"0.13","size":"118"},{"price":"0.14","size":"116.6"},{"price":"0.15","size":"120.39"},{"price":"0.16","size":"114.3"},{"price":"0.17","size":"108.39"},{"price":"0.18","size":"27.6"},{"price":"0.19","size":"31.89"},{"price":"0.2","size":"59.1"},{"price":"0.21","size":"25.7"},{"price":"0.22","size":"30.2"},{"price":"0.23","size":"119.7"},{"price":"0.24","size":"14.3"},{"price":"0.25","size":"113.9"},{"price":"0.26","size":"13.5"},{"price":"0.27","size":"113.2"},{"price":"0.28","size":"12.9"},{"price":"0.29","size":"112.6"},{"price":"0.3","size":"22.4"},{"price":"0.31","size":"112.2"},{"price":"0.32","size":"11.9"},{"price":"0.33","size":"111.8"},{"price":"0.34","size":"26.6"},{"price":"0.35","size":"125.4"},{"price":"0.36","size":"155.3"},{"price":"0.37","size":"155.2"},{"price":"0.38","size":"24"},{"price":"0.39","size":"133.9"},{"price":"0.4","size":"38.8"},{"price":"0.41","size":"162.7"},{"price":"0.42","size":"92.7"},{"price":"0.43","size":"92.6"},{"price":"0.44","size":"123.6"},{"price":"0.45","size":"51.5"},{"price":"0.46","size":"51.5"},{"price":"0.47","size":"51.4"},{"price":"0.48","size":"60.4"},{"price":"0.49","size":"60.4"},{"price":"0.5","size":"655"},{"price":"0.51","size":"50"},{"price":"0.52","size":"150"},{"price":"0.53","size":"579.64"},{"price":"0.54","size":"49"},{"price":"0.55","size":"119"},{"price":"0.56","size":"19"},{"price":"0.57","size":"24"},{"price":"0.58","size":"19"},{"price":"0.59","size":"18"},{"price":"0.6","size":"18"},{"price":"0.61","size":"84.22"},{"price":"0.62","size":"218.66"},{"price":"0.63","size":"23.57"},{"price":"0.64","size":"216.49"},{"price":"0.65","size":"18"},{"price":"0.66","size":"10"},{"price":"0.67","size":"83"},{"price":"0.68","size":"30"},{"price":"0.69","size":"193"},{"price":"0.7","size":"30"},{"price":"0.71","size":"35"},{"price":"0.72","size":"20"},{"price":"0.73","size":"38"},{"price":"0.75","size":"81.9"},{"price":"0.77","size":"45"},{"price":"0.78","size":"7"},{"price":"0.79","size":"5"},{"price":"0.8","size":"76"},{"price":"0.81","size":"10"},{"price":"0.82","size":"10"}],"event_type":"book","hash":"8182cc8b57d17f795809322ec7315452325e5a5e","last_trade_price":"0.820","market":"0xd5f15f31689703aea70b93a52194a0964220d10d92ee7497346f146a8b6ef8ab","tick_size":"0.01","timestamp":"1786845514657"}}
{"f":6,"recv_ms":1786845515154,"raw":{"asks":[{"price":"0.99","size":"94110.75"},{"price":"0.98","size":"19003"},{"price":"0.97","size":"11914.92"},{"price":"0.96","size":"388"},{"price":"0.95","size":"7079"},{"price":"0.94","size":"169"},{"price":"0.93","size":"429"},{"price":"0.92","size":"168"},{"price":"0.91","size":"664"},{"price":"0.9","size":"3450.99"},{"price":"0.89","size":"1147.8"},{"price":"0.88","size":"413.62"},{"price":"0.87","size":"379.43"},{"price":"0.86","size":"113"},{"price":"0.85","size":"3266"},{"price":"0.84","size":"18"},{"price":"0.83","size":"203"},{"price":"0.82","size":"20"},{"price":"0.81","size":"19"},{"price":"0.8","size":"706.95"},{"price":"0.79","size":"389.33"},{"price":"0.78","size":"323"},{"price":"0.77","size":"403.72"},{"price":"0.76","size":"628.86"},{"price":"0.75","size":"520.41"},{"price":"0.74","size":"667.42"},{"price":"0.73","size":"616.34"},{"price":"0.72","size":"557.9"},{"price":"0.71","size":"478.79"},{"price":"0.7","size":"255.96"},{"price":"0.69","size":"125.79"},{"price":"0.68","size":"178.29"},{"price":"0.67","size":"59.79"},{"price":"0.66","size":"24.29"},{"price":"0.65","size":"211"},{"price":"0.64","size":"93"},{"price":"0.63","size":"15"},{"price":"0.62","size":"450"},{"price":"0.61","size":"80"},{"price":"0.6","size":"45"},{"price":"0.58","size":"80"},{"price":"0.57","size":"2.58"},{"price":"0.56","size":"30"},{"price":"0.55","size":"22.78"},{"price":"0.54","size":"5"}],"asset_id":"45654842686110167876337056449737479301235917003519988189654649607054904571464","bids":[{"price":"0.01","size":"94084.89"},{"price":"0.02","size":"19003"},{"price":"0.03","size":"11896"},{"price":"0.04","size":"388"},{"price":"0.05","size":"7079"},{"price":"0.06","size":"139"},{"price":"0.07","size":"429"},{"price":"0.08","size":"168"},{"price":"0.09","size":"331"},{"price":"0.1","size":"3450.99"},{"price":"0.11","size":"1419.8"},{"price":"0.12","size":"413.62"},{"price":"0.13","size":"379.43"},{"price":"0.14","size":"113"},{"price":"0.15","size":"3266"},{"price":"0.16","size":"18"},{"price":"0.17","size":"27"},{"price":"0.18","size":"20"},{"price":"0.19","size":"19"},{"price":"0.2","size":"716.95"},{"price":"0.21","size":"531.33"},{"price":"0.22","size":"323"},{"price":"0.23","size":"397.72"},{"price":"0.24","size":"628.86"},{"price":"0.25","size":"520.41"},{"price":"0.26","size":"673.42"},{"price":"0.27","size":"610.34"},{"price":"0.28","size":"557.9"},{"price":"0.29","size":"478.79"},{"price":"0.3","size":"255.96"},{"price":"0.31","size":"125.79"},{"price":"0.32","size":"178.29"},{"price":"0.33","size":"65.79"},{"price":"0.34","size":"24.29"},{"price":"0.35","size":"211"},{"price":"0.36","size":"93"},{"price":"0.37","size":"15"},{"price":"0.38","size":"450"},{"price":"0.39","size":"80"},{"price":"0.4","size":"50"},{"price":"0.41","size":"30"},{"price":"0.42","size":"110"},{"price":"0.43","size":"102"},{"price":"0.44","size":"84"},{"price":"0.45","size":"82"},{"price":"0.46","size":"25"},{"price":"0.47","size":"220.64"},{"price":"0.48","size":"30"},{"price":"0.49","size":"115.59"},{"price":"0.5","size":"380.64"},{"price":"0.51","size":"31"},{"price":"0.52","size":"15"},{"price":"0.53","size":"30"}],"event_type":"book","hash":"a71466b4a75ac192e963535b3b517548c0edd910","last_trade_price":"0.470","market":"0x0c33f1586ca3445a41be2863746ffb0edc32df6500f4926657b2643fe8a78258","tick_size":"0.01","timestamp":"1786845510819"}}
{"f":7,"recv_ms":1786845515154,"raw":{"asks":[{"price":"0.99","size":"94084.89"},{"price":"0.98","size":"19003"},{"price":"0.97","size":"11896"},{"price":"0.96","size":"388"},{"price":"0.95","size":"7079"},{"price":"0.94","size":"139"},{"price":"0.93","size":"429"},{"price":"0.92","size":"168"},{"price":"0.91","size":"331"},{"price":"0.9","size":"3450.99"},{"price":"0.89","size":"1419.8"},{"price":"0.88","size":"413.62"},{"price":"0.87","size":"379.43"},{"price":"0.86","size":"113"},{"price":"0.85","size":"3266"},{"price":"0.84","size":"18"},{"price":"0.83","size":"27"},{"price":"0.82","size":"20"},{"price":"0.81","size":"19"},{"price":"0.8","size":"716.95"},{"price":"0.79","size":"531.33"},{"price":"0.78","size":"323"},{"price":"0.77","size":"397.72"},{"price":"0.76","size":"628.86"},{"price":"0.75","size":"520.41"},{"price":"0.74","size":"673.42"},{"price":"0.73","size":"610.34"},{"price":"0.72","size":"557.9"},{"price":"0.71","size":"478.79"},{"price":"0.7","size":"255.96"},{"price":"0.69","size":"125.79"},{"price":"0.68","size":"178.29"},{"price":"0.67","size":"65.79"},{"price":"0.66","size":"24.29"},{"price":"0.65","size":"211"},{"price":"0.64","size":"93"},{"price":"0.63","size":"15"},{"price":"0.62","size":"450"},{"price":"0.61","size":"80"},{"price":"0.6","size":"50"},{"price":"0.59","size":"30"},{"price":"0.58","size":"110"},{"price":"0.57","size":"102"},{"price":"0.56","size":"84"},{"price":"0.55","size":"82"},{"price":"0.54","size":"25"},{"price":"0.53","size":"220.64"},{"price":"0.52","size":"30"},{"price":"0.51","size":"115.59"},{"price":"0.5","size":"380.64"},{"price":"0.49","size":"31"},{"price":"0.48","size":"15"},{"price":"0.47","size":"30"}],"asset_id":"84378280634731141017197924889292000863571415141565530467641465700960218022429","bids":[{"price":"0.01","size":"94110.75"},{"price":"0.02","size":"19003"},{"price":"0.03","size":"11914.92"},{"price":"0.04","size":"388"},{"price":"0.05","size":"7079"},{"price":"0.06","size":"169"},{"price":"0.07","size":"429"},{"price":"0.08","size":"168"},{"price":"0.09","size":"664"},{"price":"0.1","size":"3450.99"},{"price":"0.11","size":"1147.8"},{"price":"0.12","size":"413.62"},{"price":"0.13","size":"379.43"},{"price":"0.14","size":"113"},{"price":"0.15","size":"3266"},{"price":"0.16","size":"18"},{"price":"0.17","size":"203"},{"price":"0.18","size":"20"},{"price":"0.19","size":"19"},{"price":"0.2","size":"706.95"},{"price":"0.21","size":"389.33"},{"price":"0.22","size":"323"},{"price":"0.23","size":"403.72"},{"price":"0.24","size":"628.86"},{"price":"0.25","size":"520.41"},{"price":"0.26","size":"667.42"},{"price":"0.27","size":"616.34"},{"price":"0.28","size":"557.9"},{"price":"0.29","size":"478.79"},{"price":"0.3","size":"255.96"},{"price":"0.31","size":"125.79"},{"price":"0.32","size":"178.29"},{"price":"0.33","size":"59.79"},{"price":"0.34","size":"24.29"},{"price":"0.35","size":"211"},{"price":"0.36","size":"93"},{"price":"0.37","size":"15"},{"price":"0.38","size":"450"},{"price":"0.39","size":"80"},{"price":"0.4","size":"45"},{"price":"0.42","size":"80"},{"price":"0.43","size":"2.58"},{"price":"0.44","size":"30"},{"price":"0.45","size":"22.78"},{"price":"0.46","size":"5"}],"event_type":"book","hash":"384fad71010ae28e319ffe5d44dccf8a9117cc07","last_trade_price":"0.470","market":"0x0c33f1586ca3445a41be2863746ffb0edc32df6500f4926657b2643fe8a78258","tick_size":"0.01","timestamp":"1786845510819"}}
{"f":8,"recv_ms":1786845515154,"raw":{"asks":[{"price":"0.99","size":"94275.85"},{"price":"0.98","size":"15503"},{"price":"0.97","size":"10616.67"},{"price":"0.96","size":"345"},{"price":"0.95","size":"6329"},{"price":"0.94","size":"138"},{"price":"0.93","size":"58"},{"price":"0.92","size":"118.5"},{"price":"0.91","size":"55"},{"price":"0.9","size":"3077"},{"price":"0.89","size":"21"},{"price":"0.88","size":"20"},{"price":"0.87","size":"18"},{"price":"0.86","size":"36"},{"price":"0.85","size":"2902"},{"price":"0.84","size":"32"},{"price":"0.83","size":"11"},{"price":"0.82","size":"42.78"},{"price":"0.81","size":"8"},{"price":"0.8","size":"35"},{"price":"0.79","size":"28.81"},{"price":"0.78","size":"25"},{"price":"0.77","size":"25"},{"price":"0.76","size":"5"},{"price":"0.75","size":"5"},{"price":"0.74","size":"5"},{"price":"0.73","size":"34.62"},{"price":"0.72","size":"5"},{"price":"0.71","size":"11"},{"price":"0.7","size":"82.5"},{"price":"0.69","size":"5"},{"price":"0.68","size":"30"},{"price":"0.67","size":"5"},{"price":"0.66","size":"5"},{"price":"0.65","size":"225.28"},{"price":"0.62","size":"13.15"},{"price":"0.61","size":"80"},{"price":"0.6","size":"46.5"},{"price":"0.59","size":"13"},{"price":"0.58","size":"92"},{"price":"0.57","size":"83"},{"price":"0.56","size":"64"},{"price":"0.55","size":"59"},{"price":"0.54","size":"23"},{"price":"0.53","size":"52.64"},{"price":"0.52","size":"36"},{"price":"0.51","size":"350.89"}],"asset_id":"91326336689285362968457805980185782713434399212786273576721749759222414518998","bids":[{"price":"0.01","size":"94253.58"},{"price":"0.02","size":"15553"},{"price":"0.03","size":"10483"},{"price":"0.04","size":"320"},{"price":"0.05","size":"6349"},{"price":"0.06","size":"108"},{"price":"0.07","size":"58"},{"price":"0.08","size":"118.5"},{"price":"0.09","size":"55"},{"price":"0.1","size":"3077"},{"price":"0.11","size":"21"},{"price":"0.12","size":"20"},{"price":"0.13","size":"18"},{"price":"0.14","size":"36"},{"price":"0.15","size":"2902"},{"price":"0.16","size":"32"},{"price":"0.17","size":"11"},{"price":"0.18","size":"15"},{"price":"0.19","size":"8"},{"price":"0.2","size":"45"},{"price":"0.21","size":"28.81"},{"price":"0.22","size":"25"},{"price":"0.23","size":"25"},{"price":"0.24","size":"5"},{"price":"0.25","size":"5"},{"price":"0.26","size":"5"},{"price":"0.27","size":"34.62"},{"price":"0.28","size":"5"},{"price":"0.29","size":"11"},{"price":"0.3","size":"82.5"},{"price":"0.31","size":"5"},{"price":"0.32","size":"30"},{"price":"0.33","size":"5"},{"price":"0.34","size":"5"},{"price":"0.35","size":"225.28"},{"price":"0.38","size":"13.15"},{"price":"0.39","size":"80"},{"price":"0.4","size":"46.5"},{"price":"0.41","size":"13"},{"price":"0.42","size":"92"},{"price":"0.43","size":"83"},{"price":"0.44","size":"64"},{"price":"0.45","size":"59"},{"price":"0.46","size":"23"},{"price":"0.47","size":"52.64"},{"price":"0.48","size":"36"},{"price":"0.49","size":"195.72"},{"price":"0.5","size":"28.75"}],"event_type":"book","hash":"f5827b84b7c52e8204e1d07db42d7af298c27de4","last_trade_price":"0.490","market":"0xf636967aa9d8794331ee10b9af364ea18fa3f1a9935f8c83ae9a249d8b08a931","tick_size":"0.01","timestamp":"1786845514459"}}
{"f":9,"recv_ms":1786845515154,"raw":{"asks":[{"price":"0.99","size":"94253.58"},{"price":"0.98","size":"15553"},{"price":"0.97","size":"10483"},{"price":"0.96","size":"320"},{"price":"0.95","size":"6349"},{"price":"0.94","size":"108"},{"price":"0.93","size":"58"},{"price":"0.92","size":"118.5"},{"price":"0.91","size":"55"},{"price":"0.9","size":"3077"},{"price":"0.89","size":"21"},{"price":"0.88","size":"20"},{"price":"0.87","size":"18"},{"price":"0.86","size":"36"},{"price":"0.85","size":"2902"},{"price":"0.84","size":"32"},{"price":"0.83","size":"11"},{"price":"0.82","size":"15"},{"price":"0.81","size":"8"},{"price":"0.8","size":"45"},{"price":"0.79","size":"28.81"},{"price":"0.78","size":"25"},{"price":"0.77","size":"25"},{"price":"0.76","size":"5"},{"price":"0.75","size":"5"},{"price":"0.74","size":"5"},{"price":"0.73","size":"34.62"},{"price":"0.72","size":"5"},{"price":"0.71","size":"11"},{"price":"0.7","size":"82.5"},{"price":"0.69","size":"5"},{"price":"0.68","size":"30"},{"price":"0.67","size":"5"},{"price":"0.66","size":"5"},{"price":"0.65","size":"225.28"},{"price":"0.62","size":"13.15"},{"price":"0.61","size":"80"},{"price":"0.6","size":"46.5"},{"price":"0.59","size":"13"},{"price":"0.58","size":"92"},{"price":"0.57","size":"83"},{"price":"0.56","size":"64"},{"price":"0.55","size":"59"},{"price":"0.54","size":"23"},{"price":"0.53","size":"52.64"},{"price":"0.52","size":"36"},{"price":"0.51","size":"195.72"},{"price":"0.5","size":"28.75"}],"asset_id":"68567158191229273715522065688080768784240867677122603193993480690378524045921","bids":[{"price":"0.01","size":"94275.85"},{"price":"0.02","size":"15503"},{"price":"0.03","size":"10616.67"},{"price":"0.04","size":"345"},{"price":"0.05","size":"6329"},{"price":"0.06","size":"138"},{"price":"0.07","size":"58"},{"price":"0.08","size":"118.5"},{"price":"0.09","size":"55"},{"price":"0.1","size":"3077"},{"price":"0.11","size":"21"},{"price":"0.12","size":"20"},{"price":"0.13","size":"18"},{"price":"0.14","size":"36"},{"price":"0.15","size":"2902"},{"price":"0.16","size":"32"},{"price":"0.17","size":"11"},{"price":"0.18","size":"42.78"},{"price":"0.19","size":"8"},{"price":"0.2","size":"35"},{"price":"0.21","size":"28.81"},{"price":"0.22","size":"25"},{"price":"0.23","size":"25"},{"price":"0.24","size":"5"},{"price":"0.25","size":"5"},{"price":"0.26","size":"5"},{"price":"0.27","size":"34.62"},{"price":"0.28","size":"5"},{"price":"0.29","size":"11"},{"price":"0.3","size":"82.5"},{"price":"0.31","size":"5"},{"price":"0.32","size":"30"},{"price":"0.33","size":"5"},{"price":"0.34","size":"5"},{"price":"0.35","size":"225.28"},{"price":"0.38","size":"13.15"},{"price":"0.39","size":"80"},{"price":"0.4","size":"46.5"},{"price":"0.41","size":"13"},{"price":"0.42","size":"92"},{"price":"0.43","size":"83"},{"price":"0.44","size":"64"},{"price":"0.45","size":"59"},{"price":"0.46","size":"23"},{"price":"0.47","size":"52.64"},{"price":"0.48","size":"36"},{"price":"0.49","size":"350.89"}],"event_type":"book","hash":"35420b6a646a1d233faa4f5c5d2c266e1c8ada1f","last_trade_price":"0.490","market":"0xf636967aa9d8794331ee10b9af364ea18fa3f1a9935f8c83ae9a249d8b08a931","tick_size":"0.01","timestamp":"1786845514459"}}
{"f":10,"recv_ms":1786845515154,"raw":{"asks":[{"price":"0.99","size":"93636.56"},{"price":"0.98","size":"15550.98"},{"price":"0.97","size":"10513"},{"price":"0.96","size":"325"},{"price":"0.95","size":"6349.91"},{"price":"0.94","size":"188"},{"price":"0.93","size":"88"},{"price":"0.92","size":"56"},{"price":"0.91","size":"45"},{"price":"0.9","size":"3067"},{"price":"0.89","size":"31"},{"price":"0.88","size":"35"},{"price":"0.87","size":"33.15"},{"price":"0.86","size":"16"},{"price":"0.85","size":"2902"},{"price":"0.84","size":"22"},{"price":"0.83","size":"21"},{"price":"0.82","size":"25"},{"price":"0.81","size":"8"},{"price":"0.8","size":"45"},{"price":"0.79","size":"15"},{"price":"0.78","size":"5"},{"price":"0.77","size":"1025"},{"price":"0.76","size":"5"},{"price":"0.75","size":"5"},{"price":"0.74","size":"15"},{"price":"0.73","size":"44.62"},{"price":"0.72","size":"535"},{"price":"0.71","size":"21"},{"price":"0.7","size":"75"},{"price":"0.69","size":"5"},{"price":"0.68","size":"35"},{"price":"0.67","size":"430.03"},{"price":"0.66","size":"10.01"},{"price":"0.65","size":"230.28"},{"price":"0.64","size":"365"},{"price":"0.63","size":"40.54"},{"price":"0.62","size":"32.88"},{"price":"0.61","size":"85.01"},{"price":"0.6","size":"379.5"},{"price":"0.59","size":"130.29"},{"price":"0.58","size":"179"},{"price":"0.57","size":"193.9"},{"price":"0.56","size":"316.27"},{"price":"0.55","size":"135"},{"price":"0.54","size":"108.6"},{"price":"0.53","size":"199.17"},{"price":"0.52","size":"74.62"},{"price":"0.51","size":"375.14"}],"asset_id":"109981215458957430670008039613114505679239971255550615765913446335529931163020","bids":[{"price":"0.01","size":"93610.49"},{"price":"0.02","size":"15550.9"},{"price":"0.03","size":"10513"},{"price":"0.04","size":"325"},{"price":"0.05","size":"6349.82"},{"price":"0.06","size":"158"},{"price":"0.07","size":"88"},{"price":"0.08","size":"56"},{"price":"0.09","size":"45"},{"price":"0.1","size":"3067"},{"price":"0.11","size":"31"},{"price":"0.12","size":"30"},{"price":"0.13","size":"38.2"},{"price":"0.14","size":"16"},{"price":"0.15","size":"2902"},{"price":"0.16","size":"22"},{"price":"0.17","size":"21"},{"price":"0.18","size":"25"},{"price":"0.19","size":"8"},{"price":"0.2","size":"45"},{"price":"0.21","size":"15"},{"price":"0.22","size":"5"},{"price":"0.23","size":"1025"},{"price":"0.24","size":"5"},{"price":"0.25","size":"5"},{"price":"0.26","size":"15"},{"price":"0.27","size":"44.62"},{"price":"0.28","size":"535"},{"price":"0.29","size":"21"},{"price":"0.3","size":"75"},{"price":"0.31","size":"5"},{"price":"0.32","size":"35"},{"price":"0.33","size":"430.03"},{"price":"0.34","size":"10.01"},{"price":"0.35","size":"230.28"},{"price":"0.36","size":"365"},{"price":"0.37","size":"40.54"},{"price":"0.38","size":"32.88"},{"price":"0.39","size":"85.01"},{"price":"0.4","size":"379.5"},{"price":"0.41","size":"130.29"},{"price":"0.42","size":"179"},{"price":"0.43","size":"193.9"},{"price":"0.44","size":"316.27"},{"price":"0.45","size":"135"},{"price":"0.46","size":"108.6"},{"price":"0.47","size":"199.17"},{"price":"0.48","size":"74.62"},{"price":"0.49","size":"219.26"},{"price":"0.5","size":"200.38"}],"event_type":"book","hash":"249b53326ea73374d06ad3ea3fad72b695b4dcf2","last_trade_price":"0.490","market":"0x0f808668c26a078e39fb08c32be2c04739e31f58d8d58dc81f3771760aa097da","tick_size":"0.01","timestamp":"1786845512925"}}
{"f":11,"recv_ms":1786845515154,"raw":{"asks":[{"price":"0.99","size":"93610.49"},{"price":"0.98","size":"15550.9"},{"price":"0.97","size":"10513"},{"price":"0.96","size":"325"},{"price":"0.95","size":"6349.82"},{"price":"0.94","size":"158"},{"price":"0.93","size":"88"},{"price":"0.92","size":"56"},{"price":"0.91","size":"45"},{"price":"0.9","size":"3067"},{"price":"0.89","size":"31"},{"price":"0.88","size":"30"},{"price":"0.87","size":"38.2"},{"price":"0.86","size":"16"},{"price":"0.85","size":"2902"},{"price":"0.84","size":"22"},{"price":"0.83","size":"21"},{"price":"0.82","size":"25"},{"price":"0.81","size":"8"},{"price":"0.8","size":"45"},{"price":"0.79","size":"15"},{"price":"0.78","size":"5"},{"price":"0.77","size":"1025"},{"price":"0.76","size":"5"},{"price":"0.75","size":"5"},{"price":"0.74","size":"15"},{"price":"0.73","size":"44.62"},{"price":"0.72","size":"535"},{"price":"0.71","size":"21"},{"price":"0.7","size":"75"},{"price":"0.69","size":"5"},{"price":"0.68","size":"35"},{"price":"0.67","size":"430.03"},{"price":"0.66","size":"10.01"},{"price":"0.65","size":"230.28"},{"price":"0.64","size":"365"},{"price":"0.63","size":"40.54"},{"price":"0.62","size":"32.88"},{"price":"0.61","size":"85.01"},{"price":"0.6","size":"379.5"},{"price":"0.59","size":"130.29"},{"price":"0.58","size":"179"},{"price":"0.57","size":"193.9"},{"price":"0.56","size":"316.27"},{"price":"0.55","size":"135"},{"price":"0.54","size":"108.6"},{"price":"0.53","size":"199.17"},{"price":"0.52","size":"74.62"},{"price":"0.51","size":"219.26"},{"price":"0.5","size":"200.38"}],"asset_id":"9052432239268584294914812202913499895678363531348080565599375753720096525063","bids":[{"price":"0.01","size":"93636.56"},{"price":"0.02","size":"15550.98"},{"price":"0.03","size":"10513"},{"price":"0.04","size":"325"},{"price":"0.05","size":"6349.91"},{"price":"0.06","size":"188"},{"price":"0.07","size":"88"},{"price":"0.08","size":"56"},{"price":"0.09","size":"45"},{"price":"0.1","size":"3067"},{"price":"0.11","size":"31"},{"price":"0.12","size":"35"},{"price":"0.13","size":"33.15"},{"price":"0.14","size":"16"},{"price":"0.15","size":"2902"},{"price":"0.16","size":"22"},{"price":"0.17","size":"21"},{"price":"0.18","size":"25"},{"price":"0.19","size":"8"},{"price":"0.2","size":"45"},{"price":"0.21","size":"15"},{"price":"0.22","size":"5"},{"price":"0.23","size":"1025"},{"price":"0.24","size":"5"},{"price":"0.25","size":"5"},{"price":"0.26","size":"15"},{"price":"0.27","size":"44.62"},{"price":"0.28","size":"535"},{"price":"0.29","size":"21"},{"price":"0.3","size":"75"},{"price":"0.31","size":"5"},{"price":"0.32","size":"35"},{"price":"0.33","size":"430.03"},{"price":"0.34","size":"10.01"},{"price":"0.35","size":"230.28"},{"price":"0.36","size":"365"},{"price":"0.37","size":"40.54"},{"price":"0.38","size":"32.88"},{"price":"0.39","size":"85.01"},{"price":"0.4","size":"379.5"},{"price":"0.41","size":"130.29"},{"price":"0.42","size":"179"},{"price":"0.43","size":"193.9"},{"price":"0.44","size":"316.27"},{"price":"0.45","size":"135"},{"price":"0.46","size":"108.6"},{"price":"0.47","size":"199.17"},{"price":"0.48","size":"74.62"},{"price":"0.49","size":"375.14"}],"event_type":"book","hash":"106e83b158247b71995fa3dd2b88c42a57162646","last_trade_price":"0.490","market":"0x0f808668c26a078e39fb08c32be2c04739e31f58d8d58dc81f3771760aa097da","tick_size":"0.01","timestamp":"1786845512925"}}
{"f":12,"recv_ms":1786845515154,"raw":{"asks":[{"price":"0.99","size":"5852.53"},{"price":"0.98","size":"1700.19"},{"price":"0.97","size":"2947.29"},{"price":"0.96","size":"477.7"},{"price":"0.95","size":"762.3"},{"price":"0.94","size":"486.1"},{"price":"0.93","size":"394.9"},{"price":"0.92","size":"145.29"},{"price":"0.91","size":"141.7"},{"price":"0.9","size":"173.9"},{"price":"0.89","size":"131.6"},{"price":"0.88","size":"124.6"},{"price":"0.87","size":"118"},{"price":"0.86","size":"116.6"},{"price":"0.85","size":"120.39"},{"price":"0.84","size":"114.3"},{"price":"0.83","size":"108.39"},{"price":"0.82","size":"27.6"},{"price":"0.81","size":"31.89"},{"price":"0.8","size":"59.1"},{"price":"0.79","size":"25.7"},{"price":"0.78","size":"30.2"},{"price":"0.77","size":"119.7"},{"price":"0.76","size":"14.3"},{"price":"0.75","size":"113.9"},{"price":"0.74","size":"13.5"},{"price":"0.73","size":"113.2"},{"price":"0.72","size":"12.9"},{"price":"0.71","size":"112.6"},{"price":"0.7","size":"22.4"},{"price":"0.69","size":"112.2"},{"price":"0.68","size":"11.9"},{"price":"0.67","size":"111.8"},{"price":"0.66","size":"26.6"},{"price":"0.65","size":"125.4"},{"price":"0.64","size":"155.3"},{"price":"0.63","size":"155.2"},{"price":"0.62","size":"24"},{"price":"0.61","size":"133.9"},{"price":"0.6","size":"38.8"},{"price":"0.59","size":"162.7"},{"price":"0.58","size":"92.7"},{"price":"0.57","size":"92.6"},{"price":"0.56","size":"123.6"},{"price":"0.55","size":"51.5"},{"price":"0.54","size":"51.5"},{"price":"0.53","size":"51.4"},{"price":"0.52","size":"60.4"},{"price":"0.51","size":"60.4"},{"price":"0.5","size":"655"},{"price":"0.49","size":"50"},{"price":"0.48","size":"150"},{"price":"0.47","size":"579.64"},{"price":"0.46","size":"49"},{"price":"0.45","size":"119"},{"price":"0.44","size":"19"},{"price":"0.43","size":"24"},{"price":"0.42","size":"19"},{"price":"0.41","size":"18"},{"price":"0.4","size":"18"},{"price":"0.39","size":"84.22"},{"price":"0.38","size":"218.66"},{"price":"0.37","size":"23.57"},{"price":"0.36","size":"216.49"},{"price":"0.35","size":"18"},{"price":"0.34","size":"10"},{"price":"0.33","size":"83"},{"price":"0.32","size":"30"},{"price":"0.31","size":"193"},{"price":"0.3","size":"30"},{"price":"0.29","size":"35"},{"price":"0.28","size":"20"},{"price":"0.27","size":"38"},{"price":"0.25","size":"81.9"},{"price":"0.23","size":"45"},{"price":"0.22","size":"7"},{"price":"0.21","size":"5"},{"price":"0.2","size":"76"},{"price":"0.19","size":"10"},{"price":"0.18","size":"10"}],"asset_id":"17406866367975599232214757606801140480252276357934486651183783311435802862074","bids":[{"price":"0.01","size":"5588.18"},{"price":"0.02","size":"1867.69"},{"price":"0.03","size":"611.3"},{"price":"0.04","size":"367.7"},{"price":"0.05","size":"759.7"},{"price":"0.06","size":"783.1"},{"price":"0.07","size":"464.86"},{"price":"0.08","size":"83.29"},{"price":"0.09","size":"76.7"},{"price":"0.1","size":"96"},{"price":"0.11","size":"10"},{"price":"0.12","size":"5"},{"price":"0.13","size":"10"},{"price":"0.14","size":"7"},{"price":"0.15","size":"5"},{"price":"0.16","size":"63.33"},{"price":"0.17","size":"143.31"}],"event_type":"book","hash":"62deef9ac1112f035ab14861d02fe5a0fb099d21","last_trade_price":"0.820","market":"0xd5f15f31689703aea70b93a52194a0964220d10d92ee7497346f146a8b6ef8ab","tick_size":"0.01","timestamp":"1786845514657"}}
{"f":13,"recv_ms":1786845515156,"raw":{"event_type":"price_change","market":"0xd5f15f31689703aea70b93a52194a0964220d10d92ee7497346f146a8b6ef8ab","price_changes":[{"asset_id":"2151378744569768920256500242561922410292857798164019061749528550808091180185","best_ask":"0.83","best_bid":"0.82","hash":"8ec2bc1725a2d6debbd1e1d34e6c2571e258a00d","price":"0.01","side":"BUY","size":"5752.53"},{"asset_id":"17406866367975599232214757606801140480252276357934486651183783311435802862074","best_ask":"0.18","best_bid":"0.17","hash":"851800b9c5bceebf640fdca00799e1c9cbef50c3","price":"0.99","side":"SELL","size":"5752.53"}],"timestamp":"1786845514694"}}
{"f":14,"recv_ms":1786845515156,"raw":{"event_type":"price_change","market":"0xd5f15f31689703aea70b93a52194a0964220d10d92ee7497346f146a8b6ef8ab","price_changes":[{"asset_id":"2151378744569768920256500242561922410292857798164019061749528550808091180185","best_ask":"0.83","best_bid":"0.82","hash":"5b25e0d689eebe8358f3bade426a27c14f28d46b","price":"0.01","side":"BUY","size":"5758.53"},{"asset_id":"17406866367975599232214757606801140480252276357934486651183783311435802862074","best_ask":"0.18","best_bid":"0.17","hash":"33ab272ecf1b4b40f3baca379fda2286f4e7d2e9","price":"0.99","side":"SELL","size":"5758.53"}],"timestamp":"1786845514712"}}
{"f":15,"recv_ms":1786845515156,"raw":{"event_type":"price_change","market":"0xd5f15f31689703aea70b93a52194a0964220d10d92ee7497346f146a8b6ef8ab","price_changes":[{"asset_id":"17406866367975599232214757606801140480252276357934486651183783311435802862074","best_ask":"0.18","best_bid":"0.17","hash":"04a0a309e4c8176c69c8a6883a9445cf38f9e18c","price":"0.16","side":"BUY","size":"53.33"},{"asset_id":"2151378744569768920256500242561922410292857798164019061749528550808091180185","best_ask":"0.83","best_bid":"0.82","hash":"243a9ed3cfd8c5be79a44c963ee207740a1ab375","price":"0.84","side":"SELL","size":"53.33"}],"timestamp":"1786845514722"}}
{"f":16,"recv_ms":1786845515156,"raw":{"event_type":"price_change","market":"0xd5f15f31689703aea70b93a52194a0964220d10d92ee7497346f146a8b6ef8ab","price_changes":[{"asset_id":"2151378744569768920256500242561922410292857798164019061749528550808091180185","best_ask":"0.83","best_bid":"0.82","hash":"0df782235edb2e0c8754211add463a5724dc218a","price":"0.01","side":"BUY","size":"5858.53"},{"asset_id":"17406866367975599232214757606801140480252276357934486651183783311435802862074","best_ask":"0.18","best_bid":"0.17","hash":"f4ecbaab3cc33e47e2a25200f422f509b8b56314","price":"0.99","side":"SELL","size":"5858.53"}],"timestamp":"1786845514733"}}
{"f":17,"recv_ms":1786845515156,"raw":{"event_type":"price_change","market":"0xd5f15f31689703aea70b93a52194a0964220d10d92ee7497346f146a8b6ef8ab","price_changes":[{"asset_id":"2151378744569768920256500242561922410292857798164019061749528550808091180185","best_ask":"0.83","best_bid":"0.82","hash":"c7bf0f6655a7114cac4f1f4c35af1827b80ee439","price":"0.01","side":"BUY","size":"5863.53"},{"asset_id":"17406866367975599232214757606801140480252276357934486651183783311435802862074","best_ask":"0.18","best_bid":"0.17","hash":"91cb90b2fd95d1df8034af74b57f27033bc23512","price":"0.99","side":"SELL","size":"5863.53"}],"timestamp":"1786845514735"}}
{"f":18,"recv_ms":1786845515156,"raw":{"event_type":"price_change","market":"0xd5f15f31689703aea70b93a52194a0964220d10d92ee7497346f146a8b6ef8ab","price_changes":[{"asset_id":"17406866367975599232214757606801140480252276357934486651183783311435802862074","best_ask":"0.18","best_bid":"0.17","hash":"f99e64f60960f142d74d2b48b4ecdeecb33e32f9","price":"0.17","side":"BUY","size":"193.31"},{"asset_id":"2151378744569768920256500242561922410292857798164019061749528550808091180185","best_ask":"0.83","best_bid":"0.82","hash":"52029ce0484f6babb1db6bdd3b33a7360be43cdd","price":"0.83","side":"SELL","size":"193.31"}],"timestamp":"1786845514736"}}
{"f":19,"recv_ms":1786845515156,"raw":{"event_type":"price_change","market":"0xd5f15f31689703aea70b93a52194a0964220d10d92ee7497346f146a8b6ef8ab","price_changes":[{"asset_id":"2151378744569768920256500242561922410292857798164019061749528550808091180185","best_ask":"0.83","best_bid":"0.82","hash":"b506900c571f98748d1d624b50688f7192ec95f0","price":"0.01","side":"BUY","size":"5857.53"},{"asset_id":"17406866367975599232214757606801140480252276357934486651183783311435802862074","best_ask":"0.18","best_bid":"0.17","hash":"9a2dbd30f4ac683641501056905d2b4287258a1c","price":"0.99","side":"SELL","size":"5857.53"}],"timestamp":"1786845514742"}}
{"f":20,"recv_ms":1786845515160,"raw":{"event_type":"price_change","market":"0xd5f15f31689703aea70b93a52194a0964220d10d92ee7497346f146a8b6ef8ab","price_changes":[{"asset_id":"2151378744569768920256500242561922410292857798164019061749528550808091180185","best_ask":"0.83","best_bid":"0.82","hash":"06487adaadafee6747a62cd9e62a5ec7dbb20ee6","price":"0.01","side":"BUY","size":"5862.54"},{"asset_id":"17406866367975599232214757606801140480252276357934486651183783311435802862074","best_ask":"0.18","best_bid":"0.17","hash":"d708d3897ac3ff8c930ee52d73158800a183519b","price":"0.99","side":"SELL","size":"5862.54"}],"timestamp":"1786845514753"}}
{"f":21,"recv_ms":1786845515160,"raw":{"event_type":"price_change","market":"0xd5f15f31689703aea70b93a52194a0964220d10d92ee7497346f146a8b6ef8ab","price_changes":[{"asset_id":"2151378744569768920256500242561922410292857798164019061749528550808091180185","best_ask":"0.83","best_bid":"0.82","hash":"6f902cb106645016beb81edef8f5046374dd51f0","price":"0.01","side":"BUY","size":"5867.54"},{"asset_id":"17406866367975599232214757606801140480252276357934486651183783311435802862074","best_ask":"0.18","best_bid":"0.17","hash":"3c175a3f665309824beb1af3bf767ad991dfa024","price":"0.99","side":"SELL","size":"5867.54"}],"timestamp":"1786845514755"}}
{"f":22,"recv_ms":1786845515160,"raw":{"event_type":"price_change","market":"0xd5f15f31689703aea70b93a52194a0964220d10d92ee7497346f146a8b6ef8ab","price_changes":[{"asset_id":"2151378744569768920256500242561922410292857798164019061749528550808091180185","best_ask":"0.83","best_bid":"0.82","hash":"8cdc985023a1ff0b03b37a31aa71573fe559834d","price":"0.01","side":"BUY","size":"5872.54"},{"asset_id":"17406866367975599232214757606801140480252276357934486651183783311435802862074","best_ask":"0.18","best_bid":"0.17","hash":"0c1607f5a6f0df5f8092822849bda994b3e601a5","price":"0.99","side":"SELL","size":"5872.54"}],"timestamp":"1786845514755"}}
{"f":23,"recv_ms":1786845515160,"raw":{"event_type":"price_change","market":"0xd5f15f31689703aea70b93a52194a0964220d10d92ee7497346f146a8b6ef8ab","price_changes":[{"asset_id":"2151378744569768920256500242561922410292857798164019061749528550808091180185","best_ask":"0.83","best_bid":"0.82","hash":"8222eda20449746dac871d0f1a32d89236ed6fdc","price":"0.01","side":"BUY","size":"5877.54"},{"asset_id":"17406866367975599232214757606801140480252276357934486651183783311435802862074","best_ask":"0.18","best_bid":"0.17","hash":"a06e244496d5240150e82be67545d2c31e38af00","price":"0.99","side":"SELL","size":"5877.54"}],"timestamp":"1786845514756"}}
{"f":24,"recv_ms":1786845515160,"raw":{"event_type":"price_change","market":"0xd5f15f31689703aea70b93a52194a0964220d10d92ee7497346f146a8b6ef8ab","price_changes":[{"asset_id":"2151378744569768920256500242561922410292857798164019061749528550808091180185","best_ask":"0.83","best_bid":"0.82","hash":"d2db1951da52e0f5bde337e9cafb65e7630a2d6d","price":"0.01","side":"BUY","size":"5872.54"},{"asset_id":"17406866367975599232214757606801140480252276357934486651183783311435802862074","best_ask":"0.18","best_bid":"0.17","hash":"83dc34aff279e9888af57aeb52fe48ec50c1ba4b","price":"0.99","side":"SELL","size":"5872.54"}],"timestamp":"1786845514763"}}
{"f":25,"recv_ms":1786845515160,"raw":{"event_type":"price_change","market":"0xf636967aa9d8794331ee10b9af364ea18fa3f1a9935f8c83ae9a249d8b08a931","price_changes":[{"asset_id":"91326336689285362968457805980185782713434399212786273576721749759222414518998","best_ask":"0.51","best_bid":"0.5","hash":"4e2dff91f1ad34d3cdc96cc0048616b101962a11","price":"0.13","side":"BUY","size":"23"},{"asset_id":"68567158191229273715522065688080768784240867677122603193993480690378524045921","best_ask":"0.5","best_bid":"0.49","hash":"6e94d55e82c8bda44dc46be6f11be054e06edda6","price":"0.87","side":"SELL","size":"23"}],"timestamp":"1786845514763"}}
{"f":26,"recv_ms":1786845515160,"raw":{"event_type":"price_change","market":"0xd5f15f31689703aea70b93a52194a0964220d10d92ee7497346f146a8b6ef8ab","price_changes":[{"asset_id":"2151378744569768920256500242561922410292857798164019061749528550808091180185","best_ask":"0.83","best_bid":"0.82","hash":"c1895c032103ca6c9516516018cddcc5ec4d9b2c","price":"0.01","side":"BUY","size":"5772.54"},{"asset_id":"17406866367975599232214757606801140480252276357934486651183783311435802862074","best_ask":"0.18","best_bid":"0.17","hash":"056bd6bff82be4d369188af64a7412ba46ca4661","price":"0.99","side":"SELL","size":"5772.54"}],"timestamp":"1786845514776"}}
{"f":27,"recv_ms":1786845515160,"raw":{"event_type":"price_change","market":"0xd5f15f31689703aea70b93a52194a0964220d10d92ee7497346f146a8b6ef8ab","price_changes":[{"asset_id":"17406866367975599232214757606801140480252276357934486651183783311435802862074","best_ask":"0.18","best_bid":"0.17","hash":"91c391adb3616bb28a0c56cdb2629e450e94ce59","price":"0.1","side":"BUY","size":"66"},{"asset_id":"2151378744569768920256500242561922410292857798164019061749528550808091180185","best_ask":"0.83","best_bid":"0.82","hash":"a75d1890242c4afb5c609a1b38ee6d1b1f643c36","price":"0.9","side":"SELL","size":"66"}],"timestamp":"1786845514778"}}
{"f":28,"recv_ms":1786845515160,"raw":{"event_type":"price_change","market":"0xd5f15f31689703aea70b93a52194a0964220d10d92ee7497346f146a8b6ef8ab","price_changes":[{"asset_id":"2151378744569768920256500242561922410292857798164019061749528550808091180185","best_ask":"0.83","best_bid":"0.82","hash":"f1932397e6885d09fc212dffe96c2037d72c86fd","price":"0.01","side":"BUY","size":"5767.53"},{"asset_id":"17406866367975599232214757606801140480252276357934486651183783311435802862074","best_ask":"0.18","best_bid":"0.17","hash":"5fb4808683773fcdc6ab400035201758040b9862","price":"0.99","side":"SELL","size":"5767.53"}],"timestamp":"1786845514781"}}
{"f":29,"recv_ms":1786845515160,"raw":{"event_type":"price_change","market":"0xd5f15f31689703aea70b93a52194a0964220d10d92ee7497346f146a8b6ef8ab","price_changes":[{"asset_id":"17406866367975599232214757606801140480252276357934486651183783311435802862074","best_ask":"0.18","best_bid":"0.17","hash":"713f6c0f1e512559a98f5fd369ba769f003134b0","price":"0.17","side":"BUY","size":"143.31"},{"asset_id":"2151378744569768920256500242561922410292857798164019061749528550808091180185","best_ask":"0.83","best_bid":"0.82","hash":"f34bcaf732595b14821d27eae7c76125089935b2","price":"0.83","side":"SELL","size":"143.31"}],"timestamp":"1786845514785"}}
{"f":30,"recv_ms":1786845515160,"raw":{"event_type":"price_change","market":"0xd5f15f31689703aea70b93a52194a0964220d10d92ee7497346f146a8b6ef8ab","price_changes":[{"asset_id":"2151378744569768920256500242561922410292857798164019061749528550808091180185","best_ask":"0.83","best_bid":"0.82","hash":"89d8db3b1f443c1c89e04c53abff9d4514ffc090","price":"0.01","side":"BUY","size":"5762.53"},{"asset_id":"17406866367975599232214757606801140480252276357934486651183783311435802862074","best_ask":"0.18","best_bid":"0.17","hash":"1b84a7a976ef48f12e004b718eacbd2f518b45e1","price":"0.99","side":"SELL","size":"5762.53"}],"timestamp":"1786845514790"}}
{"f":31,"recv_ms":1786845515160,"raw":{"event_type":"price_change","market":"0xd5f15f31689703aea70b93a52194a0964220d10d92ee7497346f146a8b6ef8ab","price_changes":[{"asset_id":"2151378744569768920256500242561922410292857798164019061749528550808091180185","best_ask":"0.83","best_bid":"0.82","hash":"8732be1f9562dcc46b455c25ea4191246f5c3f35","price":"0.01","side":"BUY","size":"5768.53"},{"asset_id":"17406866367975599232214757606801140480252276357934486651183783311435802862074","best_ask":"0.18","best_bid":"0.17","hash":"fbad7fda4efba077efc955a48ae679318f5a39f8","price":"0.99","side":"SELL","size":"5768.53"}],"timestamp":"1786845514813"}}
{"f":32,"recv_ms":1786845515160,"raw":{"event_type":"price_change","market":"0xd5f15f31689703aea70b93a52194a0964220d10d92ee7497346f146a8b6ef8ab","price_changes":[{"asset_id":"2151378744569768920256500242561922410292857798164019061749528550808091180185","best_ask":"0.83","best_bid":"0.82","hash":"24177d5fcec9e6fb008c8804a34d99f1c6281db7","price":"0.01","side":"BUY","size":"5868.53"},{"asset_id":"17406866367975599232214757606801140480252276357934486651183783311435802862074","best_ask":"0.18","best_bid":"0.17","hash":"1c3e1c3174cefe7f8915fa9fdf21b58926b40d43","price":"0.99","side":"SELL","size":"5868.53"}],"timestamp":"1786845514813"}}
{"f":33,"recv_ms":1786845515160,"raw":{"event_type":"price_change","market":"0xd5f15f31689703aea70b93a52194a0964220d10d92ee7497346f146a8b6ef8ab","price_changes":[{"asset_id":"17406866367975599232214757606801140480252276357934486651183783311435802862074","best_ask":"0.18","best_bid":"0.17","hash":"496561baeea6daa8bc1fe1c90cd5fcba4f48efc0","price":"0.01","side":"BUY","size":"5593.18"},{"asset_id":"2151378744569768920256500242561922410292857798164019061749528550808091180185","best_ask":"0.83","best_bid":"0.82","hash":"a798fe240e83fce7dbe8d44ee6bbf6decb2fb5a7","price":"0.99","side":"SELL","size":"5593.18"}],"timestamp":"1786845514816"}}
{"f":34,"recv_ms":1786845515189,"raw":{"event_type":"price_change","market":"0xd5f15f31689703aea70b93a52194a0964220d10d92ee7497346f146a8b6ef8ab","price_changes":[{"asset_id":"17406866367975599232214757606801140480252276357934486651183783311435802862074","best_ask":"0.18","best_bid":"0.17","hash":"8e31309ad48df0249d152b2d8d8df1ebb49445c9","price":"0.01","side":"BUY","size":"5588.18"},{"asset_id":"2151378744569768920256500242561922410292857798164019061749528550808091180185","best_ask":"0.83","best_bid":"0.82","hash":"e8b54f27ec862a1159907d2bfcd6a433125a09f2","price":"0.99","side":"SELL","size":"5588.18"}],"timestamp":"1786845514817"}}
{"f":35,"recv_ms":1786845515189,"raw":{"event_type":"price_change","market":"0xd5f15f31689703aea70b93a52194a0964220d10d92ee7497346f146a8b6ef8ab","price_changes":[{"asset_id":"2151378744569768920256500242561922410292857798164019061749528550808091180185","best_ask":"0.83","best_bid":"0.82","hash":"61e947e91be46646e1659dd97563c5ea6aeb919a","price":"0.82","side":"BUY","size":"15"},{"asset_id":"17406866367975599232214757606801140480252276357934486651183783311435802862074","best_ask":"0.18","best_bid":"0.17","hash":"9fc65c08ed77a4c345c3c147027fd9ae06a4859d","price":"0.18","side":"SELL","size":"15"}],"timestamp":"1786845514821"}}
{"f":36,"recv_ms":1786845515189,"raw":{"event_type":"price_change","market":"0xd5f15f31689703aea70b93a52194a0964220d10d92ee7497346f146a8b6ef8ab","price_changes":[{"asset_id":"2151378744569768920256500242561922410292857798164019061749528550808091180185","best_ask":"0.83","best_bid":"0.82","hash":"294f3aa95549c136cae716bb04cdca644ff65ed8","price":"0.01","side":"BUY","size":"5863.53"},{"asset_id":"17406866367975599232214757606801140480252276357934486651183783311435802862074","best_ask":"0.18","best_bid":"0.17","hash":"45c8645d39c33da975a2dac92f027b08284454cf","price":"0.99","side":"SELL","size":"5863.53"}],"timestamp":"1786845514821"}}
{"f":37,"recv_ms":1786845515189,"raw":{"event_type":"price_change","market":"0xd5f15f31689703aea70b93a52194a0964220d10d92ee7497346f146a8b6ef8ab","price_changes":[{"asset_id":"17406866367975599232214757606801140480252276357934486651183783311435802862074","best_ask":"0.18","best_bid":"0.17","hash":"778839e41a889094b101e66fd4bb4ef1e3de077f","price":"0.01","side":"BUY","size":"5583.18"},{"asset_id":"2151378744569768920256500242561922410292857798164019061749528550808091180185","best_ask":"0.83","best_bid":"0.82","hash":"95870780951389c390cacc61c726f0e7aba3bc8c","price":"0.99","side":"SELL","size":"5583.18"}],"timestamp":"1786845514830"}}
{"f":38,"recv_ms":1786845515189,"raw":{"event_type":"price_change","market":"0xd5f15f31689703aea70b93a52194a0964220d10d92ee7497346f146a8b6ef8ab","price_changes":[{"asset_id":"17406866367975599232214757606801140480252276357934486651183783311435802862074","best_ask":"0.18","best_bid":"0.17","hash":"f86dae8079cca5a611036656396572e3506d8016","price":"0.01","side":"BUY","size":"5588.18"},{"asset_id":"2151378744569768920256500242561922410292857798164019061749528550808091180185","best_ask":"0.83","best_bid":"0.82","hash":"ccf21f27c51693805a1f84dbfb9a1974e4c7c6e7","price":"0.99","side":"SELL","size":"5588.18"}],"timestamp":"1786845514839"}}
{"f":39,"recv_ms":1786845515509,"raw":{"event_type":"price_change","market":"0xd5f15f31689703aea70b93a52194a0964220d10d92ee7497346f146a8b6ef8ab","price_changes":[{"asset_id":"2151378744569768920256500242561922410292857798164019061749528550808091180185","best_ask":"0.83","best_bid":"0.82","hash":"e2753c4fbc1e94693d2de700ed890fdc5c9ae91e","price":"0.01","side":"BUY","size":"5857.53"},{"asset_id":"17406866367975599232214757606801140480252276357934486651183783311435802862074","best_ask":"0.18","best_bid":"0.17","hash":"efac0bf9071e8e08f3faf6324ae10de362701a1b","price":"0.99","side":"SELL","size":"5857.53"}],"timestamp":"1786845514842"}}
{"f":40,"recv_ms":1786845515509,"raw":{"event_type":"price_change","market":"0xd5f15f31689703aea70b93a52194a0964220d10d92ee7497346f146a8b6ef8ab","price_changes":[{"asset_id":"2151378744569768920256500242561922410292857798164019061749528550808091180185","best_ask":"0.83","best_bid":"0.82","hash":"9da1d531f309129ab0e998f2fbdfb8e41bb12946","price":"0.01","side":"BUY","size":"5757.53"},{"asset_id":"17406866367975599232214757606801140480252276357934486651183783311435802862074","best_ask":"0.18","best_bid":"0.17","hash":"bb8ddd66990ab148998981bcca824abb4b223a67","price":"0.99","side":"SELL","size":"5757.53"}],"timestamp":"1786845514852"}}
{"f":41,"recv_ms":1786845515509,"raw":{"event_type":"price_change","market":"0xd5f15f31689703aea70b93a52194a0964220d10d92ee7497346f146a8b6ef8ab","price_changes":[{"asset_id":"2151378744569768920256500242561922410292857798164019061749528550808091180185","best_ask":"0.83","best_bid":"0.82","hash":"4b18035d4a772e2e09783c17f3578339562c273f","price":"0.01","side":"BUY","size":"5752.53"},{"asset_id":"17406866367975599232214757606801140480252276357934486651183783311435802862074","best_ask":"0.18","best_bid":"0.17","hash":"c0d0b9e2b44187d83695596c67c3ec54b5f1b362","price":"0.99","side":"SELL","size":"5752.53"}],"timestamp":"1786845514854"}}
{"f":42,"recv_ms":1786845515509,"raw":{"event_type":"price_change","market":"0xd5f15f31689703aea70b93a52194a0964220d10d92ee7497346f146a8b6ef8ab","price_changes":[{"asset_id":"2151378744569768920256500242561922410292857798164019061749528550808091180185","best_ask":"0.83","best_bid":"0.82","hash":"2bf9dc69d02c756696fed211c68b715311c56d3c","price":"0.63","side":"BUY","size":"18"},{"asset_id":"17406866367975599232214757606801140480252276357934486651183783311435802862074","best_ask":"0.18","best_bid":"0.17","hash":"3ab0325e72ce10344c2a25781052d9526c944b0a","price":"0.37","side":"SELL","size":"18"}],"timestamp":"1786845514882"}}
{"f":43,"recv_ms":1786845515509,"raw":{"event_type":"price_change","market":"0xd5f15f31689703aea70b93a52194a0964220d10d92ee7497346f146a8b6ef8ab","price_changes":[{"asset_id":"2151378744569768920256500242561922410292857798164019061749528550808091180185","best_ask":"0.83","best_bid":"0.82","hash":"5122d6830459e6700e664164bd67b11ea5cc19fa","price":"0.01","side":"BUY","size":"5852.53"},{"asset_id":"17406866367975599232214757606801140480252276357934486651183783311435802862074","best_ask":"0.18","best_bid":"0.17","hash":"a2017cb64140a462e29a3455ed0ee046236da6c4","price":"0.99","side":"SELL","size":"5852.53"}],"timestamp":"1786845514892"}}
{"f":44,"recv_ms":1786845515509,"raw":{"event_type":"price_change","market":"0xd5f15f31689703aea70b93a52194a0964220d10d92ee7497346f146a8b6ef8ab","price_changes":[{"asset_id":"2151378744569768920256500242561922410292857798164019061749528550808091180185","best_ask":"0.83","best_bid":"0.82","hash":"3c02e49546d609872d3476483c27a6e15dcde2b5","price":"0.01","side":"BUY","size":"5858.53"},{"asset_id":"17406866367975599232214757606801140480252276357934486651183783311435802862074","best_ask":"0.18","best_bid":"0.17","hash":"ed93ab50021a931d691c6c2c1563aca6696adc53","price":"0.99","side":"SELL","size":"5858.53"}],"timestamp":"1786845514914"}}
{"f":45,"recv_ms":1786845515509,"raw":{"event_type":"price_change","market":"0xd5f15f31689703aea70b93a52194a0964220d10d92ee7497346f146a8b6ef8ab","price_changes":[{"asset_id":"2151378744569768920256500242561922410292857798164019061749528550808091180185","best_ask":"0.83","best_bid":"0.82","hash":"c6374827aa24e91e1e1bb9010cee8f25305a386e","price":"0.64","side":"BUY","size":"222.13"},{"asset_id":"17406866367975599232214757606801140480252276357934486651183783311435802862074","best_ask":"0.18","best_bid":"0.17","hash":"82f19d640484499c3f33f4e2df65665bc1b29a80","price":"0.36","side":"SELL","size":"222.13"}],"timestamp":"1786845514925"}}
{"f":46,"recv_ms":1786845515509,"raw":{"event_type":"price_change","market":"0xd5f15f31689703aea70b93a52194a0964220d10d92ee7497346f146a8b6ef8ab","price_changes":[{"asset_id":"2151378744569768920256500242561922410292857798164019061749528550808091180185","best_ask":"0.83","best_bid":"0.82","hash":"ec61127c5162b8767178ab492bfcc193d5a4fb65","price":"0.01","side":"BUY","size":"5758.53"},{"asset_id":"17406866367975599232214757606801140480252276357934486651183783311435802862074","best_ask":"0.18","best_bid":"0.17","hash":"4f9576f8892a42693fed81d78af052e7905dad9b","price":"0.99","side":"SELL","size":"5758.53"}],"timestamp":"1786845514939"}}
{"f":47,"recv_ms":1786845515509,"raw":{"event_type":"price_change","market":"0xd5f15f31689703aea70b93a52194a0964220d10d92ee7497346f146a8b6ef8ab","price_changes":[{"asset_id":"2151378744569768920256500242561922410292857798164019061749528550808091180185","best_ask":"0.83","best_bid":"0.82","hash":"f0e11d934b9e13d455d3d4cec55e86f2abd3d122","price":"0.01","side":"BUY","size":"5752.53"},{"asset_id":"17406866367975599232214757606801140480252276357934486651183783311435802862074","best_ask":"0.18","best_bid":"0.17","hash":"89cf50ce59597af927b806791f4e9a9394651d46","price":"0.99","side":"SELL","size":"5752.53"}],"timestamp":"1786845514942"}}
{"f":48,"recv_ms":1786845515509,"raw":{"event_type":"price_change","market":"0xd5f15f31689703aea70b93a52194a0964220d10d92ee7497346f146a8b6ef8ab","price_changes":[{"asset_id":"2151378744569768920256500242561922410292857798164019061749528550808091180185","best_ask":"0.83","best_bid":"0.82","hash":"fce717ea78e15d3751b21226657c12a04c7a39ad","price":"0.01","side":"BUY","size":"5757.54"},{"asset_id":"17406866367975599232214757606801140480252276357934486651183783311435802862074","best_ask":"0.18","best_bid":"0.17","hash":"c64f26408e3b98d0bcaf45f562779bfabecfbfda","price":"0.99","side":"SELL","size":"5757.54"}],"timestamp":"1786845514955"}}
{"f":49,"recv_ms":1786845515509,"raw":{"event_type":"price_change","market":"0xd5f15f31689703aea70b93a52194a0964220d10d92ee7497346f146a8b6ef8ab","price_changes":[{"asset_id":"2151378744569768920256500242561922410292857798164019061749528550808091180185","best_ask":"0.83","best_bid":"0.82","hash":"cb9202debe9c1e6e462e4e2fd9432c7234746a65","price":"0.75","side":"BUY","size":"181.9"},{"asset_id":"17406866367975599232214757606801140480252276357934486651183783311435802862074","best_ask":"0.18","best_bid":"0.17","hash":"79b80b30c1d43cd92e95db7b7e133b04f4bda336","price":"0.25","side":"SELL","size":"181.9"}],"timestamp":"1786845514967"}}
{"f":50,"recv_ms":1786845515509,"raw":{"event_type":"price_change","market":"0xd5f15f31689703aea70b93a52194a0964220d10d92ee7497346f146a8b6ef8ab","price_changes":[{"asset_id":"2151378744569768920256500242561922410292857798164019061749528550808091180185","best_ask":"0.83","best_bid":"0.82","hash":"4b086774890561df16f63f2a5976ca07a1acee9a","price":"0.01","side":"BUY","size":"5762.54"},{"asset_id":"17406866367975599232214757606801140480252276357934486651183783311435802862074","best_ask":"0.18","best_bid":"0.17","hash":"e879fbea69f57ca26126a1a2a5a95e8872126c42","price":"0.99","side":"SELL","size":"5762.54"}],"timestamp":"1786845514973"}}
{"f":51,"recv_ms":1786845515509,"raw":{"event_type":"price_change","market":"0xd5f15f31689703aea70b93a52194a0964220d10d92ee7497346f146a8b6ef8ab","price_changes":[{"asset_id":"2151378744569768920256500242561922410292857798164019061749528550808091180185","best_ask":"0.83","best_bid":"0.82","hash":"50a195a6f6752c13f4d570426b2fd5045c1678d5","price":"0.01","side":"BUY","size":"5862.54"},{"asset_id":"17406866367975599232214757606801140480252276357934486651183783311435802862074","best_ask":"0.18","best_bid":"0.17","hash":"7fdccf6182bffb9c2b964e13f25b6a1d93f0c271","price":"0.99","side":"SELL","size":"5862.54"}],"timestamp":"1786845514974"}}
{"f":52,"recv_ms":1786845515509,"raw":{"event_type":"price_change","market":"0xd5f15f31689703aea70b93a52194a0964220d10d92ee7497346f146a8b6ef8ab","price_changes":[{"asset_id":"2151378744569768920256500242561922410292857798164019061749528550808091180185","best_ask":"0.83","best_bid":"0.82","hash":"c5f807da69b9e1ae4c25dcad0a635636902d5370","price":"0.01","side":"BUY","size":"5867.54"},{"asset_id":"17406866367975599232214757606801140480252276357934486651183783311435802862074","best_ask":"0.18","best_bid":"0.17","hash":"686d688c972699f77524290255f87db37825f357","price":"0.99","side":"SELL","size":"5867.54"}],"timestamp":"1786845514975"}}
{"f":53,"recv_ms":1786845515509,"raw":{"event_type":"price_change","market":"0xd5f15f31689703aea70b93a52194a0964220d10d92ee7497346f146a8b6ef8ab","price_changes":[{"asset_id":"2151378744569768920256500242561922410292857798164019061749528550808091180185","best_ask":"0.83","best_bid":"0.82","hash":"7bc9a182ad8e04aeb4a975ad58b832d8b10d7ad4","price":"0.01","side":"BUY","size":"5872.54"},{"asset_id":"17406866367975599232214757606801140480252276357934486651183783311435802862074","best_ask":"0.18","best_bid":"0.17","hash":"50c79f9ef200b53ffaffa249b730ad6a3de7a1ae","price":"0.99","side":"SELL","size":"5872.54"}],"timestamp":"1786845514976"}}
{"f":54,"recv_ms":1786845515509,"raw":{"event_type":"price_change","market":"0xd5f15f31689703aea70b93a52194a0964220d10d92ee7497346f146a8b6ef8ab","price_changes":[{"asset_id":"2151378744569768920256500242561922410292857798164019061749528550808091180185","best_ask":"0.83","best_bid":"0.82","hash":"97a1b03e382ffede520abd201b7efffcf797e8fa","price":"0.01","side":"BUY","size":"5867.53"},{"asset_id":"17406866367975599232214757606801140480252276357934486651183783311435802862074","best_ask":"0.18","best_bid":"0.17","hash":"839e789b1cc4a657140b7dfc1b1070ad17225778","price":"0.99","side":"SELL","size":"5867.53"}],"timestamp":"1786845514981"}}
{"f":55,"recv_ms":1786845515509,"raw":{"event_type":"price_change","market":"0xd5f15f31689703aea70b93a52194a0964220d10d92ee7497346f146a8b6ef8ab","price_changes":[{"asset_id":"2151378744569768920256500242561922410292857798164019061749528550808091180185","best_ask":"0.83","best_bid":"0.82","hash":"c05ba888f0b6b34e815a77116516c6aa78a93ea4","price":"0.75","side":"BUY","size":"201.9"},{"asset_id":"17406866367975599232214757606801140480252276357934486651183783311435802862074","best_ask":"0.18","best_bid":"0.17","hash":"683ef58d3099aab7fd7ace8561236937a74af057","price":"0.25","side":"SELL","size":"201.9"}],"timestamp":"1786845514995"}}
{"f":56,"recv_ms":1786845515509,"raw":{"event_type":"price_change","market":"0xd5f15f31689703aea70b93a52194a0964220d10d92ee7497346f146a8b6ef8ab","price_changes":[{"asset_id":"2151378744569768920256500242561922410292857798164019061749528550808091180185","best_ask":"0.83","best_bid":"0.82","hash":"3ff54e6e8107d4cedff7c4a7c9ffcbb3d72dabdc","price":"0.01","side":"BUY","size":"5862.53"},{"asset_id":"17406866367975599232214757606801140480252276357934486651183783311435802862074","best_ask":"0.18","best_bid":"0.17","hash":"921fc2861b74f3ebc4ed011400a3b962a05ada76","price":"0.99","side":"SELL","size":"5862.53"}],"timestamp":"1786845515006"}}
{"f":57,"recv_ms":1786845515509,"raw":{"event_type":"price_change","market":"0xd5f15f31689703aea70b93a52194a0964220d10d92ee7497346f146a8b6ef8ab","price_changes":[{"asset_id":"2151378744569768920256500242561922410292857798164019061749528550808091180185","best_ask":"0.83","best_bid":"0.82","hash":"79b5ae7d09747b368ac7517de416df1283febf5e","price":"0.01","side":"BUY","size":"5868.53"},{"asset_id":"17406866367975599232214757606801140480252276357934486651183783311435802862074","best_ask":"0.18","best_bid":"0.17","hash":"a7a6913e70ba3d4725b6c08586f53d045e48b2ed","price":"0.99","side":"SELL","size":"5868.53"}],"timestamp":"1786845515015"}}
{"f":58,"recv_ms":1786845515509,"raw":{"event_type":"price_change","market":"0xd5f15f31689703aea70b93a52194a0964220d10d92ee7497346f146a8b6ef8ab","price_changes":[{"asset_id":"2151378744569768920256500242561922410292857798164019061749528550808091180185","best_ask":"0.83","best_bid":"0.82","hash":"4da9c9000a05b05d10f56bb84fd43b845c49dcdd","price":"0.01","side":"BUY","size":"5873.53"},{"asset_id":"17406866367975599232214757606801140480252276357934486651183783311435802862074","best_ask":"0.18","best_bid":"0.17","hash":"f7b4daae34b95e696f3719cbfaadeb151b0dfa62","price":"0.99","side":"SELL","size":"5873.53"}],"timestamp":"1786845515019"}}
{"f":59,"recv_ms":1786845515509,"raw":{"event_type":"price_change","market":"0xd5f15f31689703aea70b93a52194a0964220d10d92ee7497346f146a8b6ef8ab","price_changes":[{"asset_id":"17406866367975599232214757606801140480252276357934486651183783311435802862074","best_ask":"0.18","best_bid":"0.17","hash":"01a7e9bb67e2d5e7d4bf20dd2645f91e9030a6df","price":"0.01","side":"BUY","size":"5593.18"},{"asset_id":"2151378744569768920256500242561922410292857798164019061749528550808091180185","best_ask":"0.83","best_bid":"0.82","hash":"1d6dfee35699d1112be3b51995b145c0758a0251","price":"0.99","side":"SELL","size":"5593.18"}],"timestamp":"1786845515020"}}
{"f":60,"recv_ms":1786845515509,"raw":{"event_type":"price_change","market":"0xd5f15f31689703aea70b93a52194a0964220d10d92ee7497346f146a8b6ef8ab","price_changes":[{"asset_id":"17406866367975599232214757606801140480252276357934486651183783311435802862074","best_ask":"0.18","best_bid":"0.17","hash":"adb07f24d46973f78d5d16e904427c4239e41aa7","price":"0.01","side":"BUY","size":"5598.18"},{"asset_id":"2151378744569768920256500242561922410292857798164019061749528550808091180185","best_ask":"0.83","best_bid":"0.82","hash":"5d58bfaa2b17cd2da4cfa2747177a7a42e10abca","price":"0.99","side":"SELL","size":"5598.18"}],"timestamp":"1786845515021"}}
{"f":61,"recv_ms":1786845515509,"raw":{"event_type":"price_change","market":"0xd5f15f31689703aea70b93a52194a0964220d10d92ee7497346f146a8b6ef8ab","price_changes":[{"asset_id":"2151378744569768920256500242561922410292857798164019061749528550808091180185","best_ask":"0.83","best_bid":"0.82","hash":"92fecee48d0c5e2846e81c8be37c7361c18c7d4f","price":"0.01","side":"BUY","size":"5878.53"},{"asset_id":"17406866367975599232214757606801140480252276357934486651183783311435802862074","best_ask":"0.18","best_bid":"0.17","hash":"c8009239b707bf6f1621b30f24a5cac37fc93957","price":"0.99","side":"SELL","size":"5878.53"}],"timestamp":"1786845515021"}}
{"f":62,"recv_ms":1786845515509,"raw":{"event_type":"price_change","market":"0xd5f15f31689703aea70b93a52194a0964220d10d92ee7497346f146a8b6ef8ab","price_changes":[{"asset_id":"2151378744569768920256500242561922410292857798164019061749528550808091180185","best_ask":"0.83","best_bid":"0.82","hash":"452c8020360771a2dc7a3ce094139fdc1acaa615","price":"0.01","side":"BUY","size":"5778.53"},{"asset_id":"17406866367975599232214757606801140480252276357934486651183783311435802862074","best_ask":"0.18","best_bid":"0.17","hash":"c3dd8aba946d9bdbb256d21c8a565bcfba91a81b","price":"0.99","side":"SELL","size":"5778.53"}],"timestamp":"1786845515023"}}
{"f":63,"recv_ms":1786845515509,"raw":{"event_type":"price_change","market":"0xd5f15f31689703aea70b93a52194a0964220d10d92ee7497346f146a8b6ef8ab","price_changes":[{"asset_id":"2151378744569768920256500242561922410292857798164019061749528550808091180185","best_ask":"0.83","best_bid":"0.82","hash":"051a1e44c5e266cf67f6ba3edeab1f114537ad73","price":"0.01","side":"BUY","size":"5783.53"},{"asset_id":"17406866367975599232214757606801140480252276357934486651183783311435802862074","best_ask":"0.18","best_bid":"0.17","hash":"61ddeea7033188a434790ac41de95906cd073640","price":"0.99","side":"SELL","size":"5783.53"}],"timestamp":"1786845515023"}}
{"f":64,"recv_ms":1786845515509,"raw":{"event_type":"price_change","market":"0xd5f15f31689703aea70b93a52194a0964220d10d92ee7497346f146a8b6ef8ab","price_changes":[{"asset_id":"2151378744569768920256500242561922410292857798164019061749528550808091180185","best_ask":"0.83","best_bid":"0.82","hash":"f541f6e5832bd8c5aedbdf19039ab9d1eb90a440","price":"0.01","side":"BUY","size":"5778.53"},{"asset_id":"17406866367975599232214757606801140480252276357934486651183783311435802862074","best_ask":"0.18","best_bid":"0.17","hash":"b8b7945005f9e0aa9a24d5b114e602cabed519f5","price":"0.99","side":"SELL","size":"5778.53"}],"timestamp":"1786845515024"}}
{"f":65,"recv_ms":1786845515509,"raw":{"event_type":"price_change","market":"0xd5f15f31689703aea70b93a52194a0964220d10d92ee7497346f146a8b6ef8ab","price_changes":[{"asset_id":"2151378744569768920256500242561922410292857798164019061749528550808091180185","best_ask":"0.83","best_bid":"0.82","hash":"6e89a4d36a4975b883454fb938a69b037a3f1955","price":"0.01","side":"BUY","size":"5773.53"},{"asset_id":"17406866367975599232214757606801140480252276357934486651183783311435802862074","best_ask":"0.18","best_bid":"0.17","hash":"f42dbd50ee4fd7051ecae00bc1f408f96df7c1d9","price":"0.99","side":"SELL","size":"5773.53"}],"timestamp":"1786845515025"}}
{"f":66,"recv_ms":1786845515509,"raw":{"event_type":"price_change","market":"0xd5f15f31689703aea70b93a52194a0964220d10d92ee7497346f146a8b6ef8ab","price_changes":[{"asset_id":"2151378744569768920256500242561922410292857798164019061749528550808091180185","best_ask":"0.83","best_bid":"0.82","hash":"918ee3b5e5410b1ab422d345a9ead6c100156227","price":"0.01","side":"BUY","size":"5768.53"},{"asset_id":"17406866367975599232214757606801140480252276357934486651183783311435802862074","best_ask":"0.18","best_bid":"0.17","hash":"fcb43c9d7f704b18ccbc18fe8dea51c708b85084","price":"0.99","side":"SELL","size":"5768.53"}],"timestamp":"1786845515038"}}
{"f":67,"recv_ms":1786845515509,"raw":{"event_type":"price_change","market":"0xd5f15f31689703aea70b93a52194a0964220d10d92ee7497346f146a8b6ef8ab","price_changes":[{"asset_id":"2151378744569768920256500242561922410292857798164019061749528550808091180185","best_ask":"0.83","best_bid":"0.82","hash":"c87ecc3d04a248fc07ebe1740d25fb33b258ed8e","price":"0.01","side":"BUY","size":"5763.53"},{"asset_id":"17406866367975599232214757606801140480252276357934486651183783311435802862074","best_ask":"0.18","best_bid":"0.17","hash":"55a915b354f09e45faac4e8df82c78fc97f5aabf","price":"0.99","side":"SELL","size":"5763.53"}],"timestamp":"1786845515038"}}
{"f":68,"recv_ms":1786845515509,"raw":{"event_type":"price_change","market":"0xd5f15f31689703aea70b93a52194a0964220d10d92ee7497346f146a8b6ef8ab","price_changes":[{"asset_id":"17406866367975599232214757606801140480252276357934486651183783311435802862074","best_ask":"0.18","best_bid":"0.17","hash":"baa9d23d3bc02c9c28cb297a7d63d938ad239f0e","price":"0.01","side":"BUY","size":"5593.18"},{"asset_id":"2151378744569768920256500242561922410292857798164019061749528550808091180185","best_ask":"0.83","best_bid":"0.82","hash":"f2af5fd2d593e9af31c8077f37dfdd9aed603f3b","price":"0.99","side":"SELL","size":"5593.18"}],"timestamp":"1786845515042"}}
{"f":69,"recv_ms":1786845515509,"raw":{"event_type":"price_change","market":"0xd5f15f31689703aea70b93a52194a0964220d10d92ee7497346f146a8b6ef8ab","price_changes":[{"asset_id":"2151378744569768920256500242561922410292857798164019061749528550808091180185","best_ask":"0.83","best_bid":"0.82","hash":"562ed0d23248b2fb1cf05e4d62f2fd6ac6e2c7c7","price":"0.01","side":"BUY","size":"5757.53"},{"asset_id":"17406866367975599232214757606801140480252276357934486651183783311435802862074","best_ask":"0.18","best_bid":"0.17","hash":"786ded5c78468010c07aa7a238db4c4ebd16f78f","price":"0.99","side":"SELL","size":"5757.53"}],"timestamp":"1786845515043"}}
{"f":70,"recv_ms":1786845515509,"raw":{"event_type":"price_change","market":"0xf636967aa9d8794331ee10b9af364ea18fa3f1a9935f8c83ae9a249d8b08a931","price_changes":[{"asset_id":"68567158191229273715522065688080768784240867677122603193993480690378524045921","best_ask":"0.5","best_bid":"0.49","hash":"d468c8bccff3d06d12c28ee5a29c4f99a7bc1f0d","price":"0.12","side":"BUY","size":"25"},{"asset_id":"91326336689285362968457805980185782713434399212786273576721749759222414518998","best_ask":"0.51","best_bid":"0.5","hash":"ce0d356a2951df27e11877302477c62dfdf7247d","price":"0.88","side":"SELL","size":"25"}],"timestamp":"1786845515053"}}
{"f":71,"recv_ms":1786845515509,"raw":{"event_type":"price_change","market":"0xd5f15f31689703aea70b93a52194a0964220d10d92ee7497346f146a8b6ef8ab","price_changes":[{"asset_id":"2151378744569768920256500242561922410292857798164019061749528550808091180185","best_ask":"0.83","best_bid":"0.82","hash":"c49a74c8f33c225a5c58ebcebc386e8cc4a7af72","price":"0.01","side":"BUY","size":"5857.53"},{"asset_id":"17406866367975599232214757606801140480252276357934486651183783311435802862074","best_ask":"0.18","best_bid":"0.17","hash":"522ba34023106902c48c02bb2f7efac0e826d6ca","price":"0.99","side":"SELL","size":"5857.53"}],"timestamp":"1786845515068"}}
{"f":72,"recv_ms":1786845515509,"raw":{"event_type":"price_change","market":"0xd5f15f31689703aea70b93a52194a0964220d10d92ee7497346f146a8b6ef8ab","price_changes":[{"asset_id":"2151378744569768920256500242561922410292857798164019061749528550808091180185","best_ask":"0.83","best_bid":"0.82","hash":"9d5c18e1f366652d765919f3f56b074869dfc27c","price":"0.01","side":"BUY","size":"5852.53"},{"asset_id":"17406866367975599232214757606801140480252276357934486651183783311435802862074","best_ask":"0.18","best_bid":"0.17","hash":"fba0994eacdeffd1ede40e5a32853af56cbb6a34","price":"0.99","side":"SELL","size":"5852.53"}],"timestamp":"1786845515076"}}
{"f":73,"recv_ms":1786845515510,"raw":{"event_type":"price_change","market":"0xd5f15f31689703aea70b93a52194a0964220d10d92ee7497346f146a8b6ef8ab","price_changes":[{"asset_id":"2151378744569768920256500242561922410292857798164019061749528550808091180185","best_ask":"0.83","best_bid":"0.82","hash":"e535190c803e8761985202afc9fb44fc4c64b556","price":"0.01","side":"BUY","size":"5752.53"},{"asset_id":"17406866367975599232214757606801140480252276357934486651183783311435802862074","best_ask":"0.18","best_bid":"0.17","hash":"ad5153e3bd506b7654dbec4115eac26bbcd22c11","price":"0.99","side":"SELL","size":"5752.53"}],"timestamp":"1786845515107"}}
{"f":74,"recv_ms":1786845515510,"raw":{"event_type":"price_change","market":"0xd5f15f31689703aea70b93a52194a0964220d10d92ee7497346f146a8b6ef8ab","price_changes":[{"asset_id":"2151378744569768920256500242561922410292857798164019061749528550808091180185","best_ask":"0.83","best_bid":"0.82","hash":"5765a76c7652d5bc44c2d3c177aa4962974398a0","price":"0.01","side":"BUY","size":"5758.53"},{"asset_id":"17406866367975599232214757606801140480252276357934486651183783311435802862074","best_ask":"0.18","best_bid":"0.17","hash":"f4211432ef150644998df5ed03f40566295575d8","price":"0.99","side":"SELL","size":"5758.53"}],"timestamp":"1786845515114"}}
{"f":75,"recv_ms":1786845515510,"raw":{"event_type":"price_change","market":"0xd5f15f31689703aea70b93a52194a0964220d10d92ee7497346f146a8b6ef8ab","price_changes":[{"asset_id":"17406866367975599232214757606801140480252276357934486651183783311435802862074","best_ask":"0.18","best_bid":"0.17","hash":"6b9229c1bcabf0620772e26f1bcda42a95348b2d","price":"0.01","side":"BUY","size":"5598.18"},{"asset_id":"2151378744569768920256500242561922410292857798164019061749528550808091180185","best_ask":"0.83","best_bid":"0.82","hash":"f107bdbcb33a9760860b4281306d62a1e3dd6f66","price":"0.99","side":"SELL","size":"5598.18"}],"timestamp":"1786845515117"}}
{"f":76,"recv_ms":1786845515510,"raw":{"event_type":"price_change","market":"0xd5f15f31689703aea70b93a52194a0964220d10d92ee7497346f146a8b6ef8ab","price_changes":[{"asset_id":"2151378744569768920256500242561922410292857798164019061749528550808091180185","best_ask":"0.83","best_bid":"0.82","hash":"aab706b9824da4d13bda60e6b70dc95c2e1a1bb7","price":"0.01","side":"BUY","size":"5858.53"},{"asset_id":"17406866367975599232214757606801140480252276357934486651183783311435802862074","best_ask":"0.18","best_bid":"0.17","hash":"369a746ff86a10d14a2796220b42d8e8a5127f71","price":"0.99","side":"SELL","size":"5858.53"}],"timestamp":"1786845515133"}}
{"f":77,"recv_ms":1786845515510,"raw":{"event_type":"price_change","market":"0xd5f15f31689703aea70b93a52194a0964220d10d92ee7497346f146a8b6ef8ab","price_changes":[{"asset_id":"17406866367975599232214757606801140480252276357934486651183783311435802862074","best_ask":"0.18","best_bid":"0.17","hash":"df8226cf6f4a8978334a18611c6086479f4a690b","price":"0.01","side":"BUY","size":"5593.18"},{"asset_id":"2151378744569768920256500242561922410292857798164019061749528550808091180185","best_ask":"0.83","best_bid":"0.82","hash":"d995dd9f457b99911f4e690046558b9445f02dc1","price":"0.99","side":"SELL","size":"5593.18"}],"timestamp":"1786845515141"}}
{"f":78,"recv_ms":1786845515510,"raw":{"event_type":"price_change","market":"0xd5f15f31689703aea70b93a52194a0964220d10d92ee7497346f146a8b6ef8ab","price_changes":[{"asset_id":"2151378744569768920256500242561922410292857798164019061749528550808091180185","best_ask":"0.83","best_bid":"0.82","hash":"8462ec2aab31bda36cccbf96fbaf56d54b42f814","price":"0.01","side":"BUY","size":"5852.53"},{"asset_id":"17406866367975599232214757606801140480252276357934486651183783311435802862074","best_ask":"0.18","best_bid":"0.17","hash":"010590d83f2586dcdcb9e22a9ed4eadc7fd3198b","price":"0.99","side":"SELL","size":"5852.53"}],"timestamp":"1786845515141"}}
{"f":79,"recv_ms":1786845515510,"raw":{"event_type":"price_change","market":"0xd5f15f31689703aea70b93a52194a0964220d10d92ee7497346f146a8b6ef8ab","price_changes":[{"asset_id":"17406866367975599232214757606801140480252276357934486651183783311435802862074","best_ask":"0.18","best_bid":"0.17","hash":"d2474b9b02b4f777cf732e55cba4ca4473c8ee9d","price":"0.01","side":"BUY","size":"5588.18"},{"asset_id":"2151378744569768920256500242561922410292857798164019061749528550808091180185","best_ask":"0.83","best_bid":"0.82","hash":"c06f81449988c75b63c7c46fa251e7dcd2738bd7","price":"0.99","side":"SELL","size":"5588.18"}],"timestamp":"1786845515148"}}
{"f":80,"recv_ms":1786845515510,"raw":{"event_type":"price_change","market":"0xd5f15f31689703aea70b93a52194a0964220d10d92ee7497346f146a8b6ef8ab","price_changes":[{"asset_id":"2151378744569768920256500242561922410292857798164019061749528550808091180185","best_ask":"0.83","best_bid":"0.82","hash":"9cbacc0060c82122ae96c70210111f8eaebb7822","price":"0.01","side":"BUY","size":"5857.54"},{"asset_id":"17406866367975599232214757606801140480252276357934486651183783311435802862074","best_ask":"0.18","best_bid":"0.17","hash":"b4931306766de94838eb24e465b2c27a23e6e435","price":"0.99","side":"SELL","size":"5857.54"}],"timestamp":"1786845515152"}}
{"f":81,"recv_ms":1786845515510,"raw":{"event_type":"price_change","market":"0xd5f15f31689703aea70b93a52194a0964220d10d92ee7497346f146a8b6ef8ab","price_changes":[{"asset_id":"2151378744569768920256500242561922410292857798164019061749528550808091180185","best_ask":"0.83","best_bid":"0.82","hash":"a68ec27fc836f2c85b3ecfba0c7e85b043075e92","price":"0.48","side":"BUY","size":"50.4"},{"asset_id":"17406866367975599232214757606801140480252276357934486651183783311435802862074","best_ask":"0.18","best_bid":"0.17","hash":"dfffaee489322329f3670f2bf4d2569fce43a58a","price":"0.52","side":"SELL","size":"50.4"}],"timestamp":"1786845515159"}}
{"f":82,"recv_ms":1786845515510,"raw":{"event_type":"price_change","market":"0xd5f15f31689703aea70b93a52194a0964220d10d92ee7497346f146a8b6ef8ab","price_changes":[{"asset_id":"17406866367975599232214757606801140480252276357934486651183783311435802862074","best_ask":"0.18","best_bid":"0.17","hash":"8107864e42e2b89cb49e9fe7c3c8ef5e44375332","price":"0.39","side":"SELL","size":"94.22"},{"asset_id":"2151378744569768920256500242561922410292857798164019061749528550808091180185","best_ask":"0.83","best_bid":"0.82","hash":"f69381d8158b212cff49acf2384ae7693c0278f0","price":"0.61","side":"BUY","size":"94.22"}],"timestamp":"1786845515165"}}
{"f":83,"recv_ms":1786845515510,"raw":{"event_type":"price_change","market":"0xd5f15f31689703aea70b93a52194a0964220d10d92ee7497346f146a8b6ef8ab","price_changes":[{"asset_id":"2151378744569768920256500242561922410292857798164019061749528550808091180185","best_ask":"0.83","best_bid":"0.82","hash":"8dd4d1ab270fcb080ea500e511ffa1592ac7ddaa","price":"0.6","side":"BUY","size":"28"},{"asset_id":"17406866367975599232214757606801140480252276357934486651183783311435802862074","best_ask":"0.18","best_bid":"0.17","hash":"f82d6dd57b83bdfdaf7ba844c27d2c72a88ab621","price":"0.4","side":"SELL","size":"28"}],"timestamp":"1786845515167"}}
{"f":84,"recv_ms":1786845515510,"raw":{"event_type":"price_change","market":"0xd5f15f31689703aea70b93a52194a0964220d10d92ee7497346f146a8b6ef8ab","price_changes":[{"asset_id":"2151378744569768920256500242561922410292857798164019061749528550808091180185","best_ask":"0.83","best_bid":"0.82","hash":"6eb16d9a451e11c72450851e5a4a8ebd96871bbf","price":"0.58","side":"BUY","size":"29"},{"asset_id":"17406866367975599232214757606801140480252276357934486651183783311435802862074","best_ask":"0.18","best_bid":"0.17","hash":"7f753f2bb7a7bc3ea8fcc9867e8b16a8a35c26bb","price":"0.42","side":"SELL","size":"29"}],"timestamp":"1786845515169"}}
{"f":85,"recv_ms":1786845515510,"raw":{"event_type":"price_change","market":"0xd5f15f31689703aea70b93a52194a0964220d10d92ee7497346f146a8b6ef8ab","price_changes":[{"asset_id":"2151378744569768920256500242561922410292857798164019061749528550808091180185","best_ask":"0.83","best_bid":"0.82","hash":"0498513d790240ca20034e179a2d38b78866bcd3","price":"0.59","side":"BUY","size":"28"},{"asset_id":"17406866367975599232214757606801140480252276357934486651183783311435802862074","best_ask":"0.18","best_bid":"0.17","hash":"3afb0fbc1f62401f2622cdf36c1d769f110dd357","price":"0.41","side":"SELL","size":"28"}],"timestamp":"1786845515170"}}
{"f":86,"recv_ms":1786845515510,"raw":{"event_type":"price_change","market":"0xd5f15f31689703aea70b93a52194a0964220d10d92ee7497346f146a8b6ef8ab","price_changes":[{"asset_id":"2151378744569768920256500242561922410292857798164019061749528550808091180185","best_ask":"0.83","best_bid":"0.82","hash":"1d511e4e9b8da9a21f24b7f5b22ae705009537f1","price":"0.01","side":"BUY","size":"5757.54"},{"asset_id":"17406866367975599232214757606801140480252276357934486651183783311435802862074","best_ask":"0.18","best_bid":"0.17","hash":"9609debc4416d816129825e0be66160152ec0c34","price":"0.99","side":"SELL","size":"5757.54"}],"timestamp":"1786845515172"}}
{"f":87,"recv_ms":1786845515510,"raw":{"event_type":"price_change","market":"0xd5f15f31689703aea70b93a52194a0964220d10d92ee7497346f146a8b6ef8ab","price_changes":[{"asset_id":"17406866367975599232214757606801140480252276357934486651183783311435802862074","best_ask":"0.18","best_bid":"0.17","hash":"421a6f42c9fea653872b9c25b48f40c4598298ca","price":"0.38","side":"SELL","size":"228.66"},{"asset_id":"2151378744569768920256500242561922410292857798164019061749528550808091180185","best_ask":"0.83","best_bid":"0.82","hash":"a355c2a96e00a5ab084e31d5b4466759b7bc6abe","price":"0.62","side":"BUY","size":"228.66"}],"timestamp":"1786845515175"}}
{"f":88,"recv_ms":1786845515510,"raw":{"event_type":"price_change","market":"0xd5f15f31689703aea70b93a52194a0964220d10d92ee7497346f146a8b6ef8ab","price_changes":[{"asset_id":"2151378744569768920256500242561922410292857798164019061749528550808091180185","best_ask":"0.83","best_bid":"0.82","hash":"61b236e7f62d8a3ef46f1eec75ccde5c11db37d9","price":"0.01","side":"BUY","size":"5752.53"},{"asset_id":"17406866367975599232214757606801140480252276357934486651183783311435802862074","best_ask":"0.18","best_bid":"0.17","hash":"ada8f509241f265dc5a85a104da14a8966c969ee","price":"0.99","side":"SELL","size":"5752.53"}],"timestamp":"1786845515179"}}
{"f":89,"recv_ms":1786845515510,"raw":{"event_type":"price_change","market":"0xd5f15f31689703aea70b93a52194a0964220d10d92ee7497346f146a8b6ef8ab","price_changes":[{"asset_id":"2151378744569768920256500242561922410292857798164019061749528550808091180185","best_ask":"0.83","best_bid":"0.82","hash":"a39346caf9350afc03145f606690558d84605749","price":"0.57","side":"BUY","size":"34"},{"asset_id":"17406866367975599232214757606801140480252276357934486651183783311435802862074","best_ask":"0.18","best_bid":"0.17","hash":"d71371fe711293cee52c48ae712a77b2e9491fe8","price":"0.43","side":"SELL","size":"34"}],"timestamp":"1786845515180"}}
{"f":90,"recv_ms":1786845515510,"raw":{"event_type":"price_change","market":"0xd5f15f31689703aea70b93a52194a0964220d10d92ee7497346f146a8b6ef8ab","price_changes":[{"asset_id":"2151378744569768920256500242561922410292857798164019061749528550808091180185","best_ask":"0.83","best_bid":"0.82","hash":"d88586d92486a64354d4a6242bb3db441e63aa86","price":"0.01","side":"BUY","size":"5757.53"},{"asset_id":"17406866367975599232214757606801140480252276357934486651183783311435802862074","best_ask":"0.18","best_bid":"0.17","hash":"f94ea1932f3c1d2827215f3eda2bf1179099bd19","price":"0.99","side":"SELL","size":"5757.53"}],"timestamp":"1786845515181"}}
{"f":91,"recv_ms":1786845515511,"raw":{"event_type":"price_change","market":"0xd5f15f31689703aea70b93a52194a0964220d10d92ee7497346f146a8b6ef8ab","price_changes":[{"asset_id":"2151378744569768920256500242561922410292857798164019061749528550808091180185","best_ask":"0.83","best_bid":"0.82","hash":"653c3eec6411dfa04ce4a0b5b6aa77aa83ae39a5","price":"0.01","side":"BUY","size":"5762.53"},{"asset_id":"17406866367975599232214757606801140480252276357934486651183783311435802862074","best_ask":"0.18","best_bid":"0.17","hash":"6c23571fc24c3a6a96bedbf0a188b9281ae37cc4","price":"0.99","side":"SELL","size":"5762.53"}],"timestamp":"1786845515182"}}
{"f":92,"recv_ms":1786845515511,"raw":{"event_type":"price_change","market":"0xd5f15f31689703aea70b93a52194a0964220d10d92ee7497346f146a8b6ef8ab","price_changes":[{"asset_id":"2151378744569768920256500242561922410292857798164019061749528550808091180185","best_ask":"0.83","best_bid":"0.82","hash":"5045a1fae8f5ab8ea9483313c6ef9930728e914d","price":"0.01","side":"BUY","size":"5767.53"},{"asset_id":"17406866367975599232214757606801140480252276357934486651183783311435802862074","best_ask":"0.18","best_bid":"0.17","hash":"1b083fcaa56deff4d4ee6befd48c19946963cda6","price":"0.99","side":"SELL","size":"5767.53"}],"timestamp":"1786845515182"}}
{"f":93,"recv_ms":1786845515511,"raw":{"event_type":"price_change","market":"0xd5f15f31689703aea70b93a52194a0964220d10d92ee7497346f146a8b6ef8ab","price_changes":[{"asset_id":"2151378744569768920256500242561922410292857798164019061749528550808091180185","best_ask":"0.83","best_bid":"0.82","hash":"b70f1b7116b6b79b2aa5e9c6b01e3276a475f207","price":"0.49","side":"BUY","size":"50.4"},{"asset_id":"17406866367975599232214757606801140480252276357934486651183783311435802862074","best_ask":"0.18","best_bid":"0.17","hash":"2d55828e8f3f63ccb24f8d7c0f5cb4936cdf0b09","price":"0.51","side":"SELL","size":"50.4"}],"timestamp":"1786845515183"}}
{"f":94,"recv_ms":1786845515511,"raw":{"event_type":"price_change","market":"0xd5f15f31689703aea70b93a52194a0964220d10d92ee7497346f146a8b6ef8ab","price_changes":[{"asset_id":"2151378744569768920256500242561922410292857798164019061749528550808091180185","best_ask":"0.83","best_bid":"0.82","hash":"d291aac87d6bb12c473bffaeb0acf65340245c26","price":"0.56","side":"BUY","size":"29"},{"asset_id":"17406866367975599232214757606801140480252276357934486651183783311435802862074","best_ask":"0.18","best_bid":"0.17","hash":"50644919ed8c2c21583b0b6258e7cf4e56cb0159","price":"0.44","side":"SELL","size":"29"}],"timestamp":"1786845515189"}}
{"f":95,"recv_ms":1786845515511,"raw":{"event_type":"price_change","market":"0xd5f15f31689703aea70b93a52194a0964220d10d92ee7497346f146a8b6ef8ab","price_changes":[{"asset_id":"2151378744569768920256500242561922410292857798164019061749528550808091180185","best_ask":"0.83","best_bid":"0.82","hash":"be7e50a6df13f4b2102fff1ba2c7e4e9d5eddd6f","price":"0.62","side":"BUY","size":"198.66"},{"asset_id":"17406866367975599232214757606801140480252276357934486651183783311435802862074","best_ask":"0.18","best_bid":"0.17","hash":"615ff6e0229e3145f834b592816201bf1ebc13ec","price":"0.38","side":"SELL","size":"198.66"}],"timestamp":"1786845515202"}}
{"f":96,"recv_ms":1786845515511,"raw":{"event_type":"price_change","market":"0xd5f15f31689703aea70b93a52194a0964220d10d92ee7497346f146a8b6ef8ab","price_changes":[{"asset_id":"17406866367975599232214757606801140480252276357934486651183783311435802862074","best_ask":"0.18","best_bid":"0.17","hash":"2715cf0c8e4381819d4111534989de38362185ef","price":"0.5","side":"SELL","size":"645"},{"asset_id":"2151378744569768920256500242561922410292857798164019061749528550808091180185","best_ask":"0.83","best_bid":"0.82","hash":"6df72b1d311bfc06147a81f7b9df6ec396c1777e","price":"0.5","side":"BUY","size":"645"}],"timestamp":"1786845515210"}}
{"f":97,"recv_ms":1786845515511,"raw":{"event_type":"price_change","market":"0xd5f15f31689703aea70b93a52194a0964220d10d92ee7497346f146a8b6ef8ab","price_changes":[{"asset_id":"2151378744569768920256500242561922410292857798164019061749528550808091180185","best_ask":"0.83","best_bid":"0.82","hash":"7e4bd20e5c3ca862d5c7648a74089d4176be62be","price":"0.01","side":"BUY","size":"5773.53"},{"asset_id":"17406866367975599232214757606801140480252276357934486651183783311435802862074","best_ask":"0.18","best_bid":"0.17","hash":"d1e70efe53aa099bbc6a898cd5565e27ac198b51","price":"0.99","side":"SELL","size":"5773.53"}],"timestamp":"1786845515211"}}
{"f":98,"recv_ms":1786845515511,"raw":{"event_type":"price_change","market":"0xd5f15f31689703aea70b93a52194a0964220d10d92ee7497346f146a8b6ef8ab","price_changes":[{"asset_id":"2151378744569768920256500242561922410292857798164019061749528550808091180185","best_ask":"0.83","best_bid":"0.82","hash":"f70e6720d58c9e24e78d32157c3c304d9c4aad8e","price":"0.55","side":"BUY","size":"129"},{"asset_id":"17406866367975599232214757606801140480252276357934486651183783311435802862074","best_ask":"0.18","best_bid":"0.17","hash":"539874730ce3c627f5242f3250247d8c79744110","price":"0.45","side":"SELL","size":"129"}],"timestamp":"1786845515212"}}
{"f":99,"recv_ms":1786845515511,"raw":{"event_type":"price_change","market":"0xd5f15f31689703aea70b93a52194a0964220d10d92ee7497346f146a8b6ef8ab","price_changes":[{"asset_id":"2151378744569768920256500242561922410292857798164019061749528550808091180185","best_ask":"0.83","best_bid":"0.82","hash":"dcec20187e2913e157e63b90a97a15546d67f0c6","price":"0.01","side":"BUY","size":"5768.53"},{"asset_id":"17406866367975599232214757606801140480252276357934486651183783311435802862074","best_ask":"0.18","best_bid":"0.17","hash":"4b74015125fb96ee9707c8857a6223e6593cddb5","price":"0.99","side":"SELL","size":"5768.53"}],"timestamp":"1786845515218"}}
{"f":100,"recv_ms":1786845515511,"raw":{"event_type":"price_change","market":"0xd5f15f31689703aea70b93a52194a0964220d10d92ee7497346f146a8b6ef8ab","price_changes":[{"asset_id":"17406866367975599232214757606801140480252276357934486651183783311435802862074","best_ask":"0.18","best_bid":"0.17","hash":"5f953622b84dca3d8398d796edad5d8287d60120","price":"0.03","side":"BUY","size":"606.3"},{"asset_id":"2151378744569768920256500242561922410292857798164019061749528550808091180185","best_ask":"0.83","best_bid":"0.82","hash":"88d350d92057d83f0d45777e661922da723facc3","price":"0.97","side":"SELL","size":"606.3"}],"timestamp":"1786845515218"}}
{"f":101,"recv_ms":1786845515511,"raw":{"event_type":"price_change","market":"0xd5f15f31689703aea70b93a52194a0964220d10d92ee7497346f146a8b6ef8ab","price_changes":[{"asset_id":"17406866367975599232214757606801140480252276357934486651183783311435802862074","best_ask":"0.18","best_bid":"0.17","hash":"94e76ae939979c7df3432adc54dafa08bb7b0169","price":"0.05","side":"BUY","size":"754.7"},{"asset_id":"2151378744569768920256500242561922410292857798164019061749528550808091180185","best_ask":"0.83","best_bid":"0.82","hash":"1ec9140b29d873f5c059fc14ea759556dc4acc70","price":"0.95","side":"SELL","size":"754.7"}],"timestamp":"1786845515219"}}
{"f":102,"recv_ms":1786845515511,"raw":{"event_type":"price_change","market":"0xd5f15f31689703aea70b93a52194a0964220d10d92ee7497346f146a8b6ef8ab","price_changes":[{"asset_id":"17406866367975599232214757606801140480252276357934486651183783311435802862074","best_ask":"0.18","best_bid":"0.17","hash":"a52ed1f86d90b10d73267344585e55057fea83f5","price":"0.01","side":"BUY","size":"5583.18"},{"asset_id":"2151378744569768920256500242561922410292857798164019061749528550808091180185","best_ask":"0.83","best_bid":"0.82","hash":"ec194eb4d8a0644a9dd45ac67766764c8e012182","price":"0.99","side":"SELL","size":"5583.18"}],"timestamp":"1786845515220"}}
{"f":103,"recv_ms":1786845515511,"raw":{"event_type":"price_change","market":"0xd5f15f31689703aea70b93a52194a0964220d10d92ee7497346f146a8b6ef8ab","price_changes":[{"asset_id":"17406866367975599232214757606801140480252276357934486651183783311435802862074","best_ask":"0.18","best_bid":"0.17","hash":"0ccce442b64920fa089766b8cf5ab0fbca606dca","price":"0.01","side":"BUY","size":"5578.18"},{"asset_id":"2151378744569768920256500242561922410292857798164019061749528550808091180185","best_ask":"0.83","best_bid":"0.82","hash":"deb921991280d20d596a0fc0b3c268937632f78e","price":"0.99","side":"SELL","size":"5578.18"}],"timestamp":"1786845515222"}}
{"f":104,"recv_ms":1786845515511,"raw":{"event_type":"price_change","market":"0xd5f15f31689703aea70b93a52194a0964220d10d92ee7497346f146a8b6ef8ab","price_changes":[{"asset_id":"17406866367975599232214757606801140480252276357934486651183783311435802862074","best_ask":"0.18","best_bid":"0.17","hash":"87eb950e0dda5a7dbe4deee629c6f4c4b488b8f7","price":"0.07","side":"BUY","size":"459.86"},{"asset_id":"2151378744569768920256500242561922410292857798164019061749528550808091180185","best_ask":"0.83","best_bid":"0.82","hash":"2d9ff151e69a62dc3df3be3ce3c400f3109a940e","price":"0.93","side":"SELL","size":"459.86"}],"timestamp":"1786845515222"}}
{"f":105,"recv_ms":1786845515511,"raw":{"event_type":"price_change","market":"0xd5f15f31689703aea70b93a52194a0964220d10d92ee7497346f146a8b6ef8ab","price_changes":[{"asset_id":"17406866367975599232214757606801140480252276357934486651183783311435802862074","best_ask":"0.18","best_bid":"0.17","hash":"90f6990660cefaf338aa6fa6b2de6ed91c6d54f7","price":"0.09","side":"BUY","size":"71.7"},{"asset_id":"2151378744569768920256500242561922410292857798164019061749528550808091180185","best_ask":"0.83","best_bid":"0.82","hash":"7c710d0022b8c8f9c6121c9f9d96ed89dd28d56a","price":"0.91","side":"SELL","size":"71.7"}],"timestamp":"1786845515223"}}
{"f":106,"recv_ms":1786845515511,"raw":{"event_type":"price_change","market":"0xd5f15f31689703aea70b93a52194a0964220d10d92ee7497346f146a8b6ef8ab","price_changes":[{"asset_id":"17406866367975599232214757606801140480252276357934486651183783311435802862074","best_ask":"0.18","best_bid":"0.17","hash":"c76ecc301791d457b1eeb0ec7981d38b0ce818c2","price":"0.01","side":"BUY","size":"5583.18"},{"asset_id":"2151378744569768920256500242561922410292857798164019061749528550808091180185","best_ask":"0.83","best_bid":"0.82","hash":"fa3b0bf5945b02d913973e40ff7e867e09cb2e09","price":"0.99","side":"SELL","size":"5583.18"}],"timestamp":"1786845515226"}}
{"f":107,"recv_ms":1786845515511,"raw":{"event_type":"price_change","market":"0xd5f15f31689703aea70b93a52194a0964220d10d92ee7497346f146a8b6ef8ab","price_changes":[{"asset_id":"17406866367975599232214757606801140480252276357934486651183783311435802862074","best_ask":"0.18","best_bid":"0.17","hash":"a6a362395637d96f02a421d5649d67c2801fe448","price":"0.01","side":"BUY","size":"5588.18"},{"asset_id":"2151378744569768920256500242561922410292857798164019061749528550808091180185","best_ask":"0.83","best_bid":"0.82","hash":"684623929f2c853508542edfd6ae895297fc5fc0","price":"0.99","side":"SELL","size":"5588.18"}],"timestamp":"1786845515229"}}
{"f":108,"recv_ms":1786845515511,"raw":{"event_type":"price_change","market":"0xd5f15f31689703aea70b93a52194a0964220d10d92ee7497346f146a8b6ef8ab","price_changes":[{"asset_id":"17406866367975599232214757606801140480252276357934486651183783311435802862074","best_ask":"0.18","best_bid":"0.17","hash":"b6da13981c781af33d07e3f8ec06a41e99c1499b","price":"0.01","side":"BUY","size":"5583.18"},{"asset_id":"2151378744569768920256500242561922410292857798164019061749528550808091180185","best_ask":"0.83","best_bid":"0.82","hash":"e704174dedfea717f78cd22a8fe60fc5cbca35c1","price":"0.99","side":"SELL","size":"5583.18"}],"timestamp":"1786845515230"}}
{"f":109,"recv_ms":1786845515512,"raw":{"event_type":"price_change","market":"0xd5f15f31689703aea70b93a52194a0964220d10d92ee7497346f146a8b6ef8ab","price_changes":[{"asset_id":"2151378744569768920256500242561922410292857798164019061749528550808091180185","best_ask":"0.83","best_bid":"0.82","hash":"d64e94170131fa4581a7d93583f6a5180bec5f57","price":"0.01","side":"BUY","size":"5868.53"},{"asset_id":"17406866367975599232214757606801140480252276357934486651183783311435802862074","best_ask":"0.18","best_bid":"0.17","hash":"025e63ef592c21fe3249d9207382591af3540745","price":"0.99","side":"SELL","size":"5868.53"}],"timestamp":"1786845515237"}}
{"f":110,"recv_ms":1786845515512,"raw":{"event_type":"price_change","market":"0xd5f15f31689703aea70b93a52194a0964220d10d92ee7497346f146a8b6ef8ab","price_changes":[{"asset_id":"17406866367975599232214757606801140480252276357934486651183783311435802862074","best_ask":"0.18","best_bid":"0.17","hash":"6c48d8f4c53dfee43fa2454479827991182e63df","price":"0.49","side":"SELL","size":"40"},{"asset_id":"2151378744569768920256500242561922410292857798164019061749528550808091180185","best_ask":"0.83","best_bid":"0.82","hash":"a75ed30ebd3b15fc1dff6015aca1956700154f96","price":"0.51","side":"BUY","size":"40"}],"timestamp":"1786845515240"}}
{"f":111,"recv_ms":1786845515659,"raw":{"event_type":"price_change","market":"0xd5f15f31689703aea70b93a52194a0964220d10d92ee7497346f146a8b6ef8ab","price_changes":[{"asset_id":"2151378744569768920256500242561922410292857798164019061749528550808091180185","best_ask":"0.83","best_bid":"0.82","hash":"854eadec545879b7b891f10765347588507085b2","price":"0.01","side":"BUY","size":"5862.53"},{"asset_id":"17406866367975599232214757606801140480252276357934486651183783311435802862074","best_ask":"0.18","best_bid":"0.17","hash":"835e80f521c003d2970a0bac4b035128c877190e","price":"0.99","side":"SELL","size":"5862.53"}],"timestamp":"1786845515241"}}
{"f":112,"recv_ms":1786845515659,"raw":{"event_type":"price_change","market":"0xd5f15f31689703aea70b93a52194a0964220d10d92ee7497346f146a8b6ef8ab","price_changes":[{"asset_id":"17406866367975599232214757606801140480252276357934486651183783311435802862074","best_ask":"0.18","best_bid":"0.17","hash":"a4b3d1303f828b03cf9093c829cc827e496c311a","price":"0.46","side":"SELL","size":"59"},{"asset_id":"2151378744569768920256500242561922410292857798164019061749528550808091180185","best_ask":"0.83","best_bid":"0.82","hash":"3ba616469593c58a94cf1617289f423b5daeb34d","price":"0.54","side":"BUY","size":"59"}],"timestamp":"1786845515244"}}
{"f":113,"recv_ms":1786845515659,"raw":{"event_type":"price_change","market":"0xd5f15f31689703aea70b93a52194a0964220d10d92ee7497346f146a8b6ef8ab","price_changes":[{"asset_id":"2151378744569768920256500242561922410292857798164019061749528550808091180185","best_ask":"0.83","best_bid":"0.82","hash":"fb1004fe84644ce688988736e1636716b1efa94b","price":"0.01","side":"BUY","size":"5857.53"},{"asset_id":"17406866367975599232214757606801140480252276357934486651183783311435802862074","best_ask":"0.18","best_bid":"0.17","hash":"0c8ef586838200d4ecd5b5d81cd3cfa9cc41bf04","price":"0.99","side":"SELL","size":"5857.53"}],"timestamp":"1786845515250"}}
{"f":114,"recv_ms":1786845515659,"raw":{"event_type":"price_change","market":"0xd5f15f31689703aea70b93a52194a0964220d10d92ee7497346f146a8b6ef8ab","price_changes":[{"asset_id":"2151378744569768920256500242561922410292857798164019061749528550808091180185","best_ask":"0.83","best_bid":"0.82","hash":"cbaa0107cb2a4c6742199afd94048fcbe3c40a31","price":"0.01","side":"BUY","size":"5852.53"},{"asset_id":"17406866367975599232214757606801140480252276357934486651183783311435802862074","best_ask":"0.18","best_bid":"0.17","hash":"301a9a5d2da50c0ecaac6f86e01d63db9b37af9f","price":"0.99","side":"SELL","size":"5852.53"}],"timestamp":"1786845515281"}}
{"f":115,"recv_ms":1786845515661,"raw":{"event_type":"price_change","market":"0xd5f15f31689703aea70b93a52194a0964220d10d92ee7497346f146a8b6ef8ab","price_changes":[{"asset_id":"2151378744569768920256500242561922410292857798164019061749528550808091180185","best_ask":"0.83","best_bid":"0.82","hash":"e5e445f8791a74a2dfbe70183fbed7f1070decf9","price":"0.01","side":"BUY","size":"5952.53"},{"asset_id":"17406866367975599232214757606801140480252276357934486651183783311435802862074","best_ask":"0.18","best_bid":"0.17","hash":"c8e52a1718b12d0dd49feaa1a2a92b763fa54e6e","price":"0.99","side":"SELL","size":"5952.53"}],"timestamp":"1786845515294"}}
{"f":116,"recv_ms":1786845515661,"raw":{"event_type":"price_change","market":"0xd5f15f31689703aea70b93a52194a0964220d10d92ee7497346f146a8b6ef8ab","price_changes":[{"asset_id":"17406866367975599232214757606801140480252276357934486651183783311435802862074","best_ask":"0.18","best_bid":"0.17","hash":"bffa162c232571968c7adca41fee2d9e6b33aba0","price":"0.05","side":"BUY","size":"774.7"},{"asset_id":"2151378744569768920256500242561922410292857798164019061749528550808091180185","best_ask":"0.83","best_bid":"0.82","hash":"74033aa0cfa237c34d33aea4d2273bf45d4fbb11","price":"0.95","side":"SELL","size":"774.7"}],"timestamp":"1786845515300"}}
{"f":117,"recv_ms":1786845515661,"raw":{"event_type":"price_change","market":"0xd5f15f31689703aea70b93a52194a0964220d10d92ee7497346f146a8b6ef8ab","price_changes":[{"asset_id":"2151378744569768920256500242561922410292857798164019061749528550808091180185","best_ask":"0.83","best_bid":"0.82","hash":"ec2228b0eaae6a928747b9b28a9a83ffdc2bf2df","price":"0.8","side":"BUY","size":"86"},{"asset_id":"17406866367975599232214757606801140480252276357934486651183783311435802862074","best_ask":"0.18","best_bid":"0.17","hash":"f7c10bd206bf8c4c403e5256b74acd3c2b1846da","price":"0.2","side":"SELL","size":"86"}],"timestamp":"1786845515300"}}
{"f":118,"recv_ms":1786845515661,"raw":{"event_type":"price_change","market":"0xd5f15f31689703aea70b93a52194a0964220d10d92ee7497346f146a8b6ef8ab","price_changes":[{"asset_id":"2151378744569768920256500242561922410292857798164019061749528550808091180185","best_ask":"0.83","best_bid":"0.82","hash":"8aa668d71a349d4212410ac704c7c166e9a09050","price":"0.01","side":"BUY","size":"5852.53"},{"asset_id":"17406866367975599232214757606801140480252276357934486651183783311435802862074","best_ask":"0.18","best_bid":"0.17","hash":"d9b519917cd0376345c2c33c1d221448c05da841","price":"0.99","side":"SELL","size":"5852.53"}],"timestamp":"1786845515301"}}
{"f":119,"recv_ms":1786845515661,"raw":{"event_type":"price_change","market":"0xd5f15f31689703aea70b93a52194a0964220d10d92ee7497346f146a8b6ef8ab","price_changes":[{"asset_id":"17406866367975599232214757606801140480252276357934486651183783311435802862074","best_ask":"0.18","best_bid":"0.17","hash":"fb95d3dff69469c2db7f3d4eddf7c413735cd4be","price":"0.47","side":"SELL","size":"589.64"},{"asset_id":"2151378744569768920256500242561922410292857798164019061749528550808091180185","best_ask":"0.83","best_bid":"0.82","hash":"46834015fc490de188bd16b7906d8ada7893a091","price":"0.53","side":"BUY","size":"589.64"}],"timestamp":"1786845515303"}}
{"f":120,"recv_ms":1786845515661,"raw":{"event_type":"price_change","market":"0xd5f15f31689703aea70b93a52194a0964220d10d92ee7497346f146a8b6ef8ab","price_changes":[{"asset_id":"2151378744569768920256500242561922410292857798164019061749528550808091180185","best_ask":"0.83","best_bid":"0.82","hash":"f933a21de825b67519e331f7e2a93b61f8743b24","price":"0.01","side":"BUY","size":"5858.53"},{"asset_id":"17406866367975599232214757606801140480252276357934486651183783311435802862074","best_ask":"0.18","best_bid":"0.17","hash":"07eca2a158075325199bf7afce425d28480cc337","price":"0.99","side":"SELL","size":"5858.53"}],"timestamp":"1786845515312"}}
{"f":121,"recv_ms":1786845515661,"raw":{"event_type":"price_change","market":"0xd5f15f31689703aea70b93a52194a0964220d10d92ee7497346f146a8b6ef8ab","price_changes":[{"asset_id":"17406866367975599232214757606801140480252276357934486651183783311435802862074","best_ask":"0.18","best_bid":"0.17","hash":"241555e463f4b3190b436276fd8daaa05c8c38da","price":"0.17","side":"BUY","size":"142.1"},{"asset_id":"2151378744569768920256500242561922410292857798164019061749528550808091180185","best_ask":"0.83","best_bid":"0.82","hash":"7576ab899645be8e9b216b3e27950ab976abca3a","price":"0.83","side":"SELL","size":"142.1"}],"timestamp":"1786845515314"}}
{"f":122,"recv_ms":1786845515666,"raw":{"event_type":"price_change","market":"0xd5f15f31689703aea70b93a52194a0964220d10d92ee7497346f146a8b6ef8ab","price_changes":[{"asset_id":"2151378744569768920256500242561922410292857798164019061749528550808091180185","best_ask":"0.83","best_bid":"0.82","hash":"e816de15a57c00121fd5cf38471604bd878f7755","price":"0.01","side":"BUY","size":"5758.53"},{"asset_id":"17406866367975599232214757606801140480252276357934486651183783311435802862074","best_ask":"0.18","best_bid":"0.17","hash":"cdbf2deaac68b22ba72b2174ff8d999e669c6fbf","price":"0.99","side":"SELL","size":"5758.53"}],"timestamp":"1786845515332"}}
{"f":123,"recv_ms":1786845515666,"raw":{"event_type":"price_change","market":"0xd5f15f31689703aea70b93a52194a0964220d10d92ee7497346f146a8b6ef8ab","price_changes":[{"asset_id":"17406866367975599232214757606801140480252276357934486651183783311435802862074","best_ask":"0.18","best_bid":"0.17","hash":"211954fdaddaeea519f109022ef3e514e03e617e","price":"0.1","side":"BUY","size":"96"},{"asset_id":"2151378744569768920256500242561922410292857798164019061749528550808091180185","best_ask":"0.83","best_bid":"0.82","hash":"3c9cbe6ba8bb80955d9a099951f05a3d8bddd863","price":"0.9","side":"SELL","size":"96"}],"timestamp":"1786845515335"}}
{"f":124,"recv_ms":1786845515674,"raw":{"event_type":"price_change","market":"0xd5f15f31689703aea70b93a52194a0964220d10d92ee7497346f146a8b6ef8ab","price_changes":[{"asset_id":"2151378744569768920256500242561922410292857798164019061749528550808091180185","best_ask":"0.83","best_bid":"0.82","hash":"7fb334d861a50cb093db30c25536e39b5bbebe72","price":"0.66","side":"BUY","size":"18"},{"asset_id":"17406866367975599232214757606801140480252276357934486651183783311435802862074","best_ask":"0.18","best_bid":"0.17","hash":"46c579df3839367044fbcfc245547ee007f2b9a0","price":"0.34","side":"SELL","size":"18"}],"timestamp":"1786845515338"}}
{"f":125,"recv_ms":1786845515675,"raw":{"event_type":"price_change","market":"0xd5f15f31689703aea70b93a52194a0964220d10d92ee7497346f146a8b6ef8ab","price_changes":[{"asset_id":"2151378744569768920256500242561922410292857798164019061749528550808091180185","best_ask":"0.83","best_bid":"0.82","hash":"26c4a6261ac19623bb848c26417d5e1a000e432f","price":"0.01","side":"BUY","size":"5752.53"},{"asset_id":"17406866367975599232214757606801140480252276357934486651183783311435802862074","best_ask":"0.18","best_bid":"0.17","hash":"ffb3e42244f11bbae38c79b19a1cafc426838c85","price":"0.99","side":"SELL","size":"5752.53"}],"timestamp":"1786845515346"}}
{"f":126,"recv_ms":1786845515675,"raw":{"event_type":"price_change","market":"0xd5f15f31689703aea70b93a52194a0964220d10d92ee7497346f146a8b6ef8ab","price_changes":[{"asset_id":"2151378744569768920256500242561922410292857798164019061749528550808091180185","best_ask":"0.83","best_bid":"0.82","hash":"9ed12f40fbfda6dc22ffee07f7298c1b152ec85d","price":"0.01","side":"BUY","size":"5757.54"},{"asset_id":"17406866367975599232214757606801140480252276357934486651183783311435802862074","best_ask":"0.18","best_bid":"0.17","hash":"f412f8c2ba4074a0fcbd8b289561c37819cb9f47","price":"0.99","side":"SELL","size":"5757.54"}],"timestamp":"1786845515352"}}
{"f":127,"recv_ms":1786845515675,"raw":{"event_type":"price_change","market":"0x0c33f1586ca3445a41be2863746ffb0edc32df6500f4926657b2643fe8a78258","price_changes":[{"asset_id":"45654842686110167876337056449737479301235917003519988189654649607054904571464","best_ask":"0.54","best_bid":"0.53","hash":"6191a5541348505867242d5621a63cf3ff589f67","price":"0.53","side":"BUY","size":"35"},{"asset_id":"84378280634731141017197924889292000863571415141565530467641465700960218022429","best_ask":"0.47","best_bid":"0.46","hash":"8a25309a1941d9d96a227dcb5bd7f17a1a27b8c1","price":"0.47","side":"SELL","size":"35"}],"timestamp":"1786845515356"}}
{"f":128,"recv_ms":1786845515675,"raw":{"event_type":"price_change","market":"0xd5f15f31689703aea70b93a52194a0964220d10d92ee7497346f146a8b6ef8ab","price_changes":[{"asset_id":"17406866367975599232214757606801140480252276357934486651183783311435802862074","best_ask":"0.18","best_bid":"0.17","hash":"4764b32b07b0ef1c14bc52802975f99aad5d1226","price":"0.06","side":"BUY","size":"583.1"},{"asset_id":"2151378744569768920256500242561922410292857798164019061749528550808091180185","best_ask":"0.83","best_bid":"0.82","hash":"f066f4a60ee2c28d6b10c4f691cbc10e0108521e","price":"0.94","side":"SELL","size":"583.1"}],"timestamp":"1786845515361"}}
{"f":129,"recv_ms":1786845515675,"raw":{"event_type":"price_change","market":"0xd5f15f31689703aea70b93a52194a0964220d10d92ee7497346f146a8b6ef8ab","price_changes":[{"asset_id":"17406866367975599232214757606801140480252276357934486651183783311435802862074","best_ask":"0.18","best_bid":"0.17","hash":"a9b5f764beb8890a5129c02d348d42f5c0a452c6","price":"0.04","side":"BUY","size":"567.7"},{"asset_id":"2151378744569768920256500242561922410292857798164019061749528550808091180185","best_ask":"0.83","best_bid":"0.82","hash":"dafbaeee00930d0c62a336c7fa185603820dfb16","price":"0.96","side":"SELL","size":"567.7"}],"timestamp":"1786845515366"}}
{"f":130,"recv_ms":1786845515675,"raw":{"event_type":"price_change","market":"0xd5f15f31689703aea70b93a52194a0964220d10d92ee7497346f146a8b6ef8ab","price_changes":[{"asset_id":"2151378744569768920256500242561922410292857798164019061749528550808091180185","best_ask":"0.83","best_bid":"0.82","hash":"ed7cd4774a56a5d6afdacb049d79060e9c56d27f","price":"0.01","side":"BUY","size":"5857.54"},{"asset_id":"17406866367975599232214757606801140480252276357934486651183783311435802862074","best_ask":"0.18","best_bid":"0.17","hash":"990f0fcbcd27a432042ee8ae5588fdcee6305d47","price":"0.99","side":"SELL","size":"5857.54"}],"timestamp":"1786845515376"}}
{"f":131,"recv_ms":1786845515675,"raw":{"event_type":"price_change","market":"0xd5f15f31689703aea70b93a52194a0964220d10d92ee7497346f146a8b6ef8ab","price_changes":[{"asset_id":"2151378744569768920256500242561922410292857798164019061749528550808091180185","best_ask":"0.83","best_bid":"0.82","hash":"4c5ad9ac33b955b61e318959de69a059d2afdb25","price":"0.01","side":"BUY","size":"5852.53"},{"asset_id":"17406866367975599232214757606801140480252276357934486651183783311435802862074","best_ask":"0.18","best_bid":"0.17","hash":"ef6dc3ec98f636351d0118765bf45fad8a0b6eea","price":"0.99","side":"SELL","size":"5852.53"}],"timestamp":"1786845515379"}}
{"f":132,"recv_ms":1786845515675,"raw":{"event_type":"price_change","market":"0xd5f15f31689703aea70b93a52194a0964220d10d92ee7497346f146a8b6ef8ab","price_changes":[{"asset_id":"17406866367975599232214757606801140480252276357934486651183783311435802862074","best_ask":"0.18","best_bid":"0.17","hash":"a14128953e68c8c71a60099c8185330e2b32c4a3","price":"0.11","side":"BUY","size":"40"},{"asset_id":"2151378744569768920256500242561922410292857798164019061749528550808091180185","best_ask":"0.83","best_bid":"0.82","hash":"d194e29d3a4c4859319e38be1a4339da0bee9ea8","price":"0.89","side":"SELL","size":"40"}],"timestamp":"1786845515381"}}
{"f":133,"recv_ms":1786845515675,"raw":{"event_type":"price_change","market":"0xd5f15f31689703aea70b93a52194a0964220d10d92ee7497346f146a8b6ef8ab","price_changes":[{"asset_id":"17406866367975599232214757606801140480252276357934486651183783311435802862074","best_ask":"0.18","best_bid":"0.17","hash":"876a9588bdf6cadae1f6d85d8be4aafd845e3f63","price":"0.12","side":"BUY","size":"35"},{"asset_id":"2151378744569768920256500242561922410292857798164019061749528550808091180185","best_ask":"0.83","best_bid":"0.82","hash":"0f3a7daedf5e1561db6b8a81870a42adce6afe92","price":"0.88","side":"SELL","size":"35"}],"timestamp":"1786845515382"}}
{"f":134,"recv_ms":1786845515675,"raw":{"event_type":"price_change","market":"0xd5f15f31689703aea70b93a52194a0964220d10d92ee7497346f146a8b6ef8ab","price_changes":[{"asset_id":"2151378744569768920256500242561922410292857798164019061749528550808091180185","best_ask":"0.83","best_bid":"0.82","hash":"5dcd4c7a22f7f27b0c55003033583adedbe9eca6","price":"0.01","side":"BUY","size":"5857.53"},{"asset_id":"17406866367975599232214757606801140480252276357934486651183783311435802862074","best_ask":"0.18","best_bid":"0.17","hash":"6b903e1e385af310002e5c93daed2a496c40c69d","price":"0.99","side":"SELL","size":"5857.53"}],"timestamp":"1786845515386"}}
{"f":135,"recv_ms":1786845515675,"raw":{"event_type":"price_change","market":"0xd5f15f31689703aea70b93a52194a0964220d10d92ee7497346f146a8b6ef8ab","price_changes":[{"asset_id":"17406866367975599232214757606801140480252276357934486651183783311435802862074","best_ask":"0.18","best_bid":"0.17","hash":"28003cb17e57abf33e0c99120af539de67729255","price":"0.12","side":"BUY","size":"5"},{"asset_id":"2151378744569768920256500242561922410292857798164019061749528550808091180185","best_ask":"0.83","best_bid":"0.82","hash":"19653f5aac16156c8c706bc23d266e67a6095f35","price":"0.88","side":"SELL","size":"5"}],"timestamp":"1786845515387"}}
{"f":136,"recv_ms":1786845515675,"raw":{"event_type":"price_change","market":"0xd5f15f31689703aea70b93a52194a0964220d10d92ee7497346f146a8b6ef8ab","price_changes":[{"asset_id":"2151378744569768920256500242561922410292857798164019061749528550808091180185","best_ask":"0.83","best_bid":"0.82","hash":"398c0a3142d5fa8749acb2211f6e7db06bbac309","price":"0.01","side":"BUY","size":"5862.53"},{"asset_id":"17406866367975599232214757606801140480252276357934486651183783311435802862074","best_ask":"0.18","best_bid":"0.17","hash":"fdefcd025129e77566dd1fb9420ddde7f0b98079","price":"0.99","side":"SELL","size":"5862.53"}],"timestamp":"1786845515387"}}
{"f":137,"recv_ms":1786845515675,"raw":{"event_type":"price_change","market":"0xd5f15f31689703aea70b93a52194a0964220d10d92ee7497346f146a8b6ef8ab","price_changes":[{"asset_id":"17406866367975599232214757606801140480252276357934486651183783311435802862074","best_ask":"0.18","best_bid":"0.17","hash":"39c9bbeb1951740a7aaed933a1fc09bc52a073df","price":"0.11","side":"BUY","size":"10"},{"asset_id":"2151378744569768920256500242561922410292857798164019061749528550808091180185","best_ask":"0.83","best_bid":"0.82","hash":"00fb4bd127ba5ecf0ba334779be4a2600fcdb31a","price":"0.89","side":"SELL","size":"10"}],"timestamp":"1786845515388"}}
{"f":138,"recv_ms":1786845515675,"raw":{"event_type":"price_change","market":"0xd5f15f31689703aea70b93a52194a0964220d10d92ee7497346f146a8b6ef8ab","price_changes":[{"asset_id":"2151378744569768920256500242561922410292857798164019061749528550808091180185","best_ask":"0.83","best_bid":"0.82","hash":"ff83d8042e4b34eb4679a3526e02cc5b1793cf62","price":"0.01","side":"BUY","size":"5867.53"},{"asset_id":"17406866367975599232214757606801140480252276357934486651183783311435802862074","best_ask":"0.18","best_bid":"0.17","hash":"483ebc42b93929a2b45f690b43a14cffdb517a86","price":"0.99","side":"SELL","size":"5867.53"}],"timestamp":"1786845515388"}}
{"f":139,"recv_ms":1786845515675,"raw":{"event_type":"price_change","market":"0xd5f15f31689703aea70b93a52194a0964220d10d92ee7497346f146a8b6ef8ab","price_changes":[{"asset_id":"2151378744569768920256500242561922410292857798164019061749528550808091180185","best_ask":"0.83","best_bid":"0.82","hash":"2034cf25c5c14e30df427406963c7efe79db5930","price":"0.01","side":"BUY","size":"5873.53"},{"asset_id":"17406866367975599232214757606801140480252276357934486651183783311435802862074","best_ask":"0.18","best_bid":"0.17","hash":"b76ed009baf9efebf74914352e650296ff77a98b","price":"0.99","side":"SELL","size":"5873.53"}],"timestamp":"1786845515412"}}
{"f":140,"recv_ms":1786845515675,"raw":{"event_type":"price_change","market":"0xd5f15f31689703aea70b93a52194a0964220d10d92ee7497346f146a8b6ef8ab","price_changes":[{"asset_id":"2151378744569768920256500242561922410292857798164019061749528550808091180185","best_ask":"0.83","best_bid":"0.82","hash":"6a2bac8bf7ce4583d900a00e5f53d34bce53200b","price":"0.01","side":"BUY","size":"5773.53"},{"asset_id":"17406866367975599232214757606801140480252276357934486651183783311435802862074","best_ask":"0.18","best_bid":"0.17","hash":"0069a2ecc40719282b5ed3baa4f6a4bc3943ba1e","price":"0.99","side":"SELL","size":"5773.53"}],"timestamp":"1786845515415"}}
{"f":141,"recv_ms":1786845515675,"raw":{"asset_id":"2151378744569768920256500242561922410292857798164019061749528550808091180185","event_type":"last_trade_price","fee_rate_bps":"0","market":"0xd5f15f31689703aea70b93a52194a0964220d10d92ee7497346f146a8b6ef8ab","price":"0.83","side":"BUY","size":"1.204817","timestamp":"1786845515411","transaction_hash":"0x3f2e15cb2a68d8ad74957c8c101e7c76374291e9cd228f35baecdeda6081de8a"}}
{"f":142,"recv_ms":1786845515675,"raw":{"event_type":"price_change","market":"0xd5f15f31689703aea70b93a52194a0964220d10d92ee7497346f146a8b6ef8ab","price_changes":[{"asset_id":"2151378744569768920256500242561922410292857798164019061749528550808091180185","best_ask":"0.83","best_bid":"0.82","hash":"3fbd181427e0cae7caec4dcc3d45b4324ea391f3","price":"0.01","side":"BUY","size":"5768.53"},{"asset_id":"17406866367975599232214757606801140480252276357934486651183783311435802862074","best_ask":"0.18","best_bid":"0.17","hash":"ed2ad7aa0801b6d0e61848ce08acece2708f6ef7","price":"0.99","side":"SELL","size":"5768.53"}],"timestamp":"1786845515423"}}
{"f":143,"recv_ms":1786845515675,"raw":{"event_type":"price_change","market":"0xd5f15f31689703aea70b93a52194a0964220d10d92ee7497346f146a8b6ef8ab","price_changes":[{"asset_id":"17406866367975599232214757606801140480252276357934486651183783311435802862074","best_ask":"0.18","best_bid":"0.17","hash":"39623dacee370346f9a7622c9e580d0888c09d61","price":"0.05","side":"BUY","size":"754.7"},{"asset_id":"2151378744569768920256500242561922410292857798164019061749528550808091180185","best_ask":"0.83","best_bid":"0.82","hash":"5074f7d89978cb9d40338ee765d271356a669386","price":"0.95","side":"SELL","size":"754.7"}],"timestamp":"1786845515432"}}
{"f":144,"recv_ms":1786845515675,"raw":{"event_type":"price_change","market":"0xd5f15f31689703aea70b93a52194a0964220d10d92ee7497346f146a8b6ef8ab","price_changes":[{"asset_id":"2151378744569768920256500242561922410292857798164019061749528550808091180185","best_ask":"0.83","best_bid":"0.82","hash":"9bd7913173c01e7af4d6dbc469b70290919b81ad","price":"0.01","side":"BUY","size":"5763.53"},{"asset_id":"17406866367975599232214757606801140480252276357934486651183783311435802862074","best_ask":"0.18","best_bid":"0.17","hash":"67b7344c5cdf55a45243e43036d2c381147bbb8f","price":"0.99","side":"SELL","size":"5763.53"}],"timestamp":"1786845515432"}}
{"f":145,"recv_ms":1786845515675,"raw":{"event_type":"price_change","market":"0xd5f15f31689703aea70b93a52194a0964220d10d92ee7497346f146a8b6ef8ab","price_changes":[{"asset_id":"2151378744569768920256500242561922410292857798164019061749528550808091180185","best_ask":"0.83","best_bid":"0.82","hash":"ba7557212017de2148d9cc8ac49b7e5ce2b46d6a","price":"0.01","side":"BUY","size":"5768.53"},{"asset_id":"17406866367975599232214757606801140480252276357934486651183783311435802862074","best_ask":"0.18","best_bid":"0.17","hash":"45cb4a054e7db0d65eaffdbaeefdb1cf397061d7","price":"0.99","side":"SELL","size":"5768.53"}],"timestamp":"1786845515441"}}
{"f":146,"recv_ms":1786845515675,"raw":{"event_type":"price_change","market":"0xd5f15f31689703aea70b93a52194a0964220d10d92ee7497346f146a8b6ef8ab","price_changes":[{"asset_id":"2151378744569768920256500242561922410292857798164019061749528550808091180185","best_ask":"0.83","best_bid":"0.82","hash":"9b9be8a20561076d5548c239d7e88c4d9e9414e9","price":"0.01","side":"BUY","size":"5773.53"},{"asset_id":"17406866367975599232214757606801140480252276357934486651183783311435802862074","best_ask":"0.18","best_bid":"0.17","hash":"54633e0788db145daf0ae71e4327bc82169888d1","price":"0.99","side":"SELL","size":"5773.53"}],"timestamp":"1786845515442"}}
{"f":147,"recv_ms":1786845515675,"raw":{"event_type":"price_change","market":"0xd5f15f31689703aea70b93a52194a0964220d10d92ee7497346f146a8b6ef8ab","price_changes":[{"asset_id":"2151378744569768920256500242561922410292857798164019061749528550808091180185","best_ask":"0.83","best_bid":"0.82","hash":"2f1f892a101cf61d6fc9c59f71f30067bb63a88c","price":"0.01","side":"BUY","size":"5767.53"},{"asset_id":"17406866367975599232214757606801140480252276357934486651183783311435802862074","best_ask":"0.18","best_bid":"0.17","hash":"1bf351c9ba1892ad3adb73c829ab56caeeb9e98e","price":"0.99","side":"SELL","size":"5767.53"}],"timestamp":"1786845515444"}}
{"f":148,"recv_ms":1786845515675,"raw":{"event_type":"price_change","market":"0xd5f15f31689703aea70b93a52194a0964220d10d92ee7497346f146a8b6ef8ab","price_changes":[{"asset_id":"2151378744569768920256500242561922410292857798164019061749528550808091180185","best_ask":"0.83","best_bid":"0.82","hash":"6a1c726f88cedf2b7acee99e19071b9acba0b4e0","price":"0.03","side":"BUY","size":"2238.96"},{"asset_id":"17406866367975599232214757606801140480252276357934486651183783311435802862074","best_ask":"0.18","best_bid":"0.17","hash":"cd441f88fc2c0fd2fe3d114e46c49533260a701c","price":"0.97","side":"SELL","size":"2238.96"}],"timestamp":"1786845515450"}}
{"f":149,"recv_ms":1786845515676,"raw":{"event_type":"price_change","market":"0xd5f15f31689703aea70b93a52194a0964220d10d92ee7497346f146a8b6ef8ab","price_changes":[{"asset_id":"17406866367975599232214757606801140480252276357934486651183783311435802862074","best_ask":"0.18","best_bid":"0.17","hash":"2a65a3e7116239f7cea3d7d33562768bee47a1a0","price":"0.02","side":"BUY","size":"1792.69"},{"asset_id":"2151378744569768920256500242561922410292857798164019061749528550808091180185","best_ask":"0.83","best_bid":"0.82","hash":"e428f737ba012972b20e71b9e3c0e88a0f944434","price":"0.98","side":"SELL","size":"1792.69"}],"timestamp":"1786845515451"}}
{"f":150,"recv_ms":1786845515676,"raw":{"event_type":"price_change","market":"0xd5f15f31689703aea70b93a52194a0964220d10d92ee7497346f146a8b6ef8ab","price_changes":[{"asset_id":"2151378744569768920256500242561922410292857798164019061749528550808091180185","best_ask":"0.83","best_bid":"0.82","hash":"8ebfb7d558a4d3ff89c932e66624f6032db4dd1a","price":"0.03","side":"BUY","size":"1530.63"},{"asset_id":"17406866367975599232214757606801140480252276357934486651183783311435802862074","best_ask":"0.18","best_bid":"0.17","hash":"88227b3340b5e1dfe24b0176c428d6c715901f4a","price":"0.97","side":"SELL","size":"1530.63"}],"timestamp":"1786845515453"}}
{"f":151,"recv_ms":1786845515676,"raw":{"event_type":"price_change","market":"0xd5f15f31689703aea70b93a52194a0964220d10d92ee7497346f146a8b6ef8ab","price_changes":[{"asset_id":"17406866367975599232214757606801140480252276357934486651183783311435802862074","best_ask":"0.18","best_bid":"0.17","hash":"1229106fcf2e14f281cdf40c434cb7a82528d349","price":"0.02","side":"BUY","size":"1717.69"},{"asset_id":"2151378744569768920256500242561922410292857798164019061749528550808091180185","best_ask":"0.83","best_bid":"0.82","hash":"71605a4aafeff7eb90fb10656373779338991720","price":"0.98","side":"SELL","size":"1717.69"}],"timestamp":"1786845515454"}}
{"f":152,"recv_ms":1786845515676,"raw":{"event_type":"price_change","market":"0xd5f15f31689703aea70b93a52194a0964220d10d92ee7497346f146a8b6ef8ab","price_changes":[{"asset_id":"2151378744569768920256500242561922410292857798164019061749528550808091180185","best_ask":"0.83","best_bid":"0.82","hash":"7d038090358df2febf7c6c8e27641101bf7f8aa3","price":"0.01","side":"BUY","size":"5867.53"},{"asset_id":"17406866367975599232214757606801140480252276357934486651183783311435802862074","best_ask":"0.18","best_bid":"0.17","hash":"a0699af033056f61788d3ffca6453fdd95d8411a","price":"0.99","side":"SELL","size":"5867.53"}],"timestamp":"1786845515454"}}
{"f":153,"recv_ms":1786845515678,"raw":{"event_type":"price_change","market":"0xd5f15f31689703aea70b93a52194a0964220d10d92ee7497346f146a8b6ef8ab","price_changes":[{"asset_id":"17406866367975599232214757606801140480252276357934486651183783311435802862074","best_ask":"0.18","best_bid":"0.17","hash":"6411b71eaa962e29f140cc0ae92f9250bca52952","price":"0.02","side":"BUY","size":"1642.69"},{"asset_id":"2151378744569768920256500242561922410292857798164019061749528550808091180185","best_ask":"0.83","best_bid":"0.82","hash":"32854f75c5d0206681712c751707ac02c5dad2af","price":"0.98","side":"SELL","size":"1642.69"}],"timestamp":"1786845515455"}}
{"f":154,"recv_ms":1786845515678,"raw":{"event_type":"price_change","market":"0xd5f15f31689703aea70b93a52194a0964220d10d92ee7497346f146a8b6ef8ab","price_changes":[{"asset_id":"2151378744569768920256500242561922410292857798164019061749528550808091180185","best_ask":"0.83","best_bid":"0.82","hash":"5390621ca0f4d28900172898fc9daff8d7bdc509","price":"0.03","side":"BUY","size":"822.3"},{"asset_id":"17406866367975599232214757606801140480252276357934486651183783311435802862074","best_ask":"0.18","best_bid":"0.17","hash":"01b3b7eef756c8e8c37891755bcf14006a2150d4","price":"0.97","side":"SELL","size":"822.3"}],"timestamp":"1786845515455"}}
{"f":155,"recv_ms":1786845515678,"raw":{"event_type":"price_change","market":"0xd5f15f31689703aea70b93a52194a0964220d10d92ee7497346f146a8b6ef8ab","price_changes":[{"asset_id":"2151378744569768920256500242561922410292857798164019061749528550808091180185","best_ask":"0.83","best_bid":"0.82","hash":"38904aeaf0f6234149e05a035cd02c1c4a0aacf4","price":"0.05","side":"BUY","size":"708.3"},{"asset_id":"17406866367975599232214757606801140480252276357934486651183783311435802862074","best_ask":"0.18","best_bid":"0.17","hash":"30aa476ee05cf425a81e0ed4f7661c42b7696577","price":"0.95","side":"SELL","size":"708.3"}],"timestamp":"1786845515455"}}
{"f":156,"recv_ms":1786845515679,"raw":{"event_type":"price_change","market":"0xd5f15f31689703aea70b93a52194a0964220d10d92ee7497346f146a8b6ef8ab","price_changes":[{"asset_id":"2151378744569768920256500242561922410292857798164019061749528550808091180185","best_ask":"0.83","best_bid":"0.82","hash":"d3f9adc59fb68d99203b27181d9cc8b19b9b01f9","price":"0.05","side":"BUY","size":"654.3"},{"asset_id":"17406866367975599232214757606801140480252276357934486651183783311435802862074","best_ask":"0.18","best_bid":"0.17","hash":"b09bd373eef6a6f8bc3ff8a958c461a9c2475645","price":"0.95","side":"SELL","size":"654.3"}],"timestamp":"1786845515457"}}
{"f":157,"recv_ms":1786845515679,"raw":{"event_type":"price_change","market":"0xd5f15f31689703aea70b93a52194a0964220d10d92ee7497346f146a8b6ef8ab","price_changes":[{"asset_id":"2151378744569768920256500242561922410292857798164019061749528550808091180185","best_ask":"0.83","best_bid":"0.82","hash":"cd062112bea34fa0a2a7d694151aeaa15f3a9a5e","price":"0.05","side":"BUY","size":"600.3"},{"asset_id":"17406866367975599232214757606801140480252276357934486651183783311435802862074","best_ask":"0.18","best_bid":"0.17","hash":"6ce42a17d58df25a8d423fdc475b6f8189431623","price":"0.95","side":"SELL","size":"600.3"}],"timestamp":"1786845515458"}}
{"f":158,"recv_ms":1786845515679,"raw":{"event_type":"price_change","market":"0xd5f15f31689703aea70b93a52194a0964220d10d92ee7497346f146a8b6ef8ab","price_changes":[{"asset_id":"2151378744569768920256500242561922410292857798164019061749528550808091180185","best_ask":"0.83","best_bid":"0.82","hash":"f33276558c4fe28546281331b0dee06706a4c79b","price":"0.01","side":"BUY","size":"5862.53"},{"asset_id":"17406866367975599232214757606801140480252276357934486651183783311435802862074","best_ask":"0.18","best_bid":"0.17","hash":"3aa55a1de81592f755909a102905424a5ff6c720","price":"0.99","side":"SELL","size":"5862.53"}],"timestamp":"1786845515458"}}
{"f":159,"recv_ms":1786845515679,"raw":{"event_type":"price_change","market":"0xd5f15f31689703aea70b93a52194a0964220d10d92ee7497346f146a8b6ef8ab","price_changes":[{"asset_id":"17406866367975599232214757606801140480252276357934486651183783311435802862074","best_ask":"0.18","best_bid":"0.17","hash":"daaf9c2c72465d9807c0187f8610a040ebf78321","price":"0.15","side":"BUY","size":"83"},{"asset_id":"2151378744569768920256500242561922410292857798164019061749528550808091180185","best_ask":"0.83","best_bid":"0.82","hash":"d19be43164430735ddb7e8f91ae9bb189354d8ac","price":"0.85","side":"SELL","size":"83"}],"timestamp":"1786845515461"}}
{"f":160,"recv_ms":1786845515688,"raw":{"event_type":"price_change","market":"0xd5f15f31689703aea70b93a52194a0964220d10d92ee7497346f146a8b6ef8ab","price_changes":[{"asset_id":"2151378744569768920256500242561922410292857798164019061749528550808091180185","best_ask":"0.83","best_bid":"0.82","hash":"11670875f93e120d813ea61e8940f0d8e75a2307","price":"0.01","side":"BUY","size":"5857.53"},{"asset_id":"17406866367975599232214757606801140480252276357934486651183783311435802862074","best_ask":"0.18","best_bid":"0.17","hash":"414841406a803a42a7be26bd5f3d125a11ee79a1","price":"0.99","side":"SELL","size":"5857.53"}],"timestamp":"1786845515464"}}
{"f":161,"recv_ms":1786845515688,"raw":{"event_type":"price_change","market":"0xd5f15f31689703aea70b93a52194a0964220d10d92ee7497346f146a8b6ef8ab","price_changes":[{"asset_id":"17406866367975599232214757606801140480252276357934486651183783311435802862074","best_ask":"0.18","best_bid":"0.17","hash":"92645c9bfc0b7f997102de3a1f6a7a8e7f4d06c9","price":"0.12","side":"BUY","size":"83"},{"asset_id":"2151378744569768920256500242561922410292857798164019061749528550808091180185","best_ask":"0.83","best_bid":"0.82","hash":"2152f4c7fb4250526dc700e50bc0184fc8d514c9","price":"0.88","side":"SELL","size":"83"}],"timestamp":"1786845515464"}}
{"f":162,"recv_ms":1786845515716,"raw":{"event_type":"price_change","market":"0xd5f15f31689703aea70b93a52194a0964220d10d92ee7497346f146a8b6ef8ab","price_changes":[{"asset_id":"2151378744569768920256500242561922410292857798164019061749528550808091180185","best_ask":"0.83","best_bid":"0.82","hash":"8bf0a00d325523faf04efd7be7c067980d18fea7","price":"0.01","side":"BUY","size":"5852.53"},{"asset_id":"17406866367975599232214757606801140480252276357934486651183783311435802862074","best_ask":"0.18","best_bid":"0.17","hash":"b1cbd08e74b93dd7bc6f01ad636608a06e9ce57b","price":"0.99","side":"SELL","size":"5852.53"}],"timestamp":"1786845515492"}}
{"f":163,"recv_ms":1786845515726,"raw":{"event_type":"price_change","market":"0xd5f15f31689703aea70b93a52194a0964220d10d92ee7497346f146a8b6ef8ab","price_changes":[{"asset_id":"2151378744569768920256500242561922410292857798164019061749528550808091180185","best_ask":"0.83","best_bid":"0.82","hash":"090ac43a8d1bfd47b327a316faeb34679fe327f8","price":"0.01","side":"BUY","size":"5857.53"},{"asset_id":"17406866367975599232214757606801140480252276357934486651183783311435802862074","best_ask":"0.18","best_bid":"0.17","hash":"bff39a557767ac19e1840cca9b030173fedb15ed","price":"0.99","side":"SELL","size":"5857.53"}],"timestamp":"1786845515511"}}
{"f":164,"recv_ms":1786845515741,"raw":{"event_type":"price_change","market":"0xd5f15f31689703aea70b93a52194a0964220d10d92ee7497346f146a8b6ef8ab","price_changes":[{"asset_id":"2151378744569768920256500242561922410292857798164019061749528550808091180185","best_ask":"0.83","best_bid":"0.82","hash":"c50106aa6e466874db8e7e3a989dedff4866be9a","price":"0.01","side":"BUY","size":"5863.53"},{"asset_id":"17406866367975599232214757606801140480252276357934486651183783311435802862074","best_ask":"0.18","best_bid":"0.17","hash":"8f46a84cc73524841b97c77ec4fe976694f90cc5","price":"0.99","side":"SELL","size":"5863.53"}],"timestamp":"1786845515515"}}
{"f":165,"recv_ms":1786845515741,"raw":{"event_type":"price_change","market":"0xd5f15f31689703aea70b93a52194a0964220d10d92ee7497346f146a8b6ef8ab","price_changes":[{"asset_id":"2151378744569768920256500242561922410292857798164019061749528550808091180185","best_ask":"0.83","best_bid":"0.82","hash":"1fe629fa91a1fd5ab9664c4b36913ec6f0212217","price":"0.01","side":"BUY","size":"5763.53"},{"asset_id":"17406866367975599232214757606801140480252276357934486651183783311435802862074","best_ask":"0.18","best_bid":"0.17","hash":"80b53d02a73a01d830a28c762678ff7bcfafc01b","price":"0.99","side":"SELL","size":"5763.53"}],"timestamp":"1786845515516"}}
{"f":166,"recv_ms":1786845515745,"raw":{"event_type":"price_change","market":"0xd5f15f31689703aea70b93a52194a0964220d10d92ee7497346f146a8b6ef8ab","price_changes":[{"asset_id":"2151378744569768920256500242561922410292857798164019061749528550808091180185","best_ask":"0.83","best_bid":"0.82","hash":"7ab1b45d90f4773ae96b0f9df2e6f2713e1a40d0","price":"0.01","side":"BUY","size":"5758.53"},{"asset_id":"17406866367975599232214757606801140480252276357934486651183783311435802862074","best_ask":"0.18","best_bid":"0.17","hash":"30c28f26a595b381cc582d33783e97d14e7feb8e","price":"0.99","side":"SELL","size":"5758.53"}],"timestamp":"1786845515530"}}
{"f":167,"recv_ms":1786845515756,"raw":{"event_type":"price_change","market":"0xd5f15f31689703aea70b93a52194a0964220d10d92ee7497346f146a8b6ef8ab","price_changes":[{"asset_id":"2151378744569768920256500242561922410292857798164019061749528550808091180185","best_ask":"0.83","best_bid":"0.82","hash":"6f5b6b0fa3f50ace5bddfeac696e234e475bd1b3","price":"0.01","side":"BUY","size":"5858.53"},{"asset_id":"17406866367975599232214757606801140480252276357934486651183783311435802862074","best_ask":"0.18","best_bid":"0.17","hash":"1cc89219e2e2cc9f61eb4134baff40b4a9aed4d7","price":"0.99","side":"SELL","size":"5858.53"}],"timestamp":"1786845515535"}}
{"f":168,"recv_ms":1786845515773,"raw":{"event_type":"price_change","market":"0xd5f15f31689703aea70b93a52194a0964220d10d92ee7497346f146a8b6ef8ab","price_changes":[{"asset_id":"2151378744569768920256500242561922410292857798164019061749528550808091180185","best_ask":"0.83","best_bid":"0.82","hash":"c7b48dab42de3c4d2dc0926599a5f823a538aba1","price":"0.01","side":"BUY","size":"5852.53"},{"asset_id":"17406866367975599232214757606801140480252276357934486651183783311435802862074","best_ask":"0.18","best_bid":"0.17","hash":"aefd8db5415840093fb18c18142b5cffad5fae9f","price":"0.99","side":"SELL","size":"5852.53"}],"timestamp":"1786845515544"}}
{"f":169,"recv_ms":1786845515773,"raw":{"event_type":"price_change","market":"0xd5f15f31689703aea70b93a52194a0964220d10d92ee7497346f146a8b6ef8ab","price_changes":[{"asset_id":"2151378744569768920256500242561922410292857798164019061749528550808091180185","best_ask":"0.83","best_bid":"0.82","hash":"d6ecec3825170a8acef24bc9ddc5805b29ce1a2d","price":"0.01","side":"BUY","size":"5857.54"},{"asset_id":"17406866367975599232214757606801140480252276357934486651183783311435802862074","best_ask":"0.18","best_bid":"0.17","hash":"108048e4b11404054a946aef8a83dffa96c2c3dc","price":"0.99","side":"SELL","size":"5857.54"}],"timestamp":"1786845515553"}}
{"f":170,"recv_ms":1786845515776,"raw":{"event_type":"price_change","market":"0xd5f15f31689703aea70b93a52194a0964220d10d92ee7497346f146a8b6ef8ab","price_changes":[{"asset_id":"17406866367975599232214757606801140480252276357934486651183783311435802862074","best_ask":"0.18","best_bid":"0.17","hash":"bf6cac2e9989d67c73d9ff01dc6ef05d0df7eb3e","price":"0.01","side":"BUY","size":"5588.18"},{"asset_id":"2151378744569768920256500242561922410292857798164019061749528550808091180185","best_ask":"0.83","best_bid":"0.82","hash":"bec65270f2b515cc013eac7a065a215ab4dbeb0b","price":"0.99","side":"SELL","size":"5588.18"}],"timestamp":"1786845515564"}}
{"f":171,"recv_ms":1786845515776,"raw":{"event_type":"price_change","market":"0xd5f15f31689703aea70b93a52194a0964220d10d92ee7497346f146a8b6ef8ab","price_changes":[{"asset_id":"17406866367975599232214757606801140480252276357934486651183783311435802862074","best_ask":"0.18","best_bid":"0.17","hash":"f63f1c2523972db43d251ad50693de5818a9621c","price":"0.03","side":"BUY","size":"611.3"},{"asset_id":"2151378744569768920256500242561922410292857798164019061749528550808091180185","best_ask":"0.83","best_bid":"0.82","hash":"71a9290de5b267900519ccf310dec9089e532bb4","price":"0.97","side":"SELL","size":"611.3"}],"timestamp":"1786845515565"}}
{"f":172,"recv_ms":1786845515776,"raw":{"event_type":"price_change","market":"0xd5f15f31689703aea70b93a52194a0964220d10d92ee7497346f146a8b6ef8ab","price_changes":[{"asset_id":"17406866367975599232214757606801140480252276357934486651183783311435802862074","best_ask":"0.18","best_bid":"0.17","hash":"444d559eb2d940214eeb613802a29481160eefe0","price":"0.05","side":"BUY","size":"759.7"},{"asset_id":"2151378744569768920256500242561922410292857798164019061749528550808091180185","best_ask":"0.83","best_bid":"0.82","hash":"8c8266bd6d86685d127ea4d15a098b9104f820ee","price":"0.95","side":"SELL","size":"759.7"}],"timestamp":"1786845515565"}}
{"f":173,"recv_ms":1786845515779,"raw":{"event_type":"price_change","market":"0xd5f15f31689703aea70b93a52194a0964220d10d92ee7497346f146a8b6ef8ab","price_changes":[{"asset_id":"17406866367975599232214757606801140480252276357934486651183783311435802862074","best_ask":"0.18","best_bid":"0.17","hash":"6eef75b4f66f743882cb060b142f0779889295d7","price":"0.09","side":"BUY","size":"76.7"},{"asset_id":"2151378744569768920256500242561922410292857798164019061749528550808091180185","best_ask":"0.83","best_bid":"0.82","hash":"352557fdf75db9cc2e572f4766d5b427ed19d197","price":"0.91","side":"SELL","size":"76.7"}],"timestamp":"1786845515566"}}
{"f":174,"recv_ms":1786845515779,"raw":{"event_type":"price_change","market":"0xd5f15f31689703aea70b93a52194a0964220d10d92ee7497346f146a8b6ef8ab","price_changes":[{"asset_id":"17406866367975599232214757606801140480252276357934486651183783311435802862074","best_ask":"0.18","best_bid":"0.17","hash":"14362a26c49caa618b261f21ccd36ebf1fa5832e","price":"0.07","side":"BUY","size":"464.86"},{"asset_id":"2151378744569768920256500242561922410292857798164019061749528550808091180185","best_ask":"0.83","best_bid":"0.82","hash":"fd9fc7823e90cab7bd9d65235a83bb569a09fc83","price":"0.93","side":"SELL","size":"464.86"}],"timestamp":"1786845515567"}}
{"f":175,"recv_ms":1786845515801,"raw":{"event_type":"price_change","market":"0xd5f15f31689703aea70b93a52194a0964220d10d92ee7497346f146a8b6ef8ab","price_changes":[{"asset_id":"2151378744569768920256500242561922410292857798164019061749528550808091180185","best_ask":"0.83","best_bid":"0.82","hash":"20721a3aad3cbacebfc9f20cb075d211f4fae23a","price":"0.01","side":"BUY","size":"5757.54"},{"asset_id":"17406866367975599232214757606801140480252276357934486651183783311435802862074","best_ask":"0.18","best_bid":"0.17","hash":"740278753577a1ecd0db909a6e67bd921a0d587a","price":"0.99","side":"SELL","size":"5757.54"}],"timestamp":"1786845515568"}}
{"f":176,"recv_ms":1786845515801,"raw":{"event_type":"price_change","market":"0xd5f15f31689703aea70b93a52194a0964220d10d92ee7497346f146a8b6ef8ab","price_changes":[{"asset_id":"2151378744569768920256500242561922410292857798164019061749528550808091180185","best_ask":"0.83","best_bid":"0.82","hash":"daf115d61acfed3cf218a87421cd37bce4e5dd44","price":"0.01","side":"BUY","size":"5752.53"},{"asset_id":"17406866367975599232214757606801140480252276357934486651183783311435802862074","best_ask":"0.18","best_bid":"0.17","hash":"4540a60509aff352280154d27ca7e67268a45dc0","price":"0.99","side":"SELL","size":"5752.53"}],"timestamp":"1786845515585"}}
{"f":177,"recv_ms":1786845515809,"raw":{"event_type":"price_change","market":"0x0c33f1586ca3445a41be2863746ffb0edc32df6500f4926657b2643fe8a78258","price_changes":[{"asset_id":"45654842686110167876337056449737479301235917003519988189654649607054904571464","best_ask":"0.54","best_bid":"0.53","hash":"1eb58cb7dbc7891fef830e5eb0403d59c9266d13","price":"0.53","side":"BUY","size":"24.37"},{"asset_id":"84378280634731141017197924889292000863571415141565530467641465700960218022429","best_ask":"0.47","best_bid":"0.46","hash":"b1aa3c10b2025526958e66be3c24748b58a9b2f5","price":"0.47","side":"SELL","size":"24.37"}],"timestamp":"1786845515598"}}
{"f":178,"recv_ms":1786845515824,"raw":{"asks":[{"price":"0.99","size":"94084.89"},{"price":"0.98","size":"19003"},{"price":"0.97","size":"11896"},{"price":"0.96","size":"388"},{"price":"0.95","size":"7079"},{"price":"0.94","size":"139"},{"price":"0.93","size":"429"},{"price":"0.92","size":"168"},{"price":"0.91","size":"331"},{"price":"0.9","size":"3450.99"},{"price":"0.89","size":"1419.8"},{"price":"0.88","size":"413.62"},{"price":"0.87","size":"379.43"},{"price":"0.86","size":"113"},{"price":"0.85","size":"3266"},{"price":"0.84","size":"18"},{"price":"0.83","size":"27"},{"price":"0.82","size":"20"},{"price":"0.81","size":"19"},{"price":"0.8","size":"716.95"},{"price":"0.79","size":"531.33"},{"price":"0.78","size":"323"},{"price":"0.77","size":"397.72"},{"price":"0.76","size":"628.86"},{"price":"0.75","size":"520.41"},{"price":"0.74","size":"673.42"},{"price":"0.73","size":"610.34"},{"price":"0.72","size":"557.9"},{"price":"0.71","size":"478.79"},{"price":"0.7","size":"255.96"},{"price":"0.69","size":"125.79"},{"price":"0.68","size":"178.29"},{"price":"0.67","size":"65.79"},{"price":"0.66","size":"24.29"},{"price":"0.65","size":"211"},{"price":"0.64","size":"93"},{"price":"0.63","size":"15"},{"price":"0.62","size":"450"},{"price":"0.61","size":"80"},{"price":"0.6","size":"50"},{"price":"0.59","size":"30"},{"price":"0.58","size":"110"},{"price":"0.57","size":"102"},{"price":"0.56","size":"84"},{"price":"0.55","size":"82"},{"price":"0.54","size":"25"},{"price":"0.53","size":"220.64"},{"price":"0.52","size":"30"},{"price":"0.51","size":"115.59"},{"price":"0.5","size":"380.64"},{"price":"0.49","size":"31"},{"price":"0.48","size":"15"},{"price":"0.47","size":"24.37"}],"asset_id":"84378280634731141017197924889292000863571415141565530467641465700960218022429","bids":[{"price":"0.01","size":"94110.75"},{"price":"0.02","size":"19003"},{"price":"0.03","size":"11914.92"},{"price":"0.04","size":"388"},{"price":"0.05","size":"7079"},{"price":"0.06","size":"169"},{"price":"0.07","size":"429"},{"price":"0.08","size":"168"},{"price":"0.09","size":"664"},{"price":"0.1","size":"3450.99"},{"price":"0.11","size":"1147.8"},{"price":"0.12","size":"413.62"},{"price":"0.13","size":"379.43"},{"price":"0.14","size":"113"},{"price":"0.15","size":"3266"},{"price":"0.16","size":"18"},{"price":"0.17","size":"203"},{"price":"0.18","size":"20"},{"price":"0.19","size":"19"},{"price":"0.2","size":"706.95"},{"price":"0.21","size":"389.33"},{"price":"0.22","size":"323"},{"price":"0.23","size":"403.72"},{"price":"0.24","size":"628.86"},{"price":"0.25","size":"520.41"},{"price":"0.26","size":"667.42"},{"price":"0.27","size":"616.34"},{"price":"0.28","size":"557.9"},{"price":"0.29","size":"478.79"},{"price":"0.3","size":"255.96"},{"price":"0.31","size":"125.79"},{"price":"0.32","size":"178.29"},{"price":"0.33","size":"59.79"},{"price":"0.34","size":"24.29"},{"price":"0.35","size":"211"},{"price":"0.36","size":"93"},{"price":"0.37","size":"15"},{"price":"0.38","size":"450"},{"price":"0.39","size":"80"},{"price":"0.4","size":"45"},{"price":"0.42","size":"80"},{"price":"0.43","size":"2.58"},{"price":"0.44","size":"30"},{"price":"0.45","size":"22.78"},{"price":"0.46","size":"5"}],"event_type":"book","hash":"b1aa3c10b2025526958e66be3c24748b58a9b2f5","market":"0x0c33f1586ca3445a41be2863746ffb0edc32df6500f4926657b2643fe8a78258","timestamp":"1786845515598"}}
{"f":179,"recv_ms":1786845515825,"raw":{"event_type":"price_change","market":"0xd5f15f31689703aea70b93a52194a0964220d10d92ee7497346f146a8b6ef8ab","price_changes":[{"asset_id":"2151378744569768920256500242561922410292857798164019061749528550808091180185","best_ask":"0.83","best_bid":"0.82","hash":"de7cfbd07c12257576817527a6f93190ecf48b73","price":"0.01","side":"BUY","size":"5852.53"},{"asset_id":"17406866367975599232214757606801140480252276357934486651183783311435802862074","best_ask":"0.18","best_bid":"0.17","hash":"b3c71ea08dc53a268eb8ff63e6448f57479a060c","price":"0.99","side":"SELL","size":"5852.53"}],"timestamp":"1786845515611"}}
{"f":180,"recv_ms":1786845515830,"raw":{"event_type":"price_change","market":"0xd5f15f31689703aea70b93a52194a0964220d10d92ee7497346f146a8b6ef8ab","price_changes":[{"asset_id":"2151378744569768920256500242561922410292857798164019061749528550808091180185","best_ask":"0.83","best_bid":"0.82","hash":"a8df6340bdc08123bb112eb7539292c1704b7b1a","price":"0.01","side":"BUY","size":"5858.53"},{"asset_id":"17406866367975599232214757606801140480252276357934486651183783311435802862074","best_ask":"0.18","best_bid":"0.17","hash":"fdcc47e7250ee4a6fbfaf7b3b420116dec72258d","price":"0.99","side":"SELL","size":"5858.53"}],"timestamp":"1786845515613"}}
{"f":181,"recv_ms":1786845515848,"raw":{"event_type":"price_change","market":"0xd5f15f31689703aea70b93a52194a0964220d10d92ee7497346f146a8b6ef8ab","price_changes":[{"asset_id":"2151378744569768920256500242561922410292857798164019061749528550808091180185","best_ask":"0.83","best_bid":"0.82","hash":"bb437ae2b5106fd13cef0b36b0bf01443152ea07","price":"0.54","side":"BUY","size":"29"},{"asset_id":"17406866367975599232214757606801140480252276357934486651183783311435802862074","best_ask":"0.18","best_bid":"0.17","hash":"549e66fcfed362e7897d52bb82dede7ed939aa12","price":"0.46","side":"SELL","size":"29"}],"timestamp":"1786845515626"}}
{"f":182,"recv_ms":1786845515848,"raw":{"event_type":"price_change","market":"0xd5f15f31689703aea70b93a52194a0964220d10d92ee7497346f146a8b6ef8ab","price_changes":[{"asset_id":"17406866367975599232214757606801140480252276357934486651183783311435802862074","best_ask":"0.18","best_bid":"0.17","hash":"f77ab700a99930cecb2a5ab83d39c3a7582dbf8e","price":"0.01","side":"BUY","size":"5583.18"},{"asset_id":"2151378744569768920256500242561922410292857798164019061749528550808091180185","best_ask":"0.83","best_bid":"0.82","hash":"2e497001e3756c42b9eca8a9b94cc8b9db8bf9f8","price":"0.99","side":"SELL","size":"5583.18"}],"timestamp":"1786845515629"}}
{"f":183,"recv_ms":1786845515848,"raw":{"event_type":"price_change","market":"0xd5f15f31689703aea70b93a52194a0964220d10d92ee7497346f146a8b6ef8ab","price_changes":[{"asset_id":"17406866367975599232214757606801140480252276357934486651183783311435802862074","best_ask":"0.18","best_bid":"0.17","hash":"bd991e1c9bdb87c3cb77ba553ce6cc9b4dc5f895","price":"0.01","side":"BUY","size":"5588.18"},{"asset_id":"2151378744569768920256500242561922410292857798164019061749528550808091180185","best_ask":"0.83","best_bid":"0.82","hash":"aa4683c9bb9daa15452135bde69a9292339bfcdc","price":"0.99","side":"SELL","size":"5588.18"}],"timestamp":"1786845515635"}}
{"f":184,"recv_ms":1786845515857,"raw":{"event_type":"price_change","market":"0xd5f15f31689703aea70b93a52194a0964220d10d92ee7497346f146a8b6ef8ab","price_changes":[{"asset_id":"17406866367975599232214757606801140480252276357934486651183783311435802862074","best_ask":"0.18","best_bid":"0.17","hash":"b800af8719735f42b1b848f996d1717bc93b383a","price":"0.01","side":"BUY","size":"5593.18"},{"asset_id":"2151378744569768920256500242561922410292857798164019061749528550808091180185","best_ask":"0.83","best_bid":"0.82","hash":"f7bf05668ad90d52199bf0e08df3a9f7b57e316e","price":"0.99","side":"SELL","size":"5593.18"}],"timestamp":"1786845515636"}}
{"f":185,"recv_ms":1786845515918,"raw":{"event_type":"price_change","market":"0xd5f15f31689703aea70b93a52194a0964220d10d92ee7497346f146a8b6ef8ab","price_changes":[{"asset_id":"2151378744569768920256500242561922410292857798164019061749528550808091180185","best_ask":"0.83","best_bid":"0.82","hash":"d72d5df7c7f75a3304957bd912751e0e56be908d","price":"0.01","side":"BUY","size":"5863.53"},{"asset_id":"17406866367975599232214757606801140480252276357934486651183783311435802862074","best_ask":"0.18","best_bid":"0.17","hash":"6b4bf5cdfbe9350003aa69145a64f06f161212f5","price":"0.99","side":"SELL","size":"5863.53"}],"timestamp":"1786845515638"}}
{"f":186,"recv_ms":1786845515918,"raw":{"event_type":"price_change","market":"0xd5f15f31689703aea70b93a52194a0964220d10d92ee7497346f146a8b6ef8ab","price_changes":[{"asset_id":"2151378744569768920256500242561922410292857798164019061749528550808091180185","best_ask":"0.83","best_bid":"0.82","hash":"2c6790d109d809ef5bf172ff4185dc451c97a12f","price":"0.01","side":"BUY","size":"5868.53"},{"asset_id":"17406866367975599232214757606801140480252276357934486651183783311435802862074","best_ask":"0.18","best_bid":"0.17","hash":"4e1c1b651a6f63e059dd6d86f7a65eeb18f15421","price":"0.99","side":"SELL","size":"5868.53"}],"timestamp":"1786845515638"}}
{"f":187,"recv_ms":1786845515918,"raw":{"event_type":"price_change","market":"0xd5f15f31689703aea70b93a52194a0964220d10d92ee7497346f146a8b6ef8ab","price_changes":[{"asset_id":"2151378744569768920256500242561922410292857798164019061749528550808091180185","best_ask":"0.83","best_bid":"0.82","hash":"8e139271d3e215d2ca2e98b85261c379ebf1b58c","price":"0.01","side":"BUY","size":"5873.53"},{"asset_id":"17406866367975599232214757606801140480252276357934486651183783311435802862074","best_ask":"0.18","best_bid":"0.17","hash":"97bc91aaf63cb1ef66e4e309f5a27ea09beee0c8","price":"0.99","side":"SELL","size":"5873.53"}],"timestamp":"1786845515639"}}
{"f":188,"recv_ms":1786845515919,"raw":{"event_type":"price_change","market":"0xd5f15f31689703aea70b93a52194a0964220d10d92ee7497346f146a8b6ef8ab","price_changes":[{"asset_id":"17406866367975599232214757606801140480252276357934486651183783311435802862074","best_ask":"0.18","best_bid":"0.17","hash":"700e8ece704be1a25cceb7235bed1aef4e2b5d51","price":"0.01","side":"BUY","size":"5588.18"},{"asset_id":"2151378744569768920256500242561922410292857798164019061749528550808091180185","best_ask":"0.83","best_bid":"0.82","hash":"e2105057d90ef402743ea7055c426cb10001ba2b","price":"0.99","side":"SELL","size":"5588.18"}],"timestamp":"1786845515641"}}
{"f":189,"recv_ms":1786845515919,"raw":{"event_type":"price_change","market":"0xd5f15f31689703aea70b93a52194a0964220d10d92ee7497346f146a8b6ef8ab","price_changes":[{"asset_id":"2151378744569768920256500242561922410292857798164019061749528550808091180185","best_ask":"0.83","best_bid":"0.82","hash":"075c19c8e4cba8c967ea9edf1a7c5597dbacb9bf","price":"0.01","side":"BUY","size":"5867.53"},{"asset_id":"17406866367975599232214757606801140480252276357934486651183783311435802862074","best_ask":"0.18","best_bid":"0.17","hash":"df3b07b9529e70ab28285fadd99eadc48da9ec5e","price":"0.99","side":"SELL","size":"5867.53"}],"timestamp":"1786845515643"}}
{"f":190,"recv_ms":1786845515919,"raw":{"event_type":"price_change","market":"0xd5f15f31689703aea70b93a52194a0964220d10d92ee7497346f146a8b6ef8ab","price_changes":[{"asset_id":"2151378744569768920256500242561922410292857798164019061749528550808091180185","best_ask":"0.83","best_bid":"0.82","hash":"d054dce9ff5035fe5f318acb8eddfe1aabe3e9f8","price":"0.54","side":"BUY","size":"59"},{"asset_id":"17406866367975599232214757606801140480252276357934486651183783311435802862074","best_ask":"0.18","best_bid":"0.17","hash":"799b3fd7cf22f8f77eb0871b670eebd6a6934f17","price":"0.46","side":"SELL","size":"59"}],"timestamp":"1786845515647"}}
{"f":191,"recv_ms":1786845515919,"raw":{"event_type":"price_change","market":"0xd5f15f31689703aea70b93a52194a0964220d10d92ee7497346f146a8b6ef8ab","price_changes":[{"asset_id":"2151378744569768920256500242561922410292857798164019061749528550808091180185","best_ask":"0.83","best_bid":"0.82","hash":"90378365b06f2343cf10647fcd313444cb129251","price":"0.01","side":"BUY","size":"5767.53"},{"asset_id":"17406866367975599232214757606801140480252276357934486651183783311435802862074","best_ask":"0.18","best_bid":"0.17","hash":"9c48948913893dfef7cd2a60e9758e97e2502d01","price":"0.99","side":"SELL","size":"5767.53"}],"timestamp":"1786845515654"}}
{"f":192,"recv_ms":1786845515919,"raw":{"asset_id":"84378280634731141017197924889292000863571415141565530467641465700960218022429","event_type":"last_trade_price","fee_rate_bps":"0","market":"0x0c33f1586ca3445a41be2863746ffb0edc32df6500f4926657b2643fe8a78258","price":"0.47","side":"BUY","size":"10.63","timestamp":"1786845515668","transaction_hash":"0x5afd98de5a8f2e9a0b383960e8ff96144eb9f0a50898d601f5a599f6eb882509"}}
{"f":193,"recv_ms":1786845515919,"raw":{"event_type":"price_change","market":"0xd5f15f31689703aea70b93a52194a0964220d10d92ee7497346f146a8b6ef8ab","price_changes":[{"asset_id":"2151378744569768920256500242561922410292857798164019061749528550808091180185","best_ask":"0.83","best_bid":"0.82","hash":"fa6298e255fe87a39222a9f5a27eafdcb727ee4a","price":"0.01","side":"BUY","size":"5762.53"},{"asset_id":"17406866367975599232214757606801140480252276357934486651183783311435802862074","best_ask":"0.18","best_bid":"0.17","hash":"ae12af176a59f8eae732864f7b85d536fffab1e1","price":"0.99","side":"SELL","size":"5762.53"}],"timestamp":"1786845515671"}}
{"f":194,"recv_ms":1786845515919,"raw":{"event_type":"price_change","market":"0xd5f15f31689703aea70b93a52194a0964220d10d92ee7497346f146a8b6ef8ab","price_changes":[{"asset_id":"17406866367975599232214757606801140480252276357934486651183783311435802862074","best_ask":"0.18","best_bid":"0.17","hash":"8a11ed872e67910b8d0b07bfe4cc8f6037792b29","price":"0.02","side":"BUY","size":"1717.69"},{"asset_id":"2151378744569768920256500242561922410292857798164019061749528550808091180185","best_ask":"0.83","best_bid":"0.82","hash":"753835d5b56f54c03b419c41c52a8ad05765804c","price":"0.98","side":"SELL","size":"1717.69"}],"timestamp":"1786845515692"}}
{"f":195,"recv_ms":1786845515919,"raw":{"event_type":"price_change","market":"0xd5f15f31689703aea70b93a52194a0964220d10d92ee7497346f146a8b6ef8ab","price_changes":[{"asset_id":"2151378744569768920256500242561922410292857798164019061749528550808091180185","best_ask":"0.83","best_bid":"0.82","hash":"2c50b9304904d2e0876c758fbb1259869c5f6dc5","price":"0.02","side":"BUY","size":"2408.52"},{"asset_id":"17406866367975599232214757606801140480252276357934486651183783311435802862074","best_ask":"0.18","best_bid":"0.17","hash":"9502e354ccc1dc6383effb6e1651ab7bf975e490","price":"0.98","side":"SELL","size":"2408.52"}],"timestamp":"1786845515693"}}
{"f":196,"recv_ms":1786845515919,"raw":{"event_type":"price_change","market":"0xd5f15f31689703aea70b93a52194a0964220d10d92ee7497346f146a8b6ef8ab","price_changes":[{"asset_id":"2151378744569768920256500242561922410292857798164019061749528550808091180185","best_ask":"0.83","best_bid":"0.82","hash":"8ac433888b18e3aecfde860a9172a574806816e4","price":"0.75","side":"BUY","size":"171.9"},{"asset_id":"17406866367975599232214757606801140480252276357934486651183783311435802862074","best_ask":"0.18","best_bid":"0.17","hash":"4bb9f5f410fd574faddbaef229d644cfe5c5b1c6","price":"0.25","side":"SELL","size":"171.9"}],"timestamp":"1786845515695"}}
{"f":197,"recv_ms":1786845515919,"raw":{"event_type":"price_change","market":"0xd5f15f31689703aea70b93a52194a0964220d10d92ee7497346f146a8b6ef8ab","price_changes":[{"asset_id":"17406866367975599232214757606801140480252276357934486651183783311435802862074","best_ask":"0.18","best_bid":"0.17","hash":"9ab5c62f82d439b665de88db6112cbbb2b5b9319","price":"0.12","side":"BUY","size":"5"},{"asset_id":"2151378744569768920256500242561922410292857798164019061749528550808091180185","best_ask":"0.83","best_bid":"0.82","hash":"3fcbe63e322126e93ec878a4f515360201544199","price":"0.88","side":"SELL","size":"5"}],"timestamp":"1786845515697"}}
{"f":198,"recv_ms":1786845515919,"raw":{"event_type":"price_change","market":"0xd5f15f31689703aea70b93a52194a0964220d10d92ee7497346f146a8b6ef8ab","price_changes":[{"asset_id":"2151378744569768920256500242561922410292857798164019061749528550808091180185","best_ask":"0.83","best_bid":"0.82","hash":"1f801c04aac88658270cf5bfd45df33d4b2e0dc5","price":"0.05","side":"BUY","size":"654.3"},{"asset_id":"17406866367975599232214757606801140480252276357934486651183783311435802862074","best_ask":"0.18","best_bid":"0.17","hash":"433e0c7452370a93bf2fee1f2a1c31b15b319db6","price":"0.95","side":"SELL","size":"654.3"}],"timestamp":"1786845515699"}}
{"f":199,"recv_ms":1786845515919,"raw":{"event_type":"price_change","market":"0x0c33f1586ca3445a41be2863746ffb0edc32df6500f4926657b2643fe8a78258","price_changes":[{"asset_id":"84378280634731141017197924889292000863571415141565530467641465700960218022429","best_ask":"0.47","best_bid":"0.46","hash":"d9b11df39106aaed27b3ca5f087932f9f0639304","price":"0.46","side":"BUY","size":"10"},{"asset_id":"45654842686110167876337056449737479301235917003519988189654649607054904571464","best_ask":"0.54","best_bid":"0.53","hash":"db134fd0915ab51232463bb7bd9754959e65f3b6","price":"0.54","side":"SELL","size":"10"}],"timestamp":"1786845515700"}}
{"f":200,"recv_ms":1786845515919,"raw":{"event_type":"price_change","market":"0xd5f15f31689703aea70b93a52194a0964220d10d92ee7497346f146a8b6ef8ab","price_changes":[{"asset_id":"17406866367975599232214757606801140480252276357934486651183783311435802862074","best_ask":"0.18","best_bid":"0.17","hash":"366e2597158d2609e97a57ca26acbf0ca7cd33ca","price":"0.1","side":"BUY","size":"66"},{"asset_id":"2151378744569768920256500242561922410292857798164019061749528550808091180185","best_ask":"0.83","best_bid":"0.82","hash":"9a93bae153a495138940f5069259bac5524f67b2","price":"0.9","side":"SELL","size":"66"}],"timestamp":"1786845515700"}}
{"f":201,"recv_ms":1786845515919,"raw":{"event_type":"price_change","market":"0xd5f15f31689703aea70b93a52194a0964220d10d92ee7497346f146a8b6ef8ab","price_changes":[{"asset_id":"2151378744569768920256500242561922410292857798164019061749528550808091180185","best_ask":"0.83","best_bid":"0.82","hash":"a3504376cfd271d97df57b29e588bf724d911953","price":"0.01","side":"BUY","size":"5862.53"},{"asset_id":"17406866367975599232214757606801140480252276357934486651183783311435802862074","best_ask":"0.18","best_bid":"0.17","hash":"aa4f2b231f85d53ffd7571562bdbe0f4eb2577a5","price":"0.99","side":"SELL","size":"5862.53"}],"timestamp":"1786845515707"}}
{"f":202,"recv_ms":1786845515943,"raw":{"event_type":"price_change","market":"0xd5f15f31689703aea70b93a52194a0964220d10d92ee7497346f146a8b6ef8ab","price_changes":[{"asset_id":"2151378744569768920256500242561922410292857798164019061749528550808091180185","best_ask":"0.83","best_bid":"0.82","hash":"bda825ad22e53a5c922384183679bf79f700a999","price":"0.01","side":"BUY","size":"5857.53"},{"asset_id":"17406866367975599232214757606801140480252276357934486651183783311435802862074","best_ask":"0.18","best_bid":"0.17","hash":"defadc8a49801494d94b5c6243a8378001bed5a7","price":"0.99","side":"SELL","size":"5857.53"}],"timestamp":"1786845515707"}}
{"f":203,"recv_ms":1786845515943,"raw":{"event_type":"price_change","market":"0xd5f15f31689703aea70b93a52194a0964220d10d92ee7497346f146a8b6ef8ab","price_changes":[{"asset_id":"2151378744569768920256500242561922410292857798164019061749528550808091180185","best_ask":"0.83","best_bid":"0.82","hash":"65a31a0eb38466ba7aaed493689ee84d8681605a","price":"0.01","side":"BUY","size":"5863.53"},{"asset_id":"17406866367975599232214757606801140480252276357934486651183783311435802862074","best_ask":"0.18","best_bid":"0.17","hash":"2cdf0fc72b8b537fd06ea56a54d00e8669139a20","price":"0.99","side":"SELL","size":"5863.53"}],"timestamp":"1786845515715"}}
{"f":204,"recv_ms":1786845515946,"raw":{"event_type":"price_change","market":"0x0c33f1586ca3445a41be2863746ffb0edc32df6500f4926657b2643fe8a78258","price_changes":[{"asset_id":"84378280634731141017197924889292000863571415141565530467641465700960218022429","best_ask":"0.47","best_bid":"0.46","hash":"409bbc3267ccf6d7b65af86b132028acf4f4a7c5","price":"0.46","side":"BUY","size":"15"},{"asset_id":"45654842686110167876337056449737479301235917003519988189654649607054904571464","best_ask":"0.54","best_bid":"0.53","hash":"e4df32e1444e68f824cc1e009e8b2551e71b2abe","price":"0.54","side":"SELL","size":"15"}],"timestamp":"1786845515733"}}
{"f":205,"recv_ms":1786845515967,"raw":{"event_type":"price_change","market":"0xd5f15f31689703aea70b93a52194a0964220d10d92ee7497346f146a8b6ef8ab","price_changes":[{"asset_id":"2151378744569768920256500242561922410292857798164019061749528550808091180185","best_ask":"0.83","best_bid":"0.82","hash":"8b502aa9bbfe89db696fa0961370258297efb293","price":"0.01","side":"BUY","size":"5857.53"},{"asset_id":"17406866367975599232214757606801140480252276357934486651183783311435802862074","best_ask":"0.18","best_bid":"0.17","hash":"85c8723234d6073581c32aae738e806eb6c2644f","price":"0.99","side":"SELL","size":"5857.53"}],"timestamp":"1786845515750"}}
{"f":206,"recv_ms":1786845515967,"raw":{"event_type":"price_change","market":"0xd5f15f31689703aea70b93a52194a0964220d10d92ee7497346f146a8b6ef8ab","price_changes":[{"asset_id":"2151378744569768920256500242561922410292857798164019061749528550808091180185","best_ask":"0.83","best_bid":"0.82","hash":"47f4c7ee42ff13b832708093df6f5559222796c6","price":"0.01","side":"BUY","size":"5852.53"},{"asset_id":"17406866367975599232214757606801140480252276357934486651183783311435802862074","best_ask":"0.18","best_bid":"0.17","hash":"9fc8388188239de69cfc97b4cfbb00ef7673850a","price":"0.99","side":"SELL","size":"5852.53"}],"timestamp":"1786845515751"}}
{"f":207,"recv_ms":1786845515967,"raw":{"event_type":"price_change","market":"0xd5f15f31689703aea70b93a52194a0964220d10d92ee7497346f146a8b6ef8ab","price_changes":[{"asset_id":"17406866367975599232214757606801140480252276357934486651183783311435802862074","best_ask":"0.18","best_bid":"0.17","hash":"27c7d53f248ff57e2807fd5460b34eb88e6b59c7","price":"0.1","side":"BUY","size":"96"},{"asset_id":"2151378744569768920256500242561922410292857798164019061749528550808091180185","best_ask":"0.83","best_bid":"0.82","hash":"ced073a10804248bc365a575f317ad5bd452e4d9","price":"0.9","side":"SELL","size":"96"}],"timestamp":"1786845515755"}}
{"f":208,"recv_ms":1786845515976,"raw":{"event_type":"price_change","market":"0xd5f15f31689703aea70b93a52194a0964220d10d92ee7497346f146a8b6ef8ab","price_changes":[{"asset_id":"2151378744569768920256500242561922410292857798164019061749528550808091180185","best_ask":"0.83","best_bid":"0.82","hash":"4516f8e1d60acb3d4ecaceca3d934bc447170da7","price":"0.01","side":"BUY","size":"5857.54"},{"asset_id":"17406866367975599232214757606801140480252276357934486651183783311435802862074","best_ask":"0.18","best_bid":"0.17","hash":"93e17d3823f7e2bfcd3cf3839ba166c7fb72929a","price":"0.99","side":"SELL","size":"5857.54"}],"timestamp":"1786845515756"}}
{"f":209,"recv_ms":1786845515994,"raw":{"event_type":"price_change","market":"0xd5f15f31689703aea70b93a52194a0964220d10d92ee7497346f146a8b6ef8ab","price_changes":[{"asset_id":"2151378744569768920256500242561922410292857798164019061749528550808091180185","best_ask":"0.83","best_bid":"0.82","hash":"92fe70346828f1a6a9135283d95119dc84937021","price":"0.01","side":"BUY","size":"5957.54"},{"asset_id":"17406866367975599232214757606801140480252276357934486651183783311435802862074","best_ask":"0.18","best_bid":"0.17","hash":"c7f7f57b0b808cc1ac30407ba1a1d871653f0332","price":"0.99","side":"SELL","size":"5957.54"}],"timestamp":"1786845515773"}}
{"f":210,"recv_ms":1786845516004,"raw":{"event_type":"price_change","market":"0xd5f15f31689703aea70b93a52194a0964220d10d92ee7497346f146a8b6ef8ab","price_changes":[{"asset_id":"2151378744569768920256500242561922410292857798164019061749528550808091180185","best_ask":"0.83","best_bid":"0.82","hash":"1b5cee4e667c4b66de68af3f1a417668ea1de8c0","price":"0.01","side":"BUY","size":"5952.53"},{"asset_id":"17406866367975599232214757606801140480252276357934486651183783311435802862074","best_ask":"0.18","best_bid":"0.17","hash":"cf4329ef1dcd6cffdc082d70576d8ce4aa7d829f","price":"0.99","side":"SELL","size":"5952.53"}],"timestamp":"1786845515783"}}
{"f":211,"recv_ms":1786845516004,"raw":{"event_type":"price_change","market":"0xd5f15f31689703aea70b93a52194a0964220d10d92ee7497346f146a8b6ef8ab","price_changes":[{"asset_id":"2151378744569768920256500242561922410292857798164019061749528550808091180185","best_ask":"0.83","best_bid":"0.82","hash":"e6f944934f481dd93379d39f62d8ab452ca96dfe","price":"0.01","side":"BUY","size":"5957.53"},{"asset_id":"17406866367975599232214757606801140480252276357934486651183783311435802862074","best_ask":"0.18","best_bid":"0.17","hash":"8161022f348dd2967f6d0db15b663be1e95abef0","price":"0.99","side":"SELL","size":"5957.53"}],"timestamp":"1786845515791"}}
{"f":212,"recv_ms":1786845516024,"raw":{"event_type":"price_change","market":"0xd5f15f31689703aea70b93a52194a0964220d10d92ee7497346f146a8b6ef8ab","price_changes":[{"asset_id":"2151378744569768920256500242561922410292857798164019061749528550808091180185","best_ask":"0.83","best_bid":"0.82","hash":"d171e0aafae70fcf41b49d9f7a79f3825053fd40","price":"0.01","side":"BUY","size":"5857.53"},{"asset_id":"17406866367975599232214757606801140480252276357934486651183783311435802862074","best_ask":"0.18","best_bid":"0.17","hash":"91f39d8bb5f839e176220fd9763b24d86e5efdd8","price":"0.99","side":"SELL","size":"5857.53"}],"timestamp":"1786845515803"}}
{"f":213,"recv_ms":1786845516030,"raw":{"event_type":"price_change","market":"0xd5f15f31689703aea70b93a52194a0964220d10d92ee7497346f146a8b6ef8ab","price_changes":[{"asset_id":"2151378744569768920256500242561922410292857798164019061749528550808091180185","best_ask":"0.83","best_bid":"0.82","hash":"9a65008cc9c8291b04c64bb97a5fb3a6ef2f02a2","price":"0.01","side":"BUY","size":"5863.53"},{"asset_id":"17406866367975599232214757606801140480252276357934486651183783311435802862074","best_ask":"0.18","best_bid":"0.17","hash":"2e88e4b3d1a72ebcf06bb957cb838a3393c031a8","price":"0.99","side":"SELL","size":"5863.53"}],"timestamp":"1786845515813"}}
{"f":214,"recv_ms":1786845516030,"raw":{"event_type":"price_change","market":"0xd5f15f31689703aea70b93a52194a0964220d10d92ee7497346f146a8b6ef8ab","price_changes":[{"asset_id":"2151378744569768920256500242561922410292857798164019061749528550808091180185","best_ask":"0.83","best_bid":"0.82","hash":"4089135132168b9c5dcc49d44dc5e5d2f6a684c5","price":"0.01","side":"BUY","size":"5868.53"},{"asset_id":"17406866367975599232214757606801140480252276357934486651183783311435802862074","best_ask":"0.18","best_bid":"0.17","hash":"2947596ba02838e7f003e2ed200c00b487e85d8e","price":"0.99","side":"SELL","size":"5868.53"}],"timestamp":"1786845515817"}}
{"f":215,"recv_ms":1786845516030,"raw":{"event_type":"price_change","market":"0xd5f15f31689703aea70b93a52194a0964220d10d92ee7497346f146a8b6ef8ab","price_changes":[{"asset_id":"2151378744569768920256500242561922410292857798164019061749528550808091180185","best_ask":"0.83","best_bid":"0.82","hash":"e81f5d6e7977a7ab523c5072d05cbe6af24240eb","price":"0.02","side":"BUY","size":"3116.85"},{"asset_id":"17406866367975599232214757606801140480252276357934486651183783311435802862074","best_ask":"0.18","best_bid":"0.17","hash":"37ab0f2374abccfece1c7575b765c3a673eb2a72","price":"0.98","side":"SELL","size":"3116.85"}],"timestamp":"1786845515818"}}
{"f":216,"recv_ms":1786845516033,"raw":{"event_type":"price_change","market":"0xd5f15f31689703aea70b93a52194a0964220d10d92ee7497346f146a8b6ef8ab","price_changes":[{"asset_id":"2151378744569768920256500242561922410292857798164019061749528550808091180185","best_ask":"0.83","best_bid":"0.82","hash":"cbe0b79d2a2c2778f564c84010e502ac18c0104d","price":"0.01","side":"BUY","size":"5768.53"},{"asset_id":"17406866367975599232214757606801140480252276357934486651183783311435802862074","best_ask":"0.18","best_bid":"0.17","hash":"4a5f2a3d8501fc07868be58b6535a24467e59bb4","price":"0.99","side":"SELL","size":"5768.53"}],"timestamp":"1786845515818"}}
{"f":217,"recv_ms":1786845516034,"raw":{"event_type":"price_change","market":"0xd5f15f31689703aea70b93a52194a0964220d10d92ee7497346f146a8b6ef8ab","price_changes":[{"asset_id":"2151378744569768920256500242561922410292857798164019061749528550808091180185","best_ask":"0.83","best_bid":"0.82","hash":"fe52609b04b77667dc59d132627400cd7d95a6ca","price":"0.01","side":"BUY","size":"5763.53"},{"asset_id":"17406866367975599232214757606801140480252276357934486651183783311435802862074","best_ask":"0.18","best_bid":"0.17","hash":"00d2052613cb8d3de374d1c514c883184ec03737","price":"0.99","side":"SELL","size":"5763.53"}],"timestamp":"1786845515819"}}
{"f":218,"recv_ms":1786845516034,"raw":{"event_type":"price_change","market":"0xd5f15f31689703aea70b93a52194a0964220d10d92ee7497346f146a8b6ef8ab","price_changes":[{"asset_id":"17406866367975599232214757606801140480252276357934486651183783311435802862074","best_ask":"0.18","best_bid":"0.17","hash":"185118b454bf0491f2d0b5a7c72f6d7b968cf192","price":"0.17","side":"BUY","size":"136.1"},{"asset_id":"2151378744569768920256500242561922410292857798164019061749528550808091180185","best_ask":"0.83","best_bid":"0.82","hash":"2e29347a914ded0555f0381215cd0a6a17bef595","price":"0.83","side":"SELL","size":"136.1"}],"timestamp":"1786845515820"}}
{"f":219,"recv_ms":1786845516036,"raw":{"event_type":"price_change","market":"0xd5f15f31689703aea70b93a52194a0964220d10d92ee7497346f146a8b6ef8ab","price_changes":[{"asset_id":"17406866367975599232214757606801140480252276357934486651183783311435802862074","best_ask":"0.18","best_bid":"0.17","hash":"2df7bf688c396876cfc084b70d1e535ac7be0063","price":"0.02","side":"BUY","size":"1792.69"},{"asset_id":"2151378744569768920256500242561922410292857798164019061749528550808091180185","best_ask":"0.83","best_bid":"0.82","hash":"717c014b20f408a9a68c08db9fc812f18d97bfad","price":"0.98","side":"SELL","size":"1792.69"}],"timestamp":"1786845515824"}}
{"f":220,"recv_ms":1786845516041,"raw":{"event_type":"price_change","market":"0xd5f15f31689703aea70b93a52194a0964220d10d92ee7497346f146a8b6ef8ab","price_changes":[{"asset_id":"2151378744569768920256500242561922410292857798164019061749528550808091180185","best_ask":"0.83","best_bid":"0.82","hash":"bba027eb17dcd05c4ee67fe0b8a2127a2b2db966","price":"0.01","side":"BUY","size":"5758.53"},{"asset_id":"17406866367975599232214757606801140480252276357934486651183783311435802862074","best_ask":"0.18","best_bid":"0.17","hash":"eb96ba0a9a5757c431d3af3abcd178ad3c282afd","price":"0.99","side":"SELL","size":"5758.53"}],"timestamp":"1786845515825"}}
{"f":221,"recv_ms":1786845516041,"raw":{"event_type":"price_change","market":"0xd5f15f31689703aea70b93a52194a0964220d10d92ee7497346f146a8b6ef8ab","price_changes":[{"asset_id":"2151378744569768920256500242561922410292857798164019061749528550808091180185","best_ask":"0.83","best_bid":"0.82","hash":"9b4876aca28e82010c67ba2c907e3c82f24920e7","price":"0.01","side":"BUY","size":"5753.53"},{"asset_id":"17406866367975599232214757606801140480252276357934486651183783311435802862074","best_ask":"0.18","best_bid":"0.17","hash":"a305e0b295b573f4f58f3a8ccb8c8b7e69608fc0","price":"0.99","side":"SELL","size":"5753.53"}],"timestamp":"1786845515825"}}
{"f":222,"recv_ms":1786845516041,"raw":{"event_type":"price_change","market":"0xd5f15f31689703aea70b93a52194a0964220d10d92ee7497346f146a8b6ef8ab","price_changes":[{"asset_id":"2151378744569768920256500242561922410292857798164019061749528550808091180185","best_ask":"0.83","best_bid":"0.82","hash":"04e58d58e7505bc6e7af4c84bd052622a257c9a6","price":"0.52","side":"BUY","size":"140"},{"asset_id":"17406866367975599232214757606801140480252276357934486651183783311435802862074","best_ask":"0.18","best_bid":"0.17","hash":"52ed734ae54c7b5864c2b3e2e7e61cd378f6770d","price":"0.48","side":"SELL","size":"140"}],"timestamp":"1786845515825"}}
{"f":223,"recv_ms":1786845516041,"raw":{"event_type":"price_change","market":"0xd5f15f31689703aea70b93a52194a0964220d10d92ee7497346f146a8b6ef8ab","price_changes":[{"asset_id":"2151378744569768920256500242561922410292857798164019061749528550808091180185","best_ask":"0.83","best_bid":"0.82","hash":"d6043f75b7b54f65bc12f374cf853407ecf37d93","price":"0.05","side":"BUY","size":"708.3"},{"asset_id":"17406866367975599232214757606801140480252276357934486651183783311435802862074","best_ask":"0.18","best_bid":"0.17","hash":"59b92d22f81a9acd0dd8b765534a0aaacb138a25","price":"0.95","side":"SELL","size":"708.3"}],"timestamp":"1786845515827"}}
{"f":224,"recv_ms":1786845516058,"raw":{"event_type":"price_change","market":"0xd5f15f31689703aea70b93a52194a0964220d10d92ee7497346f146a8b6ef8ab","price_changes":[{"asset_id":"2151378744569768920256500242561922410292857798164019061749528550808091180185","best_ask":"0.83","best_bid":"0.82","hash":"8de3f4931668e55677126e20adc957a19f133b3d","price":"0.01","side":"BUY","size":"5758.53"},{"asset_id":"17406866367975599232214757606801140480252276357934486651183783311435802862074","best_ask":"0.18","best_bid":"0.17","hash":"7b2d9073bd8f707436ce9da88cdfe7f3f6b02e18","price":"0.99","side":"SELL","size":"5758.53"}],"timestamp":"1786845515829"}}
{"f":225,"recv_ms":1786845516058,"raw":{"event_type":"price_change","market":"0xd5f15f31689703aea70b93a52194a0964220d10d92ee7497346f146a8b6ef8ab","price_changes":[{"asset_id":"2151378744569768920256500242561922410292857798164019061749528550808091180185","best_ask":"0.83","best_bid":"0.82","hash":"96ed71ac37cb940b6c88412081ec793fd7560bfc","price":"0.71","side":"BUY","size":"5"},{"asset_id":"17406866367975599232214757606801140480252276357934486651183783311435802862074","best_ask":"0.18","best_bid":"0.17","hash":"e62f766ced41ee78349194e4377927bbc09bbbdd","price":"0.29","side":"SELL","size":"5"}],"timestamp":"1786845515832"}}
{"f":226,"recv_ms":1786845516063,"raw":{"event_type":"price_change","market":"0xd5f15f31689703aea70b93a52194a0964220d10d92ee7497346f146a8b6ef8ab","price_changes":[{"asset_id":"2151378744569768920256500242561922410292857798164019061749528550808091180185","best_ask":"0.83","best_bid":"0.82","hash":"7f248e5ac57d848741bf85ec26d02eb4dc6d50e9","price":"0.01","side":"BUY","size":"5752.53"},{"asset_id":"17406866367975599232214757606801140480252276357934486651183783311435802862074","best_ask":"0.18","best_bid":"0.17","hash":"105d44be34b199d2086fee6678151fade573feb9","price":"0.99","side":"SELL","size":"5752.53"}],"timestamp":"1786845515845"}}
{"f":227,"recv_ms":1786845516063,"raw":{"event_type":"price_change","market":"0xd5f15f31689703aea70b93a52194a0964220d10d92ee7497346f146a8b6ef8ab","price_changes":[{"asset_id":"2151378744569768920256500242561922410292857798164019061749528550808091180185","best_ask":"0.83","best_bid":"0.82","hash":"4ff99264d9a488dda8059e77efb86fb65d5b4ccc","price":"0.64","side":"BUY","size":"252.13"},{"asset_id":"17406866367975599232214757606801140480252276357934486651183783311435802862074","best_ask":"0.18","best_bid":"0.17","hash":"9befd9a5147d1de02aed088f6b4086850d4126ac","price":"0.36","side":"SELL","size":"252.13"}],"timestamp":"1786845515850"}}
{"f":228,"recv_ms":1786845516063,"raw":{"event_type":"price_change","market":"0xd5f15f31689703aea70b93a52194a0964220d10d92ee7497346f146a8b6ef8ab","price_changes":[{"asset_id":"2151378744569768920256500242561922410292857798164019061749528550808091180185","best_ask":"0.83","best_bid":"0.82","hash":"3010cba0852da1aa3e273cb090381f1c9c78faf3","price":"0.64","side":"BUY","size":"262.13"},{"asset_id":"17406866367975599232214757606801140480252276357934486651183783311435802862074","best_ask":"0.18","best_bid":"0.17","hash":"48d96bc90a5c44cbf6028c49a10e5d148ade54d1","price":"0.36","side":"SELL","size":"262.13"}],"timestamp":"1786845515851"}}
{"f":229,"recv_ms":1786845516065,"raw":{"event_type":"price_change","market":"0xd5f15f31689703aea70b93a52194a0964220d10d92ee7497346f146a8b6ef8ab","price_changes":[{"asset_id":"2151378744569768920256500242561922410292857798164019061749528550808091180185","best_ask":"0.83","best_bid":"0.82","hash":"087a255c7c24e460f7374c54db9bab3aa80fa865","price":"0.01","side":"BUY","size":"5852.53"},{"asset_id":"17406866367975599232214757606801140480252276357934486651183783311435802862074","best_ask":"0.18","best_bid":"0.17","hash":"d3ca12599d8757bf8982709a8b01beea981b1ac3","price":"0.99","side":"SELL","size":"5852.53"}],"timestamp":"1786845515854"}}
{"f":230,"recv_ms":1786845516071,"raw":{"event_type":"price_change","market":"0xd5f15f31689703aea70b93a52194a0964220d10d92ee7497346f146a8b6ef8ab","price_changes":[{"asset_id":"2151378744569768920256500242561922410292857798164019061749528550808091180185","best_ask":"0.83","best_bid":"0.82","hash":"8af7a3a1456b2ce985633a730ea9c4b0a946a260","price":"0.01","side":"BUY","size":"5857.53"},{"asset_id":"17406866367975599232214757606801140480252276357934486651183783311435802862074","best_ask":"0.18","best_bid":"0.17","hash":"a3b503e8622f8074150674a8169020246487de00","price":"0.99","side":"SELL","size":"5857.53"}],"timestamp":"1786845515855"}}
{"f":231,"recv_ms":1786845516071,"raw":{"event_type":"price_change","market":"0xd5f15f31689703aea70b93a52194a0964220d10d92ee7497346f146a8b6ef8ab","price_changes":[{"asset_id":"2151378744569768920256500242561922410292857798164019061749528550808091180185","best_ask":"0.83","best_bid":"0.82","hash":"0785dcadeb9e7ce8f516bb3c5e200c92a9f4cfb2","price":"0.01","side":"BUY","size":"5862.53"},{"asset_id":"17406866367975599232214757606801140480252276357934486651183783311435802862074","best_ask":"0.18","best_bid":"0.17","hash":"0417e70fab18301cd03d1040aed6e9dea19cc300","price":"0.99","side":"SELL","size":"5862.53"}],"timestamp":"1786845515856"}}
{"f":232,"recv_ms":1786845516093,"raw":{"event_type":"price_change","market":"0xd5f15f31689703aea70b93a52194a0964220d10d92ee7497346f146a8b6ef8ab","price_changes":[{"asset_id":"2151378744569768920256500242561922410292857798164019061749528550808091180185","best_ask":"0.83","best_bid":"0.82","hash":"a4bbd4ebd5cfd5fba0c4c2b0c4e83744b3d3e775","price":"0.01","side":"BUY","size":"5867.53"},{"asset_id":"17406866367975599232214757606801140480252276357934486651183783311435802862074","best_ask":"0.18","best_bid":"0.17","hash":"88a89be906f8ef6eab6fd4d5b223ff01aba0a2f9","price":"0.99","side":"SELL","size":"5867.53"}],"timestamp":"1786845515857"}}
{"f":233,"recv_ms":1786845516093,"raw":{"event_type":"price_change","market":"0xd5f15f31689703aea70b93a52194a0964220d10d92ee7497346f146a8b6ef8ab","price_changes":[{"asset_id":"17406866367975599232214757606801140480252276357934486651183783311435802862074","best_ask":"0.18","best_bid":"0.17","hash":"863a7c30f34e056ac4146aa5cbe48dad1ccfe686","price":"0.47","side":"SELL","size":"579.64"},{"asset_id":"2151378744569768920256500242561922410292857798164019061749528550808091180185","best_ask":"0.83","best_bid":"0.82","hash":"3c9980a9303c1143057445cd6c60b9c6ed42d74d","price":"0.53","side":"BUY","size":"579.64"}],"timestamp":"1786845515859"}}
{"f":234,"recv_ms":1786845516093,"raw":{"asset_id":"2151378744569768920256500242561922410292857798164019061749528550808091180185","event_type":"last_trade_price","fee_rate_bps":"0","market":"0xd5f15f31689703aea70b93a52194a0964220d10d92ee7497346f146a8b6ef8ab","price":"0.83","side":"BUY","size":"6","timestamp":"1786845515864","transaction_hash":"0x3fc6290a5a0cae4b7fd7d01289571081a9dcc3a37382429514a4edaa1012fd7c"}}
{"f":235,"recv_ms":1786845516094,"raw":{"event_type":"price_change","market":"0xd5f15f31689703aea70b93a52194a0964220d10d92ee7497346f146a8b6ef8ab","price_changes":[{"asset_id":"2151378744569768920256500242561922410292857798164019061749528550808091180185","best_ask":"0.83","best_bid":"0.82","hash":"9a775ad11e405ea6f20dce099932f2fc508c0aa2","price":"0.64","side":"BUY","size":"252.13"},{"asset_id":"17406866367975599232214757606801140480252276357934486651183783311435802862074","best_ask":"0.18","best_bid":"0.17","hash":"5fbe9d402c3a9820ef542f811981a1cf54aad31e","price":"0.36","side":"SELL","size":"252.13"}],"timestamp":"1786845515873"}}
{"f":236,"recv_ms":1786845516105,"raw":{"event_type":"price_change","market":"0xd5f15f31689703aea70b93a52194a0964220d10d92ee7497346f146a8b6ef8ab","price_changes":[{"asset_id":"17406866367975599232214757606801140480252276357934486651183783311435802862074","best_ask":"0.18","best_bid":"0.17","hash":"c6bf1bfe7b54fe7ba91e27d3ddd308eac894c27f","price":"0.02","side":"BUY","size":"1692.69"},{"asset_id":"2151378744569768920256500242561922410292857798164019061749528550808091180185","best_ask":"0.83","best_bid":"0.82","hash":"8bdc227370287231b9d6ca0678dcb957fc39b268","price":"0.98","side":"SELL","size":"1692.69"}],"timestamp":"1786845515884"}}
{"f":237,"recv_ms":1786845516112,"raw":{"event_type":"price_change","market":"0xd5f15f31689703aea70b93a52194a0964220d10d92ee7497346f146a8b6ef8ab","price_changes":[{"asset_id":"2151378744569768920256500242561922410292857798164019061749528550808091180185","best_ask":"0.83","best_bid":"0.82","hash":"09a9afe637e3f293ddc658fa48bd3569fcbc1ae9","price":"0.01","side":"BUY","size":"5862.53"},{"asset_id":"17406866367975599232214757606801140480252276357934486651183783311435802862074","best_ask":"0.18","best_bid":"0.17","hash":"9da8f23a2e3d027e405a3cfc469542a474b12626","price":"0.99","side":"SELL","size":"5862.53"}],"timestamp":"1786845515891"}}
{"f":238,"recv_ms":1786845516112,"raw":{"event_type":"price_change","market":"0xd5f15f31689703aea70b93a52194a0964220d10d92ee7497346f146a8b6ef8ab","price_changes":[{"asset_id":"2151378744569768920256500242561922410292857798164019061749528550808091180185","best_ask":"0.83","best_bid":"0.82","hash":"58924387e1bde3a2c93ccc6dc6c7cbc4b34ca68f","price":"0.01","side":"BUY","size":"5762.53"},{"asset_id":"17406866367975599232214757606801140480252276357934486651183783311435802862074","best_ask":"0.18","best_bid":"0.17","hash":"a0c0fa3ca3e721ee302bd6bc469b33122cba4b2e","price":"0.99","side":"SELL","size":"5762.53"}],"timestamp":"1786845515892"}}
{"f":239,"recv_ms":1786845516130,"raw":{"event_type":"price_change","market":"0xd5f15f31689703aea70b93a52194a0964220d10d92ee7497346f146a8b6ef8ab","price_changes":[{"asset_id":"2151378744569768920256500242561922410292857798164019061749528550808091180185","best_ask":"0.83","best_bid":"0.82","hash":"585964eee01234b2c08252b40563971b8c1edde0","price":"0.83","side":"SELL","size":"120.54"},{"asset_id":"17406866367975599232214757606801140480252276357934486651183783311435802862074","best_ask":"0.18","best_bid":"0.17","hash":"b3212bb9b54802d9218e997fe5f8f6287673a67d","price":"0.17","side":"BUY","size":"120.54"}],"timestamp":"1786845515897"}}
{"f":240,"recv_ms":1786845516130,"raw":{"event_type":"price_change","market":"0xd5f15f31689703aea70b93a52194a0964220d10d92ee7497346f146a8b6ef8ab","price_changes":[{"asset_id":"17406866367975599232214757606801140480252276357934486651183783311435802862074","best_ask":"0.18","best_bid":"0.17","hash":"b3212bb9b54802d9218e997fe5f8f6287673a67d","price":"0.17","side":"BUY","size":"120.54"},{"asset_id":"2151378744569768920256500242561922410292857798164019061749528550808091180185","best_ask":"0.83","best_bid":"0.82","hash":"585964eee01234b2c08252b40563971b8c1edde0","price":"0.83","side":"SELL","size":"120.54"}],"timestamp":"1786845515897"}}
{"f":241,"recv_ms":1786845516138,"raw":{"event_type":"price_change","market":"0xd5f15f31689703aea70b93a52194a0964220d10d92ee7497346f146a8b6ef8ab","price_changes":[{"asset_id":"2151378744569768920256500242561922410292857798164019061749528550808091180185","best_ask":"0.83","best_bid":"0.82","hash":"70d2bb817f89dafc2206ee0fa59080676a977ebe","price":"0.01","side":"BUY","size":"5768.53"},{"asset_id":"17406866367975599232214757606801140480252276357934486651183783311435802862074","best_ask":"0.18","best_bid":"0.17","hash":"e75e52d3d97ff52739006419024eee0792f7bf98","price":"0.99","side":"SELL","size":"5768.53"}],"timestamp":"1786845515918"}}
{"f":242,"recv_ms":1786845516153,"raw":{"event_type":"price_change","market":"0xd5f15f31689703aea70b93a52194a0964220d10d92ee7497346f146a8b6ef8ab","price_changes":[{"asset_id":"2151378744569768920256500242561922410292857798164019061749528550808091180185","best_ask":"0.83","best_bid":"0.82","hash":"8dbcfc2a3e48d46385630d64682b03e78b39b996","price":"0.01","side":"BUY","size":"5763.53"},{"asset_id":"17406866367975599232214757606801140480252276357934486651183783311435802862074","best_ask":"0.18","best_bid":"0.17","hash":"8874554c8eea1bfccce6bd8873a99dc2f9b19554","price":"0.99","side":"SELL","size":"5763.53"}],"timestamp":"1786845515927"}}
{"f":243,"recv_ms":1786845516153,"raw":{"event_type":"price_change","market":"0xd5f15f31689703aea70b93a52194a0964220d10d92ee7497346f146a8b6ef8ab","price_changes":[{"asset_id":"17406866367975599232214757606801140480252276357934486651183783311435802862074","best_ask":"0.18","best_bid":"0.17","hash":"f5956a1d414df17cf0665e2bf2ed2afdd868da84","price":"0.02","side":"BUY","size":"1792.69"},{"asset_id":"2151378744569768920256500242561922410292857798164019061749528550808091180185","best_ask":"0.83","best_bid":"0.82","hash":"bbf7e7e64e0fd22cd235d0036336761ae919aee7","price":"0.98","side":"SELL","size":"1792.69"}],"timestamp":"1786845515932"}}
{"f":244,"recv_ms":1786845516153,"raw":{"event_type":"price_change","market":"0xd5f15f31689703aea70b93a52194a0964220d10d92ee7497346f146a8b6ef8ab","price_changes":[{"asset_id":"2151378744569768920256500242561922410292857798164019061749528550808091180185","best_ask":"0.83","best_bid":"0.82","hash":"73e431244e02d45ff5786d949df71bf84a4e14fd","price":"0.01","side":"BUY","size":"5863.53"},{"asset_id":"17406866367975599232214757606801140480252276357934486651183783311435802862074","best_ask":"0.18","best_bid":"0.17","hash":"6f9a9a7929e5e845da1d00b3d8a1ff08a466bcab","price":"0.99","side":"SELL","size":"5863.53"}],"timestamp":"1786845515935"}}
{"f":245,"recv_ms":1786845516154,"raw":{"event_type":"price_change","market":"0xd5f15f31689703aea70b93a52194a0964220d10d92ee7497346f146a8b6ef8ab","price_changes":[{"asset_id":"2151378744569768920256500242561922410292857798164019061749528550808091180185","best_ask":"0.83","best_bid":"0.82","hash":"aa07a084e8e47e16ed803adab2b108536ac2777e","price":"0.01","side":"BUY","size":"5857.53"},{"asset_id":"17406866367975599232214757606801140480252276357934486651183783311435802862074","best_ask":"0.18","best_bid":"0.17","hash":"cb9cd671a0e39cf01aa41d2f857437de757afcd1","price":"0.99","side":"SELL","size":"5857.53"}],"timestamp":"1786845515942"}}
{"f":246,"recv_ms":1786845516154,"raw":{"event_type":"price_change","market":"0xd5f15f31689703aea70b93a52194a0964220d10d92ee7497346f146a8b6ef8ab","price_changes":[{"asset_id":"2151378744569768920256500242561922410292857798164019061749528550808091180185","best_ask":"0.83","best_bid":"0.82","hash":"f297adb6ef38f5cacda64f67131f9dc2bd6268ed","price":"0.14","side":"BUY","size":"111.6"},{"asset_id":"17406866367975599232214757606801140480252276357934486651183783311435802862074","best_ask":"0.18","best_bid":"0.17","hash":"58cd687b4f962f216c3ccd94d99b1ca5158c11fb","price":"0.86","side":"SELL","size":"111.6"}],"timestamp":"1786845515942"}}
{"f":247,"recv_ms":1786845516154,"raw":{"event_type":"price_change","market":"0xd5f15f31689703aea70b93a52194a0964220d10d92ee7497346f146a8b6ef8ab","price_changes":[{"asset_id":"2151378744569768920256500242561922410292857798164019061749528550808091180185","best_ask":"0.83","best_bid":"0.82","hash":"7a4b1c770de91bdccc7093e5bb87a5ec67bb3cef","price":"0.12","side":"BUY","size":"119.6"},{"asset_id":"17406866367975599232214757606801140480252276357934486651183783311435802862074","best_ask":"0.18","best_bid":"0.17","hash":"dd6f909069ea6d35a5a51f3aa7a4fe220c363b31","price":"0.88","side":"SELL","size":"119.6"}],"timestamp":"1786845515942"}}
{"f":248,"recv_ms":1786845516155,"raw":{"event_type":"price_change","market":"0xd5f15f31689703aea70b93a52194a0964220d10d92ee7497346f146a8b6ef8ab","price_changes":[{"asset_id":"2151378744569768920256500242561922410292857798164019061749528550808091180185","best_ask":"0.83","best_bid":"0.82","hash":"eb4a139aa08e9eeadb5f8b534ec0a1df47a87512","price":"0.02","side":"BUY","size":"3825.18"},{"asset_id":"17406866367975599232214757606801140480252276357934486651183783311435802862074","best_ask":"0.18","best_bid":"0.17","hash":"321c09df9e147f4422afa1ff74c56629fcbd326d","price":"0.98","side":"SELL","size":"3825.18"}],"timestamp":"1786845515942"}}
{"f":249,"recv_ms":1786845516155,"raw":{"event_type":"price_change","market":"0xd5f15f31689703aea70b93a52194a0964220d10d92ee7497346f146a8b6ef8ab","price_changes":[{"asset_id":"2151378744569768920256500242561922410292857798164019061749528550808091180185","best_ask":"0.83","best_bid":"0.82","hash":"cbea128b8a4fff74b877dd0fdccef73fbbbf6a7a","price":"0.16","side":"BUY","size":"109.3"},{"asset_id":"17406866367975599232214757606801140480252276357934486651183783311435802862074","best_ask":"0.18","best_bid":"0.17","hash":"1368639ce41484e8f4edf4ae3df921135c605688","price":"0.84","side":"SELL","size":"109.3"}],"timestamp":"1786845515943"}}
{"f":250,"recv_ms":1786845516170,"raw":{"event_type":"price_change","market":"0xd5f15f31689703aea70b93a52194a0964220d10d92ee7497346f146a8b6ef8ab","price_changes":[{"asset_id":"2151378744569768920256500242561922410292857798164019061749528550808091180185","best_ask":"0.83","best_bid":"0.82","hash":"82a77d537a78be77730398b0f80975a751c25c5b","price":"0.2","side":"BUY","size":"54.1"},{"asset_id":"17406866367975599232214757606801140480252276357934486651183783311435802862074","best_ask":"0.18","best_bid":"0.17","hash":"6d41537eca9128054b1d72a71fc2b25bb903762a","price":"0.8","side":"SELL","size":"54.1"}],"timestamp":"1786845515944"}}
{"f":251,"recv_ms":1786845516170,"raw":{"event_type":"price_change","market":"0xd5f15f31689703aea70b93a52194a0964220d10d92ee7497346f146a8b6ef8ab","price_changes":[{"asset_id":"2151378744569768920256500242561922410292857798164019061749528550808091180185","best_ask":"0.83","best_bid":"0.82","hash":"dceddf1625eead90605b24b7587ce045db8470e7","price":"0.01","side":"BUY","size":"5852.53"},{"asset_id":"17406866367975599232214757606801140480252276357934486651183783311435802862074","best_ask":"0.18","best_bid":"0.17","hash":"a97129f883dbfa2cf54d38635792c4573c532819","price":"0.99","side":"SELL","size":"5852.53"}],"timestamp":"1786845515945"}}
{"f":252,"recv_ms":1786845516170,"raw":{"event_type":"price_change","market":"0xd5f15f31689703aea70b93a52194a0964220d10d92ee7497346f146a8b6ef8ab","price_changes":[{"asset_id":"2151378744569768920256500242561922410292857798164019061749528550808091180185","best_ask":"0.83","best_bid":"0.82","hash":"5d9dac540843b77cd32f8f499a371a68bf8280ca","price":"0.18","side":"BUY","size":"22.6"},{"asset_id":"17406866367975599232214757606801140480252276357934486651183783311435802862074","best_ask":"0.18","best_bid":"0.17","hash":"ba5661646ab9231023811e0f22fd025b47fd0a05","price":"0.82","side":"SELL","size":"22.6"}],"timestamp":"1786845515947"}}
{"f":253,"recv_ms":1786845516171,"raw":{"event_type":"price_change","market":"0xd5f15f31689703aea70b93a52194a0964220d10d92ee7497346f146a8b6ef8ab","price_changes":[{"asset_id":"2151378744569768920256500242561922410292857798164019061749528550808091180185","best_ask":"0.83","best_bid":"0.82","hash":"75018bfc9c31ef0531ec7e88bf4b2a058cc689d7","price":"0.01","side":"BUY","size":"5857.54"},{"asset_id":"17406866367975599232214757606801140480252276357934486651183783311435802862074","best_ask":"0.18","best_bid":"0.17","hash":"6ea7e790134d84bbe5e5d2f3d7f2af6dc90b270e","price":"0.99","side":"SELL","size":"5857.54"}],"timestamp":"1786845515955"}}
{"f":254,"recv_ms":1786845516182,"raw":{"event_type":"price_change","market":"0xd5f15f31689703aea70b93a52194a0964220d10d92ee7497346f146a8b6ef8ab","price_changes":[{"asset_id":"2151378744569768920256500242561922410292857798164019061749528550808091180185","best_ask":"0.83","best_bid":"0.82","hash":"51c2aa0b010822421753272a85eb69da248e5276","price":"0.05","side":"BUY","size":"762.3"},{"asset_id":"17406866367975599232214757606801140480252276357934486651183783311435802862074","best_ask":"0.18","best_bid":"0.17","hash":"125d0b64393253e6eca58ac06418ba4c9919e1eb","price":"0.95","side":"SELL","size":"762.3"}],"timestamp":"1786845515959"}}
{"f":255,"recv_ms":1786845516182,"raw":{"event_type":"price_change","market":"0xd5f15f31689703aea70b93a52194a0964220d10d92ee7497346f146a8b6ef8ab","price_changes":[{"asset_id":"17406866367975599232214757606801140480252276357934486651183783311435802862074","best_ask":"0.18","best_bid":"0.17","hash":"1a40064e1ed86f2f16802068074c9ecaf436b61f","price":"0.02","side":"BUY","size":"1867.69"},{"asset_id":"2151378744569768920256500242561922410292857798164019061749528550808091180185","best_ask":"0.83","best_bid":"0.82","hash":"58045e81e85c57e2c235fcbaff6d54c060571194","price":"0.98","side":"SELL","size":"1867.69"}],"timestamp":"1786845515965"}}
{"f":256,"recv_ms":1786845516195,"raw":{"event_type":"price_change","market":"0xd5f15f31689703aea70b93a52194a0964220d10d92ee7497346f146a8b6ef8ab","price_changes":[{"asset_id":"17406866367975599232214757606801140480252276357934486651183783311435802862074","best_ask":"0.18","best_bid":"0.17","hash":"9a32f04a9588659fe01c28a78e1be61c42e3775f","price":"0.16","side":"BUY","size":"43.33"},{"asset_id":"2151378744569768920256500242561922410292857798164019061749528550808091180185","best_ask":"0.83","best_bid":"0.82","hash":"6605e93b6fa0658f2af888781fb54313484e0d0b","price":"0.84","side":"SELL","size":"43.33"}],"timestamp":"1786845515966"}}
{"f":257,"recv_ms":1786845516195,"raw":{"event_type":"price_change","market":"0xd5f15f31689703aea70b93a52194a0964220d10d92ee7497346f146a8b6ef8ab","price_changes":[{"asset_id":"2151378744569768920256500242561922410292857798164019061749528550808091180185","best_ask":"0.83","best_bid":"0.82","hash":"17691850e4860fb44c458df20b85af1f9a0f0cb7","price":"0.01","side":"BUY","size":"5757.54"},{"asset_id":"17406866367975599232214757606801140480252276357934486651183783311435802862074","best_ask":"0.18","best_bid":"0.17","hash":"16a472ec1b7600ab3d3ace5f7d62853ee50f11c3","price":"0.99","side":"SELL","size":"5757.54"}],"timestamp":"1786845515976"}}
{"f":258,"recv_ms":1786845516200,"raw":{"event_type":"price_change","market":"0xd5f15f31689703aea70b93a52194a0964220d10d92ee7497346f146a8b6ef8ab","price_changes":[{"asset_id":"2151378744569768920256500242561922410292857798164019061749528550808091180185","best_ask":"0.83","best_bid":"0.82","hash":"eaac5f7ffa47ad181b9d38a1709fbb9322d62e9a","price":"0.01","side":"BUY","size":"5752.53"},{"asset_id":"17406866367975599232214757606801140480252276357934486651183783311435802862074","best_ask":"0.18","best_bid":"0.17","hash":"a037534349f6b4e13f8395d6282d88cd72463194","price":"0.99","side":"SELL","size":"5752.53"}],"timestamp":"1786845515982"}}
{"f":259,"recv_ms":1786845516229,"raw":{"event_type":"price_change","market":"0xd5f15f31689703aea70b93a52194a0964220d10d92ee7497346f146a8b6ef8ab","price_changes":[{"asset_id":"2151378744569768920256500242561922410292857798164019061749528550808091180185","best_ask":"0.83","best_bid":"0.82","hash":"f4d500bb69730ef7d6076a0359fc0fd4d51e83c4","price":"0.01","side":"BUY","size":"5758.53"},{"asset_id":"17406866367975599232214757606801140480252276357934486651183783311435802862074","best_ask":"0.18","best_bid":"0.17","hash":"4fe3a640173e046586b06951ea069a9e9bea92d5","price":"0.99","side":"SELL","size":"5758.53"}],"timestamp":"1786845516013"}}
{"f":260,"recv_ms":1786845516230,"raw":{"event_type":"price_change","market":"0xd5f15f31689703aea70b93a52194a0964220d10d92ee7497346f146a8b6ef8ab","price_changes":[{"asset_id":"17406866367975599232214757606801140480252276357934486651183783311435802862074","best_ask":"0.18","best_bid":"0.17","hash":"a0bf9a5527358f1afb04b70c843e13316ad0ba55","price":"0.01","side":"BUY","size":"5593.18"},{"asset_id":"2151378744569768920256500242561922410292857798164019061749528550808091180185","best_ask":"0.83","best_bid":"0.82","hash":"797caa895cdbc6e7cae797b2b1805c5e801ddd92","price":"0.99","side":"SELL","size":"5593.18"}],"timestamp":"1786845516018"}}
{"f":261,"recv_ms":1786845516234,"raw":{"event_type":"price_change","market":"0xd5f15f31689703aea70b93a52194a0964220d10d92ee7497346f146a8b6ef8ab","price_changes":[{"asset_id":"17406866367975599232214757606801140480252276357934486651183783311435802862074","best_ask":"0.18","best_bid":"0.17","hash":"5c8e3bdcb845360efab7a89400ed3ebb95c83535","price":"0.01","side":"BUY","size":"5598.18"},{"asset_id":"2151378744569768920256500242561922410292857798164019061749528550808091180185","best_ask":"0.83","best_bid":"0.82","hash":"5eb9a5a286a3b86143f3f6bec5380ac97ae4efc7","price":"0.99","side":"SELL","size":"5598.18"}],"timestamp":"1786845516019"}}
{"f":262,"recv_ms":1786845516250,"raw":{"event_type":"price_change","market":"0xd5f15f31689703aea70b93a52194a0964220d10d92ee7497346f146a8b6ef8ab","price_changes":[{"asset_id":"2151378744569768920256500242561922410292857798164019061749528550808091180185","best_ask":"0.83","best_bid":"0.82","hash":"1e2c56fd3a18af34d7fb6d5dc38b9eb655c8ce5a","price":"0.01","side":"BUY","size":"5763.53"},{"asset_id":"17406866367975599232214757606801140480252276357934486651183783311435802862074","best_ask":"0.18","best_bid":"0.17","hash":"dffcc1ab4076a963e02122ddf0264892fe2fe1df","price":"0.99","side":"SELL","size":"5763.53"}],"timestamp":"1786845516022"}}
{"f":263,"recv_ms":1786845516250,"raw":{"event_type":"price_change","market":"0xd5f15f31689703aea70b93a52194a0964220d10d92ee7497346f146a8b6ef8ab","price_changes":[{"asset_id":"17406866367975599232214757606801140480252276357934486651183783311435802862074","best_ask":"0.18","best_bid":"0.17","hash":"605f0bb1d865b3707ad803dca906c089322adc66","price":"0.01","side":"BUY","size":"5593.18"},{"asset_id":"2151378744569768920256500242561922410292857798164019061749528550808091180185","best_ask":"0.83","best_bid":"0.82","hash":"7708c401fca66c9491d442c719e42a1531cd61fe","price":"0.99","side":"SELL","size":"5593.18"}],"timestamp":"1786845516031"}}
{"f":264,"recv_ms":1786845516252,"raw":{"event_type":"price_change","market":"0xd5f15f31689703aea70b93a52194a0964220d10d92ee7497346f146a8b6ef8ab","price_changes":[{"asset_id":"17406866367975599232214757606801140480252276357934486651183783311435802862074","best_ask":"0.18","best_bid":"0.17","hash":"7c73d6ed805fbb72e4021d0c9c3b1659831a1763","price":"0.01","side":"BUY","size":"5598.18"},{"asset_id":"2151378744569768920256500242561922410292857798164019061749528550808091180185","best_ask":"0.83","best_bid":"0.82","hash":"44e26f63b5bf9a59094bf0ad03136c590fc5547d","price":"0.99","side":"SELL","size":"5598.18"}],"timestamp":"1786845516038"}}
{"f":265,"recv_ms":1786845516252,"raw":{"event_type":"price_change","market":"0xd5f15f31689703aea70b93a52194a0964220d10d92ee7497346f146a8b6ef8ab","price_changes":[{"asset_id":"17406866367975599232214757606801140480252276357934486651183783311435802862074","best_ask":"0.18","best_bid":"0.17","hash":"d3f33d7b1b610ee7b7518b2a89b46289cfa6a10d","price":"0.01","side":"BUY","size":"5603.18"},{"asset_id":"2151378744569768920256500242561922410292857798164019061749528550808091180185","best_ask":"0.83","best_bid":"0.82","hash":"ae21ecf735f939581a15b7bf6a9723d080d2e164","price":"0.99","side":"SELL","size":"5603.18"}],"timestamp":"1786845516039"}}
{"f":266,"recv_ms":1786845516252,"raw":{"event_type":"price_change","market":"0xd5f15f31689703aea70b93a52194a0964220d10d92ee7497346f146a8b6ef8ab","price_changes":[{"asset_id":"2151378744569768920256500242561922410292857798164019061749528550808091180185","best_ask":"0.83","best_bid":"0.82","hash":"dd8d85f5c5a65281999335b9125ab529221e4e87","price":"0.01","side":"BUY","size":"5863.53"},{"asset_id":"17406866367975599232214757606801140480252276357934486651183783311435802862074","best_ask":"0.18","best_bid":"0.17","hash":"de1f53461149d3656e6469e681bae994ea50a9d8","price":"0.99","side":"SELL","size":"5863.53"}],"timestamp":"1786845516040"}}
{"f":267,"recv_ms":1786845516252,"raw":{"event_type":"price_change","market":"0xd5f15f31689703aea70b93a52194a0964220d10d92ee7497346f146a8b6ef8ab","price_changes":[{"asset_id":"17406866367975599232214757606801140480252276357934486651183783311435802862074","best_ask":"0.18","best_bid":"0.17","hash":"fbe0c6b1b43c0a96133a828d06837e002969bf1e","price":"0.01","side":"BUY","size":"5598.18"},{"asset_id":"2151378744569768920256500242561922410292857798164019061749528550808091180185","best_ask":"0.83","best_bid":"0.82","hash":"a64738e25897eca9df06fd918fbd50a3ade18a21","price":"0.99","side":"SELL","size":"5598.18"}],"timestamp":"1786845516041"}}
{"f":268,"recv_ms":1786845516257,"raw":{"event_type":"price_change","market":"0xd5f15f31689703aea70b93a52194a0964220d10d92ee7497346f146a8b6ef8ab","price_changes":[{"asset_id":"17406866367975599232214757606801140480252276357934486651183783311435802862074","best_ask":"0.18","best_bid":"0.17","hash":"c7cafa9babd8c9bceecd261e1a9beec1ac7ea7fa","price":"0.01","side":"BUY","size":"5593.18"},{"asset_id":"2151378744569768920256500242561922410292857798164019061749528550808091180185","best_ask":"0.83","best_bid":"0.82","hash":"f1c8d31905a3911190721fd74303f276e4911074","price":"0.99","side":"SELL","size":"5593.18"}],"timestamp":"1786845516041"}}
{"f":269,"recv_ms":1786845516257,"raw":{"event_type":"price_change","market":"0xd5f15f31689703aea70b93a52194a0964220d10d92ee7497346f146a8b6ef8ab","price_changes":[{"asset_id":"2151378744569768920256500242561922410292857798164019061749528550808091180185","best_ask":"0.83","best_bid":"0.82","hash":"7a00a1bca143b83cabed833d523e7ddb09304afa","price":"0.01","side":"BUY","size":"5857.53"},{"asset_id":"17406866367975599232214757606801140480252276357934486651183783311435802862074","best_ask":"0.18","best_bid":"0.17","hash":"d9c4b15663e6e49a64796d2b2c9ca5c631b2f5f2","price":"0.99","side":"SELL","size":"5857.53"}],"timestamp":"1786845516043"}}
{"f":270,"recv_ms":1786845516260,"raw":{"event_type":"price_change","market":"0xd5f15f31689703aea70b93a52194a0964220d10d92ee7497346f146a8b6ef8ab","price_changes":[{"asset_id":"2151378744569768920256500242561922410292857798164019061749528550808091180185","best_ask":"0.83","best_bid":"0.82","hash":"aa2a3b612dd0511472d5d70c309ee59638d67ea9","price":"0.01","side":"BUY","size":"5852.53"},{"asset_id":"17406866367975599232214757606801140480252276357934486651183783311435802862074","best_ask":"0.18","best_bid":"0.17","hash":"02cda9edfe9f79beed424fcda455feff51722025","price":"0.99","side":"SELL","size":"5852.53"}],"timestamp":"1786845516046"}}
{"f":271,"recv_ms":1786845516289,"raw":{"event_type":"price_change","market":"0xd5f15f31689703aea70b93a52194a0964220d10d92ee7497346f146a8b6ef8ab","price_changes":[{"asset_id":"2151378744569768920256500242561922410292857798164019061749528550808091180185","best_ask":"0.83","best_bid":"0.82","hash":"86790e63cf89c7db1595453047f762f407035c2c","price":"0.01","side":"BUY","size":"5857.58"},{"asset_id":"17406866367975599232214757606801140480252276357934486651183783311435802862074","best_ask":"0.18","best_bid":"0.17","hash":"926131ebaba84497717045d1616289d6d587846d","price":"0.99","side":"SELL","size":"5857.58"}],"timestamp":"1786845516062"}}
{"f":272,"recv_ms":1786845516289,"raw":{"event_type":"price_change","market":"0xd5f15f31689703aea70b93a52194a0964220d10d92ee7497346f146a8b6ef8ab","price_changes":[{"asset_id":"2151378744569768920256500242561922410292857798164019061749528550808091180185","best_ask":"0.83","best_bid":"0.82","hash":"2e23ac3239447caa1c824ca464e67bb7f09a0d9f","price":"0.08","side":"BUY","size":"65.29"},{"asset_id":"17406866367975599232214757606801140480252276357934486651183783311435802862074","best_ask":"0.18","best_bid":"0.17","hash":"4461c30a5b9d39a0ce326727fa7ff6e44a8d1afb","price":"0.92","side":"SELL","size":"65.29"}],"timestamp":"1786845516078"}}
{"f":273,"recv_ms":1786845516292,"raw":{"event_type":"price_change","market":"0xd5f15f31689703aea70b93a52194a0964220d10d92ee7497346f146a8b6ef8ab","price_changes":[{"asset_id":"2151378744569768920256500242561922410292857798164019061749528550808091180185","best_ask":"0.83","best_bid":"0.82","hash":"ce568e56372f3ec8a54353b20e0be0596c2d6128","price":"0.03","side":"BUY","size":"742.3"},{"asset_id":"17406866367975599232214757606801140480252276357934486651183783311435802862074","best_ask":"0.18","best_bid":"0.17","hash":"157268a5135e79d31d5a0c1060d2e50b99294f17","price":"0.97","side":"SELL","size":"742.3"}],"timestamp":"1786845516079"}}
