{"f":898,"recv_ms":1786845519851,"raw":{"event_type":"price_change","market":"0xd5f15f31689703aea70b93a52194a0964220d10d92ee7497346f146a8b6ef8ab","price_changes":[{"asset_id":"2151378744569768920256500242561922410292857798164019061749528550808091180185","best_ask":"0.86","best_bid":"0.85","hash":"7c06513fe25bf91225ad73bbf87a52712669a585","price":"0.84","side":"BUY","size":"233.74"},{"asset_id":"17406866367975599232214757606801140480252276357934486651183783311435802862074","best_ask":"0.15","best_bid":"0.14","hash":"0be355ba6ec14e75f69e53d5f95c0027d4001301","price":"0.16","side":"SELL","size":"233.74"}],"timestamp":"1786845519600"}}
{"f":899,"recv_ms":1786845519851,"raw":{"event_type":"price_change","market":"0xd5f15f31689703aea70b93a52194a0964220d10d92ee7497346f146a8b6ef8ab","price_changes":[{"asset_id":"17406866367975599232214757606801140480252276357934486651183783311435802862074","best_ask":"0.15","best_bid":"0.14","hash":"7009ba89f4fbb1d19105e563672b2a09487419a5","price":"0.02","side":"BUY","size":"1842.69"},{"asset_id":"2151378744569768920256500242561922410292857798164019061749528550808091180185","best_ask":"0.86","best_bid":"0.85","hash":"9d8ee24963d950d23f7c76b1981ce2110833c3ac","price":"0.98","side":"SELL","size":"1842.69"}],"timestamp":"1786845519601"}}
{"f":900,"recv_ms":1786845519851,"raw":{"event_type":"price_change","market":"0xd5f15f31689703aea70b93a52194a0964220d10d92ee7497346f146a8b6ef8ab","price_changes":[{"asset_id":"2151378744569768920256500242561922410292857798164019061749528550808091180185","best_ask":"0.86","best_bid":"0.85","hash":"79368c2fea0dfaf5be51b2475f072f035fb8dfa5","price":"0.85","side":"BUY","size":"143.82"},{"asset_id":"17406866367975599232214757606801140480252276357934486651183783311435802862074","best_ask":"0.15","best_bid":"0.14","hash":"38ff95d16c81deddbfcebc17aa832b2301a70017","price":"0.15","side":"SELL","size":"143.82"}],"timestamp":"1786845519602"}}
{"f":901,"recv_ms":1786845519851,"raw":{"event_type":"price_change","market":"0xd5f15f31689703aea70b93a52194a0964220d10d92ee7497346f146a8b6ef8ab","price_changes":[{"asset_id":"2151378744569768920256500242561922410292857798164019061749528550808091180185","best_ask":"0.86","best_bid":"0.85","hash":"44f3c85c7d73f0b094d9097953ebb5f1d66e0be1","price":"0.01","side":"BUY","size":"5872.54"},{"asset_id":"17406866367975599232214757606801140480252276357934486651183783311435802862074","best_ask":"0.15","best_bid":"0.14","hash":"e2989faa8eac9bb6c617b0361d11520da578a561","price":"0.99","side":"SELL","size":"5872.54"}],"timestamp":"1786845519603"}}
{"f":902,"recv_ms":1786845519851,"raw":{"event_type":"price_change","market":"0xd5f15f31689703aea70b93a52194a0964220d10d92ee7497346f146a8b6ef8ab","price_changes":[{"asset_id":"2151378744569768920256500242561922410292857798164019061749528550808091180185","best_ask":"0.86","best_bid":"0.85","hash":"f7d5181f51ad22bbd69b77cadd65b27e90f3fdd5","price":"0.83","side":"BUY","size":"197.93"},{"asset_id":"17406866367975599232214757606801140480252276357934486651183783311435802862074","best_ask":"0.15","best_bid":"0.14","hash":"974eb515bdf2eb5331195b143c8cc9c7ff037cd8","price":"0.17","side":"SELL","size":"197.93"}],"timestamp":"1786845519604"}}
{"f":903,"recv_ms":1786845519851,"raw":{"event_type":"price_change","market":"0xd5f15f31689703aea70b93a52194a0964220d10d92ee7497346f146a8b6ef8ab","price_changes":[{"asset_id":"17406866367975599232214757606801140480252276357934486651183783311435802862074","best_ask":"0.15","best_bid":"0.14","hash":"4a3e67b508e02a3c81041b251e7989278c9a5a16","price":"0.17","side":"SELL","size":"185.93"},{"asset_id":"2151378744569768920256500242561922410292857798164019061749528550808091180185","best_ask":"0.86","best_bid":"0.85","hash":"358c9865eb2485c8fca3c85dc49c1a082f394938","price":"0.83","side":"BUY","size":"185.93"}],"timestamp":"1786845519604"}}
{"f":904,"recv_ms":1786845519851,"raw":{"event_type":"price_change","market":"0xd5f15f31689703aea70b93a52194a0964220d10d92ee7497346f146a8b6ef8ab","price_changes":[{"asset_id":"17406866367975599232214757606801140480252276357934486651183783311435802862074","best_ask":"0.15","best_bid":"0.14","hash":"b29d84945174aeb350ec086582fa0c1bfcb0d087","price":"0.15","side":"SELL","size":"153.1"},{"asset_id":"2151378744569768920256500242561922410292857798164019061749528550808091180185","best_ask":"0.86","best_bid":"0.85","hash":"bedd9f82dfe8d93c8d6b3ff080e09dd31b876ab9","price":"0.85","side":"BUY","size":"153.1"}],"timestamp":"1786845519604"}}
{"f":905,"recv_ms":1786845519852,"raw":{"event_type":"price_change","market":"0xd5f15f31689703aea70b93a52194a0964220d10d92ee7497346f146a8b6ef8ab","price_changes":[{"asset_id":"2151378744569768920256500242561922410292857798164019061749528550808091180185","best_ask":"0.86","best_bid":"0.85","hash":"4a498f5a7f9c5b3e1653311ab6f27c7c353a26f9","price":"0.47","side":"BUY","size":"252.23"},{"asset_id":"17406866367975599232214757606801140480252276357934486651183783311435802862074","best_ask":"0.15","best_bid":"0.14","hash":"1a9b333aa5bff2af8ccfe6504b4c97c2727133eb","price":"0.53","side":"SELL","size":"252.23"}],"timestamp":"1786845519605"}}
{"f":906,"recv_ms":1786845519852,"raw":{"event_type":"price_change","market":"0xd5f15f31689703aea70b93a52194a0964220d10d92ee7497346f146a8b6ef8ab","price_changes":[{"asset_id":"2151378744569768920256500242561922410292857798164019061749528550808091180185","best_ask":"0.86","best_bid":"0.85","hash":"649f00ee2a8a43de323b01d11c294d09328c85c6","price":"0.74","side":"BUY","size":"0"},{"asset_id":"17406866367975599232214757606801140480252276357934486651183783311435802862074","best_ask":"0.15","best_bid":"0.14","hash":"f1c45be499138870972eeeb9a65fe701446a21de","price":"0.26","side":"SELL","size":"0"}],"timestamp":"1786845519606"}}
{"f":907,"recv_ms":1786845519852,"raw":{"event_type":"price_change","market":"0xd5f15f31689703aea70b93a52194a0964220d10d92ee7497346f146a8b6ef8ab","price_changes":[{"asset_id":"17406866367975599232214757606801140480252276357934486651183783311435802862074","best_ask":"0.15","best_bid":"0.14","hash":"b4346a39389d2a21cb13c9eb8bd7283ea7e9c5ef","price":"0.17","side":"SELL","size":"175.93"},{"asset_id":"2151378744569768920256500242561922410292857798164019061749528550808091180185","best_ask":"0.86","best_bid":"0.85","hash":"696f1d93ed66479a05df6391306bfaa6fe3a429e","price":"0.83","side":"BUY","size":"175.93"}],"timestamp":"1786845519607"}}
{"f":908,"recv_ms":1786845519852,"raw":{"event_type":"price_change","market":"0xd5f15f31689703aea70b93a52194a0964220d10d92ee7497346f146a8b6ef8ab","price_changes":[{"asset_id":"17406866367975599232214757606801140480252276357934486651183783311435802862074","best_ask":"0.15","best_bid":"0.14","hash":"86ec28bd3a873e36426ca6b8b78f27db160c3a79","price":"0.07","side":"BUY","size":"349.86"},{"asset_id":"2151378744569768920256500242561922410292857798164019061749528550808091180185","best_ask":"0.86","best_bid":"0.85","hash":"d0bc34b6a81a8ca0b756d5533659af44700d13cf","price":"0.93","side":"SELL","size":"349.86"}],"timestamp":"1786845519607"}}
{"f":909,"recv_ms":1786845519853,"raw":{"event_type":"price_change","market":"0xd5f15f31689703aea70b93a52194a0964220d10d92ee7497346f146a8b6ef8ab","price_changes":[{"asset_id":"17406866367975599232214757606801140480252276357934486651183783311435802862074","best_ask":"0.15","best_bid":"0.14","hash":"d26825163e7aa15c8c352601d4f384e25f77066a","price":"0.17","side":"SELL","size":"165.93"},{"asset_id":"2151378744569768920256500242561922410292857798164019061749528550808091180185","best_ask":"0.86","best_bid":"0.85","hash":"53339496092d65943538fe706d1015780a3c91e5","price":"0.83","side":"BUY","size":"165.93"}],"timestamp":"1786845519608"}}
{"f":910,"recv_ms":1786845519853,"raw":{"event_type":"price_change","market":"0xd5f15f31689703aea70b93a52194a0964220d10d92ee7497346f146a8b6ef8ab","price_changes":[{"asset_id":"17406866367975599232214757606801140480252276357934486651183783311435802862074","best_ask":"0.15","best_bid":"0.14","hash":"defcb8778e1ffcad6042fc52fb05484ca36b97e4","price":"0.31","side":"SELL","size":"50"},{"asset_id":"2151378744569768920256500242561922410292857798164019061749528550808091180185","best_ask":"0.86","best_bid":"0.85","hash":"17fa2beb5da4a5487e43f11bdc1645e5c773b3f4","price":"0.69","side":"BUY","size":"50"}],"timestamp":"1786845519608"}}
{"f":911,"recv_ms":1786845519853,"raw":{"event_type":"price_change","market":"0xd5f15f31689703aea70b93a52194a0964220d10d92ee7497346f146a8b6ef8ab","price_changes":[{"asset_id":"2151378744569768920256500242561922410292857798164019061749528550808091180185","best_ask":"0.86","best_bid":"0.85","hash":"80181f23b1c71d0cec42b1bcdc299b31f4743777","price":"0.01","side":"BUY","size":"5972.54"},{"asset_id":"17406866367975599232214757606801140480252276357934486651183783311435802862074","best_ask":"0.15","best_bid":"0.14","hash":"7f03333088b2187a224c60d0cd8c7258c165cb98","price":"0.99","side":"SELL","size":"5972.54"}],"timestamp":"1786845519609"}}
{"f":912,"recv_ms":1786845519870,"raw":{"event_type":"price_change","market":"0xd5f15f31689703aea70b93a52194a0964220d10d92ee7497346f146a8b6ef8ab","price_changes":[{"asset_id":"2151378744569768920256500242561922410292857798164019061749528550808091180185","best_ask":"0.86","best_bid":"0.85","hash":"f1ae9f177d57194fb44bcc7d86435db60f1d3fb1","price":"0.01","side":"BUY","size":"5977.54"},{"asset_id":"17406866367975599232214757606801140480252276357934486651183783311435802862074","best_ask":"0.15","best_bid":"0.14","hash":"63d0d6f37495346992c7716d7fa39f7c9f87ad96","price":"0.99","side":"SELL","size":"5977.54"}],"timestamp":"1786845519610"}}
{"f":913,"recv_ms":1786845519870,"raw":{"event_type":"price_change","market":"0xd5f15f31689703aea70b93a52194a0964220d10d92ee7497346f146a8b6ef8ab","price_changes":[{"asset_id":"2151378744569768920256500242561922410292857798164019061749528550808091180185","best_ask":"0.86","best_bid":"0.85","hash":"bb27967343217c9635f8cfc45fa4825764533332","price":"0.83","side":"BUY","size":"156.61"},{"asset_id":"17406866367975599232214757606801140480252276357934486651183783311435802862074","best_ask":"0.15","best_bid":"0.14","hash":"c2cfef173766f71cd52ae5d6f5738ff8f34bb4c7","price":"0.17","side":"SELL","size":"156.61"}],"timestamp":"1786845519610"}}
{"f":914,"recv_ms":1786845519870,"raw":{"event_type":"price_change","market":"0xd5f15f31689703aea70b93a52194a0964220d10d92ee7497346f146a8b6ef8ab","price_changes":[{"asset_id":"2151378744569768920256500242561922410292857798164019061749528550808091180185","best_ask":"0.86","best_bid":"0.85","hash":"eb1aae0fa0a9bc193b3259fbf7e8031275af1b75","price":"0.01","side":"BUY","size":"5982.55"},{"asset_id":"17406866367975599232214757606801140480252276357934486651183783311435802862074","best_ask":"0.15","best_bid":"0.14","hash":"c9e8710b9daef3d437c0e80752e8b60f8f3f5ccc","price":"0.99","side":"SELL","size":"5982.55"}],"timestamp":"1786845519611"}}
{"f":915,"recv_ms":1786845519870,"raw":{"event_type":"price_change","market":"0xd5f15f31689703aea70b93a52194a0964220d10d92ee7497346f146a8b6ef8ab","price_changes":[{"asset_id":"17406866367975599232214757606801140480252276357934486651183783311435802862074","best_ask":"0.15","best_bid":"0.14","hash":"3bf882b8fa988f44009dc8c7e0dad51454a7eada","price":"0.17","side":"SELL","size":"151.61"},{"asset_id":"2151378744569768920256500242561922410292857798164019061749528550808091180185","best_ask":"0.86","best_bid":"0.85","hash":"e97280a44b6dd8ea34ecf291cbb08276b4716286","price":"0.83","side":"BUY","size":"151.61"}],"timestamp":"1786845519611"}}
{"f":916,"recv_ms":1786845519870,"raw":{"event_type":"price_change","market":"0xd5f15f31689703aea70b93a52194a0964220d10d92ee7497346f146a8b6ef8ab","price_changes":[{"asset_id":"2151378744569768920256500242561922410292857798164019061749528550808091180185","best_ask":"0.86","best_bid":"0.85","hash":"8fdfe2acc20d361c5144c169d9c6efe17ec9f21f","price":"0.64","side":"BUY","size":"256.49"},{"asset_id":"17406866367975599232214757606801140480252276357934486651183783311435802862074","best_ask":"0.15","best_bid":"0.14","hash":"7237f27a47fac43291a09064c91d7d0893ac0f6c","price":"0.36","side":"SELL","size":"256.49"}],"timestamp":"1786845519612"}}
{"f":917,"recv_ms":1786845519870,"raw":{"event_type":"price_change","market":"0xd5f15f31689703aea70b93a52194a0964220d10d92ee7497346f146a8b6ef8ab","price_changes":[{"asset_id":"2151378744569768920256500242561922410292857798164019061749528550808091180185","best_ask":"0.86","best_bid":"0.85","hash":"a7e072a63c7b473aef6378e476d45cc7a9e28359","price":"0.83","side":"BUY","size":"146.61"},{"asset_id":"17406866367975599232214757606801140480252276357934486651183783311435802862074","best_ask":"0.15","best_bid":"0.14","hash":"a98d592779747555493f4f8c57a584293091f80a","price":"0.17","side":"SELL","size":"146.61"}],"timestamp":"1786845519613"}}
{"f":918,"recv_ms":1786845519870,"raw":{"event_type":"price_change","market":"0xd5f15f31689703aea70b93a52194a0964220d10d92ee7497346f146a8b6ef8ab","price_changes":[{"asset_id":"17406866367975599232214757606801140480252276357934486651183783311435802862074","best_ask":"0.15","best_bid":"0.14","hash":"1b4aafde81561223e5525e0d96560ba9eb3923ea","price":"0.06","side":"BUY","size":"483.1"},{"asset_id":"2151378744569768920256500242561922410292857798164019061749528550808091180185","best_ask":"0.86","best_bid":"0.85","hash":"1f2127a18b37901b7016715a6a20f912a6c5f0e7","price":"0.94","side":"SELL","size":"483.1"}],"timestamp":"1786845519613"}}
{"f":919,"recv_ms":1786845519900,"raw":{"event_type":"price_change","market":"0xd5f15f31689703aea70b93a52194a0964220d10d92ee7497346f146a8b6ef8ab","price_changes":[{"asset_id":"17406866367975599232214757606801140480252276357934486651183783311435802862074","best_ask":"0.15","best_bid":"0.14","hash":"e261ede817cc5b39ba5f698d2cb408bafdcc504a","price":"0.17","side":"SELL","size":"141.61"},{"asset_id":"2151378744569768920256500242561922410292857798164019061749528550808091180185","best_ask":"0.86","best_bid":"0.85","hash":"fda21bd4b8e5c8b624a5a823c8df47e319b6c8f4","price":"0.83","side":"BUY","size":"141.61"}],"timestamp":"1786845519614"}}
{"f":920,"recv_ms":1786845519900,"raw":{"event_type":"price_change","market":"0xd5f15f31689703aea70b93a52194a0964220d10d92ee7497346f146a8b6ef8ab","price_changes":[{"asset_id":"17406866367975599232214757606801140480252276357934486651183783311435802862074","best_ask":"0.15","best_bid":"0.14","hash":"f1b898b6d2c948c2e2f61f9b01305dcbaaf16d03","price":"0.15","side":"SELL","size":"159.1"},{"asset_id":"2151378744569768920256500242561922410292857798164019061749528550808091180185","best_ask":"0.86","best_bid":"0.85","hash":"0f97c2c32bc5e1151fef6f04f63881e211998658","price":"0.85","side":"BUY","size":"159.1"}],"timestamp":"1786845519614"}}
{"f":921,"recv_ms":1786845519900,"raw":{"event_type":"price_change","market":"0xd5f15f31689703aea70b93a52194a0964220d10d92ee7497346f146a8b6ef8ab","price_changes":[{"asset_id":"2151378744569768920256500242561922410292857798164019061749528550808091180185","best_ask":"0.86","best_bid":"0.85","hash":"793c1946e96470e6997d444755e9711f6f576b20","price":"0.69","side":"BUY","size":"60"},{"asset_id":"17406866367975599232214757606801140480252276357934486651183783311435802862074","best_ask":"0.15","best_bid":"0.14","hash":"3d6e4def3ab3360768e97b5381e29327050f3e76","price":"0.31","side":"SELL","size":"60"}],"timestamp":"1786845519615"}}
{"f":922,"recv_ms":1786845519900,"raw":{"event_type":"price_change","market":"0xd5f15f31689703aea70b93a52194a0964220d10d92ee7497346f146a8b6ef8ab","price_changes":[{"asset_id":"17406866367975599232214757606801140480252276357934486651183783311435802862074","best_ask":"0.15","best_bid":"0.14","hash":"6a4438f9b1bc77955e6647e225410eb22fce3d3c","price":"0.17","side":"SELL","size":"136.61"},{"asset_id":"2151378744569768920256500242561922410292857798164019061749528550808091180185","best_ask":"0.86","best_bid":"0.85","hash":"55410cfce508ba620d8fc626c8568c4ff82259e3","price":"0.83","side":"BUY","size":"136.61"}],"timestamp":"1786845519616"}}
{"f":923,"recv_ms":1786845519900,"raw":{"event_type":"price_change","market":"0xd5f15f31689703aea70b93a52194a0964220d10d92ee7497346f146a8b6ef8ab","price_changes":[{"asset_id":"2151378744569768920256500242561922410292857798164019061749528550808091180185","best_ask":"0.86","best_bid":"0.85","hash":"d25ede623293a2e6c76b2256598d37045f959ac2","price":"0.83","side":"BUY","size":"103.28"},{"asset_id":"17406866367975599232214757606801140480252276357934486651183783311435802862074","best_ask":"0.15","best_bid":"0.14","hash":"fceb97f1902817700c3dee896b4f9937dcf017b2","price":"0.17","side":"SELL","size":"103.28"}],"timestamp":"1786845519616"}}
{"f":924,"recv_ms":1786845519900,"raw":{"event_type":"price_change","market":"0xd5f15f31689703aea70b93a52194a0964220d10d92ee7497346f146a8b6ef8ab","price_changes":[{"asset_id":"2151378744569768920256500242561922410292857798164019061749528550808091180185","best_ask":"0.86","best_bid":"0.85","hash":"e155ba6fbea8defc3bc1e4833a8579e0d594175e","price":"0.84","side":"BUY","size":"243.74"},{"asset_id":"17406866367975599232214757606801140480252276357934486651183783311435802862074","best_ask":"0.15","best_bid":"0.14","hash":"fcbbd64feec9adba376508c422017009f9a67399","price":"0.16","side":"SELL","size":"243.74"}],"timestamp":"1786845519617"}}
{"f":925,"recv_ms":1786845519900,"raw":{"event_type":"price_change","market":"0xd5f15f31689703aea70b93a52194a0964220d10d92ee7497346f146a8b6ef8ab","price_changes":[{"asset_id":"17406866367975599232214757606801140480252276357934486651183783311435802862074","best_ask":"0.15","best_bid":"0.14","hash":"a26660b6f2b2e021388f242c971cc334b9f3eb2f","price":"0.01","side":"BUY","size":"5588.18"},{"asset_id":"2151378744569768920256500242561922410292857798164019061749528550808091180185","best_ask":"0.86","best_bid":"0.85","hash":"672e90ec81b1a0dd8b2e7eeaeb109fefc343d50f","price":"0.99","side":"SELL","size":"5588.18"}],"timestamp":"1786845519618"}}
{"f":926,"recv_ms":1786845519900,"raw":{"event_type":"price_change","market":"0xd5f15f31689703aea70b93a52194a0964220d10d92ee7497346f146a8b6ef8ab","price_changes":[{"asset_id":"2151378744569768920256500242561922410292857798164019061749528550808091180185","best_ask":"0.86","best_bid":"0.85","hash":"aa099b64e3d95e61a5ec0b6884f86410da130550","price":"0.65","side":"BUY","size":"18"},{"asset_id":"17406866367975599232214757606801140480252276357934486651183783311435802862074","best_ask":"0.15","best_bid":"0.14","hash":"df02b0447ba138aa530d19ff11d8222f9dfd6c0e","price":"0.35","side":"SELL","size":"18"}],"timestamp":"1786845519618"}}
{"f":927,"recv_ms":1786845519900,"raw":{"event_type":"price_change","market":"0xd5f15f31689703aea70b93a52194a0964220d10d92ee7497346f146a8b6ef8ab","price_changes":[{"asset_id":"2151378744569768920256500242561922410292857798164019061749528550808091180185","best_ask":"0.86","best_bid":"0.85","hash":"2a2a8cec0fae014a2a500d383af0b3a6aadfb037","price":"0.83","side":"BUY","size":"93.28"},{"asset_id":"17406866367975599232214757606801140480252276357934486651183783311435802862074","best_ask":"0.15","best_bid":"0.14","hash":"00ba6ab99bac2fde9d497ea4ef209740ae8bf7aa","price":"0.17","side":"SELL","size":"93.28"}],"timestamp":"1786845519618"}}
{"f":928,"recv_ms":1786845519900,"raw":{"event_type":"price_change","market":"0xd5f15f31689703aea70b93a52194a0964220d10d92ee7497346f146a8b6ef8ab","price_changes":[{"asset_id":"2151378744569768920256500242561922410292857798164019061749528550808091180185","best_ask":"0.86","best_bid":"0.85","hash":"b2cab9f3c1f3a0bfebd46be1b11eae8f6d143e0f","price":"0.85","side":"BUY","size":"169.1"},{"asset_id":"17406866367975599232214757606801140480252276357934486651183783311435802862074","best_ask":"0.15","best_bid":"0.14","hash":"f1849d4428f33e88385e3d45bdb2e6e1e4dfded8","price":"0.15","side":"SELL","size":"169.1"}],"timestamp":"1786845519618"}}
{"f":929,"recv_ms":1786845519958,"raw":{"event_type":"price_change","market":"0xd5f15f31689703aea70b93a52194a0964220d10d92ee7497346f146a8b6ef8ab","price_changes":[{"asset_id":"2151378744569768920256500242561922410292857798164019061749528550808091180185","best_ask":"0.86","best_bid":"0.85","hash":"844df4987eff2aaedf666e4bed86347eb79b4e3b","price":"0.01","side":"BUY","size":"5977.55"},{"asset_id":"17406866367975599232214757606801140480252276357934486651183783311435802862074","best_ask":"0.15","best_bid":"0.14","hash":"0ff96dae098ec4c2db4fbacb147ee251e2600ef3","price":"0.99","side":"SELL","size":"5977.55"}],"timestamp":"1786845519619"}}
{"f":930,"recv_ms":1786845519958,"raw":{"event_type":"price_change","market":"0xd5f15f31689703aea70b93a52194a0964220d10d92ee7497346f146a8b6ef8ab","price_changes":[{"asset_id":"2151378744569768920256500242561922410292857798164019061749528550808091180185","best_ask":"0.86","best_bid":"0.85","hash":"65861fa51069ae6f0f07df81a44a77375dd18945","price":"0.85","side":"BUY","size":"179.1"},{"asset_id":"17406866367975599232214757606801140480252276357934486651183783311435802862074","best_ask":"0.15","best_bid":"0.14","hash":"7a6086ae8730394e479dfc995846ccae8bf7e482","price":"0.15","side":"SELL","size":"179.1"}],"timestamp":"1786845519619"}}
{"f":931,"recv_ms":1786845519958,"raw":{"event_type":"price_change","market":"0xd5f15f31689703aea70b93a52194a0964220d10d92ee7497346f146a8b6ef8ab","price_changes":[{"asset_id":"17406866367975599232214757606801140480252276357934486651183783311435802862074","best_ask":"0.15","best_bid":"0.14","hash":"108f5184ebee1fca689aa27bafb8154d76e3a27f","price":"0.15","side":"SELL","size":"185.1"},{"asset_id":"2151378744569768920256500242561922410292857798164019061749528550808091180185","best_ask":"0.86","best_bid":"0.85","hash":"a0ab341c1d7d7c5f5db150c001bc4b8011814648","price":"0.85","side":"BUY","size":"185.1"}],"timestamp":"1786845519620"}}
{"f":932,"recv_ms":1786845519958,"raw":{"event_type":"price_change","market":"0xd5f15f31689703aea70b93a52194a0964220d10d92ee7497346f146a8b6ef8ab","price_changes":[{"asset_id":"2151378744569768920256500242561922410292857798164019061749528550808091180185","best_ask":"0.86","best_bid":"0.85","hash":"d09f51f109a970bf5d7708c1d4f3ae43e0f082da","price":"0.47","side":"BUY","size":"552.04"},{"asset_id":"17406866367975599232214757606801140480252276357934486651183783311435802862074","best_ask":"0.15","best_bid":"0.14","hash":"644aa17df37ea8c8d3de48527a278658761ba2ea","price":"0.53","side":"SELL","size":"552.04"}],"timestamp":"1786845519621"}}
{"f":933,"recv_ms":1786845519958,"raw":{"event_type":"price_change","market":"0xd5f15f31689703aea70b93a52194a0964220d10d92ee7497346f146a8b6ef8ab","price_changes":[{"asset_id":"17406866367975599232214757606801140480252276357934486651183783311435802862074","best_ask":"0.15","best_bid":"0.14","hash":"ff5919a8674d75a0f55a8ca05c483ec30119286b","price":"0.05","side":"BUY","size":"559.7"},{"asset_id":"2151378744569768920256500242561922410292857798164019061749528550808091180185","best_ask":"0.86","best_bid":"0.85","hash":"b4fa84dad1d5f651814ae0c8c82b4c1f765965f1","price":"0.95","side":"SELL","size":"559.7"}],"timestamp":"1786845519622"}}
{"f":934,"recv_ms":1786845519978,"raw":{"event_type":"price_change","market":"0xd5f15f31689703aea70b93a52194a0964220d10d92ee7497346f146a8b6ef8ab","price_changes":[{"asset_id":"2151378744569768920256500242561922410292857798164019061749528550808091180185","best_ask":"0.86","best_bid":"0.85","hash":"7db537c4e4ee16ec275380e9bed17947a811cb1b","price":"0.01","side":"BUY","size":"6077.55"},{"asset_id":"17406866367975599232214757606801140480252276357934486651183783311435802862074","best_ask":"0.15","best_bid":"0.14","hash":"9d0eb472e0a8d87de13594c8231c3d0ff89a0e81","price":"0.99","side":"SELL","size":"6077.55"}],"timestamp":"1786845519623"}}
{"f":935,"recv_ms":1786845519979,"raw":{"event_type":"price_change","market":"0xd5f15f31689703aea70b93a52194a0964220d10d92ee7497346f146a8b6ef8ab","price_changes":[{"asset_id":"2151378744569768920256500242561922410292857798164019061749528550808091180185","best_ask":"0.86","best_bid":"0.85","hash":"8010e6bc28ecf91b09530d6aa4ccf3926ccfdacd","price":"0.84","side":"BUY","size":"253.74"},{"asset_id":"17406866367975599232214757606801140480252276357934486651183783311435802862074","best_ask":"0.15","best_bid":"0.14","hash":"e6f73868fadcef06aeb149b81f7440f373007fb5","price":"0.16","side":"SELL","size":"253.74"}],"timestamp":"1786845519624"}}
{"f":936,"recv_ms":1786845519979,"raw":{"event_type":"price_change","market":"0xd5f15f31689703aea70b93a52194a0964220d10d92ee7497346f146a8b6ef8ab","price_changes":[{"asset_id":"2151378744569768920256500242561922410292857798164019061749528550808091180185","best_ask":"0.86","best_bid":"0.85","hash":"6d1854d03d58030aab5ad412242fc2fef95b3e80","price":"0.01","side":"BUY","size":"6082.56"},{"asset_id":"17406866367975599232214757606801140480252276357934486651183783311435802862074","best_ask":"0.15","best_bid":"0.14","hash":"c0a59d58ea7a47a0fc6a7c9298d8e77d3dce3f9e","price":"0.99","side":"SELL","size":"6082.56"}],"timestamp":"1786845519625"}}
{"f":937,"recv_ms":1786845519979,"raw":{"event_type":"price_change","market":"0xd5f15f31689703aea70b93a52194a0964220d10d92ee7497346f146a8b6ef8ab","price_changes":[{"asset_id":"2151378744569768920256500242561922410292857798164019061749528550808091180185","best_ask":"0.86","best_bid":"0.85","hash":"085dc9eadc2a2303e028c31a1198f81ac0d162ab","price":"0.84","side":"BUY","size":"303.74"},{"asset_id":"17406866367975599232214757606801140480252276357934486651183783311435802862074","best_ask":"0.15","best_bid":"0.14","hash":"3fa6309d86e80a2d0383929c101dee39140987a6","price":"0.16","side":"SELL","size":"303.74"}],"timestamp":"1786845519626"}}
{"f":938,"recv_ms":1786845519986,"raw":{"event_type":"price_change","market":"0xd5f15f31689703aea70b93a52194a0964220d10d92ee7497346f146a8b6ef8ab","price_changes":[{"asset_id":"2151378744569768920256500242561922410292857798164019061749528550808091180185","best_ask":"0.86","best_bid":"0.85","hash":"68d9aaac140c66559d81fa005fde22ccfb68520e","price":"0.83","side":"BUY","size":"99.79"},{"asset_id":"17406866367975599232214757606801140480252276357934486651183783311435802862074","best_ask":"0.15","best_bid":"0.14","hash":"7ff091fd91d13e1d80d860d6873a4ad74b323a18","price":"0.17","side":"SELL","size":"99.79"}],"timestamp":"1786845519627"}}
{"f":939,"recv_ms":1786845519986,"raw":{"event_type":"price_change","market":"0xd5f15f31689703aea70b93a52194a0964220d10d92ee7497346f146a8b6ef8ab","price_changes":[{"asset_id":"2151378744569768920256500242561922410292857798164019061749528550808091180185","best_ask":"0.86","best_bid":"0.85","hash":"0292f89365395adb604cc708797dfadc97057ba9","price":"0.72","side":"BUY","size":"30"},{"asset_id":"17406866367975599232214757606801140480252276357934486651183783311435802862074","best_ask":"0.15","best_bid":"0.14","hash":"8d66654d38680bb829e22f6238d5c82ac5759820","price":"0.28","side":"SELL","size":"30"}],"timestamp":"1786845519628"}}
{"f":940,"recv_ms":1786845519986,"raw":{"event_type":"price_change","market":"0xd5f15f31689703aea70b93a52194a0964220d10d92ee7497346f146a8b6ef8ab","price_changes":[{"asset_id":"2151378744569768920256500242561922410292857798164019061749528550808091180185","best_ask":"0.86","best_bid":"0.85","hash":"4a2ca13c35c074fde5212e50003895f4b2d2d812","price":"0.37","side":"BUY","size":"255.2"},{"asset_id":"17406866367975599232214757606801140480252276357934486651183783311435802862074","best_ask":"0.15","best_bid":"0.14","hash":"9d777859ac71e55c478682bda9146014d7c1396e","price":"0.63","side":"SELL","size":"255.2"}],"timestamp":"1786845519629"}}
{"f":941,"recv_ms":1786845519986,"raw":{"event_type":"price_change","market":"0xd5f15f31689703aea70b93a52194a0964220d10d92ee7497346f146a8b6ef8ab","price_changes":[{"asset_id":"2151378744569768920256500242561922410292857798164019061749528550808091180185","best_ask":"0.86","best_bid":"0.85","hash":"4f07f945c3100bb7249c035e2b8fa3d8484ad985","price":"0.85","side":"BUY","size":"195.1"},{"asset_id":"17406866367975599232214757606801140480252276357934486651183783311435802862074","best_ask":"0.15","best_bid":"0.14","hash":"fb20ab386717a707b688a71b386f21ec4d54064d","price":"0.15","side":"SELL","size":"195.1"}],"timestamp":"1786845519630"}}
{"f":942,"recv_ms":1786845519986,"raw":{"event_type":"price_change","market":"0xd5f15f31689703aea70b93a52194a0964220d10d92ee7497346f146a8b6ef8ab","price_changes":[{"asset_id":"2151378744569768920256500242561922410292857798164019061749528550808091180185","best_ask":"0.86","best_bid":"0.85","hash":"2900de02d7a47104f678cbcf98a28106738cf2db","price":"0.84","side":"BUY","size":"313.74"},{"asset_id":"17406866367975599232214757606801140480252276357934486651183783311435802862074","best_ask":"0.15","best_bid":"0.14","hash":"eceeece86c4f94ac18b262fbe99e0b69011ba4cd","price":"0.16","side":"SELL","size":"313.74"}],"timestamp":"1786845519631"}}
{"f":943,"recv_ms":1786845519989,"raw":{"event_type":"price_change","market":"0xd5f15f31689703aea70b93a52194a0964220d10d92ee7497346f146a8b6ef8ab","price_changes":[{"asset_id":"17406866367975599232214757606801140480252276357934486651183783311435802862074","best_ask":"0.15","best_bid":"0.14","hash":"812e87106aa9ddfb699accb6dd51e29ec3826650","price":"0.14","side":"BUY","size":"9.39"},{"asset_id":"2151378744569768920256500242561922410292857798164019061749528550808091180185","best_ask":"0.86","best_bid":"0.85","hash":"305da39dbf85583e260dbade3b8f8e7c3bd67da2","price":"0.86","side":"SELL","size":"9.39"}],"timestamp":"1786845519632"}}
{"f":944,"recv_ms":1786845519989,"raw":{"event_type":"price_change","market":"0xd5f15f31689703aea70b93a52194a0964220d10d92ee7497346f146a8b6ef8ab","price_changes":[{"asset_id":"2151378744569768920256500242561922410292857798164019061749528550808091180185","best_ask":"0.86","best_bid":"0.85","hash":"64f6301027971227581fb24323972a19e3d51c05","price":"0.01","side":"BUY","size":"6088.56"},{"asset_id":"17406866367975599232214757606801140480252276357934486651183783311435802862074","best_ask":"0.15","best_bid":"0.14","hash":"4dd06149715a3fa3eca8681f7fa86d7a13a0b0b3","price":"0.99","side":"SELL","size":"6088.56"}],"timestamp":"1786845519633"}}
{"f":945,"recv_ms":1786845519989,"raw":{"event_type":"price_change","market":"0xd5f15f31689703aea70b93a52194a0964220d10d92ee7497346f146a8b6ef8ab","price_changes":[{"asset_id":"17406866367975599232214757606801140480252276357934486651183783311435802862074","best_ask":"0.15","best_bid":"0.14","hash":"a7e81936d64f6294cd2b1074d64e14e4af653ac8","price":"0.13","side":"BUY","size":"88"},{"asset_id":"2151378744569768920256500242561922410292857798164019061749528550808091180185","best_ask":"0.86","best_bid":"0.85","hash":"7d0b7f0f21e45e931133417d7362575f5a1453c7","price":"0.87","side":"SELL","size":"88"}],"timestamp":"1786845519634"}}
{"f":946,"recv_ms":1786845519989,"raw":{"event_type":"price_change","market":"0xd5f15f31689703aea70b93a52194a0964220d10d92ee7497346f146a8b6ef8ab","price_changes":[{"asset_id":"17406866367975599232214757606801140480252276357934486651183783311435802862074","best_ask":"0.15","best_bid":"0.14","hash":"6f71538e4c94c7bbfdfae9ae3455bde65795b518","price":"0.01","side":"BUY","size":"5593.18"},{"asset_id":"2151378744569768920256500242561922410292857798164019061749528550808091180185","best_ask":"0.86","best_bid":"0.85","hash":"fe61f367c6c3c78769646eb6a24e391c4b071ce5","price":"0.99","side":"SELL","size":"5593.18"}],"timestamp":"1786845519635"}}
{"f":947,"recv_ms":1786845519989,"raw":{"event_type":"price_change","market":"0xd5f15f31689703aea70b93a52194a0964220d10d92ee7497346f146a8b6ef8ab","price_changes":[{"asset_id":"17406866367975599232214757606801140480252276357934486651183783311435802862074","best_ask":"0.15","best_bid":"0.14","hash":"03b0fe0ecb2d023c5666e8eaf694484829727408","price":"0.03","side":"BUY","size":"611.3"},{"asset_id":"2151378744569768920256500242561922410292857798164019061749528550808091180185","best_ask":"0.86","best_bid":"0.85","hash":"ced3cd511c756a96403cb28530a3d977a2cdbfe0","price":"0.97","side":"SELL","size":"611.3"}],"timestamp":"1786845519636"}}
{"f":948,"recv_ms":1786845519989,"raw":{"event_type":"price_change","market":"0xd5f15f31689703aea70b93a52194a0964220d10d92ee7497346f146a8b6ef8ab","price_changes":[{"asset_id":"2151378744569768920256500242561922410292857798164019061749528550808091180185","best_ask":"0.86","best_bid":"0.85","hash":"a52a8ce08ef3c7947309bfb100b5ead553f225ab","price":"0.86","side":"SELL","size":"17.39"},{"asset_id":"17406866367975599232214757606801140480252276357934486651183783311435802862074","best_ask":"0.15","best_bid":"0.14","hash":"ebf2f5b2eba9861865a4bc3b92e530cfbdd50317","price":"0.14","side":"BUY","size":"17.39"}],"timestamp":"1786845519637"}}
{"f":949,"recv_ms":1786845519989,"raw":{"event_type":"price_change","market":"0xd5f15f31689703aea70b93a52194a0964220d10d92ee7497346f146a8b6ef8ab","price_changes":[{"asset_id":"17406866367975599232214757606801140480252276357934486651183783311435802862074","best_ask":"0.15","best_bid":"0.14","hash":"6dd79adb1d673fff8a0cf469ca10541caba692b5","price":"0.01","side":"BUY","size":"5598.18"},{"asset_id":"2151378744569768920256500242561922410292857798164019061749528550808091180185","best_ask":"0.86","best_bid":"0.85","hash":"6c7c8162c0db6ac3ea09cee560b9df34575ecfbf","price":"0.99","side":"SELL","size":"5598.18"}],"timestamp":"1786845519638"}}
{"f":950,"recv_ms":1786845519989,"raw":{"event_type":"price_change","market":"0xd5f15f31689703aea70b93a52194a0964220d10d92ee7497346f146a8b6ef8ab","price_changes":[{"asset_id":"2151378744569768920256500242561922410292857798164019061749528550808091180185","best_ask":"0.86","best_bid":"0.85","hash":"d003d23d46654c0812dea1bf1926ff6d03bdb5a0","price":"0.01","side":"BUY","size":"6093.56"},{"asset_id":"17406866367975599232214757606801140480252276357934486651183783311435802862074","best_ask":"0.15","best_bid":"0.14","hash":"ffc30bd07abc565489773a661139fb7ed0c3008d","price":"0.99","side":"SELL","size":"6093.56"}],"timestamp":"1786845519639"}}
{"f":951,"recv_ms":1786845519989,"raw":{"event_type":"price_change","market":"0xd5f15f31689703aea70b93a52194a0964220d10d92ee7497346f146a8b6ef8ab","price_changes":[{"asset_id":"2151378744569768920256500242561922410292857798164019061749528550808091180185","best_ask":"0.86","best_bid":"0.85","hash":"b495876d323287b8fb8a2396228156fc05d6b1b3","price":"0.01","side":"BUY","size":"6098.57"},{"asset_id":"17406866367975599232214757606801140480252276357934486651183783311435802862074","best_ask":"0.15","best_bid":"0.14","hash":"6c118b07c2e993f87c7686306ea04e86c2fcd3b6","price":"0.99","side":"SELL","size":"6098.57"}],"timestamp":"1786845519640"}}
{"f":952,"recv_ms":1786845519989,"raw":{"event_type":"price_change","market":"0xd5f15f31689703aea70b93a52194a0964220d10d92ee7497346f146a8b6ef8ab","price_changes":[{"asset_id":"2151378744569768920256500242561922410292857798164019061749528550808091180185","best_ask":"0.86","best_bid":"0.85","hash":"a262e53be33a8c406896bfa4a9ee75642050bed5","price":"0.54","side":"BUY","size":"119"},{"asset_id":"17406866367975599232214757606801140480252276357934486651183783311435802862074","best_ask":"0.15","best_bid":"0.14","hash":"0598d5bbe742277a49ae4c4f17e5e4dae7975568","price":"0.46","side":"SELL","size":"119"}],"timestamp":"1786845519641"}}
{"f":953,"recv_ms":1786845519991,"raw":{"event_type":"price_change","market":"0xd5f15f31689703aea70b93a52194a0964220d10d92ee7497346f146a8b6ef8ab","price_changes":[{"asset_id":"17406866367975599232214757606801140480252276357934486651183783311435802862074","best_ask":"0.15","best_bid":"0.14","hash":"cbc77ef4bbfe86194d8cfa4f9be599f24ad6872e","price":"0.12","side":"BUY","size":"35"},{"asset_id":"2151378744569768920256500242561922410292857798164019061749528550808091180185","best_ask":"0.86","best_bid":"0.85","hash":"5887d87c7afc0bba852e696eef22a093d38af606","price":"0.88","side":"SELL","size":"35"}],"timestamp":"1786845519642"}}
{"f":954,"recv_ms":1786845519991,"raw":{"event_type":"price_change","market":"0xd5f15f31689703aea70b93a52194a0964220d10d92ee7497346f146a8b6ef8ab","price_changes":[{"asset_id":"2151378744569768920256500242561922410292857798164019061749528550808091180185","best_ask":"0.86","best_bid":"0.85","hash":"0e36712deb1cfe193e01f00ceab2c6e7342c94ec","price":"0.85","side":"BUY","size":"205.1"},{"asset_id":"17406866367975599232214757606801140480252276357934486651183783311435802862074","best_ask":"0.15","best_bid":"0.14","hash":"0363cbfb96c4029db3344ebaa479fef1c47b414f","price":"0.15","side":"SELL","size":"205.1"}],"timestamp":"1786845519643"}}
{"f":955,"recv_ms":1786845519991,"raw":{"event_type":"price_change","market":"0xd5f15f31689703aea70b93a52194a0964220d10d92ee7497346f146a8b6ef8ab","price_changes":[{"asset_id":"2151378744569768920256500242561922410292857798164019061749528550808091180185","best_ask":"0.86","best_bid":"0.85","hash":"b8bc2b77c72b187a9d074f3458274489317a1a05","price":"0.84","side":"BUY","size":"281.74"},{"asset_id":"17406866367975599232214757606801140480252276357934486651183783311435802862074","best_ask":"0.15","best_bid":"0.14","hash":"f32685057db1b45045813dde540832343bbf25a4","price":"0.16","side":"SELL","size":"281.74"}],"timestamp":"1786845519644"}}
{"f":956,"recv_ms":1786845519991,"raw":{"event_type":"price_change","market":"0xd5f15f31689703aea70b93a52194a0964220d10d92ee7497346f146a8b6ef8ab","price_changes":[{"asset_id":"2151378744569768920256500242561922410292857798164019061749528550808091180185","best_ask":"0.86","best_bid":"0.85","hash":"b192349bfb6434e19ca1cbac118b151d50e09ff6","price":"0.84","side":"BUY","size":"254.66"},{"asset_id":"17406866367975599232214757606801140480252276357934486651183783311435802862074","best_ask":"0.15","best_bid":"0.14","hash":"5180a38e9690221b6e3d24896b47dafd0341277c","price":"0.16","side":"SELL","size":"254.66"}],"timestamp":"1786845519644"}}
{"f":957,"recv_ms":1786845519991,"raw":{"event_type":"price_change","market":"0xd5f15f31689703aea70b93a52194a0964220d10d92ee7497346f146a8b6ef8ab","price_changes":[{"asset_id":"2151378744569768920256500242561922410292857798164019061749528550808091180185","best_ask":"0.86","best_bid":"0.85","hash":"31973fa432f68b35c233ebf2feded08a121261df","price":"0.71","side":"BUY","size":"5"},{"asset_id":"17406866367975599232214757606801140480252276357934486651183783311435802862074","best_ask":"0.15","best_bid":"0.14","hash":"55eea02cdc02d4c4f2373365d72b990c399c23d9","price":"0.29","side":"SELL","size":"5"}],"timestamp":"1786845519644"}}
{"f":958,"recv_ms":1786845519991,"raw":{"event_type":"price_change","market":"0xd5f15f31689703aea70b93a52194a0964220d10d92ee7497346f146a8b6ef8ab","price_changes":[{"asset_id":"2151378744569768920256500242561922410292857798164019061749528550808091180185","best_ask":"0.86","best_bid":"0.85","hash":"23aab0a6fc79c06fa7201b53e00ed16976d5fa26","price":"0.84","side":"BUY","size":"221.33"},{"asset_id":"17406866367975599232214757606801140480252276357934486651183783311435802862074","best_ask":"0.15","best_bid":"0.14","hash":"8639d48bfdaa55b33ce6fadb9d1a13ea363b84b1","price":"0.16","side":"SELL","size":"221.33"}],"timestamp":"1786845519644"}}
{"f":959,"recv_ms":1786845519991,"raw":{"event_type":"price_change","market":"0xd5f15f31689703aea70b93a52194a0964220d10d92ee7497346f146a8b6ef8ab","price_changes":[{"asset_id":"17406866367975599232214757606801140480252276357934486651183783311435802862074","best_ask":"0.15","best_bid":"0.14","hash":"0231ce72aad11d47bfae8a887ec7ca1cb16c0a3d","price":"0.31","side":"SELL","size":"50"},{"asset_id":"2151378744569768920256500242561922410292857798164019061749528550808091180185","best_ask":"0.86","best_bid":"0.85","hash":"fe0b0327cbd25f75575bbb6c05fa33a2491eb4d9","price":"0.69","side":"BUY","size":"50"}],"timestamp":"1786845519645"}}
{"f":960,"recv_ms":1786845519991,"raw":{"event_type":"price_change","market":"0xd5f15f31689703aea70b93a52194a0964220d10d92ee7497346f146a8b6ef8ab","price_changes":[{"asset_id":"2151378744569768920256500242561922410292857798164019061749528550808091180185","best_ask":"0.86","best_bid":"0.85","hash":"9c3cf7c3a924be37c11313bf436ff69afbb37d05","price":"0.84","side":"BUY","size":"188"},{"asset_id":"17406866367975599232214757606801140480252276357934486651183783311435802862074","best_ask":"0.15","best_bid":"0.14","hash":"6ec7a80726d4e59b1d66382768a4920d52b4ed5d","price":"0.16","side":"SELL","size":"188"}],"timestamp":"1786845519645"}}
{"f":961,"recv_ms":1786845519991,"raw":{"event_type":"price_change","market":"0xd5f15f31689703aea70b93a52194a0964220d10d92ee7497346f146a8b6ef8ab","price_changes":[{"asset_id":"2151378744569768920256500242561922410292857798164019061749528550808091180185","best_ask":"0.86","best_bid":"0.85","hash":"804de83f9506d9da1073b10eed8d845ea5bcc4f9","price":"0.54","side":"BUY","size":"109"},{"asset_id":"17406866367975599232214757606801140480252276357934486651183783311435802862074","best_ask":"0.15","best_bid":"0.14","hash":"5afd4fe881bbcf9db45f1cbd047bc80efd8f9d9a","price":"0.46","side":"SELL","size":"109"}],"timestamp":"1786845519645"}}
{"f":962,"recv_ms":1786845519993,"raw":{"event_type":"price_change","market":"0xd5f15f31689703aea70b93a52194a0964220d10d92ee7497346f146a8b6ef8ab","price_changes":[{"asset_id":"2151378744569768920256500242561922410292857798164019061749528550808091180185","best_ask":"0.86","best_bid":"0.85","hash":"46f5d74b746a78a7692a7167ada11022e78e4053","price":"0.69","side":"BUY","size":"40"},{"asset_id":"17406866367975599232214757606801140480252276357934486651183783311435802862074","best_ask":"0.15","best_bid":"0.14","hash":"387408f2ece70d77573e653a6a9d75303147ad8d","price":"0.31","side":"SELL","size":"40"}],"timestamp":"1786845519645"}}
{"f":963,"recv_ms":1786845519993,"raw":{"event_type":"price_change","market":"0xd5f15f31689703aea70b93a52194a0964220d10d92ee7497346f146a8b6ef8ab","price_changes":[{"asset_id":"2151378744569768920256500242561922410292857798164019061749528550808091180185","best_ask":"0.86","best_bid":"0.85","hash":"4946328887436aabaadec3ae814704ed826cae1f","price":"0.84","side":"BUY","size":"178"},{"asset_id":"17406866367975599232214757606801140480252276357934486651183783311435802862074","best_ask":"0.15","best_bid":"0.14","hash":"fbdc92f8fb25c0abaf726e0c36a2ed4831a4e6d0","price":"0.16","side":"SELL","size":"178"}],"timestamp":"1786845519645"}}
{"f":964,"recv_ms":1786845519993,"raw":{"event_type":"price_change","market":"0xd5f15f31689703aea70b93a52194a0964220d10d92ee7497346f146a8b6ef8ab","price_changes":[{"asset_id":"2151378744569768920256500242561922410292857798164019061749528550808091180185","best_ask":"0.86","best_bid":"0.85","hash":"1cd98d8ed76fab24f5bb78d393dfa52e5fe8bfbc","price":"0.01","side":"BUY","size":"6198.57"},{"asset_id":"17406866367975599232214757606801140480252276357934486651183783311435802862074","best_ask":"0.15","best_bid":"0.14","hash":"1528fe3038e7a3a46230ba35ada13e9d2e4e927c","price":"0.99","side":"SELL","size":"6198.57"}],"timestamp":"1786845519645"}}
{"f":965,"recv_ms":1786845519993,"raw":{"event_type":"price_change","market":"0xd5f15f31689703aea70b93a52194a0964220d10d92ee7497346f146a8b6ef8ab","price_changes":[{"asset_id":"2151378744569768920256500242561922410292857798164019061749528550808091180185","best_ask":"0.86","best_bid":"0.85","hash":"2eea74b247a387da7749afbc67d21af87d873334","price":"0.01","side":"BUY","size":"6203.58"},{"asset_id":"17406866367975599232214757606801140480252276357934486651183783311435802862074","best_ask":"0.15","best_bid":"0.14","hash":"a4fbcdc5df1852f0678db04353ab218fee4e59c5","price":"0.99","side":"SELL","size":"6203.58"}],"timestamp":"1786845519646"}}
{"f":966,"recv_ms":1786845519993,"raw":{"event_type":"price_change","market":"0xd5f15f31689703aea70b93a52194a0964220d10d92ee7497346f146a8b6ef8ab","price_changes":[{"asset_id":"2151378744569768920256500242561922410292857798164019061749528550808091180185","best_ask":"0.86","best_bid":"0.85","hash":"a83b54ab7bfb4ef7e96b7b6e89239194a4a7d673","price":"0.83","side":"BUY","size":"49.79"},{"asset_id":"17406866367975599232214757606801140480252276357934486651183783311435802862074","best_ask":"0.15","best_bid":"0.14","hash":"84afa0e764464159b7e205656fb1aa5bd6d80e23","price":"0.17","side":"SELL","size":"49.79"}],"timestamp":"1786845519647"}}
{"f":967,"recv_ms":1786845519993,"raw":{"event_type":"price_change","market":"0xd5f15f31689703aea70b93a52194a0964220d10d92ee7497346f146a8b6ef8ab","price_changes":[{"asset_id":"17406866367975599232214757606801140480252276357934486651183783311435802862074","best_ask":"0.15","best_bid":"0.14","hash":"0551173f2beec546b682599fac5b51ff7584fe44","price":"0.18","side":"SELL","size":"49.22"},{"asset_id":"2151378744569768920256500242561922410292857798164019061749528550808091180185","best_ask":"0.86","best_bid":"0.85","hash":"7392a83386d49f39615b744ad8244b7778df2813","price":"0.82","side":"BUY","size":"49.22"}],"timestamp":"1786845519647"}}
{"f":968,"recv_ms":1786845519993,"raw":{"event_type":"price_change","market":"0xd5f15f31689703aea70b93a52194a0964220d10d92ee7497346f146a8b6ef8ab","price_changes":[{"asset_id":"17406866367975599232214757606801140480252276357934486651183783311435802862074","best_ask":"0.15","best_bid":"0.14","hash":"3750dff242fc3398f5a7cb4364c381127a3e5a77","price":"0.15","side":"SELL","size":"222.1"},{"asset_id":"2151378744569768920256500242561922410292857798164019061749528550808091180185","best_ask":"0.86","best_bid":"0.85","hash":"4f1e9f0cc3c0c3d4fd0543c2df933b248986fddb","price":"0.85","side":"BUY","size":"222.1"}],"timestamp":"1786845519647"}}
{"f":969,"recv_ms":1786845519993,"raw":{"event_type":"price_change","market":"0xd5f15f31689703aea70b93a52194a0964220d10d92ee7497346f146a8b6ef8ab","price_changes":[{"asset_id":"17406866367975599232214757606801140480252276357934486651183783311435802862074","best_ask":"0.15","best_bid":"0.14","hash":"d221fec42d75c7adf8838ac7e5936cc787543e4e","price":"0.01","side":"BUY","size":"5593.18"},{"asset_id":"2151378744569768920256500242561922410292857798164019061749528550808091180185","best_ask":"0.86","best_bid":"0.85","hash":"76d77b6bcbf65e2a020bb0574fb2a0796b20bb26","price":"0.99","side":"SELL","size":"5593.18"}],"timestamp":"1786845519648"}}
{"f":970,"recv_ms":1786845519993,"raw":{"event_type":"price_change","market":"0xd5f15f31689703aea70b93a52194a0964220d10d92ee7497346f146a8b6ef8ab","price_changes":[{"asset_id":"2151378744569768920256500242561922410292857798164019061749528550808091180185","best_ask":"0.86","best_bid":"0.85","hash":"634bcd19c395833d74760ca7069c638ef4ac710b","price":"0.84","side":"BUY","size":"168"},{"asset_id":"17406866367975599232214757606801140480252276357934486651183783311435802862074","best_ask":"0.15","best_bid":"0.14","hash":"04dc9a46af5c8eaa3ae9885b00d568da46b00fbc","price":"0.16","side":"SELL","size":"168"}],"timestamp":"1786845519648"}}
{"f":971,"recv_ms":1786845519993,"raw":{"event_type":"price_change","market":"0xd5f15f31689703aea70b93a52194a0964220d10d92ee7497346f146a8b6ef8ab","price_changes":[{"asset_id":"2151378744569768920256500242561922410292857798164019061749528550808091180185","best_ask":"0.86","best_bid":"0.85","hash":"6997fbf3958a45d81c2b0ca076b9cf2760e683da","price":"0.78","side":"BUY","size":"107"},{"asset_id":"17406866367975599232214757606801140480252276357934486651183783311435802862074","best_ask":"0.15","best_bid":"0.14","hash":"886de0f25eca5e04551a11905751c27d562b1157","price":"0.22","side":"SELL","size":"107"}],"timestamp":"1786845519649"}}
{"f":972,"recv_ms":1786845519993,"raw":{"event_type":"price_change","market":"0xd5f15f31689703aea70b93a52194a0964220d10d92ee7497346f146a8b6ef8ab","price_changes":[{"asset_id":"17406866367975599232214757606801140480252276357934486651183783311435802862074","best_ask":"0.15","best_bid":"0.14","hash":"60aa078dda21e106abe144ef13cf0b040bb58577","price":"0.12","side":"BUY","size":"5"},{"asset_id":"2151378744569768920256500242561922410292857798164019061749528550808091180185","best_ask":"0.86","best_bid":"0.85","hash":"765eec667ecac92185e8d272601d815f8e344a13","price":"0.88","side":"SELL","size":"5"}],"timestamp":"1786845519650"}}
{"f":973,"recv_ms":1786845519993,"raw":{"event_type":"price_change","market":"0xd5f15f31689703aea70b93a52194a0964220d10d92ee7497346f146a8b6ef8ab","price_changes":[{"asset_id":"2151378744569768920256500242561922410292857798164019061749528550808091180185","best_ask":"0.86","best_bid":"0.85","hash":"5b08e3f02a686994f84bf6c248e00a34931775d6","price":"0.84","side":"BUY","size":"178"},{"asset_id":"17406866367975599232214757606801140480252276357934486651183783311435802862074","best_ask":"0.15","best_bid":"0.14","hash":"8692dcb285f292f8f379f97ac94a26c4a46bb3de","price":"0.16","side":"SELL","size":"178"}],"timestamp":"1786845519650"}}
{"f":974,"recv_ms":1786845520000,"raw":{"event_type":"price_change","market":"0xd5f15f31689703aea70b93a52194a0964220d10d92ee7497346f146a8b6ef8ab","price_changes":[{"asset_id":"2151378744569768920256500242561922410292857798164019061749528550808091180185","best_ask":"0.86","best_bid":"0.85","hash":"b5178e11cc46b1c8fe4d19955431d01fe880c1ad","price":"0.01","side":"BUY","size":"6208.59"},{"asset_id":"17406866367975599232214757606801140480252276357934486651183783311435802862074","best_ask":"0.15","best_bid":"0.14","hash":"1bacca71f47de480f45cc7a9675589cc5fa5e475","price":"0.99","side":"SELL","size":"6208.59"}],"timestamp":"1786845519651"}}
{"f":975,"recv_ms":1786845520000,"raw":{"event_type":"price_change","market":"0xd5f15f31689703aea70b93a52194a0964220d10d92ee7497346f146a8b6ef8ab","price_changes":[{"asset_id":"2151378744569768920256500242561922410292857798164019061749528550808091180185","best_ask":"0.86","best_bid":"0.85","hash":"f8a767e615467d13bf23c7cc87ad9542e39f8fdd","price":"0.84","side":"BUY","size":"168"},{"asset_id":"17406866367975599232214757606801140480252276357934486651183783311435802862074","best_ask":"0.15","best_bid":"0.14","hash":"6336f12853fa98e8fe3b5b238e6d07c338104d4b","price":"0.16","side":"SELL","size":"168"}],"timestamp":"1786845519652"}}
{"f":976,"recv_ms":1786845520000,"raw":{"event_type":"price_change","market":"0xd5f15f31689703aea70b93a52194a0964220d10d92ee7497346f146a8b6ef8ab","price_changes":[{"asset_id":"2151378744569768920256500242561922410292857798164019061749528550808091180185","best_ask":"0.86","best_bid":"0.85","hash":"9d69af9bf30a03f2d98cdf93072596b4d181448b","price":"0.83","side":"BUY","size":"40.51"},{"asset_id":"17406866367975599232214757606801140480252276357934486651183783311435802862074","best_ask":"0.15","best_bid":"0.14","hash":"63a2e1789cf037e21875c5b33049c9074f5910cc","price":"0.17","side":"SELL","size":"40.51"}],"timestamp":"1786845519652"}}
{"f":977,"recv_ms":1786845520000,"raw":{"event_type":"price_change","market":"0xd5f15f31689703aea70b93a52194a0964220d10d92ee7497346f146a8b6ef8ab","price_changes":[{"asset_id":"2151378744569768920256500242561922410292857798164019061749528550808091180185","best_ask":"0.86","best_bid":"0.85","hash":"3e709d413a19c5aefdcd9457f5bfb095e82da417","price":"0.01","side":"BUY","size":"6203.59"},{"asset_id":"17406866367975599232214757606801140480252276357934486651183783311435802862074","best_ask":"0.15","best_bid":"0.14","hash":"d0405c2d3d3288bf2a631a11b5ff39716f8f0732","price":"0.99","side":"SELL","size":"6203.59"}],"timestamp":"1786845519653"}}
{"f":978,"recv_ms":1786845520000,"raw":{"event_type":"price_change","market":"0xd5f15f31689703aea70b93a52194a0964220d10d92ee7497346f146a8b6ef8ab","price_changes":[{"asset_id":"17406866367975599232214757606801140480252276357934486651183783311435802862074","best_ask":"0.15","best_bid":"0.14","hash":"d8731bd60d10411e89d228b891379a5059e0dd6b","price":"0.06","side":"BUY","size":"383.1"},{"asset_id":"2151378744569768920256500242561922410292857798164019061749528550808091180185","best_ask":"0.86","best_bid":"0.85","hash":"41d43fe9e888528e575a1c0a6df8bcf544e5de23","price":"0.94","side":"SELL","size":"383.1"}],"timestamp":"1786845519653"}}
{"f":979,"recv_ms":1786845520000,"raw":{"event_type":"price_change","market":"0xd5f15f31689703aea70b93a52194a0964220d10d92ee7497346f146a8b6ef8ab","price_changes":[{"asset_id":"2151378744569768920256500242561922410292857798164019061749528550808091180185","best_ask":"0.86","best_bid":"0.85","hash":"5bef0d9c7c8aa38acae88246c59c2ed7735a1688","price":"0.01","side":"BUY","size":"6198.58"},{"asset_id":"17406866367975599232214757606801140480252276357934486651183783311435802862074","best_ask":"0.15","best_bid":"0.14","hash":"21320a90acfd056b3eed1fe886b01937c71da104","price":"0.99","side":"SELL","size":"6198.58"}],"timestamp":"1786845519653"}}
{"f":980,"recv_ms":1786845520000,"raw":{"event_type":"price_change","market":"0xd5f15f31689703aea70b93a52194a0964220d10d92ee7497346f146a8b6ef8ab","price_changes":[{"asset_id":"2151378744569768920256500242561922410292857798164019061749528550808091180185","best_ask":"0.86","best_bid":"0.85","hash":"08e9ad92af522fd0cdceda0a86caa630fd7ad230","price":"0.84","side":"BUY","size":"163"},{"asset_id":"17406866367975599232214757606801140480252276357934486651183783311435802862074","best_ask":"0.15","best_bid":"0.14","hash":"db79f1cebfa6cc61f66241112583bb1321aca330","price":"0.16","side":"SELL","size":"163"}],"timestamp":"1786845519654"}}
{"f":981,"recv_ms":1786845520000,"raw":{"event_type":"price_change","market":"0xd5f15f31689703aea70b93a52194a0964220d10d92ee7497346f146a8b6ef8ab","price_changes":[{"asset_id":"2151378744569768920256500242561922410292857798164019061749528550808091180185","best_ask":"0.86","best_bid":"0.85","hash":"e4ef3cfc326dd7ecf7cf810b49bf915b39619b62","price":"0.56","side":"BUY","size":"19"},{"asset_id":"17406866367975599232214757606801140480252276357934486651183783311435802862074","best_ask":"0.15","best_bid":"0.14","hash":"5618b4fff7a25e9ea675300fd84cfd9eba8045b6","price":"0.44","side":"SELL","size":"19"}],"timestamp":"1786845519654"}}
{"f":982,"recv_ms":1786845520004,"raw":{"event_type":"price_change","market":"0xd5f15f31689703aea70b93a52194a0964220d10d92ee7497346f146a8b6ef8ab","price_changes":[{"asset_id":"17406866367975599232214757606801140480252276357934486651183783311435802862074","best_ask":"0.15","best_bid":"0.14","hash":"a204835f3f0311f049e96ae62888053312359d79","price":"0.01","side":"BUY","size":"5588.18"},{"asset_id":"2151378744569768920256500242561922410292857798164019061749528550808091180185","best_ask":"0.86","best_bid":"0.85","hash":"9f589d9cc3f76e0268649a4454a2b8bd02396046","price":"0.99","side":"SELL","size":"5588.18"}],"timestamp":"1786845519654"}}
{"f":983,"recv_ms":1786845520004,"raw":{"event_type":"price_change","market":"0xd5f15f31689703aea70b93a52194a0964220d10d92ee7497346f146a8b6ef8ab","price_changes":[{"asset_id":"2151378744569768920256500242561922410292857798164019061749528550808091180185","best_ask":"0.86","best_bid":"0.85","hash":"9446f46966cb862bd6ba67a8b91a82a83e05dc6c","price":"0.85","side":"BUY","size":"232.1"},{"asset_id":"17406866367975599232214757606801140480252276357934486651183783311435802862074","best_ask":"0.15","best_bid":"0.14","hash":"053d3ae38c3972fe59582a17f60cfcae0455878c","price":"0.15","side":"SELL","size":"232.1"}],"timestamp":"1786845519654"}}
{"f":984,"recv_ms":1786845520004,"raw":{"event_type":"price_change","market":"0xd5f15f31689703aea70b93a52194a0964220d10d92ee7497346f146a8b6ef8ab","price_changes":[{"asset_id":"2151378744569768920256500242561922410292857798164019061749528550808091180185","best_ask":"0.86","best_bid":"0.85","hash":"83807b61e86603bc13bc9a8e7de3673cb856ad1c","price":"0.73","side":"BUY","size":"22"},{"asset_id":"17406866367975599232214757606801140480252276357934486651183783311435802862074","best_ask":"0.15","best_bid":"0.14","hash":"a621de8ede5dcf21ba0d8edc309f0de36435ac7c","price":"0.27","side":"SELL","size":"22"}],"timestamp":"1786845519655"}}
{"f":985,"recv_ms":1786845520004,"raw":{"event_type":"price_change","market":"0xd5f15f31689703aea70b93a52194a0964220d10d92ee7497346f146a8b6ef8ab","price_changes":[{"asset_id":"17406866367975599232214757606801140480252276357934486651183783311435802862074","best_ask":"0.15","best_bid":"0.14","hash":"c02faf2221c6e85d583145c05c1011ac662f5bba","price":"0.09","side":"BUY","size":"40"},{"asset_id":"2151378744569768920256500242561922410292857798164019061749528550808091180185","best_ask":"0.86","best_bid":"0.85","hash":"a9339d23611c567f2b04c4f8ee21cfcd81860eda","price":"0.91","side":"SELL","size":"40"}],"timestamp":"1786845519657"}}
{"f":986,"recv_ms":1786845520004,"raw":{"event_type":"price_change","market":"0xd5f15f31689703aea70b93a52194a0964220d10d92ee7497346f146a8b6ef8ab","price_changes":[{"asset_id":"2151378744569768920256500242561922410292857798164019061749528550808091180185","best_ask":"0.86","best_bid":"0.85","hash":"c5a3fee24266ee6ec4fe51b7e65f17848a8f6c5d","price":"0.85","side":"BUY","size":"238.31"},{"asset_id":"17406866367975599232214757606801140480252276357934486651183783311435802862074","best_ask":"0.15","best_bid":"0.14","hash":"0fd028181f101da15811a486cfc505b935eeb60c","price":"0.15","side":"SELL","size":"238.31"}],"timestamp":"1786845519658"}}
{"f":987,"recv_ms":1786845520004,"raw":{"event_type":"price_change","market":"0xd5f15f31689703aea70b93a52194a0964220d10d92ee7497346f146a8b6ef8ab","price_changes":[{"asset_id":"2151378744569768920256500242561922410292857798164019061749528550808091180185","best_ask":"0.86","best_bid":"0.85","hash":"3e343e208ae35a1dd2b4b2489be4dfa9c93f2630","price":"0.85","side":"BUY","size":"248.31"},{"asset_id":"17406866367975599232214757606801140480252276357934486651183783311435802862074","best_ask":"0.15","best_bid":"0.14","hash":"dfec34bd03905d050c9ddce79362d924d5a44800","price":"0.15","side":"SELL","size":"248.31"}],"timestamp":"1786845519658"}}
{"f":988,"recv_ms":1786845520004,"raw":{"event_type":"price_change","market":"0xd5f15f31689703aea70b93a52194a0964220d10d92ee7497346f146a8b6ef8ab","price_changes":[{"asset_id":"2151378744569768920256500242561922410292857798164019061749528550808091180185","best_ask":"0.86","best_bid":"0.85","hash":"a4a291ffe471ef36e4714b4a70e479f05a7d31f0","price":"0.01","side":"BUY","size":"6298.58"},{"asset_id":"17406866367975599232214757606801140480252276357934486651183783311435802862074","best_ask":"0.15","best_bid":"0.14","hash":"d26f1ee3aea9d86f6cb138078e65f904753bb742","price":"0.99","side":"SELL","size":"6298.58"}],"timestamp":"1786845519659"}}
{"f":989,"recv_ms":1786845520004,"raw":{"event_type":"price_change","market":"0xd5f15f31689703aea70b93a52194a0964220d10d92ee7497346f146a8b6ef8ab","price_changes":[{"asset_id":"17406866367975599232214757606801140480252276357934486651183783311435802862074","best_ask":"0.15","best_bid":"0.14","hash":"875225ecf590723bd35c452855827b7251cbe6de","price":"0.15","side":"SELL","size":"253.31"},{"asset_id":"2151378744569768920256500242561922410292857798164019061749528550808091180185","best_ask":"0.86","best_bid":"0.85","hash":"511c501e3413920534be3846b4859fad7330c0d6","price":"0.85","side":"BUY","size":"253.31"}],"timestamp":"1786845519661"}}
{"f":990,"recv_ms":1786845520004,"raw":{"event_type":"price_change","market":"0xd5f15f31689703aea70b93a52194a0964220d10d92ee7497346f146a8b6ef8ab","price_changes":[{"asset_id":"17406866367975599232214757606801140480252276357934486651183783311435802862074","best_ask":"0.15","best_bid":"0.14","hash":"22731c123c5553cebd4b22ed49d18d18cf59aa15","price":"0.17","side":"SELL","size":"34.51"},{"asset_id":"2151378744569768920256500242561922410292857798164019061749528550808091180185","best_ask":"0.86","best_bid":"0.85","hash":"0d2cf66f543ef5cdfacc7fac752b8496fe18de92","price":"0.83","side":"BUY","size":"34.51"}],"timestamp":"1786845519662"}}
{"f":991,"recv_ms":1786845520004,"raw":{"event_type":"price_change","market":"0xd5f15f31689703aea70b93a52194a0964220d10d92ee7497346f146a8b6ef8ab","price_changes":[{"asset_id":"2151378744569768920256500242561922410292857798164019061749528550808091180185","best_ask":"0.86","best_bid":"0.85","hash":"af1bc741170ea44dfcf602c1c5dcd07e3672712a","price":"0.36","side":"BUY","size":"55.3"},{"asset_id":"17406866367975599232214757606801140480252276357934486651183783311435802862074","best_ask":"0.15","best_bid":"0.14","hash":"8e3e09c4fa9e4056efce9201695b3dcc3be2ba83","price":"0.64","side":"SELL","size":"55.3"}],"timestamp":"1786845519662"}}
{"f":992,"recv_ms":1786845520004,"raw":{"event_type":"price_change","market":"0xd5f15f31689703aea70b93a52194a0964220d10d92ee7497346f146a8b6ef8ab","price_changes":[{"asset_id":"2151378744569768920256500242561922410292857798164019061749528550808091180185","best_ask":"0.86","best_bid":"0.85","hash":"0dc7c5ad38fa27c875e29c200111a062ea14aad1","price":"0.64","side":"BUY","size":"246.49"},{"asset_id":"17406866367975599232214757606801140480252276357934486651183783311435802862074","best_ask":"0.15","best_bid":"0.14","hash":"375ede2f75d5ec8f4e0f8c24d3d8149edf2ea795","price":"0.36","side":"SELL","size":"246.49"}],"timestamp":"1786845519662"}}
{"f":993,"recv_ms":1786845520004,"raw":{"event_type":"price_change","market":"0xd5f15f31689703aea70b93a52194a0964220d10d92ee7497346f146a8b6ef8ab","price_changes":[{"asset_id":"17406866367975599232214757606801140480252276357934486651183783311435802862074","best_ask":"0.15","best_bid":"0.14","hash":"e17f159e73f376524b04ce4db37a576a96fa6c81","price":"0.17","side":"SELL","size":"28.51"},{"asset_id":"2151378744569768920256500242561922410292857798164019061749528550808091180185","best_ask":"0.86","best_bid":"0.85","hash":"612b754ac59d3a41ff6beb17b5642b320436ffb1","price":"0.83","side":"BUY","size":"28.51"}],"timestamp":"1786845519663"}}
{"f":994,"recv_ms":1786845520004,"raw":{"event_type":"price_change","market":"0xd5f15f31689703aea70b93a52194a0964220d10d92ee7497346f146a8b6ef8ab","price_changes":[{"asset_id":"2151378744569768920256500242561922410292857798164019061749528550808091180185","best_ask":"0.86","best_bid":"0.85","hash":"d1975e34879764e45dbcce2f58a79930f391f5fd","price":"0.01","side":"BUY","size":"6293.58"},{"asset_id":"17406866367975599232214757606801140480252276357934486651183783311435802862074","best_ask":"0.15","best_bid":"0.14","hash":"580338d2a6f62c830c6b2e2107a7b6f3988ca865","price":"0.99","side":"SELL","size":"6293.58"}],"timestamp":"1786845519663"}}
{"f":995,"recv_ms":1786845520004,"raw":{"event_type":"price_change","market":"0xd5f15f31689703aea70b93a52194a0964220d10d92ee7497346f146a8b6ef8ab","price_changes":[{"asset_id":"2151378744569768920256500242561922410292857798164019061749528550808091180185","best_ask":"0.86","best_bid":"0.85","hash":"f64b0a7ab67012aeadfd000144cdfd963014d40a","price":"0.01","side":"BUY","size":"6298.59"},{"asset_id":"17406866367975599232214757606801140480252276357934486651183783311435802862074","best_ask":"0.15","best_bid":"0.14","hash":"d789fc0c058ab06ca3459e853d7410ec2c673355","price":"0.99","side":"SELL","size":"6298.59"}],"timestamp":"1786845519663"}}
{"f":996,"recv_ms":1786845520004,"raw":{"event_type":"price_change","market":"0xd5f15f31689703aea70b93a52194a0964220d10d92ee7497346f146a8b6ef8ab","price_changes":[{"asset_id":"2151378744569768920256500242561922410292857798164019061749528550808091180185","best_ask":"0.86","best_bid":"0.85","hash":"04b198fb4ce9df4511fa441cd35e2c5e176d2976","price":"0.01","side":"BUY","size":"6293.58"},{"asset_id":"17406866367975599232214757606801140480252276357934486651183783311435802862074","best_ask":"0.15","best_bid":"0.14","hash":"6ec788146f0e74f03711f54c805b8d19f557f012","price":"0.99","side":"SELL","size":"6293.58"}],"timestamp":"1786845519664"}}
{"f":997,"recv_ms":1786845520004,"raw":{"event_type":"price_change","market":"0xd5f15f31689703aea70b93a52194a0964220d10d92ee7497346f146a8b6ef8ab","price_changes":[{"asset_id":"2151378744569768920256500242561922410292857798164019061749528550808091180185","best_ask":"0.86","best_bid":"0.85","hash":"e10d7caab1e9a14ba5380b55788478db5b31c3ad","price":"0.84","side":"BUY","size":"153"},{"asset_id":"17406866367975599232214757606801140480252276357934486651183783311435802862074","best_ask":"0.15","best_bid":"0.14","hash":"1cff5970475e5f89d85cdc90180770f986bb036e","price":"0.16","side":"SELL","size":"153"}],"timestamp":"1786845519665"}}
{"f":998,"recv_ms":1786845520004,"raw":{"event_type":"price_change","market":"0xd5f15f31689703aea70b93a52194a0964220d10d92ee7497346f146a8b6ef8ab","price_changes":[{"asset_id":"2151378744569768920256500242561922410292857798164019061749528550808091180185","best_ask":"0.86","best_bid":"0.85","hash":"2a7ad7cc9568d9d65f3b63c9211f05251cac27b9","price":"0.84","side":"BUY","size":"143"},{"asset_id":"17406866367975599232214757606801140480252276357934486651183783311435802862074","best_ask":"0.15","best_bid":"0.14","hash":"3dd0a90e199aaf56b48dee0b8d4ec4fae6861431","price":"0.16","side":"SELL","size":"143"}],"timestamp":"1786845519665"}}
{"f":999,"recv_ms":1786845520004,"raw":{"event_type":"price_change","market":"0xd5f15f31689703aea70b93a52194a0964220d10d92ee7497346f146a8b6ef8ab","price_changes":[{"asset_id":"17406866367975599232214757606801140480252276357934486651183783311435802862074","best_ask":"0.15","best_bid":"0.14","hash":"b4414f8dc1032ec88676c398c4d50f4a28eb3da2","price":"0.13","side":"BUY","size":"93"},{"asset_id":"2151378744569768920256500242561922410292857798164019061749528550808091180185","best_ask":"0.86","best_bid":"0.85","hash":"18d72ff02a947316942261fd7dbbbebd1f239c1d","price":"0.87","side":"SELL","size":"93"}],"timestamp":"1786845519665"}}
{"f":1000,"recv_ms":1786845520004,"raw":{"event_type":"price_change","market":"0xd5f15f31689703aea70b93a52194a0964220d10d92ee7497346f146a8b6ef8ab","price_changes":[{"asset_id":"2151378744569768920256500242561922410292857798164019061749528550808091180185","best_ask":"0.86","best_bid":"0.85","hash":"0537e26ea91d72f1dba9c1d4f57bdd406b93c7ec","price":"0.55","side":"BUY","size":"109"},{"asset_id":"17406866367975599232214757606801140480252276357934486651183783311435802862074","best_ask":"0.15","best_bid":"0.14","hash":"b4003efd0fe963eb8662d884e2693a654c51251e","price":"0.45","side":"SELL","size":"109"}],"timestamp":"1786845519666"}}
{"f":1001,"recv_ms":1786845520009,"raw":{"event_type":"price_change","market":"0xd5f15f31689703aea70b93a52194a0964220d10d92ee7497346f146a8b6ef8ab","price_changes":[{"asset_id":"2151378744569768920256500242561922410292857798164019061749528550808091180185","best_ask":"0.86","best_bid":"0.85","hash":"b57143d7aed98678ff0359aa7916b0a2750f9c61","price":"0.01","side":"BUY","size":"6298.58"},{"asset_id":"17406866367975599232214757606801140480252276357934486651183783311435802862074","best_ask":"0.15","best_bid":"0.14","hash":"10d62b8b379bf205d7dcae82b63c400f899378f8","price":"0.99","side":"SELL","size":"6298.58"}],"timestamp":"1786845519667"}}
{"f":1002,"recv_ms":1786845520009,"raw":{"event_type":"price_change","market":"0xd5f15f31689703aea70b93a52194a0964220d10d92ee7497346f146a8b6ef8ab","price_changes":[{"asset_id":"17406866367975599232214757606801140480252276357934486651183783311435802862074","best_ask":"0.15","best_bid":"0.14","hash":"9f925465028ce09b3bb3b85e546c54df51bd0db1","price":"0.17","side":"SELL","size":"22.51"},{"asset_id":"2151378744569768920256500242561922410292857798164019061749528550808091180185","best_ask":"0.86","best_bid":"0.85","hash":"28b5086304e59f8bba34056e32a24df055e460a3","price":"0.83","side":"BUY","size":"22.51"}],"timestamp":"1786845519667"}}
{"f":1003,"recv_ms":1786845520009,"raw":{"event_type":"price_change","market":"0xd5f15f31689703aea70b93a52194a0964220d10d92ee7497346f146a8b6ef8ab","price_changes":[{"asset_id":"2151378744569768920256500242561922410292857798164019061749528550808091180185","best_ask":"0.86","best_bid":"0.85","hash":"57021bcfe7a1c7e92fb9893fb9da00f77c731544","price":"0.85","side":"BUY","size":"263.31"},{"asset_id":"17406866367975599232214757606801140480252276357934486651183783311435802862074","best_ask":"0.15","best_bid":"0.14","hash":"4b4bab2262b341b288158e2848e6cf6af8eda346","price":"0.15","side":"SELL","size":"263.31"}],"timestamp":"1786845519668"}}
{"f":1004,"recv_ms":1786845520009,"raw":{"event_type":"price_change","market":"0xd5f15f31689703aea70b93a52194a0964220d10d92ee7497346f146a8b6ef8ab","price_changes":[{"asset_id":"2151378744569768920256500242561922410292857798164019061749528550808091180185","best_ask":"0.86","best_bid":"0.85","hash":"5a5dd95d4ebb605151dd759550266c3f9ee11b0d","price":"0.01","side":"BUY","size":"6293.57"},{"asset_id":"17406866367975599232214757606801140480252276357934486651183783311435802862074","best_ask":"0.15","best_bid":"0.14","hash":"a4ef49c1722942fed3aa2a3eaa37d3b3ce61fec3","price":"0.99","side":"SELL","size":"6293.57"}],"timestamp":"1786845519669"}}
{"f":1005,"recv_ms":1786845520009,"raw":{"event_type":"price_change","market":"0xd5f15f31689703aea70b93a52194a0964220d10d92ee7497346f146a8b6ef8ab","price_changes":[{"asset_id":"2151378744569768920256500242561922410292857798164019061749528550808091180185","best_ask":"0.86","best_bid":"0.85","hash":"09fcbe5ef71bd71f5159570839bcaa723d3a5bfd","price":"0.53","side":"BUY","size":"114"},{"asset_id":"17406866367975599232214757606801140480252276357934486651183783311435802862074","best_ask":"0.15","best_bid":"0.14","hash":"b887d758ba51e3666399971f54976453bfa53968","price":"0.47","side":"SELL","size":"114"}],"timestamp":"1786845519669"}}
{"f":1006,"recv_ms":1786845520009,"raw":{"event_type":"price_change","market":"0xd5f15f31689703aea70b93a52194a0964220d10d92ee7497346f146a8b6ef8ab","price_changes":[{"asset_id":"17406866367975599232214757606801140480252276357934486651183783311435802862074","best_ask":"0.15","best_bid":"0.14","hash":"d4605d03b92f7c5a566c8fc40aaedd95670a91ae","price":"0.08","side":"BUY","size":"83.29"},{"asset_id":"2151378744569768920256500242561922410292857798164019061749528550808091180185","best_ask":"0.86","best_bid":"0.85","hash":"e99dc786242a4cfd6d371c37007086a3e022eddb","price":"0.92","side":"SELL","size":"83.29"}],"timestamp":"1786845519670"}}
{"f":1007,"recv_ms":1786845520009,"raw":{"event_type":"price_change","market":"0xd5f15f31689703aea70b93a52194a0964220d10d92ee7497346f146a8b6ef8ab","price_changes":[{"asset_id":"2151378744569768920256500242561922410292857798164019061749528550808091180185","best_ask":"0.86","best_bid":"0.85","hash":"1b86dd9dc91128dde6e59679b8a1e93b19bce1fc","price":"0.72","side":"BUY","size":"20"},{"asset_id":"17406866367975599232214757606801140480252276357934486651183783311435802862074","best_ask":"0.15","best_bid":"0.14","hash":"0b9f2b3d90e4b514d63e3783a131c77a754ffb0c","price":"0.28","side":"SELL","size":"20"}],"timestamp":"1786845519670"}}
{"f":1008,"recv_ms":1786845520009,"raw":{"event_type":"price_change","market":"0xd5f15f31689703aea70b93a52194a0964220d10d92ee7497346f146a8b6ef8ab","price_changes":[{"asset_id":"2151378744569768920256500242561922410292857798164019061749528550808091180185","best_ask":"0.86","best_bid":"0.85","hash":"de33efe9f5854697143f36370222072010a790f8","price":"0.84","side":"BUY","size":"133"},{"asset_id":"17406866367975599232214757606801140480252276357934486651183783311435802862074","best_ask":"0.15","best_bid":"0.14","hash":"ba1355570616a45909f76d97884b2de0f59428f5","price":"0.16","side":"SELL","size":"133"}],"timestamp":"1786845519671"}}
{"f":1009,"recv_ms":1786845520009,"raw":{"event_type":"price_change","market":"0xd5f15f31689703aea70b93a52194a0964220d10d92ee7497346f146a8b6ef8ab","price_changes":[{"asset_id":"2151378744569768920256500242561922410292857798164019061749528550808091180185","best_ask":"0.86","best_bid":"0.85","hash":"46f5cdb2e419b01402b298755a143676656e3e1b","price":"0.01","side":"BUY","size":"6288.57"},{"asset_id":"17406866367975599232214757606801140480252276357934486651183783311435802862074","best_ask":"0.15","best_bid":"0.14","hash":"1c4d972d01722f6dea9fdb0e8b46bf9980f4251b","price":"0.99","side":"SELL","size":"6288.57"}],"timestamp":"1786845519671"}}
{"f":1010,"recv_ms":1786845520009,"raw":{"event_type":"price_change","market":"0xd5f15f31689703aea70b93a52194a0964220d10d92ee7497346f146a8b6ef8ab","price_changes":[{"asset_id":"2151378744569768920256500242561922410292857798164019061749528550808091180185","best_ask":"0.86","best_bid":"0.85","hash":"61da754ee71a15737a30155fee4574af72ee73c9","price":"0.01","side":"BUY","size":"6388.57"},{"asset_id":"17406866367975599232214757606801140480252276357934486651183783311435802862074","best_ask":"0.15","best_bid":"0.14","hash":"f176a9b2c2e390f09336a9bb9e464edbe879d14f","price":"0.99","side":"SELL","size":"6388.57"}],"timestamp":"1786845519671"}}
{"f":1011,"recv_ms":1786845520009,"raw":{"event_type":"price_change","market":"0xd5f15f31689703aea70b93a52194a0964220d10d92ee7497346f146a8b6ef8ab","price_changes":[{"asset_id":"17406866367975599232214757606801140480252276357934486651183783311435802862074","best_ask":"0.15","best_bid":"0.14","hash":"f20a5a7316c8f3736b5168d69310fbbc9cb0163c","price":"0.01","side":"BUY","size":"5593.18"},{"asset_id":"2151378744569768920256500242561922410292857798164019061749528550808091180185","best_ask":"0.86","best_bid":"0.85","hash":"07b7d255eb466f8cff5d0df3ae90a4312366f0d6","price":"0.99","side":"SELL","size":"5593.18"}],"timestamp":"1786845519672"}}
{"f":1012,"recv_ms":1786845520009,"raw":{"event_type":"price_change","market":"0xd5f15f31689703aea70b93a52194a0964220d10d92ee7497346f146a8b6ef8ab","price_changes":[{"asset_id":"17406866367975599232214757606801140480252276357934486651183783311435802862074","best_ask":"0.15","best_bid":"0.14","hash":"8f3fe8d3b48e464808a354aabbfade39929f9969","price":"0.16","side":"SELL","size":"138.66"},{"asset_id":"2151378744569768920256500242561922410292857798164019061749528550808091180185","best_ask":"0.86","best_bid":"0.85","hash":"03253ae8fc5288d8c6c634604f7449e760e8c9ac","price":"0.84","side":"BUY","size":"138.66"}],"timestamp":"1786845519673"}}
{"f":1013,"recv_ms":1786845520010,"raw":{"event_type":"price_change","market":"0xd5f15f31689703aea70b93a52194a0964220d10d92ee7497346f146a8b6ef8ab","price_changes":[{"asset_id":"2151378744569768920256500242561922410292857798164019061749528550808091180185","best_ask":"0.86","best_bid":"0.85","hash":"7c5d3c91dedafa7d28ee6575f78fa79a6bc8fa2f","price":"0.01","side":"BUY","size":"6393.58"},{"asset_id":"17406866367975599232214757606801140480252276357934486651183783311435802862074","best_ask":"0.15","best_bid":"0.14","hash":"75366ec9fc359d93d6bcec63d94ade597c45f87d","price":"0.99","side":"SELL","size":"6393.58"}],"timestamp":"1786845519674"}}
{"f":1014,"recv_ms":1786845520010,"raw":{"event_type":"price_change","market":"0xd5f15f31689703aea70b93a52194a0964220d10d92ee7497346f146a8b6ef8ab","price_changes":[{"asset_id":"2151378744569768920256500242561922410292857798164019061749528550808091180185","best_ask":"0.86","best_bid":"0.85","hash":"7c63a846c4a24de7f007df00bcdfee0ef48744ef","price":"0.21","side":"BUY","size":"20.7"},{"asset_id":"17406866367975599232214757606801140480252276357934486651183783311435802862074","best_ask":"0.15","best_bid":"0.14","hash":"a4f46ba6656257fde1e85bce303f596a539bbdbb","price":"0.79","side":"SELL","size":"20.7"}],"timestamp":"1786845519675"}}
{"f":1015,"recv_ms":1786845520010,"raw":{"event_type":"price_change","market":"0xd5f15f31689703aea70b93a52194a0964220d10d92ee7497346f146a8b6ef8ab","price_changes":[{"asset_id":"2151378744569768920256500242561922410292857798164019061749528550808091180185","best_ask":"0.86","best_bid":"0.85","hash":"4cf6be8e7b93b4845199efbeb7ed6a503c423556","price":"0.63","side":"BUY","size":"23.57"},{"asset_id":"17406866367975599232214757606801140480252276357934486651183783311435802862074","best_ask":"0.15","best_bid":"0.14","hash":"1a57f626d2056b2ddcd2b445b9542ee1ac796252","price":"0.37","side":"SELL","size":"23.57"}],"timestamp":"1786845519675"}}
{"f":1016,"recv_ms":1786845520010,"raw":{"event_type":"price_change","market":"0xd5f15f31689703aea70b93a52194a0964220d10d92ee7497346f146a8b6ef8ab","price_changes":[{"asset_id":"17406866367975599232214757606801140480252276357934486651183783311435802862074","best_ask":"0.15","best_bid":"0.14","hash":"8a64cc913411537deeace82e795e966017dd858b","price":"0.01","side":"BUY","size":"5693.18"},{"asset_id":"2151378744569768920256500242561922410292857798164019061749528550808091180185","best_ask":"0.86","best_bid":"0.85","hash":"191b7a70470e2d895e7bf22f352b7d9e9ea5f18e","price":"0.99","side":"SELL","size":"5693.18"}],"timestamp":"1786845519676"}}
{"f":1017,"recv_ms":1786845520010,"raw":{"asset_id":"2151378744569768920256500242561922410292857798164019061749528550808091180185","event_type":"last_trade_price","fee_rate_bps":"0","market":"0xd5f15f31689703aea70b93a52194a0964220d10d92ee7497346f146a8b6ef8ab","price":"0.84","side":"BUY","size":"36.072586","timestamp":"1786845519673","transaction_hash":"0x1b1216366045152896ff978540fe6313d6f2facbae2d5d48337da53e5f28d2ce"}}
{"f":1018,"recv_ms":1786845520010,"raw":{"event_type":"price_change","market":"0xd5f15f31689703aea70b93a52194a0964220d10d92ee7497346f146a8b6ef8ab","price_changes":[{"asset_id":"17406866367975599232214757606801140480252276357934486651183783311435802862074","best_ask":"0.15","best_bid":"0.14","hash":"adeb161f5513cc5e968bb9cb70c46af7c29e4f77","price":"0.36","side":"SELL","size":"252.49"},{"asset_id":"2151378744569768920256500242561922410292857798164019061749528550808091180185","best_ask":"0.86","best_bid":"0.85","hash":"a66f557acec4c896a43633f4585319d56c2a2721","price":"0.64","side":"BUY","size":"252.49"}],"timestamp":"1786845519677"}}
{"f":1019,"recv_ms":1786845520010,"raw":{"event_type":"price_change","market":"0xd5f15f31689703aea70b93a52194a0964220d10d92ee7497346f146a8b6ef8ab","price_changes":[{"asset_id":"2151378744569768920256500242561922410292857798164019061749528550808091180185","best_ask":"0.86","best_bid":"0.85","hash":"c93a7f150313996a13680c8063b6cd0edd82a5f2","price":"0.01","side":"BUY","size":"6388.57"},{"asset_id":"17406866367975599232214757606801140480252276357934486651183783311435802862074","best_ask":"0.15","best_bid":"0.14","hash":"e46aaa6b28e99425f0d448d51200235fdf6951a5","price":"0.99","side":"SELL","size":"6388.57"}],"timestamp":"1786845519678"}}
{"f":1020,"recv_ms":1786845520010,"raw":{"event_type":"price_change","market":"0xd5f15f31689703aea70b93a52194a0964220d10d92ee7497346f146a8b6ef8ab","price_changes":[{"asset_id":"2151378744569768920256500242561922410292857798164019061749528550808091180185","best_ask":"0.86","best_bid":"0.85","hash":"655531be1729413654cee7a7ea4d5ebc991a8af5","price":"0.85","side":"BUY","size":"273.31"},{"asset_id":"17406866367975599232214757606801140480252276357934486651183783311435802862074","best_ask":"0.15","best_bid":"0.14","hash":"6e7964ae72e160e79cdd320b5648bba5a1654639","price":"0.15","side":"SELL","size":"273.31"}],"timestamp":"1786845519679"}}
{"f":1021,"recv_ms":1786845520015,"raw":{"event_type":"price_change","market":"0xd5f15f31689703aea70b93a52194a0964220d10d92ee7497346f146a8b6ef8ab","price_changes":[{"asset_id":"2151378744569768920256500242561922410292857798164019061749528550808091180185","best_ask":"0.86","best_bid":"0.85","hash":"521fc1fe9a41cf8daeb98567e9cb1ee8750ec556","price":"0.01","side":"BUY","size":"6488.57"},{"asset_id":"17406866367975599232214757606801140480252276357934486651183783311435802862074","best_ask":"0.15","best_bid":"0.14","hash":"1d4fbf873bb018b7f2dd39070bfe6a6b7c36a365","price":"0.99","side":"SELL","size":"6488.57"}],"timestamp":"1786845519680"}}
{"f":1022,"recv_ms":1786845520015,"raw":{"event_type":"price_change","market":"0xd5f15f31689703aea70b93a52194a0964220d10d92ee7497346f146a8b6ef8ab","price_changes":[{"asset_id":"2151378744569768920256500242561922410292857798164019061749528550808091180185","best_ask":"0.86","best_bid":"0.85","hash":"f44f3e3f939ce0ac9b57273029908fb6d66f8b6e","price":"0.64","side":"BUY","size":"258.49"},{"asset_id":"17406866367975599232214757606801140480252276357934486651183783311435802862074","best_ask":"0.15","best_bid":"0.14","hash":"ea4b88e92ae761ed4bc27a9d5e869290e0f52224","price":"0.36","side":"SELL","size":"258.49"}],"timestamp":"1786845519681"}}
{"f":1023,"recv_ms":1786845520015,"raw":{"event_type":"price_change","market":"0xd5f15f31689703aea70b93a52194a0964220d10d92ee7497346f146a8b6ef8ab","price_changes":[{"asset_id":"2151378744569768920256500242561922410292857798164019061749528550808091180185","best_ask":"0.86","best_bid":"0.85","hash":"7e153d3e10232205e01fcba3eabb3b3ed51f54cb","price":"0.01","side":"BUY","size":"6483.56"},{"asset_id":"17406866367975599232214757606801140480252276357934486651183783311435802862074","best_ask":"0.15","best_bid":"0.14","hash":"02443bfe14c8d9177cdc1c045d9e90de50fbe956","price":"0.99","side":"SELL","size":"6483.56"}],"timestamp":"1786845519682"}}
{"f":1024,"recv_ms":1786845520015,"raw":{"event_type":"price_change","market":"0xd5f15f31689703aea70b93a52194a0964220d10d92ee7497346f146a8b6ef8ab","price_changes":[{"asset_id":"2151378744569768920256500242561922410292857798164019061749528550808091180185","best_ask":"0.86","best_bid":"0.85","hash":"9f1728cae6e64e7e1eb955535fdd0e3c607c641f","price":"0.01","side":"BUY","size":"6488.57"},{"asset_id":"17406866367975599232214757606801140480252276357934486651183783311435802862074","best_ask":"0.15","best_bid":"0.14","hash":"d7b8ec04ea8b654a63c8aafc934ad4901413ddea","price":"0.99","side":"SELL","size":"6488.57"}],"timestamp":"1786845519682"}}
{"f":1025,"recv_ms":1786845520015,"raw":{"event_type":"price_change","market":"0xd5f15f31689703aea70b93a52194a0964220d10d92ee7497346f146a8b6ef8ab","price_changes":[{"asset_id":"2151378744569768920256500242561922410292857798164019061749528550808091180185","best_ask":"0.86","best_bid":"0.85","hash":"9831d3e5aa4f8fe1aeea255b8f39a0429c965863","price":"0.85","side":"BUY","size":"283.31"},{"asset_id":"17406866367975599232214757606801140480252276357934486651183783311435802862074","best_ask":"0.15","best_bid":"0.14","hash":"ead03561ce82ee9a582b28af59e48b07449e9e5e","price":"0.15","side":"SELL","size":"283.31"}],"timestamp":"1786845519683"}}
{"f":1026,"recv_ms":1786845520015,"raw":{"event_type":"price_change","market":"0xd5f15f31689703aea70b93a52194a0964220d10d92ee7497346f146a8b6ef8ab","price_changes":[{"asset_id":"17406866367975599232214757606801140480252276357934486651183783311435802862074","best_ask":"0.15","best_bid":"0.14","hash":"4f16c02d262c78f1cb1131fb57efdde3dd6047b0","price":"0.16","side":"SELL","size":"121.66"},{"asset_id":"2151378744569768920256500242561922410292857798164019061749528550808091180185","best_ask":"0.86","best_bid":"0.85","hash":"91a9c775162acaed89ea7ac9b6f3088b8b36e619","price":"0.84","side":"BUY","size":"121.66"}],"timestamp":"1786845519684"}}
{"f":1027,"recv_ms":1786845520015,"raw":{"event_type":"price_change","market":"0xd5f15f31689703aea70b93a52194a0964220d10d92ee7497346f146a8b6ef8ab","price_changes":[{"asset_id":"2151378744569768920256500242561922410292857798164019061749528550808091180185","best_ask":"0.86","best_bid":"0.85","hash":"8fe67e5d1260fa5500cbd3b31628d18830b88f46","price":"0.54","side":"BUY","size":"9"},{"asset_id":"17406866367975599232214757606801140480252276357934486651183783311435802862074","best_ask":"0.15","best_bid":"0.14","hash":"0b2d8fc9190ab9d98cfcfa121d13769320f63529","price":"0.46","side":"SELL","size":"9"}],"timestamp":"1786845519684"}}
{"f":1028,"recv_ms":1786845520015,"raw":{"event_type":"price_change","market":"0xd5f15f31689703aea70b93a52194a0964220d10d92ee7497346f146a8b6ef8ab","price_changes":[{"asset_id":"2151378744569768920256500242561922410292857798164019061749528550808091180185","best_ask":"0.86","best_bid":"0.85","hash":"b6347bbed0f25caf19605a2c3a663cecf498d345","price":"0.7","side":"BUY","size":"50"},{"asset_id":"17406866367975599232214757606801140480252276357934486651183783311435802862074","best_ask":"0.15","best_bid":"0.14","hash":"b7648501ca4cf2c7716f338fd8a0fc724819b0da","price":"0.3","side":"SELL","size":"50"}],"timestamp":"1786845519684"}}
{"f":1029,"recv_ms":1786845520015,"raw":{"event_type":"price_change","market":"0xd5f15f31689703aea70b93a52194a0964220d10d92ee7497346f146a8b6ef8ab","price_changes":[{"asset_id":"2151378744569768920256500242561922410292857798164019061749528550808091180185","best_ask":"0.86","best_bid":"0.85","hash":"6d4cce61a489b4f761cb07f46f794f118b79b100","price":"0.78","side":"BUY","size":"7"},{"asset_id":"17406866367975599232214757606801140480252276357934486651183783311435802862074","best_ask":"0.15","best_bid":"0.14","hash":"ca44feb19e3b345cbd976eddfdb8fb6408c7aa06","price":"0.22","side":"SELL","size":"7"}],"timestamp":"1786845519685"}}
{"f":1030,"recv_ms":1786845520015,"raw":{"event_type":"price_change","market":"0xd5f15f31689703aea70b93a52194a0964220d10d92ee7497346f146a8b6ef8ab","price_changes":[{"asset_id":"2151378744569768920256500242561922410292857798164019061749528550808091180185","best_ask":"0.86","best_bid":"0.85","hash":"2070ddc7d901aa19c78c97d5fc5213188e7083d7","price":"0.01","side":"BUY","size":"6588.57"},{"asset_id":"17406866367975599232214757606801140480252276357934486651183783311435802862074","best_ask":"0.15","best_bid":"0.14","hash":"180a42a16b07d84105aa34337721c4ef49911429","price":"0.99","side":"SELL","size":"6588.57"}],"timestamp":"1786845519686"}}
{"f":1031,"recv_ms":1786845520015,"raw":{"event_type":"price_change","market":"0xd5f15f31689703aea70b93a52194a0964220d10d92ee7497346f146a8b6ef8ab","price_changes":[{"asset_id":"2151378744569768920256500242561922410292857798164019061749528550808091180185","best_ask":"0.86","best_bid":"0.85","hash":"b84a9f498a14c6fa8c1da9a8b793f6a43309d42e","price":"0.01","side":"BUY","size":"6583.56"},{"asset_id":"17406866367975599232214757606801140480252276357934486651183783311435802862074","best_ask":"0.15","best_bid":"0.14","hash":"bdcee9bf260e03f1e37090c32b60b5d174c1f8e1","price":"0.99","side":"SELL","size":"6583.56"}],"timestamp":"1786845519686"}}
{"f":1032,"recv_ms":1786845520015,"raw":{"event_type":"price_change","market":"0xd5f15f31689703aea70b93a52194a0964220d10d92ee7497346f146a8b6ef8ab","price_changes":[{"asset_id":"2151378744569768920256500242561922410292857798164019061749528550808091180185","best_ask":"0.86","best_bid":"0.85","hash":"61b7e9de5b43d7d39e2f2deecd6a27cff43d9fc4","price":"0.69","side":"BUY","size":"50"},{"asset_id":"17406866367975599232214757606801140480252276357934486651183783311435802862074","best_ask":"0.15","best_bid":"0.14","hash":"666672e6fdcbf4c4d4d04ba8d4166886dce0b245","price":"0.31","side":"SELL","size":"50"}],"timestamp":"1786845519687"}}
{"f":1033,"recv_ms":1786845520015,"raw":{"event_type":"price_change","market":"0xd5f15f31689703aea70b93a52194a0964220d10d92ee7497346f146a8b6ef8ab","price_changes":[{"asset_id":"2151378744569768920256500242561922410292857798164019061749528550808091180185","best_ask":"0.86","best_bid":"0.85","hash":"9362297b0581b689e00017c9ecaaceed511016e6","price":"0.85","side":"BUY","size":"293.31"},{"asset_id":"17406866367975599232214757606801140480252276357934486651183783311435802862074","best_ask":"0.15","best_bid":"0.14","hash":"4eacf9113d8ac58d3d7a2126f3aec366f6f7e63f","price":"0.15","side":"SELL","size":"293.31"}],"timestamp":"1786845519687"}}
{"f":1034,"recv_ms":1786845520015,"raw":{"event_type":"price_change","market":"0xd5f15f31689703aea70b93a52194a0964220d10d92ee7497346f146a8b6ef8ab","price_changes":[{"asset_id":"2151378744569768920256500242561922410292857798164019061749528550808091180185","best_ask":"0.86","best_bid":"0.85","hash":"8de3cd5fb54106242418cd2a9923d59d50de687a","price":"0.01","side":"BUY","size":"6683.56"},{"asset_id":"17406866367975599232214757606801140480252276357934486651183783311435802862074","best_ask":"0.15","best_bid":"0.14","hash":"32e369164f37fb5c8024e58d42aeaa7f30eaff81","price":"0.99","side":"SELL","size":"6683.56"}],"timestamp":"1786845519688"}}
{"f":1035,"recv_ms":1786845520019,"raw":{"event_type":"price_change","market":"0xd5f15f31689703aea70b93a52194a0964220d10d92ee7497346f146a8b6ef8ab","price_changes":[{"asset_id":"2151378744569768920256500242561922410292857798164019061749528550808091180185","best_ask":"0.86","best_bid":"0.85","hash":"0cc75f653871f8ff6544e680972761901eb4ce3a","price":"0.01","side":"BUY","size":"6688.56"},{"asset_id":"17406866367975599232214757606801140480252276357934486651183783311435802862074","best_ask":"0.15","best_bid":"0.14","hash":"c76d6e6c1dd9255b934d9deef7caf3a84111d073","price":"0.99","side":"SELL","size":"6688.56"}],"timestamp":"1786845519689"}}
{"f":1036,"recv_ms":1786845520019,"raw":{"event_type":"price_change","market":"0xd5f15f31689703aea70b93a52194a0964220d10d92ee7497346f146a8b6ef8ab","price_changes":[{"asset_id":"2151378744569768920256500242561922410292857798164019061749528550808091180185","best_ask":"0.86","best_bid":"0.85","hash":"b22eab67c7d337a12e70a30eb9b67d0a0c439c49","price":"0.85","side":"BUY","size":"303.31"},{"asset_id":"17406866367975599232214757606801140480252276357934486651183783311435802862074","best_ask":"0.15","best_bid":"0.14","hash":"3bb187b8ab7fb99824738a86346bfce3c43a57a5","price":"0.15","side":"SELL","size":"303.31"}],"timestamp":"1786845519690"}}
{"f":1037,"recv_ms":1786845520019,"raw":{"event_type":"price_change","market":"0xd5f15f31689703aea70b93a52194a0964220d10d92ee7497346f146a8b6ef8ab","price_changes":[{"asset_id":"17406866367975599232214757606801140480252276357934486651183783311435802862074","best_ask":"0.15","best_bid":"0.14","hash":"680faba833c96cee0e259ecc8357b5bba64ac173","price":"0.07","side":"BUY","size":"449.86"},{"asset_id":"2151378744569768920256500242561922410292857798164019061749528550808091180185","best_ask":"0.86","best_bid":"0.85","hash":"7c953739ee7021b5eea5bade81d09a25e96721fd","price":"0.93","side":"SELL","size":"449.86"}],"timestamp":"1786845519691"}}
{"f":1038,"recv_ms":1786845520019,"raw":{"event_type":"price_change","market":"0xd5f15f31689703aea70b93a52194a0964220d10d92ee7497346f146a8b6ef8ab","price_changes":[{"asset_id":"2151378744569768920256500242561922410292857798164019061749528550808091180185","best_ask":"0.86","best_bid":"0.85","hash":"b3fa78ad9e8c5f13937b29ededd3a217f5fbe32f","price":"0.84","side":"BUY","size":"71.66"},{"asset_id":"17406866367975599232214757606801140480252276357934486651183783311435802862074","best_ask":"0.15","best_bid":"0.14","hash":"c7141cb4e95cdf6bd3e0ceb1e7a3a01cda1f44d3","price":"0.16","side":"SELL","size":"71.66"}],"timestamp":"1786845519693"}}
{"f":1039,"recv_ms":1786845520019,"raw":{"event_type":"price_change","market":"0xd5f15f31689703aea70b93a52194a0964220d10d92ee7497346f146a8b6ef8ab","price_changes":[{"asset_id":"17406866367975599232214757606801140480252276357934486651183783311435802862074","best_ask":"0.15","best_bid":"0.14","hash":"19c568b297ebb9d9032b88032cb2d06ccc5a5413","price":"0.16","side":"SELL","size":"66.66"},{"asset_id":"2151378744569768920256500242561922410292857798164019061749528550808091180185","best_ask":"0.86","best_bid":"0.85","hash":"6a402a931376a00ad1fc46e3e3897500232aa748","price":"0.84","side":"BUY","size":"66.66"}],"timestamp":"1786845519693"}}
{"f":1040,"recv_ms":1786845520019,"raw":{"event_type":"price_change","market":"0xd5f15f31689703aea70b93a52194a0964220d10d92ee7497346f146a8b6ef8ab","price_changes":[{"asset_id":"2151378744569768920256500242561922410292857798164019061749528550808091180185","best_ask":"0.86","best_bid":"0.85","hash":"ac4954718114a6d1736855cc7f32634330745753","price":"0.73","side":"BUY","size":"12"},{"asset_id":"17406866367975599232214757606801140480252276357934486651183783311435802862074","best_ask":"0.15","best_bid":"0.14","hash":"bcd0183a69b9684c27e1930f33a0d83b4e40479f","price":"0.27","side":"SELL","size":"12"}],"timestamp":"1786845519693"}}
{"f":1041,"recv_ms":1786845520019,"raw":{"event_type":"price_change","market":"0xd5f15f31689703aea70b93a52194a0964220d10d92ee7497346f146a8b6ef8ab","price_changes":[{"asset_id":"2151378744569768920256500242561922410292857798164019061749528550808091180185","best_ask":"0.86","best_bid":"0.85","hash":"2d66cf59af7339555442e1d03e5be3dee1e76c16","price":"0.01","side":"BUY","size":"6788.56"},{"asset_id":"17406866367975599232214757606801140480252276357934486651183783311435802862074","best_ask":"0.15","best_bid":"0.14","hash":"f08fa1c01a23eac21bc847b0cb361b9166b818d4","price":"0.99","side":"SELL","size":"6788.56"}],"timestamp":"1786845519693"}}
{"f":1042,"recv_ms":1786845520019,"raw":{"event_type":"price_change","market":"0xd5f15f31689703aea70b93a52194a0964220d10d92ee7497346f146a8b6ef8ab","price_changes":[{"asset_id":"2151378744569768920256500242561922410292857798164019061749528550808091180185","best_ask":"0.86","best_bid":"0.85","hash":"c47283f5d175ac498d0047f627e10eb8c0e930cd","price":"0.01","side":"BUY","size":"6783.55"},{"asset_id":"17406866367975599232214757606801140480252276357934486651183783311435802862074","best_ask":"0.15","best_bid":"0.14","hash":"a42c9dfe90c4170e11ec02012e75802d72c1b631","price":"0.99","side":"SELL","size":"6783.55"}],"timestamp":"1786845519694"}}
{"f":1043,"recv_ms":1786845520019,"raw":{"event_type":"price_change","market":"0xd5f15f31689703aea70b93a52194a0964220d10d92ee7497346f146a8b6ef8ab","price_changes":[{"asset_id":"17406866367975599232214757606801140480252276357934486651183783311435802862074","best_ask":"0.15","best_bid":"0.14","hash":"25e0206f84125415811d0280280dacbe71de83e3","price":"0.07","side":"BUY","size":"464.86"},{"asset_id":"2151378744569768920256500242561922410292857798164019061749528550808091180185","best_ask":"0.86","best_bid":"0.85","hash":"349a4080b4bb918319abd9d3f00aaffc2eaa2676","price":"0.93","side":"SELL","size":"464.86"}],"timestamp":"1786845519695"}}
{"f":1044,"recv_ms":1786845520020,"raw":{"event_type":"price_change","market":"0xd5f15f31689703aea70b93a52194a0964220d10d92ee7497346f146a8b6ef8ab","price_changes":[{"asset_id":"17406866367975599232214757606801140480252276357934486651183783311435802862074","best_ask":"0.15","best_bid":"0.14","hash":"0a6e72bcf920cbc067871d41dd6a19412178e7c8","price":"0.01","side":"BUY","size":"5688.18"},{"asset_id":"2151378744569768920256500242561922410292857798164019061749528550808091180185","best_ask":"0.86","best_bid":"0.85","hash":"592e5ab7de6a5a5239f5424403409f0e3e0bd039","price":"0.99","side":"SELL","size":"5688.18"}],"timestamp":"1786845519695"}}
{"f":1045,"recv_ms":1786845520020,"raw":{"event_type":"price_change","market":"0xd5f15f31689703aea70b93a52194a0964220d10d92ee7497346f146a8b6ef8ab","price_changes":[{"asset_id":"2151378744569768920256500242561922410292857798164019061749528550808091180185","best_ask":"0.86","best_bid":"0.85","hash":"d5f1a292c3b738c03bbea5d8560d1d6030374bb1","price":"0.01","side":"BUY","size":"6883.55"},{"asset_id":"17406866367975599232214757606801140480252276357934486651183783311435802862074","best_ask":"0.15","best_bid":"0.14","hash":"8c460ebac7d3964aadb789066418c209be3334a4","price":"0.99","side":"SELL","size":"6883.55"}],"timestamp":"1786845519696"}}
{"f":1046,"recv_ms":1786845520020,"raw":{"event_type":"price_change","market":"0xd5f15f31689703aea70b93a52194a0964220d10d92ee7497346f146a8b6ef8ab","price_changes":[{"asset_id":"2151378744569768920256500242561922410292857798164019061749528550808091180185","best_ask":"0.86","best_bid":"0.85","hash":"54d952dbc6edd0cabe5f7ada4cda87556d0db0be","price":"0.01","side":"BUY","size":"6878.55"},{"asset_id":"17406866367975599232214757606801140480252276357934486651183783311435802862074","best_ask":"0.15","best_bid":"0.14","hash":"b5ab0003512d3e647faa6c4ac4bc433f2a8b06e2","price":"0.99","side":"SELL","size":"6878.55"}],"timestamp":"1786845519696"}}
{"f":1047,"recv_ms":1786845520020,"raw":{"event_type":"price_change","market":"0xd5f15f31689703aea70b93a52194a0964220d10d92ee7497346f146a8b6ef8ab","price_changes":[{"asset_id":"2151378744569768920256500242561922410292857798164019061749528550808091180185","best_ask":"0.86","best_bid":"0.85","hash":"7cb67c9166d88f1f40a23f77c9cd2cf06fb0acf1","price":"0.77","side":"BUY","size":"145"},{"asset_id":"17406866367975599232214757606801140480252276357934486651183783311435802862074","best_ask":"0.15","best_bid":"0.14","hash":"6cbfc9abe64f8d8d02daa8d79c6cf2a035e5c3a0","price":"0.23","side":"SELL","size":"145"}],"timestamp":"1786845519697"}}
{"f":1048,"recv_ms":1786845520020,"raw":{"event_type":"price_change","market":"0xd5f15f31689703aea70b93a52194a0964220d10d92ee7497346f146a8b6ef8ab","price_changes":[{"asset_id":"2151378744569768920256500242561922410292857798164019061749528550808091180185","best_ask":"0.86","best_bid":"0.85","hash":"8ffeb83a9138e61dde45073585c65ce045560ef5","price":"0.01","side":"BUY","size":"6978.55"},{"asset_id":"17406866367975599232214757606801140480252276357934486651183783311435802862074","best_ask":"0.15","best_bid":"0.14","hash":"5dbbae0d46dcb65cb06bfecb6961c843f4b88696","price":"0.99","side":"SELL","size":"6978.55"}],"timestamp":"1786845519698"}}
{"f":1049,"recv_ms":1786845520020,"raw":{"event_type":"price_change","market":"0xd5f15f31689703aea70b93a52194a0964220d10d92ee7497346f146a8b6ef8ab","price_changes":[{"asset_id":"2151378744569768920256500242561922410292857798164019061749528550808091180185","best_ask":"0.86","best_bid":"0.85","hash":"9d3354d49dcee6ce957e45cdfbe5d0dde4e4d4e2","price":"0.53","side":"BUY","size":"14"},{"asset_id":"17406866367975599232214757606801140480252276357934486651183783311435802862074","best_ask":"0.15","best_bid":"0.14","hash":"6949da538898ce0115e955b94678c2bcf42ede17","price":"0.47","side":"SELL","size":"14"}],"timestamp":"1786845519699"}}
{"f":1050,"recv_ms":1786845520020,"raw":{"event_type":"price_change","market":"0xd5f15f31689703aea70b93a52194a0964220d10d92ee7497346f146a8b6ef8ab","price_changes":[{"asset_id":"2151378744569768920256500242561922410292857798164019061749528550808091180185","best_ask":"0.86","best_bid":"0.85","hash":"7939e38f94f0f6e977aab3a76d09cc78bb04c66a","price":"0.75","side":"BUY","size":"127.9"},{"asset_id":"17406866367975599232214757606801140480252276357934486651183783311435802862074","best_ask":"0.15","best_bid":"0.14","hash":"ef7b503384bf4fad9f0b756670e5e43f01cdae37","price":"0.25","side":"SELL","size":"127.9"}],"timestamp":"1786845519699"}}
{"f":1051,"recv_ms":1786845520020,"raw":{"event_type":"price_change","market":"0xd5f15f31689703aea70b93a52194a0964220d10d92ee7497346f146a8b6ef8ab","price_changes":[{"asset_id":"2151378744569768920256500242561922410292857798164019061749528550808091180185","best_ask":"0.86","best_bid":"0.85","hash":"2d4cde274620ae15ed54432ea633e6dfb02dabee","price":"0.01","side":"BUY","size":"7078.55"},{"asset_id":"17406866367975599232214757606801140480252276357934486651183783311435802862074","best_ask":"0.15","best_bid":"0.14","hash":"0765b2a55f351399a585df57f2c215dc9a7d0d71","price":"0.99","side":"SELL","size":"7078.55"}],"timestamp":"1786845519700"}}
{"f":1052,"recv_ms":1786845520020,"raw":{"event_type":"price_change","market":"0xd5f15f31689703aea70b93a52194a0964220d10d92ee7497346f146a8b6ef8ab","price_changes":[{"asset_id":"2151378744569768920256500242561922410292857798164019061749528550808091180185","best_ask":"0.86","best_bid":"0.85","hash":"93ba36335efa378796549aa02f6c36297959c32b","price":"0.76","side":"BUY","size":"30"},{"asset_id":"17406866367975599232214757606801140480252276357934486651183783311435802862074","best_ask":"0.15","best_bid":"0.14","hash":"8de61e5e5f76a45c4915799cae360a5a3e1bea82","price":"0.24","side":"SELL","size":"30"}],"timestamp":"1786845519701"}}
{"f":1053,"recv_ms":1786845520020,"raw":{"event_type":"price_change","market":"0xd5f15f31689703aea70b93a52194a0964220d10d92ee7497346f146a8b6ef8ab","price_changes":[{"asset_id":"2151378744569768920256500242561922410292857798164019061749528550808091180185","best_ask":"0.86","best_bid":"0.85","hash":"dacd167b77ca8c4ce2b853ddcd51ccf11e4e1c00","price":"0.01","side":"BUY","size":"7178.55"},{"asset_id":"17406866367975599232214757606801140480252276357934486651183783311435802862074","best_ask":"0.15","best_bid":"0.14","hash":"d99c650b74d0b4dbccaadf5f3ec65cac12b18eeb","price":"0.99","side":"SELL","size":"7178.55"}],"timestamp":"1786845519702"}}
{"f":1054,"recv_ms":1786845520020,"raw":{"event_type":"price_change","market":"0xd5f15f31689703aea70b93a52194a0964220d10d92ee7497346f146a8b6ef8ab","price_changes":[{"asset_id":"17406866367975599232214757606801140480252276357934486651183783311435802862074","best_ask":"0.15","best_bid":"0.14","hash":"ec06dc5d9f39c4a65936982b673bd45dc3c46ce1","price":"0.06","side":"BUY","size":"483.1"},{"asset_id":"2151378744569768920256500242561922410292857798164019061749528550808091180185","best_ask":"0.86","best_bid":"0.85","hash":"7ff69fc77421270f88e20d97f06a2f66186d2cb2","price":"0.94","side":"SELL","size":"483.1"}],"timestamp":"1786845519703"}}
{"f":1055,"recv_ms":1786845520020,"raw":{"event_type":"price_change","market":"0xd5f15f31689703aea70b93a52194a0964220d10d92ee7497346f146a8b6ef8ab","price_changes":[{"asset_id":"2151378744569768920256500242561922410292857798164019061749528550808091180185","best_ask":"0.86","best_bid":"0.85","hash":"64a489037dfed3f0d269c0d8a249ebbab55b2c54","price":"0.01","side":"BUY","size":"7278.55"},{"asset_id":"17406866367975599232214757606801140480252276357934486651183783311435802862074","best_ask":"0.15","best_bid":"0.14","hash":"4d79a936c2362eccd91239a1a33eae110f904a21","price":"0.99","side":"SELL","size":"7278.55"}],"timestamp":"1786845519704"}}
{"f":1056,"recv_ms":1786845520020,"raw":{"event_type":"price_change","market":"0xd5f15f31689703aea70b93a52194a0964220d10d92ee7497346f146a8b6ef8ab","price_changes":[{"asset_id":"2151378744569768920256500242561922410292857798164019061749528550808091180185","best_ask":"0.86","best_bid":"0.85","hash":"8de6e4cda8015c3000599acaaec7d3a02e72cb06","price":"0.71","side":"BUY","size":"15"},{"asset_id":"17406866367975599232214757606801140480252276357934486651183783311435802862074","best_ask":"0.15","best_bid":"0.14","hash":"5d0bf2f971b2a9e455c24c496e7a137a80887ad4","price":"0.29","side":"SELL","size":"15"}],"timestamp":"1786845519705"}}
{"f":1057,"recv_ms":1786845520020,"raw":{"event_type":"price_change","market":"0xd5f15f31689703aea70b93a52194a0964220d10d92ee7497346f146a8b6ef8ab","price_changes":[{"asset_id":"2151378744569768920256500242561922410292857798164019061749528550808091180185","best_ask":"0.86","best_bid":"0.85","hash":"2005306326d72b00589844e4d2c6cd85a0daf901","price":"0.01","side":"BUY","size":"7378.55"},{"asset_id":"17406866367975599232214757606801140480252276357934486651183783311435802862074","best_ask":"0.15","best_bid":"0.14","hash":"6c423590d188331f0e3449987811f9063d90970b","price":"0.99","side":"SELL","size":"7378.55"}],"timestamp":"1786845519706"}}
{"f":1058,"recv_ms":1786845520020,"raw":{"event_type":"price_change","market":"0xd5f15f31689703aea70b93a52194a0964220d10d92ee7497346f146a8b6ef8ab","price_changes":[{"asset_id":"2151378744569768920256500242561922410292857798164019061749528550808091180185","best_ask":"0.86","best_bid":"0.85","hash":"80f91e4e10226c839d7c45748f9df8ba3a6c742f","price":"0.01","side":"BUY","size":"7373.54"},{"asset_id":"17406866367975599232214757606801140480252276357934486651183783311435802862074","best_ask":"0.15","best_bid":"0.14","hash":"0947ecdad445ea9022d3e46bf5ef7cc0adefde0e","price":"0.99","side":"SELL","size":"7373.54"}],"timestamp":"1786845519707"}}
{"f":1059,"recv_ms":1786845520025,"raw":{"event_type":"price_change","market":"0xd5f15f31689703aea70b93a52194a0964220d10d92ee7497346f146a8b6ef8ab","price_changes":[{"asset_id":"2151378744569768920256500242561922410292857798164019061749528550808091180185","best_ask":"0.86","best_bid":"0.85","hash":"92f7bebc0ed76af6379758fdbcb9d38a14db1310","price":"0.57","side":"BUY","size":"64"},{"asset_id":"17406866367975599232214757606801140480252276357934486651183783311435802862074","best_ask":"0.15","best_bid":"0.14","hash":"11515e7181a9d488c675519afcd1e37f983a0a21","price":"0.43","side":"SELL","size":"64"}],"timestamp":"1786845519707"}}
{"f":1060,"recv_ms":1786845520025,"raw":{"event_type":"price_change","market":"0xd5f15f31689703aea70b93a52194a0964220d10d92ee7497346f146a8b6ef8ab","price_changes":[{"asset_id":"2151378744569768920256500242561922410292857798164019061749528550808091180185","best_ask":"0.86","best_bid":"0.85","hash":"a31e5edbcb8fe5143a8e1acaa0fca3b5cebe62e7","price":"0.01","side":"BUY","size":"7473.54"},{"asset_id":"17406866367975599232214757606801140480252276357934486651183783311435802862074","best_ask":"0.15","best_bid":"0.14","hash":"f4e842882c5ab29a10b6f18e7eeb880d32fae18c","price":"0.99","side":"SELL","size":"7473.54"}],"timestamp":"1786845519708"}}
{"f":1061,"recv_ms":1786845520025,"raw":{"event_type":"price_change","market":"0xd5f15f31689703aea70b93a52194a0964220d10d92ee7497346f146a8b6ef8ab","price_changes":[{"asset_id":"2151378744569768920256500242561922410292857798164019061749528550808091180185","best_ask":"0.86","best_bid":"0.85","hash":"a1726e72034e6995af6284cf64a700566ef3e8f6","price":"0.56","side":"BUY","size":"49"},{"asset_id":"17406866367975599232214757606801140480252276357934486651183783311435802862074","best_ask":"0.15","best_bid":"0.14","hash":"743db6ccc0c5bdc0a4a9a75a9e0e28e2169b7a05","price":"0.44","side":"SELL","size":"49"}],"timestamp":"1786845519709"}}
{"f":1062,"recv_ms":1786845520028,"raw":{"event_type":"price_change","market":"0xd5f15f31689703aea70b93a52194a0964220d10d92ee7497346f146a8b6ef8ab","price_changes":[{"asset_id":"2151378744569768920256500242561922410292857798164019061749528550808091180185","best_ask":"0.86","best_bid":"0.85","hash":"3cf134913bc176de0e6378684ad2dbadc52e9662","price":"0.01","side":"BUY","size":"7573.54"},{"asset_id":"17406866367975599232214757606801140480252276357934486651183783311435802862074","best_ask":"0.15","best_bid":"0.14","hash":"59845f575042e8cfd8c45620f75370bd079e56d5","price":"0.99","side":"SELL","size":"7573.54"}],"timestamp":"1786845519710"}}
{"f":1063,"recv_ms":1786845520028,"raw":{"event_type":"price_change","market":"0xd5f15f31689703aea70b93a52194a0964220d10d92ee7497346f146a8b6ef8ab","price_changes":[{"asset_id":"2151378744569768920256500242561922410292857798164019061749528550808091180185","best_ask":"0.86","best_bid":"0.85","hash":"135957d236b02a1585f1d9eb42747017b44cac1b","price":"0.72","side":"BUY","size":"30"},{"asset_id":"17406866367975599232214757606801140480252276357934486651183783311435802862074","best_ask":"0.15","best_bid":"0.14","hash":"f344a5daba8c285008cfac7f001ba4d5238da1f2","price":"0.28","side":"SELL","size":"30"}],"timestamp":"1786845519711"}}
{"f":1064,"recv_ms":1786845520028,"raw":{"event_type":"price_change","market":"0xd5f15f31689703aea70b93a52194a0964220d10d92ee7497346f146a8b6ef8ab","price_changes":[{"asset_id":"2151378744569768920256500242561922410292857798164019061749528550808091180185","best_ask":"0.86","best_bid":"0.85","hash":"73249d19a5ea2a484a2cfd9763822c250e7142c1","price":"0.01","side":"BUY","size":"7673.54"},{"asset_id":"17406866367975599232214757606801140480252276357934486651183783311435802862074","best_ask":"0.15","best_bid":"0.14","hash":"51b1f4cd5726b7216718c0c49b2a228197775a28","price":"0.99","side":"SELL","size":"7673.54"}],"timestamp":"1786845519711"}}
{"f":1065,"recv_ms":1786845520028,"raw":{"event_type":"price_change","market":"0xd5f15f31689703aea70b93a52194a0964220d10d92ee7497346f146a8b6ef8ab","price_changes":[{"asset_id":"2151378744569768920256500242561922410292857798164019061749528550808091180185","best_ask":"0.86","best_bid":"0.85","hash":"4411709683d5bdf8a0a275930f4e79df5efd4755","price":"0.01","side":"BUY","size":"7668.54"},{"asset_id":"17406866367975599232214757606801140480252276357934486651183783311435802862074","best_ask":"0.15","best_bid":"0.14","hash":"58d3052837fbf634885264ea09fd056ab8ef4397","price":"0.99","side":"SELL","size":"7668.54"}],"timestamp":"1786845519712"}}
{"f":1066,"recv_ms":1786845520028,"raw":{"event_type":"price_change","market":"0xd5f15f31689703aea70b93a52194a0964220d10d92ee7497346f146a8b6ef8ab","price_changes":[{"asset_id":"2151378744569768920256500242561922410292857798164019061749528550808091180185","best_ask":"0.86","best_bid":"0.85","hash":"3a4037ff48ca4f18cd0da12752cfc202fe368d7e","price":"0.01","side":"BUY","size":"7768.54"},{"asset_id":"17406866367975599232214757606801140480252276357934486651183783311435802862074","best_ask":"0.15","best_bid":"0.14","hash":"e44908560327bd4a4ef9ca242a10915c4deaae55","price":"0.99","side":"SELL","size":"7768.54"}],"timestamp":"1786845519713"}}
{"f":1067,"recv_ms":1786845520028,"raw":{"event_type":"price_change","market":"0xd5f15f31689703aea70b93a52194a0964220d10d92ee7497346f146a8b6ef8ab","price_changes":[{"asset_id":"2151378744569768920256500242561922410292857798164019061749528550808091180185","best_ask":"0.86","best_bid":"0.85","hash":"2dc1039c778285890302cd3431caffb79dd15969","price":"0.84","side":"BUY","size":"72.38"},{"asset_id":"17406866367975599232214757606801140480252276357934486651183783311435802862074","best_ask":"0.15","best_bid":"0.14","hash":"de5a710fe7c5dd2e3c71e57959109f40b89854c7","price":"0.16","side":"SELL","size":"72.38"}],"timestamp":"1786845519714"}}
{"f":1068,"recv_ms":1786845520028,"raw":{"event_type":"price_change","market":"0xd5f15f31689703aea70b93a52194a0964220d10d92ee7497346f146a8b6ef8ab","price_changes":[{"asset_id":"2151378744569768920256500242561922410292857798164019061749528550808091180185","best_ask":"0.86","best_bid":"0.85","hash":"18ae0beb3c86f06066bc579fe0ac625ae0618882","price":"0.01","side":"BUY","size":"7868.54"},{"asset_id":"17406866367975599232214757606801140480252276357934486651183783311435802862074","best_ask":"0.15","best_bid":"0.14","hash":"8d24a24a31b81a0de323cc2246353fa4e3e1a7e4","price":"0.99","side":"SELL","size":"7868.54"}],"timestamp":"1786845519714"}}
{"f":1069,"recv_ms":1786845520028,"raw":{"event_type":"price_change","market":"0xd5f15f31689703aea70b93a52194a0964220d10d92ee7497346f146a8b6ef8ab","price_changes":[{"asset_id":"2151378744569768920256500242561922410292857798164019061749528550808091180185","best_ask":"0.86","best_bid":"0.85","hash":"dc68f736b3fee74e6a9254ac1702ad9d21cce60b","price":"0.01","side":"BUY","size":"7863.53"},{"asset_id":"17406866367975599232214757606801140480252276357934486651183783311435802862074","best_ask":"0.15","best_bid":"0.14","hash":"e4dc901ade3f5ac3a33bbadc01503ffa011ef78a","price":"0.99","side":"SELL","size":"7863.53"}],"timestamp":"1786845519715"}}
{"f":1070,"recv_ms":1786845520028,"raw":{"event_type":"price_change","market":"0xd5f15f31689703aea70b93a52194a0964220d10d92ee7497346f146a8b6ef8ab","price_changes":[{"asset_id":"2151378744569768920256500242561922410292857798164019061749528550808091180185","best_ask":"0.86","best_bid":"0.85","hash":"66ba39d77336bfea692b6a7c00b10055f3b94ef0","price":"0.7","side":"BUY","size":"40"},{"asset_id":"17406866367975599232214757606801140480252276357934486651183783311435802862074","best_ask":"0.15","best_bid":"0.14","hash":"a00abefcc9204307f99300eb0ed099a2b6e1e24e","price":"0.3","side":"SELL","size":"40"}],"timestamp":"1786845519716"}}
{"f":1071,"recv_ms":1786845520028,"raw":{"event_type":"price_change","market":"0xd5f15f31689703aea70b93a52194a0964220d10d92ee7497346f146a8b6ef8ab","price_changes":[{"asset_id":"2151378744569768920256500242561922410292857798164019061749528550808091180185","best_ask":"0.86","best_bid":"0.85","hash":"2408b94b02b8552648ac0a35769a83d96efef3d0","price":"0.01","side":"BUY","size":"7963.53"},{"asset_id":"17406866367975599232214757606801140480252276357934486651183783311435802862074","best_ask":"0.15","best_bid":"0.14","hash":"df4c8ca08ab548c5aa80c5474cc1afb9a9d697b1","price":"0.99","side":"SELL","size":"7963.53"}],"timestamp":"1786845519716"}}
{"f":1072,"recv_ms":1786845520028,"raw":{"event_type":"price_change","market":"0xd5f15f31689703aea70b93a52194a0964220d10d92ee7497346f146a8b6ef8ab","price_changes":[{"asset_id":"2151378744569768920256500242561922410292857798164019061749528550808091180185","best_ask":"0.86","best_bid":"0.85","hash":"da2fcd89292862e7468cf8b5840eae47a3c1296e","price":"0.01","side":"BUY","size":"8063.53"},{"asset_id":"17406866367975599232214757606801140480252276357934486651183783311435802862074","best_ask":"0.15","best_bid":"0.14","hash":"05c30e9ae2119e4256ed763a10eb3c8c21e787d1","price":"0.99","side":"SELL","size":"8063.53"}],"timestamp":"1786845519717"}}
{"f":1073,"recv_ms":1786845520028,"raw":{"event_type":"price_change","market":"0xd5f15f31689703aea70b93a52194a0964220d10d92ee7497346f146a8b6ef8ab","price_changes":[{"asset_id":"17406866367975599232214757606801140480252276357934486651183783311435802862074","best_ask":"0.15","best_bid":"0.14","hash":"d69e01a754e9d5189bd9b4ac44939ff2e2a75939","price":"0.01","side":"BUY","size":"5588.18"},{"asset_id":"2151378744569768920256500242561922410292857798164019061749528550808091180185","best_ask":"0.86","best_bid":"0.85","hash":"bbdadd15ce30123fcdbd876fd76d8faa87e6ded7","price":"0.99","side":"SELL","size":"5588.18"}],"timestamp":"1786845519718"}}
{"f":1074,"recv_ms":1786845520028,"raw":{"event_type":"price_change","market":"0xd5f15f31689703aea70b93a52194a0964220d10d92ee7497346f146a8b6ef8ab","price_changes":[{"asset_id":"2151378744569768920256500242561922410292857798164019061749528550808091180185","best_ask":"0.86","best_bid":"0.85","hash":"cffe17ce092d6511dbdc3486aa399f246ff5c4b5","price":"0.01","side":"BUY","size":"8163.53"},{"asset_id":"17406866367975599232214757606801140480252276357934486651183783311435802862074","best_ask":"0.15","best_bid":"0.14","hash":"ac46ffcee07970bc5f727d6ff194653a1143d951","price":"0.99","side":"SELL","size":"8163.53"}],"timestamp":"1786845519718"}}
{"f":1075,"recv_ms":1786845520028,"raw":{"event_type":"price_change","market":"0xd5f15f31689703aea70b93a52194a0964220d10d92ee7497346f146a8b6ef8ab","price_changes":[{"asset_id":"17406866367975599232214757606801140480252276357934486651183783311435802862074","best_ask":"0.15","best_bid":"0.14","hash":"c98d3b2e9ef3f85c28b83338d860c95c805aff15","price":"0.07","side":"BUY","size":"364.86"},{"asset_id":"2151378744569768920256500242561922410292857798164019061749528550808091180185","best_ask":"0.86","best_bid":"0.85","hash":"569c6638cc6bf0189424b6b4a4fd55b2a049f9a9","price":"0.93","side":"SELL","size":"364.86"}],"timestamp":"1786845519719"}}
{"f":1076,"recv_ms":1786845520028,"raw":{"event_type":"price_change","market":"0xd5f15f31689703aea70b93a52194a0964220d10d92ee7497346f146a8b6ef8ab","price_changes":[{"asset_id":"2151378744569768920256500242561922410292857798164019061749528550808091180185","best_ask":"0.86","best_bid":"0.85","hash":"86bcd0231048f038c0a57dbfb41ab446c6623be4","price":"0.01","side":"BUY","size":"8263.53"},{"asset_id":"17406866367975599232214757606801140480252276357934486651183783311435802862074","best_ask":"0.15","best_bid":"0.14","hash":"2b56c224389574d5058473fdfc31537cfe07bae1","price":"0.99","side":"SELL","size":"8263.53"}],"timestamp":"1786845519719"}}
{"f":1077,"recv_ms":1786845520028,"raw":{"event_type":"price_change","market":"0xd5f15f31689703aea70b93a52194a0964220d10d92ee7497346f146a8b6ef8ab","price_changes":[{"asset_id":"2151378744569768920256500242561922410292857798164019061749528550808091180185","best_ask":"0.86","best_bid":"0.85","hash":"49b37095d31459514eadf58d3b36f17137ecf350","price":"0.02","side":"BUY","size":"1775.19"},{"asset_id":"17406866367975599232214757606801140480252276357934486651183783311435802862074","best_ask":"0.15","best_bid":"0.14","hash":"b56b61434689910207875ece5f60733f88493554","price":"0.98","side":"SELL","size":"1775.19"}],"timestamp":"1786845519720"}}
{"f":1078,"recv_ms":1786845520030,"raw":{"event_type":"price_change","market":"0xd5f15f31689703aea70b93a52194a0964220d10d92ee7497346f146a8b6ef8ab","price_changes":[{"asset_id":"2151378744569768920256500242561922410292857798164019061749528550808091180185","best_ask":"0.86","best_bid":"0.85","hash":"d7e26b399dedd183bbc81d92abed65410bd117b7","price":"0.01","side":"BUY","size":"8258.53"},{"asset_id":"17406866367975599232214757606801140480252276357934486651183783311435802862074","best_ask":"0.15","best_bid":"0.14","hash":"5831d13f7f63d009948c989400af9d4d1a606084","price":"0.99","side":"SELL","size":"8258.53"}],"timestamp":"1786845519721"}}
{"f":1079,"recv_ms":1786845520030,"raw":{"event_type":"price_change","market":"0xd5f15f31689703aea70b93a52194a0964220d10d92ee7497346f146a8b6ef8ab","price_changes":[{"asset_id":"2151378744569768920256500242561922410292857798164019061749528550808091180185","best_ask":"0.86","best_bid":"0.85","hash":"345d6794041eda98243f7ea5e19964032f30f704","price":"0.01","side":"BUY","size":"8358.53"},{"asset_id":"17406866367975599232214757606801140480252276357934486651183783311435802862074","best_ask":"0.15","best_bid":"0.14","hash":"da7560c52ca43effa573194f79372565892d4e91","price":"0.99","side":"SELL","size":"8358.53"}],"timestamp":"1786845519722"}}
{"f":1080,"recv_ms":1786845520030,"raw":{"event_type":"price_change","market":"0xd5f15f31689703aea70b93a52194a0964220d10d92ee7497346f146a8b6ef8ab","price_changes":[{"asset_id":"2151378744569768920256500242561922410292857798164019061749528550808091180185","best_ask":"0.86","best_bid":"0.85","hash":"fca5c6c8b9e908fac27b50e17be6f97701e949a6","price":"0.78","side":"BUY","size":"107"},{"asset_id":"17406866367975599232214757606801140480252276357934486651183783311435802862074","best_ask":"0.15","best_bid":"0.14","hash":"ff25738cd7c153ab1799b03ddfde3003034040a5","price":"0.22","side":"SELL","size":"107"}],"timestamp":"1786845519723"}}
{"f":1081,"recv_ms":1786845520030,"raw":{"event_type":"price_change","market":"0xd5f15f31689703aea70b93a52194a0964220d10d92ee7497346f146a8b6ef8ab","price_changes":[{"asset_id":"2151378744569768920256500242561922410292857798164019061749528550808091180185","best_ask":"0.86","best_bid":"0.85","hash":"014dabe96071447d723e8f0dd4e87c8d64a1d115","price":"0.77","side":"BUY","size":"45"},{"asset_id":"17406866367975599232214757606801140480252276357934486651183783311435802862074","best_ask":"0.15","best_bid":"0.14","hash":"e6f064460c8396dd4d41d8dbf69f7c012f8c3330","price":"0.23","side":"SELL","size":"45"}],"timestamp":"1786845519723"}}
{"f":1082,"recv_ms":1786845520030,"raw":{"event_type":"price_change","market":"0xd5f15f31689703aea70b93a52194a0964220d10d92ee7497346f146a8b6ef8ab","price_changes":[{"asset_id":"2151378744569768920256500242561922410292857798164019061749528550808091180185","best_ask":"0.86","best_bid":"0.85","hash":"64bf50d4cc4885e1d751b50003097285531903ed","price":"0.01","side":"BUY","size":"8458.53"},{"asset_id":"17406866367975599232214757606801140480252276357934486651183783311435802862074","best_ask":"0.15","best_bid":"0.14","hash":"2b88c508a0ce5e769d539f6597dee28fdb8bb1e7","price":"0.99","side":"SELL","size":"8458.53"}],"timestamp":"1786845519724"}}
{"f":1083,"recv_ms":1786845520031,"raw":{"event_type":"price_change","market":"0xd5f15f31689703aea70b93a52194a0964220d10d92ee7497346f146a8b6ef8ab","price_changes":[{"asset_id":"2151378744569768920256500242561922410292857798164019061749528550808091180185","best_ask":"0.86","best_bid":"0.85","hash":"dda225a13dd143e9b261443c689d56e12c87159e","price":"0.54","side":"BUY","size":"109"},{"asset_id":"17406866367975599232214757606801140480252276357934486651183783311435802862074","best_ask":"0.15","best_bid":"0.14","hash":"3613435d6486999c14178ade77b1c2f5b647cdfa","price":"0.46","side":"SELL","size":"109"}],"timestamp":"1786845519724"}}
{"f":1084,"recv_ms":1786845520031,"raw":{"event_type":"price_change","market":"0xd5f15f31689703aea70b93a52194a0964220d10d92ee7497346f146a8b6ef8ab","price_changes":[{"asset_id":"2151378744569768920256500242561922410292857798164019061749528550808091180185","best_ask":"0.86","best_bid":"0.85","hash":"7a50a0b084cf4e2d0e7a7ce9a46dba52222d8cd1","price":"0.01","side":"BUY","size":"8558.53"},{"asset_id":"17406866367975599232214757606801140480252276357934486651183783311435802862074","best_ask":"0.15","best_bid":"0.14","hash":"b9d60b68b83f795990eb2628d853b5511973f98d","price":"0.99","side":"SELL","size":"8558.53"}],"timestamp":"1786845519725"}}
{"f":1085,"recv_ms":1786845520031,"raw":{"event_type":"price_change","market":"0xd5f15f31689703aea70b93a52194a0964220d10d92ee7497346f146a8b6ef8ab","price_changes":[{"asset_id":"2151378744569768920256500242561922410292857798164019061749528550808091180185","best_ask":"0.86","best_bid":"0.85","hash":"9eb7dca3c994df564946f5acc0c2cab54a92b561","price":"0.55","side":"BUY","size":"139"},{"asset_id":"17406866367975599232214757606801140480252276357934486651183783311435802862074","best_ask":"0.15","best_bid":"0.14","hash":"fdef59bfbbf7ddbbf34c4c7f5bdbb4051651e6f3","price":"0.45","side":"SELL","size":"139"}],"timestamp":"1786845519726"}}
{"f":1086,"recv_ms":1786845520031,"raw":{"event_type":"price_change","market":"0xd5f15f31689703aea70b93a52194a0964220d10d92ee7497346f146a8b6ef8ab","price_changes":[{"asset_id":"2151378744569768920256500242561922410292857798164019061749528550808091180185","best_ask":"0.86","best_bid":"0.85","hash":"18f08818b3d3b21491622bddb19ba471d7be2ab1","price":"0.76","side":"BUY","size":"0"},{"asset_id":"17406866367975599232214757606801140480252276357934486651183783311435802862074","best_ask":"0.15","best_bid":"0.14","hash":"d1d41d725389c21148b9329c22d884aca9b5bc67","price":"0.24","side":"SELL","size":"0"}],"timestamp":"1786845519727"}}
{"f":1087,"recv_ms":1786845520031,"raw":{"event_type":"price_change","market":"0xd5f15f31689703aea70b93a52194a0964220d10d92ee7497346f146a8b6ef8ab","price_changes":[{"asset_id":"2151378744569768920256500242561922410292857798164019061749528550808091180185","best_ask":"0.86","best_bid":"0.85","hash":"d8ef024a7ffc125e44daa4bfcc7e0386604f5a6f","price":"0.85","side":"BUY","size":"289.97"},{"asset_id":"17406866367975599232214757606801140480252276357934486651183783311435802862074","best_ask":"0.15","best_bid":"0.14","hash":"2bd2711d5271b7bfc1ba5860546cd341f96c34ee","price":"0.15","side":"SELL","size":"289.97"}],"timestamp":"1786845519728"}}
{"f":1088,"recv_ms":1786845520036,"raw":{"asks":[{"price":"0.99","size":"5588.18"},{"price":"0.98","size":"1842.69"},{"price":"0.97","size":"611.3"},{"price":"0.96","size":"367.7"},{"price":"0.95","size":"559.7"},{"price":"0.94","size":"483.1"},{"price":"0.93","size":"364.86"},{"price":"0.92","size":"83.29"},{"price":"0.91","size":"40"},{"price":"0.9","size":"70"},{"price":"0.89","size":"10"},{"price":"0.88","size":"5"},{"price":"0.87","size":"93"},{"price":"0.86","size":"17.39"}],"asset_id":"2151378744569768920256500242561922410292857798164019061749528550808091180185","bids":[{"price":"0.01","size":"8558.53"},{"price":"0.02","size":"1775.19"},{"price":"0.03","size":"822.3"},{"price":"0.04","size":"552.7"},{"price":"0.05","size":"600.3"},{"price":"0.06","size":"486.1"},{"price":"0.07","size":"394.9"},{"price":"0.08","size":"145.29"},{"price":"0.09","size":"141.7"},{"price":"0.1","size":"173.9"},{"price":"0.11","size":"131.6"},{"price":"0.12","size":"119.6"},{"price":"0.13","size":"118"},{"price":"0.14","size":"111.6"},{"price":"0.15","size":"120.39"},{"price":"0.16","size":"109.3"},{"price":"0.17","size":"108.39"},{"price":"0.18","size":"22.6"},{"price":"0.19","size":"31.89"},{"price":"0.2","size":"54.1"},{"price":"0.21","size":"20.7"},{"price":"0.22","size":"30.2"},{"price":"0.23","size":"119.7"},{"price":"0.24","size":"14.3"},{"price":"0.25","size":"113.9"},{"price":"0.26","size":"13.5"},{"price":"0.27","size":"113.2"},{"price":"0.28","size":"12.9"},{"price":"0.29","size":"112.6"},{"price":"0.3","size":"22.4"},{"price":"0.31","size":"112.2"},{"price":"0.32","size":"11.9"},{"price":"0.33","size":"111.8"},{"price":"0.34","size":"26.6"},{"price":"0.35","size":"125.4"},{"price":"0.36","size":"55.3"},{"price":"0.37","size":"255.2"},{"price":"0.38","size":"24"},{"price":"0.39","size":"133.9"},{"price":"0.4","size":"38.8"},{"price":"0.41","size":"132.7"},{"price":"0.42","size":"62.7"},{"price":"0.43","size":"62.6"},{"price":"0.44","size":"693.6"},{"price":"0.45","size":"21.5"},{"price":"0.46","size":"21.5"},{"price":"0.47","size":"552.04"},{"price":"0.48","size":"20.4"},{"price":"0.49","size":"20.4"},{"price":"0.5","size":"20.4"},{"price":"0.51","size":"20.4"},{"price":"0.52","size":"20.4"},{"price":"0.53","size":"14"},{"price":"0.54","size":"109"},{"price":"0.55","size":"139"},{"price":"0.56","size":"49"},{"price":"0.57","size":"64"},{"price":"0.58","size":"29"},{"price":"0.59","size":"28"},{"price":"0.6","size":"28"},{"price":"0.61","size":"94.22"},{"price":"0.62","size":"198.66"},{"price":"0.63","size":"23.57"},{"price":"0.64","size":"258.49"},{"price":"0.65","size":"18"},{"price":"0.66","size":"18"},{"price":"0.67","size":"47"},{"price":"0.68","size":"105"},{"price":"0.69","size":"50"},{"price":"0.7","size":"40"},{"price":"0.71","size":"15"},{"price":"0.72","size":"30"},{"price":"0.73","size":"12"},{"price":"0.75","size":"127.9"},{"price":"0.77","size":"45"},{"price":"0.78","size":"107"},{"price":"0.79","size":"5"},{"price":"0.81","size":"10"},{"price":"0.82","size":"49.22"},{"price":"0.83","size":"22.51"},{"price":"0.84","size":"72.38"},{"price":"0.85","size":"289.97"}],"event_type":"book","hash":"d8ef024a7ffc125e44daa4bfcc7e0386604f5a6f","market":"0xd5f15f31689703aea70b93a52194a0964220d10d92ee7497346f146a8b6ef8ab","timestamp":"1786845519728"}}
{"f":1089,"recv_ms":1786845520036,"raw":{"event_type":"price_change","market":"0xd5f15f31689703aea70b93a52194a0964220d10d92ee7497346f146a8b6ef8ab","price_changes":[{"asset_id":"17406866367975599232214757606801140480252276357934486651183783311435802862074","best_ask":"0.15","best_bid":"0.14","hash":"a792df2896e83f330025363473ac1f93a40f054b","price":"0.07","side":"BUY","size":"349.86"},{"asset_id":"2151378744569768920256500242561922410292857798164019061749528550808091180185","best_ask":"0.86","best_bid":"0.85","hash":"60e1c53d3e1b40c48c2a7cd586f12c2473eeee5d","price":"0.93","side":"SELL","size":"349.86"}],"timestamp":"1786845519733"}}
{"f":1090,"recv_ms":1786845520036,"raw":{"event_type":"price_change","market":"0xd5f15f31689703aea70b93a52194a0964220d10d92ee7497346f146a8b6ef8ab","price_changes":[{"asset_id":"2151378744569768920256500242561922410292857798164019061749528550808091180185","best_ask":"0.86","best_bid":"0.85","hash":"6701a4310265e902146722605d8d7cd5b39a8240","price":"0.55","side":"BUY","size":"239"},{"asset_id":"17406866367975599232214757606801140480252276357934486651183783311435802862074","best_ask":"0.15","best_bid":"0.14","hash":"ba80578e937a503eea7663d4b7c89b78e578d670","price":"0.45","side":"SELL","size":"239"}],"timestamp":"1786845519734"}}
{"f":1091,"recv_ms":1786845520036,"raw":{"event_type":"price_change","market":"0xd5f15f31689703aea70b93a52194a0964220d10d92ee7497346f146a8b6ef8ab","price_changes":[{"asset_id":"2151378744569768920256500242561922410292857798164019061749528550808091180185","best_ask":"0.86","best_bid":"0.85","hash":"985bb76497cef5ccce44d8a7a9d9132068607fa8","price":"0.53","side":"BUY","size":"44"},{"asset_id":"17406866367975599232214757606801140480252276357934486651183783311435802862074","best_ask":"0.15","best_bid":"0.14","hash":"863941adedb0dd7d921c48479a98fc9cb825eff7","price":"0.47","side":"SELL","size":"44"}],"timestamp":"1786845519735"}}
{"f":1092,"recv_ms":1786845520036,"raw":{"event_type":"price_change","market":"0xd5f15f31689703aea70b93a52194a0964220d10d92ee7497346f146a8b6ef8ab","price_changes":[{"asset_id":"2151378744569768920256500242561922410292857798164019061749528550808091180185","best_ask":"0.86","best_bid":"0.85","hash":"bec11d2a32baf4811fc75c20a29eb8d070bc6461","price":"0.54","side":"BUY","size":"139"},{"asset_id":"17406866367975599232214757606801140480252276357934486651183783311435802862074","best_ask":"0.15","best_bid":"0.14","hash":"cc3240c9c84a371e5afeeac48cf7d32681a88334","price":"0.46","side":"SELL","size":"139"}],"timestamp":"1786845519736"}}
{"f":1093,"recv_ms":1786845520036,"raw":{"event_type":"price_change","market":"0xd5f15f31689703aea70b93a52194a0964220d10d92ee7497346f146a8b6ef8ab","price_changes":[{"asset_id":"17406866367975599232214757606801140480252276357934486651183783311435802862074","best_ask":"0.15","best_bid":"0.14","hash":"3d077610350f077f60010258311da6d14f1d5ffa","price":"0.04","side":"BUY","size":"467.7"},{"asset_id":"2151378744569768920256500242561922410292857798164019061749528550808091180185","best_ask":"0.86","best_bid":"0.85","hash":"fd9f1718926abfa3c4ca7e06b5ce52a6d99c0e11","price":"0.96","side":"SELL","size":"467.7"}],"timestamp":"1786845519737"}}
{"f":1094,"recv_ms":1786845520036,"raw":{"event_type":"price_change","market":"0xd5f15f31689703aea70b93a52194a0964220d10d92ee7497346f146a8b6ef8ab","price_changes":[{"asset_id":"2151378744569768920256500242561922410292857798164019061749528550808091180185","best_ask":"0.86","best_bid":"0.85","hash":"e8505b1dac79da0ea72e301edfeac7fb20dc1879","price":"0.5","side":"BUY","size":"50.4"},{"asset_id":"17406866367975599232214757606801140480252276357934486651183783311435802862074","best_ask":"0.15","best_bid":"0.14","hash":"c1ef3035aedca2036266e2b35b9645203b15e96b","price":"0.5","side":"SELL","size":"50.4"}],"timestamp":"1786845519738"}}
{"f":1095,"recv_ms":1786845520036,"raw":{"event_type":"price_change","market":"0xd5f15f31689703aea70b93a52194a0964220d10d92ee7497346f146a8b6ef8ab","price_changes":[{"asset_id":"2151378744569768920256500242561922410292857798164019061749528550808091180185","best_ask":"0.86","best_bid":"0.85","hash":"f8dbf0f3733add52f6a6b96be3582d7dc125d4d0","price":"0.51","side":"BUY","size":"50.4"},{"asset_id":"17406866367975599232214757606801140480252276357934486651183783311435802862074","best_ask":"0.15","best_bid":"0.14","hash":"784f59093df94d7e443cb05abde152bfb626ad61","price":"0.49","side":"SELL","size":"50.4"}],"timestamp":"1786845519738"}}
{"f":1096,"recv_ms":1786845520036,"raw":{"event_type":"price_change","market":"0xd5f15f31689703aea70b93a52194a0964220d10d92ee7497346f146a8b6ef8ab","price_changes":[{"asset_id":"2151378744569768920256500242561922410292857798164019061749528550808091180185","best_ask":"0.86","best_bid":"0.85","hash":"8691657d9d427a8ff79bc1028b201eecee1d2c69","price":"0.52","side":"BUY","size":"50.4"},{"asset_id":"17406866367975599232214757606801140480252276357934486651183783311435802862074","best_ask":"0.15","best_bid":"0.14","hash":"78e539fa0093b833363f199897964522819e3e9f","price":"0.48","side":"SELL","size":"50.4"}],"timestamp":"1786845519739"}}
{"f":1097,"recv_ms":1786845520038,"raw":{"event_type":"price_change","market":"0xd5f15f31689703aea70b93a52194a0964220d10d92ee7497346f146a8b6ef8ab","price_changes":[{"asset_id":"2151378744569768920256500242561922410292857798164019061749528550808091180185","best_ask":"0.86","best_bid":"0.85","hash":"691cfa78d61d7ad1d65bf8450967d147b4331e03","price":"0.01","side":"BUY","size":"8458.53"},{"asset_id":"17406866367975599232214757606801140480252276357934486651183783311435802862074","best_ask":"0.15","best_bid":"0.14","hash":"c5ced812a5082cf86a19258a65d40f700a48d1e1","price":"0.99","side":"SELL","size":"8458.53"}],"timestamp":"1786845519740"}}
{"f":1098,"recv_ms":1786845520038,"raw":{"event_type":"price_change","market":"0xd5f15f31689703aea70b93a52194a0964220d10d92ee7497346f146a8b6ef8ab","price_changes":[{"asset_id":"2151378744569768920256500242561922410292857798164019061749528550808091180185","best_ask":"0.86","best_bid":"0.85","hash":"32b0294ba9f3bb6f0ff26717d7bc8a07f80f5692","price":"0.01","side":"BUY","size":"8358.53"},{"asset_id":"17406866367975599232214757606801140480252276357934486651183783311435802862074","best_ask":"0.15","best_bid":"0.14","hash":"39bb259a5dcce2a2740bb32127d7814675cb0b5e","price":"0.99","side":"SELL","size":"8358.53"}],"timestamp":"1786845519740"}}
{"f":1099,"recv_ms":1786845520038,"raw":{"event_type":"price_change","market":"0xd5f15f31689703aea70b93a52194a0964220d10d92ee7497346f146a8b6ef8ab","price_changes":[{"asset_id":"17406866367975599232214757606801140480252276357934486651183783311435802862074","best_ask":"0.15","best_bid":"0.14","hash":"6cc4c0c3cd4305a93b00e2c298558912c086a91d","price":"0.05","side":"BUY","size":"459.7"},{"asset_id":"2151378744569768920256500242561922410292857798164019061749528550808091180185","best_ask":"0.86","best_bid":"0.85","hash":"b86ddb586da895d99c4aa1b0137e16ad0fe61c06","price":"0.95","side":"SELL","size":"459.7"}],"timestamp":"1786845519741"}}
{"f":1100,"recv_ms":1786845520038,"raw":{"event_type":"price_change","market":"0xd5f15f31689703aea70b93a52194a0964220d10d92ee7497346f146a8b6ef8ab","price_changes":[{"asset_id":"2151378744569768920256500242561922410292857798164019061749528550808091180185","best_ask":"0.86","best_bid":"0.85","hash":"cd936bf41d8cdcb8a700fc52a90fc54c7bde2948","price":"0.44","side":"BUY","size":"723.6"},{"asset_id":"17406866367975599232214757606801140480252276357934486651183783311435802862074","best_ask":"0.15","best_bid":"0.14","hash":"71cb25708bce8e3cd9df3b36cb3a96297e8cf341","price":"0.56","side":"SELL","size":"723.6"}],"timestamp":"1786845519741"}}
{"f":1101,"recv_ms":1786845520038,"raw":{"event_type":"price_change","market":"0xd5f15f31689703aea70b93a52194a0964220d10d92ee7497346f146a8b6ef8ab","price_changes":[{"asset_id":"2151378744569768920256500242561922410292857798164019061749528550808091180185","best_ask":"0.86","best_bid":"0.85","hash":"fc3097ab239f5a2a1534b79ee508e3f662c4acf2","price":"0.47","side":"BUY","size":"582.04"},{"asset_id":"17406866367975599232214757606801140480252276357934486651183783311435802862074","best_ask":"0.15","best_bid":"0.14","hash":"635e4fda134de2c1b28c8e9278757d7f4aea7fd8","price":"0.53","side":"SELL","size":"582.04"}],"timestamp":"1786845519742"}}
{"f":1102,"recv_ms":1786845520040,"raw":{"event_type":"price_change","market":"0xd5f15f31689703aea70b93a52194a0964220d10d92ee7497346f146a8b6ef8ab","price_changes":[{"asset_id":"2151378744569768920256500242561922410292857798164019061749528550808091180185","best_ask":"0.86","best_bid":"0.85","hash":"d69c4a7a4b550f7663fa358c01c97600adaeabda","price":"0.01","side":"BUY","size":"8352.53"},{"asset_id":"17406866367975599232214757606801140480252276357934486651183783311435802862074","best_ask":"0.15","best_bid":"0.14","hash":"cf52991f7ac1ff40408b85b505b4df2f60fdb06b","price":"0.99","side":"SELL","size":"8352.53"}],"timestamp":"1786845519743"}}
{"f":1103,"recv_ms":1786845520040,"raw":{"event_type":"price_change","market":"0xd5f15f31689703aea70b93a52194a0964220d10d92ee7497346f146a8b6ef8ab","price_changes":[{"asset_id":"2151378744569768920256500242561922410292857798164019061749528550808091180185","best_ask":"0.86","best_bid":"0.85","hash":"d6355df2bb6c55560b32c3e6d7e0ae74fb36324a","price":"0.49","side":"BUY","size":"50.4"},{"asset_id":"17406866367975599232214757606801140480252276357934486651183783311435802862074","best_ask":"0.15","best_bid":"0.14","hash":"2d052b9306195d173b8c7e5fd390676fd45093c8","price":"0.51","side":"SELL","size":"50.4"}],"timestamp":"1786845519743"}}
{"f":1104,"recv_ms":1786845520040,"raw":{"event_type":"price_change","market":"0xd5f15f31689703aea70b93a52194a0964220d10d92ee7497346f146a8b6ef8ab","price_changes":[{"asset_id":"2151378744569768920256500242561922410292857798164019061749528550808091180185","best_ask":"0.86","best_bid":"0.85","hash":"caeba0d940501fa311765eae1a7fac6eaf182e2f","price":"0.45","side":"BUY","size":"51.5"},{"asset_id":"17406866367975599232214757606801140480252276357934486651183783311435802862074","best_ask":"0.15","best_bid":"0.14","hash":"1eb138be5489bfe8bc8c731f706f9a7fa34cae8a","price":"0.55","side":"SELL","size":"51.5"}],"timestamp":"1786845519744"}}
{"f":1105,"recv_ms":1786845520040,"raw":{"event_type":"price_change","market":"0xd5f15f31689703aea70b93a52194a0964220d10d92ee7497346f146a8b6ef8ab","price_changes":[{"asset_id":"2151378744569768920256500242561922410292857798164019061749528550808091180185","best_ask":"0.86","best_bid":"0.85","hash":"b15d143c90d95880d6815d11e48af0d616527fe6","price":"0.48","side":"BUY","size":"50.4"},{"asset_id":"17406866367975599232214757606801140480252276357934486651183783311435802862074","best_ask":"0.15","best_bid":"0.14","hash":"e1a0526fa90d7695b1ec0def2dd8c1b418399a77","price":"0.52","side":"SELL","size":"50.4"}],"timestamp":"1786845519745"}}
{"f":1106,"recv_ms":1786845520040,"raw":{"event_type":"price_change","market":"0xd5f15f31689703aea70b93a52194a0964220d10d92ee7497346f146a8b6ef8ab","price_changes":[{"asset_id":"2151378744569768920256500242561922410292857798164019061749528550808091180185","best_ask":"0.86","best_bid":"0.85","hash":"4a75c98c17c8c0b614860b1a2bbadefe65904d70","price":"0.46","side":"BUY","size":"51.5"},{"asset_id":"17406866367975599232214757606801140480252276357934486651183783311435802862074","best_ask":"0.15","best_bid":"0.14","hash":"58914d832c40ceca8463a5018347810d321dc5ac","price":"0.54","side":"SELL","size":"51.5"}],"timestamp":"1786845519746"}}
{"f":1107,"recv_ms":1786845520040,"raw":{"event_type":"price_change","market":"0xd5f15f31689703aea70b93a52194a0964220d10d92ee7497346f146a8b6ef8ab","price_changes":[{"asset_id":"2151378744569768920256500242561922410292857798164019061749528550808091180185","best_ask":"0.86","best_bid":"0.85","hash":"64257afa279b8d07e56b9f6cfacb5c05458ee726","price":"0.75","side":"BUY","size":"97.9"},{"asset_id":"17406866367975599232214757606801140480252276357934486651183783311435802862074","best_ask":"0.15","best_bid":"0.14","hash":"1f41a557fb9c7aa3ccdbf4330625ebc13166aa3d","price":"0.25","side":"SELL","size":"97.9"}],"timestamp":"1786845519747"}}
{"f":1108,"recv_ms":1786845520040,"raw":{"event_type":"price_change","market":"0xd5f15f31689703aea70b93a52194a0964220d10d92ee7497346f146a8b6ef8ab","price_changes":[{"asset_id":"17406866367975599232214757606801140480252276357934486651183783311435802862074","best_ask":"0.15","best_bid":"0.14","hash":"67114b233789214ede6da33d99724b0f9bb3d82c","price":"0.32","side":"SELL","size":"10"},{"asset_id":"2151378744569768920256500242561922410292857798164019061749528550808091180185","best_ask":"0.86","best_bid":"0.85","hash":"ca33b4a7cb3874cbdf2f43bace3ab4d673158ca1","price":"0.68","side":"BUY","size":"10"}],"timestamp":"1786845519747"}}
{"f":1109,"recv_ms":1786845520040,"raw":{"event_type":"price_change","market":"0xd5f15f31689703aea70b93a52194a0964220d10d92ee7497346f146a8b6ef8ab","price_changes":[{"asset_id":"2151378744569768920256500242561922410292857798164019061749528550808091180185","best_ask":"0.86","best_bid":"0.85","hash":"cbcb31fe52c87ea8bda1eb1295a74df5012d29ad","price":"0.04","side":"BUY","size":"477.7"},{"asset_id":"17406866367975599232214757606801140480252276357934486651183783311435802862074","best_ask":"0.15","best_bid":"0.14","hash":"78d3f4165a665802c5e98deccb16fba70b971704","price":"0.96","side":"SELL","size":"477.7"}],"timestamp":"1786845519750"}}
{"f":1110,"recv_ms":1786845520040,"raw":{"event_type":"price_change","market":"0xd5f15f31689703aea70b93a52194a0964220d10d92ee7497346f146a8b6ef8ab","price_changes":[{"asset_id":"17406866367975599232214757606801140480252276357934486651183783311435802862074","best_ask":"0.15","best_bid":"0.14","hash":"28cc973e61092058ae556168c64cbba610f8c92a","price":"0.34","side":"SELL","size":"116"},{"asset_id":"2151378744569768920256500242561922410292857798164019061749528550808091180185","best_ask":"0.86","best_bid":"0.85","hash":"dca82792d186e896bf8cd00b11a603173b4d05b0","price":"0.66","side":"BUY","size":"116"}],"timestamp":"1786845519750"}}
{"f":1111,"recv_ms":1786845520040,"raw":{"event_type":"price_change","market":"0xd5f15f31689703aea70b93a52194a0964220d10d92ee7497346f146a8b6ef8ab","price_changes":[{"asset_id":"2151378744569768920256500242561922410292857798164019061749528550808091180185","best_ask":"0.86","best_bid":"0.85","hash":"4916d3782777f9f078e7553f20bd7121d25fe36d","price":"0.77","side":"BUY","size":"75"},{"asset_id":"17406866367975599232214757606801140480252276357934486651183783311435802862074","best_ask":"0.15","best_bid":"0.14","hash":"6fbddee15a4b095ee1fad87434c3fb8ae1c95566","price":"0.23","side":"SELL","size":"75"}],"timestamp":"1786845519754"}}
{"f":1112,"recv_ms":1786845520042,"raw":{"event_type":"price_change","market":"0xd5f15f31689703aea70b93a52194a0964220d10d92ee7497346f146a8b6ef8ab","price_changes":[{"asset_id":"2151378744569768920256500242561922410292857798164019061749528550808091180185","best_ask":"0.86","best_bid":"0.85","hash":"4b5691d3994e0f9fce0ae1098ab37f2571931898","price":"0.01","side":"BUY","size":"8357.54"},{"asset_id":"17406866367975599232214757606801140480252276357934486651183783311435802862074","best_ask":"0.15","best_bid":"0.14","hash":"a299031e2441d9135578808304e22a1e133a1652","price":"0.99","side":"SELL","size":"8357.54"}],"timestamp":"1786845519755"}}
{"f":1113,"recv_ms":1786845520042,"raw":{"event_type":"price_change","market":"0xd5f15f31689703aea70b93a52194a0964220d10d92ee7497346f146a8b6ef8ab","price_changes":[{"asset_id":"2151378744569768920256500242561922410292857798164019061749528550808091180185","best_ask":"0.86","best_bid":"0.85","hash":"61b19dcec5cd71316ef920f77b4ed64d9759bec1","price":"0.54","side":"BUY","size":"39"},{"asset_id":"17406866367975599232214757606801140480252276357934486651183783311435802862074","best_ask":"0.15","best_bid":"0.14","hash":"c07b54a49ec68221710e5628ab96bf22aa45da72","price":"0.46","side":"SELL","size":"39"}],"timestamp":"1786845519757"}}
{"f":1114,"recv_ms":1786845520042,"raw":{"event_type":"price_change","market":"0xf636967aa9d8794331ee10b9af364ea18fa3f1a9935f8c83ae9a249d8b08a931","price_changes":[{"asset_id":"91326336689285362968457805980185782713434399212786273576721749759222414518998","best_ask":"0.51","best_bid":"0.5","hash":"3c6fc06e9ad6567afe0265deae7c5ebc9bf06c8e","price":"0.13","side":"BUY","size":"23"},{"asset_id":"68567158191229273715522065688080768784240867677122603193993480690378524045921","best_ask":"0.5","best_bid":"0.49","hash":"96f1c43990674ccee264da540c317df0bd28ca22","price":"0.87","side":"SELL","size":"23"}],"timestamp":"1786845519768"}}
{"f":1115,"recv_ms":1786845520042,"raw":{"asset_id":"2151378744569768920256500242561922410292857798164019061749528550808091180185","event_type":"last_trade_price","fee_rate_bps":"0","market":"0xd5f15f31689703aea70b93a52194a0964220d10d92ee7497346f146a8b6ef8ab","price":"0.86","side":"BUY","size":"5.698714","timestamp":"1786845519770","transaction_hash":"0x8cd4ee47611b30c246e1d5983dbf048c4175eeb38142c153170153e1d078b3b0"}}
{"f":1116,"recv_ms":1786845520042,"raw":{"event_type":"price_change","market":"0xd5f15f31689703aea70b93a52194a0964220d10d92ee7497346f146a8b6ef8ab","price_changes":[{"asset_id":"2151378744569768920256500242561922410292857798164019061749528550808091180185","best_ask":"0.86","best_bid":"0.85","hash":"6b763ad62a5c858460d5133c9233e9081af5ebb1","price":"0.01","side":"BUY","size":"8257.54"},{"asset_id":"17406866367975599232214757606801140480252276357934486651183783311435802862074","best_ask":"0.15","best_bid":"0.14","hash":"dd484fb169be2ef34dda2b3428610d66b198091c","price":"0.99","side":"SELL","size":"8257.54"}],"timestamp":"1786845519779"}}
{"f":1117,"recv_ms":1786845520042,"raw":{"event_type":"price_change","market":"0xd5f15f31689703aea70b93a52194a0964220d10d92ee7497346f146a8b6ef8ab","price_changes":[{"asset_id":"2151378744569768920256500242561922410292857798164019061749528550808091180185","best_ask":"0.86","best_bid":"0.85","hash":"a35278379e423e4120b1927bc195f776395372e1","price":"0.01","side":"BUY","size":"8252.53"},{"asset_id":"17406866367975599232214757606801140480252276357934486651183783311435802862074","best_ask":"0.15","best_bid":"0.14","hash":"4c750708a1136041aeddb07a131d845f30892c2e","price":"0.99","side":"SELL","size":"8252.53"}],"timestamp":"1786845519783"}}
{"f":1118,"recv_ms":1786845520042,"raw":{"event_type":"price_change","market":"0xd5f15f31689703aea70b93a52194a0964220d10d92ee7497346f146a8b6ef8ab","price_changes":[{"asset_id":"2151378744569768920256500242561922410292857798164019061749528550808091180185","best_ask":"0.86","best_bid":"0.85","hash":"eafe1a00b4663d285916586d5cee713429467856","price":"0.01","side":"BUY","size":"8152.53"},{"asset_id":"17406866367975599232214757606801140480252276357934486651183783311435802862074","best_ask":"0.15","best_bid":"0.14","hash":"9308f6ff604cf54f7cb570d4bd4c38c4774e31d2","price":"0.99","side":"SELL","size":"8152.53"}],"timestamp":"1786845519796"}}
{"f":1119,"recv_ms":1786845520042,"raw":{"event_type":"price_change","market":"0xd5f15f31689703aea70b93a52194a0964220d10d92ee7497346f146a8b6ef8ab","price_changes":[{"asset_id":"2151378744569768920256500242561922410292857798164019061749528550808091180185","best_ask":"0.86","best_bid":"0.85","hash":"ce76fbfb27b7f4d266e05b540a65450307dfad5e","price":"0.01","side":"BUY","size":"8052.53"},{"asset_id":"17406866367975599232214757606801140480252276357934486651183783311435802862074","best_ask":"0.15","best_bid":"0.14","hash":"31385f368aca778329ddd296f7948b49bb2eb074","price":"0.99","side":"SELL","size":"8052.53"}],"timestamp":"1786845519802"}}
{"f":1120,"recv_ms":1786845520042,"raw":{"event_type":"price_change","market":"0xd5f15f31689703aea70b93a52194a0964220d10d92ee7497346f146a8b6ef8ab","price_changes":[{"asset_id":"2151378744569768920256500242561922410292857798164019061749528550808091180185","best_ask":"0.86","best_bid":"0.85","hash":"bbebacd2a8278ea7e555d991f4efe9f4a9d992e5","price":"0.78","side":"BUY","size":"7"},{"asset_id":"17406866367975599232214757606801140480252276357934486651183783311435802862074","best_ask":"0.15","best_bid":"0.14","hash":"268f0e873912f3ce7ad88cb2de9f60a73c18e97d","price":"0.22","side":"SELL","size":"7"}],"timestamp":"1786845519804"}}
{"f":1121,"recv_ms":1786845520042,"raw":{"event_type":"price_change","market":"0xd5f15f31689703aea70b93a52194a0964220d10d92ee7497346f146a8b6ef8ab","price_changes":[{"asset_id":"2151378744569768920256500242561922410292857798164019061749528550808091180185","best_ask":"0.86","best_bid":"0.85","hash":"1756f495b4a1ca6ed48e0f6e2f16045aafda1e5f","price":"0.01","side":"BUY","size":"7952.53"},{"asset_id":"17406866367975599232214757606801140480252276357934486651183783311435802862074","best_ask":"0.15","best_bid":"0.14","hash":"5588be937ab81f91ad15589946003e0351da2589","price":"0.99","side":"SELL","size":"7952.53"}],"timestamp":"1786845519807"}}
{"f":1122,"recv_ms":1786845520042,"raw":{"event_type":"price_change","market":"0xd5f15f31689703aea70b93a52194a0964220d10d92ee7497346f146a8b6ef8ab","price_changes":[{"asset_id":"2151378744569768920256500242561922410292857798164019061749528550808091180185","best_ask":"0.86","best_bid":"0.85","hash":"199cb7a1b9b3a9828a2fc8614cad843512e0281a","price":"0.01","side":"BUY","size":"7852.53"},{"asset_id":"17406866367975599232214757606801140480252276357934486651183783311435802862074","best_ask":"0.15","best_bid":"0.14","hash":"e481c58545669e2f1abdac28cf312cd9b855f1f0","price":"0.99","side":"SELL","size":"7852.53"}],"timestamp":"1786845519808"}}
{"f":1123,"recv_ms":1786845520042,"raw":{"event_type":"price_change","market":"0xd5f15f31689703aea70b93a52194a0964220d10d92ee7497346f146a8b6ef8ab","price_changes":[{"asset_id":"2151378744569768920256500242561922410292857798164019061749528550808091180185","best_ask":"0.86","best_bid":"0.85","hash":"fe56833c0c9a49678ae103a8452db688572b56ff","price":"0.79","side":"BUY","size":"105"},{"asset_id":"17406866367975599232214757606801140480252276357934486651183783311435802862074","best_ask":"0.15","best_bid":"0.14","hash":"c7f854d478fe2137131d4c5c6adc8fa10de5b4cd","price":"0.21","side":"SELL","size":"105"}],"timestamp":"1786845519808"}}
{"f":1124,"recv_ms":1786845520042,"raw":{"event_type":"price_change","market":"0xd5f15f31689703aea70b93a52194a0964220d10d92ee7497346f146a8b6ef8ab","price_changes":[{"asset_id":"2151378744569768920256500242561922410292857798164019061749528550808091180185","best_ask":"0.86","best_bid":"0.85","hash":"9660352fc5ec1c46369e0c7c40e716a48450cfdf","price":"0.01","side":"BUY","size":"7952.53"},{"asset_id":"17406866367975599232214757606801140480252276357934486651183783311435802862074","best_ask":"0.15","best_bid":"0.14","hash":"633fe404edd4145c66bf7d1b0d06248ad68a2803","price":"0.99","side":"SELL","size":"7952.53"}],"timestamp":"1786845519809"}}
{"f":1125,"recv_ms":1786845520042,"raw":{"event_type":"price_change","market":"0xd5f15f31689703aea70b93a52194a0964220d10d92ee7497346f146a8b6ef8ab","price_changes":[{"asset_id":"2151378744569768920256500242561922410292857798164019061749528550808091180185","best_ask":"0.86","best_bid":"0.85","hash":"0a091678854508314a4a43f6ffae59e38f7a7f62","price":"0.01","side":"BUY","size":"7852.53"},{"asset_id":"17406866367975599232214757606801140480252276357934486651183783311435802862074","best_ask":"0.15","best_bid":"0.14","hash":"4500fc8031c4abea346f0ab73fd5696493c8c226","price":"0.99","side":"SELL","size":"7852.53"}],"timestamp":"1786845519813"}}
{"f":1126,"recv_ms":1786845520042,"raw":{"event_type":"price_change","market":"0xd5f15f31689703aea70b93a52194a0964220d10d92ee7497346f146a8b6ef8ab","price_changes":[{"asset_id":"2151378744569768920256500242561922410292857798164019061749528550808091180185","best_ask":"0.86","best_bid":"0.85","hash":"1c985a085b6cfaef72f85bd2e88cec2e215c7f17","price":"0.01","side":"BUY","size":"7847.53"},{"asset_id":"17406866367975599232214757606801140480252276357934486651183783311435802862074","best_ask":"0.15","best_bid":"0.14","hash":"68755763b82b0b954698096bbb48339fe8899ea9","price":"0.99","side":"SELL","size":"7847.53"}],"timestamp":"1786845519814"}}
{"f":1127,"recv_ms":1786845520042,"raw":{"event_type":"price_change","market":"0xd5f15f31689703aea70b93a52194a0964220d10d92ee7497346f146a8b6ef8ab","price_changes":[{"asset_id":"2151378744569768920256500242561922410292857798164019061749528550808091180185","best_ask":"0.86","best_bid":"0.85","hash":"34d77d4d5d13a60e223df51d0106c605dabaf90c","price":"0.01","side":"BUY","size":"7747.53"},{"asset_id":"17406866367975599232214757606801140480252276357934486651183783311435802862074","best_ask":"0.15","best_bid":"0.14","hash":"c42af9796791851b6666da7002cf542a6bc303dc","price":"0.99","side":"SELL","size":"7747.53"}],"timestamp":"1786845519814"}}
{"f":1128,"recv_ms":1786845520042,"raw":{"event_type":"price_change","market":"0xd5f15f31689703aea70b93a52194a0964220d10d92ee7497346f146a8b6ef8ab","price_changes":[{"asset_id":"2151378744569768920256500242561922410292857798164019061749528550808091180185","best_ask":"0.86","best_bid":"0.85","hash":"606f843f9d38925d795873ead00e1265ee812b04","price":"0.01","side":"BUY","size":"7647.53"},{"asset_id":"17406866367975599232214757606801140480252276357934486651183783311435802862074","best_ask":"0.15","best_bid":"0.14","hash":"ab392d7529a09fb30b9dc48bdfc28295fcae6aa2","price":"0.99","side":"SELL","size":"7647.53"}],"timestamp":"1786845519819"}}
{"f":1129,"recv_ms":1786845520042,"raw":{"event_type":"price_change","market":"0xd5f15f31689703aea70b93a52194a0964220d10d92ee7497346f146a8b6ef8ab","price_changes":[{"asset_id":"2151378744569768920256500242561922410292857798164019061749528550808091180185","best_ask":"0.86","best_bid":"0.85","hash":"801f146ba10f8f652446ae70952022e1d9257497","price":"0.01","side":"BUY","size":"7653.53"},{"asset_id":"17406866367975599232214757606801140480252276357934486651183783311435802862074","best_ask":"0.15","best_bid":"0.14","hash":"e7dff40f1b74e1ebe73deafc2fccd1aa5d146bfd","price":"0.99","side":"SELL","size":"7653.53"}],"timestamp":"1786845519820"}}
{"f":1130,"recv_ms":1786845520042,"raw":{"event_type":"price_change","market":"0xd5f15f31689703aea70b93a52194a0964220d10d92ee7497346f146a8b6ef8ab","price_changes":[{"asset_id":"2151378744569768920256500242561922410292857798164019061749528550808091180185","best_ask":"0.86","best_bid":"0.85","hash":"c991cc412089f68da60da9312417b2ecabced182","price":"0.01","side":"BUY","size":"7658.53"},{"asset_id":"17406866367975599232214757606801140480252276357934486651183783311435802862074","best_ask":"0.15","best_bid":"0.14","hash":"763b6c8b8e73a4b68d027979a60040e34af2ef9f","price":"0.99","side":"SELL","size":"7658.53"}],"timestamp":"1786845519821"}}
{"f":1131,"recv_ms":1786845520042,"raw":{"event_type":"price_change","market":"0xd5f15f31689703aea70b93a52194a0964220d10d92ee7497346f146a8b6ef8ab","price_changes":[{"asset_id":"2151378744569768920256500242561922410292857798164019061749528550808091180185","best_ask":"0.86","best_bid":"0.85","hash":"8407d108401fb1b0f085bd5a9f8c2b8d93d4cf1d","price":"0.77","side":"BUY","size":"45"},{"asset_id":"17406866367975599232214757606801140480252276357934486651183783311435802862074","best_ask":"0.15","best_bid":"0.14","hash":"0a7b774f066ec5c34cdb4dee089e820535ae14d4","price":"0.23","side":"SELL","size":"45"}],"timestamp":"1786845519822"}}
{"f":1132,"recv_ms":1786845520042,"raw":{"event_type":"price_change","market":"0xd5f15f31689703aea70b93a52194a0964220d10d92ee7497346f146a8b6ef8ab","price_changes":[{"asset_id":"2151378744569768920256500242561922410292857798164019061749528550808091180185","best_ask":"0.86","best_bid":"0.85","hash":"36aa2644a46514e50575e6914eb723282378e9b5","price":"0.78","side":"BUY","size":"37"},{"asset_id":"17406866367975599232214757606801140480252276357934486651183783311435802862074","best_ask":"0.15","best_bid":"0.14","hash":"ca51a51599902e88a8b6a8a82b0a378567215b0f","price":"0.22","side":"SELL","size":"37"}],"timestamp":"1786845519823"}}
{"f":1133,"recv_ms":1786845520042,"raw":{"event_type":"price_change","market":"0xd5f15f31689703aea70b93a52194a0964220d10d92ee7497346f146a8b6ef8ab","price_changes":[{"asset_id":"2151378744569768920256500242561922410292857798164019061749528550808091180185","best_ask":"0.86","best_bid":"0.85","hash":"44c56fa61132a02bd8b5c07bb1ca0315f903d64e","price":"0.01","side":"BUY","size":"7663.53"},{"asset_id":"17406866367975599232214757606801140480252276357934486651183783311435802862074","best_ask":"0.15","best_bid":"0.14","hash":"7fb974ea1ea7f0a768e75a28f9f8a9a6872d2a21","price":"0.99","side":"SELL","size":"7663.53"}],"timestamp":"1786845519824"}}
{"f":1134,"recv_ms":1786845520042,"raw":{"event_type":"price_change","market":"0xd5f15f31689703aea70b93a52194a0964220d10d92ee7497346f146a8b6ef8ab","price_changes":[{"asset_id":"2151378744569768920256500242561922410292857798164019061749528550808091180185","best_ask":"0.86","best_bid":"0.85","hash":"97cfd27314251cc81956e45a00a6ca923642e94e","price":"0.01","side":"BUY","size":"7563.53"},{"asset_id":"17406866367975599232214757606801140480252276357934486651183783311435802862074","best_ask":"0.15","best_bid":"0.14","hash":"ead259920d88bea3e538ca788b514b3a96325e12","price":"0.99","side":"SELL","size":"7563.53"}],"timestamp":"1786845519825"}}
{"f":1135,"recv_ms":1786845520042,"raw":{"event_type":"price_change","market":"0xd5f15f31689703aea70b93a52194a0964220d10d92ee7497346f146a8b6ef8ab","price_changes":[{"asset_id":"2151378744569768920256500242561922410292857798164019061749528550808091180185","best_ask":"0.86","best_bid":"0.85","hash":"52a4a93e551dd3496de973d9dbef94b833d3e450","price":"0.01","side":"BUY","size":"7558.53"},{"asset_id":"17406866367975599232214757606801140480252276357934486651183783311435802862074","best_ask":"0.15","best_bid":"0.14","hash":"23cfed4fee5c95dfbe2ccc60b129339d6fa3402c","price":"0.99","side":"SELL","size":"7558.53"}],"timestamp":"1786845519826"}}
{"f":1136,"recv_ms":1786845520042,"raw":{"event_type":"price_change","market":"0xd5f15f31689703aea70b93a52194a0964220d10d92ee7497346f146a8b6ef8ab","price_changes":[{"asset_id":"2151378744569768920256500242561922410292857798164019061749528550808091180185","best_ask":"0.86","best_bid":"0.85","hash":"e5666be3c7e2cdbd37a180e6f4b78a75d20036c6","price":"0.01","side":"BUY","size":"7458.53"},{"asset_id":"17406866367975599232214757606801140480252276357934486651183783311435802862074","best_ask":"0.15","best_bid":"0.14","hash":"1bd5917f7af0da36c43292ecc7844890e8f2297d","price":"0.99","side":"SELL","size":"7458.53"}],"timestamp":"1786845519826"}}
{"f":1137,"recv_ms":1786845520042,"raw":{"event_type":"price_change","market":"0xd5f15f31689703aea70b93a52194a0964220d10d92ee7497346f146a8b6ef8ab","price_changes":[{"asset_id":"2151378744569768920256500242561922410292857798164019061749528550808091180185","best_ask":"0.86","best_bid":"0.85","hash":"a613f650633fa4957e0ed8aec15edf1f9f2db114","price":"0.01","side":"BUY","size":"7358.53"},{"asset_id":"17406866367975599232214757606801140480252276357934486651183783311435802862074","best_ask":"0.15","best_bid":"0.14","hash":"d4958bccfcf0c7589b6bbb35a2a2674e869bc27f","price":"0.99","side":"SELL","size":"7358.53"}],"timestamp":"1786845519827"}}
{"f":1138,"recv_ms":1786845520042,"raw":{"event_type":"price_change","market":"0xd5f15f31689703aea70b93a52194a0964220d10d92ee7497346f146a8b6ef8ab","price_changes":[{"asset_id":"2151378744569768920256500242561922410292857798164019061749528550808091180185","best_ask":"0.86","best_bid":"0.85","hash":"596fd51286d9e0eebb0fbfd694bae5bc56140a44","price":"0.01","side":"BUY","size":"7363.53"},{"asset_id":"17406866367975599232214757606801140480252276357934486651183783311435802862074","best_ask":"0.15","best_bid":"0.14","hash":"64885254d8d8c337f7ed2b5938b08157456aed5f","price":"0.99","side":"SELL","size":"7363.53"}],"timestamp":"1786845519830"}}
{"f":1139,"recv_ms":1786845520042,"raw":{"event_type":"price_change","market":"0xd5f15f31689703aea70b93a52194a0964220d10d92ee7497346f146a8b6ef8ab","price_changes":[{"asset_id":"2151378744569768920256500242561922410292857798164019061749528550808091180185","best_ask":"0.86","best_bid":"0.85","hash":"ad8565bf33a02de4c436b254ecd8317f52c2faa2","price":"0.01","side":"BUY","size":"7368.53"},{"asset_id":"17406866367975599232214757606801140480252276357934486651183783311435802862074","best_ask":"0.15","best_bid":"0.14","hash":"8fa9fd76a4f1e0c18e245dd848b3112f7a213faa","price":"0.99","side":"SELL","size":"7368.53"}],"timestamp":"1786845519831"}}
{"f":1140,"recv_ms":1786845520048,"raw":{"event_type":"price_change","market":"0xd5f15f31689703aea70b93a52194a0964220d10d92ee7497346f146a8b6ef8ab","price_changes":[{"asset_id":"2151378744569768920256500242561922410292857798164019061749528550808091180185","best_ask":"0.86","best_bid":"0.85","hash":"b70d0bec4bd4ef57179f88e9f38f7ae4e77f3faf","price":"0.01","side":"BUY","size":"7373.53"},{"asset_id":"17406866367975599232214757606801140480252276357934486651183783311435802862074","best_ask":"0.15","best_bid":"0.14","hash":"00951538621640d49415ab8cb234a6e6b6ae879b","price":"0.99","side":"SELL","size":"7373.53"}],"timestamp":"1786845519832"}}
{"f":1141,"recv_ms":1786845520048,"raw":{"event_type":"price_change","market":"0xd5f15f31689703aea70b93a52194a0964220d10d92ee7497346f146a8b6ef8ab","price_changes":[{"asset_id":"17406866367975599232214757606801140480252276357934486651183783311435802862074","best_ask":"0.15","best_bid":"0.14","hash":"7b9f128534f5e049820d49660f380738aa3c06b3","price":"0.05","side":"BUY","size":"464.7"},{"asset_id":"2151378744569768920256500242561922410292857798164019061749528550808091180185","best_ask":"0.86","best_bid":"0.85","hash":"681cd4a32d58c0893dbd4b2e1eeceab4a2279473","price":"0.95","side":"SELL","size":"464.7"}],"timestamp":"1786845519835"}}
{"f":1142,"recv_ms":1786845520048,"raw":{"event_type":"price_change","market":"0xd5f15f31689703aea70b93a52194a0964220d10d92ee7497346f146a8b6ef8ab","price_changes":[{"asset_id":"2151378744569768920256500242561922410292857798164019061749528550808091180185","best_ask":"0.86","best_bid":"0.85","hash":"f29393acabd6e982f1d33c412e8d48ff7c251c47","price":"0.81","side":"BUY","size":"15"},{"asset_id":"17406866367975599232214757606801140480252276357934486651183783311435802862074","best_ask":"0.15","best_bid":"0.14","hash":"6fb6090ef6d49de2c3d0482a4837332a36743a4c","price":"0.19","side":"SELL","size":"15"}],"timestamp":"1786845519836"}}
{"f":1143,"recv_ms":1786845520059,"raw":{"event_type":"price_change","market":"0xd5f15f31689703aea70b93a52194a0964220d10d92ee7497346f146a8b6ef8ab","price_changes":[{"asset_id":"17406866367975599232214757606801140480252276357934486651183783311435802862074","best_ask":"0.15","best_bid":"0.14","hash":"95462e9b9212e1cf5d33f37324d68b0bb1a17e19","price":"0.13","side":"BUY","size":"88"},{"asset_id":"2151378744569768920256500242561922410292857798164019061749528550808091180185","best_ask":"0.86","best_bid":"0.85","hash":"0d88a058571cd4762379d17b9019cc6d4991c0ea","price":"0.87","side":"SELL","size":"88"}],"timestamp":"1786845519837"}}
{"f":1144,"recv_ms":1786845520059,"raw":{"event_type":"price_change","market":"0xd5f15f31689703aea70b93a52194a0964220d10d92ee7497346f146a8b6ef8ab","price_changes":[{"asset_id":"2151378744569768920256500242561922410292857798164019061749528550808091180185","best_ask":"0.86","best_bid":"0.85","hash":"0d88a058571cd4762379d17b9019cc6d4991c0ea","price":"0.71","side":"BUY","size":"10"},{"asset_id":"17406866367975599232214757606801140480252276357934486651183783311435802862074","best_ask":"0.15","best_bid":"0.14","hash":"95462e9b9212e1cf5d33f37324d68b0bb1a17e19","price":"0.29","side":"SELL","size":"10"}],"timestamp":"1786845519837"}}
{"f":1145,"recv_ms":1786845520063,"raw":{"event_type":"price_change","market":"0xd5f15f31689703aea70b93a52194a0964220d10d92ee7497346f146a8b6ef8ab","price_changes":[{"asset_id":"2151378744569768920256500242561922410292857798164019061749528550808091180185","best_ask":"0.86","best_bid":"0.85","hash":"dcabd962288e9a4e4f9727ed2087480593e3b743","price":"0.01","side":"BUY","size":"7273.53"},{"asset_id":"17406866367975599232214757606801140480252276357934486651183783311435802862074","best_ask":"0.15","best_bid":"0.14","hash":"567fc0fa11acd9b006170431f74312eb00c98e38","price":"0.99","side":"SELL","size":"7273.53"}],"timestamp":"1786845519839"}}
{"f":1146,"recv_ms":1786845520063,"raw":{"event_type":"price_change","market":"0xd5f15f31689703aea70b93a52194a0964220d10d92ee7497346f146a8b6ef8ab","price_changes":[{"asset_id":"2151378744569768920256500242561922410292857798164019061749528550808091180185","best_ask":"0.86","best_bid":"0.85","hash":"c43f62e191675a1822fa1de70f0b48fcce447ad8","price":"0.73","side":"BUY","size":"22"},{"asset_id":"17406866367975599232214757606801140480252276357934486651183783311435802862074","best_ask":"0.15","best_bid":"0.14","hash":"9ae9cb8600e606603b84d1eeb1fe5923027cfcf4","price":"0.27","side":"SELL","size":"22"}],"timestamp":"1786845519840"}}
{"f":1147,"recv_ms":1786845520063,"raw":{"event_type":"price_change","market":"0xd5f15f31689703aea70b93a52194a0964220d10d92ee7497346f146a8b6ef8ab","price_changes":[{"asset_id":"2151378744569768920256500242561922410292857798164019061749528550808091180185","best_ask":"0.86","best_bid":"0.85","hash":"c286873a7440382d4ccb67ca31b9765bd2bc9f2d","price":"0.01","side":"BUY","size":"7173.53"},{"asset_id":"17406866367975599232214757606801140480252276357934486651183783311435802862074","best_ask":"0.15","best_bid":"0.14","hash":"fccfb52952ba07047cb32988cea3e80d7aeb66dc","price":"0.99","side":"SELL","size":"7173.53"}],"timestamp":"1786845519842"}}
{"f":1148,"recv_ms":1786845520068,"raw":{"event_type":"price_change","market":"0xd5f15f31689703aea70b93a52194a0964220d10d92ee7497346f146a8b6ef8ab","price_changes":[{"asset_id":"2151378744569768920256500242561922410292857798164019061749528550808091180185","best_ask":"0.86","best_bid":"0.85","hash":"c331d5cce812d5a842543af7c81422e8475ec16c","price":"0.01","side":"BUY","size":"7073.53"},{"asset_id":"17406866367975599232214757606801140480252276357934486651183783311435802862074","best_ask":"0.15","best_bid":"0.14","hash":"07ebcc7d7f71b6cda80e88bd3b0c233a2496604f","price":"0.99","side":"SELL","size":"7073.53"}],"timestamp":"1786845519848"}}
{"f":1149,"recv_ms":1786845520068,"raw":{"event_type":"price_change","market":"0xd5f15f31689703aea70b93a52194a0964220d10d92ee7497346f146a8b6ef8ab","price_changes":[{"asset_id":"2151378744569768920256500242561922410292857798164019061749528550808091180185","best_ask":"0.86","best_bid":"0.85","hash":"53b60c8f4de209e74c4f0d2e1d7a363af39bfd1e","price":"0.01","side":"BUY","size":"6973.53"},{"asset_id":"17406866367975599232214757606801140480252276357934486651183783311435802862074","best_ask":"0.15","best_bid":"0.14","hash":"4beffb53c3745fde12adf678428257a88243c2ae","price":"0.99","side":"SELL","size":"6973.53"}],"timestamp":"1786845519848"}}
{"f":1150,"recv_ms":1786845520068,"raw":{"event_type":"price_change","market":"0xd5f15f31689703aea70b93a52194a0964220d10d92ee7497346f146a8b6ef8ab","price_changes":[{"asset_id":"2151378744569768920256500242561922410292857798164019061749528550808091180185","best_ask":"0.86","best_bid":"0.85","hash":"0e254b66682dd7022b7d5b394d1cb76b8d0b1c86","price":"0.01","side":"BUY","size":"6967.53"},{"asset_id":"17406866367975599232214757606801140480252276357934486651183783311435802862074","best_ask":"0.15","best_bid":"0.14","hash":"db3b725c16c8806ae692c9bd35a2530e3b2a2fc0","price":"0.99","side":"SELL","size":"6967.53"}],"timestamp":"1786845519850"}}
{"f":1151,"recv_ms":1786845520068,"raw":{"event_type":"price_change","market":"0xd5f15f31689703aea70b93a52194a0964220d10d92ee7497346f146a8b6ef8ab","price_changes":[{"asset_id":"2151378744569768920256500242561922410292857798164019061749528550808091180185","best_ask":"0.86","best_bid":"0.85","hash":"0e8ae6ee35ae8bb5a05f745b6ac9022816504503","price":"0.02","side":"BUY","size":"1850.19"},{"asset_id":"17406866367975599232214757606801140480252276357934486651183783311435802862074","best_ask":"0.15","best_bid":"0.14","hash":"9d5be01a720c46048cc46b5b42e50cc0ede474f8","price":"0.98","side":"SELL","size":"1850.19"}],"timestamp":"1786845519851"}}
{"f":1152,"recv_ms":1786845520075,"raw":{"event_type":"price_change","market":"0xd5f15f31689703aea70b93a52194a0964220d10d92ee7497346f146a8b6ef8ab","price_changes":[{"asset_id":"2151378744569768920256500242561922410292857798164019061749528550808091180185","best_ask":"0.86","best_bid":"0.85","hash":"7f1e7518a3e21cfc39a2ffc49ce5dca983d36656","price":"0.01","side":"BUY","size":"6867.53"},{"asset_id":"17406866367975599232214757606801140480252276357934486651183783311435802862074","best_ask":"0.15","best_bid":"0.14","hash":"0fb97ce98d1fbd84791dd105f93bb38d98c8e1c1","price":"0.99","side":"SELL","size":"6867.53"}],"timestamp":"1786845519855"}}
{"f":1153,"recv_ms":1786845520078,"raw":{"event_type":"price_change","market":"0xd5f15f31689703aea70b93a52194a0964220d10d92ee7497346f146a8b6ef8ab","price_changes":[{"asset_id":"2151378744569768920256500242561922410292857798164019061749528550808091180185","best_ask":"0.86","best_bid":"0.85","hash":"4c7759532204b1a5a09f5db968695f20c62d848d","price":"0.01","side":"BUY","size":"6767.53"},{"asset_id":"17406866367975599232214757606801140480252276357934486651183783311435802862074","best_ask":"0.15","best_bid":"0.14","hash":"76f96c4c7cf02525bb47e1269c6d73df1e9c6af6","price":"0.99","side":"SELL","size":"6767.53"}],"timestamp":"1786845519860"}}
{"f":1154,"recv_ms":1786845520078,"raw":{"event_type":"price_change","market":"0xd5f15f31689703aea70b93a52194a0964220d10d92ee7497346f146a8b6ef8ab","price_changes":[{"asset_id":"2151378744569768920256500242561922410292857798164019061749528550808091180185","best_ask":"0.86","best_bid":"0.85","hash":"76f24ddfe3026c6758222b7e886688712ce0baa7","price":"0.01","side":"BUY","size":"6667.53"},{"asset_id":"17406866367975599232214757606801140480252276357934486651183783311435802862074","best_ask":"0.15","best_bid":"0.14","hash":"332c07132fd698fc10ee06b736b3fa70d43fd873","price":"0.99","side":"SELL","size":"6667.53"}],"timestamp":"1786845519861"}}
{"f":1155,"recv_ms":1786845520078,"raw":{"event_type":"price_change","market":"0xd5f15f31689703aea70b93a52194a0964220d10d92ee7497346f146a8b6ef8ab","price_changes":[{"asset_id":"2151378744569768920256500242561922410292857798164019061749528550808091180185","best_ask":"0.86","best_bid":"0.85","hash":"32239eba674580a2ce48c61844da1bec01721f96","price":"0.01","side":"BUY","size":"6662.53"},{"asset_id":"17406866367975599232214757606801140480252276357934486651183783311435802862074","best_ask":"0.15","best_bid":"0.14","hash":"068b1295c485ffeccb30dd91fdba0b42a3a4f2f3","price":"0.99","side":"SELL","size":"6662.53"}],"timestamp":"1786845519863"}}
{"f":1156,"recv_ms":1786845520082,"raw":{"event_type":"price_change","market":"0xd5f15f31689703aea70b93a52194a0964220d10d92ee7497346f146a8b6ef8ab","price_changes":[{"asset_id":"2151378744569768920256500242561922410292857798164019061749528550808091180185","best_ask":"0.86","best_bid":"0.85","hash":"428d81ed327a6ed3a9052024309b20abc6c78779","price":"0.01","side":"BUY","size":"6562.53"},{"asset_id":"17406866367975599232214757606801140480252276357934486651183783311435802862074","best_ask":"0.15","best_bid":"0.14","hash":"6e4bf20341b45317f01b473419aa22b428e9af92","price":"0.99","side":"SELL","size":"6562.53"}],"timestamp":"1786845519864"}}
{"f":1157,"recv_ms":1786845520082,"raw":{"event_type":"price_change","market":"0xd5f15f31689703aea70b93a52194a0964220d10d92ee7497346f146a8b6ef8ab","price_changes":[{"asset_id":"2151378744569768920256500242561922410292857798164019061749528550808091180185","best_ask":"0.86","best_bid":"0.85","hash":"b87b3a10cd5df9b5fb858ba1f7847f6433c3dcfa","price":"0.01","side":"BUY","size":"6462.53"},{"asset_id":"17406866367975599232214757606801140480252276357934486651183783311435802862074","best_ask":"0.15","best_bid":"0.14","hash":"cc988030e97988b64b22091b0ba90647a7570dba","price":"0.99","side":"SELL","size":"6462.53"}],"timestamp":"1786845519864"}}
{"f":1158,"recv_ms":1786845520082,"raw":{"event_type":"price_change","market":"0xd5f15f31689703aea70b93a52194a0964220d10d92ee7497346f146a8b6ef8ab","price_changes":[{"asset_id":"2151378744569768920256500242561922410292857798164019061749528550808091180185","best_ask":"0.86","best_bid":"0.85","hash":"24ebe24272e762e6f3648c27db69d21ec38f734f","price":"0.38","side":"BUY","size":"124"},{"asset_id":"17406866367975599232214757606801140480252276357934486651183783311435802862074","best_ask":"0.15","best_bid":"0.14","hash":"dd97643eda7c606194cafc60c160c6cb337ef9ca","price":"0.62","side":"SELL","size":"124"}],"timestamp":"1786845519866"}}
{"f":1159,"recv_ms":1786845520082,"raw":{"event_type":"price_change","market":"0xd5f15f31689703aea70b93a52194a0964220d10d92ee7497346f146a8b6ef8ab","price_changes":[{"asset_id":"2151378744569768920256500242561922410292857798164019061749528550808091180185","best_ask":"0.86","best_bid":"0.85","hash":"44bcba9eb8cc0f1a60216fafce8a998c1a949c84","price":"0.01","side":"BUY","size":"6362.53"},{"asset_id":"17406866367975599232214757606801140480252276357934486651183783311435802862074","best_ask":"0.15","best_bid":"0.14","hash":"546fb8b8a8d134e44c7be1e689f19bd8824ec5f7","price":"0.99","side":"SELL","size":"6362.53"}],"timestamp":"1786845519867"}}
{"f":1160,"recv_ms":1786845520082,"raw":{"event_type":"price_change","market":"0xd5f15f31689703aea70b93a52194a0964220d10d92ee7497346f146a8b6ef8ab","price_changes":[{"asset_id":"2151378744569768920256500242561922410292857798164019061749528550808091180185","best_ask":"0.86","best_bid":"0.85","hash":"92762c835a591e615f7e19750a9bcfde8242028c","price":"0.37","side":"BUY","size":"155.2"},{"asset_id":"17406866367975599232214757606801140480252276357934486651183783311435802862074","best_ask":"0.15","best_bid":"0.14","hash":"f0019585770ccd11256db90e13d47eeb782f3b77","price":"0.63","side":"SELL","size":"155.2"}],"timestamp":"1786845519868"}}
{"f":1161,"recv_ms":1786845520084,"raw":{"event_type":"price_change","market":"0xd5f15f31689703aea70b93a52194a0964220d10d92ee7497346f146a8b6ef8ab","price_changes":[{"asset_id":"2151378744569768920256500242561922410292857798164019061749528550808091180185","best_ask":"0.86","best_bid":"0.85","hash":"2c1838b01204039abec69d2444896ae44b64c499","price":"0.01","side":"BUY","size":"6262.53"},{"asset_id":"17406866367975599232214757606801140480252276357934486651183783311435802862074","best_ask":"0.15","best_bid":"0.14","hash":"2b33ced69c412191a8e64955374f1ba12a349189","price":"0.99","side":"SELL","size":"6262.53"}],"timestamp":"1786845519870"}}
{"f":1162,"recv_ms":1786845520084,"raw":{"event_type":"price_change","market":"0xd5f15f31689703aea70b93a52194a0964220d10d92ee7497346f146a8b6ef8ab","price_changes":[{"asset_id":"2151378744569768920256500242561922410292857798164019061749528550808091180185","best_ask":"0.86","best_bid":"0.85","hash":"830b30fea539eda8b6d9d91d7a3e71d998942223","price":"0.01","side":"BUY","size":"6162.53"},{"asset_id":"17406866367975599232214757606801140480252276357934486651183783311435802862074","best_ask":"0.15","best_bid":"0.14","hash":"46bef13f321cf46f2eb6d92f6b39ccc721d34614","price":"0.99","side":"SELL","size":"6162.53"}],"timestamp":"1786845519872"}}
{"f":1163,"recv_ms":1786845520086,"raw":{"event_type":"price_change","market":"0xd5f15f31689703aea70b93a52194a0964220d10d92ee7497346f146a8b6ef8ab","price_changes":[{"asset_id":"2151378744569768920256500242561922410292857798164019061749528550808091180185","best_ask":"0.86","best_bid":"0.85","hash":"dc39964d3fa7808739af6e56839d7a473d82feea","price":"0.2","side":"BUY","size":"59.1"},{"asset_id":"17406866367975599232214757606801140480252276357934486651183783311435802862074","best_ask":"0.15","best_bid":"0.14","hash":"0ef5bb5a5459ce0819864dbc465fa2a69d75fbb1","price":"0.8","side":"SELL","size":"59.1"}],"timestamp":"1786845519873"}}
{"f":1164,"recv_ms":1786845520086,"raw":{"event_type":"price_change","market":"0xd5f15f31689703aea70b93a52194a0964220d10d92ee7497346f146a8b6ef8ab","price_changes":[{"asset_id":"2151378744569768920256500242561922410292857798164019061749528550808091180185","best_ask":"0.86","best_bid":"0.85","hash":"2b64479d50a6a4b041eb774e8975f2949e90b3f3","price":"0.01","side":"BUY","size":"6062.53"},{"asset_id":"17406866367975599232214757606801140480252276357934486651183783311435802862074","best_ask":"0.15","best_bid":"0.14","hash":"2be0dd6a854eb9b3c9ff444b3937e47e251b79b1","price":"0.99","side":"SELL","size":"6062.53"}],"timestamp":"1786845519874"}}
{"f":1165,"recv_ms":1786845520105,"raw":{"event_type":"price_change","market":"0xd5f15f31689703aea70b93a52194a0964220d10d92ee7497346f146a8b6ef8ab","price_changes":[{"asset_id":"2151378744569768920256500242561922410292857798164019061749528550808091180185","best_ask":"0.86","best_bid":"0.85","hash":"bc3ba0037ef3077b48df6d2e165396a47a305f5f","price":"0.01","side":"BUY","size":"6162.53"},{"asset_id":"17406866367975599232214757606801140480252276357934486651183783311435802862074","best_ask":"0.15","best_bid":"0.14","hash":"faf28073458e933d97683ea5e659b47041129895","price":"0.99","side":"SELL","size":"6162.53"}],"timestamp":"1786845519874"}}
{"f":1166,"recv_ms":1786845520105,"raw":{"event_type":"price_change","market":"0xd5f15f31689703aea70b93a52194a0964220d10d92ee7497346f146a8b6ef8ab","price_changes":[{"asset_id":"2151378744569768920256500242561922410292857798164019061749528550808091180185","best_ask":"0.86","best_bid":"0.85","hash":"b83e7f614fdf2208336669b87f4eecf0b8deea40","price":"0.01","side":"BUY","size":"6062.53"},{"asset_id":"17406866367975599232214757606801140480252276357934486651183783311435802862074","best_ask":"0.15","best_bid":"0.14","hash":"f091e5e4309a20eba7e43cb10880b938f06ece48","price":"0.99","side":"SELL","size":"6062.53"}],"timestamp":"1786845519876"}}
{"f":1167,"recv_ms":1786845520106,"raw":{"event_type":"price_change","market":"0xd5f15f31689703aea70b93a52194a0964220d10d92ee7497346f146a8b6ef8ab","price_changes":[{"asset_id":"2151378744569768920256500242561922410292857798164019061749528550808091180185","best_ask":"0.86","best_bid":"0.85","hash":"f69603fd78606bcb8dd6516c32ab6d40b656f3fc","price":"0.01","side":"BUY","size":"6057.53"},{"asset_id":"17406866367975599232214757606801140480252276357934486651183783311435802862074","best_ask":"0.15","best_bid":"0.14","hash":"1e136713f93708fa0820b9f7590d7ba88daf40d3","price":"0.99","side":"SELL","size":"6057.53"}],"timestamp":"1786845519893"}}
{"f":1168,"recv_ms":1786845520124,"raw":{"event_type":"price_change","market":"0x0f808668c26a078e39fb08c32be2c04739e31f58d8d58dc81f3771760aa097da","price_changes":[{"asset_id":"109981215458957430670008039613114505679239971255550615765913446335529931163020","best_ask":"0.51","best_bid":"0.5","hash":"54d88079896dcdd916226e0dab5992ebd4e3017b","price":"0.13","side":"BUY","size":"33.2"},{"asset_id":"9052432239268584294914812202913499895678363531348080565599375753720096525063","best_ask":"0.5","best_bid":"0.49","hash":"9f1e9937ba79c77e69809180624bdcdf5a8565d8","price":"0.87","side":"SELL","size":"33.2"}],"timestamp":"1786845519897"}}
{"f":1169,"recv_ms":1786845520124,"raw":{"asset_id":"17406866367975599232214757606801140480252276357934486651183783311435802862074","event_type":"last_trade_price","fee_rate_bps":"0","market":"0xd5f15f31689703aea70b93a52194a0964220d10d92ee7497346f146a8b6ef8ab","price":"0.15","side":"BUY","size":"13.333332","timestamp":"1786845519906","transaction_hash":"0x8dea86e1b9ebcb049222efbd25ba2ab127d9aeb6bb64ae6a801906f88fcad2d1"}}
{"f":1170,"recv_ms":1786845520134,"raw":{"asset_id":"17406866367975599232214757606801140480252276357934486651183783311435802862074","event_type":"last_trade_price","fee_rate_bps":"0","market":"0xd5f15f31689703aea70b93a52194a0964220d10d92ee7497346f146a8b6ef8ab","price":"0.16","side":"BUY","size":"6.25","timestamp":"1786845519909","transaction_hash":"0x42cdfef4e54ec6d30cba4df9b1d50b8b34f641f73873880a2bbcaed0050a5f26"}}
{"f":1171,"recv_ms":1786845520134,"raw":{"event_type":"price_change","market":"0xd5f15f31689703aea70b93a52194a0964220d10d92ee7497346f146a8b6ef8ab","price_changes":[{"asset_id":"2151378744569768920256500242561922410292857798164019061749528550808091180185","best_ask":"0.86","best_bid":"0.85","hash":"c4e25b752ef086728da683c62fb9629a44c75aa8","price":"0.01","side":"BUY","size":"6063.53"},{"asset_id":"17406866367975599232214757606801140480252276357934486651183783311435802862074","best_ask":"0.15","best_bid":"0.14","hash":"25e04d1e67d6d075ce6104004cbef0f912fb88da","price":"0.99","side":"SELL","size":"6063.53"}],"timestamp":"1786845519921"}}
{"f":1172,"recv_ms":1786845520135,"raw":{"event_type":"price_change","market":"0xd5f15f31689703aea70b93a52194a0964220d10d92ee7497346f146a8b6ef8ab","price_changes":[{"asset_id":"2151378744569768920256500242561922410292857798164019061749528550808091180185","best_ask":"0.86","best_bid":"0.85","hash":"c907d5a12b885d1a46e1b8447fa75be5ab2babbb","price":"0.01","side":"BUY","size":"5963.53"},{"asset_id":"17406866367975599232214757606801140480252276357934486651183783311435802862074","best_ask":"0.15","best_bid":"0.14","hash":"194cca3b5e32be3527c65db3815bbdd576cb0077","price":"0.99","side":"SELL","size":"5963.53"}],"timestamp":"1786845519922"}}
{"f":1173,"recv_ms":1786845520137,"raw":{"event_type":"price_change","market":"0xd5f15f31689703aea70b93a52194a0964220d10d92ee7497346f146a8b6ef8ab","price_changes":[{"asset_id":"2151378744569768920256500242561922410292857798164019061749528550808091180185","best_ask":"0.86","best_bid":"0.85","hash":"8ae8203abc1059b5d84550480fb655f7ab2b3add","price":"0.01","side":"BUY","size":"5863.53"},{"asset_id":"17406866367975599232214757606801140480252276357934486651183783311435802862074","best_ask":"0.15","best_bid":"0.14","hash":"9db252902efdd377f59c47570a78e642001f650c","price":"0.99","side":"SELL","size":"5863.53"}],"timestamp":"1786845519924"}}
{"f":1174,"recv_ms":1786845520154,"raw":{"event_type":"price_change","market":"0xd5f15f31689703aea70b93a52194a0964220d10d92ee7497346f146a8b6ef8ab","price_changes":[{"asset_id":"2151378744569768920256500242561922410292857798164019061749528550808091180185","best_ask":"0.86","best_bid":"0.85","hash":"96d13d0641881cb2805005e8a628cabef79f217c","price":"0.01","side":"BUY","size":"5858.53"},{"asset_id":"17406866367975599232214757606801140480252276357934486651183783311435802862074","best_ask":"0.15","best_bid":"0.14","hash":"43ad3500dd2cea968a5ab4aede333df5383339ea","price":"0.99","side":"SELL","size":"5858.53"}],"timestamp":"1786845519926"}}
{"f":1175,"recv_ms":1786845520154,"raw":{"event_type":"price_change","market":"0xd5f15f31689703aea70b93a52194a0964220d10d92ee7497346f146a8b6ef8ab","price_changes":[{"asset_id":"2151378744569768920256500242561922410292857798164019061749528550808091180185","best_ask":"0.86","best_bid":"0.85","hash":"ed2bda23c1d23cd4edea6c47a75e23ad6c4e1f6d","price":"0.01","side":"BUY","size":"5958.53"},{"asset_id":"17406866367975599232214757606801140480252276357934486651183783311435802862074","best_ask":"0.15","best_bid":"0.14","hash":"9fe1b81666dc284acabc099dde9a64428cc8b7f2","price":"0.99","side":"SELL","size":"5958.53"}],"timestamp":"1786845519936"}}
{"f":1176,"recv_ms":1786845520159,"raw":{"event_type":"price_change","market":"0xd5f15f31689703aea70b93a52194a0964220d10d92ee7497346f146a8b6ef8ab","price_changes":[{"asset_id":"2151378744569768920256500242561922410292857798164019061749528550808091180185","best_ask":"0.86","best_bid":"0.85","hash":"fd4417c1409e77a56179aab14519708a7c6d70d0","price":"0.01","side":"BUY","size":"5858.53"},{"asset_id":"17406866367975599232214757606801140480252276357934486651183783311435802862074","best_ask":"0.15","best_bid":"0.14","hash":"e2fabc8c5b9c248a67c7440a0a4e31d3d9a6c710","price":"0.99","side":"SELL","size":"5858.53"}],"timestamp":"1786845519942"}}
{"f":1177,"recv_ms":1786845520159,"raw":{"event_type":"price_change","market":"0xd5f15f31689703aea70b93a52194a0964220d10d92ee7497346f146a8b6ef8ab","price_changes":[{"asset_id":"2151378744569768920256500242561922410292857798164019061749528550808091180185","best_ask":"0.86","best_bid":"0.85","hash":"c780625b7bb8a6a0fbbedcfbc5a5256b97ea2fb4","price":"0.01","side":"BUY","size":"5852.53"},{"asset_id":"17406866367975599232214757606801140480252276357934486651183783311435802862074","best_ask":"0.15","best_bid":"0.14","hash":"bad5624d07af25ad47e084241e308fcd236b1862","price":"0.99","side":"SELL","size":"5852.53"}],"timestamp":"1786845519943"}}
{"f":1178,"recv_ms":1786845520162,"raw":{"event_type":"price_change","market":"0xd5f15f31689703aea70b93a52194a0964220d10d92ee7497346f146a8b6ef8ab","price_changes":[{"asset_id":"2151378744569768920256500242561922410292857798164019061749528550808091180185","best_ask":"0.86","best_bid":"0.85","hash":"d5ab5ce62162cb0330f7311fb6fd4dfe25cb8aa6","price":"0.57","side":"BUY","size":"54"},{"asset_id":"17406866367975599232214757606801140480252276357934486651183783311435802862074","best_ask":"0.15","best_bid":"0.14","hash":"06814ca5a34d34e08d93efc47afe36c599adc421","price":"0.43","side":"SELL","size":"54"}],"timestamp":"1786845519948"}}
{"f":1179,"recv_ms":1786845520186,"raw":{"event_type":"price_change","market":"0xd5f15f31689703aea70b93a52194a0964220d10d92ee7497346f146a8b6ef8ab","price_changes":[{"asset_id":"2151378744569768920256500242561922410292857798164019061749528550808091180185","best_ask":"0.86","best_bid":"0.85","hash":"38097ca3bd64e3e35b38a65025b2c8eefa6f7269","price":"0.01","side":"BUY","size":"5857.54"},{"asset_id":"17406866367975599232214757606801140480252276357934486651183783311435802862074","best_ask":"0.15","best_bid":"0.14","hash":"bcbb946672665937b7b50faba89ea2a42523444a","price":"0.99","side":"SELL","size":"5857.54"}],"timestamp":"1786845519952"}}
{"f":1180,"recv_ms":1786845520189,"raw":{"event_type":"price_change","market":"0xd5f15f31689703aea70b93a52194a0964220d10d92ee7497346f146a8b6ef8ab","price_changes":[{"asset_id":"2151378744569768920256500242561922410292857798164019061749528550808091180185","best_ask":"0.86","best_bid":"0.85","hash":"9d9afa41971912eb99be38040bc3bfee804f958b","price":"0.7","side":"BUY","size":"50"},{"asset_id":"17406866367975599232214757606801140480252276357934486651183783311435802862074","best_ask":"0.15","best_bid":"0.14","hash":"5ba56fcde04cfdeafa73fb50af7dafbb2c385edf","price":"0.3","side":"SELL","size":"50"}],"timestamp":"1786845519974"}}
{"f":1181,"recv_ms":1786845520189,"raw":{"event_type":"price_change","market":"0xd5f15f31689703aea70b93a52194a0964220d10d92ee7497346f146a8b6ef8ab","price_changes":[{"asset_id":"17406866367975599232214757606801140480252276357934486651183783311435802862074","best_ask":"0.15","best_bid":"0.14","hash":"5f4c7bcc683a3d9f97bc6a95d69765c2b937f8a6","price":"0.01","side":"BUY","size":"5688.18"},{"asset_id":"2151378744569768920256500242561922410292857798164019061749528550808091180185","best_ask":"0.86","best_bid":"0.85","hash":"bd3b08a05049d6bad7faa2897292320ad2c6c95f","price":"0.99","side":"SELL","size":"5688.18"}],"timestamp":"1786845519977"}}
{"f":1182,"recv_ms":1786845520197,"raw":{"event_type":"price_change","market":"0xd5f15f31689703aea70b93a52194a0964220d10d92ee7497346f146a8b6ef8ab","price_changes":[{"asset_id":"2151378744569768920256500242561922410292857798164019061749528550808091180185","best_ask":"0.86","best_bid":"0.85","hash":"c2f695ada9ae9d46fbd19e52c90220506a2a8560","price":"0.02","side":"BUY","size":"1925.19"},{"asset_id":"17406866367975599232214757606801140480252276357934486651183783311435802862074","best_ask":"0.15","best_bid":"0.14","hash":"4217d36d54247b00db86927e21550aef9a956b37","price":"0.98","side":"SELL","size":"1925.19"}],"timestamp":"1786845519980"}}
{"f":1183,"recv_ms":1786845520218,"raw":{"event_type":"price_change","market":"0xd5f15f31689703aea70b93a52194a0964220d10d92ee7497346f146a8b6ef8ab","price_changes":[{"asset_id":"2151378744569768920256500242561922410292857798164019061749528550808091180185","best_ask":"0.86","best_bid":"0.85","hash":"a1f350ee7efe75256ddd3f3841cbe8cfb87380bd","price":"0.01","side":"BUY","size":"5852.53"},{"asset_id":"17406866367975599232214757606801140480252276357934486651183783311435802862074","best_ask":"0.15","best_bid":"0.14","hash":"35f0a6f763eca0bcc463fa096387fa249bad8682","price":"0.99","side":"SELL","size":"5852.53"}],"timestamp":"1786845519981"}}
{"f":1184,"recv_ms":1786845520218,"raw":{"event_type":"price_change","market":"0xd5f15f31689703aea70b93a52194a0964220d10d92ee7497346f146a8b6ef8ab","price_changes":[{"asset_id":"2151378744569768920256500242561922410292857798164019061749528550808091180185","best_ask":"0.86","best_bid":"0.85","hash":"b621bd6ff2b75393c34de088f8c7392ab332b008","price":"0.01","side":"BUY","size":"5752.53"},{"asset_id":"17406866367975599232214757606801140480252276357934486651183783311435802862074","best_ask":"0.15","best_bid":"0.14","hash":"76b04f73328b78c07b4231077212a36ecc4544ed","price":"0.99","side":"SELL","size":"5752.53"}],"timestamp":"1786845519983"}}
{"f":1185,"recv_ms":1786845520241,"raw":{"event_type":"price_change","market":"0xd5f15f31689703aea70b93a52194a0964220d10d92ee7497346f146a8b6ef8ab","price_changes":[{"asset_id":"2151378744569768920256500242561922410292857798164019061749528550808091180185","best_ask":"0.86","best_bid":"0.85","hash":"01b07970f0a2e1eb4d49dedab75b1664f209db8a","price":"0.01","side":"BUY","size":"5758.53"},{"asset_id":"17406866367975599232214757606801140480252276357934486651183783311435802862074","best_ask":"0.15","best_bid":"0.14","hash":"4c9dd793e66f56418a18b2b2119366954ac6c302","price":"0.99","side":"SELL","size":"5758.53"}],"timestamp":"1786845520012"}}
{"f":1186,"recv_ms":1786845520241,"raw":{"event_type":"price_change","market":"0xd5f15f31689703aea70b93a52194a0964220d10d92ee7497346f146a8b6ef8ab","price_changes":[{"asset_id":"2151378744569768920256500242561922410292857798164019061749528550808091180185","best_ask":"0.86","best_bid":"0.85","hash":"ae36f46861bc09c02d64e0dc819d62131719be66","price":"0.01","side":"BUY","size":"5858.53"},{"asset_id":"17406866367975599232214757606801140480252276357934486651183783311435802862074","best_ask":"0.15","best_bid":"0.14","hash":"99897f605b56ccb86214c2bd2742b29346d7dbe3","price":"0.99","side":"SELL","size":"5858.53"}],"timestamp":"1786845520013"}}
{"f":1187,"recv_ms":1786845520241,"raw":{"event_type":"price_change","market":"0xd5f15f31689703aea70b93a52194a0964220d10d92ee7497346f146a8b6ef8ab","price_changes":[{"asset_id":"2151378744569768920256500242561922410292857798164019061749528550808091180185","best_ask":"0.86","best_bid":"0.85","hash":"4ff62653ed2f1d50677dbfe1f3c5bf361e362b63","price":"0.01","side":"BUY","size":"5863.53"},{"asset_id":"17406866367975599232214757606801140480252276357934486651183783311435802862074","best_ask":"0.15","best_bid":"0.14","hash":"8143a09484d6792b9899a260e410f196742a671a","price":"0.99","side":"SELL","size":"5863.53"}],"timestamp":"1786845520015"}}
{"f":1188,"recv_ms":1786845520245,"raw":{"event_type":"price_change","market":"0xd5f15f31689703aea70b93a52194a0964220d10d92ee7497346f146a8b6ef8ab","price_changes":[{"asset_id":"17406866367975599232214757606801140480252276357934486651183783311435802862074","best_ask":"0.15","best_bid":"0.14","hash":"f61ae1a18789e46df4bc9616c8506798d8884761","price":"0.01","side":"BUY","size":"5683.18"},{"asset_id":"2151378744569768920256500242561922410292857798164019061749528550808091180185","best_ask":"0.86","best_bid":"0.85","hash":"bbdcd25b5f29bcefa48c52af04400d95a87ec222","price":"0.99","side":"SELL","size":"5683.18"}],"timestamp":"1786845520030"}}
{"f":1189,"recv_ms":1786845520245,"raw":{"event_type":"price_change","market":"0xd5f15f31689703aea70b93a52194a0964220d10d92ee7497346f146a8b6ef8ab","price_changes":[{"asset_id":"2151378744569768920256500242561922410292857798164019061749528550808091180185","best_ask":"0.86","best_bid":"0.85","hash":"b1e9691dfa59a80f0102ed48f10653fc1336f1f6","price":"0.01","side":"BUY","size":"5868.53"},{"asset_id":"17406866367975599232214757606801140480252276357934486651183783311435802862074","best_ask":"0.15","best_bid":"0.14","hash":"a7a64cec91484f0de746f6399ff96eef8328e6c6","price":"0.99","side":"SELL","size":"5868.53"}],"timestamp":"1786845520033"}}
{"f":1190,"recv_ms":1786845520246,"raw":{"event_type":"price_change","market":"0xd5f15f31689703aea70b93a52194a0964220d10d92ee7497346f146a8b6ef8ab","price_changes":[{"asset_id":"2151378744569768920256500242561922410292857798164019061749528550808091180185","best_ask":"0.86","best_bid":"0.85","hash":"ecf0069952514bbe67b58ed76a935fb0d63c6a2c","price":"0.01","side":"BUY","size":"5873.53"},{"asset_id":"17406866367975599232214757606801140480252276357934486651183783311435802862074","best_ask":"0.15","best_bid":"0.14","hash":"7019e12a44512e3768188eb3285847a328dbcf36","price":"0.99","side":"SELL","size":"5873.53"}],"timestamp":"1786845520034"}}
{"f":1191,"recv_ms":1786845520248,"raw":{"event_type":"price_change","market":"0xd5f15f31689703aea70b93a52194a0964220d10d92ee7497346f146a8b6ef8ab","price_changes":[{"asset_id":"2151378744569768920256500242561922410292857798164019061749528550808091180185","best_ask":"0.86","best_bid":"0.85","hash":"92b4533cb005ca5c13698352586eb94867e20d77","price":"0.01","side":"BUY","size":"5878.53"},{"asset_id":"17406866367975599232214757606801140480252276357934486651183783311435802862074","best_ask":"0.15","best_bid":"0.14","hash":"2e6fe06a3b4c69a1983501c077f10a1515d6f111","price":"0.99","side":"SELL","size":"5878.53"}],"timestamp":"1786845520036"}}
{"f":1192,"recv_ms":1786845520250,"raw":{"event_type":"price_change","market":"0xd5f15f31689703aea70b93a52194a0964220d10d92ee7497346f146a8b6ef8ab","price_changes":[{"asset_id":"2151378744569768920256500242561922410292857798164019061749528550808091180185","best_ask":"0.86","best_bid":"0.85","hash":"6e200081afc2d88a049155524210f12fda9936b9","price":"0.01","side":"BUY","size":"5873.53"},{"asset_id":"17406866367975599232214757606801140480252276357934486651183783311435802862074","best_ask":"0.15","best_bid":"0.14","hash":"9c68391d24f57636a8f552ec9ad883bf688bb663","price":"0.99","side":"SELL","size":"5873.53"}],"timestamp":"1786845520037"}}
{"f":1193,"recv_ms":1786845520256,"raw":{"event_type":"price_change","market":"0xd5f15f31689703aea70b93a52194a0964220d10d92ee7497346f146a8b6ef8ab","price_changes":[{"asset_id":"17406866367975599232214757606801140480252276357934486651183783311435802862074","best_ask":"0.15","best_bid":"0.14","hash":"640908b9fad67d043f67b3cb568427a709d19ed6","price":"0.01","side":"BUY","size":"5688.18"},{"asset_id":"2151378744569768920256500242561922410292857798164019061749528550808091180185","best_ask":"0.86","best_bid":"0.85","hash":"68dba752e1d439f906c4ce61b73bccea9e6d0cde","price":"0.99","side":"SELL","size":"5688.18"}],"timestamp":"1786845520038"}}
{"f":1194,"recv_ms":1786845520257,"raw":{"event_type":"price_change","market":"0xd5f15f31689703aea70b93a52194a0964220d10d92ee7497346f146a8b6ef8ab","price_changes":[{"asset_id":"17406866367975599232214757606801140480252276357934486651183783311435802862074","best_ask":"0.15","best_bid":"0.14","hash":"6b742aa500e9a66db700a8823bea8243b7929e6f","price":"0.01","side":"BUY","size":"5683.18"},{"asset_id":"2151378744569768920256500242561922410292857798164019061749528550808091180185","best_ask":"0.86","best_bid":"0.85","hash":"201acb3e2c67015c781a0ddd2e621d01b18c54ba","price":"0.99","side":"SELL","size":"5683.18"}],"timestamp":"1786845520038"}}
{"f":1195,"recv_ms":1786845520257,"raw":{"event_type":"price_change","market":"0xd5f15f31689703aea70b93a52194a0964220d10d92ee7497346f146a8b6ef8ab","price_changes":[{"asset_id":"17406866367975599232214757606801140480252276357934486651183783311435802862074","best_ask":"0.15","best_bid":"0.14","hash":"788c0765a80c24b17d00fd47475782771f37e931","price":"0.01","side":"BUY","size":"5688.18"},{"asset_id":"2151378744569768920256500242561922410292857798164019061749528550808091180185","best_ask":"0.86","best_bid":"0.85","hash":"f77806ba0391f2458bde947aff5640aad82360b1","price":"0.99","side":"SELL","size":"5688.18"}],"timestamp":"1786845520039"}}
{"f":1196,"recv_ms":1786845520261,"raw":{"event_type":"price_change","market":"0xd5f15f31689703aea70b93a52194a0964220d10d92ee7497346f146a8b6ef8ab","price_changes":[{"asset_id":"2151378744569768920256500242561922410292857798164019061749528550808091180185","best_ask":"0.86","best_bid":"0.85","hash":"71ba4df022b9e406a1f27e6060df04f05f6b9762","price":"0.01","side":"BUY","size":"5773.53"},{"asset_id":"17406866367975599232214757606801140480252276357934486651183783311435802862074","best_ask":"0.15","best_bid":"0.14","hash":"6740335bdab1b5888dbee61a1303f223936ad4a8","price":"0.99","side":"SELL","size":"5773.53"}],"timestamp":"1786845520045"}}
{"f":1197,"recv_ms":1786845520274,"raw":{"event_type":"price_change","market":"0xd5f15f31689703aea70b93a52194a0964220d10d92ee7497346f146a8b6ef8ab","price_changes":[{"asset_id":"2151378744569768920256500242561922410292857798164019061749528550808091180185","best_ask":"0.86","best_bid":"0.85","hash":"35e6279140e637a988ac011c60cb9d1b8a7fc2ef","price":"0.58","side":"BUY","size":"19"},{"asset_id":"17406866367975599232214757606801140480252276357934486651183783311435802862074","best_ask":"0.15","best_bid":"0.14","hash":"d67ff0e60d2425ca58672dafe3a065609c039d7c","price":"0.42","side":"SELL","size":"19"}],"timestamp":"1786845520049"}}
{"f":1198,"recv_ms":1786845520274,"raw":{"event_type":"price_change","market":"0xd5f15f31689703aea70b93a52194a0964220d10d92ee7497346f146a8b6ef8ab","price_changes":[{"asset_id":"17406866367975599232214757606801140480252276357934486651183783311435802862074","best_ask":"0.15","best_bid":"0.14","hash":"2a25cb944d1b6a986773504fbf3e91236af23c93","price":"0.38","side":"SELL","size":"188.66"},{"asset_id":"2151378744569768920256500242561922410292857798164019061749528550808091180185","best_ask":"0.86","best_bid":"0.85","hash":"0154b5aca8c7eb9ddcb1058523a3f19d9f9a9121","price":"0.62","side":"BUY","size":"188.66"}],"timestamp":"1786845520049"}}
{"f":1199,"recv_ms":1786845520274,"raw":{"event_type":"price_change","market":"0xd5f15f31689703aea70b93a52194a0964220d10d92ee7497346f146a8b6ef8ab","price_changes":[{"asset_id":"2151378744569768920256500242561922410292857798164019061749528550808091180185","best_ask":"0.86","best_bid":"0.85","hash":"12fd5c8e112b79870895de42771d96acc5702d7e","price":"0.01","side":"BUY","size":"5767.53"},{"asset_id":"17406866367975599232214757606801140480252276357934486651183783311435802862074","best_ask":"0.15","best_bid":"0.14","hash":"d30234c7c288f76480a4b11a26a92a9bf3558b19","price":"0.99","side":"SELL","size":"5767.53"}],"timestamp":"1786845520049"}}
{"f":1200,"recv_ms":1786845520274,"raw":{"event_type":"price_change","market":"0xd5f15f31689703aea70b93a52194a0964220d10d92ee7497346f146a8b6ef8ab","price_changes":[{"asset_id":"2151378744569768920256500242561922410292857798164019061749528550808091180185","best_ask":"0.86","best_bid":"0.85","hash":"6c5189440c477b58929d8db1f921aa939e287043","price":"0.6","side":"BUY","size":"18"},{"asset_id":"17406866367975599232214757606801140480252276357934486651183783311435802862074","best_ask":"0.15","best_bid":"0.14","hash":"8dc53fd8045901c27e8db8fa42ef0f9b1b700d25","price":"0.4","side":"SELL","size":"18"}],"timestamp":"1786845520050"}}
{"f":1201,"recv_ms":1786845520274,"raw":{"event_type":"price_change","market":"0xd5f15f31689703aea70b93a52194a0964220d10d92ee7497346f146a8b6ef8ab","price_changes":[{"asset_id":"2151378744569768920256500242561922410292857798164019061749528550808091180185","best_ask":"0.86","best_bid":"0.85","hash":"727c36f46ad990178f79774a3c70fc6358a2bc80","price":"0.59","side":"BUY","size":"18"},{"asset_id":"17406866367975599232214757606801140480252276357934486651183783311435802862074","best_ask":"0.15","best_bid":"0.14","hash":"3e7005c475bdf54f49ac07cea5ec7aaccd8b9dc0","price":"0.41","side":"SELL","size":"18"}],"timestamp":"1786845520050"}}
{"f":1202,"recv_ms":1786845520274,"raw":{"event_type":"price_change","market":"0xd5f15f31689703aea70b93a52194a0964220d10d92ee7497346f146a8b6ef8ab","price_changes":[{"asset_id":"17406866367975599232214757606801140480252276357934486651183783311435802862074","best_ask":"0.15","best_bid":"0.14","hash":"8dcbd96df8a7724e0f6b7abd0f95a0f38b5b31d9","price":"0.39","side":"SELL","size":"84.22"},{"asset_id":"2151378744569768920256500242561922410292857798164019061749528550808091180185","best_ask":"0.86","best_bid":"0.85","hash":"0394d83cadf6c25346b29fc5a5457d7a0b909d2f","price":"0.61","side":"BUY","size":"84.22"}],"timestamp":"1786845520050"}}
{"f":1203,"recv_ms":1786845520299,"raw":{"event_type":"price_change","market":"0xd5f15f31689703aea70b93a52194a0964220d10d92ee7497346f146a8b6ef8ab","price_changes":[{"asset_id":"2151378744569768920256500242561922410292857798164019061749528550808091180185","best_ask":"0.86","best_bid":"0.85","hash":"49e33ef631b581b8825116fa311ad80f14179055","price":"0.01","side":"BUY","size":"5762.53"},{"asset_id":"17406866367975599232214757606801140480252276357934486651183783311435802862074","best_ask":"0.15","best_bid":"0.14","hash":"8cdf0968a86384bbaa17965c3bdc7bd0be581f51","price":"0.99","side":"SELL","size":"5762.53"}],"timestamp":"1786845520067"}}
{"f":1204,"recv_ms":1786845520301,"raw":{"event_type":"price_change","market":"0xd5f15f31689703aea70b93a52194a0964220d10d92ee7497346f146a8b6ef8ab","price_changes":[{"asset_id":"2151378744569768920256500242561922410292857798164019061749528550808091180185","best_ask":"0.86","best_bid":"0.85","hash":"c6fb3c76908bc03a927d09aaf24279e84a86598a","price":"0.79","side":"BUY","size":"5"},{"asset_id":"17406866367975599232214757606801140480252276357934486651183783311435802862074","best_ask":"0.15","best_bid":"0.14","hash":"be5fadf7a8cb0d7780934535bb6383f725d876f3","price":"0.21","side":"SELL","size":"5"}],"timestamp":"1786845520089"}}
{"f":1205,"recv_ms":1786845520301,"raw":{"event_type":"price_change","market":"0xd5f15f31689703aea70b93a52194a0964220d10d92ee7497346f146a8b6ef8ab","price_changes":[{"asset_id":"17406866367975599232214757606801140480252276357934486651183783311435802862074","best_ask":"0.15","best_bid":"0.14","hash":"fa3b8f5de81cd08919e77b2b7832cf9a5053a259","price":"0.04","side":"BUY","size":"367.7"},{"asset_id":"2151378744569768920256500242561922410292857798164019061749528550808091180185","best_ask":"0.86","best_bid":"0.85","hash":"23e70d981aece2f1deee1168ec9b4bd07dceb222","price":"0.96","side":"SELL","size":"367.7"}],"timestamp":"1786845520090"}}
{"f":1206,"recv_ms":1786845520303,"raw":{"event_type":"price_change","market":"0xd5f15f31689703aea70b93a52194a0964220d10d92ee7497346f146a8b6ef8ab","price_changes":[{"asset_id":"2151378744569768920256500242561922410292857798164019061749528550808091180185","best_ask":"0.86","best_bid":"0.85","hash":"64f64d712abfa49d6fa90bf246096e5f3bdda23d","price":"0.78","side":"BUY","size":"7"},{"asset_id":"17406866367975599232214757606801140480252276357934486651183783311435802862074","best_ask":"0.15","best_bid":"0.14","hash":"33188aa19c84eba337521be83189a02076f36215","price":"0.22","side":"SELL","size":"7"}],"timestamp":"1786845520091"}}
{"f":1207,"recv_ms":1786845520303,"raw":{"event_type":"price_change","market":"0xd5f15f31689703aea70b93a52194a0964220d10d92ee7497346f146a8b6ef8ab","price_changes":[{"asset_id":"2151378744569768920256500242561922410292857798164019061749528550808091180185","best_ask":"0.86","best_bid":"0.85","hash":"914feb12a52e65a02ea009995da09b2f38cfad21","price":"0.72","side":"BUY","size":"20"},{"asset_id":"17406866367975599232214757606801140480252276357934486651183783311435802862074","best_ask":"0.15","best_bid":"0.14","hash":"a6ac9f24b5bbc078ff7efff1b627d6ec15e68e61","price":"0.28","side":"SELL","size":"20"}],"timestamp":"1786845520091"}}
