{"f":1208,"recv_ms":1786845520308,"raw":{"event_type":"price_change","market":"0xd5f15f31689703aea70b93a52194a0964220d10d92ee7497346f146a8b6ef8ab","price_changes":[{"asset_id":"2151378744569768920256500242561922410292857798164019061749528550808091180185","best_ask":"0.86","best_bid":"0.85","hash":"28ce09b14fa5cf46e18dd0d1378a9030f244ecdd","price":"0.38","side":"BUY","size":"24"},{"asset_id":"17406866367975599232214757606801140480252276357934486651183783311435802862074","best_ask":"0.15","best_bid":"0.14","hash":"3e47cddfef8729a57bf9909f96fcc31272c461ad","price":"0.62","side":"SELL","size":"24"}],"timestamp":"1786845520091"}}
{"f":1209,"recv_ms":1786845520308,"raw":{"event_type":"price_change","market":"0xd5f15f31689703aea70b93a52194a0964220d10d92ee7497346f146a8b6ef8ab","price_changes":[{"asset_id":"2151378744569768920256500242561922410292857798164019061749528550808091180185","best_ask":"0.86","best_bid":"0.85","hash":"f93d87c19d7a5a3d422494f93833ed9b88e2f163","price":"0.73","side":"BUY","size":"12"},{"asset_id":"17406866367975599232214757606801140480252276357934486651183783311435802862074","best_ask":"0.15","best_bid":"0.14","hash":"aba9984e8cb0333703235060b41c2231c4869742","price":"0.27","side":"SELL","size":"12"}],"timestamp":"1786845520091"}}
{"f":1210,"recv_ms":1786845520308,"raw":{"event_type":"price_change","market":"0xd5f15f31689703aea70b93a52194a0964220d10d92ee7497346f146a8b6ef8ab","price_changes":[{"asset_id":"17406866367975599232214757606801140480252276357934486651183783311435802862074","best_ask":"0.15","best_bid":"0.14","hash":"de37760cd714b775e61b0453f5c5aa8d1526eed4","price":"0.34","side":"SELL","size":"18"},{"asset_id":"2151378744569768920256500242561922410292857798164019061749528550808091180185","best_ask":"0.86","best_bid":"0.85","hash":"fb899c21be5999f882c1c82b1c2cf3558906822a","price":"0.66","side":"BUY","size":"18"}],"timestamp":"1786845520093"}}
{"f":1211,"recv_ms":1786845520314,"raw":{"event_type":"price_change","market":"0xd5f15f31689703aea70b93a52194a0964220d10d92ee7497346f146a8b6ef8ab","price_changes":[{"asset_id":"2151378744569768920256500242561922410292857798164019061749528550808091180185","best_ask":"0.86","best_bid":"0.85","hash":"b7641a9fe20c449be5cfa375e1dfb402a539a595","price":"0.55","side":"BUY","size":"139"},{"asset_id":"17406866367975599232214757606801140480252276357934486651183783311435802862074","best_ask":"0.15","best_bid":"0.14","hash":"23161819e9011406f91aaa84777e3122f4b23d57","price":"0.45","side":"SELL","size":"139"}],"timestamp":"1786845520097"}}
{"f":1212,"recv_ms":1786845520314,"raw":{"event_type":"price_change","market":"0xd5f15f31689703aea70b93a52194a0964220d10d92ee7497346f146a8b6ef8ab","price_changes":[{"asset_id":"17406866367975599232214757606801140480252276357934486651183783311435802862074","best_ask":"0.15","best_bid":"0.14","hash":"1e9bee3eb3a0c15d4cb5b1f217aacf9c9baafbdf","price":"0.33","side":"SELL","size":"123"},{"asset_id":"2151378744569768920256500242561922410292857798164019061749528550808091180185","best_ask":"0.86","best_bid":"0.85","hash":"493d4a85cd11d6e7def64beff57a53c97d970fdb","price":"0.67","side":"BUY","size":"123"}],"timestamp":"1786845520100"}}
{"f":1213,"recv_ms":1786845520329,"raw":{"event_type":"price_change","market":"0xd5f15f31689703aea70b93a52194a0964220d10d92ee7497346f146a8b6ef8ab","price_changes":[{"asset_id":"2151378744569768920256500242561922410292857798164019061749528550808091180185","best_ask":"0.86","best_bid":"0.85","hash":"a842c89d805b4887a70672e4fd36380332dba5c4","price":"0.01","side":"BUY","size":"5757.53"},{"asset_id":"17406866367975599232214757606801140480252276357934486651183783311435802862074","best_ask":"0.15","best_bid":"0.14","hash":"4a851883572a370a3875d9be1e6423f84f4b74ab","price":"0.99","side":"SELL","size":"5757.53"}],"timestamp":"1786845520103"}}
{"f":1214,"recv_ms":1786845520329,"raw":{"event_type":"price_change","market":"0xd5f15f31689703aea70b93a52194a0964220d10d92ee7497346f146a8b6ef8ab","price_changes":[{"asset_id":"2151378744569768920256500242561922410292857798164019061749528550808091180185","best_ask":"0.86","best_bid":"0.85","hash":"200f13c4fcd454267c14e1bde0c31eab78e86819","price":"0.01","side":"BUY","size":"5857.53"},{"asset_id":"17406866367975599232214757606801140480252276357934486651183783311435802862074","best_ask":"0.15","best_bid":"0.14","hash":"d8114b87e3ae8d89280953b8927e2724eba69a6c","price":"0.99","side":"SELL","size":"5857.53"}],"timestamp":"1786845520107"}}
{"f":1215,"recv_ms":1786845520329,"raw":{"event_type":"price_change","market":"0xd5f15f31689703aea70b93a52194a0964220d10d92ee7497346f146a8b6ef8ab","price_changes":[{"asset_id":"2151378744569768920256500242561922410292857798164019061749528550808091180185","best_ask":"0.86","best_bid":"0.85","hash":"c08df7e7cbc778b0f0cc370a162d0eaec7dab785","price":"0.01","side":"BUY","size":"5863.53"},{"asset_id":"17406866367975599232214757606801140480252276357934486651183783311435802862074","best_ask":"0.15","best_bid":"0.14","hash":"c6322aad83ba15a9a687ea68254049ad7eab9a18","price":"0.99","side":"SELL","size":"5863.53"}],"timestamp":"1786845520117"}}
{"f":1216,"recv_ms":1786845520334,"raw":{"event_type":"price_change","market":"0xd5f15f31689703aea70b93a52194a0964220d10d92ee7497346f146a8b6ef8ab","price_changes":[{"asset_id":"17406866367975599232214757606801140480252276357934486651183783311435802862074","best_ask":"0.15","best_bid":"0.14","hash":"c31b30545c6eea9db0a9a8ca31f7846ea63b71d0","price":"0.01","side":"BUY","size":"5693.18"},{"asset_id":"2151378744569768920256500242561922410292857798164019061749528550808091180185","best_ask":"0.86","best_bid":"0.85","hash":"10c776b29fcc9acab9e65a1ce6ad5946b933ef26","price":"0.99","side":"SELL","size":"5693.18"}],"timestamp":"1786845520121"}}
{"f":1217,"recv_ms":1786845520354,"raw":{"event_type":"price_change","market":"0xd5f15f31689703aea70b93a52194a0964220d10d92ee7497346f146a8b6ef8ab","price_changes":[{"asset_id":"2151378744569768920256500242561922410292857798164019061749528550808091180185","best_ask":"0.86","best_bid":"0.85","hash":"1b4ca2d47cc0a35c098d6d21d3234ea19d497f85","price":"0.76","side":"BUY","size":"30"},{"asset_id":"17406866367975599232214757606801140480252276357934486651183783311435802862074","best_ask":"0.15","best_bid":"0.14","hash":"ef4f982d34b8df3576ac6c054d565be719e2d50e","price":"0.24","side":"SELL","size":"30"}],"timestamp":"1786845520123"}}
{"f":1218,"recv_ms":1786845520354,"raw":{"event_type":"price_change","market":"0xd5f15f31689703aea70b93a52194a0964220d10d92ee7497346f146a8b6ef8ab","price_changes":[{"asset_id":"2151378744569768920256500242561922410292857798164019061749528550808091180185","best_ask":"0.86","best_bid":"0.85","hash":"b176a10bda737ee7cb97b985c2c4120ce626505d","price":"0.01","side":"BUY","size":"5858.53"},{"asset_id":"17406866367975599232214757606801140480252276357934486651183783311435802862074","best_ask":"0.15","best_bid":"0.14","hash":"6edbc0529d15e8605e05bac25c959fd787cc6bf5","price":"0.99","side":"SELL","size":"5858.53"}],"timestamp":"1786845520136"}}
{"f":1219,"recv_ms":1786845520357,"raw":{"event_type":"price_change","market":"0xd5f15f31689703aea70b93a52194a0964220d10d92ee7497346f146a8b6ef8ab","price_changes":[{"asset_id":"2151378744569768920256500242561922410292857798164019061749528550808091180185","best_ask":"0.86","best_bid":"0.85","hash":"f9f1e64dc79cd55c59651cf4f0441f00dc7e25f1","price":"0.77","side":"BUY","size":"75"},{"asset_id":"17406866367975599232214757606801140480252276357934486651183783311435802862074","best_ask":"0.15","best_bid":"0.14","hash":"0e698b2135580c3c1f18190318537135f4158d04","price":"0.23","side":"SELL","size":"75"}],"timestamp":"1786845520143"}}
{"f":1220,"recv_ms":1786845520357,"raw":{"event_type":"price_change","market":"0xd5f15f31689703aea70b93a52194a0964220d10d92ee7497346f146a8b6ef8ab","price_changes":[{"asset_id":"2151378744569768920256500242561922410292857798164019061749528550808091180185","best_ask":"0.86","best_bid":"0.85","hash":"ff62a3e17837b94b0104aedb8b8e1d41a3e445f9","price":"0.01","side":"BUY","size":"5852.53"},{"asset_id":"17406866367975599232214757606801140480252276357934486651183783311435802862074","best_ask":"0.15","best_bid":"0.14","hash":"cb6ca1859cae7460db7e0c8761b1ab48bfc7bee8","price":"0.99","side":"SELL","size":"5852.53"}],"timestamp":"1786845520144"}}
{"f":1221,"recv_ms":1786845520359,"raw":{"event_type":"price_change","market":"0xd5f15f31689703aea70b93a52194a0964220d10d92ee7497346f146a8b6ef8ab","price_changes":[{"asset_id":"17406866367975599232214757606801140480252276357934486651183783311435802862074","best_ask":"0.15","best_bid":"0.14","hash":"481a8c63eab5c7b40702e6c53728a61dfca6f4ea","price":"0.01","side":"BUY","size":"5688.18"},{"asset_id":"2151378744569768920256500242561922410292857798164019061749528550808091180185","best_ask":"0.86","best_bid":"0.85","hash":"35316c5e993286f185d42a93d1e6ad847652b747","price":"0.99","side":"SELL","size":"5688.18"}],"timestamp":"1786845520146"}}
{"f":1222,"recv_ms":1786845520359,"raw":{"event_type":"price_change","market":"0xd5f15f31689703aea70b93a52194a0964220d10d92ee7497346f146a8b6ef8ab","price_changes":[{"asset_id":"17406866367975599232214757606801140480252276357934486651183783311435802862074","best_ask":"0.15","best_bid":"0.14","hash":"6a301302f6f0ccf72bedfd9a4c76a63b2889451d","price":"0.01","side":"BUY","size":"5693.18"},{"asset_id":"2151378744569768920256500242561922410292857798164019061749528550808091180185","best_ask":"0.86","best_bid":"0.85","hash":"abe3b71740ab94239d4d41864da970547fce1565","price":"0.99","side":"SELL","size":"5693.18"}],"timestamp":"1786845520148"}}
{"f":1223,"recv_ms":1786845520364,"raw":{"event_type":"price_change","market":"0xd5f15f31689703aea70b93a52194a0964220d10d92ee7497346f146a8b6ef8ab","price_changes":[{"asset_id":"2151378744569768920256500242561922410292857798164019061749528550808091180185","best_ask":"0.86","best_bid":"0.85","hash":"33f230a8d771b7e5e88c4a8322215e2585e6b116","price":"0.76","side":"BUY","size":"0"},{"asset_id":"17406866367975599232214757606801140480252276357934486651183783311435802862074","best_ask":"0.15","best_bid":"0.14","hash":"725c9131cc5c8203218dc7fb3a1787cca779a421","price":"0.24","side":"SELL","size":"0"}],"timestamp":"1786845520148"}}
{"f":1224,"recv_ms":1786845520364,"raw":{"event_type":"price_change","market":"0xd5f15f31689703aea70b93a52194a0964220d10d92ee7497346f146a8b6ef8ab","price_changes":[{"asset_id":"2151378744569768920256500242561922410292857798164019061749528550808091180185","best_ask":"0.86","best_bid":"0.85","hash":"9cae88ce45e0cb530d6cf90afb5528474183438d","price":"0.01","side":"BUY","size":"5857.54"},{"asset_id":"17406866367975599232214757606801140480252276357934486651183783311435802862074","best_ask":"0.15","best_bid":"0.14","hash":"ab44bedddce96b7bba5a6e88aae36343564f0c2e","price":"0.99","side":"SELL","size":"5857.54"}],"timestamp":"1786845520151"}}
{"f":1225,"recv_ms":1786845520386,"raw":{"event_type":"price_change","market":"0xd5f15f31689703aea70b93a52194a0964220d10d92ee7497346f146a8b6ef8ab","price_changes":[{"asset_id":"2151378744569768920256500242561922410292857798164019061749528550808091180185","best_ask":"0.86","best_bid":"0.85","hash":"6a09200d058fc94a6a98ecd25fb395f5ea4a0acf","price":"0.01","side":"BUY","size":"5757.54"},{"asset_id":"17406866367975599232214757606801140480252276357934486651183783311435802862074","best_ask":"0.15","best_bid":"0.14","hash":"6eea64802e82da2b1edc6c78223d01df2ac3a80d","price":"0.99","side":"SELL","size":"5757.54"}],"timestamp":"1786845520153"}}
{"f":1226,"recv_ms":1786845520387,"raw":{"event_type":"price_change","market":"0xd5f15f31689703aea70b93a52194a0964220d10d92ee7497346f146a8b6ef8ab","price_changes":[{"asset_id":"17406866367975599232214757606801140480252276357934486651183783311435802862074","best_ask":"0.15","best_bid":"0.14","hash":"45bc443ca30a93b40824b90d231e6133e6419c4a","price":"0.01","side":"BUY","size":"5688.18"},{"asset_id":"2151378744569768920256500242561922410292857798164019061749528550808091180185","best_ask":"0.86","best_bid":"0.85","hash":"2ebd60c2e382ac877c5159981ed45c7e1d63bb92","price":"0.99","side":"SELL","size":"5688.18"}],"timestamp":"1786845520169"}}
{"f":1227,"recv_ms":1786845520388,"raw":{"event_type":"price_change","market":"0xd5f15f31689703aea70b93a52194a0964220d10d92ee7497346f146a8b6ef8ab","price_changes":[{"asset_id":"2151378744569768920256500242561922410292857798164019061749528550808091180185","best_ask":"0.86","best_bid":"0.85","hash":"68742899add56f05e89b001adefb9a84e20046ca","price":"0.01","side":"BUY","size":"5857.54"},{"asset_id":"17406866367975599232214757606801140480252276357934486651183783311435802862074","best_ask":"0.15","best_bid":"0.14","hash":"6bb6b354c6ae15e1b747e89e04c720a1d4d20c7b","price":"0.99","side":"SELL","size":"5857.54"}],"timestamp":"1786845520175"}}
{"f":1228,"recv_ms":1786845520416,"raw":{"event_type":"price_change","market":"0xd5f15f31689703aea70b93a52194a0964220d10d92ee7497346f146a8b6ef8ab","price_changes":[{"asset_id":"2151378744569768920256500242561922410292857798164019061749528550808091180185","best_ask":"0.86","best_bid":"0.85","hash":"629902d91c67b4cd794abe45148f8648e492fd09","price":"0.01","side":"BUY","size":"5852.53"},{"asset_id":"17406866367975599232214757606801140480252276357934486651183783311435802862074","best_ask":"0.15","best_bid":"0.14","hash":"fb35a0c2254bc66ae7e48066309508004caf483e","price":"0.99","side":"SELL","size":"5852.53"}],"timestamp":"1786845520179"}}
{"f":1229,"recv_ms":1786845520429,"raw":{"event_type":"price_change","market":"0xd5f15f31689703aea70b93a52194a0964220d10d92ee7497346f146a8b6ef8ab","price_changes":[{"asset_id":"2151378744569768920256500242561922410292857798164019061749528550808091180185","best_ask":"0.86","best_bid":"0.85","hash":"9d8180e958b8b56ffc835b9e24f23a0d66648a27","price":"0.01","side":"BUY","size":"5752.53"},{"asset_id":"17406866367975599232214757606801140480252276357934486651183783311435802862074","best_ask":"0.15","best_bid":"0.14","hash":"d89b30ee0ee2ddaa502214a41d8925dbf63aa202","price":"0.99","side":"SELL","size":"5752.53"}],"timestamp":"1786845520209"}}
{"f":1230,"recv_ms":1786845520442,"raw":{"event_type":"price_change","market":"0xd5f15f31689703aea70b93a52194a0964220d10d92ee7497346f146a8b6ef8ab","price_changes":[{"asset_id":"2151378744569768920256500242561922410292857798164019061749528550808091180185","best_ask":"0.86","best_bid":"0.85","hash":"ae219bd24e6d019a90b80ead8232f215dea2a7c7","price":"0.01","side":"BUY","size":"5758.53"},{"asset_id":"17406866367975599232214757606801140480252276357934486651183783311435802862074","best_ask":"0.15","best_bid":"0.14","hash":"43113a308c3abf5990c26df3500f95cd7bafded2","price":"0.99","side":"SELL","size":"5758.53"}],"timestamp":"1786845520217"}}
{"f":1231,"recv_ms":1786845520445,"raw":{"event_type":"price_change","market":"0xd5f15f31689703aea70b93a52194a0964220d10d92ee7497346f146a8b6ef8ab","price_changes":[{"asset_id":"2151378744569768920256500242561922410292857798164019061749528550808091180185","best_ask":"0.86","best_bid":"0.85","hash":"2b1177b7c6cc2d88c7b2d81ff70615f177d0655f","price":"0.63","side":"BUY","size":"18"},{"asset_id":"17406866367975599232214757606801140480252276357934486651183783311435802862074","best_ask":"0.15","best_bid":"0.14","hash":"7f228acb6631feb52fe6f4f3c91a162e72fad465","price":"0.37","side":"SELL","size":"18"}],"timestamp":"1786845520223"}}
{"f":1232,"recv_ms":1786845520445,"raw":{"event_type":"price_change","market":"0xd5f15f31689703aea70b93a52194a0964220d10d92ee7497346f146a8b6ef8ab","price_changes":[{"asset_id":"2151378744569768920256500242561922410292857798164019061749528550808091180185","best_ask":"0.86","best_bid":"0.85","hash":"af1fbd3e243dbfbeede24473e951b0506e2eb631","price":"0.01","side":"BUY","size":"5753.53"},{"asset_id":"17406866367975599232214757606801140480252276357934486651183783311435802862074","best_ask":"0.15","best_bid":"0.14","hash":"440b19f220a964e38e2cedb67592df021e0c663c","price":"0.99","side":"SELL","size":"5753.53"}],"timestamp":"1786845520227"}}
{"f":1233,"recv_ms":1786845520455,"raw":{"event_type":"price_change","market":"0xd5f15f31689703aea70b93a52194a0964220d10d92ee7497346f146a8b6ef8ab","price_changes":[{"asset_id":"2151378744569768920256500242561922410292857798164019061749528550808091180185","best_ask":"0.86","best_bid":"0.85","hash":"9fc8a0a1150dadf9fe3dff88c3b5c0a0b1665533","price":"0.01","side":"BUY","size":"5758.53"},{"asset_id":"17406866367975599232214757606801140480252276357934486651183783311435802862074","best_ask":"0.15","best_bid":"0.14","hash":"d4cf3ce15a0a7e1f282186905e472a4a9aceb6b5","price":"0.99","side":"SELL","size":"5758.53"}],"timestamp":"1786845520235"}}
{"f":1234,"recv_ms":1786845520455,"raw":{"event_type":"price_change","market":"0xd5f15f31689703aea70b93a52194a0964220d10d92ee7497346f146a8b6ef8ab","price_changes":[{"asset_id":"2151378744569768920256500242561922410292857798164019061749528550808091180185","best_ask":"0.86","best_bid":"0.85","hash":"f171d0d275c89c67663c3f2b3b3206c9854bcc3a","price":"0.01","side":"BUY","size":"5753.53"},{"asset_id":"17406866367975599232214757606801140480252276357934486651183783311435802862074","best_ask":"0.15","best_bid":"0.14","hash":"e78196cd18850a98ca102612545751d962eeeb9b","price":"0.99","side":"SELL","size":"5753.53"}],"timestamp":"1786845520236"}}
{"f":1235,"recv_ms":1786845520456,"raw":{"event_type":"price_change","market":"0xd5f15f31689703aea70b93a52194a0964220d10d92ee7497346f146a8b6ef8ab","price_changes":[{"asset_id":"2151378744569768920256500242561922410292857798164019061749528550808091180185","best_ask":"0.86","best_bid":"0.85","hash":"a7fc1e6da9ad535cd15dcb613ff7a6f64da723a5","price":"0.01","side":"BUY","size":"5758.53"},{"asset_id":"17406866367975599232214757606801140480252276357934486651183783311435802862074","best_ask":"0.15","best_bid":"0.14","hash":"75ce7aeb3eecbe623156d7655109998a4936ecbc","price":"0.99","side":"SELL","size":"5758.53"}],"timestamp":"1786845520240"}}
{"f":1236,"recv_ms":1786845520456,"raw":{"event_type":"price_change","market":"0xd5f15f31689703aea70b93a52194a0964220d10d92ee7497346f146a8b6ef8ab","price_changes":[{"asset_id":"2151378744569768920256500242561922410292857798164019061749528550808091180185","best_ask":"0.86","best_bid":"0.85","hash":"8c3dd68a95983c31755052ddecd114ede1a55207","price":"0.78","side":"BUY","size":"107"},{"asset_id":"17406866367975599232214757606801140480252276357934486651183783311435802862074","best_ask":"0.15","best_bid":"0.14","hash":"42a4bd3960fdc3c5fc5ae2c337e2e98b0897dc67","price":"0.22","side":"SELL","size":"107"}],"timestamp":"1786845520242"}}
{"f":1237,"recv_ms":1786845520456,"raw":{"event_type":"price_change","market":"0xd5f15f31689703aea70b93a52194a0964220d10d92ee7497346f146a8b6ef8ab","price_changes":[{"asset_id":"2151378744569768920256500242561922410292857798164019061749528550808091180185","best_ask":"0.86","best_bid":"0.85","hash":"b1cb7f9e49b479f92c35ce410b68fc67178b894d","price":"0.01","side":"BUY","size":"5752.53"},{"asset_id":"17406866367975599232214757606801140480252276357934486651183783311435802862074","best_ask":"0.15","best_bid":"0.14","hash":"497104efd4f6f77e38d74648e51ef66e7d945a96","price":"0.99","side":"SELL","size":"5752.53"}],"timestamp":"1786845520243"}}
{"f":1238,"recv_ms":1786845520456,"raw":{"event_type":"price_change","market":"0xd5f15f31689703aea70b93a52194a0964220d10d92ee7497346f146a8b6ef8ab","price_changes":[{"asset_id":"2151378744569768920256500242561922410292857798164019061749528550808091180185","best_ask":"0.86","best_bid":"0.85","hash":"2bc675f39a2559ad9080d79d387a764f4c04c24d","price":"0.01","side":"BUY","size":"5757.53"},{"asset_id":"17406866367975599232214757606801140480252276357934486651183783311435802862074","best_ask":"0.15","best_bid":"0.14","hash":"c22769b962fc92b9bf7d817b2db5bd7fefc141e7","price":"0.99","side":"SELL","size":"5757.53"}],"timestamp":"1786845520243"}}
{"f":1239,"recv_ms":1786845520456,"raw":{"event_type":"price_change","market":"0xd5f15f31689703aea70b93a52194a0964220d10d92ee7497346f146a8b6ef8ab","price_changes":[{"asset_id":"2151378744569768920256500242561922410292857798164019061749528550808091180185","best_ask":"0.86","best_bid":"0.85","hash":"281e115a9ea3ec37e6e52caee07513b59f511064","price":"0.01","side":"BUY","size":"5762.53"},{"asset_id":"17406866367975599232214757606801140480252276357934486651183783311435802862074","best_ask":"0.15","best_bid":"0.14","hash":"e0763e35333008d14200d5c393c8f0d7684732bd","price":"0.99","side":"SELL","size":"5762.53"}],"timestamp":"1786845520244"}}
{"f":1240,"recv_ms":1786845520464,"raw":{"event_type":"price_change","market":"0xd5f15f31689703aea70b93a52194a0964220d10d92ee7497346f146a8b6ef8ab","price_changes":[{"asset_id":"2151378744569768920256500242561922410292857798164019061749528550808091180185","best_ask":"0.86","best_bid":"0.85","hash":"eccd96ecd600257acdc2c8f5cacdb15221b4e2c6","price":"0.79","side":"BUY","size":"105"},{"asset_id":"17406866367975599232214757606801140480252276357934486651183783311435802862074","best_ask":"0.15","best_bid":"0.14","hash":"1ee49c3e4a609799ee62c2626612655c6a50fe06","price":"0.21","side":"SELL","size":"105"}],"timestamp":"1786845520245"}}
{"f":1241,"recv_ms":1786845520464,"raw":{"event_type":"price_change","market":"0xd5f15f31689703aea70b93a52194a0964220d10d92ee7497346f146a8b6ef8ab","price_changes":[{"asset_id":"2151378744569768920256500242561922410292857798164019061749528550808091180185","best_ask":"0.86","best_bid":"0.85","hash":"ab958edea524f0eb1a451b87033161e40e7d7401","price":"0.01","side":"BUY","size":"5767.53"},{"asset_id":"17406866367975599232214757606801140480252276357934486651183783311435802862074","best_ask":"0.15","best_bid":"0.14","hash":"51c70f578ffdedf2901503604e6a23d86e24a1b8","price":"0.99","side":"SELL","size":"5767.53"}],"timestamp":"1786845520246"}}
{"f":1242,"recv_ms":1786845520473,"raw":{"event_type":"price_change","market":"0xd5f15f31689703aea70b93a52194a0964220d10d92ee7497346f146a8b6ef8ab","price_changes":[{"asset_id":"2151378744569768920256500242561922410292857798164019061749528550808091180185","best_ask":"0.86","best_bid":"0.85","hash":"5273f2d9ebe86cdc9c74ee43681e11d3d04442e5","price":"0.01","side":"BUY","size":"5867.53"},{"asset_id":"17406866367975599232214757606801140480252276357934486651183783311435802862074","best_ask":"0.15","best_bid":"0.14","hash":"16caefdc11e0c2b737073e9c91421834fa34687f","price":"0.99","side":"SELL","size":"5867.53"}],"timestamp":"1786845520253"}}
{"f":1243,"recv_ms":1786845520483,"raw":{"event_type":"price_change","market":"0xd5f15f31689703aea70b93a52194a0964220d10d92ee7497346f146a8b6ef8ab","price_changes":[{"asset_id":"2151378744569768920256500242561922410292857798164019061749528550808091180185","best_ask":"0.86","best_bid":"0.85","hash":"5b075a7498edadc9a2e84ef434b6dab19408c2d7","price":"0.65","side":"BUY","size":"23.71"},{"asset_id":"17406866367975599232214757606801140480252276357934486651183783311435802862074","best_ask":"0.15","best_bid":"0.14","hash":"6cfef6534dbf162ae44ff7051102334ef59313f1","price":"0.35","side":"SELL","size":"23.71"}],"timestamp":"1786845520262"}}
{"f":1244,"recv_ms":1786845520495,"raw":{"event_type":"price_change","market":"0xd5f15f31689703aea70b93a52194a0964220d10d92ee7497346f146a8b6ef8ab","price_changes":[{"asset_id":"2151378744569768920256500242561922410292857798164019061749528550808091180185","best_ask":"0.86","best_bid":"0.85","hash":"fa77167e2f17fae3e0783787f6730a9f0678642c","price":"0.78","side":"BUY","size":"7"},{"asset_id":"17406866367975599232214757606801140480252276357934486651183783311435802862074","best_ask":"0.15","best_bid":"0.14","hash":"381d9ea91cc41dc3ed3d062c815fcd1d3f166d2d","price":"0.22","side":"SELL","size":"7"}],"timestamp":"1786845520272"}}
{"f":1245,"recv_ms":1786845520495,"raw":{"event_type":"price_change","market":"0xd5f15f31689703aea70b93a52194a0964220d10d92ee7497346f146a8b6ef8ab","price_changes":[{"asset_id":"2151378744569768920256500242561922410292857798164019061749528550808091180185","best_ask":"0.86","best_bid":"0.85","hash":"de2461379adb5188b852d4bba13d9a5952b1adaf","price":"0.01","side":"BUY","size":"5862.53"},{"asset_id":"17406866367975599232214757606801140480252276357934486651183783311435802862074","best_ask":"0.15","best_bid":"0.14","hash":"eaae427bf55f3b847b043e2b50d21532958d0836","price":"0.99","side":"SELL","size":"5862.53"}],"timestamp":"1786845520279"}}
{"f":1246,"recv_ms":1786845520502,"raw":{"event_type":"price_change","market":"0xd5f15f31689703aea70b93a52194a0964220d10d92ee7497346f146a8b6ef8ab","price_changes":[{"asset_id":"2151378744569768920256500242561922410292857798164019061749528550808091180185","best_ask":"0.86","best_bid":"0.85","hash":"3ea5118c210f22f15d195a21ccfaa30968a0c7ec","price":"0.01","side":"BUY","size":"5762.53"},{"asset_id":"17406866367975599232214757606801140480252276357934486651183783311435802862074","best_ask":"0.15","best_bid":"0.14","hash":"57334c56803386558ceb8b0899ec773b8225bd41","price":"0.99","side":"SELL","size":"5762.53"}],"timestamp":"1786845520284"}}
{"f":1247,"recv_ms":1786845520502,"raw":{"event_type":"price_change","market":"0xd5f15f31689703aea70b93a52194a0964220d10d92ee7497346f146a8b6ef8ab","price_changes":[{"asset_id":"2151378744569768920256500242561922410292857798164019061749528550808091180185","best_ask":"0.86","best_bid":"0.85","hash":"e07d0f120fc6ac2a5068854f73b6c5c519f7323a","price":"0.78","side":"BUY","size":"37"},{"asset_id":"17406866367975599232214757606801140480252276357934486651183783311435802862074","best_ask":"0.15","best_bid":"0.14","hash":"c7f76047026e3fd42f2563b88218b5d8cac825da","price":"0.22","side":"SELL","size":"37"}],"timestamp":"1786845520291"}}
{"f":1248,"recv_ms":1786845520522,"raw":{"event_type":"price_change","market":"0xd5f15f31689703aea70b93a52194a0964220d10d92ee7497346f146a8b6ef8ab","price_changes":[{"asset_id":"2151378744569768920256500242561922410292857798164019061749528550808091180185","best_ask":"0.86","best_bid":"0.85","hash":"adf170e97388b8bc01515b854cc9f3976ea3a9d2","price":"0.77","side":"BUY","size":"45"},{"asset_id":"17406866367975599232214757606801140480252276357934486651183783311435802862074","best_ask":"0.15","best_bid":"0.14","hash":"8ac8e00a6ded60dc84f9f5eee385844270b74a38","price":"0.23","side":"SELL","size":"45"}],"timestamp":"1786845520295"}}
{"f":1249,"recv_ms":1786845520522,"raw":{"event_type":"price_change","market":"0xd5f15f31689703aea70b93a52194a0964220d10d92ee7497346f146a8b6ef8ab","price_changes":[{"asset_id":"2151378744569768920256500242561922410292857798164019061749528550808091180185","best_ask":"0.86","best_bid":"0.85","hash":"92e1bd9f7bb5f15411dbc4333d4f26c44390be8d","price":"0.81","side":"BUY","size":"5"},{"asset_id":"17406866367975599232214757606801140480252276357934486651183783311435802862074","best_ask":"0.15","best_bid":"0.14","hash":"9b3209951f77f9fd269e8d7c875b71312a5385d8","price":"0.19","side":"SELL","size":"5"}],"timestamp":"1786845520297"}}
{"f":1250,"recv_ms":1786845520522,"raw":{"event_type":"price_change","market":"0xd5f15f31689703aea70b93a52194a0964220d10d92ee7497346f146a8b6ef8ab","price_changes":[{"asset_id":"2151378744569768920256500242561922410292857798164019061749528550808091180185","best_ask":"0.86","best_bid":"0.85","hash":"063ce80babca277f81b75319fdaaa2f60ece6696","price":"0.52","side":"BUY","size":"40"},{"asset_id":"17406866367975599232214757606801140480252276357934486651183783311435802862074","best_ask":"0.15","best_bid":"0.14","hash":"b9788e83eb0dca7007e33122f7c4163fd55ae886","price":"0.48","side":"SELL","size":"40"}],"timestamp":"1786845520300"}}
{"f":1251,"recv_ms":1786845520530,"raw":{"event_type":"price_change","market":"0xd5f15f31689703aea70b93a52194a0964220d10d92ee7497346f146a8b6ef8ab","price_changes":[{"asset_id":"2151378744569768920256500242561922410292857798164019061749528550808091180185","best_ask":"0.86","best_bid":"0.85","hash":"8abb05421105ceed9b0de934823ef1e7607fdce5","price":"0.01","side":"BUY","size":"5757.53"},{"asset_id":"17406866367975599232214757606801140480252276357934486651183783311435802862074","best_ask":"0.15","best_bid":"0.14","hash":"7a1cc407aafc7c791415a5964036d8ea85dbc475","price":"0.99","side":"SELL","size":"5757.53"}],"timestamp":"1786845520312"}}
{"f":1252,"recv_ms":1786845520542,"raw":{"event_type":"price_change","market":"0xd5f15f31689703aea70b93a52194a0964220d10d92ee7497346f146a8b6ef8ab","price_changes":[{"asset_id":"2151378744569768920256500242561922410292857798164019061749528550808091180185","best_ask":"0.86","best_bid":"0.85","hash":"78062232646150e409181ba23daec4b6f4a1bfc2","price":"0.01","side":"BUY","size":"5763.53"},{"asset_id":"17406866367975599232214757606801140480252276357934486651183783311435802862074","best_ask":"0.15","best_bid":"0.14","hash":"55202ca0227e51563a08b22bfb45ec2dde4b7c91","price":"0.99","side":"SELL","size":"5763.53"}],"timestamp":"1786845520319"}}
{"f":1253,"recv_ms":1786845520545,"raw":{"event_type":"price_change","market":"0xd5f15f31689703aea70b93a52194a0964220d10d92ee7497346f146a8b6ef8ab","price_changes":[{"asset_id":"17406866367975599232214757606801140480252276357934486651183783311435802862074","best_ask":"0.15","best_bid":"0.14","hash":"e42551bac1941808de1bb57390628c7d58e34d24","price":"0.09","side":"BUY","size":"71.7"},{"asset_id":"2151378744569768920256500242561922410292857798164019061749528550808091180185","best_ask":"0.86","best_bid":"0.85","hash":"15f5bce71425544f59f3405f31240eacc9db3df2","price":"0.91","side":"SELL","size":"71.7"}],"timestamp":"1786845520331"}}
{"f":1254,"recv_ms":1786845520545,"raw":{"event_type":"price_change","market":"0xd5f15f31689703aea70b93a52194a0964220d10d92ee7497346f146a8b6ef8ab","price_changes":[{"asset_id":"2151378744569768920256500242561922410292857798164019061749528550808091180185","best_ask":"0.86","best_bid":"0.85","hash":"b5b0b4502d0e16fac33ad73d149476a62d61611d","price":"0.01","side":"BUY","size":"5863.53"},{"asset_id":"17406866367975599232214757606801140480252276357934486651183783311435802862074","best_ask":"0.15","best_bid":"0.14","hash":"349a1accc34a7c0f9311e1568347157369a2c6d2","price":"0.99","side":"SELL","size":"5863.53"}],"timestamp":"1786845520333"}}
{"f":1255,"recv_ms":1786845520550,"raw":{"event_type":"price_change","market":"0xd5f15f31689703aea70b93a52194a0964220d10d92ee7497346f146a8b6ef8ab","price_changes":[{"asset_id":"2151378744569768920256500242561922410292857798164019061749528550808091180185","best_ask":"0.86","best_bid":"0.85","hash":"b259b2ffd5515dab739f1a17a062ec7cb1dfa043","price":"0.85","side":"BUY","size":"299.97"},{"asset_id":"17406866367975599232214757606801140480252276357934486651183783311435802862074","best_ask":"0.15","best_bid":"0.14","hash":"64a3883ecb3225cae54df97953cbc02a39bf232a","price":"0.15","side":"SELL","size":"299.97"}],"timestamp":"1786845520334"}}
{"f":1256,"recv_ms":1786845520550,"raw":{"event_type":"price_change","market":"0xd5f15f31689703aea70b93a52194a0964220d10d92ee7497346f146a8b6ef8ab","price_changes":[{"asset_id":"2151378744569768920256500242561922410292857798164019061749528550808091180185","best_ask":"0.86","best_bid":"0.85","hash":"9559a5826fec4db330c6294658a7a2a648d59876","price":"0.02","side":"BUY","size":"1850.19"},{"asset_id":"17406866367975599232214757606801140480252276357934486651183783311435802862074","best_ask":"0.15","best_bid":"0.14","hash":"efa04fd61b56c7aa4168ba5a305b0277570d6ddc","price":"0.98","side":"SELL","size":"1850.19"}],"timestamp":"1786845520335"}}
{"f":1257,"recv_ms":1786845520554,"raw":{"event_type":"price_change","market":"0xd5f15f31689703aea70b93a52194a0964220d10d92ee7497346f146a8b6ef8ab","price_changes":[{"asset_id":"2151378744569768920256500242561922410292857798164019061749528550808091180185","best_ask":"0.86","best_bid":"0.85","hash":"88bad8d378dd2b4575b4d48662415e008123c414","price":"0.02","side":"BUY","size":"1775.19"},{"asset_id":"17406866367975599232214757606801140480252276357934486651183783311435802862074","best_ask":"0.15","best_bid":"0.14","hash":"75a61b0413f0f798599ebe9f9c3e56c1e6c5652c","price":"0.98","side":"SELL","size":"1775.19"}],"timestamp":"1786845520338"}}
{"f":1258,"recv_ms":1786845520554,"raw":{"event_type":"price_change","market":"0xd5f15f31689703aea70b93a52194a0964220d10d92ee7497346f146a8b6ef8ab","price_changes":[{"asset_id":"2151378744569768920256500242561922410292857798164019061749528550808091180185","best_ask":"0.86","best_bid":"0.85","hash":"981c227aa36a8dd60c61751854e8a0969be7db30","price":"0.02","side":"BUY","size":"1700.19"},{"asset_id":"17406866367975599232214757606801140480252276357934486651183783311435802862074","best_ask":"0.15","best_bid":"0.14","hash":"5d6419fe4af29a6bc31c4e4931675b4c9e1bfb67","price":"0.98","side":"SELL","size":"1700.19"}],"timestamp":"1786845520340"}}
{"f":1259,"recv_ms":1786845520557,"raw":{"event_type":"price_change","market":"0xd5f15f31689703aea70b93a52194a0964220d10d92ee7497346f146a8b6ef8ab","price_changes":[{"asset_id":"2151378744569768920256500242561922410292857798164019061749528550808091180185","best_ask":"0.86","best_bid":"0.85","hash":"4cee95338a9b35c5f1991700c7f046bb3e4c5d2f","price":"0.01","side":"BUY","size":"5857.53"},{"asset_id":"17406866367975599232214757606801140480252276357934486651183783311435802862074","best_ask":"0.15","best_bid":"0.14","hash":"b497efe9890e78c204f855c7f969eb449839e5cc","price":"0.99","side":"SELL","size":"5857.53"}],"timestamp":"1786845520343"}}
{"f":1260,"recv_ms":1786845520557,"raw":{"event_type":"price_change","market":"0xd5f15f31689703aea70b93a52194a0964220d10d92ee7497346f146a8b6ef8ab","price_changes":[{"asset_id":"2151378744569768920256500242561922410292857798164019061749528550808091180185","best_ask":"0.86","best_bid":"0.85","hash":"f8063ba6305ba9f7eb364472104af8c936e745a3","price":"0.01","side":"BUY","size":"5852.53"},{"asset_id":"17406866367975599232214757606801140480252276357934486651183783311435802862074","best_ask":"0.15","best_bid":"0.14","hash":"ed8bfa245d1662740537c0cfa1bd332d97c2fac1","price":"0.99","side":"SELL","size":"5852.53"}],"timestamp":"1786845520344"}}
{"f":1261,"recv_ms":1786845520567,"raw":{"event_type":"price_change","market":"0xd5f15f31689703aea70b93a52194a0964220d10d92ee7497346f146a8b6ef8ab","price_changes":[{"asset_id":"2151378744569768920256500242561922410292857798164019061749528550808091180185","best_ask":"0.86","best_bid":"0.85","hash":"2ef4595c24363fa637d6062f7cb2d74b2ac72b3a","price":"0.01","side":"BUY","size":"5857.54"},{"asset_id":"17406866367975599232214757606801140480252276357934486651183783311435802862074","best_ask":"0.15","best_bid":"0.14","hash":"570b7a59d78e1cbeb24fafeaa34f5acd60411fe7","price":"0.99","side":"SELL","size":"5857.54"}],"timestamp":"1786845520353"}}
{"f":1262,"recv_ms":1786845520581,"raw":{"event_type":"price_change","market":"0xd5f15f31689703aea70b93a52194a0964220d10d92ee7497346f146a8b6ef8ab","price_changes":[{"asset_id":"2151378744569768920256500242561922410292857798164019061749528550808091180185","best_ask":"0.86","best_bid":"0.85","hash":"0e68822c012cf5a403c81f00b1b869bdb4e3f625","price":"0.2","side":"BUY","size":"54.1"},{"asset_id":"17406866367975599232214757606801140480252276357934486651183783311435802862074","best_ask":"0.15","best_bid":"0.14","hash":"766f5b321cb2a5a0c5f9abe627623e8c9ef08664","price":"0.8","side":"SELL","size":"54.1"}],"timestamp":"1786845520356"}}
{"f":1263,"recv_ms":1786845520581,"raw":{"event_type":"price_change","market":"0xd5f15f31689703aea70b93a52194a0964220d10d92ee7497346f146a8b6ef8ab","price_changes":[{"asset_id":"17406866367975599232214757606801140480252276357934486651183783311435802862074","best_ask":"0.15","best_bid":"0.14","hash":"6b95b711531233880061e14c5dec33cdd449b0ab","price":"0.36","side":"SELL","size":"252.49"},{"asset_id":"2151378744569768920256500242561922410292857798164019061749528550808091180185","best_ask":"0.86","best_bid":"0.85","hash":"c30c0f7bd5b68a73fd08c08bcacf74b2b8a112cc","price":"0.64","side":"BUY","size":"252.49"}],"timestamp":"1786845520369"}}
{"f":1264,"recv_ms":1786845520583,"raw":{"event_type":"price_change","market":"0xd5f15f31689703aea70b93a52194a0964220d10d92ee7497346f146a8b6ef8ab","price_changes":[{"asset_id":"2151378744569768920256500242561922410292857798164019061749528550808091180185","best_ask":"0.86","best_bid":"0.85","hash":"ec44ff596504d25e8d317a2424920f53982afa9f","price":"0.64","side":"BUY","size":"246.49"},{"asset_id":"17406866367975599232214757606801140480252276357934486651183783311435802862074","best_ask":"0.15","best_bid":"0.14","hash":"127fceda2c8b9be74f4e5c81605f551e436ae37b","price":"0.36","side":"SELL","size":"246.49"}],"timestamp":"1786845520370"}}
{"f":1265,"recv_ms":1786845520583,"raw":{"event_type":"price_change","market":"0xd5f15f31689703aea70b93a52194a0964220d10d92ee7497346f146a8b6ef8ab","price_changes":[{"asset_id":"17406866367975599232214757606801140480252276357934486651183783311435802862074","best_ask":"0.15","best_bid":"0.14","hash":"e08b8a94ae6e5f8ef3f1ff9bfb463a8387ae17f5","price":"0.14","side":"BUY","size":"9.39"},{"asset_id":"2151378744569768920256500242561922410292857798164019061749528550808091180185","best_ask":"0.86","best_bid":"0.85","hash":"f567dd165dd9957e9b2d43d3fab00b695afa08c5","price":"0.86","side":"SELL","size":"9.39"}],"timestamp":"1786845520371"}}
{"f":1266,"recv_ms":1786845520585,"raw":{"event_type":"price_change","market":"0xd5f15f31689703aea70b93a52194a0964220d10d92ee7497346f146a8b6ef8ab","price_changes":[{"asset_id":"2151378744569768920256500242561922410292857798164019061749528550808091180185","best_ask":"0.86","best_bid":"0.85","hash":"a5f96462c11b601f1d0ba2d6ee514de65fe4bcb6","price":"0.86","side":"SELL","size":"1.39"},{"asset_id":"17406866367975599232214757606801140480252276357934486651183783311435802862074","best_ask":"0.15","best_bid":"0.14","hash":"f7abc5031641f1a45e38c894e57ab05f49ad902e","price":"0.14","side":"BUY","size":"1.39"}],"timestamp":"1786845520372"}}
{"f":1267,"recv_ms":1786845520589,"raw":{"event_type":"price_change","market":"0xd5f15f31689703aea70b93a52194a0964220d10d92ee7497346f146a8b6ef8ab","price_changes":[{"asset_id":"17406866367975599232214757606801140480252276357934486651183783311435802862074","best_ask":"0.15","best_bid":"0.14","hash":"3335fb0d60cb596b13d344f02498b1a0d2e61eb8","price":"0.34","side":"SELL","size":"26"},{"asset_id":"2151378744569768920256500242561922410292857798164019061749528550808091180185","best_ask":"0.86","best_bid":"0.85","hash":"b66d9d2ec595c5711d15bde5d618237fe029ff81","price":"0.66","side":"BUY","size":"26"}],"timestamp":"1786845520376"}}
{"f":1268,"recv_ms":1786845520590,"raw":{"event_type":"price_change","market":"0xd5f15f31689703aea70b93a52194a0964220d10d92ee7497346f146a8b6ef8ab","price_changes":[{"asset_id":"2151378744569768920256500242561922410292857798164019061749528550808091180185","best_ask":"0.86","best_bid":"0.85","hash":"a693bea0b584994aefc3984f6c16d69c80bc53fa","price":"0.01","side":"BUY","size":"5757.54"},{"asset_id":"17406866367975599232214757606801140480252276357934486651183783311435802862074","best_ask":"0.15","best_bid":"0.14","hash":"66595d91d23dd5f24720df6c2637cdc19cd416f1","price":"0.99","side":"SELL","size":"5757.54"}],"timestamp":"1786845520377"}}
{"f":1269,"recv_ms":1786845520590,"raw":{"event_type":"price_change","market":"0xd5f15f31689703aea70b93a52194a0964220d10d92ee7497346f146a8b6ef8ab","price_changes":[{"asset_id":"2151378744569768920256500242561922410292857798164019061749528550808091180185","best_ask":"0.86","best_bid":"0.85","hash":"d2cb8b782963ef5e0eca776a249d214f21fa440d","price":"0.01","side":"BUY","size":"5752.53"},{"asset_id":"17406866367975599232214757606801140480252276357934486651183783311435802862074","best_ask":"0.15","best_bid":"0.14","hash":"5f33f69e1bda81cf66cd132830e825ffa241e6f0","price":"0.99","side":"SELL","size":"5752.53"}],"timestamp":"1786845520378"}}
{"f":1270,"recv_ms":1786845520603,"raw":{"event_type":"price_change","market":"0xd5f15f31689703aea70b93a52194a0964220d10d92ee7497346f146a8b6ef8ab","price_changes":[{"asset_id":"2151378744569768920256500242561922410292857798164019061749528550808091180185","best_ask":"0.86","best_bid":"0.85","hash":"063ef628cab7770096bdebd460e85977d73976d1","price":"0.66","side":"BUY","size":"34"},{"asset_id":"17406866367975599232214757606801140480252276357934486651183783311435802862074","best_ask":"0.15","best_bid":"0.14","hash":"1b20f18ed6bbf15d25994262912ddd81d01937b8","price":"0.34","side":"SELL","size":"34"}],"timestamp":"1786845520379"}}
{"f":1271,"recv_ms":1786845520603,"raw":{"event_type":"price_change","market":"0xd5f15f31689703aea70b93a52194a0964220d10d92ee7497346f146a8b6ef8ab","price_changes":[{"asset_id":"2151378744569768920256500242561922410292857798164019061749528550808091180185","best_ask":"0.86","best_bid":"0.85","hash":"d446a11b050634a727ec50e40a05879c9335c5fe","price":"0.02","side":"BUY","size":"1775.19"},{"asset_id":"17406866367975599232214757606801140480252276357934486651183783311435802862074","best_ask":"0.15","best_bid":"0.14","hash":"12b031efd1ebcb4dde145fc9804c50a284088b15","price":"0.98","side":"SELL","size":"1775.19"}],"timestamp":"1786845520390"}}
{"f":1272,"recv_ms":1786845520614,"raw":{"event_type":"price_change","market":"0xd5f15f31689703aea70b93a52194a0964220d10d92ee7497346f146a8b6ef8ab","price_changes":[{"asset_id":"2151378744569768920256500242561922410292857798164019061749528550808091180185","best_ask":"0.86","best_bid":"0.85","hash":"de1d99761b89e0b8f6544bedcb6e233b832ad7fb","price":"0.86","side":"SELL","size":"7.39"},{"asset_id":"17406866367975599232214757606801140480252276357934486651183783311435802862074","best_ask":"0.15","best_bid":"0.14","hash":"fe0918f0aa7e7ee1179a23072064e7d99a559f1b","price":"0.14","side":"BUY","size":"7.39"}],"timestamp":"1786845520392"}}
{"f":1273,"recv_ms":1786845520626,"raw":{"event_type":"price_change","market":"0x0f808668c26a078e39fb08c32be2c04739e31f58d8d58dc81f3771760aa097da","price_changes":[{"asset_id":"109981215458957430670008039613114505679239971255550615765913446335529931163020","best_ask":"0.51","best_bid":"0.5","hash":"949be9ddff62be2aaeb6b9de5fe2f2d83c46da46","price":"0.13","side":"BUY","size":"38.2"},{"asset_id":"9052432239268584294914812202913499895678363531348080565599375753720096525063","best_ask":"0.5","best_bid":"0.49","hash":"8466872141a00f0011c79ae1412b65e6fd852d5b","price":"0.87","side":"SELL","size":"38.2"}],"timestamp":"1786845520409"}}
{"f":1274,"recv_ms":1786845520631,"raw":{"event_type":"price_change","market":"0xd5f15f31689703aea70b93a52194a0964220d10d92ee7497346f146a8b6ef8ab","price_changes":[{"asset_id":"2151378744569768920256500242561922410292857798164019061749528550808091180185","best_ask":"0.86","best_bid":"0.85","hash":"384d5a769cc3a398ec261b11f77896758e2c3cb3","price":"0.01","side":"BUY","size":"5758.53"},{"asset_id":"17406866367975599232214757606801140480252276357934486651183783311435802862074","best_ask":"0.15","best_bid":"0.14","hash":"1bb7a2001b37f1df00459adb89529cb91d527cf3","price":"0.99","side":"SELL","size":"5758.53"}],"timestamp":"1786845520411"}}
{"f":1275,"recv_ms":1786845520632,"raw":{"event_type":"price_change","market":"0xd5f15f31689703aea70b93a52194a0964220d10d92ee7497346f146a8b6ef8ab","price_changes":[{"asset_id":"2151378744569768920256500242561922410292857798164019061749528550808091180185","best_ask":"0.86","best_bid":"0.85","hash":"343eab35d4e4b21bd9fdfe7ce77e81709a6f0934","price":"0.01","side":"BUY","size":"5858.53"},{"asset_id":"17406866367975599232214757606801140480252276357934486651183783311435802862074","best_ask":"0.15","best_bid":"0.14","hash":"652b70f03626aad5bdbbe8ced43793b925edcc71","price":"0.99","side":"SELL","size":"5858.53"}],"timestamp":"1786845520413"}}
{"f":1276,"recv_ms":1786845520641,"raw":{"event_type":"price_change","market":"0xd5f15f31689703aea70b93a52194a0964220d10d92ee7497346f146a8b6ef8ab","price_changes":[{"asset_id":"17406866367975599232214757606801140480252276357934486651183783311435802862074","best_ask":"0.15","best_bid":"0.14","hash":"6ac4bddb7545d7bcf6e5f0c8eb13aa58ba9985dd","price":"0.01","side":"BUY","size":"5693.18"},{"asset_id":"2151378744569768920256500242561922410292857798164019061749528550808091180185","best_ask":"0.86","best_bid":"0.85","hash":"660b68f2bad07839f48617a4e934fc1672562bd1","price":"0.99","side":"SELL","size":"5693.18"}],"timestamp":"1786845520419"}}
{"f":1277,"recv_ms":1786845520644,"raw":{"event_type":"price_change","market":"0xd5f15f31689703aea70b93a52194a0964220d10d92ee7497346f146a8b6ef8ab","price_changes":[{"asset_id":"17406866367975599232214757606801140480252276357934486651183783311435802862074","best_ask":"0.15","best_bid":"0.14","hash":"5f07509c24e9c5653b3c0d7d3ff4a8d97fa09b16","price":"0.01","side":"BUY","size":"5688.18"},{"asset_id":"2151378744569768920256500242561922410292857798164019061749528550808091180185","best_ask":"0.86","best_bid":"0.85","hash":"5761e990a1524f6d80b9686b09f16345299105f3","price":"0.99","side":"SELL","size":"5688.18"}],"timestamp":"1786845520428"}}
{"f":1278,"recv_ms":1786845520645,"raw":{"event_type":"price_change","market":"0xd5f15f31689703aea70b93a52194a0964220d10d92ee7497346f146a8b6ef8ab","price_changes":[{"asset_id":"2151378744569768920256500242561922410292857798164019061749528550808091180185","best_ask":"0.86","best_bid":"0.85","hash":"aa0223536d0f55032b3f88d54c6e702272a7df5b","price":"0.86","side":"SELL","size":"4.99"},{"asset_id":"17406866367975599232214757606801140480252276357934486651183783311435802862074","best_ask":"0.15","best_bid":"0.14","hash":"806a5ca5db1792c075a3d505cfbb88ff32db378b","price":"0.14","side":"BUY","size":"4.99"}],"timestamp":"1786845520433"}}
{"f":1279,"recv_ms":1786845520646,"raw":{"event_type":"price_change","market":"0xd5f15f31689703aea70b93a52194a0964220d10d92ee7497346f146a8b6ef8ab","price_changes":[{"asset_id":"17406866367975599232214757606801140480252276357934486651183783311435802862074","best_ask":"0.15","best_bid":"0.14","hash":"806a5ca5db1792c075a3d505cfbb88ff32db378b","price":"0.14","side":"BUY","size":"4.99"},{"asset_id":"2151378744569768920256500242561922410292857798164019061749528550808091180185","best_ask":"0.86","best_bid":"0.85","hash":"aa0223536d0f55032b3f88d54c6e702272a7df5b","price":"0.86","side":"SELL","size":"4.99"}],"timestamp":"1786845520433"}}
{"f":1280,"recv_ms":1786845520650,"raw":{"event_type":"price_change","market":"0xd5f15f31689703aea70b93a52194a0964220d10d92ee7497346f146a8b6ef8ab","price_changes":[{"asset_id":"17406866367975599232214757606801140480252276357934486651183783311435802862074","best_ask":"0.15","best_bid":"0.14","hash":"6b476fe68666cac98082f90ac66c6e1a86370f34","price":"0.01","side":"BUY","size":"5683.18"},{"asset_id":"2151378744569768920256500242561922410292857798164019061749528550808091180185","best_ask":"0.86","best_bid":"0.85","hash":"66710e565b8bb2d965fe84df09901e20e486be9b","price":"0.99","side":"SELL","size":"5683.18"}],"timestamp":"1786845520438"}}
{"f":1281,"recv_ms":1786845520662,"raw":{"event_type":"price_change","market":"0xd5f15f31689703aea70b93a52194a0964220d10d92ee7497346f146a8b6ef8ab","price_changes":[{"asset_id":"17406866367975599232214757606801140480252276357934486651183783311435802862074","best_ask":"0.15","best_bid":"0.14","hash":"be08c13a3e9f1e82a518a1a500791346ecb04950","price":"0.01","side":"BUY","size":"5688.18"},{"asset_id":"2151378744569768920256500242561922410292857798164019061749528550808091180185","best_ask":"0.86","best_bid":"0.85","hash":"a24070ad46f3f44bb9df5652d2bd054dbc068df4","price":"0.99","side":"SELL","size":"5688.18"}],"timestamp":"1786845520439"}}
{"f":1282,"recv_ms":1786845520662,"raw":{"event_type":"price_change","market":"0xd5f15f31689703aea70b93a52194a0964220d10d92ee7497346f146a8b6ef8ab","price_changes":[{"asset_id":"2151378744569768920256500242561922410292857798164019061749528550808091180185","best_ask":"0.86","best_bid":"0.85","hash":"846cf6c17642e82dea5f52ebc65e4c2559834d4b","price":"0.01","side":"BUY","size":"5852.53"},{"asset_id":"17406866367975599232214757606801140480252276357934486651183783311435802862074","best_ask":"0.15","best_bid":"0.14","hash":"eb21ba52a07f2653aad410010b80013cb5ca2907","price":"0.99","side":"SELL","size":"5852.53"}],"timestamp":"1786845520446"}}
{"f":1283,"recv_ms":1786845520664,"raw":{"event_type":"price_change","market":"0xd5f15f31689703aea70b93a52194a0964220d10d92ee7497346f146a8b6ef8ab","price_changes":[{"asset_id":"2151378744569768920256500242561922410292857798164019061749528550808091180185","best_ask":"0.86","best_bid":"0.85","hash":"2af2176b222cb6b4f257b13c7836633e8893269d","price":"0.01","side":"BUY","size":"5857.53"},{"asset_id":"17406866367975599232214757606801140480252276357934486651183783311435802862074","best_ask":"0.15","best_bid":"0.14","hash":"19bde7864112e1ceae00c24d8ec7952c620d396a","price":"0.99","side":"SELL","size":"5857.53"}],"timestamp":"1786845520451"}}
{"f":1284,"recv_ms":1786845520664,"raw":{"event_type":"price_change","market":"0xd5f15f31689703aea70b93a52194a0964220d10d92ee7497346f146a8b6ef8ab","price_changes":[{"asset_id":"2151378744569768920256500242561922410292857798164019061749528550808091180185","best_ask":"0.86","best_bid":"0.85","hash":"bdf7dc8ca4342771ad561c239eac26edddf44ba3","price":"0.01","side":"BUY","size":"5862.53"},{"asset_id":"17406866367975599232214757606801140480252276357934486651183783311435802862074","best_ask":"0.15","best_bid":"0.14","hash":"5cc04b4c3180b69fad652f8301e844bf17aca914","price":"0.99","side":"SELL","size":"5862.53"}],"timestamp":"1786845520453"}}
{"f":1285,"recv_ms":1786845520669,"raw":{"event_type":"price_change","market":"0xd5f15f31689703aea70b93a52194a0964220d10d92ee7497346f146a8b6ef8ab","price_changes":[{"asset_id":"2151378744569768920256500242561922410292857798164019061749528550808091180185","best_ask":"0.86","best_bid":"0.85","hash":"017acb77ea0556b7aecfcdd8d228836087bd335a","price":"0.01","side":"BUY","size":"5867.53"},{"asset_id":"17406866367975599232214757606801140480252276357934486651183783311435802862074","best_ask":"0.15","best_bid":"0.14","hash":"5030a21e43805d80513d5c7b38c14f7cf944d8c8","price":"0.99","side":"SELL","size":"5867.53"}],"timestamp":"1786845520454"}}
{"f":1286,"recv_ms":1786845520697,"raw":{"event_type":"price_change","market":"0xd5f15f31689703aea70b93a52194a0964220d10d92ee7497346f146a8b6ef8ab","price_changes":[{"asset_id":"2151378744569768920256500242561922410292857798164019061749528550808091180185","best_ask":"0.86","best_bid":"0.85","hash":"ee49a1e9268267251b4079245326b6c8060b011a","price":"0.01","side":"BUY","size":"5767.53"},{"asset_id":"17406866367975599232214757606801140480252276357934486651183783311435802862074","best_ask":"0.15","best_bid":"0.14","hash":"4eb0fe5d51d2a83179532a3b3962a91bca765d23","price":"0.99","side":"SELL","size":"5767.53"}],"timestamp":"1786845520461"}}
{"f":1287,"recv_ms":1786845520698,"raw":{"asset_id":"2151378744569768920256500242561922410292857798164019061749528550808091180185","event_type":"last_trade_price","fee_rate_bps":"0","market":"0xd5f15f31689703aea70b93a52194a0964220d10d92ee7497346f146a8b6ef8ab","price":"0.86","side":"BUY","size":"2.395347","timestamp":"1786845520481","transaction_hash":"0xc51a8246a8f8a821bba9b100e4209ade4c34e9bf00a1e1ba9d7cd149d4dd7e5f"}}
{"f":1288,"recv_ms":1786845520698,"raw":{"event_type":"price_change","market":"0xd5f15f31689703aea70b93a52194a0964220d10d92ee7497346f146a8b6ef8ab","price_changes":[{"asset_id":"2151378744569768920256500242561922410292857798164019061749528550808091180185","best_ask":"0.86","best_bid":"0.85","hash":"64b814c6ca7a61867af210d04c39afe688bca8fe","price":"0.01","side":"BUY","size":"5762.53"},{"asset_id":"17406866367975599232214757606801140480252276357934486651183783311435802862074","best_ask":"0.15","best_bid":"0.14","hash":"29dd1660cee3c0c20f45f77a8500ce7e58b762c1","price":"0.99","side":"SELL","size":"5762.53"}],"timestamp":"1786845520485"}}
{"f":1289,"recv_ms":1786845520725,"raw":{"event_type":"price_change","market":"0xd5f15f31689703aea70b93a52194a0964220d10d92ee7497346f146a8b6ef8ab","price_changes":[{"asset_id":"2151378744569768920256500242561922410292857798164019061749528550808091180185","best_ask":"0.86","best_bid":"0.85","hash":"b468b55ed410a22cb3274998343152d7941d4e3f","price":"0.01","side":"BUY","size":"5862.53"},{"asset_id":"17406866367975599232214757606801140480252276357934486651183783311435802862074","best_ask":"0.15","best_bid":"0.14","hash":"e08b4c93f22c11762fbfa13dcb43ac1e17d0b9b4","price":"0.99","side":"SELL","size":"5862.53"}],"timestamp":"1786845520496"}}
{"f":1290,"recv_ms":1786845520732,"raw":{"event_type":"price_change","market":"0xd5f15f31689703aea70b93a52194a0964220d10d92ee7497346f146a8b6ef8ab","price_changes":[{"asset_id":"2151378744569768920256500242561922410292857798164019061749528550808091180185","best_ask":"0.86","best_bid":"0.85","hash":"c5de853d096b9c91d920cc30e9195ac384f29faf","price":"0.01","side":"BUY","size":"5868.53"},{"asset_id":"17406866367975599232214757606801140480252276357934486651183783311435802862074","best_ask":"0.15","best_bid":"0.14","hash":"05a8139b2316d8c3c13f0393ba6f8ac66f5914bc","price":"0.99","side":"SELL","size":"5868.53"}],"timestamp":"1786845520513"}}
{"f":1291,"recv_ms":1786845520732,"raw":{"event_type":"price_change","market":"0xd5f15f31689703aea70b93a52194a0964220d10d92ee7497346f146a8b6ef8ab","price_changes":[{"asset_id":"2151378744569768920256500242561922410292857798164019061749528550808091180185","best_ask":"0.86","best_bid":"0.85","hash":"871673333d486a235eb86ca3eefd8965e0d8464c","price":"0.86","side":"SELL","size":"9.99"},{"asset_id":"17406866367975599232214757606801140480252276357934486651183783311435802862074","best_ask":"0.15","best_bid":"0.14","hash":"ca493e51bea3c10f69e377351cc356031795ca13","price":"0.14","side":"BUY","size":"9.99"}],"timestamp":"1786845520514"}}
{"f":1292,"recv_ms":1786845520733,"raw":{"event_type":"price_change","market":"0xd5f15f31689703aea70b93a52194a0964220d10d92ee7497346f146a8b6ef8ab","price_changes":[{"asset_id":"2151378744569768920256500242561922410292857798164019061749528550808091180185","best_ask":"0.86","best_bid":"0.85","hash":"d315ee90b1aa5aee77488940494e22c175cd7260","price":"0.01","side":"BUY","size":"5863.53"},{"asset_id":"17406866367975599232214757606801140480252276357934486651183783311435802862074","best_ask":"0.15","best_bid":"0.14","hash":"e8f8a380097eee71a68690e6343967a2ed03c1d9","price":"0.99","side":"SELL","size":"5863.53"}],"timestamp":"1786845520519"}}
{"f":1293,"recv_ms":1786845520744,"raw":{"event_type":"price_change","market":"0xd5f15f31689703aea70b93a52194a0964220d10d92ee7497346f146a8b6ef8ab","price_changes":[{"asset_id":"2151378744569768920256500242561922410292857798164019061749528550808091180185","best_ask":"0.86","best_bid":"0.85","hash":"cf6c50e1748389d265b10fa3ef1bc546161cdee2","price":"0.02","side":"BUY","size":"1850.19"},{"asset_id":"17406866367975599232214757606801140480252276357934486651183783311435802862074","best_ask":"0.15","best_bid":"0.14","hash":"76738203535e407776571375578258471ff4fff0","price":"0.98","side":"SELL","size":"1850.19"}],"timestamp":"1786845520521"}}
{"f":1294,"recv_ms":1786845520744,"raw":{"event_type":"price_change","market":"0xd5f15f31689703aea70b93a52194a0964220d10d92ee7497346f146a8b6ef8ab","price_changes":[{"asset_id":"2151378744569768920256500242561922410292857798164019061749528550808091180185","best_ask":"0.86","best_bid":"0.85","hash":"3e54044fd7837a9de40c945a4dfd89764a6755f2","price":"0.01","side":"BUY","size":"5868.53"},{"asset_id":"17406866367975599232214757606801140480252276357934486651183783311435802862074","best_ask":"0.15","best_bid":"0.14","hash":"a51ded1ecdfcefbd2fa3e9af254e5a355772a28b","price":"0.99","side":"SELL","size":"5868.53"}],"timestamp":"1786845520526"}}
{"f":1295,"recv_ms":1786845520745,"raw":{"event_type":"price_change","market":"0xd5f15f31689703aea70b93a52194a0964220d10d92ee7497346f146a8b6ef8ab","price_changes":[{"asset_id":"2151378744569768920256500242561922410292857798164019061749528550808091180185","best_ask":"0.86","best_bid":"0.85","hash":"03a2c6c31666a0ccced718cc08a50fd55325af80","price":"0.01","side":"BUY","size":"5768.53"},{"asset_id":"17406866367975599232214757606801140480252276357934486651183783311435802862074","best_ask":"0.15","best_bid":"0.14","hash":"24a5282489009a8742d1ec11d8fa314832277540","price":"0.99","side":"SELL","size":"5768.53"}],"timestamp":"1786845520527"}}
{"f":1296,"recv_ms":1786845520745,"raw":{"event_type":"price_change","market":"0xd5f15f31689703aea70b93a52194a0964220d10d92ee7497346f146a8b6ef8ab","price_changes":[{"asset_id":"17406866367975599232214757606801140480252276357934486651183783311435802862074","best_ask":"0.15","best_bid":"0.14","hash":"a2fed247e3297406e46566433738739f6aa5a1ef","price":"0.11","side":"BUY","size":"40"},{"asset_id":"2151378744569768920256500242561922410292857798164019061749528550808091180185","best_ask":"0.86","best_bid":"0.85","hash":"1f2ed840a48ec0c478b42de012fa73a30a081de8","price":"0.89","side":"SELL","size":"40"}],"timestamp":"1786845520533"}}
{"f":1297,"recv_ms":1786845520749,"raw":{"event_type":"price_change","market":"0xd5f15f31689703aea70b93a52194a0964220d10d92ee7497346f146a8b6ef8ab","price_changes":[{"asset_id":"17406866367975599232214757606801140480252276357934486651183783311435802862074","best_ask":"0.15","best_bid":"0.14","hash":"a6274a4d060268f5f38fbe543fc82129dab47b49","price":"0.13","side":"BUY","size":"118"},{"asset_id":"2151378744569768920256500242561922410292857798164019061749528550808091180185","best_ask":"0.86","best_bid":"0.85","hash":"ee7bffe51fcc136631d4f70ed8c4963fae8d6960","price":"0.87","side":"SELL","size":"118"}],"timestamp":"1786845520534"}}
{"f":1298,"recv_ms":1786845520749,"raw":{"event_type":"price_change","market":"0xd5f15f31689703aea70b93a52194a0964220d10d92ee7497346f146a8b6ef8ab","price_changes":[{"asset_id":"17406866367975599232214757606801140480252276357934486651183783311435802862074","best_ask":"0.15","best_bid":"0.14","hash":"3bc0b9371bbbe4e6ee575ed7bb1cb2d1c6a88597","price":"0.11","side":"BUY","size":"10"},{"asset_id":"2151378744569768920256500242561922410292857798164019061749528550808091180185","best_ask":"0.86","best_bid":"0.85","hash":"8fdb58d686f04b023935b94eeb0364509a883a5e","price":"0.89","side":"SELL","size":"10"}],"timestamp":"1786845520535"}}
{"f":1299,"recv_ms":1786845520753,"raw":{"event_type":"price_change","market":"0xd5f15f31689703aea70b93a52194a0964220d10d92ee7497346f146a8b6ef8ab","price_changes":[{"asset_id":"17406866367975599232214757606801140480252276357934486651183783311435802862074","best_ask":"0.15","best_bid":"0.14","hash":"b928148af42d7a88f874f01e8b464ce1416a03e1","price":"0.12","side":"BUY","size":"35"},{"asset_id":"2151378744569768920256500242561922410292857798164019061749528550808091180185","best_ask":"0.86","best_bid":"0.85","hash":"175d127bf56d0b437b78189647a6b49f45741086","price":"0.88","side":"SELL","size":"35"}],"timestamp":"1786845520535"}}
{"f":1300,"recv_ms":1786845520753,"raw":{"event_type":"price_change","market":"0xd5f15f31689703aea70b93a52194a0964220d10d92ee7497346f146a8b6ef8ab","price_changes":[{"asset_id":"17406866367975599232214757606801140480252276357934486651183783311435802862074","best_ask":"0.15","best_bid":"0.14","hash":"8349d648c9c3fe1c3aaee7e432a9a894daa3c348","price":"0.14","side":"BUY","size":"39.99"},{"asset_id":"2151378744569768920256500242561922410292857798164019061749528550808091180185","best_ask":"0.86","best_bid":"0.85","hash":"2fd02b09650c4a4b70dfe5da12ac4b5bfe8d432e","price":"0.86","side":"SELL","size":"39.99"}],"timestamp":"1786845520536"}}
{"f":1301,"recv_ms":1786845520757,"raw":{"event_type":"price_change","market":"0xd5f15f31689703aea70b93a52194a0964220d10d92ee7497346f146a8b6ef8ab","price_changes":[{"asset_id":"2151378744569768920256500242561922410292857798164019061749528550808091180185","best_ask":"0.86","best_bid":"0.85","hash":"628c2b219bb7f71f4611e002a037cc80694b0109","price":"0.01","side":"BUY","size":"5762.53"},{"asset_id":"17406866367975599232214757606801140480252276357934486651183783311435802862074","best_ask":"0.15","best_bid":"0.14","hash":"e0691c34d10d08a8ac7e849dbaf09260d9f59644","price":"0.99","side":"SELL","size":"5762.53"}],"timestamp":"1786845520541"}}
{"f":1302,"recv_ms":1786845520757,"raw":{"event_type":"price_change","market":"0xd5f15f31689703aea70b93a52194a0964220d10d92ee7497346f146a8b6ef8ab","price_changes":[{"asset_id":"17406866367975599232214757606801140480252276357934486651183783311435802862074","best_ask":"0.15","best_bid":"0.14","hash":"d03e25a952742d83695c36105ef85a8644a8afec","price":"0.33","side":"SELL","size":"47"},{"asset_id":"2151378744569768920256500242561922410292857798164019061749528550808091180185","best_ask":"0.86","best_bid":"0.85","hash":"8d62b8ffcd2195d4dd6c1716aa1ebf37a43ba5fd","price":"0.67","side":"BUY","size":"47"}],"timestamp":"1786845520544"}}
{"f":1303,"recv_ms":1786845520761,"raw":{"event_type":"price_change","market":"0xd5f15f31689703aea70b93a52194a0964220d10d92ee7497346f146a8b6ef8ab","price_changes":[{"asset_id":"2151378744569768920256500242561922410292857798164019061749528550808091180185","best_ask":"0.86","best_bid":"0.85","hash":"1d80f74b37e6c11121d3974a0898709607389f3c","price":"0.21","side":"BUY","size":"25.7"},{"asset_id":"17406866367975599232214757606801140480252276357934486651183783311435802862074","best_ask":"0.15","best_bid":"0.14","hash":"ee56efe9d9d54461b8da5142489ef9354d616412","price":"0.79","side":"SELL","size":"25.7"}],"timestamp":"1786845520545"}}
{"f":1304,"recv_ms":1786845520761,"raw":{"event_type":"price_change","market":"0xd5f15f31689703aea70b93a52194a0964220d10d92ee7497346f146a8b6ef8ab","price_changes":[{"asset_id":"17406866367975599232214757606801140480252276357934486651183783311435802862074","best_ask":"0.15","best_bid":"0.14","hash":"eb73086a012f2254a1684ce600fcb9467185c830","price":"0.32","side":"SELL","size":"85"},{"asset_id":"2151378744569768920256500242561922410292857798164019061749528550808091180185","best_ask":"0.86","best_bid":"0.85","hash":"25a92f87a3232145504610eb03c6eaf9b1bb91fc","price":"0.68","side":"BUY","size":"85"}],"timestamp":"1786845520546"}}
{"f":1305,"recv_ms":1786845520761,"raw":{"event_type":"price_change","market":"0xd5f15f31689703aea70b93a52194a0964220d10d92ee7497346f146a8b6ef8ab","price_changes":[{"asset_id":"2151378744569768920256500242561922410292857798164019061749528550808091180185","best_ask":"0.86","best_bid":"0.85","hash":"750856787e655fd43db0caa9cb1587fb6c16b795","price":"0.01","side":"BUY","size":"5757.53"},{"asset_id":"17406866367975599232214757606801140480252276357934486651183783311435802862074","best_ask":"0.15","best_bid":"0.14","hash":"7bb31809e91afaf1e25f846634c52693ca7493b4","price":"0.99","side":"SELL","size":"5757.53"}],"timestamp":"1786845520550"}}
{"f":1306,"recv_ms":1786845520775,"raw":{"event_type":"price_change","market":"0xd5f15f31689703aea70b93a52194a0964220d10d92ee7497346f146a8b6ef8ab","price_changes":[{"asset_id":"2151378744569768920256500242561922410292857798164019061749528550808091180185","best_ask":"0.86","best_bid":"0.85","hash":"0f60ed63f93d9a872e1c65658a6bbfde23586cb5","price":"0.01","side":"BUY","size":"5752.53"},{"asset_id":"17406866367975599232214757606801140480252276357934486651183783311435802862074","best_ask":"0.15","best_bid":"0.14","hash":"8682116efd7c50068bd6aa8fbaabb644ec431d0b","price":"0.99","side":"SELL","size":"5752.53"}],"timestamp":"1786845520551"}}
{"f":1307,"recv_ms":1786845520775,"raw":{"event_type":"price_change","market":"0xd5f15f31689703aea70b93a52194a0964220d10d92ee7497346f146a8b6ef8ab","price_changes":[{"asset_id":"2151378744569768920256500242561922410292857798164019061749528550808091180185","best_ask":"0.86","best_bid":"0.85","hash":"5ac5a30f7c6dc96d38f95ce524cdc63c5ea1e13b","price":"0.01","side":"BUY","size":"5757.54"},{"asset_id":"17406866367975599232214757606801140480252276357934486651183783311435802862074","best_ask":"0.15","best_bid":"0.14","hash":"41bda135f56f7e15b66035e30d6ead166c94fe46","price":"0.99","side":"SELL","size":"5757.54"}],"timestamp":"1786845520554"}}
{"f":1308,"recv_ms":1786845520777,"raw":{"event_type":"price_change","market":"0xd5f15f31689703aea70b93a52194a0964220d10d92ee7497346f146a8b6ef8ab","price_changes":[{"asset_id":"2151378744569768920256500242561922410292857798164019061749528550808091180185","best_ask":"0.86","best_bid":"0.85","hash":"01ba8fd0cc53c3ba9ac795a9c90cbee50b044c54","price":"0.18","side":"BUY","size":"27.6"},{"asset_id":"17406866367975599232214757606801140480252276357934486651183783311435802862074","best_ask":"0.15","best_bid":"0.14","hash":"61e46a3c8a27d1e4c934cb95dbd63457f1674557","price":"0.82","side":"SELL","size":"27.6"}],"timestamp":"1786845520564"}}
{"f":1309,"recv_ms":1786845520777,"raw":{"event_type":"price_change","market":"0xd5f15f31689703aea70b93a52194a0964220d10d92ee7497346f146a8b6ef8ab","price_changes":[{"asset_id":"2151378744569768920256500242561922410292857798164019061749528550808091180185","best_ask":"0.86","best_bid":"0.85","hash":"c73c89de052fa025c4d0e0d65fce025f3934b3f7","price":"0.16","side":"BUY","size":"114.3"},{"asset_id":"17406866367975599232214757606801140480252276357934486651183783311435802862074","best_ask":"0.15","best_bid":"0.14","hash":"0e9613509fa9bb9937e3c9aa42d00d7e91539a9e","price":"0.84","side":"SELL","size":"114.3"}],"timestamp":"1786845520565"}}
{"f":1310,"recv_ms":1786845520781,"raw":{"event_type":"price_change","market":"0xd5f15f31689703aea70b93a52194a0964220d10d92ee7497346f146a8b6ef8ab","price_changes":[{"asset_id":"2151378744569768920256500242561922410292857798164019061749528550808091180185","best_ask":"0.86","best_bid":"0.85","hash":"151a9b1030293bc8f5e54c230b64673ae40d6151","price":"0.01","side":"BUY","size":"5762.54"},{"asset_id":"17406866367975599232214757606801140480252276357934486651183783311435802862074","best_ask":"0.15","best_bid":"0.14","hash":"c2babb872ce4b2ce89b15c3caee547ac2c6a3026","price":"0.99","side":"SELL","size":"5762.54"}],"timestamp":"1786845520566"}}
{"f":1311,"recv_ms":1786845520781,"raw":{"event_type":"price_change","market":"0xd5f15f31689703aea70b93a52194a0964220d10d92ee7497346f146a8b6ef8ab","price_changes":[{"asset_id":"2151378744569768920256500242561922410292857798164019061749528550808091180185","best_ask":"0.86","best_bid":"0.85","hash":"f7586bd58cb91e12d92f5efce11fcbcc5bb0e40c","price":"0.12","side":"BUY","size":"124.6"},{"asset_id":"17406866367975599232214757606801140480252276357934486651183783311435802862074","best_ask":"0.15","best_bid":"0.14","hash":"5de91322013d3a6bc0930b270015f49baa27cc04","price":"0.88","side":"SELL","size":"124.6"}],"timestamp":"1786845520567"}}
{"f":1312,"recv_ms":1786845520782,"raw":{"event_type":"price_change","market":"0xd5f15f31689703aea70b93a52194a0964220d10d92ee7497346f146a8b6ef8ab","price_changes":[{"asset_id":"17406866367975599232214757606801140480252276357934486651183783311435802862074","best_ask":"0.15","best_bid":"0.14","hash":"a8fd4c196735ea762625dfaf1b34ebd97558ef8b","price":"0.01","side":"BUY","size":"5693.18"},{"asset_id":"2151378744569768920256500242561922410292857798164019061749528550808091180185","best_ask":"0.86","best_bid":"0.85","hash":"5616b2fc52efe14cba222bf95f8ec84a93d9f979","price":"0.99","side":"SELL","size":"5693.18"}],"timestamp":"1786845520568"}}
{"f":1313,"recv_ms":1786845520782,"raw":{"event_type":"price_change","market":"0xd5f15f31689703aea70b93a52194a0964220d10d92ee7497346f146a8b6ef8ab","price_changes":[{"asset_id":"2151378744569768920256500242561922410292857798164019061749528550808091180185","best_ask":"0.86","best_bid":"0.85","hash":"094722dd548100e1d6f62992d033c2fbd2bb4d86","price":"0.14","side":"BUY","size":"116.6"},{"asset_id":"17406866367975599232214757606801140480252276357934486651183783311435802862074","best_ask":"0.15","best_bid":"0.14","hash":"a2a9fac088fce66f4ef7232fc7d088b0279987ea","price":"0.86","side":"SELL","size":"116.6"}],"timestamp":"1786845520569"}}
{"f":1314,"recv_ms":1786845520785,"raw":{"event_type":"price_change","market":"0xd5f15f31689703aea70b93a52194a0964220d10d92ee7497346f146a8b6ef8ab","price_changes":[{"asset_id":"2151378744569768920256500242561922410292857798164019061749528550808091180185","best_ask":"0.86","best_bid":"0.85","hash":"53aa2d119fa841f5478b60244954c7407ed18e72","price":"0.2","side":"BUY","size":"59.1"},{"asset_id":"17406866367975599232214757606801140480252276357934486651183783311435802862074","best_ask":"0.15","best_bid":"0.14","hash":"0ca89f977cb5bac81d9b69c310676649d2b6a1aa","price":"0.8","side":"SELL","size":"59.1"}],"timestamp":"1786845520570"}}
{"f":1315,"recv_ms":1786845520785,"raw":{"event_type":"price_change","market":"0xd5f15f31689703aea70b93a52194a0964220d10d92ee7497346f146a8b6ef8ab","price_changes":[{"asset_id":"17406866367975599232214757606801140480252276357934486651183783311435802862074","best_ask":"0.15","best_bid":"0.14","hash":"ea4e1dc1a7e377656fcf89a2c035c6585cc24fe6","price":"0.16","side":"SELL","size":"66.72"},{"asset_id":"2151378744569768920256500242561922410292857798164019061749528550808091180185","best_ask":"0.86","best_bid":"0.85","hash":"b4ae166df32b516d8c20a1299821208c48c6f341","price":"0.84","side":"BUY","size":"66.72"}],"timestamp":"1786845520571"}}
{"f":1316,"recv_ms":1786845520793,"raw":{"event_type":"price_change","market":"0xd5f15f31689703aea70b93a52194a0964220d10d92ee7497346f146a8b6ef8ab","price_changes":[{"asset_id":"17406866367975599232214757606801140480252276357934486651183783311435802862074","best_ask":"0.15","best_bid":"0.14","hash":"8b7ced7bcb4a6fb509536d5c0ca49b340dba3971","price":"0.11","side":"BUY","size":"40"},{"asset_id":"2151378744569768920256500242561922410292857798164019061749528550808091180185","best_ask":"0.86","best_bid":"0.85","hash":"c660ce869acaacb94c9f47aab1dce107f8cb5f88","price":"0.89","side":"SELL","size":"40"}],"timestamp":"1786845520573"}}
{"f":1317,"recv_ms":1786845520794,"raw":{"event_type":"price_change","market":"0xd5f15f31689703aea70b93a52194a0964220d10d92ee7497346f146a8b6ef8ab","price_changes":[{"asset_id":"2151378744569768920256500242561922410292857798164019061749528550808091180185","best_ask":"0.86","best_bid":"0.85","hash":"f772adc680ace6e052079c3b1920e77ed8b12b47","price":"0.01","side":"BUY","size":"5862.54"},{"asset_id":"17406866367975599232214757606801140480252276357934486651183783311435802862074","best_ask":"0.15","best_bid":"0.14","hash":"0a6f673ef9b6c67ea982d00df2854885b3bc9550","price":"0.99","side":"SELL","size":"5862.54"}],"timestamp":"1786845520574"}}
{"f":1318,"recv_ms":1786845520803,"raw":{"event_type":"price_change","market":"0xd5f15f31689703aea70b93a52194a0964220d10d92ee7497346f146a8b6ef8ab","price_changes":[{"asset_id":"17406866367975599232214757606801140480252276357934486651183783311435802862074","best_ask":"0.15","best_bid":"0.14","hash":"3cc05de28ce62c105365053c376f5806d476b4cb","price":"0.13","side":"BUY","size":"40"},{"asset_id":"2151378744569768920256500242561922410292857798164019061749528550808091180185","best_ask":"0.86","best_bid":"0.85","hash":"309824383e3a4f26f0c9fbab47f37702c1f34f4f","price":"0.87","side":"SELL","size":"40"}],"timestamp":"1786845520578"}}
{"f":1319,"recv_ms":1786845520803,"raw":{"event_type":"price_change","market":"0xd5f15f31689703aea70b93a52194a0964220d10d92ee7497346f146a8b6ef8ab","price_changes":[{"asset_id":"2151378744569768920256500242561922410292857798164019061749528550808091180185","best_ask":"0.86","best_bid":"0.85","hash":"a70814d51194aa10cf7c99499543a76cac019211","price":"0.01","side":"BUY","size":"5857.53"},{"asset_id":"17406866367975599232214757606801140480252276357934486651183783311435802862074","best_ask":"0.15","best_bid":"0.14","hash":"445bde9202bb5dd8a5ab5f7d5949de8725af0491","price":"0.99","side":"SELL","size":"5857.53"}],"timestamp":"1786845520582"}}
{"f":1320,"recv_ms":1786845520803,"raw":{"event_type":"price_change","market":"0xd5f15f31689703aea70b93a52194a0964220d10d92ee7497346f146a8b6ef8ab","price_changes":[{"asset_id":"2151378744569768920256500242561922410292857798164019061749528550808091180185","best_ask":"0.86","best_bid":"0.85","hash":"6a0bd1bd753647e47ca3b455f7e6ebeeda8344fb","price":"0.79","side":"BUY","size":"171"},{"asset_id":"17406866367975599232214757606801140480252276357934486651183783311435802862074","best_ask":"0.15","best_bid":"0.14","hash":"95c7e19e6d8d7691a19ab529b56f010143abaeea","price":"0.21","side":"SELL","size":"171"}],"timestamp":"1786845520588"}}
{"f":1321,"recv_ms":1786845520804,"raw":{"event_type":"price_change","market":"0xd5f15f31689703aea70b93a52194a0964220d10d92ee7497346f146a8b6ef8ab","price_changes":[{"asset_id":"17406866367975599232214757606801140480252276357934486651183783311435802862074","best_ask":"0.15","best_bid":"0.14","hash":"1e7d5e147b31da0afcd5c441b9823d37db5a40c0","price":"0.04","side":"BUY","size":"467.7"},{"asset_id":"2151378744569768920256500242561922410292857798164019061749528550808091180185","best_ask":"0.86","best_bid":"0.85","hash":"6066d0e2209b046f147c1dbb0d22e419df1098c9","price":"0.96","side":"SELL","size":"467.7"}],"timestamp":"1786845520590"}}
{"f":1322,"recv_ms":1786845520804,"raw":{"event_type":"price_change","market":"0xd5f15f31689703aea70b93a52194a0964220d10d92ee7497346f146a8b6ef8ab","price_changes":[{"asset_id":"17406866367975599232214757606801140480252276357934486651183783311435802862074","best_ask":"0.15","best_bid":"0.14","hash":"2358baac98602fba2794ef1598becf5dd67557d4","price":"0.01","side":"BUY","size":"5688.18"},{"asset_id":"2151378744569768920256500242561922410292857798164019061749528550808091180185","best_ask":"0.86","best_bid":"0.85","hash":"a460cfc62a0ad1a8fc0bc563ee94f810c3fb03a0","price":"0.99","side":"SELL","size":"5688.18"}],"timestamp":"1786845520591"}}
{"f":1323,"recv_ms":1786845520807,"raw":{"event_type":"price_change","market":"0xd5f15f31689703aea70b93a52194a0964220d10d92ee7497346f146a8b6ef8ab","price_changes":[{"asset_id":"2151378744569768920256500242561922410292857798164019061749528550808091180185","best_ask":"0.86","best_bid":"0.85","hash":"8816346590576b4b9ee14418cc4b697bae68e1c1","price":"0.73","side":"BUY","size":"22"},{"asset_id":"17406866367975599232214757606801140480252276357934486651183783311435802862074","best_ask":"0.15","best_bid":"0.14","hash":"3f8bc70e10d28781d72c512240a4e2473cdf4b2e","price":"0.27","side":"SELL","size":"22"}],"timestamp":"1786845520592"}}
{"f":1324,"recv_ms":1786845520807,"raw":{"event_type":"price_change","market":"0xd5f15f31689703aea70b93a52194a0964220d10d92ee7497346f146a8b6ef8ab","price_changes":[{"asset_id":"2151378744569768920256500242561922410292857798164019061749528550808091180185","best_ask":"0.86","best_bid":"0.85","hash":"81bcb008fb178bc41f9340fa37af26dfa8589b74","price":"0.01","side":"BUY","size":"5852.53"},{"asset_id":"17406866367975599232214757606801140480252276357934486651183783311435802862074","best_ask":"0.15","best_bid":"0.14","hash":"9b81a3a5a5fb67e2b322446804256a89d5a82170","price":"0.99","side":"SELL","size":"5852.53"}],"timestamp":"1786845520593"}}
{"f":1325,"recv_ms":1786845520808,"raw":{"event_type":"price_change","market":"0xd5f15f31689703aea70b93a52194a0964220d10d92ee7497346f146a8b6ef8ab","price_changes":[{"asset_id":"2151378744569768920256500242561922410292857798164019061749528550808091180185","best_ask":"0.86","best_bid":"0.85","hash":"e6cdaa65f68b10f8a9d444c9e69cedfc6c8ad89c","price":"0.55","side":"BUY","size":"239"},{"asset_id":"17406866367975599232214757606801140480252276357934486651183783311435802862074","best_ask":"0.15","best_bid":"0.14","hash":"46f87a56d7318eaff0e19297f393f6945726ce11","price":"0.45","side":"SELL","size":"239"}],"timestamp":"1786845520595"}}
{"f":1326,"recv_ms":1786845520808,"raw":{"event_type":"price_change","market":"0xd5f15f31689703aea70b93a52194a0964220d10d92ee7497346f146a8b6ef8ab","price_changes":[{"asset_id":"2151378744569768920256500242561922410292857798164019061749528550808091180185","best_ask":"0.86","best_bid":"0.85","hash":"1f861779bec4e92796349e0008e8fbae3128ef07","price":"0.72","side":"BUY","size":"30"},{"asset_id":"17406866367975599232214757606801140480252276357934486651183783311435802862074","best_ask":"0.15","best_bid":"0.14","hash":"07db898732242f4ff1ffe335489d4608d80db4b5","price":"0.28","side":"SELL","size":"30"}],"timestamp":"1786845520596"}}
{"f":1327,"recv_ms":1786845520824,"raw":{"event_type":"price_change","market":"0xd5f15f31689703aea70b93a52194a0964220d10d92ee7497346f146a8b6ef8ab","price_changes":[{"asset_id":"2151378744569768920256500242561922410292857798164019061749528550808091180185","best_ask":"0.86","best_bid":"0.85","hash":"5e542a7f9155dcab1dc9c82220480e3e0c4bf292","price":"0.38","side":"BUY","size":"124"},{"asset_id":"17406866367975599232214757606801140480252276357934486651183783311435802862074","best_ask":"0.15","best_bid":"0.14","hash":"6d9b4f784b7e954e2f94d056a5ec4ba2cd93df34","price":"0.62","side":"SELL","size":"124"}],"timestamp":"1786845520597"}}
{"f":1328,"recv_ms":1786845520824,"raw":{"event_type":"price_change","market":"0xd5f15f31689703aea70b93a52194a0964220d10d92ee7497346f146a8b6ef8ab","price_changes":[{"asset_id":"2151378744569768920256500242561922410292857798164019061749528550808091180185","best_ask":"0.86","best_bid":"0.85","hash":"bb45ea05aa539dadbb5af7119b6b513a710f2434","price":"0.75","side":"BUY","size":"152.9"},{"asset_id":"17406866367975599232214757606801140480252276357934486651183783311435802862074","best_ask":"0.15","best_bid":"0.14","hash":"3b02f61e4a403d64d84de53e24404f2db2df7753","price":"0.25","side":"SELL","size":"152.9"}],"timestamp":"1786845520598"}}
{"f":1329,"recv_ms":1786845520825,"raw":{"event_type":"price_change","market":"0xd5f15f31689703aea70b93a52194a0964220d10d92ee7497346f146a8b6ef8ab","price_changes":[{"asset_id":"2151378744569768920256500242561922410292857798164019061749528550808091180185","best_ask":"0.86","best_bid":"0.85","hash":"c01aba4164a0e33ae37b22ffecdbed9863706be4","price":"0.01","side":"BUY","size":"5847.53"},{"asset_id":"17406866367975599232214757606801140480252276357934486651183783311435802862074","best_ask":"0.15","best_bid":"0.14","hash":"d5cba2927aba7ac3a80d685360f8d37f1afc15be","price":"0.99","side":"SELL","size":"5847.53"}],"timestamp":"1786845520612"}}
{"f":1330,"recv_ms":1786845520828,"raw":{"event_type":"price_change","market":"0xd5f15f31689703aea70b93a52194a0964220d10d92ee7497346f146a8b6ef8ab","price_changes":[{"asset_id":"2151378744569768920256500242561922410292857798164019061749528550808091180185","best_ask":"0.86","best_bid":"0.85","hash":"00398864edbfdc1790108430facd867fb679d1ae","price":"0.01","side":"BUY","size":"5747.53"},{"asset_id":"17406866367975599232214757606801140480252276357934486651183783311435802862074","best_ask":"0.15","best_bid":"0.14","hash":"c246f926dd7ade25bd4d4721f980093eb7a54d7f","price":"0.99","side":"SELL","size":"5747.53"}],"timestamp":"1786845520614"}}
{"f":1331,"recv_ms":1786845520828,"raw":{"event_type":"price_change","market":"0xd5f15f31689703aea70b93a52194a0964220d10d92ee7497346f146a8b6ef8ab","price_changes":[{"asset_id":"2151378744569768920256500242561922410292857798164019061749528550808091180185","best_ask":"0.86","best_bid":"0.85","hash":"4ea3646fea7ada27faeca98f4831e21828605e43","price":"0.01","side":"BUY","size":"5753.53"},{"asset_id":"17406866367975599232214757606801140480252276357934486651183783311435802862074","best_ask":"0.15","best_bid":"0.14","hash":"a976fda39240ca4dff4b197c77641759532d5c97","price":"0.99","side":"SELL","size":"5753.53"}],"timestamp":"1786845520615"}}
{"f":1332,"recv_ms":1786845520831,"raw":{"event_type":"price_change","market":"0xd5f15f31689703aea70b93a52194a0964220d10d92ee7497346f146a8b6ef8ab","price_changes":[{"asset_id":"17406866367975599232214757606801140480252276357934486651183783311435802862074","best_ask":"0.15","best_bid":"0.14","hash":"f312c56cd31b87b8676292d8e7dffba3aa29b433","price":"0.11","side":"BUY","size":"10"},{"asset_id":"2151378744569768920256500242561922410292857798164019061749528550808091180185","best_ask":"0.86","best_bid":"0.85","hash":"358f8a8c32202856399e699917b63a561f4023b1","price":"0.89","side":"SELL","size":"10"}],"timestamp":"1786845520618"}}
{"f":1333,"recv_ms":1786845520831,"raw":{"event_type":"price_change","market":"0xd5f15f31689703aea70b93a52194a0964220d10d92ee7497346f146a8b6ef8ab","price_changes":[{"asset_id":"2151378744569768920256500242561922410292857798164019061749528550808091180185","best_ask":"0.86","best_bid":"0.85","hash":"0c85a48074f8887430ac00afed0492a0d2677d57","price":"0.01","side":"BUY","size":"5748.53"},{"asset_id":"17406866367975599232214757606801140480252276357934486651183783311435802862074","best_ask":"0.15","best_bid":"0.14","hash":"a3458a9af6f4d2b5c8c115ab143ce417bf33f14e","price":"0.99","side":"SELL","size":"5748.53"}],"timestamp":"1786845520618"}}
{"f":1334,"recv_ms":1786845520852,"raw":{"event_type":"price_change","market":"0xd5f15f31689703aea70b93a52194a0964220d10d92ee7497346f146a8b6ef8ab","price_changes":[{"asset_id":"2151378744569768920256500242561922410292857798164019061749528550808091180185","best_ask":"0.86","best_bid":"0.85","hash":"2a774bad822cd257312e8b211add449953d58f7a","price":"0.01","side":"BUY","size":"5753.53"},{"asset_id":"17406866367975599232214757606801140480252276357934486651183783311435802862074","best_ask":"0.15","best_bid":"0.14","hash":"711f49958cd542c5300ce969e0c02ed18104de78","price":"0.99","side":"SELL","size":"5753.53"}],"timestamp":"1786845520621"}}
{"f":1335,"recv_ms":1786845520852,"raw":{"event_type":"price_change","market":"0xd5f15f31689703aea70b93a52194a0964220d10d92ee7497346f146a8b6ef8ab","price_changes":[{"asset_id":"2151378744569768920256500242561922410292857798164019061749528550808091180185","best_ask":"0.86","best_bid":"0.85","hash":"11c5f25d49eb10255b84e78b76df5ec9e7420156","price":"0.01","side":"BUY","size":"5758.53"},{"asset_id":"17406866367975599232214757606801140480252276357934486651183783311435802862074","best_ask":"0.15","best_bid":"0.14","hash":"bcfa3f42508a7c02ed7ec4fd5097a23f2b6709d5","price":"0.99","side":"SELL","size":"5758.53"}],"timestamp":"1786845520622"}}
{"f":1336,"recv_ms":1786845520859,"raw":{"event_type":"price_change","market":"0xd5f15f31689703aea70b93a52194a0964220d10d92ee7497346f146a8b6ef8ab","price_changes":[{"asset_id":"2151378744569768920256500242561922410292857798164019061749528550808091180185","best_ask":"0.86","best_bid":"0.85","hash":"be5e6b83fe94199a3db0826a55b3a01df511af2e","price":"0.01","side":"BUY","size":"5752.53"},{"asset_id":"17406866367975599232214757606801140480252276357934486651183783311435802862074","best_ask":"0.15","best_bid":"0.14","hash":"d39f8afa0010d6b1ea3a6c6c4970f0d8227e0250","price":"0.99","side":"SELL","size":"5752.53"}],"timestamp":"1786845520645"}}
{"f":1337,"recv_ms":1786845520868,"raw":{"event_type":"price_change","market":"0xd5f15f31689703aea70b93a52194a0964220d10d92ee7497346f146a8b6ef8ab","price_changes":[{"asset_id":"2151378744569768920256500242561922410292857798164019061749528550808091180185","best_ask":"0.86","best_bid":"0.85","hash":"940787695e860efd6c642f857799f66f4dba8236","price":"0.02","side":"BUY","size":"1925.19"},{"asset_id":"17406866367975599232214757606801140480252276357934486651183783311435802862074","best_ask":"0.15","best_bid":"0.14","hash":"86b780b918a43a5af240b1e2d1e5d05314af9b70","price":"0.98","side":"SELL","size":"1925.19"}],"timestamp":"1786845520648"}}
{"f":1338,"recv_ms":1786845520868,"raw":{"event_type":"price_change","market":"0xd5f15f31689703aea70b93a52194a0964220d10d92ee7497346f146a8b6ef8ab","price_changes":[{"asset_id":"2151378744569768920256500242561922410292857798164019061749528550808091180185","best_ask":"0.86","best_bid":"0.85","hash":"41d4b9d5bdd9f29c6adb699381fec625a3fe0131","price":"0.01","side":"BUY","size":"5852.53"},{"asset_id":"17406866367975599232214757606801140480252276357934486651183783311435802862074","best_ask":"0.15","best_bid":"0.14","hash":"78d8b51bf177e9f93e92118a859af49fb01f3198","price":"0.99","side":"SELL","size":"5852.53"}],"timestamp":"1786845520654"}}
{"f":1339,"recv_ms":1786845520869,"raw":{"event_type":"price_change","market":"0xd5f15f31689703aea70b93a52194a0964220d10d92ee7497346f146a8b6ef8ab","price_changes":[{"asset_id":"2151378744569768920256500242561922410292857798164019061749528550808091180185","best_ask":"0.86","best_bid":"0.85","hash":"2e0ad0b6c2bc40efbcf231b7c9c5dfeba505149e","price":"0.01","side":"BUY","size":"5857.53"},{"asset_id":"17406866367975599232214757606801140480252276357934486651183783311435802862074","best_ask":"0.15","best_bid":"0.14","hash":"20c6157a9e2b9987cd8fef3a30e78ed10d940ed0","price":"0.99","side":"SELL","size":"5857.53"}],"timestamp":"1786845520656"}}
{"f":1340,"recv_ms":1786845520869,"raw":{"event_type":"price_change","market":"0xd5f15f31689703aea70b93a52194a0964220d10d92ee7497346f146a8b6ef8ab","price_changes":[{"asset_id":"2151378744569768920256500242561922410292857798164019061749528550808091180185","best_ask":"0.86","best_bid":"0.85","hash":"c4b490367e1bf3dafce3b0cb49ad9bc31797b08b","price":"0.01","side":"BUY","size":"5862.53"},{"asset_id":"17406866367975599232214757606801140480252276357934486651183783311435802862074","best_ask":"0.15","best_bid":"0.14","hash":"93a69bb5fe7db24ec40940f6f2df8268f4d97435","price":"0.99","side":"SELL","size":"5862.53"}],"timestamp":"1786845520657"}}
{"f":1341,"recv_ms":1786845520882,"raw":{"event_type":"price_change","market":"0xd5f15f31689703aea70b93a52194a0964220d10d92ee7497346f146a8b6ef8ab","price_changes":[{"asset_id":"2151378744569768920256500242561922410292857798164019061749528550808091180185","best_ask":"0.86","best_bid":"0.85","hash":"727a6e76bfbb2ccfe13b74745c73e1817cc8a632","price":"0.01","side":"BUY","size":"5867.53"},{"asset_id":"17406866367975599232214757606801140480252276357934486651183783311435802862074","best_ask":"0.15","best_bid":"0.14","hash":"e7a8a85ea25ed8ec9b0b1bafffa727f0ef022418","price":"0.99","side":"SELL","size":"5867.53"}],"timestamp":"1786845520658"}}
{"f":1342,"recv_ms":1786845520914,"raw":{"event_type":"price_change","market":"0xd5f15f31689703aea70b93a52194a0964220d10d92ee7497346f146a8b6ef8ab","price_changes":[{"asset_id":"2151378744569768920256500242561922410292857798164019061749528550808091180185","best_ask":"0.86","best_bid":"0.85","hash":"9bedb9ab7008c1e6a2d9f32ad52972b386a70be1","price":"0.01","side":"BUY","size":"5767.53"},{"asset_id":"17406866367975599232214757606801140480252276357934486651183783311435802862074","best_ask":"0.15","best_bid":"0.14","hash":"57104ec21dea2e68a0dcc6b518a72107da274b19","price":"0.99","side":"SELL","size":"5767.53"}],"timestamp":"1786845520703"}}
{"f":1343,"recv_ms":1786845520923,"raw":{"event_type":"price_change","market":"0xd5f15f31689703aea70b93a52194a0964220d10d92ee7497346f146a8b6ef8ab","price_changes":[{"asset_id":"2151378744569768920256500242561922410292857798164019061749528550808091180185","best_ask":"0.86","best_bid":"0.85","hash":"3eea768cd67a649f4fa1c8caf07a73247af28b7d","price":"0.01","side":"BUY","size":"5762.53"},{"asset_id":"17406866367975599232214757606801140480252276357934486651183783311435802862074","best_ask":"0.15","best_bid":"0.14","hash":"922b4f92aed8d67c0472ad2fb63f0579410d83d7","price":"0.99","side":"SELL","size":"5762.53"}],"timestamp":"1786845520705"}}
{"f":1344,"recv_ms":1786845520923,"raw":{"event_type":"price_change","market":"0xd5f15f31689703aea70b93a52194a0964220d10d92ee7497346f146a8b6ef8ab","price_changes":[{"asset_id":"2151378744569768920256500242561922410292857798164019061749528550808091180185","best_ask":"0.86","best_bid":"0.85","hash":"3fe824708e3c576c1c1b2633f0ab37a761af39a9","price":"0.86","side":"SELL","size":"34.99"},{"asset_id":"17406866367975599232214757606801140480252276357934486651183783311435802862074","best_ask":"0.15","best_bid":"0.14","hash":"de559c2a8ec98474fd1220e54f3e45754ce64844","price":"0.14","side":"BUY","size":"34.99"}],"timestamp":"1786845520712"}}
{"f":1345,"recv_ms":1786845520944,"raw":{"event_type":"price_change","market":"0xd5f15f31689703aea70b93a52194a0964220d10d92ee7497346f146a8b6ef8ab","price_changes":[{"asset_id":"2151378744569768920256500242561922410292857798164019061749528550808091180185","best_ask":"0.86","best_bid":"0.85","hash":"b747a67b856d603455bf5b1129f91d5ca7e57c65","price":"0.01","side":"BUY","size":"5768.53"},{"asset_id":"17406866367975599232214757606801140480252276357934486651183783311435802862074","best_ask":"0.15","best_bid":"0.14","hash":"57763acf43cc0bbfd31283d1f237b7066d424ac2","price":"0.99","side":"SELL","size":"5768.53"}],"timestamp":"1786845520718"}}
{"f":1346,"recv_ms":1786845520950,"raw":{"event_type":"price_change","market":"0xd5f15f31689703aea70b93a52194a0964220d10d92ee7497346f146a8b6ef8ab","price_changes":[{"asset_id":"2151378744569768920256500242561922410292857798164019061749528550808091180185","best_ask":"0.86","best_bid":"0.85","hash":"9bd64564fb1eaffdaf84200bb711d4c1ac0809e2","price":"0.01","side":"BUY","size":"5868.53"},{"asset_id":"17406866367975599232214757606801140480252276357934486651183783311435802862074","best_ask":"0.15","best_bid":"0.14","hash":"14157c0931216245f78232eb6a78f86162f66a36","price":"0.99","side":"SELL","size":"5868.53"}],"timestamp":"1786845520738"}}
{"f":1347,"recv_ms":1786845520962,"raw":{"event_type":"price_change","market":"0xd5f15f31689703aea70b93a52194a0964220d10d92ee7497346f146a8b6ef8ab","price_changes":[{"asset_id":"2151378744569768920256500242561922410292857798164019061749528550808091180185","best_ask":"0.86","best_bid":"0.85","hash":"501b96135411aa5a30dbbbb8eeea4e07c7260410","price":"0.01","side":"BUY","size":"5863.53"},{"asset_id":"17406866367975599232214757606801140480252276357934486651183783311435802862074","best_ask":"0.15","best_bid":"0.14","hash":"a7f48cf8dd4188c77139a0516a8720bba63b3050","price":"0.99","side":"SELL","size":"5863.53"}],"timestamp":"1786845520739"}}
{"f":1348,"recv_ms":1786845520962,"raw":{"event_type":"price_change","market":"0xd5f15f31689703aea70b93a52194a0964220d10d92ee7497346f146a8b6ef8ab","price_changes":[{"asset_id":"2151378744569768920256500242561922410292857798164019061749528550808091180185","best_ask":"0.86","best_bid":"0.85","hash":"b4b9eab64dd7ec9091276f08e830018fa0f88933","price":"0.01","side":"BUY","size":"5857.53"},{"asset_id":"17406866367975599232214757606801140480252276357934486651183783311435802862074","best_ask":"0.15","best_bid":"0.14","hash":"2a8520eef21978d6f69e2d336c7d80206e4d7697","price":"0.99","side":"SELL","size":"5857.53"}],"timestamp":"1786845520742"}}
{"f":1349,"recv_ms":1786845520971,"raw":{"event_type":"price_change","market":"0xd5f15f31689703aea70b93a52194a0964220d10d92ee7497346f146a8b6ef8ab","price_changes":[{"asset_id":"2151378744569768920256500242561922410292857798164019061749528550808091180185","best_ask":"0.86","best_bid":"0.85","hash":"8b1c62a522f42019c3d992f89c08a7e9b89676ad","price":"0.43","side":"BUY","size":"92.6"},{"asset_id":"17406866367975599232214757606801140480252276357934486651183783311435802862074","best_ask":"0.15","best_bid":"0.14","hash":"a52068007f226daf0e046889e63841628472fd12","price":"0.57","side":"SELL","size":"92.6"}],"timestamp":"1786845520751"}}
{"f":1350,"recv_ms":1786845520971,"raw":{"event_type":"price_change","market":"0xd5f15f31689703aea70b93a52194a0964220d10d92ee7497346f146a8b6ef8ab","price_changes":[{"asset_id":"2151378744569768920256500242561922410292857798164019061749528550808091180185","best_ask":"0.86","best_bid":"0.85","hash":"d469e13299dc3f041df2d2ebb30672691929dc34","price":"0.01","side":"BUY","size":"5862.54"},{"asset_id":"17406866367975599232214757606801140480252276357934486651183783311435802862074","best_ask":"0.15","best_bid":"0.14","hash":"e96710af1dc14d070b48ff0827908b19ce4094ce","price":"0.99","side":"SELL","size":"5862.54"}],"timestamp":"1786845520754"}}
{"f":1351,"recv_ms":1786845520985,"raw":{"event_type":"price_change","market":"0xd5f15f31689703aea70b93a52194a0964220d10d92ee7497346f146a8b6ef8ab","price_changes":[{"asset_id":"2151378744569768920256500242561922410292857798164019061749528550808091180185","best_ask":"0.86","best_bid":"0.85","hash":"cdcde7e1ce896c8da70dbc01fc414f2291f58614","price":"0.01","side":"BUY","size":"5857.54"},{"asset_id":"17406866367975599232214757606801140480252276357934486651183783311435802862074","best_ask":"0.15","best_bid":"0.14","hash":"4d80278fe07737081adf05e59213af38d44a3819","price":"0.99","side":"SELL","size":"5857.54"}],"timestamp":"1786845520768"}}
{"f":1352,"recv_ms":1786845521000,"raw":{"event_type":"price_change","market":"0xd5f15f31689703aea70b93a52194a0964220d10d92ee7497346f146a8b6ef8ab","price_changes":[{"asset_id":"2151378744569768920256500242561922410292857798164019061749528550808091180185","best_ask":"0.86","best_bid":"0.85","hash":"54c2dd3e2c31e2ee1a61d6b204bc16e88686e6ac","price":"0.01","side":"BUY","size":"5757.54"},{"asset_id":"17406866367975599232214757606801140480252276357934486651183783311435802862074","best_ask":"0.15","best_bid":"0.14","hash":"ee35dcd37d84ed4faf496fb0d14a69d7b6e5433f","price":"0.99","side":"SELL","size":"5757.54"}],"timestamp":"1786845520774"}}
{"f":1353,"recv_ms":1786845521000,"raw":{"event_type":"price_change","market":"0xd5f15f31689703aea70b93a52194a0964220d10d92ee7497346f146a8b6ef8ab","price_changes":[{"asset_id":"2151378744569768920256500242561922410292857798164019061749528550808091180185","best_ask":"0.86","best_bid":"0.85","hash":"65fc553747a2e47769e00ae62d64c20aee66f81f","price":"0.01","side":"BUY","size":"5752.53"},{"asset_id":"17406866367975599232214757606801140480252276357934486651183783311435802862074","best_ask":"0.15","best_bid":"0.14","hash":"ed3af5e708a122b148375664c4e9eb120d1398aa","price":"0.99","side":"SELL","size":"5752.53"}],"timestamp":"1786845520785"}}
{"f":1354,"recv_ms":1786845521024,"raw":{"asset_id":"2151378744569768920256500242561922410292857798164019061749528550808091180185","event_type":"last_trade_price","fee_rate_bps":"0","market":"0xd5f15f31689703aea70b93a52194a0964220d10d92ee7497346f146a8b6ef8ab","price":"0.86","side":"BUY","size":"5","timestamp":"1786845520788","transaction_hash":"0xedc7ee79550127573f0ff62ca8e0ac5361ec8e3938398fbd29db999541ac5937"}}
{"f":1355,"recv_ms":1786845521024,"raw":{"event_type":"price_change","market":"0xd5f15f31689703aea70b93a52194a0964220d10d92ee7497346f146a8b6ef8ab","price_changes":[{"asset_id":"2151378744569768920256500242561922410292857798164019061749528550808091180185","best_ask":"0.86","best_bid":"0.85","hash":"eed3c2d4a628cec16d0fa2741429e9b453a325a3","price":"0.01","side":"BUY","size":"5758.53"},{"asset_id":"17406866367975599232214757606801140480252276357934486651183783311435802862074","best_ask":"0.15","best_bid":"0.14","hash":"1d7513bf7672420f1bc560490f560fc14168d7d8","price":"0.99","side":"SELL","size":"5758.53"}],"timestamp":"1786845520811"}}
{"f":1356,"recv_ms":1786845521028,"raw":{"event_type":"price_change","market":"0xd5f15f31689703aea70b93a52194a0964220d10d92ee7497346f146a8b6ef8ab","price_changes":[{"asset_id":"2151378744569768920256500242561922410292857798164019061749528550808091180185","best_ask":"0.86","best_bid":"0.85","hash":"4e9d4f286e0f811b5787980dab8a54781ac81d6b","price":"0.01","side":"BUY","size":"5858.53"},{"asset_id":"17406866367975599232214757606801140480252276357934486651183783311435802862074","best_ask":"0.15","best_bid":"0.14","hash":"926439475c094061473c86398a12b0897668cbaf","price":"0.99","side":"SELL","size":"5858.53"}],"timestamp":"1786845520813"}}
{"f":1357,"recv_ms":1786845521047,"raw":{"event_type":"price_change","market":"0xd5f15f31689703aea70b93a52194a0964220d10d92ee7497346f146a8b6ef8ab","price_changes":[{"asset_id":"17406866367975599232214757606801140480252276357934486651183783311435802862074","best_ask":"0.15","best_bid":"0.14","hash":"54d7e30c374a75192ffdaa5ff7b649fc7574e34f","price":"0.01","side":"BUY","size":"5683.18"},{"asset_id":"2151378744569768920256500242561922410292857798164019061749528550808091180185","best_ask":"0.86","best_bid":"0.85","hash":"8e7362593b116b238c71dfdee50ece9307ffab01","price":"0.99","side":"SELL","size":"5683.18"}],"timestamp":"1786845520829"}}
{"f":1358,"recv_ms":1786845521048,"raw":{"event_type":"price_change","market":"0xd5f15f31689703aea70b93a52194a0964220d10d92ee7497346f146a8b6ef8ab","price_changes":[{"asset_id":"17406866367975599232214757606801140480252276357934486651183783311435802862074","best_ask":"0.15","best_bid":"0.14","hash":"ac8b4b7ec5513316cec3f7c1703c41d60cc99efe","price":"0.01","side":"BUY","size":"5688.18"},{"asset_id":"2151378744569768920256500242561922410292857798164019061749528550808091180185","best_ask":"0.86","best_bid":"0.85","hash":"14a2aee70c7ccda09d6a35ff09b32d27a5b9d9fb","price":"0.99","side":"SELL","size":"5688.18"}],"timestamp":"1786845520836"}}
{"f":1359,"recv_ms":1786845521048,"raw":{"event_type":"price_change","market":"0xd5f15f31689703aea70b93a52194a0964220d10d92ee7497346f146a8b6ef8ab","price_changes":[{"asset_id":"17406866367975599232214757606801140480252276357934486651183783311435802862074","best_ask":"0.15","best_bid":"0.14","hash":"eeb4760f6a5ca7ac63a8c4c2a86f895fa661580f","price":"0.01","side":"BUY","size":"5683.18"},{"asset_id":"2151378744569768920256500242561922410292857798164019061749528550808091180185","best_ask":"0.86","best_bid":"0.85","hash":"aafa5b7ea0198f8d8bdde76fc7833ec7f51e4413","price":"0.99","side":"SELL","size":"5683.18"}],"timestamp":"1786845520837"}}
{"f":1360,"recv_ms":1786845521056,"raw":{"event_type":"price_change","market":"0xd5f15f31689703aea70b93a52194a0964220d10d92ee7497346f146a8b6ef8ab","price_changes":[{"asset_id":"17406866367975599232214757606801140480252276357934486651183783311435802862074","best_ask":"0.15","best_bid":"0.14","hash":"91f9adf988b9accf82ba794d3902602371c253cd","price":"0.01","side":"BUY","size":"5688.18"},{"asset_id":"2151378744569768920256500242561922410292857798164019061749528550808091180185","best_ask":"0.86","best_bid":"0.85","hash":"9a40dc10af57ed2dc9bafc38e5b98bad3c88995c","price":"0.99","side":"SELL","size":"5688.18"}],"timestamp":"1786845520837"}}
{"f":1361,"recv_ms":1786845521056,"raw":{"event_type":"price_change","market":"0xd5f15f31689703aea70b93a52194a0964220d10d92ee7497346f146a8b6ef8ab","price_changes":[{"asset_id":"2151378744569768920256500242561922410292857798164019061749528550808091180185","best_ask":"0.86","best_bid":"0.85","hash":"977673cbc4becf6dff3745dd1ef1630ec3d036bf","price":"0.01","side":"BUY","size":"5852.53"},{"asset_id":"17406866367975599232214757606801140480252276357934486651183783311435802862074","best_ask":"0.15","best_bid":"0.14","hash":"436a57655627640b361edbbc380f4f660e69dffc","price":"0.99","side":"SELL","size":"5852.53"}],"timestamp":"1786845520843"}}
{"f":1362,"recv_ms":1786845521065,"raw":{"event_type":"price_change","market":"0xd5f15f31689703aea70b93a52194a0964220d10d92ee7497346f146a8b6ef8ab","price_changes":[{"asset_id":"2151378744569768920256500242561922410292857798164019061749528550808091180185","best_ask":"0.86","best_bid":"0.85","hash":"22feeba91e92ad938f9cd27ede69ff8a5dfab119","price":"0.75","side":"BUY","size":"97.9"},{"asset_id":"17406866367975599232214757606801140480252276357934486651183783311435802862074","best_ask":"0.15","best_bid":"0.14","hash":"79201e4a0e80933597bcf1cfdb47795223e413bb","price":"0.25","side":"SELL","size":"97.9"}],"timestamp":"1786845520847"}}
{"f":1363,"recv_ms":1786845521083,"raw":{"event_type":"price_change","market":"0xd5f15f31689703aea70b93a52194a0964220d10d92ee7497346f146a8b6ef8ab","price_changes":[{"asset_id":"2151378744569768920256500242561922410292857798164019061749528550808091180185","best_ask":"0.86","best_bid":"0.85","hash":"f33a567ee2318f4c6ca28d3e7cc95b165de2a3a2","price":"0.01","side":"BUY","size":"5752.53"},{"asset_id":"17406866367975599232214757606801140480252276357934486651183783311435802862074","best_ask":"0.15","best_bid":"0.14","hash":"8b46fea24f05ec40f6b276be100d207b103bf799","price":"0.99","side":"SELL","size":"5752.53"}],"timestamp":"1786845520854"}}
{"f":1364,"recv_ms":1786845521105,"raw":{"event_type":"price_change","market":"0xd5f15f31689703aea70b93a52194a0964220d10d92ee7497346f146a8b6ef8ab","price_changes":[{"asset_id":"2151378744569768920256500242561922410292857798164019061749528550808091180185","best_ask":"0.86","best_bid":"0.85","hash":"3905f1127b3bbe1a83c901eac8c8a519aacffba6","price":"0.01","side":"BUY","size":"5757.53"},{"asset_id":"17406866367975599232214757606801140480252276357934486651183783311435802862074","best_ask":"0.15","best_bid":"0.14","hash":"a6a5fb41fcfa0498eb3b0c8aaad30696c8f340e1","price":"0.99","side":"SELL","size":"5757.53"}],"timestamp":"1786845520870"}}
{"f":1365,"recv_ms":1786845521105,"raw":{"event_type":"price_change","market":"0xd5f15f31689703aea70b93a52194a0964220d10d92ee7497346f146a8b6ef8ab","price_changes":[{"asset_id":"2151378744569768920256500242561922410292857798164019061749528550808091180185","best_ask":"0.86","best_bid":"0.85","hash":"25daba7f7f28f29957514e6bdb7ffa7598c18646","price":"0.01","side":"BUY","size":"5762.53"},{"asset_id":"17406866367975599232214757606801140480252276357934486651183783311435802862074","best_ask":"0.15","best_bid":"0.14","hash":"6493068ffc99e2f35cd96a7b191f1e54f64e2d07","price":"0.99","side":"SELL","size":"5762.53"}],"timestamp":"1786845520871"}}
{"f":1366,"recv_ms":1786845521105,"raw":{"event_type":"price_change","market":"0xd5f15f31689703aea70b93a52194a0964220d10d92ee7497346f146a8b6ef8ab","price_changes":[{"asset_id":"2151378744569768920256500242561922410292857798164019061749528550808091180185","best_ask":"0.86","best_bid":"0.85","hash":"02b125d9ba0597ab7ae08cc4f92a9d91468cba9e","price":"0.01","side":"BUY","size":"5767.53"},{"asset_id":"17406866367975599232214757606801140480252276357934486651183783311435802862074","best_ask":"0.15","best_bid":"0.14","hash":"9524c98fd3f437783db955196dba4ff0691591cf","price":"0.99","side":"SELL","size":"5767.53"}],"timestamp":"1786845520872"}}
{"f":1367,"recv_ms":1786845521111,"raw":{"event_type":"price_change","market":"0xd5f15f31689703aea70b93a52194a0964220d10d92ee7497346f146a8b6ef8ab","price_changes":[{"asset_id":"2151378744569768920256500242561922410292857798164019061749528550808091180185","best_ask":"0.86","best_bid":"0.85","hash":"b37426c5031d678ac75a9423295ba9dd2c440d08","price":"0.01","side":"BUY","size":"5867.53"},{"asset_id":"17406866367975599232214757606801140480252276357934486651183783311435802862074","best_ask":"0.15","best_bid":"0.14","hash":"ce1514066b007f81c7de15fb0488966009e56c1e","price":"0.99","side":"SELL","size":"5867.53"}],"timestamp":"1786845520893"}}
{"f":1368,"recv_ms":1786845521140,"raw":{"event_type":"price_change","market":"0xd5f15f31689703aea70b93a52194a0964220d10d92ee7497346f146a8b6ef8ab","price_changes":[{"asset_id":"2151378744569768920256500242561922410292857798164019061749528550808091180185","best_ask":"0.86","best_bid":"0.85","hash":"bfef0523d34bf3e41322b8a5141b942274ea0d8b","price":"0.01","side":"BUY","size":"5873.53"},{"asset_id":"17406866367975599232214757606801140480252276357934486651183783311435802862074","best_ask":"0.15","best_bid":"0.14","hash":"e49582190dad6b08479c51e5ae12ab77a5257677","price":"0.99","side":"SELL","size":"5873.53"}],"timestamp":"1786845520917"}}
{"f":1369,"recv_ms":1786845521153,"raw":{"event_type":"price_change","market":"0xd5f15f31689703aea70b93a52194a0964220d10d92ee7497346f146a8b6ef8ab","price_changes":[{"asset_id":"2151378744569768920256500242561922410292857798164019061749528550808091180185","best_ask":"0.86","best_bid":"0.85","hash":"2db5c07ae20ca3fdba85d0955c7349fc25d57df2","price":"0.01","side":"BUY","size":"5868.53"},{"asset_id":"17406866367975599232214757606801140480252276357934486651183783311435802862074","best_ask":"0.15","best_bid":"0.14","hash":"f40b395e811610d3c66d40bbcce36b2a27bd8d5f","price":"0.99","side":"SELL","size":"5868.53"}],"timestamp":"1786845520930"}}
{"f":1370,"recv_ms":1786845521168,"raw":{"event_type":"price_change","market":"0xd5f15f31689703aea70b93a52194a0964220d10d92ee7497346f146a8b6ef8ab","price_changes":[{"asset_id":"2151378744569768920256500242561922410292857798164019061749528550808091180185","best_ask":"0.86","best_bid":"0.85","hash":"0d5be93e14684d73c1aae81a15d40de108961119","price":"0.01","side":"BUY","size":"5768.53"},{"asset_id":"17406866367975599232214757606801140480252276357934486651183783311435802862074","best_ask":"0.15","best_bid":"0.14","hash":"e06c261ccc9e338a7896bbca17d1391a3eba34f9","price":"0.99","side":"SELL","size":"5768.53"}],"timestamp":"1786845520942"}}
{"f":1371,"recv_ms":1786845521169,"raw":{"event_type":"price_change","market":"0xd5f15f31689703aea70b93a52194a0964220d10d92ee7497346f146a8b6ef8ab","price_changes":[{"asset_id":"2151378744569768920256500242561922410292857798164019061749528550808091180185","best_ask":"0.86","best_bid":"0.85","hash":"bc0e6fd4baa974ab044b98664d2ecee8bf799b5b","price":"0.01","side":"BUY","size":"5762.53"},{"asset_id":"17406866367975599232214757606801140480252276357934486651183783311435802862074","best_ask":"0.15","best_bid":"0.14","hash":"44c8766be4b1e78c2538682d821f4ae856296b9c","price":"0.99","side":"SELL","size":"5762.53"}],"timestamp":"1786845520945"}}
{"f":1372,"recv_ms":1786845521175,"raw":{"event_type":"price_change","market":"0xd5f15f31689703aea70b93a52194a0964220d10d92ee7497346f146a8b6ef8ab","price_changes":[{"asset_id":"2151378744569768920256500242561922410292857798164019061749528550808091180185","best_ask":"0.86","best_bid":"0.85","hash":"9522194c8f80366d33f3b444012f088ff83bae38","price":"0.01","side":"BUY","size":"5767.54"},{"asset_id":"17406866367975599232214757606801140480252276357934486651183783311435802862074","best_ask":"0.15","best_bid":"0.14","hash":"01555c834c5a161fee74989ae89596deba53c8e9","price":"0.99","side":"SELL","size":"5767.54"}],"timestamp":"1786845520959"}}
{"f":1373,"recv_ms":1786845521198,"raw":{"event_type":"price_change","market":"0xd5f15f31689703aea70b93a52194a0964220d10d92ee7497346f146a8b6ef8ab","price_changes":[{"asset_id":"2151378744569768920256500242561922410292857798164019061749528550808091180185","best_ask":"0.86","best_bid":"0.85","hash":"abaa69df6baa4434de7c95e58fe9021b9af1ee2f","price":"0.01","side":"BUY","size":"5762.54"},{"asset_id":"17406866367975599232214757606801140480252276357934486651183783311435802862074","best_ask":"0.15","best_bid":"0.14","hash":"de09556dd3c597485a618d613c2e6d4d93850545","price":"0.99","side":"SELL","size":"5762.54"}],"timestamp":"1786845520965"}}
{"f":1374,"recv_ms":1786845521198,"raw":{"event_type":"price_change","market":"0xd5f15f31689703aea70b93a52194a0964220d10d92ee7497346f146a8b6ef8ab","price_changes":[{"asset_id":"2151378744569768920256500242561922410292857798164019061749528550808091180185","best_ask":"0.86","best_bid":"0.85","hash":"589be149b75cf8081ae1099ceec3a985765f26cd","price":"0.01","side":"BUY","size":"5757.53"},{"asset_id":"17406866367975599232214757606801140480252276357934486651183783311435802862074","best_ask":"0.15","best_bid":"0.14","hash":"315c02a10f751362024066fd3ac99e69000daf09","price":"0.99","side":"SELL","size":"5757.53"}],"timestamp":"1786845520987"}}
{"f":1375,"recv_ms":1786845521211,"raw":{"event_type":"price_change","market":"0xd5f15f31689703aea70b93a52194a0964220d10d92ee7497346f146a8b6ef8ab","price_changes":[{"asset_id":"2151378744569768920256500242561922410292857798164019061749528550808091180185","best_ask":"0.86","best_bid":"0.85","hash":"526dd1f7acb00a66724dacc16d90be0ff761ff2c","price":"0.01","side":"BUY","size":"5857.53"},{"asset_id":"17406866367975599232214757606801140480252276357934486651183783311435802862074","best_ask":"0.15","best_bid":"0.14","hash":"c974236ee20087848178d6158b35cc9cb9fddbee","price":"0.99","side":"SELL","size":"5857.53"}],"timestamp":"1786845520994"}}
{"f":1376,"recv_ms":1786845521228,"raw":{"event_type":"price_change","market":"0xd5f15f31689703aea70b93a52194a0964220d10d92ee7497346f146a8b6ef8ab","price_changes":[{"asset_id":"2151378744569768920256500242561922410292857798164019061749528550808091180185","best_ask":"0.86","best_bid":"0.85","hash":"e7817c48adbd814dafbdb242f1f16e4952b54f5e","price":"0.01","side":"BUY","size":"5852.53"},{"asset_id":"17406866367975599232214757606801140480252276357934486651183783311435802862074","best_ask":"0.15","best_bid":"0.14","hash":"b313150c18c70f3d6842449ccb46a6d14316ef19","price":"0.99","side":"SELL","size":"5852.53"}],"timestamp":"1786845521000"}}
{"f":1377,"recv_ms":1786845521234,"raw":{"event_type":"price_change","market":"0xd5f15f31689703aea70b93a52194a0964220d10d92ee7497346f146a8b6ef8ab","price_changes":[{"asset_id":"17406866367975599232214757606801140480252276357934486651183783311435802862074","best_ask":"0.15","best_bid":"0.14","hash":"eec0462d80c35445152ccffc0a16958af9c3f0b0","price":"0.01","side":"BUY","size":"5693.18"},{"asset_id":"2151378744569768920256500242561922410292857798164019061749528550808091180185","best_ask":"0.86","best_bid":"0.85","hash":"b115d4ea156929c482796870bd8ebcaeaee5e04e","price":"0.99","side":"SELL","size":"5693.18"}],"timestamp":"1786845521016"}}
{"f":1378,"recv_ms":1786845521239,"raw":{"event_type":"price_change","market":"0xd5f15f31689703aea70b93a52194a0964220d10d92ee7497346f146a8b6ef8ab","price_changes":[{"asset_id":"2151378744569768920256500242561922410292857798164019061749528550808091180185","best_ask":"0.86","best_bid":"0.85","hash":"3df87fa89bd1df8893b686790fb1e0a2fc2f8b99","price":"0.01","side":"BUY","size":"5858.53"},{"asset_id":"17406866367975599232214757606801140480252276357934486651183783311435802862074","best_ask":"0.15","best_bid":"0.14","hash":"7820dd2c1efc8aa1603590a55bdfe2907c622a19","price":"0.99","side":"SELL","size":"5858.53"}],"timestamp":"1786845521017"}}
{"f":1379,"recv_ms":1786845521239,"raw":{"event_type":"price_change","market":"0xd5f15f31689703aea70b93a52194a0964220d10d92ee7497346f146a8b6ef8ab","price_changes":[{"asset_id":"2151378744569768920256500242561922410292857798164019061749528550808091180185","best_ask":"0.86","best_bid":"0.85","hash":"c6c207400e6a521767d46834803487fd2569b374","price":"0.01","side":"BUY","size":"5853.53"},{"asset_id":"17406866367975599232214757606801140480252276357934486651183783311435802862074","best_ask":"0.15","best_bid":"0.14","hash":"36b9e4093ccca79ac5f4eee49b58fc1315f22f01","price":"0.99","side":"SELL","size":"5853.53"}],"timestamp":"1786845521018"}}
{"f":1380,"recv_ms":1786845521239,"raw":{"event_type":"price_change","market":"0xd5f15f31689703aea70b93a52194a0964220d10d92ee7497346f146a8b6ef8ab","price_changes":[{"asset_id":"2151378744569768920256500242561922410292857798164019061749528550808091180185","best_ask":"0.86","best_bid":"0.85","hash":"f95047384a3dc4fca0e8dc6e5f8147a363d104f8","price":"0.01","side":"BUY","size":"5848.53"},{"asset_id":"17406866367975599232214757606801140480252276357934486651183783311435802862074","best_ask":"0.15","best_bid":"0.14","hash":"eea29206559c98a2952c256b6d7f1ae96a42f38a","price":"0.99","side":"SELL","size":"5848.53"}],"timestamp":"1786845521019"}}
{"f":1381,"recv_ms":1786845521239,"raw":{"event_type":"price_change","market":"0xd5f15f31689703aea70b93a52194a0964220d10d92ee7497346f146a8b6ef8ab","price_changes":[{"asset_id":"2151378744569768920256500242561922410292857798164019061749528550808091180185","best_ask":"0.86","best_bid":"0.85","hash":"f3abf5d8b662bb2d7350fa7f4dfd9b90225d77bf","price":"0.01","side":"BUY","size":"5853.53"},{"asset_id":"17406866367975599232214757606801140480252276357934486651183783311435802862074","best_ask":"0.15","best_bid":"0.14","hash":"137e7187fcc8bc1b12cce7375319d3997317bd16","price":"0.99","side":"SELL","size":"5853.53"}],"timestamp":"1786845521021"}}
{"f":1382,"recv_ms":1786845521239,"raw":{"event_type":"price_change","market":"0xd5f15f31689703aea70b93a52194a0964220d10d92ee7497346f146a8b6ef8ab","price_changes":[{"asset_id":"17406866367975599232214757606801140480252276357934486651183783311435802862074","best_ask":"0.15","best_bid":"0.14","hash":"179c188d08ce7b9a41657ef4f287d9eac94fe6a1","price":"0.01","side":"BUY","size":"5698.18"},{"asset_id":"2151378744569768920256500242561922410292857798164019061749528550808091180185","best_ask":"0.86","best_bid":"0.85","hash":"6249d7f99cbb53d9dcce261137af0b75aa6b542d","price":"0.99","side":"SELL","size":"5698.18"}],"timestamp":"1786845521021"}}
{"f":1383,"recv_ms":1786845521239,"raw":{"event_type":"price_change","market":"0xd5f15f31689703aea70b93a52194a0964220d10d92ee7497346f146a8b6ef8ab","price_changes":[{"asset_id":"2151378744569768920256500242561922410292857798164019061749528550808091180185","best_ask":"0.86","best_bid":"0.85","hash":"855434f921e201c97fe3673a31481bd05c4689f8","price":"0.01","side":"BUY","size":"5858.53"},{"asset_id":"17406866367975599232214757606801140480252276357934486651183783311435802862074","best_ask":"0.15","best_bid":"0.14","hash":"21db083e41c4335a3dbe829d6ba8dfb31235260b","price":"0.99","side":"SELL","size":"5858.53"}],"timestamp":"1786845521023"}}
{"f":1384,"recv_ms":1786845521253,"raw":{"event_type":"price_change","market":"0xd5f15f31689703aea70b93a52194a0964220d10d92ee7497346f146a8b6ef8ab","price_changes":[{"asset_id":"2151378744569768920256500242561922410292857798164019061749528550808091180185","best_ask":"0.86","best_bid":"0.85","hash":"f0da97c1ce3354bcd6c08005f5a958485c776d6c","price":"0.01","side":"BUY","size":"5863.53"},{"asset_id":"17406866367975599232214757606801140480252276357934486651183783311435802862074","best_ask":"0.15","best_bid":"0.14","hash":"233e0dfb30626e9b1541c0a8e884dcbc85423844","price":"0.99","side":"SELL","size":"5863.53"}],"timestamp":"1786845521028"}}
{"f":1385,"recv_ms":1786845521253,"raw":{"event_type":"price_change","market":"0xd5f15f31689703aea70b93a52194a0964220d10d92ee7497346f146a8b6ef8ab","price_changes":[{"asset_id":"2151378744569768920256500242561922410292857798164019061749528550808091180185","best_ask":"0.86","best_bid":"0.85","hash":"950638dc13c25b427d9ca05da5e0f7cceca0d3a6","price":"0.01","side":"BUY","size":"5763.53"},{"asset_id":"17406866367975599232214757606801140480252276357934486651183783311435802862074","best_ask":"0.15","best_bid":"0.14","hash":"ef409a89cb6fcb2a4bdeb7e3ddaa63ef22734d94","price":"0.99","side":"SELL","size":"5763.53"}],"timestamp":"1786845521029"}}
{"f":1386,"recv_ms":1786845521256,"raw":{"event_type":"price_change","market":"0xd5f15f31689703aea70b93a52194a0964220d10d92ee7497346f146a8b6ef8ab","price_changes":[{"asset_id":"2151378744569768920256500242561922410292857798164019061749528550808091180185","best_ask":"0.86","best_bid":"0.85","hash":"8e5207595df149b521afb06d39e146410f6d20c8","price":"0.01","side":"BUY","size":"5757.53"},{"asset_id":"17406866367975599232214757606801140480252276357934486651183783311435802862074","best_ask":"0.15","best_bid":"0.14","hash":"46b61c839a1214f5349469d33f1c3ef8f586578a","price":"0.99","side":"SELL","size":"5757.53"}],"timestamp":"1786845521042"}}
{"f":1387,"recv_ms":1786845521256,"raw":{"event_type":"price_change","market":"0xd5f15f31689703aea70b93a52194a0964220d10d92ee7497346f146a8b6ef8ab","price_changes":[{"asset_id":"17406866367975599232214757606801140480252276357934486651183783311435802862074","best_ask":"0.15","best_bid":"0.14","hash":"4fa41e6f06cdc37e86295aee8676f6c072ed223b","price":"0.01","side":"BUY","size":"5693.18"},{"asset_id":"2151378744569768920256500242561922410292857798164019061749528550808091180185","best_ask":"0.86","best_bid":"0.85","hash":"17ed8622db8a484a997ff86d7387e3cb49173925","price":"0.99","side":"SELL","size":"5693.18"}],"timestamp":"1786845521043"}}
{"f":1388,"recv_ms":1786845521267,"raw":{"event_type":"price_change","market":"0xd5f15f31689703aea70b93a52194a0964220d10d92ee7497346f146a8b6ef8ab","price_changes":[{"asset_id":"2151378744569768920256500242561922410292857798164019061749528550808091180185","best_ask":"0.86","best_bid":"0.85","hash":"f6787fbbaf90ecfd11a9bce16b36d1437b949ba8","price":"0.01","side":"BUY","size":"5752.53"},{"asset_id":"17406866367975599232214757606801140480252276357934486651183783311435802862074","best_ask":"0.15","best_bid":"0.14","hash":"1d2c90341733c8717f2c24ba6564774d6a863d94","price":"0.99","side":"SELL","size":"5752.53"}],"timestamp":"1786845521046"}}
{"f":1389,"recv_ms":1786845521285,"raw":{"event_type":"price_change","market":"0xd5f15f31689703aea70b93a52194a0964220d10d92ee7497346f146a8b6ef8ab","price_changes":[{"asset_id":"2151378744569768920256500242561922410292857798164019061749528550808091180185","best_ask":"0.86","best_bid":"0.85","hash":"a3aa76bbf124a7e9b97232fcb2db09679443d1b6","price":"0.01","side":"BUY","size":"5852.53"},{"asset_id":"17406866367975599232214757606801140480252276357934486651183783311435802862074","best_ask":"0.15","best_bid":"0.14","hash":"eb3abf9b10dd862b5aa1f80741ea91df8cd051a3","price":"0.99","side":"SELL","size":"5852.53"}],"timestamp":"1786845521055"}}
{"f":1390,"recv_ms":1786845521285,"raw":{"event_type":"price_change","market":"0xd5f15f31689703aea70b93a52194a0964220d10d92ee7497346f146a8b6ef8ab","price_changes":[{"asset_id":"17406866367975599232214757606801140480252276357934486651183783311435802862074","best_ask":"0.15","best_bid":"0.14","hash":"a2b5eee9439c31b20db2790a0e46fdd4188a68e0","price":"0.01","side":"BUY","size":"5688.18"},{"asset_id":"2151378744569768920256500242561922410292857798164019061749528550808091180185","best_ask":"0.86","best_bid":"0.85","hash":"6170fe68965f0e4d1c394528819eb6a75d516636","price":"0.99","side":"SELL","size":"5688.18"}],"timestamp":"1786845521061"}}
{"f":1391,"recv_ms":1786845521285,"raw":{"event_type":"price_change","market":"0xd5f15f31689703aea70b93a52194a0964220d10d92ee7497346f146a8b6ef8ab","price_changes":[{"asset_id":"2151378744569768920256500242561922410292857798164019061749528550808091180185","best_ask":"0.86","best_bid":"0.85","hash":"5df30e5b1ab9f9a63de1fd48ac6eb7574de06bc9","price":"0.92","side":"SELL","size":"70.29"},{"asset_id":"17406866367975599232214757606801140480252276357934486651183783311435802862074","best_ask":"0.15","best_bid":"0.14","hash":"9c5fd90c7e2d8ace1741de1e6bcadb1fa8d7fcef","price":"0.08","side":"BUY","size":"70.29"}],"timestamp":"1786845521074"}}
{"f":1392,"recv_ms":1786845521312,"raw":{"event_type":"price_change","market":"0xd5f15f31689703aea70b93a52194a0964220d10d92ee7497346f146a8b6ef8ab","price_changes":[{"asset_id":"2151378744569768920256500242561922410292857798164019061749528550808091180185","best_ask":"0.86","best_bid":"0.85","hash":"a45b40e17568e61e32f045597b41cb5078dc35df","price":"0.01","side":"BUY","size":"5752.53"},{"asset_id":"17406866367975599232214757606801140480252276357934486651183783311435802862074","best_ask":"0.15","best_bid":"0.14","hash":"e6e317de739642c15d8ee6bb2c96cf7bc4300b6e","price":"0.99","side":"SELL","size":"5752.53"}],"timestamp":"1786845521089"}}
{"f":1393,"recv_ms":1786845521313,"raw":{"event_type":"price_change","market":"0xd5f15f31689703aea70b93a52194a0964220d10d92ee7497346f146a8b6ef8ab","price_changes":[{"asset_id":"2151378744569768920256500242561922410292857798164019061749528550808091180185","best_ask":"0.86","best_bid":"0.85","hash":"e2657d741a1bad3975502bc9b17617277348795e","price":"0.01","side":"BUY","size":"5757.53"},{"asset_id":"17406866367975599232214757606801140480252276357934486651183783311435802862074","best_ask":"0.15","best_bid":"0.14","hash":"2bdef666c54195405ebc61322f140195be61e6af","price":"0.99","side":"SELL","size":"5757.53"}],"timestamp":"1786845521102"}}
{"f":1394,"recv_ms":1786845521314,"raw":{"event_type":"price_change","market":"0xd5f15f31689703aea70b93a52194a0964220d10d92ee7497346f146a8b6ef8ab","price_changes":[{"asset_id":"2151378744569768920256500242561922410292857798164019061749528550808091180185","best_ask":"0.86","best_bid":"0.85","hash":"cdcf91eeb43231b63708f2f3fe6802f76c67dc3d","price":"0.01","side":"BUY","size":"5762.53"},{"asset_id":"17406866367975599232214757606801140480252276357934486651183783311435802862074","best_ask":"0.15","best_bid":"0.14","hash":"ebe9f4dcd49aab075017a3f78b3821072b4e328c","price":"0.99","side":"SELL","size":"5762.53"}],"timestamp":"1786845521103"}}
{"f":1395,"recv_ms":1786845521343,"raw":{"event_type":"price_change","market":"0xd5f15f31689703aea70b93a52194a0964220d10d92ee7497346f146a8b6ef8ab","price_changes":[{"asset_id":"2151378744569768920256500242561922410292857798164019061749528550808091180185","best_ask":"0.86","best_bid":"0.85","hash":"b34c1f2fa5d2c4a2990ada1247e84a9431f005a7","price":"0.01","side":"BUY","size":"5767.53"},{"asset_id":"17406866367975599232214757606801140480252276357934486651183783311435802862074","best_ask":"0.15","best_bid":"0.14","hash":"1aac44040d3cc73e4c184d5852d3f02089ae143b","price":"0.99","side":"SELL","size":"5767.53"}],"timestamp":"1786845521104"}}
{"f":1396,"recv_ms":1786845521343,"raw":{"event_type":"price_change","market":"0xd5f15f31689703aea70b93a52194a0964220d10d92ee7497346f146a8b6ef8ab","price_changes":[{"asset_id":"2151378744569768920256500242561922410292857798164019061749528550808091180185","best_ask":"0.86","best_bid":"0.85","hash":"538ab97809e49d003c57292b4c0e775653714ebf","price":"0.01","side":"BUY","size":"5773.53"},{"asset_id":"17406866367975599232214757606801140480252276357934486651183783311435802862074","best_ask":"0.15","best_bid":"0.14","hash":"a3f2c9219b4516be45754a73a64fec648d44a8a9","price":"0.99","side":"SELL","size":"5773.53"}],"timestamp":"1786845521112"}}
{"f":1397,"recv_ms":1786845521346,"raw":{"event_type":"price_change","market":"0xd5f15f31689703aea70b93a52194a0964220d10d92ee7497346f146a8b6ef8ab","price_changes":[{"asset_id":"2151378744569768920256500242561922410292857798164019061749528550808091180185","best_ask":"0.86","best_bid":"0.85","hash":"75990f33c28a6ea3513d5879e4850307b378b255","price":"0.01","side":"BUY","size":"5873.53"},{"asset_id":"17406866367975599232214757606801140480252276357934486651183783311435802862074","best_ask":"0.15","best_bid":"0.14","hash":"2c9df78dadd515c4e4561ae60cd172235b263184","price":"0.99","side":"SELL","size":"5873.53"}],"timestamp":"1786845521134"}}
{"f":1398,"recv_ms":1786845521355,"raw":{"event_type":"price_change","market":"0xd5f15f31689703aea70b93a52194a0964220d10d92ee7497346f146a8b6ef8ab","price_changes":[{"asset_id":"2151378744569768920256500242561922410292857798164019061749528550808091180185","best_ask":"0.86","best_bid":"0.85","hash":"ba9b28d80489f0e263e30dd803ebb1d4395ce8d0","price":"0.01","side":"BUY","size":"5868.53"},{"asset_id":"17406866367975599232214757606801140480252276357934486651183783311435802862074","best_ask":"0.15","best_bid":"0.14","hash":"d5d10d6d060ee7d0c57dbc0b54e928de9d5b3444","price":"0.99","side":"SELL","size":"5868.53"}],"timestamp":"1786845521135"}}
{"f":1399,"recv_ms":1786845521355,"raw":{"event_type":"price_change","market":"0xd5f15f31689703aea70b93a52194a0964220d10d92ee7497346f146a8b6ef8ab","price_changes":[{"asset_id":"2151378744569768920256500242561922410292857798164019061749528550808091180185","best_ask":"0.86","best_bid":"0.85","hash":"e63ae1a1241c3884214424c39149b2b62f7683a6","price":"0.01","side":"BUY","size":"5978.53"},{"asset_id":"17406866367975599232214757606801140480252276357934486651183783311435802862074","best_ask":"0.15","best_bid":"0.14","hash":"6cb82ae2248cbe515e43686154eb5049f12cfaa1","price":"0.99","side":"SELL","size":"5978.53"}],"timestamp":"1786845521141"}}
{"f":1400,"recv_ms":1786845521364,"raw":{"event_type":"price_change","market":"0xd5f15f31689703aea70b93a52194a0964220d10d92ee7497346f146a8b6ef8ab","price_changes":[{"asset_id":"2151378744569768920256500242561922410292857798164019061749528550808091180185","best_ask":"0.86","best_bid":"0.85","hash":"f700480eab54d550a508dda55244e370623d5645","price":"0.01","side":"BUY","size":"5972.53"},{"asset_id":"17406866367975599232214757606801140480252276357934486651183783311435802862074","best_ask":"0.15","best_bid":"0.14","hash":"ae8c529025753fc9e5c6bafe79bba45b07d0eb99","price":"0.99","side":"SELL","size":"5972.53"}],"timestamp":"1786845521144"}}
{"f":1401,"recv_ms":1786845521364,"raw":{"event_type":"price_change","market":"0xd5f15f31689703aea70b93a52194a0964220d10d92ee7497346f146a8b6ef8ab","price_changes":[{"asset_id":"2151378744569768920256500242561922410292857798164019061749528550808091180185","best_ask":"0.86","best_bid":"0.85","hash":"1b902590f0523f20b00db9af4a5e477e90ed1730","price":"0.01","side":"BUY","size":"5977.54"},{"asset_id":"17406866367975599232214757606801140480252276357934486651183783311435802862074","best_ask":"0.15","best_bid":"0.14","hash":"8c6480fdafda19152638a37049e3849950fd53c0","price":"0.99","side":"SELL","size":"5977.54"}],"timestamp":"1786845521153"}}
{"f":1402,"recv_ms":1786845521365,"raw":{"event_type":"price_change","market":"0xd5f15f31689703aea70b93a52194a0964220d10d92ee7497346f146a8b6ef8ab","price_changes":[{"asset_id":"2151378744569768920256500242561922410292857798164019061749528550808091180185","best_ask":"0.86","best_bid":"0.85","hash":"19812ba3e1a6b7cd7d558f5d66c1f93d0de6fe86","price":"0.79","side":"BUY","size":"71"},{"asset_id":"17406866367975599232214757606801140480252276357934486651183783311435802862074","best_ask":"0.15","best_bid":"0.14","hash":"18c999d24ab5788b722096af6a94a3aac9a6458c","price":"0.21","side":"SELL","size":"71"}],"timestamp":"1786845521153"}}
{"f":1403,"recv_ms":1786845521365,"raw":{"event_type":"price_change","market":"0xd5f15f31689703aea70b93a52194a0964220d10d92ee7497346f146a8b6ef8ab","price_changes":[{"asset_id":"2151378744569768920256500242561922410292857798164019061749528550808091180185","best_ask":"0.86","best_bid":"0.85","hash":"e948a73a118c5896055c9af8c6e9f5ac5c705ac2","price":"0.8","side":"BUY","size":"100"},{"asset_id":"17406866367975599232214757606801140480252276357934486651183783311435802862074","best_ask":"0.15","best_bid":"0.14","hash":"1a1c5064d102a87d6bd37eba073ebaa5e543cc23","price":"0.2","side":"SELL","size":"100"}],"timestamp":"1786845521154"}}
{"f":1404,"recv_ms":1786845521366,"raw":{"event_type":"price_change","market":"0xd5f15f31689703aea70b93a52194a0964220d10d92ee7497346f146a8b6ef8ab","price_changes":[{"asset_id":"17406866367975599232214757606801140480252276357934486651183783311435802862074","best_ask":"0.15","best_bid":"0.14","hash":"ad6695b6a57200d532ed033c047d8b4ce63e99a8","price":"0.06","side":"BUY","size":"466.1"},{"asset_id":"2151378744569768920256500242561922410292857798164019061749528550808091180185","best_ask":"0.86","best_bid":"0.85","hash":"557e779dee62c916576da73a249172b9461784a3","price":"0.94","side":"SELL","size":"466.1"}],"timestamp":"1786845521155"}}
{"f":1405,"recv_ms":1786845521366,"raw":{"event_type":"price_change","market":"0xd5f15f31689703aea70b93a52194a0964220d10d92ee7497346f146a8b6ef8ab","price_changes":[{"asset_id":"17406866367975599232214757606801140480252276357934486651183783311435802862074","best_ask":"0.15","best_bid":"0.14","hash":"0916b488dc30d0ca665c850cb20a6aeaf8ae25b2","price":"0.06","side":"BUY","size":"366.1"},{"asset_id":"2151378744569768920256500242561922410292857798164019061749528550808091180185","best_ask":"0.86","best_bid":"0.85","hash":"cee469a2aa0f7a79cd217322e1c28ea3ad5261f0","price":"0.94","side":"SELL","size":"366.1"}],"timestamp":"1786845521155"}}
{"f":1406,"recv_ms":1786845521367,"raw":{"event_type":"price_change","market":"0xd5f15f31689703aea70b93a52194a0964220d10d92ee7497346f146a8b6ef8ab","price_changes":[{"asset_id":"2151378744569768920256500242561922410292857798164019061749528550808091180185","best_ask":"0.86","best_bid":"0.85","hash":"bce03d1549764c3c1b9d5e0e898ff4557dd9adf2","price":"0.74","side":"BUY","size":"10"},{"asset_id":"17406866367975599232214757606801140480252276357934486651183783311435802862074","best_ask":"0.15","best_bid":"0.14","hash":"49320b85f66cad66385052e876aad9c5159db37a","price":"0.26","side":"SELL","size":"10"}],"timestamp":"1786845521156"}}
{"f":1407,"recv_ms":1786845521369,"raw":{"event_type":"price_change","market":"0xd5f15f31689703aea70b93a52194a0964220d10d92ee7497346f146a8b6ef8ab","price_changes":[{"asset_id":"2151378744569768920256500242561922410292857798164019061749528550808091180185","best_ask":"0.86","best_bid":"0.85","hash":"f52caf032fb719642e7a790630767b65a84a4efb","price":"0.55","side":"BUY","size":"139"},{"asset_id":"17406866367975599232214757606801140480252276357934486651183783311435802862074","best_ask":"0.15","best_bid":"0.14","hash":"a32250570ae4910bf4381feb237be95f05069a0c","price":"0.45","side":"SELL","size":"139"}],"timestamp":"1786845521156"}}
{"f":1408,"recv_ms":1786845521369,"raw":{"event_type":"price_change","market":"0xd5f15f31689703aea70b93a52194a0964220d10d92ee7497346f146a8b6ef8ab","price_changes":[{"asset_id":"17406866367975599232214757606801140480252276357934486651183783311435802862074","best_ask":"0.15","best_bid":"0.14","hash":"c77dbc05d1903d940c4e6c47058c30c249469f68","price":"0.05","side":"BUY","size":"564.7"},{"asset_id":"2151378744569768920256500242561922410292857798164019061749528550808091180185","best_ask":"0.86","best_bid":"0.85","hash":"98e9887756f08dcde782e167c9e883df682fb7a5","price":"0.95","side":"SELL","size":"564.7"}],"timestamp":"1786845521157"}}
{"f":1409,"recv_ms":1786845521369,"raw":{"event_type":"price_change","market":"0xd5f15f31689703aea70b93a52194a0964220d10d92ee7497346f146a8b6ef8ab","price_changes":[{"asset_id":"2151378744569768920256500242561922410292857798164019061749528550808091180185","best_ask":"0.86","best_bid":"0.85","hash":"723ae092b8f3f3f9cb3610bbb69f9decdb4c35fb","price":"0.8","side":"BUY","size":"130"},{"asset_id":"17406866367975599232214757606801140480252276357934486651183783311435802862074","best_ask":"0.15","best_bid":"0.14","hash":"04c757ef035a760134b440f140169f8218443f0d","price":"0.2","side":"SELL","size":"130"}],"timestamp":"1786845521158"}}
{"f":1410,"recv_ms":1786845521371,"raw":{"event_type":"price_change","market":"0xd5f15f31689703aea70b93a52194a0964220d10d92ee7497346f146a8b6ef8ab","price_changes":[{"asset_id":"2151378744569768920256500242561922410292857798164019061749528550808091180185","best_ask":"0.86","best_bid":"0.85","hash":"0e7d6a812567efb3795ecd4b59fe692d910bbd22","price":"0.57","side":"BUY","size":"154"},{"asset_id":"17406866367975599232214757606801140480252276357934486651183783311435802862074","best_ask":"0.15","best_bid":"0.14","hash":"8ae5561a50524a3823889e34441c0cf2fe20978e","price":"0.43","side":"SELL","size":"154"}],"timestamp":"1786845521158"}}
{"f":1411,"recv_ms":1786845521371,"raw":{"event_type":"price_change","market":"0xd5f15f31689703aea70b93a52194a0964220d10d92ee7497346f146a8b6ef8ab","price_changes":[{"asset_id":"2151378744569768920256500242561922410292857798164019061749528550808091180185","best_ask":"0.86","best_bid":"0.85","hash":"c0bdaabf7f62371981c78237ef3336496877375c","price":"0.78","side":"BUY","size":"7"},{"asset_id":"17406866367975599232214757606801140480252276357934486651183783311435802862074","best_ask":"0.15","best_bid":"0.14","hash":"6c90989d0902a56e1e5ac7a499b832c779564f67","price":"0.22","side":"SELL","size":"7"}],"timestamp":"1786845521159"}}
{"f":1412,"recv_ms":1786845521373,"raw":{"event_type":"price_change","market":"0xd5f15f31689703aea70b93a52194a0964220d10d92ee7497346f146a8b6ef8ab","price_changes":[{"asset_id":"2151378744569768920256500242561922410292857798164019061749528550808091180185","best_ask":"0.86","best_bid":"0.85","hash":"73e7544ba039a20d6bb4a1c75a0e69899eb56dbd","price":"0.01","side":"BUY","size":"5867.54"},{"asset_id":"17406866367975599232214757606801140480252276357934486651183783311435802862074","best_ask":"0.15","best_bid":"0.14","hash":"0b427ffa6815c6cad2cdc5d702ed1a06ab4afe74","price":"0.99","side":"SELL","size":"5867.54"}],"timestamp":"1786845521160"}}
{"f":1413,"recv_ms":1786845521373,"raw":{"event_type":"price_change","market":"0xd5f15f31689703aea70b93a52194a0964220d10d92ee7497346f146a8b6ef8ab","price_changes":[{"asset_id":"2151378744569768920256500242561922410292857798164019061749528550808091180185","best_ask":"0.86","best_bid":"0.85","hash":"3d22968cd4f2e510fd54bea6e25ba8cad2aa3ac7","price":"0.75","side":"BUY","size":"107.9"},{"asset_id":"17406866367975599232214757606801140480252276357934486651183783311435802862074","best_ask":"0.15","best_bid":"0.14","hash":"ddb07f132e8b6d3767798640dd78532543994006","price":"0.25","side":"SELL","size":"107.9"}],"timestamp":"1786845521161"}}
{"f":1414,"recv_ms":1786845521381,"raw":{"event_type":"price_change","market":"0xd5f15f31689703aea70b93a52194a0964220d10d92ee7497346f146a8b6ef8ab","price_changes":[{"asset_id":"2151378744569768920256500242561922410292857798164019061749528550808091180185","best_ask":"0.86","best_bid":"0.85","hash":"f07d49554c2cf2fac72a076155236291185ab79b","price":"0.79","side":"BUY","size":"5"},{"asset_id":"17406866367975599232214757606801140480252276357934486651183783311435802862074","best_ask":"0.15","best_bid":"0.14","hash":"5079c4c950fb22d50a08b56dad10975ed764f8a3","price":"0.21","side":"SELL","size":"5"}],"timestamp":"1786845521162"}}
{"f":1415,"recv_ms":1786845521383,"raw":{"event_type":"price_change","market":"0xd5f15f31689703aea70b93a52194a0964220d10d92ee7497346f146a8b6ef8ab","price_changes":[{"asset_id":"2151378744569768920256500242561922410292857798164019061749528550808091180185","best_ask":"0.86","best_bid":"0.85","hash":"2b1e751435fce6b4f26c35692a56f18b2345d05a","price":"0.01","side":"BUY","size":"5862.54"},{"asset_id":"17406866367975599232214757606801140480252276357934486651183783311435802862074","best_ask":"0.15","best_bid":"0.14","hash":"84471d0b1f3ca259a3b4b8810117f406dfb6da5e","price":"0.99","side":"SELL","size":"5862.54"}],"timestamp":"1786845521171"}}
{"f":1416,"recv_ms":1786845521383,"raw":{"event_type":"price_change","market":"0xd5f15f31689703aea70b93a52194a0964220d10d92ee7497346f146a8b6ef8ab","price_changes":[{"asset_id":"2151378744569768920256500242561922410292857798164019061749528550808091180185","best_ask":"0.86","best_bid":"0.85","hash":"db3dc6b6bdef826c39634147567ba6ebb6856e36","price":"0.8","side":"BUY","size":"196"},{"asset_id":"17406866367975599232214757606801140480252276357934486651183783311435802862074","best_ask":"0.15","best_bid":"0.14","hash":"c2b3b93a8ddd5fb468b93dc5d1475a4d7e7e2b3d","price":"0.2","side":"SELL","size":"196"}],"timestamp":"1786845521171"}}
{"f":1417,"recv_ms":1786845521390,"raw":{"event_type":"price_change","market":"0xd5f15f31689703aea70b93a52194a0964220d10d92ee7497346f146a8b6ef8ab","price_changes":[{"asset_id":"2151378744569768920256500242561922410292857798164019061749528550808091180185","best_ask":"0.86","best_bid":"0.85","hash":"02b7cfc30df43f4f3c8d4281889bcc94e96c3d2d","price":"0.82","side":"BUY","size":"39.22"},{"asset_id":"17406866367975599232214757606801140480252276357934486651183783311435802862074","best_ask":"0.15","best_bid":"0.14","hash":"848756fb16c418193ed1560e017cac7d9de48a3f","price":"0.18","side":"SELL","size":"39.22"}],"timestamp":"1786845521173"}}
{"f":1418,"recv_ms":1786845521390,"raw":{"event_type":"price_change","market":"0xd5f15f31689703aea70b93a52194a0964220d10d92ee7497346f146a8b6ef8ab","price_changes":[{"asset_id":"2151378744569768920256500242561922410292857798164019061749528550808091180185","best_ask":"0.86","best_bid":"0.85","hash":"cf873822b695082cdb6b1da398c566dff201b671","price":"0.01","side":"BUY","size":"5762.54"},{"asset_id":"17406866367975599232214757606801140480252276357934486651183783311435802862074","best_ask":"0.15","best_bid":"0.14","hash":"e2323d76649c0d0926d23a2c540042ce56312eb6","price":"0.99","side":"SELL","size":"5762.54"}],"timestamp":"1786845521175"}}
{"f":1419,"recv_ms":1786845521397,"raw":{"event_type":"price_change","market":"0xd5f15f31689703aea70b93a52194a0964220d10d92ee7497346f146a8b6ef8ab","price_changes":[{"asset_id":"2151378744569768920256500242561922410292857798164019061749528550808091180185","best_ask":"0.86","best_bid":"0.85","hash":"7e5892b165072d8c0d649c781d2f23574c573788","price":"0.01","side":"BUY","size":"5757.53"},{"asset_id":"17406866367975599232214757606801140480252276357934486651183783311435802862074","best_ask":"0.15","best_bid":"0.14","hash":"a620bdbff53d6f13cf1c98a02a900a8162bc20d3","price":"0.99","side":"SELL","size":"5757.53"}],"timestamp":"1786845521180"}}
{"f":1420,"recv_ms":1786845521397,"raw":{"event_type":"price_change","market":"0xd5f15f31689703aea70b93a52194a0964220d10d92ee7497346f146a8b6ef8ab","price_changes":[{"asset_id":"2151378744569768920256500242561922410292857798164019061749528550808091180185","best_ask":"0.86","best_bid":"0.85","hash":"de2bf5f883c5db99ee1fcab5cd202c2dff635750","price":"0.56","side":"BUY","size":"149"},{"asset_id":"17406866367975599232214757606801140480252276357934486651183783311435802862074","best_ask":"0.15","best_bid":"0.14","hash":"00048d9dda8f0fd36bb5f8c2eb760235030650ad","price":"0.44","side":"SELL","size":"149"}],"timestamp":"1786845521181"}}
{"f":1421,"recv_ms":1786845521402,"raw":{"event_type":"price_change","market":"0xd5f15f31689703aea70b93a52194a0964220d10d92ee7497346f146a8b6ef8ab","price_changes":[{"asset_id":"2151378744569768920256500242561922410292857798164019061749528550808091180185","best_ask":"0.86","best_bid":"0.85","hash":"872c2ea249321a5d0e71aa607fce9aebc9761b92","price":"0.57","side":"BUY","size":"54"},{"asset_id":"17406866367975599232214757606801140480252276357934486651183783311435802862074","best_ask":"0.15","best_bid":"0.14","hash":"fa5caae146439323f9d16a9c9e9e8fecb31cc8aa","price":"0.43","side":"SELL","size":"54"}],"timestamp":"1786845521187"}}
{"f":1422,"recv_ms":1786845521412,"raw":{"event_type":"price_change","market":"0xd5f15f31689703aea70b93a52194a0964220d10d92ee7497346f146a8b6ef8ab","price_changes":[{"asset_id":"2151378744569768920256500242561922410292857798164019061749528550808091180185","best_ask":"0.86","best_bid":"0.85","hash":"aabf38bfbb643dc9e05b3d92c5e536c22bce2f81","price":"0.8","side":"BUY","size":"166"},{"asset_id":"17406866367975599232214757606801140480252276357934486651183783311435802862074","best_ask":"0.15","best_bid":"0.14","hash":"5b70d529b4216c09ea959209a5d29fec9e5ffae9","price":"0.2","side":"SELL","size":"166"}],"timestamp":"1786845521198"}}
{"f":1423,"recv_ms":1786845521426,"raw":{"event_type":"price_change","market":"0xd5f15f31689703aea70b93a52194a0964220d10d92ee7497346f146a8b6ef8ab","price_changes":[{"asset_id":"2151378744569768920256500242561922410292857798164019061749528550808091180185","best_ask":"0.86","best_bid":"0.85","hash":"c1c1fc962df7f4c9d93d0fa409b1ea40b2d2afbb","price":"0.01","side":"BUY","size":"5752.53"},{"asset_id":"17406866367975599232214757606801140480252276357934486651183783311435802862074","best_ask":"0.15","best_bid":"0.14","hash":"8288bef7cffc112417eec60a2cc3d8697d02f7da","price":"0.99","side":"SELL","size":"5752.53"}],"timestamp":"1786845521201"}}
{"f":1424,"recv_ms":1786845521426,"raw":{"event_type":"price_change","market":"0xd5f15f31689703aea70b93a52194a0964220d10d92ee7497346f146a8b6ef8ab","price_changes":[{"asset_id":"2151378744569768920256500242561922410292857798164019061749528550808091180185","best_ask":"0.86","best_bid":"0.85","hash":"1c8a3a4d255746e55d1b321fc6a32a6e3a67f61c","price":"0.01","side":"BUY","size":"5758.53"},{"asset_id":"17406866367975599232214757606801140480252276357934486651183783311435802862074","best_ask":"0.15","best_bid":"0.14","hash":"ed1c2a0a08dbb0fada97916e2501efd737379069","price":"0.99","side":"SELL","size":"5758.53"}],"timestamp":"1786845521212"}}
{"f":1425,"recv_ms":1786845521430,"raw":{"event_type":"price_change","market":"0xd5f15f31689703aea70b93a52194a0964220d10d92ee7497346f146a8b6ef8ab","price_changes":[{"asset_id":"17406866367975599232214757606801140480252276357934486651183783311435802862074","best_ask":"0.15","best_bid":"0.14","hash":"797b367a65a953e23ac2d0f424acda08ce72c2bf","price":"0.01","side":"BUY","size":"5683.18"},{"asset_id":"2151378744569768920256500242561922410292857798164019061749528550808091180185","best_ask":"0.86","best_bid":"0.85","hash":"20ef2538cfd39d074ce2a1c436aca29808e1e446","price":"0.99","side":"SELL","size":"5683.18"}],"timestamp":"1786845521215"}}
{"f":1426,"recv_ms":1786845521430,"raw":{"event_type":"price_change","market":"0xd5f15f31689703aea70b93a52194a0964220d10d92ee7497346f146a8b6ef8ab","price_changes":[{"asset_id":"2151378744569768920256500242561922410292857798164019061749528550808091180185","best_ask":"0.86","best_bid":"0.85","hash":"18256417fac9078b01bf8fbde1c5d4367805ec41","price":"0.01","side":"BUY","size":"5858.53"},{"asset_id":"17406866367975599232214757606801140480252276357934486651183783311435802862074","best_ask":"0.15","best_bid":"0.14","hash":"160868d618490ddcc27900ec8408479f17468afb","price":"0.99","side":"SELL","size":"5858.53"}],"timestamp":"1786845521216"}}
{"f":1427,"recv_ms":1786845521434,"raw":{"event_type":"price_change","market":"0xd5f15f31689703aea70b93a52194a0964220d10d92ee7497346f146a8b6ef8ab","price_changes":[{"asset_id":"17406866367975599232214757606801140480252276357934486651183783311435802862074","best_ask":"0.15","best_bid":"0.14","hash":"ee9b493cbc24ba941d01ce66f167d7a8eece0d56","price":"0.01","side":"BUY","size":"5688.18"},{"asset_id":"2151378744569768920256500242561922410292857798164019061749528550808091180185","best_ask":"0.86","best_bid":"0.85","hash":"9fa189d339994773aecf11c911a70069a173731c","price":"0.99","side":"SELL","size":"5688.18"}],"timestamp":"1786845521223"}}
{"f":1428,"recv_ms":1786845521436,"raw":{"event_type":"price_change","market":"0xd5f15f31689703aea70b93a52194a0964220d10d92ee7497346f146a8b6ef8ab","price_changes":[{"asset_id":"2151378744569768920256500242561922410292857798164019061749528550808091180185","best_ask":"0.86","best_bid":"0.85","hash":"7330344e936b637a7354327d28b12d0a79428566","price":"0.85","side":"BUY","size":"309.97"},{"asset_id":"17406866367975599232214757606801140480252276357934486651183783311435802862074","best_ask":"0.15","best_bid":"0.14","hash":"691561e3d1f129062ba3370e2d7113ac2ea57251","price":"0.15","side":"SELL","size":"309.97"}],"timestamp":"1786845521224"}}
{"f":1429,"recv_ms":1786845521436,"raw":{"event_type":"price_change","market":"0xd5f15f31689703aea70b93a52194a0964220d10d92ee7497346f146a8b6ef8ab","price_changes":[{"asset_id":"17406866367975599232214757606801140480252276357934486651183783311435802862074","best_ask":"0.15","best_bid":"0.14","hash":"62bc95885c080e61c4c038723253d991036462c8","price":"0.01","side":"BUY","size":"5693.18"},{"asset_id":"2151378744569768920256500242561922410292857798164019061749528550808091180185","best_ask":"0.86","best_bid":"0.85","hash":"ccc23b78971a609ea4db04c261fe46dddfab2f4f","price":"0.99","side":"SELL","size":"5693.18"}],"timestamp":"1786845521225"}}
{"f":1430,"recv_ms":1786845521453,"raw":{"event_type":"price_change","market":"0xd5f15f31689703aea70b93a52194a0964220d10d92ee7497346f146a8b6ef8ab","price_changes":[{"asset_id":"17406866367975599232214757606801140480252276357934486651183783311435802862074","best_ask":"0.15","best_bid":"0.14","hash":"d779a8e08a3dc59b4848661b08c6a25880952f95","price":"0.01","side":"BUY","size":"5688.18"},{"asset_id":"2151378744569768920256500242561922410292857798164019061749528550808091180185","best_ask":"0.86","best_bid":"0.85","hash":"07eac746bc5fe2972541d96cc198b1fd14eb2f00","price":"0.99","side":"SELL","size":"5688.18"}],"timestamp":"1786845521226"}}
{"f":1431,"recv_ms":1786845521453,"raw":{"event_type":"price_change","market":"0xd5f15f31689703aea70b93a52194a0964220d10d92ee7497346f146a8b6ef8ab","price_changes":[{"asset_id":"2151378744569768920256500242561922410292857798164019061749528550808091180185","best_ask":"0.86","best_bid":"0.85","hash":"f5cd71921a666953cd748a9cf199eeffd1f9f4d0","price":"0.75","side":"BUY","size":"97.9"},{"asset_id":"17406866367975599232214757606801140480252276357934486651183783311435802862074","best_ask":"0.15","best_bid":"0.14","hash":"e27f4a2282f8fb922a7c362f59c5b15aacc76cfd","price":"0.25","side":"SELL","size":"97.9"}],"timestamp":"1786845521240"}}
{"f":1432,"recv_ms":1786845521459,"raw":{"event_type":"price_change","market":"0xd5f15f31689703aea70b93a52194a0964220d10d92ee7497346f146a8b6ef8ab","price_changes":[{"asset_id":"2151378744569768920256500242561922410292857798164019061749528550808091180185","best_ask":"0.86","best_bid":"0.85","hash":"b0d95a1e14d3a4a5f37150d62f59e64a2fec287c","price":"0.01","side":"BUY","size":"5852.53"},{"asset_id":"17406866367975599232214757606801140480252276357934486651183783311435802862074","best_ask":"0.15","best_bid":"0.14","hash":"49d39b6fe8583fcdbc50abb78bd093dbb825de8d","price":"0.99","side":"SELL","size":"5852.53"}],"timestamp":"1786845521243"}}
{"f":1433,"recv_ms":1786845521459,"raw":{"event_type":"price_change","market":"0xd5f15f31689703aea70b93a52194a0964220d10d92ee7497346f146a8b6ef8ab","price_changes":[{"asset_id":"2151378744569768920256500242561922410292857798164019061749528550808091180185","best_ask":"0.86","best_bid":"0.85","hash":"c02477f39b0b10e2305acd79e2ce21d533e6712e","price":"0.01","side":"BUY","size":"5752.53"},{"asset_id":"17406866367975599232214757606801140480252276357934486651183783311435802862074","best_ask":"0.15","best_bid":"0.14","hash":"ad01e5d69ad78f00801431404cfca21ec933795e","price":"0.99","side":"SELL","size":"5752.53"}],"timestamp":"1786845521247"}}
{"f":1434,"recv_ms":1786845521503,"raw":{"event_type":"price_change","market":"0xd5f15f31689703aea70b93a52194a0964220d10d92ee7497346f146a8b6ef8ab","price_changes":[{"asset_id":"2151378744569768920256500242561922410292857798164019061749528550808091180185","best_ask":"0.86","best_bid":"0.85","hash":"e3a0383b9aef1ef4bc5d4af8fc18ac964cb182b9","price":"0.01","side":"BUY","size":"5852.53"},{"asset_id":"17406866367975599232214757606801140480252276357934486651183783311435802862074","best_ask":"0.15","best_bid":"0.14","hash":"78de31ad60d8d2c9b0e15599a5901e69ad4af9ec","price":"0.99","side":"SELL","size":"5852.53"}],"timestamp":"1786845521291"}}
{"f":1435,"recv_ms":1786845521527,"raw":{"event_type":"price_change","market":"0xd5f15f31689703aea70b93a52194a0964220d10d92ee7497346f146a8b6ef8ab","price_changes":[{"asset_id":"17406866367975599232214757606801140480252276357934486651183783311435802862074","best_ask":"0.15","best_bid":"0.14","hash":"d40a3a17ae34159bead3e658c6218b2366845ebe","price":"0.14","side":"BUY","size":"29.17"},{"asset_id":"2151378744569768920256500242561922410292857798164019061749528550808091180185","best_ask":"0.86","best_bid":"0.85","hash":"4b23369d4f44b4a739e59baf5023b5bb1fa8cd1d","price":"0.86","side":"SELL","size":"29.17"}],"timestamp":"1786845521315"}}
{"f":1436,"recv_ms":1786845521527,"raw":{"event_type":"price_change","market":"0xd5f15f31689703aea70b93a52194a0964220d10d92ee7497346f146a8b6ef8ab","price_changes":[{"asset_id":"2151378744569768920256500242561922410292857798164019061749528550808091180185","best_ask":"0.86","best_bid":"0.85","hash":"4b23369d4f44b4a739e59baf5023b5bb1fa8cd1d","price":"0.86","side":"SELL","size":"29.17"},{"asset_id":"17406866367975599232214757606801140480252276357934486651183783311435802862074","best_ask":"0.15","best_bid":"0.14","hash":"d40a3a17ae34159bead3e658c6218b2366845ebe","price":"0.14","side":"BUY","size":"29.17"}],"timestamp":"1786845521315"}}
{"f":1437,"recv_ms":1786845521539,"raw":{"event_type":"price_change","market":"0xd5f15f31689703aea70b93a52194a0964220d10d92ee7497346f146a8b6ef8ab","price_changes":[{"asset_id":"2151378744569768920256500242561922410292857798164019061749528550808091180185","best_ask":"0.86","best_bid":"0.85","hash":"f58a49aeef24436c15b27c20020228669493f58e","price":"0.8","side":"BUY","size":"66"},{"asset_id":"17406866367975599232214757606801140480252276357934486651183783311435802862074","best_ask":"0.15","best_bid":"0.14","hash":"d223d2860240652d7bf5376aac6cefed0428c77c","price":"0.2","side":"SELL","size":"66"}],"timestamp":"1786845521320"}}
{"f":1438,"recv_ms":1786845521545,"raw":{"event_type":"price_change","market":"0xd5f15f31689703aea70b93a52194a0964220d10d92ee7497346f146a8b6ef8ab","price_changes":[{"asset_id":"2151378744569768920256500242561922410292857798164019061749528550808091180185","best_ask":"0.86","best_bid":"0.85","hash":"4c1f795dbbadd4624791f06143ffa6dd52e01f64","price":"0.01","side":"BUY","size":"5858.53"},{"asset_id":"17406866367975599232214757606801140480252276357934486651183783311435802862074","best_ask":"0.15","best_bid":"0.14","hash":"e16a59878dbcc32700e47b1959ae22ec56a630a2","price":"0.99","side":"SELL","size":"5858.53"}],"timestamp":"1786845521324"}}
{"f":1439,"recv_ms":1786845521545,"raw":{"event_type":"price_change","market":"0xd5f15f31689703aea70b93a52194a0964220d10d92ee7497346f146a8b6ef8ab","price_changes":[{"asset_id":"2151378744569768920256500242561922410292857798164019061749528550808091180185","best_ask":"0.86","best_bid":"0.85","hash":"22840d5d13a3546d99081cce16edb72a62ddf8b1","price":"0.01","side":"BUY","size":"5863.53"},{"asset_id":"17406866367975599232214757606801140480252276357934486651183783311435802862074","best_ask":"0.15","best_bid":"0.14","hash":"6e3ef8752b05c42c431073bf91d00e7cdb80b0c4","price":"0.99","side":"SELL","size":"5863.53"}],"timestamp":"1786845521334"}}
{"f":1440,"recv_ms":1786845521556,"raw":{"event_type":"price_change","market":"0xd5f15f31689703aea70b93a52194a0964220d10d92ee7497346f146a8b6ef8ab","price_changes":[{"asset_id":"2151378744569768920256500242561922410292857798164019061749528550808091180185","best_ask":"0.86","best_bid":"0.85","hash":"17d45c0deaebcb071643627cc22af6c64f12a5b7","price":"0.01","side":"BUY","size":"5868.53"},{"asset_id":"17406866367975599232214757606801140480252276357934486651183783311435802862074","best_ask":"0.15","best_bid":"0.14","hash":"2ab1ba166403830c9a465c057211b212df246402","price":"0.99","side":"SELL","size":"5868.53"}],"timestamp":"1786845521335"}}
{"f":1441,"recv_ms":1786845521556,"raw":{"event_type":"price_change","market":"0xd5f15f31689703aea70b93a52194a0964220d10d92ee7497346f146a8b6ef8ab","price_changes":[{"asset_id":"2151378744569768920256500242561922410292857798164019061749528550808091180185","best_ask":"0.86","best_bid":"0.85","hash":"5097455e0ea43df1283937cf5d081864b48521e3","price":"0.01","side":"BUY","size":"5873.53"},{"asset_id":"17406866367975599232214757606801140480252276357934486651183783311435802862074","best_ask":"0.15","best_bid":"0.14","hash":"cc481b75e74ec409a98b2f087eb96150e15e8c29","price":"0.99","side":"SELL","size":"5873.53"}],"timestamp":"1786845521335"}}
{"f":1442,"recv_ms":1786845521558,"raw":{"event_type":"price_change","market":"0xd5f15f31689703aea70b93a52194a0964220d10d92ee7497346f146a8b6ef8ab","price_changes":[{"asset_id":"2151378744569768920256500242561922410292857798164019061749528550808091180185","best_ask":"0.86","best_bid":"0.85","hash":"3aa15edb964fef06828df5ead0b6d701cdceab5a","price":"0.01","side":"BUY","size":"5773.53"},{"asset_id":"17406866367975599232214757606801140480252276357934486651183783311435802862074","best_ask":"0.15","best_bid":"0.14","hash":"7c1c861191c4f7b830a2c4360eb71dfc91833cc9","price":"0.99","side":"SELL","size":"5773.53"}],"timestamp":"1786845521345"}}
{"f":1443,"recv_ms":1786845521558,"raw":{"event_type":"price_change","market":"0xd5f15f31689703aea70b93a52194a0964220d10d92ee7497346f146a8b6ef8ab","price_changes":[{"asset_id":"2151378744569768920256500242561922410292857798164019061749528550808091180185","best_ask":"0.86","best_bid":"0.85","hash":"4bf4683c7d6ee2159494c6cb3afd6ec6ac4d4c7d","price":"0.01","side":"BUY","size":"5767.53"},{"asset_id":"17406866367975599232214757606801140480252276357934486651183783311435802862074","best_ask":"0.15","best_bid":"0.14","hash":"82e705d6f67b514ef8e0ddfd40cc643ef62e081f","price":"0.99","side":"SELL","size":"5767.53"}],"timestamp":"1786845521345"}}
{"f":1444,"recv_ms":1786845521581,"raw":{"event_type":"price_change","market":"0xd5f15f31689703aea70b93a52194a0964220d10d92ee7497346f146a8b6ef8ab","price_changes":[{"asset_id":"2151378744569768920256500242561922410292857798164019061749528550808091180185","best_ask":"0.86","best_bid":"0.85","hash":"4e4b1161995490e80acf3f1da1ea2617f055580a","price":"0.01","side":"BUY","size":"5772.54"},{"asset_id":"17406866367975599232214757606801140480252276357934486651183783311435802862074","best_ask":"0.15","best_bid":"0.14","hash":"7b970c12bbfd76643b3017e177665ae5fd5cf72c","price":"0.99","side":"SELL","size":"5772.54"}],"timestamp":"1786845521354"}}
{"f":1445,"recv_ms":1786845521587,"raw":{"event_type":"price_change","market":"0xd5f15f31689703aea70b93a52194a0964220d10d92ee7497346f146a8b6ef8ab","price_changes":[{"asset_id":"2151378744569768920256500242561922410292857798164019061749528550808091180185","best_ask":"0.86","best_bid":"0.85","hash":"1bb8cf2d3a7f4ff3fd54f0ff5a8de2515100fa43","price":"0.01","side":"BUY","size":"5767.54"},{"asset_id":"17406866367975599232214757606801140480252276357934486651183783311435802862074","best_ask":"0.15","best_bid":"0.14","hash":"b73c04236c3eb4c7dce3b8b6e70feb8987604a9c","price":"0.99","side":"SELL","size":"5767.54"}],"timestamp":"1786845521370"}}
{"f":1446,"recv_ms":1786845521587,"raw":{"event_type":"price_change","market":"0xd5f15f31689703aea70b93a52194a0964220d10d92ee7497346f146a8b6ef8ab","price_changes":[{"asset_id":"2151378744569768920256500242561922410292857798164019061749528550808091180185","best_ask":"0.86","best_bid":"0.85","hash":"6462a02ff334d8dd0504a0bd562bd5e6cf4b8a60","price":"0.84","side":"BUY","size":"76.72"},{"asset_id":"17406866367975599232214757606801140480252276357934486651183783311435802862074","best_ask":"0.15","best_bid":"0.14","hash":"3ccce3c3e543c5d97ecae3c5d028ae2a86f50423","price":"0.16","side":"SELL","size":"76.72"}],"timestamp":"1786845521370"}}
{"f":1447,"recv_ms":1786845521593,"raw":{"event_type":"price_change","market":"0xd5f15f31689703aea70b93a52194a0964220d10d92ee7497346f146a8b6ef8ab","price_changes":[{"asset_id":"2151378744569768920256500242561922410292857798164019061749528550808091180185","best_ask":"0.86","best_bid":"0.85","hash":"0072a180ec18e80357aec43a4a6d33818d5eb2de","price":"0.01","side":"BUY","size":"5867.54"},{"asset_id":"17406866367975599232214757606801140480252276357934486651183783311435802862074","best_ask":"0.15","best_bid":"0.14","hash":"f6dff14476eb1d3dc2d8c08747a6137a5eb6889f","price":"0.99","side":"SELL","size":"5867.54"}],"timestamp":"1786845521379"}}
{"f":1448,"recv_ms":1786845521614,"raw":{"event_type":"price_change","market":"0xd5f15f31689703aea70b93a52194a0964220d10d92ee7497346f146a8b6ef8ab","price_changes":[{"asset_id":"2151378744569768920256500242561922410292857798164019061749528550808091180185","best_ask":"0.86","best_bid":"0.85","hash":"50955d0b9536076548f94dfb9fa705d08a08a76d","price":"0.01","side":"BUY","size":"5862.53"},{"asset_id":"17406866367975599232214757606801140480252276357934486651183783311435802862074","best_ask":"0.15","best_bid":"0.14","hash":"11b1f2b3f6d9ed4ab0d22b89ebf4156796e42d9e","price":"0.99","side":"SELL","size":"5862.53"}],"timestamp":"1786845521382"}}
{"f":1449,"recv_ms":1786845521621,"raw":{"event_type":"price_change","market":"0xd5f15f31689703aea70b93a52194a0964220d10d92ee7497346f146a8b6ef8ab","price_changes":[{"asset_id":"2151378744569768920256500242561922410292857798164019061749528550808091180185","best_ask":"0.86","best_bid":"0.85","hash":"eb49fa8ab2f18711b0bb0142d34b68166f9aca4b","price":"0.01","side":"BUY","size":"5857.53"},{"asset_id":"17406866367975599232214757606801140480252276357934486651183783311435802862074","best_ask":"0.15","best_bid":"0.14","hash":"d59f15d4cbca62e0021d25baa660e47feea711d0","price":"0.99","side":"SELL","size":"5857.53"}],"timestamp":"1786845521405"}}
{"f":1450,"recv_ms":1786845521625,"raw":{"event_type":"price_change","market":"0xd5f15f31689703aea70b93a52194a0964220d10d92ee7497346f146a8b6ef8ab","price_changes":[{"asset_id":"2151378744569768920256500242561922410292857798164019061749528550808091180185","best_ask":"0.86","best_bid":"0.85","hash":"1dc858a22482398f710f3ccb7d4baae02291ff18","price":"0.01","side":"BUY","size":"5757.53"},{"asset_id":"17406866367975599232214757606801140480252276357934486651183783311435802862074","best_ask":"0.15","best_bid":"0.14","hash":"e77e0fa64130f96f2f7382bdf9976481c22a45a8","price":"0.99","side":"SELL","size":"5757.53"}],"timestamp":"1786845521410"}}
{"f":1451,"recv_ms":1786845521625,"raw":{"event_type":"price_change","market":"0xd5f15f31689703aea70b93a52194a0964220d10d92ee7497346f146a8b6ef8ab","price_changes":[{"asset_id":"2151378744569768920256500242561922410292857798164019061749528550808091180185","best_ask":"0.86","best_bid":"0.85","hash":"09b999f23d72f43709554f2f2dbde825d2af97b6","price":"0.01","side":"BUY","size":"5763.53"},{"asset_id":"17406866367975599232214757606801140480252276357934486651183783311435802862074","best_ask":"0.15","best_bid":"0.14","hash":"002e640119955672ce2b941b325b5763131cf49d","price":"0.99","side":"SELL","size":"5763.53"}],"timestamp":"1786845521411"}}
{"f":1452,"recv_ms":1786845521625,"raw":{"event_type":"price_change","market":"0xd5f15f31689703aea70b93a52194a0964220d10d92ee7497346f146a8b6ef8ab","price_changes":[{"asset_id":"17406866367975599232214757606801140480252276357934486651183783311435802862074","best_ask":"0.15","best_bid":"0.14","hash":"547100dd7f7622e5d6183af829ba2f08718f8d07","price":"0.14","side":"BUY","size":"28"},{"asset_id":"2151378744569768920256500242561922410292857798164019061749528550808091180185","best_ask":"0.86","best_bid":"0.85","hash":"2a840afbe58b20ae52b9dfbf49f20b564691861f","price":"0.86","side":"SELL","size":"28"}],"timestamp":"1786845521414"}}
{"f":1453,"recv_ms":1786845521643,"raw":{"event_type":"price_change","market":"0xd5f15f31689703aea70b93a52194a0964220d10d92ee7497346f146a8b6ef8ab","price_changes":[{"asset_id":"2151378744569768920256500242561922410292857798164019061749528550808091180185","best_ask":"0.86","best_bid":"0.85","hash":"6ab4f17815db55b4f03b26d2f56987cb8e669b84","price":"0.01","side":"BUY","size":"5758.53"},{"asset_id":"17406866367975599232214757606801140480252276357934486651183783311435802862074","best_ask":"0.15","best_bid":"0.14","hash":"bac0af724f6469d254665e6ee4ae092dfbb956ca","price":"0.99","side":"SELL","size":"5758.53"}],"timestamp":"1786845521423"}}
{"f":1454,"recv_ms":1786845521646,"raw":{"event_type":"price_change","market":"0xd5f15f31689703aea70b93a52194a0964220d10d92ee7497346f146a8b6ef8ab","price_changes":[{"asset_id":"2151378744569768920256500242561922410292857798164019061749528550808091180185","best_ask":"0.86","best_bid":"0.85","hash":"3f5f45206ac960597a9cc02e86d602a54a6b2471","price":"0.74","side":"BUY","size":"0"},{"asset_id":"17406866367975599232214757606801140480252276357934486651183783311435802862074","best_ask":"0.15","best_bid":"0.14","hash":"1c55ed6c456d53c2e2bf12fb8e099b9b773a0615","price":"0.26","side":"SELL","size":"0"}],"timestamp":"1786845521430"}}
{"f":1455,"recv_ms":1786845521646,"raw":{"asset_id":"2151378744569768920256500242561922410292857798164019061749528550808091180185","event_type":"last_trade_price","fee_rate_bps":"0","market":"0xd5f15f31689703aea70b93a52194a0964220d10d92ee7497346f146a8b6ef8ab","price":"0.86","side":"BUY","size":"5.81395","timestamp":"1786845521427","transaction_hash":"0x05ca436a9dd4856f865a74bb08e96cc592a68a0bde05c7338cee83fe1f4bc346"}}
{"f":1456,"recv_ms":1786845521646,"raw":{"event_type":"price_change","market":"0xd5f15f31689703aea70b93a52194a0964220d10d92ee7497346f146a8b6ef8ab","price_changes":[{"asset_id":"2151378744569768920256500242561922410292857798164019061749528550808091180185","best_ask":"0.86","best_bid":"0.85","hash":"e1e766c32841bed4036bdd2e01a7b38c0c7fcb14","price":"0.01","side":"BUY","size":"5763.53"},{"asset_id":"17406866367975599232214757606801140480252276357934486651183783311435802862074","best_ask":"0.15","best_bid":"0.14","hash":"486c6737b0fff628c4e48d48a7d680386cc6e08d","price":"0.99","side":"SELL","size":"5763.53"}],"timestamp":"1786845521430"}}
{"f":1457,"recv_ms":1786845521646,"raw":{"event_type":"price_change","market":"0xd5f15f31689703aea70b93a52194a0964220d10d92ee7497346f146a8b6ef8ab","price_changes":[{"asset_id":"2151378744569768920256500242561922410292857798164019061749528550808091180185","best_ask":"0.86","best_bid":"0.85","hash":"5391528c99e1cfbf5cfda35a5c23c5fce6d97a17","price":"0.01","side":"BUY","size":"5758.53"},{"asset_id":"17406866367975599232214757606801140480252276357934486651183783311435802862074","best_ask":"0.15","best_bid":"0.14","hash":"caf62ec8cec8383d78d66c5d44a02b27db9c86f9","price":"0.99","side":"SELL","size":"5758.53"}],"timestamp":"1786845521431"}}
{"f":1458,"recv_ms":1786845521655,"raw":{"event_type":"price_change","market":"0xd5f15f31689703aea70b93a52194a0964220d10d92ee7497346f146a8b6ef8ab","price_changes":[{"asset_id":"17406866367975599232214757606801140480252276357934486651183783311435802862074","best_ask":"0.15","best_bid":"0.14","hash":"a3e06bbeefb2a7245333f1e412c4f778b95e1269","price":"0.05","side":"BUY","size":"464.7"},{"asset_id":"2151378744569768920256500242561922410292857798164019061749528550808091180185","best_ask":"0.86","best_bid":"0.85","hash":"862d4604d8259c89ce6a269f789dfd47d031a1d3","price":"0.95","side":"SELL","size":"464.7"}],"timestamp":"1786845521435"}}
{"f":1459,"recv_ms":1786845521655,"raw":{"event_type":"price_change","market":"0xd5f15f31689703aea70b93a52194a0964220d10d92ee7497346f146a8b6ef8ab","price_changes":[{"asset_id":"2151378744569768920256500242561922410292857798164019061749528550808091180185","best_ask":"0.86","best_bid":"0.85","hash":"bb2cbb10b626bf7289405d7ba57c7b5314213937","price":"0.01","side":"BUY","size":"5753.53"},{"asset_id":"17406866367975599232214757606801140480252276357934486651183783311435802862074","best_ask":"0.15","best_bid":"0.14","hash":"08920254b64450b82b3b7806e189e340eca755a7","price":"0.99","side":"SELL","size":"5753.53"}],"timestamp":"1786845521436"}}
{"f":1460,"recv_ms":1786845521659,"raw":{"event_type":"price_change","market":"0xd5f15f31689703aea70b93a52194a0964220d10d92ee7497346f146a8b6ef8ab","price_changes":[{"asset_id":"2151378744569768920256500242561922410292857798164019061749528550808091180185","best_ask":"0.86","best_bid":"0.85","hash":"6334ebeba9a543757b2cdd45124c3220821a698f","price":"0.01","side":"BUY","size":"5747.53"},{"asset_id":"17406866367975599232214757606801140480252276357934486651183783311435802862074","best_ask":"0.15","best_bid":"0.14","hash":"fe6aa4b5ec447d931752a87406226cd96c31ce74","price":"0.99","side":"SELL","size":"5747.53"}],"timestamp":"1786845521444"}}
{"f":1461,"recv_ms":1786845521659,"raw":{"event_type":"price_change","market":"0xd5f15f31689703aea70b93a52194a0964220d10d92ee7497346f146a8b6ef8ab","price_changes":[{"asset_id":"17406866367975599232214757606801140480252276357934486651183783311435802862074","best_ask":"0.15","best_bid":"0.14","hash":"d27ef9b55492d1ce461423425ce486e3f843c802","price":"0.12","side":"BUY","size":"5"},{"asset_id":"2151378744569768920256500242561922410292857798164019061749528550808091180185","best_ask":"0.86","best_bid":"0.85","hash":"a3083bd02932cc44ec714049ab9ceb9faa9985a7","price":"0.88","side":"SELL","size":"5"}],"timestamp":"1786845521447"}}
{"f":1462,"recv_ms":1786845521660,"raw":{"event_type":"price_change","market":"0xd5f15f31689703aea70b93a52194a0964220d10d92ee7497346f146a8b6ef8ab","price_changes":[{"asset_id":"17406866367975599232214757606801140480252276357934486651183783311435802862074","best_ask":"0.15","best_bid":"0.14","hash":"d27ef9b55492d1ce461423425ce486e3f843c802","price":"0.13","side":"BUY","size":"10"},{"asset_id":"2151378744569768920256500242561922410292857798164019061749528550808091180185","best_ask":"0.86","best_bid":"0.85","hash":"a3083bd02932cc44ec714049ab9ceb9faa9985a7","price":"0.87","side":"SELL","size":"10"}],"timestamp":"1786845521447"}}
{"f":1463,"recv_ms":1786845521660,"raw":{"event_type":"price_change","market":"0xd5f15f31689703aea70b93a52194a0964220d10d92ee7497346f146a8b6ef8ab","price_changes":[{"asset_id":"2151378744569768920256500242561922410292857798164019061749528550808091180185","best_ask":"0.86","best_bid":"0.85","hash":"498f7482058ea3972768fcf67d32f110c6742d4c","price":"0.01","side":"BUY","size":"5752.53"},{"asset_id":"17406866367975599232214757606801140480252276357934486651183783311435802862074","best_ask":"0.15","best_bid":"0.14","hash":"84b533c60c052b9dec4a1a9cfb9f239b36c02938","price":"0.99","side":"SELL","size":"5752.53"}],"timestamp":"1786845521448"}}
{"f":1464,"recv_ms":1786845521660,"raw":{"event_type":"price_change","market":"0xd5f15f31689703aea70b93a52194a0964220d10d92ee7497346f146a8b6ef8ab","price_changes":[{"asset_id":"17406866367975599232214757606801140480252276357934486651183783311435802862074","best_ask":"0.15","best_bid":"0.13","hash":"0e71bd81db110c9e093c9e47e2f6ceef769c86ff","price":"0.14","side":"BUY","size":"0"},{"asset_id":"2151378744569768920256500242561922410292857798164019061749528550808091180185","best_ask":"0.87","best_bid":"0.85","hash":"b514ca1eb561c743f6548ea25297b649ff877004","price":"0.86","side":"SELL","size":"0"}],"timestamp":"1786845521448"}}
{"f":1465,"recv_ms":1786845521660,"raw":{"event_type":"price_change","market":"0xd5f15f31689703aea70b93a52194a0964220d10d92ee7497346f146a8b6ef8ab","price_changes":[{"asset_id":"2151378744569768920256500242561922410292857798164019061749528550808091180185","best_ask":"0.87","best_bid":"0.86","hash":"1b5781023d274cb9792659767d9394070a701e7e","price":"0.86","side":"BUY","size":"33.33"},{"asset_id":"17406866367975599232214757606801140480252276357934486651183783311435802862074","best_ask":"0.14","best_bid":"0.13","hash":"c9bb4f7dbdb005392c2f38842833401014699e4f","price":"0.14","side":"SELL","size":"33.33"}],"timestamp":"1786845521449"}}
{"f":1466,"recv_ms":1786845521663,"raw":{"event_type":"price_change","market":"0xd5f15f31689703aea70b93a52194a0964220d10d92ee7497346f146a8b6ef8ab","price_changes":[{"asset_id":"17406866367975599232214757606801140480252276357934486651183783311435802862074","best_ask":"0.14","best_bid":"0.13","hash":"cb1a16b47a5f504cee9f316cb883fe2d8cc0e76b","price":"0.14","side":"SELL","size":"39.33"},{"asset_id":"2151378744569768920256500242561922410292857798164019061749528550808091180185","best_ask":"0.87","best_bid":"0.86","hash":"ad0eef742372ff73c888db70a0ad4ecf5e47c4b2","price":"0.86","side":"BUY","size":"39.33"}],"timestamp":"1786845521450"}}
{"f":1467,"recv_ms":1786845521663,"raw":{"event_type":"price_change","market":"0xd5f15f31689703aea70b93a52194a0964220d10d92ee7497346f146a8b6ef8ab","price_changes":[{"asset_id":"17406866367975599232214757606801140480252276357934486651183783311435802862074","best_ask":"0.14","best_bid":"0.13","hash":"5cd42906d0a5e95e3acdc6177acc21ada9c15a57","price":"0.14","side":"SELL","size":"54.33"},{"asset_id":"2151378744569768920256500242561922410292857798164019061749528550808091180185","best_ask":"0.87","best_bid":"0.86","hash":"918dd096ba241eeaf455e4ef63b7a062b17f6453","price":"0.86","side":"BUY","size":"54.33"}],"timestamp":"1786845521450"}}
{"f":1468,"recv_ms":1786845521664,"raw":{"event_type":"price_change","market":"0xd5f15f31689703aea70b93a52194a0964220d10d92ee7497346f146a8b6ef8ab","price_changes":[{"asset_id":"2151378744569768920256500242561922410292857798164019061749528550808091180185","best_ask":"0.87","best_bid":"0.86","hash":"9e28421a3376b4bd9d1615e69b9fa9c4328fa5af","price":"0.86","side":"BUY","size":"87.66"},{"asset_id":"17406866367975599232214757606801140480252276357934486651183783311435802862074","best_ask":"0.14","best_bid":"0.13","hash":"1e333255730a8b4dcd425ff2a954ee102bc148a6","price":"0.14","side":"SELL","size":"87.66"}],"timestamp":"1786845521451"}}
{"f":1469,"recv_ms":1786845521664,"raw":{"event_type":"price_change","market":"0xd5f15f31689703aea70b93a52194a0964220d10d92ee7497346f146a8b6ef8ab","price_changes":[{"asset_id":"17406866367975599232214757606801140480252276357934486651183783311435802862074","best_ask":"0.14","best_bid":"0.13","hash":"8205bfea50a6408f728069d1916eeb0702332379","price":"0.14","side":"SELL","size":"99.66"},{"asset_id":"2151378744569768920256500242561922410292857798164019061749528550808091180185","best_ask":"0.87","best_bid":"0.86","hash":"0866c74ffe340fb96cf6a40f77f86de0a9626b05","price":"0.86","side":"BUY","size":"99.66"}],"timestamp":"1786845521452"}}
{"f":1470,"recv_ms":1786845521665,"raw":{"event_type":"price_change","market":"0xd5f15f31689703aea70b93a52194a0964220d10d92ee7497346f146a8b6ef8ab","price_changes":[{"asset_id":"17406866367975599232214757606801140480252276357934486651183783311435802862074","best_ask":"0.14","best_bid":"0.13","hash":"80b0e86d90226e435b57a8e3509cf03f07e48319","price":"0.14","side":"SELL","size":"114.66"},{"asset_id":"2151378744569768920256500242561922410292857798164019061749528550808091180185","best_ask":"0.87","best_bid":"0.86","hash":"63b2b91be62287f6a4bd558fc675bcb58d95cdc4","price":"0.86","side":"BUY","size":"114.66"}],"timestamp":"1786845521453"}}
{"f":1471,"recv_ms":1786845521665,"raw":{"event_type":"price_change","market":"0xd5f15f31689703aea70b93a52194a0964220d10d92ee7497346f146a8b6ef8ab","price_changes":[{"asset_id":"17406866367975599232214757606801140480252276357934486651183783311435802862074","best_ask":"0.14","best_bid":"0.13","hash":"ec62c7f78ed91aa7cfae01f9f58bba5c58578dac","price":"0.14","side":"SELL","size":"120.66"},{"asset_id":"2151378744569768920256500242561922410292857798164019061749528550808091180185","best_ask":"0.87","best_bid":"0.86","hash":"0a6ac3c54f8c7aac9212e06f83720f408f8fc8a4","price":"0.86","side":"BUY","size":"120.66"}],"timestamp":"1786845521454"}}
{"f":1472,"recv_ms":1786845521667,"raw":{"event_type":"price_change","market":"0xd5f15f31689703aea70b93a52194a0964220d10d92ee7497346f146a8b6ef8ab","price_changes":[{"asset_id":"17406866367975599232214757606801140480252276357934486651183783311435802862074","best_ask":"0.14","best_bid":"0.13","hash":"1bc1aba1ab5ce64ad25584eeadbd582088ea3281","price":"0.14","side":"SELL","size":"125.66"},{"asset_id":"2151378744569768920256500242561922410292857798164019061749528550808091180185","best_ask":"0.87","best_bid":"0.86","hash":"4c82cafe79988b36ba5be2cda20ee0d07b6e7bf4","price":"0.86","side":"BUY","size":"125.66"}],"timestamp":"1786845521454"}}
{"f":1473,"recv_ms":1786845521668,"raw":{"event_type":"price_change","market":"0xd5f15f31689703aea70b93a52194a0964220d10d92ee7497346f146a8b6ef8ab","price_changes":[{"asset_id":"17406866367975599232214757606801140480252276357934486651183783311435802862074","best_ask":"0.14","best_bid":"0.13","hash":"57cc6ad6ef7e12fae0b42a152ec028fef56bf9d6","price":"0.14","side":"SELL","size":"131.66"},{"asset_id":"2151378744569768920256500242561922410292857798164019061749528550808091180185","best_ask":"0.87","best_bid":"0.86","hash":"5bc89eb343b23ee7081b68d600958ab6df84b9a0","price":"0.86","side":"BUY","size":"131.66"}],"timestamp":"1786845521455"}}
{"f":1474,"recv_ms":1786845521668,"raw":{"event_type":"price_change","market":"0xd5f15f31689703aea70b93a52194a0964220d10d92ee7497346f146a8b6ef8ab","price_changes":[{"asset_id":"2151378744569768920256500242561922410292857798164019061749528550808091180185","best_ask":"0.87","best_bid":"0.86","hash":"131abfd60a7ecb3c8a6b6e6b19bf92ede80f706c","price":"0.86","side":"BUY","size":"163.66"},{"asset_id":"17406866367975599232214757606801140480252276357934486651183783311435802862074","best_ask":"0.14","best_bid":"0.13","hash":"15a144ccb0ff2ad6c6bff8744076556e5b76c7b9","price":"0.14","side":"SELL","size":"163.66"}],"timestamp":"1786845521456"}}
{"f":1475,"recv_ms":1786845521669,"raw":{"event_type":"price_change","market":"0xd5f15f31689703aea70b93a52194a0964220d10d92ee7497346f146a8b6ef8ab","price_changes":[{"asset_id":"2151378744569768920256500242561922410292857798164019061749528550808091180185","best_ask":"0.87","best_bid":"0.86","hash":"a7f2007ceab793c05761095f9a38bc6261f0e94f","price":"0.01","side":"BUY","size":"5852.53"},{"asset_id":"17406866367975599232214757606801140480252276357934486651183783311435802862074","best_ask":"0.14","best_bid":"0.13","hash":"aec083cc48b557426031daaf063b4424c95302f4","price":"0.99","side":"SELL","size":"5852.53"}],"timestamp":"1786845521457"}}
{"f":1476,"recv_ms":1786845521669,"raw":{"event_type":"price_change","market":"0xd5f15f31689703aea70b93a52194a0964220d10d92ee7497346f146a8b6ef8ab","price_changes":[{"asset_id":"17406866367975599232214757606801140480252276357934486651183783311435802862074","best_ask":"0.14","best_bid":"0.13","hash":"cc506a407fbe56762bbe5412ef61ca3789d9eb37","price":"0.14","side":"SELL","size":"168.66"},{"asset_id":"2151378744569768920256500242561922410292857798164019061749528550808091180185","best_ask":"0.87","best_bid":"0.86","hash":"c43713de6b097cafc3926e4a053e2e33e3f6a464","price":"0.86","side":"BUY","size":"168.66"}],"timestamp":"1786845521458"}}
{"f":1477,"recv_ms":1786845521670,"raw":{"event_type":"price_change","market":"0xd5f15f31689703aea70b93a52194a0964220d10d92ee7497346f146a8b6ef8ab","price_changes":[{"asset_id":"17406866367975599232214757606801140480252276357934486651183783311435802862074","best_ask":"0.14","best_bid":"0.13","hash":"5925afbbdbd85abd628b5f3015a9251c9dc7ae5f","price":"0.14","side":"SELL","size":"162.66"},{"asset_id":"2151378744569768920256500242561922410292857798164019061749528550808091180185","best_ask":"0.87","best_bid":"0.86","hash":"93daed9fa0e09d55783d7cfe4690286aec3799c3","price":"0.86","side":"BUY","size":"162.66"}],"timestamp":"1786845521458"}}
{"f":1478,"recv_ms":1786845521670,"raw":{"event_type":"price_change","market":"0xd5f15f31689703aea70b93a52194a0964220d10d92ee7497346f146a8b6ef8ab","price_changes":[{"asset_id":"2151378744569768920256500242561922410292857798164019061749528550808091180185","best_ask":"0.87","best_bid":"0.86","hash":"f86069529d2bb1cc2d38ccdfe5fd3c44979d3119","price":"0.85","side":"BUY","size":"317.97"},{"asset_id":"17406866367975599232214757606801140480252276357934486651183783311435802862074","best_ask":"0.14","best_bid":"0.13","hash":"c36cabf439def22e49a49a2537221435bc9e9a6e","price":"0.15","side":"SELL","size":"317.97"}],"timestamp":"1786845521459"}}
{"f":1479,"recv_ms":1786845521671,"raw":{"event_type":"price_change","market":"0xd5f15f31689703aea70b93a52194a0964220d10d92ee7497346f146a8b6ef8ab","price_changes":[{"asset_id":"17406866367975599232214757606801140480252276357934486651183783311435802862074","best_ask":"0.14","best_bid":"0.13","hash":"1329f1a8a0f5865d955dd8f8440d79ad5f7017bf","price":"0.14","side":"SELL","size":"167.66"},{"asset_id":"2151378744569768920256500242561922410292857798164019061749528550808091180185","best_ask":"0.87","best_bid":"0.86","hash":"62b8deadf43ff0193d6cf0fff33435c156f311c9","price":"0.86","side":"BUY","size":"167.66"}],"timestamp":"1786845521460"}}
{"f":1480,"recv_ms":1786845521676,"raw":{"event_type":"price_change","market":"0xd5f15f31689703aea70b93a52194a0964220d10d92ee7497346f146a8b6ef8ab","price_changes":[{"asset_id":"2151378744569768920256500242561922410292857798164019061749528550808091180185","best_ask":"0.87","best_bid":"0.86","hash":"1f59ab8ded994e17873e60fd2a244645ce45d0a3","price":"0.86","side":"BUY","size":"200.99"},{"asset_id":"17406866367975599232214757606801140480252276357934486651183783311435802862074","best_ask":"0.14","best_bid":"0.13","hash":"510ebdfd879151bdb5fa4901d27741e6ea1fe698","price":"0.14","side":"SELL","size":"200.99"}],"timestamp":"1786845521460"}}
{"f":1481,"recv_ms":1786845521676,"raw":{"event_type":"price_change","market":"0xd5f15f31689703aea70b93a52194a0964220d10d92ee7497346f146a8b6ef8ab","price_changes":[{"asset_id":"2151378744569768920256500242561922410292857798164019061749528550808091180185","best_ask":"0.87","best_bid":"0.86","hash":"44a5fdd1b6793093d5ee797ed7eae66ffa97be82","price":"0.86","side":"BUY","size":"210.99"},{"asset_id":"17406866367975599232214757606801140480252276357934486651183783311435802862074","best_ask":"0.14","best_bid":"0.13","hash":"2380629a6d06d23b8c4678bdd61fc804e835bd1d","price":"0.14","side":"SELL","size":"210.99"}],"timestamp":"1786845521464"}}
{"f":1482,"recv_ms":1786845521678,"raw":{"event_type":"price_change","market":"0xd5f15f31689703aea70b93a52194a0964220d10d92ee7497346f146a8b6ef8ab","price_changes":[{"asset_id":"2151378744569768920256500242561922410292857798164019061749528550808091180185","best_ask":"0.87","best_bid":"0.86","hash":"705cbb4e07d1b53dee085433444f9fbb576dbb2b","price":"0.85","side":"BUY","size":"307.97"},{"asset_id":"17406866367975599232214757606801140480252276357934486651183783311435802862074","best_ask":"0.14","best_bid":"0.13","hash":"10c08cb129078358844f9a3ba0fdf28967d53ab1","price":"0.15","side":"SELL","size":"307.97"}],"timestamp":"1786845521465"}}
{"f":1483,"recv_ms":1786845521678,"raw":{"event_type":"price_change","market":"0xd5f15f31689703aea70b93a52194a0964220d10d92ee7497346f146a8b6ef8ab","price_changes":[{"asset_id":"2151378744569768920256500242561922410292857798164019061749528550808091180185","best_ask":"0.87","best_bid":"0.86","hash":"133394a5cbe970e224a4be4010e5d98fcbaea8b3","price":"0.85","side":"BUY","size":"297.97"},{"asset_id":"17406866367975599232214757606801140480252276357934486651183783311435802862074","best_ask":"0.14","best_bid":"0.13","hash":"c7d5455daa85c82f0564715594e2bca96badc75b","price":"0.15","side":"SELL","size":"297.97"}],"timestamp":"1786845521466"}}
{"f":1484,"recv_ms":1786845521679,"raw":{"event_type":"price_change","market":"0xd5f15f31689703aea70b93a52194a0964220d10d92ee7497346f146a8b6ef8ab","price_changes":[{"asset_id":"2151378744569768920256500242561922410292857798164019061749528550808091180185","best_ask":"0.87","best_bid":"0.86","hash":"85f00bb532030a3b894fab6cace03357ba537d4c","price":"0.85","side":"BUY","size":"287.97"},{"asset_id":"17406866367975599232214757606801140480252276357934486651183783311435802862074","best_ask":"0.14","best_bid":"0.13","hash":"87444488320bab0f1430686e772132363c48fd32","price":"0.15","side":"SELL","size":"287.97"}],"timestamp":"1786845521467"}}
{"f":1485,"recv_ms":1786845521679,"raw":{"event_type":"price_change","market":"0xd5f15f31689703aea70b93a52194a0964220d10d92ee7497346f146a8b6ef8ab","price_changes":[{"asset_id":"2151378744569768920256500242561922410292857798164019061749528550808091180185","best_ask":"0.87","best_bid":"0.86","hash":"9f711b58f996dbfe24a046b0c0273aee6647442b","price":"0.43","side":"BUY","size":"62.6"},{"asset_id":"17406866367975599232214757606801140480252276357934486651183783311435802862074","best_ask":"0.14","best_bid":"0.13","hash":"ae931c7979d55fa9ef079cb4dd9a29cfd01337b8","price":"0.57","side":"SELL","size":"62.6"}],"timestamp":"1786845521468"}}
{"f":1486,"recv_ms":1786845521680,"raw":{"event_type":"price_change","market":"0xd5f15f31689703aea70b93a52194a0964220d10d92ee7497346f146a8b6ef8ab","price_changes":[{"asset_id":"2151378744569768920256500242561922410292857798164019061749528550808091180185","best_ask":"0.87","best_bid":"0.86","hash":"2d070e3c56e1c051edd7c79fa4c32a3532c9a033","price":"0.85","side":"BUY","size":"277.97"},{"asset_id":"17406866367975599232214757606801140480252276357934486651183783311435802862074","best_ask":"0.14","best_bid":"0.13","hash":"9c58d3b8eccfeb212a5ed8d991d8bbf189d698ed","price":"0.15","side":"SELL","size":"277.97"}],"timestamp":"1786845521468"}}
{"f":1487,"recv_ms":1786845521680,"raw":{"event_type":"price_change","market":"0xd5f15f31689703aea70b93a52194a0964220d10d92ee7497346f146a8b6ef8ab","price_changes":[{"asset_id":"2151378744569768920256500242561922410292857798164019061749528550808091180185","best_ask":"0.87","best_bid":"0.86","hash":"7a60eae9dfe0a7e4f5479d2899737742087b9145","price":"0.86","side":"BUY","size":"220.99"},{"asset_id":"17406866367975599232214757606801140480252276357934486651183783311435802862074","best_ask":"0.14","best_bid":"0.13","hash":"5ca51cb8165478252721f36b3e1ad31278fd40ea","price":"0.14","side":"SELL","size":"220.99"}],"timestamp":"1786845521469"}}
{"f":1488,"recv_ms":1786845521681,"raw":{"event_type":"price_change","market":"0xd5f15f31689703aea70b93a52194a0964220d10d92ee7497346f146a8b6ef8ab","price_changes":[{"asset_id":"2151378744569768920256500242561922410292857798164019061749528550808091180185","best_ask":"0.87","best_bid":"0.86","hash":"dadf1d47e1800ca342211157dc82c6ce8959b149","price":"0.85","side":"BUY","size":"267.97"},{"asset_id":"17406866367975599232214757606801140480252276357934486651183783311435802862074","best_ask":"0.14","best_bid":"0.13","hash":"2cc888e8bcae2188d21e4def3e3723a3526f00df","price":"0.15","side":"SELL","size":"267.97"}],"timestamp":"1786845521469"}}
{"f":1489,"recv_ms":1786845521681,"raw":{"event_type":"price_change","market":"0xd5f15f31689703aea70b93a52194a0964220d10d92ee7497346f146a8b6ef8ab","price_changes":[{"asset_id":"17406866367975599232214757606801140480252276357934486651183783311435802862074","best_ask":"0.14","best_bid":"0.13","hash":"8609c32d3298b45853483fe1092f035b9935efdd","price":"0.13","side":"BUY","size":"40"},{"asset_id":"2151378744569768920256500242561922410292857798164019061749528550808091180185","best_ask":"0.87","best_bid":"0.86","hash":"dabbd4a0850127bf1ac774158072865a9ab8c963","price":"0.87","side":"SELL","size":"40"}],"timestamp":"1786845521470"}}
{"f":1490,"recv_ms":1786845521682,"raw":{"event_type":"price_change","market":"0xd5f15f31689703aea70b93a52194a0964220d10d92ee7497346f146a8b6ef8ab","price_changes":[{"asset_id":"2151378744569768920256500242561922410292857798164019061749528550808091180185","best_ask":"0.87","best_bid":"0.86","hash":"60f470c3d147c554b8f549e94381a8d026c1fd34","price":"0.85","side":"BUY","size":"234.64"},{"asset_id":"17406866367975599232214757606801140480252276357934486651183783311435802862074","best_ask":"0.14","best_bid":"0.13","hash":"c0c9bab10359389bfafdfab1dfeafa180702ca09","price":"0.15","side":"SELL","size":"234.64"}],"timestamp":"1786845521471"}}
{"f":1491,"recv_ms":1786845521682,"raw":{"event_type":"price_change","market":"0xd5f15f31689703aea70b93a52194a0964220d10d92ee7497346f146a8b6ef8ab","price_changes":[{"asset_id":"2151378744569768920256500242561922410292857798164019061749528550808091180185","best_ask":"0.87","best_bid":"0.86","hash":"6dec94b5cb71842602187673bafd34c58ddfb14c","price":"0.85","side":"BUY","size":"224.64"},{"asset_id":"17406866367975599232214757606801140480252276357934486651183783311435802862074","best_ask":"0.14","best_bid":"0.13","hash":"96e8b7fb00a0255c4882fccc6e6a4a2f23a6aaad","price":"0.15","side":"SELL","size":"224.64"}],"timestamp":"1786845521471"}}
{"f":1492,"recv_ms":1786845521683,"raw":{"event_type":"price_change","market":"0xd5f15f31689703aea70b93a52194a0964220d10d92ee7497346f146a8b6ef8ab","price_changes":[{"asset_id":"2151378744569768920256500242561922410292857798164019061749528550808091180185","best_ask":"0.87","best_bid":"0.86","hash":"8fbbe3e3588e4a06eeedfa913e2c114e0638352c","price":"0.85","side":"BUY","size":"214.64"},{"asset_id":"17406866367975599232214757606801140480252276357934486651183783311435802862074","best_ask":"0.14","best_bid":"0.13","hash":"4df0a5fdd83ef03897e188dde9312449dfb14097","price":"0.15","side":"SELL","size":"214.64"}],"timestamp":"1786845521471"}}
{"f":1493,"recv_ms":1786845521683,"raw":{"event_type":"price_change","market":"0xd5f15f31689703aea70b93a52194a0964220d10d92ee7497346f146a8b6ef8ab","price_changes":[{"asset_id":"2151378744569768920256500242561922410292857798164019061749528550808091180185","best_ask":"0.87","best_bid":"0.86","hash":"7bd70b2d508d2776ee2b8f1dd212a0e5164a2bc8","price":"0.85","side":"BUY","size":"204.64"},{"asset_id":"17406866367975599232214757606801140480252276357934486651183783311435802862074","best_ask":"0.14","best_bid":"0.13","hash":"0798828d9106d5f785afbafe08e09cfeca6ed229","price":"0.15","side":"SELL","size":"204.64"}],"timestamp":"1786845521471"}}
{"f":1494,"recv_ms":1786845521683,"raw":{"event_type":"price_change","market":"0xd5f15f31689703aea70b93a52194a0964220d10d92ee7497346f146a8b6ef8ab","price_changes":[{"asset_id":"2151378744569768920256500242561922410292857798164019061749528550808091180185","best_ask":"0.87","best_bid":"0.86","hash":"94b96467c87ff013fcf999973b50aaec2e8e4286","price":"0.85","side":"BUY","size":"194.64"},{"asset_id":"17406866367975599232214757606801140480252276357934486651183783311435802862074","best_ask":"0.14","best_bid":"0.13","hash":"8ebade38dc831f96ff3dda18b1d7a51245965478","price":"0.15","side":"SELL","size":"194.64"}],"timestamp":"1786845521472"}}
{"f":1495,"recv_ms":1786845521684,"raw":{"event_type":"price_change","market":"0xd5f15f31689703aea70b93a52194a0964220d10d92ee7497346f146a8b6ef8ab","price_changes":[{"asset_id":"2151378744569768920256500242561922410292857798164019061749528550808091180185","best_ask":"0.87","best_bid":"0.86","hash":"ecfe5f36eb556d40b000435257556e5620e24a75","price":"0.85","side":"BUY","size":"161.31"},{"asset_id":"17406866367975599232214757606801140480252276357934486651183783311435802862074","best_ask":"0.14","best_bid":"0.13","hash":"d2db50b6fc919a214508f1ba6137511e87a3f3c2","price":"0.15","side":"SELL","size":"161.31"}],"timestamp":"1786845521472"}}
{"f":1496,"recv_ms":1786845521684,"raw":{"event_type":"price_change","market":"0xd5f15f31689703aea70b93a52194a0964220d10d92ee7497346f146a8b6ef8ab","price_changes":[{"asset_id":"2151378744569768920256500242561922410292857798164019061749528550808091180185","best_ask":"0.87","best_bid":"0.86","hash":"5c15835b2937748d439adeb8332762bdbff2e861","price":"0.85","side":"BUY","size":"151.31"},{"asset_id":"17406866367975599232214757606801140480252276357934486651183783311435802862074","best_ask":"0.14","best_bid":"0.13","hash":"22f026d62109171fcd7af11a0f30334020f0495b","price":"0.15","side":"SELL","size":"151.31"}],"timestamp":"1786845521472"}}
{"f":1497,"recv_ms":1786845521684,"raw":{"event_type":"price_change","market":"0xd5f15f31689703aea70b93a52194a0964220d10d92ee7497346f146a8b6ef8ab","price_changes":[{"asset_id":"2151378744569768920256500242561922410292857798164019061749528550808091180185","best_ask":"0.87","best_bid":"0.86","hash":"f30180db5a45f1b3dca54c872401d071bd9fdbba","price":"0.85","side":"BUY","size":"141.31"},{"asset_id":"17406866367975599232214757606801140480252276357934486651183783311435802862074","best_ask":"0.14","best_bid":"0.13","hash":"f01565058d83a98b6b07f28be8ea2dfc241b92b9","price":"0.15","side":"SELL","size":"141.31"}],"timestamp":"1786845521472"}}
{"f":1498,"recv_ms":1786845521684,"raw":{"event_type":"price_change","market":"0xd5f15f31689703aea70b93a52194a0964220d10d92ee7497346f146a8b6ef8ab","price_changes":[{"asset_id":"2151378744569768920256500242561922410292857798164019061749528550808091180185","best_ask":"0.87","best_bid":"0.86","hash":"d14faadadb73c91fc9590b6e6f3a51760130ff8c","price":"0.85","side":"BUY","size":"131.31"},{"asset_id":"17406866367975599232214757606801140480252276357934486651183783311435802862074","best_ask":"0.14","best_bid":"0.13","hash":"b2a5d4f1e80fc4c7b597428555d57ad859b9ff88","price":"0.15","side":"SELL","size":"131.31"}],"timestamp":"1786845521472"}}
{"f":1499,"recv_ms":1786845521684,"raw":{"event_type":"price_change","market":"0xd5f15f31689703aea70b93a52194a0964220d10d92ee7497346f146a8b6ef8ab","price_changes":[{"asset_id":"2151378744569768920256500242561922410292857798164019061749528550808091180185","best_ask":"0.87","best_bid":"0.86","hash":"836415f6e80a90aba41551affcb3eac912fe3117","price":"0.85","side":"BUY","size":"121.31"},{"asset_id":"17406866367975599232214757606801140480252276357934486651183783311435802862074","best_ask":"0.14","best_bid":"0.13","hash":"a2c3135be96e34958a533aee8b8c3ca27f49348f","price":"0.15","side":"SELL","size":"121.31"}],"timestamp":"1786845521473"}}
{"f":1500,"recv_ms":1786845521686,"raw":{"event_type":"price_change","market":"0xd5f15f31689703aea70b93a52194a0964220d10d92ee7497346f146a8b6ef8ab","price_changes":[{"asset_id":"2151378744569768920256500242561922410292857798164019061749528550808091180185","best_ask":"0.87","best_bid":"0.86","hash":"a505086dc4665fb2550227bba6bdcb59b4d215a4","price":"0.86","side":"BUY","size":"230.99"},{"asset_id":"17406866367975599232214757606801140480252276357934486651183783311435802862074","best_ask":"0.14","best_bid":"0.13","hash":"8c3d190df0a3bf213694d3807075e78dec6c0735","price":"0.14","side":"SELL","size":"230.99"}],"timestamp":"1786845521473"}}
{"f":1501,"recv_ms":1786845521686,"raw":{"event_type":"price_change","market":"0xd5f15f31689703aea70b93a52194a0964220d10d92ee7497346f146a8b6ef8ab","price_changes":[{"asset_id":"2151378744569768920256500242561922410292857798164019061749528550808091180185","best_ask":"0.87","best_bid":"0.86","hash":"eba0e59c9a55e980b5183079c1dfd0b36dbd8b2e","price":"0.86","side":"BUY","size":"197.66"},{"asset_id":"17406866367975599232214757606801140480252276357934486651183783311435802862074","best_ask":"0.14","best_bid":"0.13","hash":"0bd70c042ea25f74cfc73fc2c43347504dbb0c71","price":"0.14","side":"SELL","size":"197.66"}],"timestamp":"1786845521474"}}
{"f":1502,"recv_ms":1786845521686,"raw":{"event_type":"price_change","market":"0xd5f15f31689703aea70b93a52194a0964220d10d92ee7497346f146a8b6ef8ab","price_changes":[{"asset_id":"17406866367975599232214757606801140480252276357934486651183783311435802862074","best_ask":"0.14","best_bid":"0.13","hash":"4204d9f9877dfd952d4573520b1b2e2f480820c2","price":"0.11","side":"BUY","size":"40"},{"asset_id":"2151378744569768920256500242561922410292857798164019061749528550808091180185","best_ask":"0.87","best_bid":"0.86","hash":"6c0ede8fec1d028b07ef4024dbbe81aa23823209","price":"0.89","side":"SELL","size":"40"}],"timestamp":"1786845521474"}}
{"f":1503,"recv_ms":1786845521686,"raw":{"event_type":"price_change","market":"0xd5f15f31689703aea70b93a52194a0964220d10d92ee7497346f146a8b6ef8ab","price_changes":[{"asset_id":"2151378744569768920256500242561922410292857798164019061749528550808091180185","best_ask":"0.87","best_bid":"0.86","hash":"17258cd499afe2fe329c034dd97da4211c94f156","price":"0.78","side":"BUY","size":"0"},{"asset_id":"17406866367975599232214757606801140480252276357934486651183783311435802862074","best_ask":"0.14","best_bid":"0.13","hash":"1281880ca2dc22c2e5793bdb4d748c70c7dbed20","price":"0.22","side":"SELL","size":"0"}],"timestamp":"1786845521475"}}
{"f":1504,"recv_ms":1786845521686,"raw":{"event_type":"price_change","market":"0xd5f15f31689703aea70b93a52194a0964220d10d92ee7497346f146a8b6ef8ab","price_changes":[{"asset_id":"2151378744569768920256500242561922410292857798164019061749528550808091180185","best_ask":"0.87","best_bid":"0.86","hash":"9061a0131f0e07e8c9c597033494118b8ab65007","price":"0.85","side":"BUY","size":"101.32"},{"asset_id":"17406866367975599232214757606801140480252276357934486651183783311435802862074","best_ask":"0.14","best_bid":"0.13","hash":"9effd25b7a6c562eb85feeabfae3538f1c293011","price":"0.15","side":"SELL","size":"101.32"}],"timestamp":"1786845521475"}}
{"f":1505,"recv_ms":1786845521686,"raw":{"event_type":"price_change","market":"0xd5f15f31689703aea70b93a52194a0964220d10d92ee7497346f146a8b6ef8ab","price_changes":[{"asset_id":"2151378744569768920256500242561922410292857798164019061749528550808091180185","best_ask":"0.87","best_bid":"0.86","hash":"81e62d43e56dfb0138fe89dba981c9e793de6864","price":"0.84","side":"BUY","size":"66.72"},{"asset_id":"17406866367975599232214757606801140480252276357934486651183783311435802862074","best_ask":"0.14","best_bid":"0.13","hash":"b1fff7f730683baf02a8c60f39deed90d670af9f","price":"0.16","side":"SELL","size":"66.72"}],"timestamp":"1786845521475"}}
{"f":1506,"recv_ms":1786845521688,"raw":{"event_type":"price_change","market":"0xd5f15f31689703aea70b93a52194a0964220d10d92ee7497346f146a8b6ef8ab","price_changes":[{"asset_id":"17406866367975599232214757606801140480252276357934486651183783311435802862074","best_ask":"0.14","best_bid":"0.13","hash":"d4d7c728a6e46fc025862208cf33446b7126eae8","price":"0.12","side":"BUY","size":"35"},{"asset_id":"2151378744569768920256500242561922410292857798164019061749528550808091180185","best_ask":"0.87","best_bid":"0.86","hash":"ff8b5fd39869d5f9265a2ffc10c1dacf6b9e61bb","price":"0.88","side":"SELL","size":"35"}],"timestamp":"1786845521475"}}
{"f":1507,"recv_ms":1786845521688,"raw":{"event_type":"price_change","market":"0xd5f15f31689703aea70b93a52194a0964220d10d92ee7497346f146a8b6ef8ab","price_changes":[{"asset_id":"2151378744569768920256500242561922410292857798164019061749528550808091180185","best_ask":"0.87","best_bid":"0.86","hash":"415f1d381513532ee014410e2de829e331591e04","price":"0.86","side":"BUY","size":"207.66"},{"asset_id":"17406866367975599232214757606801140480252276357934486651183783311435802862074","best_ask":"0.14","best_bid":"0.13","hash":"665d6697d7d1e752a57da722a35f48102052db82","price":"0.14","side":"SELL","size":"207.66"}],"timestamp":"1786845521476"}}
{"f":1508,"recv_ms":1786845521689,"raw":{"event_type":"price_change","market":"0xd5f15f31689703aea70b93a52194a0964220d10d92ee7497346f146a8b6ef8ab","price_changes":[{"asset_id":"2151378744569768920256500242561922410292857798164019061749528550808091180185","best_ask":"0.87","best_bid":"0.86","hash":"406cc2329ff185be7c6522cac718458729122e26","price":"0.56","side":"BUY","size":"139"},{"asset_id":"17406866367975599232214757606801140480252276357934486651183783311435802862074","best_ask":"0.14","best_bid":"0.13","hash":"a07fbe78d443910204460f564e52d5007fe410ef","price":"0.44","side":"SELL","size":"139"}],"timestamp":"1786845521477"}}
{"f":1509,"recv_ms":1786845521689,"raw":{"event_type":"price_change","market":"0xd5f15f31689703aea70b93a52194a0964220d10d92ee7497346f146a8b6ef8ab","price_changes":[{"asset_id":"2151378744569768920256500242561922410292857798164019061749528550808091180185","best_ask":"0.87","best_bid":"0.86","hash":"96bcee108566b62c3336aaa8a61ef3b5d04854fb","price":"0.84","side":"BUY","size":"74.72"},{"asset_id":"17406866367975599232214757606801140480252276357934486651183783311435802862074","best_ask":"0.14","best_bid":"0.13","hash":"17eca2bc9b978810105c6a2073227c697927d441","price":"0.16","side":"SELL","size":"74.72"}],"timestamp":"1786845521477"}}
{"f":1510,"recv_ms":1786845521689,"raw":{"event_type":"price_change","market":"0xd5f15f31689703aea70b93a52194a0964220d10d92ee7497346f146a8b6ef8ab","price_changes":[{"asset_id":"2151378744569768920256500242561922410292857798164019061749528550808091180185","best_ask":"0.87","best_bid":"0.86","hash":"a857cf38e083178c33af79e9d74195f8f4807147","price":"0.85","side":"BUY","size":"93.32"},{"asset_id":"17406866367975599232214757606801140480252276357934486651183783311435802862074","best_ask":"0.14","best_bid":"0.13","hash":"db16c42a74ca155e7234d42a4447f47f4e62af9b","price":"0.15","side":"SELL","size":"93.32"}],"timestamp":"1786845521478"}}
{"f":1511,"recv_ms":1786845521689,"raw":{"event_type":"price_change","market":"0xd5f15f31689703aea70b93a52194a0964220d10d92ee7497346f146a8b6ef8ab","price_changes":[{"asset_id":"17406866367975599232214757606801140480252276357934486651183783311435802862074","best_ask":"0.14","best_bid":"0.13","hash":"3854a0d1fb4e7b2d99973efa92fe699683e32e73","price":"0.15","side":"SELL","size":"76.32"},{"asset_id":"2151378744569768920256500242561922410292857798164019061749528550808091180185","best_ask":"0.87","best_bid":"0.86","hash":"8fb72781a6fe4c0cd82fcb2c39e6d4d182f866bd","price":"0.85","side":"BUY","size":"76.32"}],"timestamp":"1786845521479"}}
{"f":1512,"recv_ms":1786845521690,"raw":{"event_type":"price_change","market":"0xd5f15f31689703aea70b93a52194a0964220d10d92ee7497346f146a8b6ef8ab","price_changes":[{"asset_id":"17406866367975599232214757606801140480252276357934486651183783311435802862074","best_ask":"0.14","best_bid":"0.13","hash":"9eb5085316a817bc7e85442dbe1ebc6c95a0a92a","price":"0.07","side":"BUY","size":"299.86"},{"asset_id":"2151378744569768920256500242561922410292857798164019061749528550808091180185","best_ask":"0.87","best_bid":"0.86","hash":"04d4d7958175153abaf3814d6861d1baada5d0b8","price":"0.93","side":"SELL","size":"299.86"}],"timestamp":"1786845521479"}}
{"f":1513,"recv_ms":1786845521690,"raw":{"event_type":"price_change","market":"0xd5f15f31689703aea70b93a52194a0964220d10d92ee7497346f146a8b6ef8ab","price_changes":[{"asset_id":"17406866367975599232214757606801140480252276357934486651183783311435802862074","best_ask":"0.14","best_bid":"0.13","hash":"4568deba502e519734839401f201f41dd923784f","price":"0.17","side":"SELL","size":"16.51"},{"asset_id":"2151378744569768920256500242561922410292857798164019061749528550808091180185","best_ask":"0.87","best_bid":"0.86","hash":"708ca6651234baf7cda668c05e335a427cbc028c","price":"0.83","side":"BUY","size":"16.51"}],"timestamp":"1786845521479"}}
{"f":1514,"recv_ms":1786845521693,"raw":{"event_type":"price_change","market":"0xd5f15f31689703aea70b93a52194a0964220d10d92ee7497346f146a8b6ef8ab","price_changes":[{"asset_id":"17406866367975599232214757606801140480252276357934486651183783311435802862074","best_ask":"0.14","best_bid":"0.13","hash":"4e2f96b3fad9cc576d18709810c50818098e82cf","price":"0.16","side":"SELL","size":"64.72"},{"asset_id":"2151378744569768920256500242561922410292857798164019061749528550808091180185","best_ask":"0.87","best_bid":"0.86","hash":"afcff9deae081d7fb9a24ec87365269f25c63a4b","price":"0.84","side":"BUY","size":"64.72"}],"timestamp":"1786845521479"}}
{"f":1515,"recv_ms":1786845521693,"raw":{"event_type":"price_change","market":"0xd5f15f31689703aea70b93a52194a0964220d10d92ee7497346f146a8b6ef8ab","price_changes":[{"asset_id":"17406866367975599232214757606801140480252276357934486651183783311435802862074","best_ask":"0.14","best_bid":"0.13","hash":"c570a647bb3db5c1479e1aae8dd327c6a9346b46","price":"0.15","side":"SELL","size":"70.32"},{"asset_id":"2151378744569768920256500242561922410292857798164019061749528550808091180185","best_ask":"0.87","best_bid":"0.86","hash":"53946494041c224e0226c3fbcf932c26f3b29c5a","price":"0.85","side":"BUY","size":"70.32"}],"timestamp":"1786845521480"}}
{"f":1516,"recv_ms":1786845521695,"raw":{"event_type":"price_change","market":"0xd5f15f31689703aea70b93a52194a0964220d10d92ee7497346f146a8b6ef8ab","price_changes":[{"asset_id":"17406866367975599232214757606801140480252276357934486651183783311435802862074","best_ask":"0.14","best_bid":"0.13","hash":"c5dab1815e80eacf7d0102fa825f0bbd4932316d","price":"0.15","side":"SELL","size":"64.32"},{"asset_id":"2151378744569768920256500242561922410292857798164019061749528550808091180185","best_ask":"0.87","best_bid":"0.86","hash":"160c8629e358d7afae5eb875fb11bb68fa44b040","price":"0.85","side":"BUY","size":"64.32"}],"timestamp":"1786845521482"}}
{"f":1517,"recv_ms":1786845521696,"raw":{"event_type":"price_change","market":"0xd5f15f31689703aea70b93a52194a0964220d10d92ee7497346f146a8b6ef8ab","price_changes":[{"asset_id":"17406866367975599232214757606801140480252276357934486651183783311435802862074","best_ask":"0.14","best_bid":"0.13","hash":"4fc2a2a680a716a2df112c705b960dc2c2b19b27","price":"0.16","side":"SELL","size":"59.72"},{"asset_id":"2151378744569768920256500242561922410292857798164019061749528550808091180185","best_ask":"0.87","best_bid":"0.86","hash":"f22d554451e70d4b73ab39ff18580047449b0072","price":"0.84","side":"BUY","size":"59.72"}],"timestamp":"1786845521482"}}
{"f":1518,"recv_ms":1786845521696,"raw":{"event_type":"price_change","market":"0xd5f15f31689703aea70b93a52194a0964220d10d92ee7497346f146a8b6ef8ab","price_changes":[{"asset_id":"17406866367975599232214757606801140480252276357934486651183783311435802862074","best_ask":"0.14","best_bid":"0.13","hash":"a7a80a409e5648e3151d87dc4ffa586943013cce","price":"0.16","side":"SELL","size":"44.72"},{"asset_id":"2151378744569768920256500242561922410292857798164019061749528550808091180185","best_ask":"0.87","best_bid":"0.86","hash":"246e695b80f243a156fefcff864be154ba82285f","price":"0.84","side":"BUY","size":"44.72"}],"timestamp":"1786845521484"}}
{"f":1519,"recv_ms":1786845521696,"raw":{"event_type":"price_change","market":"0xd5f15f31689703aea70b93a52194a0964220d10d92ee7497346f146a8b6ef8ab","price_changes":[{"asset_id":"17406866367975599232214757606801140480252276357934486651183783311435802862074","best_ask":"0.14","best_bid":"0.13","hash":"2163903b99708ea7e47b0b6271d7656a620abd0a","price":"0.15","side":"SELL","size":"59.32"},{"asset_id":"2151378744569768920256500242561922410292857798164019061749528550808091180185","best_ask":"0.87","best_bid":"0.86","hash":"796edd0efab341f8687b278ba4929679626132d8","price":"0.85","side":"BUY","size":"59.32"}],"timestamp":"1786845521485"}}
{"f":1520,"recv_ms":1786845521697,"raw":{"event_type":"price_change","market":"0xd5f15f31689703aea70b93a52194a0964220d10d92ee7497346f146a8b6ef8ab","price_changes":[{"asset_id":"17406866367975599232214757606801140480252276357934486651183783311435802862074","best_ask":"0.14","best_bid":"0.13","hash":"1fc7502801fba77fa2a00159ecfa79eaa73d26fb","price":"0.31","side":"SELL","size":"127"},{"asset_id":"2151378744569768920256500242561922410292857798164019061749528550808091180185","best_ask":"0.87","best_bid":"0.86","hash":"b0bc69e295ec0a136eeaa1b6ca11ddf16d1d64cf","price":"0.69","side":"BUY","size":"127"}],"timestamp":"1786845521485"}}
